File: data-raw/Experiment 2/Results/INSTRON data/Experiment 2.is_ccyclic_RawData/Specimen_RawData_12.csv
Text Inputs : Specimen label,"Short Plate 1 T3"

Time,Extension,Load,Compressive extension,Compressive load,Segment ID,Total Cycle Count
(sec),(mm),(N),(mm),(N),,
0.00000,-0.02602,0.03006,0.00000,-0.03006,12835,0
1.09580,-0.02757,0.01351,0.00155,-0.01351,3220,0
2.41580,-0.69097,-0.31828,0.66495,0.31828,3220,0
3.13180,-1.10563,-8.95335,1.07960,8.95335,3220,0
4.04380,-2.02164,-23.48114,1.99562,23.48114,22476,0
4.54580,-2.52353,-33.14593,2.49751,33.14594,22476,0
4.89580,-2.87351,-40.31138,2.84749,40.31138,22476,0
5.31080,-3.28849,-48.87933,3.26247,48.87933,22476,0
5.90720,-3.88456,-61.10059,3.85854,61.10059,22476,0
6.47680,-4.20957,-65.36926,4.18355,65.36926,22476,0
6.92780,-3.74405,-50.74247,3.71803,50.74247,22412,0
7.43880,-3.23227,-36.66363,3.20625,36.66363,22412,0
8.06580,-2.60534,-23.15201,2.57932,23.15201,22412,0
9.23380,-1.56456,-8.96238,1.53854,8.96238,22412,0
10.20180,-2.55571,-28.69727,2.52969,28.69727,22476,1
10.85180,-3.20553,-43.50256,3.17951,43.50256,22476,1
11.43180,-3.78559,-56.33018,3.75957,56.33018,22476,1
11.95080,-4.30471,-67.74294,4.27868,67.74294,22476,1
12.42180,-4.00857,-56.38981,3.98255,56.38981,22412,1
12.82580,-3.60178,-44.32255,3.57575,44.32255,22412,1
13.21180,-3.21543,-34.54882,3.18941,34.54882,22412,1
13.73680,-2.69043,-23.36834,2.66441,23.36834,22412,1
14.76880,-1.65857,-8.43687,1.63255,8.43687,22412,1
15.50180,-2.23515,-20.77563,2.20913,20.77563,22476,2
15.89380,-2.62763,-29.03160,2.60161,29.03160,22476,2
16.09580,-2.82966,-33.74434,2.80364,33.74434,22476,2
16.32680,-3.06079,-39.05690,3.03477,39.05690,22476,2
16.55180,-3.28569,-44.15643,3.25967,44.15643,22476,2
16.78580,-3.51983,-49.49211,3.49381,49.49211,22476,2
16.97780,-3.71166,-53.76305,3.68564,53.76305,22476,2
17.21380,-3.94783,-58.93591,3.92181,58.93591,22476,2
17.38080,-4.11467,-62.78621,4.08865,62.78621,22476,2
17.56680,-4.30075,-66.83308,4.27473,66.83308,22476,2
17.79580,-4.31872,-65.51994,4.29270,65.51994,22476,2
18.03980,-4.06119,-57.00872,4.03517,57.00872,22412,2
18.37580,-3.72190,-46.88988,3.69588,46.88988,22412,2
18.75380,-3.34368,-36.80587,3.31766,36.80587,22412,2
19.11980,-2.97781,-28.25387,2.95179,28.25387,22412,2
19.95280,-2.14466,-14.42187,2.11864,14.42187,22412,2
20.66180,-1.78666,-11.78044,1.76064,11.78044,22412,2
21.18180,-2.31751,-21.74159,2.29149,21.74159,22476,3
21.50980,-2.64570,-28.63564,2.61968,28.63564,22476,3
21.70680,-2.84272,-33.24056,2.81670,33.24056,22476,3
21.93480,-3.07081,-38.50356,3.04479,38.50356,22476,3
22.14180,-3.27772,-43.32256,3.25170,43.32256,22476,3
22.39580,-3.53189,-49.05066,3.50587,49.05066,22476,3
22.62880,-3.76466,-54.20541,3.73864,54.20541,22476,3
22.92880,-4.06490,-60.98533,4.03888,60.98533,22476,3
23.21780,-4.35383,-67.47019,4.32781,67.47019,22476,3
23.48780,-4.30387,-63.92729,4.27785,63.92729,22476,3
23.81780,-3.96309,-53.11688,3.93707,53.11688,22412,3
24.07980,-3.69987,-45.30676,3.67385,45.30676,22412,3
24.37080,-3.40881,-37.74549,3.38279,37.74549,22412,3
24.68280,-3.09671,-30.20346,3.07069,30.20346,22412,3
25.12080,-2.65869,-21.79570,2.63267,21.79570,22412,3
25.56380,-2.21556,-15.04767,2.18954,15.04768,22412,3
25.98180,-1.79752,-9.46023,1.77150,9.46023,22412,3
26.46280,-1.98501,-14.88067,1.95899,14.88067,22476,3
27.07580,-2.60174,-27.00439,2.57572,27.00439,22476,4
27.44080,-2.96686,-35.51084,2.94084,35.51084,22476,4
27.84580,-3.37188,-44.83732,3.34586,44.83732,22476,4
28.15480,-3.68081,-51.94845,3.65479,51.94845,22476,4
28.50720,-4.03299,-59.77768,4.00697,59.77768,22476,4
28.99380,-4.45879,-68.85268,4.43277,68.85268,22476,4
29.38780,-4.03793,-54.85006,4.01191,54.85006,22412,4
29.79380,-3.62995,-42.86807,3.60393,42.86807,22412,4
30.35680,-3.06679,-29.16702,3.04077,29.16702,22412,4
31.21380,-2.20965,-14.65775,2.18363,14.65775,22412,4
32.19280,-2.08279,-16.45458,2.05677,16.45458,22476,4
32.80480,-2.69680,-28.80406,2.67078,28.80406,22476,5
33.18980,-3.08195,-37.83505,3.05593,37.83505,22476,5
33.49580,-3.38805,-44.84425,3.36203,44.84425,22476,5
33.89380,-3.78589,-53.80615,3.75987,53.80615,22476,5
34.44280,-4.33497,-66.25611,4.30895,66.25611,22476,5
34.92880,-4.16889,-58.37368,4.14287,58.37368,22412,5
35.30180,-3.79208,-47.18594,3.76606,47.18594,22412,5
35.72980,-3.36383,-35.70836,3.33781,35.70836,22412,5
36.17980,-2.91384,-25.68246,2.88782,25.68246,22412,5
37.32580,-1.76768,-8.54534,1.74166,8.54534,22412,5
38.26180,-2.50980,-24.40482,2.48378,24.40482,22476,6
38.86880,-3.11694,-38.29399,3.09092,38.29399,22476,6
39.46580,-3.71388,-51.99536,3.68786,51.99536,22476,6
40.04980,-4.29797,-65.16325,4.27195,65.16325,22476,6
40.55380,-4.20658,-59.24817,4.18056,59.24817,22412,6
40.95780,-3.79805,-46.99399,3.77203,46.99399,22412,6
41.27180,-3.48387,-38.40619,3.45785,38.40619,22412,6
41.66180,-3.09381,-29.12250,3.06779,29.12250,22412,6
42.27380,-2.48174,-18.14075,2.45572,18.14075,22412,6
43.07480,-1.70063,-7.57233,1.67461,7.57233,22412,6
43.84880,-2.49860,-23.87698,2.47258,23.87698,22476,7
44.18880,-2.83875,-31.40141,2.81272,31.40141,22476,7
44.56980,-3.21966,-40.28425,3.19364,40.28424,22476,7
44.91380,-3.56386,-48.35183,3.53784,48.35183,22476,7
45.33080,-3.98091,-57.71533,3.95489,57.71533,22476,7
45.67780,-4.32781,-65.64710,4.30179,65.64710,22476,7
46.03780,-4.33884,-63.34356,4.31282,63.34356,22476,7
46.42580,-3.94060,-50.93962,3.91458,50.93962,22412,7
46.86980,-3.49585,-38.49401,3.46983,38.49401,22412,7
47.48180,-2.88376,-24.64624,2.85774,24.64624,22412,7
48.54380,-1.82152,-8.89535,1.79550,8.89535,22412,7
49.49280,-2.51065,-23.99072,2.48463,23.99072,22604,8
50.23080,-3.24868,-40.77688,3.22266,40.77688,22604,8
50.90780,-3.92593,-56.31687,3.89991,56.31688,22604,8
51.46280,-4.48084,-68.82925,4.45482,68.82925,22604,8
51.97280,-4.05241,-53.82362,4.02639,53.82362,22540,8
52.42280,-3.60077,-40.70957,3.57475,40.70957,22540,8
52.88680,-3.13671,-29.62493,3.11069,29.62493,22540,8
53.51780,-2.50573,-18.13509,2.47971,18.13509,22540,8
54.22380,-1.79951,-8.49522,1.77349,8.49522,22540,8
54.96180,-2.39113,-21.31396,2.36511,21.31396,22604,9
55.61880,-3.04868,-35.88453,3.02266,35.88453,22604,9
56.10720,-3.53671,-47.38092,3.51069,47.38092,22604,9
56.61680,-4.04677,-58.79563,4.02075,58.79563,22604,9
57.06980,-4.49963,-69.19151,4.47361,69.19151,22604,9
57.41680,-4.21473,-58.71468,4.18871,58.71468,22540,9
57.79280,-3.83468,-47.29021,3.80866,47.29021,22540,9
58.29880,-3.32841,-33.92239,3.30239,33.92239,22540,9
59.02380,-2.60346,-19.47221,2.57743,19.47221,22540,9
60.23480,-1.71799,-8.23343,1.69197,8.23343,22540,9
61.14080,-2.54594,-24.77024,2.51992,24.77024,22476,9
61.69280,-3.09792,-37.26312,3.07190,37.26312,22476,10
62.08180,-3.48710,-46.25427,3.46108,46.25427,22476,10
62.54380,-3.94910,-56.72497,3.92308,56.72497,22476,10
63.16480,-4.51938,-69.15311,4.49336,69.15311,22476,10
63.61580,-4.04039,-53.22009,4.01437,53.22009,22412,10
64.12480,-3.52998,-38.72470,3.50396,38.72470,22412,10
64.83380,-2.82075,-23.16161,2.79473,23.16161,22412,10
65.86980,-1.78471,-8.08729,1.75869,8.08729,22412,10
66.53280,-2.33923,-19.98759,2.31321,19.98759,22476,10
67.05980,-2.86679,-31.37328,2.84077,31.37328,22476,11
67.48180,-3.28873,-41.23181,3.26271,41.23181,22476,11
67.93880,-3.74573,-51.74591,3.71971,51.74591,22476,11
68.65980,-4.46682,-68.15697,4.44080,68.15697,22476,11
69.13080,-4.12823,-55.89661,4.10221,55.89661,22412,11
69.57980,-3.67687,-42.41149,3.65085,42.41149,22412,11
70.07080,-3.18565,-30.22599,3.15963,30.22599,22412,11
70.67880,-2.57773,-18.95247,2.55171,18.95247,22412,11
71.70720,-1.93198,-12.19980,1.90596,12.19980,22412,11
72.46580,-2.70061,-27.27273,2.67459,27.27273,22476,12
72.91280,-3.14781,-37.83055,3.12179,37.83055,22476,12
73.20980,-3.44490,-44.71488,3.41888,44.71487,22476,12
73.57680,-3.81178,-53.06897,3.78576,53.06897,22476,12
74.13080,-4.36576,-65.81642,4.33974,65.81642,22476,12
74.47780,-4.38663,-63.84272,4.36061,63.84272,22476,12
74.84480,-4.00879,-51.93354,3.98277,51.93354,22412,12
75.19680,-3.65576,-41.55787,3.62974,41.55787,22412,12
75.64580,-3.20648,-30.57560,3.18046,30.57560,22412,12
76.20720,-2.64561,-19.80500,2.61959,19.80500,22412,12
77.00980,-1.84243,-8.67232,1.81641,8.67232,22412,12
77.75380,-2.39008,-20.71332,2.36406,20.71332,22476,13
78.20880,-2.84555,-30.52771,2.81953,30.52771,22476,13
78.53080,-3.16760,-38.20511,3.14158,38.20510,22476,13
78.89580,-3.53270,-46.73162,3.50668,46.73162,22476,13
79.21780,-3.85459,-53.97912,3.82857,53.97913,22476,13
79.66180,-4.29857,-64.15285,4.27255,64.15285,22476,13
79.99280,-4.46571,-66.60823,4.43969,66.60823,22476,13
80.35580,-4.08424,-54.11113,4.05822,54.11113,22412,13
80.60080,-3.83764,-46.82557,3.81162,46.82557,22412,13
80.80720,-3.63156,-40.79473,3.60554,40.79473,22412,13
81.00720,-3.43154,-35.72934,3.40552,35.72934,22412,13
81.23180,-3.20631,-30.44890,3.18029,30.44890,22412,13
81.60720,-2.83134,-22.92933,2.80532,22.92933,22412,13
82.06380,-2.37440,-15.74044,2.34838,15.74044,22412,13
82.59780,-1.84025,-8.53595,1.81423,8.53595,22412,13
83.11780,-2.20244,-16.98723,2.17642,16.98723,22476,13
83.73180,-2.81846,-29.77916,2.79244,29.77916,22476,14
84.02280,-3.10946,-36.64637,3.08344,36.64637,22476,14
84.40720,-3.49361,-45.56933,3.46759,45.56933,22476,14
84.68180,-3.76842,-51.95142,3.74240,51.95142,22476,14
85.05080,-4.13743,-60.34927,4.11141,60.34927,22476,14
85.47080,-4.55204,-69.79391,4.52602,69.79391,22476,14
85.92980,-4.08393,-53.89294,4.05791,53.89294,22412,14
86.34280,-3.66938,-41.67347,3.64336,41.67347,22412,14
86.91880,-3.09329,-27.73414,3.06727,27.73414,22412,14
88.10720,-1.90535,-9.31052,1.87933,9.31052,22412,14
89.03280,-2.53307,-23.46509,2.50705,23.46509,22476,15
89.74780,-3.24810,-39.76730,3.22208,39.76730,22476,15
90.39580,-3.89632,-54.70666,3.87030,54.70666,22476,15
90.81080,-4.31120,-64.26755,4.28518,64.26755,22476,15
91.19080,-4.43179,-65.06047,4.40577,65.06046,22476,15
91.52680,-4.08263,-53.74726,4.05661,53.74726,22412,15
91.90720,-3.70106,-42.53750,3.67504,42.53750,22412,15
92.25280,-3.35502,-33.71299,3.32900,33.71299,22412,15
92.78280,-2.82492,-22.63200,2.79890,22.63200,22412,15
93.89380,-1.77711,-7.96765,1.75109,7.96765,22412,15
94.83280,-2.74481,-27.81486,2.71879,27.81486,22476,16
95.19380,-3.10595,-36.34664,3.07992,36.34664,22476,16
95.59780,-3.51020,-45.74248,3.48418,45.74248,22476,16
96.09080,-4.00318,-57.14036,3.97716,57.14036,22476,16
96.60080,-4.51302,-68.73704,4.48700,68.73704,22476,16
97.00720,-4.20202,-57.37995,4.17600,57.37995,22412,16
97.50280,-3.70286,-42.48507,3.67684,42.48507,22412,16
97.90480,-3.30073,-32.25238,3.27471,32.25238,22412,16
98.65580,-2.54988,-18.10071,2.52386,18.10071,22412,16
99.60720,-1.93133,-11.60653,1.90531,11.60653,22412,16
100.47580,-2.81184,-29.27010,2.78582,29.27010,22476,17
101.01380,-3.34986,-41.89457,3.32384,41.89457,22476,17
101.66080,-3.99699,-56.90744,3.97097,56.90744,22476,17
102.14480,-4.48083,-67.90473,4.45481,67.90473,22476,17
102.48880,-4.29062,-60.19716,4.26459,60.19716,22476,17
102.91880,-3.85476,-46.90290,3.82874,46.90290,22412,17
103.36380,-3.40963,-34.72910,3.38361,34.72910,22412,17
103.94680,-2.82643,-22.52489,2.80040,22.52489,22412,17
105.03480,-1.76576,-7.38309,1.73974,7.38309,22412,17
105.95280,-2.71042,-26.86436,2.68440,26.86436,22604,18
106.50580,-3.26349,-39.83733,3.23746,39.83733,22604,18
107.13580,-3.89369,-54.37721,3.86767,54.37721,22604,18
107.52180,-4.27951,-63.28600,4.25348,63.28600,22604,18
107.94080,-4.44963,-65.30427,4.42361,65.30428,22604,18
108.22080,-4.15673,-55.77936,4.13071,55.77936,22540,18
108.52580,-3.84957,-46.60135,3.82355,46.60135,22540,18
108.88680,-3.48847,-36.44095,3.46245,36.44095,22540,18
109.26380,-3.11144,-27.75675,3.08542,27.75675,22540,18
110.09780,-2.27740,-14.02081,2.25138,14.02081,22540,18
110.97080,-2.14121,-15.39729,2.11519,15.39729,22604,18
111.73180,-2.90546,-31.28535,2.87944,31.28535,22604,19
112.09280,-3.26628,-39.84345,3.24026,39.84346,22604,19
112.42780,-3.60151,-47.81014,3.57549,47.81015,22604,19
112.75780,-3.93157,-55.21592,3.90555,55.21592,22604,19
113.01680,-4.19023,-61.18220,4.16421,61.18220,22604,19
113.30580,-4.47940,-67.77886,4.45338,67.77885,22604,19
113.53580,-4.41235,-64.08941,4.38633,64.08941,22604,19
113.74880,-4.18923,-56.77181,4.16321,56.77181,22540,19
113.93880,-3.99717,-50.94976,3.97115,50.94976,22540,19
114.20780,-3.72719,-42.97898,3.70116,42.97898,22540,19
114.45280,-3.48223,-36.19571,3.45621,36.19571,22540,19
114.68380,-3.25107,-30.79112,3.22505,30.79112,22540,19
114.95680,-2.97826,-25.09052,2.95224,25.09052,22540,19
115.41580,-2.51925,-17.40661,2.49323,17.40661,22540,19
115.98480,-1.95018,-9.63071,1.92416,9.63071,22540,19
116.34380,-1.78474,-8.08321,1.75872,8.08321,22540,19
116.63980,-1.88535,-10.91447,1.85933,10.91447,22540,19
117.10580,-2.36020,-19.86611,2.33418,19.86611,22476,19
117.46480,-2.71943,-27.34774,2.69341,27.34774,22476,20
117.66380,-2.91865,-31.90493,2.89263,31.90493,22476,20
117.89180,-3.14659,-37.31181,3.12057,37.31181,22476,20
118.10080,-3.35563,-42.14592,3.32961,42.14592,22476,20
118.29180,-3.54668,-46.60542,3.52066,46.60542,22476,20
118.49480,-3.74952,-51.22491,3.72350,51.22491,22476,20
118.66980,-3.92477,-55.20786,3.89875,55.20786,22476,20
118.89980,-4.15450,-60.44972,4.12848,60.44972,22476,20
119.07580,-4.33053,-64.51356,4.30451,64.51356,22476,20
119.26880,-4.52359,-68.88877,4.49757,68.88877,22476,20
119.50580,-4.35151,-62.09672,4.32549,62.09672,22476,20
119.80980,-4.03969,-52.26011,4.01367,52.26011,22412,20
120.09480,-3.75343,-43.76010,3.72741,43.76010,22412,20
120.36580,-3.48240,-36.22978,3.45638,36.22978,22412,20
120.69680,-3.15134,-28.56624,3.12531,28.56624,22412,20
121.39580,-2.45227,-16.47382,2.42625,16.47382,22412,20
122.23780,-1.93450,-11.42672,1.90848,11.42672,22412,20
122.79380,-2.50207,-22.44322,2.47605,22.44322,22476,21
123.20680,-2.91542,-31.47992,2.88940,31.47992,22476,21
123.59380,-3.30223,-40.58583,3.27621,40.58583,22476,21
124.02780,-3.73627,-50.70340,3.71025,50.70340,22476,21
124.41780,-4.12630,-59.63679,4.10028,59.63679,22476,21
124.76680,-4.47535,-67.64232,4.44933,67.64233,22476,21
125.04780,-4.39278,-63.14214,4.36676,63.14214,22476,21
125.35580,-4.07546,-53.04652,4.04944,53.04652,22412,21
125.70720,-3.72306,-42.73580,3.69704,42.73580,22412,21
126.02780,-3.40213,-34.28214,3.37611,34.28214,22412,21
126.61880,-2.81097,-21.98018,2.78495,21.98018,22412,21
127.50720,-1.92313,-9.11790,1.89711,9.11790,22412,21
128.40720,-2.56694,-23.55919,2.54092,23.55919,22476,22
129.19780,-3.35809,-41.80760,3.33206,41.80759,22476,22
129.98280,-4.14306,-59.93482,4.11704,59.93482,22476,22
130.60480,-4.39534,-63.18338,4.36932,63.18338,22476,22
131.03580,-3.95444,-49.32185,3.92842,49.32185,22412,22
131.51180,-3.47789,-35.84658,3.45186,35.84658,22412,22
131.99380,-2.99596,-25.27376,2.96994,25.27376,22412,22
132.96380,-2.02594,-10.51452,1.99992,10.51452,22412,22
133.82280,-2.42034,-20.44717,2.39432,20.44717,22476,23
134.28380,-2.88196,-30.56430,2.85594,30.56429,22476,23
134.60780,-3.20577,-38.22459,3.17975,38.22459,22476,23
135.04280,-3.64098,-48.39395,3.61496,48.39395,22476,23
135.53980,-4.13784,-59.70917,4.11182,59.70917,22476,23
135.96480,-4.56271,-69.51524,4.53669,69.51524,22476,23
136.38180,-4.16800,-55.80420,4.14198,55.80420,22412,23
136.86680,-3.68066,-41.28896,3.65464,41.28896,22412,23
137.30719,-3.24049,-30.23762,3.21447,30.23762,22412,23
138.10719,-2.44051,-16.01307,2.41449,16.01307,22412,23
138.99980,-2.02641,-12.93198,2.00039,12.93198,22412,23
139.71280,-2.74639,-27.32343,2.72037,27.32343,22476,24
140.09380,-3.12763,-36.25225,3.10161,36.25225,22476,24
140.46580,-3.49970,-44.97621,3.47368,44.97621,22476,24
140.87280,-3.90672,-54.37724,3.88070,54.37724,22476,24
141.40720,-4.44063,-66.62359,4.41461,66.62359,22476,24
141.87280,-4.25240,-58.31251,4.22638,58.31251,22412,24
142.31580,-3.80545,-44.83296,3.77943,44.83295,22412,24
142.94980,-3.17132,-28.64859,3.14530,28.64858,22412,24
144.05680,-2.06435,-10.89665,2.03833,10.89665,22412,24
145.03880,-2.51816,-22.36901,2.49214,22.36901,22476,25
145.71680,-3.19632,-37.85269,3.17030,37.85268,22476,25
146.34580,-3.82544,-52.45166,3.79942,52.45166,22476,25
147.05580,-4.53545,-68.76264,4.50943,68.76263,22476,25
147.48780,-4.19787,-56.57060,4.17185,56.57060,22412,25
148.09580,-3.58728,-38.53064,3.56126,38.53064,22412,25
148.67780,-3.00536,-25.19047,2.97934,25.19047,22412,25
149.67980,-2.00332,-10.09674,1.97730,10.09674,22412,25
150.41178,-2.31822,-18.42638,2.29220,18.42638,22476,25
151.11680,-3.02435,-33.77281,2.99833,33.77281,22476,26
151.69080,-3.59836,-47.34986,3.57234,47.34986,22476,26
152.22080,-4.12823,-59.34469,4.10221,59.34469,22476,26
152.80580,-4.45385,-64.95180,4.42783,64.95180,22476,26
153.36380,-3.88139,-47.09921,3.85537,47.09921,22412,26
153.90380,-3.34098,-32.26453,3.31496,32.26453,22412,26
154.77180,-2.47299,-16.39436,2.44697,16.39436,22412,26
155.78480,-2.13841,-14.89888,2.11239,14.89888,22476,26
156.52580,-2.88328,-30.34998,2.85726,30.34998,22476,27
157.03180,-3.38940,-42.32397,3.36338,42.32397,22476,27
157.43580,-3.79327,-51.74209,3.76725,51.74209,22476,27
157.77580,-4.13317,-59.48137,4.10715,59.48137,22476,27
158.13680,-4.49428,-67.77700,4.46826,67.77700,22476,27
158.46680,-4.33505,-60.90208,4.30903,60.90208,22476,27
158.81780,-3.97775,-49.80057,3.95173,49.80057,22412,27
159.12680,-3.66812,-40.77199,3.64210,40.77199,22412,27
159.47680,-3.31792,-31.60181,3.29190,31.60181,22412,27
159.84780,-2.94707,-23.97024,2.92105,23.97025,22412,27
160.28180,-2.51313,-16.92268,2.48711,16.92267,22412,27
161.08580,-1.92224,-10.38056,1.89622,10.38056,22412,27
161.78780,-2.64096,-24.77466,2.61494,24.77466,22604,28
162.28180,-3.13518,-36.29262,3.10916,36.29262,22604,28
162.62380,-3.47721,-44.28784,3.45119,44.28784,22604,28
162.92880,-3.78213,-51.37862,3.75611,51.37862,22604,28
163.27080,-4.12408,-59.23984,4.09806,59.23984,22604,28
163.50680,-4.36008,-64.66545,4.33406,64.66545,22604,28
163.73780,-4.57870,-69.64161,4.55268,69.64161,22604,28
163.98880,-4.31408,-60.15889,4.28806,60.15889,22604,28
164.24780,-4.05011,-51.93583,4.02409,51.93583,22540,28
164.51980,-3.77702,-43.86071,3.75100,43.86071,22540,28
164.74578,-3.55098,-37.45085,3.52496,37.45086,22540,28
164.93180,-3.36488,-32.72106,3.33886,32.72106,22540,28
165.09480,-3.20173,-28.97281,3.17571,28.97281,22540,28
165.39580,-2.90096,-23.12540,2.87493,23.12540,22540,28
165.80719,-2.48987,-16.54777,2.46385,16.54778,22540,28
166.28180,-2.01504,-10.16268,1.98902,10.16268,22540,28
166.62078,-1.93543,-10.75637,1.90941,10.75637,22540,28
167.09480,-2.42341,-20.21601,2.39739,20.21601,22604,29
167.44580,-2.77490,-27.66615,2.74888,27.66615,22604,29
167.65480,-2.98404,-32.70672,2.95802,32.70672,22604,29
167.91380,-3.24279,-38.83911,3.21677,38.83911,22604,29
168.25580,-3.58514,-46.88516,3.55912,46.88516,22604,29
168.79580,-4.12496,-59.17530,4.09894,59.17530,22604,29
169.26380,-4.58877,-69.85351,4.56275,69.85351,22604,29
169.62680,-4.22076,-57.03363,4.19474,57.03363,22540,29
169.92780,-3.91724,-47.93440,3.89122,47.93440,22540,29
170.32680,-3.51787,-36.48833,3.49185,36.48833,22540,29
170.75780,-3.08676,-26.50694,3.06074,26.50694,22540,29
171.90380,-1.94096,-9.00543,1.91494,9.00543,22540,29
172.74980,-2.15219,-15.50335,2.12617,15.50335,22476,29
173.48380,-2.88812,-30.73341,2.86210,30.73341,22476,30
173.93380,-3.33811,-41.26237,3.31209,41.26237,22476,30
174.50720,-3.91124,-54.35634,3.88522,54.35634,22476,30
175.20720,-4.58705,-69.69582,4.56102,69.69582,22476,30
175.65280,-4.11649,-53.84909,4.09047,53.84909,22412,30
176.09180,-3.67595,-40.88765,3.64993,40.88765,22412,30
176.60180,-3.16585,-28.09590,3.13983,28.09590,22412,30
177.53678,-2.23083,-12.86852,2.20481,12.86852,22412,30
178.48780,-2.34292,-18.74406,2.31690,18.74406,22476,30
179.10980,-2.96598,-32.25291,2.93996,32.25291,22476,31
179.64480,-3.50107,-44.75825,3.47505,44.75824,22476,31
179.97380,-3.83001,-52.35962,3.80398,52.35962,22476,31
180.35980,-4.21566,-61.27399,4.18964,61.27399,22476,31
180.69680,-4.55296,-69.02900,4.52694,69.02900,22476,31
180.93978,-4.36227,-61.75052,4.33624,61.75051,22476,31
181.16378,-4.13167,-54.32565,4.10565,54.32565,22412,31
181.39878,-3.89518,-47.39847,3.86915,47.39848,22412,31
181.64380,-3.64985,-40.13637,3.62383,40.13637,22412,31
181.85980,-3.43380,-34.31793,3.40778,34.31792,22412,31
182.03180,-3.26166,-30.18800,3.23564,30.18800,22412,31
182.39180,-2.90180,-22.99801,2.87578,22.99801,22412,31
182.80178,-2.49177,-16.47383,2.46575,16.47383,22412,31
183.20180,-2.09168,-10.99445,2.06566,10.99445,22412,31
183.76980,-2.11671,-14.26335,2.09069,14.26335,22476,31
184.16880,-2.52051,-22.24905,2.49449,22.24905,22476,32
184.44080,-2.79267,-28.05547,2.76665,28.05547,22476,32
184.60580,-2.95792,-31.94549,2.93190,31.94549,22476,32
184.80178,-3.15378,-36.65383,3.12775,36.65383,22476,32
184.95580,-3.30785,-40.26428,3.28183,40.26428,22476,32
185.09380,-3.44592,-43.50466,3.41990,43.50466,22476,32
185.27880,-3.63091,-47.85892,3.60489,47.85892,22476,32
185.47480,-3.82683,-52.30507,3.80080,52.30507,22476,32
185.70478,-4.05698,-57.54850,4.03096,57.54850,22476,32
185.88578,-4.23758,-61.80403,4.21156,61.80404,22476,32
186.15280,-4.50483,-67.86148,4.47881,67.86148,22476,32
186.34080,-4.49683,-66.10566,4.47081,66.10566,22476,32
186.57580,-4.24731,-57.77379,4.22129,57.77380,22412,32
186.86680,-3.95314,-48.87440,3.92712,48.87440,22412,32
187.12480,-3.69462,-41.32043,3.66860,41.32043,22412,32
187.40580,-3.41365,-33.76033,3.38763,33.76033,22412,32
187.66780,-3.15159,-27.59761,3.12557,27.59761,22412,32
188.12180,-2.69743,-19.47195,2.67141,19.47195,22412,32
188.62580,-2.19353,-12.36102,2.16751,12.36102,22412,32
188.94280,-1.87673,-8.05674,1.85070,8.05674,22412,32
189.30780,-2.15536,-14.92694,2.12934,14.92694,22476,32
189.70180,-2.55341,-22.75411,2.52739,22.75411,22476,33
189.92080,-2.77247,-27.46625,2.74645,27.46625,22476,33
190.13780,-2.98967,-32.59868,2.96365,32.59868,22476,33
190.34180,-3.19348,-37.50113,3.16746,37.50113,22476,33
190.52980,-3.38171,-41.97409,3.35569,41.97409,22476,33
190.71380,-3.56582,-46.26546,3.53980,46.26546,22476,33
190.97480,-3.82663,-52.16230,3.80061,52.16230,22476,33
191.28280,-4.13459,-59.30584,4.10857,59.30584,22476,33
191.56280,-4.41473,-65.74172,4.38871,65.74171,22476,33
191.81080,-4.54068,-67.58149,4.51466,67.58149,22476,33
192.16480,-4.16459,-55.12080,4.13857,55.12080,22412,33
192.53780,-3.78959,-43.97614,3.76357,43.97614,22412,33
192.90880,-3.41852,-33.68800,3.39250,33.68800,22412,33
193.46680,-2.86046,-22.18001,2.83444,22.18001,22412,33
194.44880,-1.87864,-8.02716,1.85262,8.02716,22412,33
194.93380,-2.25737,-16.87307,2.23135,16.87308,22476,33
195.34580,-2.67129,-25.33325,2.64527,25.33325,22476,34
195.63180,-2.95751,-31.78849,2.93149,31.78849,22476,34
195.92380,-3.24929,-38.85567,3.22327,38.85567,22476,34
196.22080,-3.54652,-45.69142,3.52050,45.69141,22476,34
196.52480,-3.85048,-52.73441,3.82446,52.73441,22476,34
196.79180,-4.11738,-58.87922,4.09136,58.87922,22476,34
197.13980,-4.46542,-66.88041,4.43940,66.88041,22476,34
197.45980,-4.40959,-63.03664,4.38356,63.03664,22476,34
197.81678,-4.04330,-51.41975,4.01728,51.41975,22412,34
198.23780,-3.62128,-39.17455,3.59526,39.17455,22412,34
198.55580,-3.30312,-30.85424,3.27710,30.85424,22412,34
199.10719,-2.75215,-20.20869,2.72613,20.20869,22412,34
199.97380,-1.88548,-8.06247,1.85946,8.06247,22412,34
200.84478,-2.62999,-24.35765,2.60397,24.35765,22476,35
201.47980,-3.26517,-39.18026,3.23915,39.18026,22476,35
201.90580,-3.69120,-49.08819,3.66518,49.08820,22476,35
202.35380,-4.13909,-59.38640,4.11307,59.38640,22476,35
202.66980,-4.45521,-66.62640,4.42919,66.62640,22476,35
202.96680,-4.44479,-64.15923,4.41877,64.15923,22476,35
203.39080,-4.00884,-50.42049,3.98282,50.42049,22412,35
203.86280,-3.53604,-36.68788,3.51002,36.68788,22412,35
204.40720,-2.99209,-24.38536,2.96607,24.38536,22412,35
205.50878,-1.89021,-8.11562,1.86419,8.11562,22412,35
206.40720,-2.65781,-24.95233,2.63179,24.95233,22476,36
207.00720,-3.25799,-39.08080,3.23197,39.08080,22476,36
207.69080,-3.94214,-54.80919,3.91612,54.80919,22476,36
208.24778,-4.49895,-67.53709,4.47293,67.53709,22476,36
208.56678,-4.37832,-61.92352,4.35230,61.92352,22476,36
209.01880,-3.91832,-47.70936,3.89230,47.70936,22412,36
209.50720,-3.42994,-33.80444,3.40392,33.80444,22412,36
210.05480,-2.88192,-22.42984,2.85590,22.42983,22412,36
211.09780,-1.83993,-7.40299,1.81391,7.40299,22412,36
211.98580,-2.72274,-26.29368,2.69672,26.29368,22476,37
212.57978,-3.31694,-40.36026,3.29092,40.36026,22476,37
213.11680,-3.85403,-52.74268,3.82801,52.74268,22476,37
213.60719,-4.34389,-64.03391,4.31787,64.03391,22476,37
213.99380,-4.47164,-65.01984,4.44562,65.01984,22476,37
214.22780,-4.22577,-56.90029,4.19975,56.90029,22412,37
214.51480,-3.93624,-48.15768,3.91022,48.15768,22412,37
214.78580,-3.66485,-40.25570,3.63883,40.25570,22412,37
215.11480,-3.33568,-31.37595,3.30966,31.37595,22412,37
215.44080,-3.00994,-24.59754,2.98392,24.59754,22412,37
216.12380,-2.32673,-13.85406,2.30071,13.85406,22412,37
216.92080,-2.16338,-14.85140,2.13736,14.85140,22604,37
217.52980,-2.77672,-27.45860,2.75070,27.45860,22604,38
217.79080,-3.03785,-33.85967,3.01183,33.85966,22604,38
218.17280,-3.41997,-42.98761,3.39395,42.98761,22604,38
218.50719,-3.75386,-50.63923,3.72784,50.63923,22604,38
218.80719,-4.05403,-57.45645,4.02801,57.45645,22604,38
219.07978,-4.32684,-63.76830,4.30082,63.76831,22604,38
219.38080,-4.57932,-69.08192,4.55330,69.08192,22604,38
219.69780,-4.23595,-57.32283,4.20993,57.32283,22540,38
219.92380,-4.00751,-50.35851,3.98149,50.35851,22540,38
220.19178,-3.73866,-42.47036,3.71264,42.47036,22540,38
220.40580,-3.52475,-36.41231,3.49873,36.41232,22540,38
220.64380,-3.28654,-30.09689,3.26052,30.09689,22540,38
220.88280,-3.04774,-25.15782,3.02172,25.15782,22540,38
221.20720,-2.72345,-19.51502,2.69743,19.51502,22540,38
221.90720,-2.02387,-9.80450,1.99785,9.80450,22540,38
222.37780,-2.13132,-14.23421,2.10530,14.23421,22604,38
222.92380,-2.68246,-25.37434,2.65644,25.37434,22604,39
223.25580,-3.01471,-33.14916,2.98869,33.14916,22604,39
223.70180,-3.46073,-43.77414,3.43471,43.77414,22604,39
224.15780,-3.91679,-54.26671,3.89077,54.26671,22604,39
224.70720,-4.46570,-66.82356,4.43968,66.82356,22604,39
225.11580,-4.33438,-60.29685,4.30836,60.29685,22540,39
225.51078,-3.93388,-48.07481,3.90786,48.07481,22540,39
225.84680,-3.59749,-38.36147,3.57147,38.36147,22540,39
226.12580,-3.31831,-30.79090,3.29229,30.79090,22540,39
226.52780,-2.91648,-22.90655,2.89046,22.90656,22540,39
227.04580,-2.39843,-14.88500,2.37241,14.88500,22540,39
227.56678,-1.87761,-7.77198,1.85159,7.77198,22540,39
227.85978,-1.83859,-8.10554,1.81257,8.10554,22540,39
228.10778,-1.93176,-10.65872,1.90574,10.65872,22540,39
228.41080,-2.24275,-16.93245,2.21673,16.93245,22476,39
228.70678,-2.53994,-22.73739,2.51392,22.73739,22476,39
228.96080,-2.79404,-28.08801,2.76802,28.08801,22476,40
229.15780,-2.99114,-32.75061,2.96512,32.75061,22476,40
229.34680,-3.17997,-37.24059,3.15395,37.24059,22476,40
229.46978,-3.30305,-40.14565,3.27703,40.14565,22476,40
229.60380,-3.43717,-43.38900,3.41115,43.38900,22476,40
229.75980,-3.59319,-47.04315,3.56717,47.04315,22476,40
229.92678,-3.76005,-50.86445,3.73403,50.86445,22476,40
230.13280,-3.96619,-55.54315,3.94017,55.54316,22476,40
230.31878,-4.15196,-59.70248,4.12594,59.70248,22476,40
230.46778,-4.30099,-63.17634,4.27497,63.17634,22476,40
230.69880,-4.53202,-68.45292,4.50600,68.45293,22476,40
230.87380,-4.46654,-65.12064,4.44052,65.12064,22476,40
231.04780,-4.28173,-58.84657,4.25571,58.84657,22412,40
231.21880,-4.10738,-53.38010,4.08136,53.38010,22412,40
231.36680,-3.95843,-48.91894,3.93241,48.91894,22412,40
231.54280,-3.78191,-43.82638,3.75589,43.82638,22412,40
231.71180,-3.61287,-38.98893,3.58685,38.98893,22412,40
231.92480,-3.39987,-33.09220,3.37385,33.09221,22412,40
232.24680,-3.07783,-25.78318,3.05181,25.78318,22412,40
232.64580,-2.67871,-18.91124,2.65269,18.91124,22412,40
233.05480,-2.26983,-13.15986,2.24381,13.15986,22412,40
233.43680,-1.88807,-8.03545,1.86205,8.03545,22412,40
233.79180,-2.16243,-14.80071,2.13641,14.80071,22476,40
234.17580,-2.55071,-22.45112,2.52469,22.45112,22476,41
234.38778,-2.76278,-27.11925,2.73676,27.11925,22476,41
234.53480,-2.91001,-30.65266,2.88399,30.65266,22476,41
234.70720,-3.08190,-34.80920,3.05588,34.80920,22476,41
234.89480,-3.26995,-39.34055,3.24393,39.34055,22476,41
235.03980,-3.41512,-42.76146,3.38910,42.76146,22476,41
235.19178,-3.56713,-46.29694,3.54111,46.29694,22476,41
235.34080,-3.71593,-49.65809,3.68991,49.65809,22476,41
235.49980,-3.87501,-53.23336,3.84899,53.23336,22476,41
235.61480,-3.99016,-55.97129,3.96414,55.97129,22476,41
235.72980,-4.10495,-58.50693,4.07893,58.50693,22476,41
235.83880,-4.21377,-61.03104,4.18775,61.03104,22476,41
235.95780,-4.33298,-63.67707,4.30696,63.67707,22476,41
236.07280,-4.44800,-66.38162,4.42198,66.38161,22476,41
236.20780,-4.58227,-69.52910,4.55625,69.52910,22476,41
236.32978,-4.48557,-65.46499,4.45955,65.46499,22476,41
236.44080,-4.36584,-61.44663,4.33982,61.44662,22476,41
236.54880,-4.25357,-57.74006,4.22755,57.74006,22412,41
236.70980,-4.09007,-52.63960,4.06405,52.63960,22412,41
236.89878,-3.90013,-47.13696,3.87411,47.13696,22412,41
237.04180,-3.75680,-42.87905,3.73078,42.87904,22412,41
237.20180,-3.59676,-38.38457,3.57074,38.38457,22412,41
237.37880,-3.41982,-33.39990,3.39380,33.39990,22412,41
237.53180,-3.26666,-29.71432,3.24064,29.71432,22412,41
237.70720,-3.09173,-26.12806,3.06571,26.12806,22412,41
237.87380,-2.92479,-23.00816,2.89877,23.00816,22412,41
238.05280,-2.74561,-19.97585,2.71959,19.97585,22412,41
238.29280,-2.50578,-16.48386,2.47976,16.48386,22412,41
238.57978,-2.21864,-12.48475,2.19262,12.48475,22412,41
238.86180,-1.93693,-8.60239,1.91091,8.60239,22412,41
239.09080,-1.96922,-10.81776,1.94319,10.81776,22412,41
239.34980,-2.24011,-16.23039,2.21408,16.23039,22476,41
239.51780,-2.40998,-19.52109,2.38396,19.52109,22476,41
239.69178,-2.58458,-23.11134,2.55856,23.11134,22476,42
239.83178,-2.72459,-26.19731,2.69857,26.19731,22476,42
239.94080,-2.83379,-28.63526,2.80777,28.63526,22476,42
240.06280,-2.95591,-31.49395,2.92989,31.49395,22476,42
240.17080,-3.06386,-34.21956,3.03784,34.21956,22476,42
240.27180,-3.16489,-36.58811,3.13887,36.58811,22476,42
240.38680,-3.27980,-39.41362,3.25378,39.41362,22476,42
240.49280,-3.38605,-41.86209,3.36003,41.86209,22476,42
240.63680,-3.52995,-45.24285,3.50393,45.24285,22476,42
240.78280,-3.67591,-48.74493,3.64989,48.74493,22476,42
240.91578,-3.80888,-51.76322,3.78286,51.76322,22476,42
241.03678,-3.93000,-54.50183,3.90398,54.50183,22476,42
241.18280,-4.07597,-57.86376,4.04995,57.86377,22476,42
241.29980,-4.19265,-60.45314,4.16663,60.45314,22476,42
241.43180,-4.32480,-63.51698,4.29878,63.51698,22476,42
241.55880,-4.45184,-66.36775,4.42582,66.36774,22476,42
241.67580,-4.56874,-69.15835,4.54272,69.15835,22476,42
241.78280,-4.52520,-66.84402,4.49918,66.84402,22476,42
241.93380,-4.36031,-61.17274,4.33429,61.17274,22476,42
242.08280,-4.20629,-56.20398,4.18027,56.20398,22412,42
242.34080,-3.94614,-48.34734,3.92011,48.34734,22412,42
242.56780,-3.71861,-41.66842,3.69259,41.66842,22412,42
242.84180,-3.44468,-34.01103,3.41866,34.01103,22412,42
243.17678,-3.10964,-26.30990,3.08362,26.30990,22412,42
243.57380,-2.71246,-19.40162,2.68644,19.40162,22412,42
244.16780,-2.11856,-11.06026,2.09253,11.06026,22412,42
244.49380,-1.92163,-9.34144,1.89561,9.34144,22412,42
244.78580,-2.23365,-15.97593,2.20763,15.97593,22476,42
244.97280,-2.42299,-19.61752,2.39697,19.61752,22476,42
245.09580,-2.54663,-22.26461,2.52060,22.26461,22476,43
245.24778,-2.69865,-25.45852,2.67263,25.45852,22476,43
245.36680,-2.81790,-28.14128,2.79188,28.14128,22476,43
245.46480,-2.91604,-30.47603,2.89002,30.47603,22476,43
245.56878,-3.02003,-33.14253,2.99401,33.14252,22476,43
245.66578,-3.11683,-35.37342,3.09081,35.37342,22476,43
245.77480,-3.22577,-37.97514,3.19975,37.97514,22476,43
245.88680,-3.33786,-40.66455,3.31184,40.66455,22476,43
245.99480,-3.44604,-43.27863,3.42002,43.27863,22476,43
246.08480,-3.53607,-45.37688,3.51005,45.37688,22476,43
246.19280,-3.64400,-48.10569,3.61798,48.10569,22476,43
246.28180,-3.73287,-49.96543,3.70685,49.96544,22476,43
246.38180,-3.83295,-52.28573,3.80693,52.28574,22476,43
246.47480,-3.92611,-54.41567,3.90009,54.41567,22476,43
246.57580,-4.02708,-56.77189,4.00106,56.77189,22476,43
246.67780,-4.12879,-58.98710,4.10277,58.98710,22476,43
246.77378,-4.22473,-61.24331,4.19871,61.24331,22476,43
246.85580,-4.30683,-63.15205,4.28081,63.15205,22476,43
246.96380,-4.41502,-65.54036,4.38899,65.54036,22476,43
247.08280,-4.53391,-68.24981,4.50789,68.24981,22476,43
247.19480,-4.56174,-68.17333,4.53572,68.17332,22476,43
247.29580,-4.44590,-64.00034,4.41988,64.00034,22476,43
247.41680,-4.31757,-59.73154,4.29155,59.73154,22412,43
247.52280,-4.20853,-56.27263,4.18251,56.27263,22412,43
247.64180,-4.08812,-52.52763,4.06210,52.52763,22412,43
247.78780,-3.94134,-48.17779,3.91532,48.17779,22412,43
247.99280,-3.73585,-42.11207,3.70983,42.11207,22412,43
248.20980,-3.51895,-35.94445,3.49293,35.94445,22412,43
248.36580,-3.36284,-31.71546,3.33682,31.71546,22412,43
248.51580,-3.21266,-28.30853,3.18664,28.30853,22412,43
248.70720,-3.02200,-24.59249,2.99598,24.59249,22412,43
248.88378,-2.84475,-21.51613,2.81872,21.51613,22412,43
249.21580,-2.51289,-16.44415,2.48687,16.44415,22412,43
249.67580,-2.05300,-10.19819,2.02698,10.19819,22412,43
250.20478,-2.17368,-14.89388,2.14766,14.89388,22476,43
250.64780,-2.62070,-23.79286,2.59468,23.79286,22476,44
251.01380,-2.98705,-32.20073,2.96103,32.20073,22476,44
251.26880,-3.24177,-38.41319,3.21575,38.41319,22476,44
251.50719,-3.48003,-44.02301,3.45401,44.02301,22476,44
251.75180,-3.72488,-49.62607,3.69886,49.62607,22476,44
252.05980,-4.03310,-56.77657,4.00708,56.77657,22476,44
252.29880,-4.27183,-62.29870,4.24581,62.29870,22476,44
252.53878,-4.51195,-67.71480,4.48593,67.71480,22476,44
252.72280,-4.51716,-66.30324,4.49114,66.30324,22476,44
252.91080,-4.31518,-59.57263,4.28916,59.57262,22476,44
253.17780,-4.04384,-51.12148,4.01782,51.12148,22412,44
253.41980,-3.80085,-43.90151,3.77483,43.90151,22412,44
253.72780,-3.49285,-35.25525,3.46683,35.25525,22412,44
253.98980,-3.23062,-28.71919,3.20460,28.71919,22412,44
254.76980,-2.45072,-15.46358,2.42470,15.46358,22412,44
255.49280,-1.95359,-10.33882,1.92757,10.33882,22412,44
256.21180,-2.68869,-25.25088,2.66267,25.25088,22476,45
256.57780,-3.05504,-33.92336,3.02902,33.92336,22476,45
256.95480,-3.43205,-42.89056,3.40603,42.89056,22476,45
257.28980,-3.76686,-50.70830,3.74084,50.70830,22476,45
257.57581,-4.05306,-57.17517,4.02704,57.17517,22476,45
257.84478,-4.32182,-63.34328,4.29580,63.34328,22476,45
258.18478,-4.56883,-68.15372,4.54281,68.15372,22476,45
258.50681,-4.22251,-56.55050,4.19649,56.55050,22412,45
258.82880,-3.89811,-46.79963,3.87209,46.79963,22412,45
259.13080,-3.59580,-38.10142,3.56978,38.10143,22412,45
259.42481,-3.30165,-30.25432,3.27563,30.25432,22412,45
260.03580,-2.69062,-19.01585,2.66460,19.01585,22412,45
260.56980,-2.15672,-11.52581,2.13070,11.52581,22412,45
261.02478,-1.99880,-11.27973,1.97278,11.27973,22412,45
261.39780,-2.38387,-18.94301,2.35785,18.94301,22476,45
261.73981,-2.72666,-26.04829,2.70064,26.04829,22476,46
261.89578,-2.88296,-29.70539,2.85694,29.70539,22476,46
262.03878,-3.02597,-33.27160,2.99995,33.27160,22476,46
262.17178,-3.15900,-36.38725,3.13298,36.38725,22476,46
262.32778,-3.31493,-40.03798,3.28891,40.03798,22476,46
262.46381,-3.45108,-43.30593,3.42506,43.30593,22476,46
262.63278,-3.62005,-47.34250,3.59403,47.34250,22476,46
262.80578,-3.79297,-51.30297,3.76694,51.30297,22476,46
262.98378,-3.97111,-55.43791,3.94509,55.43791,22476,46
263.15381,-4.14081,-59.22435,4.11479,59.22435,22476,46
263.25581,-4.24281,-61.57096,4.21679,61.57096,22476,46
263.40178,-4.38902,-64.90330,4.36300,64.90330,22476,46
263.55978,-4.54689,-68.50946,4.52087,68.50946,22476,46
263.69278,-4.53149,-66.87775,4.50547,66.87775,22476,46
263.79581,-4.41742,-62.95815,4.39140,62.95815,22476,46
263.90878,-4.29867,-59.05157,4.27265,59.05157,22412,46
264.05578,-4.14858,-54.23236,4.12256,54.23236,22412,46
264.20481,-3.99852,-49.70898,3.97250,49.70898,22412,46
264.31878,-3.88402,-46.36059,3.85800,46.36059,22412,46
264.44681,-3.75579,-42.65423,3.72977,42.65423,22412,46
264.58078,-3.62179,-38.86600,3.59577,38.86600,22412,46
264.69378,-3.50884,-35.64813,3.48282,35.64813,22412,46
264.81778,-3.38480,-32.26562,3.35878,32.26562,22412,46
264.92778,-3.27466,-29.52037,3.24864,29.52037,22412,46
265.07481,-3.12776,-26.47742,3.10173,26.47742,22412,46
265.25978,-2.94275,-23.09931,2.91673,23.09931,22412,46
265.50581,-2.69654,-19.02267,2.67052,19.02267,22412,46
265.73778,-2.46468,-15.69175,2.43866,15.69175,22412,46
266.11678,-2.08570,-10.54288,2.05968,10.54288,22412,46
266.40378,-1.89431,-8.60604,1.86829,8.60604,22412,46
266.76778,-2.28282,-16.87073,2.25680,16.87073,22476,46
267.11178,-2.62873,-23.83336,2.60271,23.83336,22476,47
267.31578,-2.83286,-28.41356,2.80684,28.41356,22476,47
267.49078,-3.00801,-32.67944,2.98199,32.67944,22476,47
267.64578,-3.16302,-36.38730,3.13700,36.38730,22476,47
267.80278,-3.31996,-40.10754,3.29394,40.10754,22476,47
267.93878,-3.45610,-43.44923,3.43008,43.44923,22476,47
268.13081,-3.64806,-47.94529,3.62204,47.94529,22476,47
268.35778,-3.87504,-53.13956,3.84902,53.13956,22476,47
268.59578,-4.11289,-58.56540,4.08687,58.56540,22476,47
268.87378,-4.39109,-64.94697,4.36507,64.94697,22476,47
269.13878,-4.58045,-68.52384,4.55443,68.52384,22476,47
269.43281,-4.26146,-57.67124,4.23544,57.67124,22412,47
269.70481,-3.98647,-49.21833,3.96045,49.21833,22412,47
269.93781,-3.75285,-42.42710,3.72683,42.42710,22412,47
270.15681,-3.53393,-36.23223,3.50791,36.23223,22412,47
270.55781,-3.13283,-26.52102,3.10681,26.52102,22412,47
271.50281,-2.18770,-11.92298,2.16168,11.92298,22412,47
272.23881,-2.26146,-16.43679,2.23544,16.43679,22604,47
272.85878,-2.88402,-29.69477,2.85800,29.69477,22604,48
273.15978,-3.18501,-36.91138,3.15899,36.91138,22604,48
273.41081,-3.43616,-42.87948,3.41014,42.87948,22604,48
273.63981,-3.66507,-48.25144,3.63905,48.25144,22604,48
273.89978,-3.92514,-54.19137,3.89912,54.19136,22604,48
274.15078,-4.17579,-59.89211,4.14977,59.89211,22604,48
274.49078,-4.51598,-67.71767,4.48996,67.71767,22604,48
274.80719,-4.38196,-61.53204,4.35594,61.53204,22604,48
275.20719,-3.97441,-48.86309,3.94839,48.86309,22540,48
275.55278,-3.62789,-38.89002,3.60187,38.89001,22540,48
275.83881,-3.34173,-30.96427,3.31571,30.96427,22540,48
276.19581,-2.98491,-23.71483,2.95889,23.71483,22540,48
276.78378,-2.39686,-14.61460,2.37084,14.61460,22540,48
277.39381,-1.89119,-8.59852,1.86517,8.59852,22540,48
277.91278,-2.43516,-19.80521,2.40914,19.80521,22604,48
278.21078,-2.73372,-26.16918,2.70770,26.16918,22604,49
278.36781,-2.89098,-29.89508,2.86496,29.89508,22604,49
278.53681,-3.06003,-33.98357,3.03400,33.98357,22604,49
278.73578,-3.25884,-38.64032,3.23282,38.64032,22604,49
278.99878,-3.52207,-44.89111,3.49604,44.89111,22604,49
279.20719,-3.72991,-49.72808,3.70389,49.72808,22604,49
279.48578,-4.00917,-56.18545,3.98315,56.18545,22604,49
279.75878,-4.28185,-62.34116,4.25583,62.34116,22604,49
280.13778,-4.57882,-68.41094,4.55280,68.41094,22604,49
280.39778,-4.29524,-58.64573,4.26922,58.64573,22540,49
280.68478,-4.00454,-49.74676,3.97851,49.74675,22540,49
280.94181,-3.74677,-42.16353,3.72075,42.16353,22540,49
281.33178,-3.35670,-31.32319,3.33068,31.32319,22540,49
281.79881,-2.88979,-22.11232,2.86377,22.11232,22540,49
282.55978,-2.12873,-11.02905,2.10271,11.02905,22540,49
283.10378,-1.85225,-8.16692,1.82622,8.16692,22540,49
283.63678,-2.28801,-17.34837,2.26199,17.34837,22476,49
284.06078,-2.71279,-26.00267,2.68677,26.00267,22476,49
284.26778,-2.91998,-30.81165,2.89396,30.81165,22476,50
284.49978,-3.15196,-36.37011,3.12594,36.37011,22476,50
284.77178,-3.42407,-42.80310,3.39805,42.80310,22476,50
285.04881,-3.70103,-49.31608,3.67501,49.31608,22476,50
285.32081,-3.97314,-55.58357,3.94712,55.58356,22476,50
285.54778,-4.19976,-60.62224,4.17374,60.62224,22476,50
285.73081,-4.38300,-64.80011,4.35698,64.80010,22476,50
285.97278,-4.58950,-69.21246,4.56347,69.21246,22476,50
286.18178,-4.35926,-61.03373,4.33324,61.03373,22476,50
286.40719,-4.12846,-53.66237,4.10244,53.66238,22412,50
286.66478,-3.86903,-45.91671,3.84301,45.91671,22412,50
286.87578,-3.65788,-39.79988,3.63186,39.79988,22412,50
287.15978,-3.37383,-31.83711,3.34781,31.83711,22412,50
287.55578,-2.97786,-23.62124,2.95184,23.62124,22412,50
288.08178,-2.45175,-15.42409,2.42573,15.42409,22412,50
288.66581,-1.86784,-7.47185,1.84182,7.47185,22412,50
289.05578,-2.22471,-15.73485,2.19869,15.73485,22476,50
289.27078,-2.44214,-19.93971,2.41612,19.93971,22476,51
289.49878,-2.67067,-24.79486,2.64465,24.79486,22476,51
289.67778,-2.84981,-28.83359,2.82379,28.83359,22476,51
289.79981,-2.97186,-31.79910,2.94584,31.79910,22476,51
289.89881,-3.07093,-34.31761,3.04491,34.31761,22476,51
290.02781,-3.19974,-37.31538,3.17372,37.31538,22476,51
290.15378,-3.32592,-40.19219,3.29990,40.19220,22476,51
290.32181,-3.49405,-44.23148,3.46803,44.23148,22476,51
290.50878,-3.68093,-48.63994,3.65491,48.63994,22476,51
290.75478,-3.92704,-54.29590,3.90102,54.29590,22476,51
290.93478,-4.10686,-58.31830,4.08084,58.31830,22476,51
291.17178,-4.34384,-63.78400,4.31782,63.78400,22476,51
291.42678,-4.59750,-69.63059,4.57148,69.63058,22476,51
291.62878,-4.40846,-62.53662,4.38244,62.53662,22476,51
291.89178,-4.13735,-53.77249,4.11133,53.77249,22412,51
292.20719,-3.82069,-44.32965,3.79467,44.32965,22412,51
292.50719,-3.52075,-35.85708,3.49473,35.85708,22412,51
292.80578,-3.22150,-28.21934,3.19548,28.21934,22412,51
293.41581,-2.61162,-17.62565,2.58559,17.62565,22412,51
294.20719,-1.86729,-7.74564,1.84127,7.74564,22412,51
294.79481,-2.48416,-20.83947,2.45814,20.83947,22476,52
295.15378,-2.84365,-28.75176,2.81762,28.75176,22476,52
295.34378,-3.03375,-33.39939,3.00773,33.39939,22476,52
295.57178,-3.26160,-38.82723,3.23558,38.82722,22476,52
295.86781,-3.55787,-45.73268,3.53185,45.73269,22476,52
296.20081,-3.89083,-53.45537,3.86481,53.45537,22476,52
296.58678,-4.27667,-62.32883,4.25065,62.32883,22476,52
296.92678,-4.60812,-69.78865,4.58210,69.78865,22476,52
297.16778,-4.35835,-60.79948,4.33233,60.79948,22476,52
297.40719,-4.11383,-52.97473,4.08781,52.97473,22412,52
297.64278,-3.87671,-45.95652,3.85069,45.95652,22412,52
297.84378,-3.67550,-40.12094,3.64948,40.12094,22412,52
298.04378,-3.47551,-34.62642,3.44949,34.62642,22412,52
298.24178,-3.27737,-29.41573,3.25135,29.41573,22412,52
298.55781,-2.96153,-23.16697,2.93550,23.16697,22412,52
299.14578,-2.37350,-14.22294,2.34748,14.22294,22412,52
299.76378,-1.96867,-10.28714,1.94265,10.28714,22412,52
300.45578,-2.67747,-24.79652,2.65145,24.79652,22476,53
300.78978,-3.01172,-32.69097,2.98570,32.69097,22476,53
301.18978,-3.41175,-42.29718,3.38573,42.29718,22476,53
301.50281,-3.72464,-49.55925,3.69862,49.55925,22476,53
301.80078,-4.02285,-56.42523,3.99682,56.42523,22476,53
302.03281,-4.25451,-61.66276,4.22849,61.66275,22476,53
302.27578,-4.49761,-67.20001,4.47159,67.20000,22476,53
302.47181,-4.52559,-66.55312,4.49957,66.55312,22476,53
302.65878,-4.32406,-59.68571,4.29804,59.68571,22412,53
302.80978,-4.16948,-54.75791,4.14346,54.75791,22412,53
302.96281,-4.01534,-50.13096,3.98932,50.13096,22412,53
303.14881,-3.82849,-44.50902,3.80247,44.50902,22412,53
303.34878,-3.62852,-38.96241,3.60250,38.96241,22412,53
303.50778,-3.46948,-34.47909,3.44346,34.47909,22412,53
303.70578,-3.27136,-29.23001,3.24534,29.23001,22412,53
303.92481,-3.05248,-24.87560,3.02646,24.87560,22412,53
304.27878,-2.69828,-18.89910,2.67226,18.89910,22412,53
304.73981,-2.23740,-12.38523,2.21138,12.38523,22412,53
305.30578,-2.05574,-12.28570,2.02972,12.28570,22412,53
305.84078,-2.60036,-23.10991,2.57434,23.10991,22476,54
306.11278,-2.87260,-29.20976,2.84658,29.20975,22476,54
306.25878,-3.01869,-32.81605,2.99267,32.81605,22476,54
306.41878,-3.17851,-36.63456,3.15249,36.63456,22476,54
306.57878,-3.33863,-40.43623,3.31261,40.43623,22476,54
306.74978,-3.50976,-44.45612,3.48374,44.45612,22476,54
306.90719,-3.66661,-48.20292,3.64059,48.20292,22476,54
307.06478,-3.82459,-51.84305,3.79856,51.84306,22476,54
307.23081,-3.99083,-55.62957,3.96481,55.62957,22476,54
307.42881,-4.18851,-60.12813,4.16249,60.12813,22476,54
307.60581,-4.36563,-64.23581,4.33960,64.23582,22476,54
307.77678,-4.53664,-68.12370,4.51062,68.12370,22476,54
307.91278,-4.56391,-67.88121,4.53789,67.88121,22476,54
308.08078,-4.37821,-61.40726,4.35218,61.40726,22476,54
308.25581,-4.19765,-55.59194,4.17163,55.59194,22412,54
308.40281,-4.04943,-51.04577,4.02341,51.04577,22412,54
308.56078,-3.89073,-46.40638,3.86471,46.40638,22412,54
308.76981,-3.68144,-40.21659,3.65542,40.21659,22412,54
308.99781,-3.45345,-34.00769,3.42743,34.00769,22412,54
309.21978,-3.23126,-28.33940,3.20524,28.33940,22412,54
309.46781,-2.98350,-23.56163,2.95748,23.56163,22412,54
309.80178,-2.64942,-18.13895,2.62340,18.13895,22412,54
310.39278,-2.05849,-10.00267,2.03247,10.00267,22412,54
310.97181,-2.24879,-16.08413,2.22277,16.08413,22476,54
311.59578,-2.87571,-29.33239,2.84969,29.33239,22476,55
311.84878,-3.12871,-35.45700,3.10269,35.45700,22476,55
312.14078,-3.42090,-42.51812,3.39488,42.51812,22476,55
312.30478,-3.58487,-46.34913,3.55885,46.34913,22476,55
312.48981,-3.76971,-50.69420,3.74369,50.69420,22476,55
312.65178,-3.93186,-54.37453,3.90584,54.37453,22476,55
312.82778,-4.10765,-58.29252,4.08163,58.29252,22476,55
313.07878,-4.35868,-64.06887,4.33266,64.06887,22476,55
313.26081,-4.54073,-68.27924,4.51471,68.27924,22476,55
313.46878,-4.47476,-64.63788,4.44874,64.63789,22476,55
313.64381,-4.28990,-58.45530,4.26388,58.45530,22412,55
313.82778,-4.10277,-52.59454,4.07675,52.59454,22412,55
314.00719,-3.92295,-47.34720,3.89693,47.34720,22412,55
314.20678,-3.72249,-41.46097,3.69646,41.46097,22412,55
314.39381,-3.53561,-36.20753,3.50958,36.20753,22412,55
314.58178,-3.34747,-31.04681,3.32145,31.04681,22412,55
314.91581,-3.01366,-24.06075,2.98764,24.06075,22412,55
315.30978,-2.61949,-17.63057,2.59347,17.63057,22412,55
315.82081,-2.10848,-10.61018,2.08245,10.61018,22412,55
316.30178,-2.10839,-13.23603,2.08237,13.23603,22412,55
316.97378,-2.78764,-27.11017,2.76162,27.11017,22476,56
317.27578,-3.08968,-34.55277,3.06366,34.55277,22476,56
317.54081,-3.35475,-40.79263,3.32873,40.79263,22476,56
317.75878,-3.57290,-46.00166,3.54688,46.00166,22476,56
317.97478,-3.78879,-51.00824,3.76277,51.00824,22476,56
318.19181,-4.00595,-55.95167,3.97993,55.95167,22476,56
318.38878,-4.20249,-60.45676,4.17647,60.45676,22476,56
318.63678,-4.45078,-66.10835,4.42476,66.10835,22476,56
318.86078,-4.56170,-67.71641,4.53568,67.71642,22476,56
319.05578,-4.34802,-60.31622,4.32200,60.31622,22476,56
319.22181,-4.17768,-54.93923,4.15166,54.93923,22412,56
319.38278,-4.01553,-49.99210,3.98951,49.99210,22412,56
319.54278,-3.85480,-45.21730,3.82878,45.21730,22412,56
319.69581,-3.70164,-40.79038,3.67562,40.79038,22412,56
319.83578,-3.56172,-36.94206,3.53570,36.94207,22412,56
319.99078,-3.40670,-32.59484,3.38068,32.59484,22412,56
320.18878,-3.20850,-27.72804,3.18248,27.72804,22412,56
320.46381,-2.93370,-22.66314,2.90768,22.66314,22412,56
320.80978,-2.58761,-17.13478,2.56159,17.13478,22412,56
321.28978,-2.10760,-10.59016,2.08158,10.59016,22412,56
321.70081,-2.06451,-12.24200,2.03849,12.24200,22412,56
321.98178,-2.35437,-18.02525,2.32834,18.02526,22476,56
322.21078,-2.58468,-22.67377,2.55866,22.67377,22476,57
322.43178,-2.80590,-27.49033,2.77988,27.49033,22476,57
322.57878,-2.95308,-31.06201,2.92706,31.06201,22476,57
322.73278,-3.10690,-34.78426,3.08088,34.78426,22476,57
322.85278,-3.22677,-37.74868,3.20075,37.74868,22476,57
323.00978,-3.38416,-41.47331,3.35814,41.47331,22476,57
323.15978,-3.53412,-45.01787,3.50810,45.01787,22476,57
323.30178,-3.67600,-48.39009,3.64998,48.39009,22476,57
323.49478,-3.86902,-52.79424,3.84300,52.79424,22476,57
323.67481,-4.04921,-56.88648,4.02319,56.88648,22476,57
323.82481,-4.19878,-60.33976,4.17276,60.33976,22476,57
323.99878,-4.37303,-64.38889,4.34701,64.38889,22476,57
324.19181,-4.56597,-68.79184,4.53995,68.79184,22476,57
324.35378,-4.50237,-65.53674,4.47635,65.53674,22476,57
324.53078,-4.31383,-59.18746,4.28781,59.18746,22476,57
324.68281,-4.15862,-54.22123,4.13260,54.22123,22412,57
324.86578,-3.97435,-48.76271,3.94833,48.76271,22412,57
325.04778,-3.79186,-43.42521,3.76583,43.42521,22412,57
325.22778,-3.61185,-38.33027,3.58583,38.33027,22412,57
325.42278,-3.41684,-32.89256,3.39082,32.89256,22412,57
325.63478,-3.20464,-27.57600,3.17862,27.57600,22412,57
325.92978,-2.90986,-22.21295,2.88384,22.21295,22412,57
326.29778,-2.54188,-16.48340,2.51586,16.48340,22412,57
326.87878,-1.96096,-8.52745,1.93494,8.52745,22412,57
327.30719,-2.20910,-15.21085,2.18308,15.21085,22604,57
327.85181,-2.75787,-26.48049,2.73185,26.48049,22604,58
328.20578,-3.11204,-34.96113,3.08602,34.96114,22604,58
328.58278,-3.48922,-44.03227,3.46320,44.03227,22604,58
329.07678,-3.98323,-55.40042,3.95721,55.40042,22604,58
329.52578,-4.43215,-65.68635,4.40613,65.68635,22604,58
329.83881,-4.48364,-64.90970,4.45762,64.90971,22604,58
330.18281,-4.12633,-53.24652,4.10031,53.24652,22540,58
330.54881,-3.75890,-42.42251,3.73288,42.42251,22540,58
330.91278,-3.39490,-32.28262,3.36888,32.28262,22540,58
331.69981,-2.60778,-17.41170,2.58176,17.41170,22540,58
332.55478,-1.98081,-10.42953,1.95479,10.42953,22540,58
333.24381,-2.68585,-24.82244,2.65983,24.82244,22604,59
333.61178,-3.05410,-33.60103,3.02808,33.60104,22604,59
333.89481,-3.33695,-40.40100,3.31093,40.40100,22604,59
334.11781,-3.56014,-45.66122,3.53412,45.66122,22604,59
334.32378,-3.76604,-50.47357,3.74002,50.47357,22604,59
334.52781,-3.97022,-55.11525,3.94419,55.11525,22604,59
334.71078,-4.15296,-59.32740,4.12694,59.32740,22604,59
334.86978,-4.31205,-62.90846,4.28602,62.90845,22604,59
335.04178,-4.48401,-66.86652,4.45799,66.86652,22604,59
335.17778,-4.60532,-69.57433,4.57930,69.57433,22604,59
335.35481,-4.41699,-62.61070,4.39097,62.61070,22604,59
335.56681,-4.19709,-55.47730,4.17106,55.47729,22540,59
335.74978,-4.01262,-49.84261,3.98660,49.84261,22540,59
335.92178,-3.83986,-44.73270,3.81383,44.73270,22540,59
336.14678,-3.61484,-38.35607,3.58882,38.35606,22540,59
336.28181,-3.47982,-34.59547,3.45380,34.59547,22540,59
336.47878,-3.28270,-29.35290,3.25668,29.35290,22540,59
336.74478,-3.01694,-24.07517,2.99092,24.07517,22540,59
337.10878,-2.65278,-18.09402,2.62675,18.09402,22540,59
337.49781,-2.26375,-12.61405,2.23773,12.61405,22540,59
337.92678,-1.86057,-7.21747,1.83455,7.21747,22540,59