File: data-raw/Experiment 2/Results/INSTRON data/Experiment 2.is_ccyclic_RawData/Specimen_RawData_21.csv
Text Inputs : Specimen label,"Long Plate 6 T1"

Time,Extension,Load,Compressive extension,Compressive load,Segment ID,Total Cycle Count
(sec),(mm),(N),(mm),(N),,
0.00000,-0.02626,-0.01116,0.00000,0.01116,12835,0
2.41420,-0.71384,-0.00923,0.68758,0.00923,3220,0
3.31420,-1.17875,-7.40656,1.15249,7.40656,3220,0
3.93680,-1.80861,-16.44691,1.78235,16.44691,22476,0
4.56780,-2.43959,-25.96856,2.41333,25.96856,22476,0
5.08080,-2.95280,-35.39735,2.92654,35.39735,22476,0
5.57480,-3.44660,-44.73037,3.42034,44.73037,22476,0
6.10780,-3.97974,-54.96838,3.95348,54.96838,22476,0
6.58180,-4.45378,-64.00157,4.42752,64.00156,22476,0
7.01080,-4.63989,-66.24877,4.61363,66.24877,22476,0
7.39780,-4.23874,-55.73707,4.21248,55.73707,22412,0
7.75780,-3.87776,-47.02787,3.85149,47.02787,22412,0
8.21420,-3.42145,-36.85047,3.39519,36.85048,22412,0
8.65780,-2.97759,-27.63838,2.95133,27.63838,22412,0
9.26280,-2.37260,-17.99646,2.34634,17.99646,22412,0
9.96880,-1.66637,-8.89440,1.64011,8.89440,22412,0
10.50580,-1.94710,-14.51197,1.92084,14.51197,22476,0
11.08180,-2.52531,-23.97141,2.49905,23.97141,22476,1
11.53480,-2.97850,-32.83708,2.95224,32.83708,22476,1
11.99580,-3.43933,-42.35818,3.41307,42.35818,22476,1
12.49180,-3.93552,-52.40494,3.90926,52.40494,22476,1
12.92480,-4.36867,-61.12799,4.34241,61.12799,22476,1
13.38980,-4.80598,-69.78367,4.77972,69.78368,22476,1
13.75780,-4.41404,-59.16451,4.38778,59.16451,22412,1
14.13480,-4.03446,-49.73712,4.00820,49.73712,22412,1
14.61380,-3.55523,-39.10260,3.52897,39.10260,22412,1
15.08280,-3.08624,-29.20542,3.05998,29.20543,22412,1
15.66380,-2.50520,-19.36582,2.47894,19.36582,22412,1
16.35480,-1.81438,-10.36818,1.78812,10.36818,22412,1
16.91420,-1.88305,-12.91039,1.85678,12.91039,22476,1
17.49080,-2.46427,-22.32107,2.43801,22.32107,22476,2
18.01420,-2.98746,-32.33137,2.96120,32.33138,22476,2
18.45080,-3.42433,-41.36908,3.39807,41.36908,22476,2
18.93780,-3.91160,-51.37227,3.88534,51.37227,22476,2
19.41180,-4.38561,-60.94053,4.35935,60.94053,22476,2
19.85880,-4.81877,-69.72360,4.79251,69.72360,22476,2
20.22380,-4.43623,-59.33236,4.40997,59.33236,22412,2
20.65480,-4.00247,-48.59866,3.97621,48.59866,22412,2
21.08780,-3.56923,-39.04145,3.54297,39.04145,22412,2
21.55980,-3.09719,-29.08406,3.07093,29.08406,22412,2
22.13080,-2.52613,-19.39066,2.49987,19.39066,22412,2
22.82180,-1.83538,-10.40025,1.80912,10.40025,22412,2
23.37580,-1.90890,-12.95452,1.88264,12.95452,22476,2
23.95980,-2.49721,-22.53579,2.47095,22.53579,22476,3
24.46280,-3.00035,-32.26731,2.97408,32.26731,22476,3
24.94980,-3.48729,-42.35766,3.46103,42.35766,22476,3
25.44580,-3.98340,-52.45160,3.95714,52.45160,22476,3
25.93280,-4.47045,-62.37249,4.44419,62.37249,22476,3
26.35580,-4.80185,-68.78114,4.77559,68.78114,22476,3
26.72880,-4.40431,-58.13794,4.37805,58.13794,22412,3
27.16580,-3.96543,-47.55123,3.93917,47.55124,22412,3
27.59680,-3.53408,-38.01614,3.50782,38.01614,22412,3
28.01780,-3.11310,-29.15604,3.08684,29.15604,22412,3
28.61420,-2.51706,-19.09444,2.49080,19.09444,22412,3
29.30780,-1.82332,-10.06880,1.79706,10.06880,22412,3
29.88180,-1.96608,-13.61525,1.93982,13.61525,22476,3
30.44580,-2.53318,-22.92642,2.50692,22.92642,22476,4
30.95680,-3.04429,-32.89943,3.01803,32.89943,22476,4
31.43480,-3.52229,-42.88094,3.49602,42.88094,22476,4
31.92780,-4.01531,-52.88628,3.98905,52.88628,22476,4
32.38380,-4.47146,-62.25772,4.44520,62.25772,22476,4
32.80980,-4.81249,-68.84640,4.78623,68.84640,22476,4
33.18380,-4.41334,-58.10315,4.38708,58.10315,22412,4
33.57480,-4.02032,-48.55425,3.99406,48.55425,22412,4
33.95180,-3.64318,-40.10537,3.61692,40.10537,22412,4
34.40180,-3.19327,-30.58116,3.16701,30.58116,22412,4
34.93580,-2.65913,-21.04378,2.63287,21.04378,22412,4
35.61980,-1.97523,-11.91121,1.94897,11.91121,22412,4
36.11420,-1.78448,-10.44530,1.75822,10.44530,22412,4
36.71420,-2.39703,-20.28812,2.37077,20.28811,22476,5
37.21880,-2.90234,-29.76110,2.87607,29.76110,22476,5
37.71420,-3.39729,-39.96646,3.37103,39.96646,22476,5
38.16680,-3.85051,-49.32123,3.82425,49.32124,22476,5
38.61420,-4.29744,-58.45451,4.27117,58.45451,22476,5
39.11420,-4.79731,-68.69765,4.77105,68.69765,22476,5
39.46680,-4.54698,-61.43105,4.52072,61.43105,22412,5
39.89180,-4.11746,-50.63774,4.09120,50.63774,22412,5
40.33680,-3.67222,-40.58641,3.64596,40.58641,22412,5
40.73180,-3.27743,-32.19549,3.25117,32.19549,22412,5
41.28480,-2.72425,-21.99493,2.69799,21.99493,22412,5
41.94680,-2.06209,-12.84892,2.03583,12.84892,22412,5
42.53080,-1.76696,-10.04766,1.74070,10.04766,22412,5
43.11420,-2.36316,-19.65422,2.33690,19.65422,22476,6
43.64380,-2.89339,-29.37303,2.86712,29.37303,22476,6
44.10080,-3.35048,-38.94777,3.32422,38.94777,22476,6
44.59180,-3.84154,-48.99463,3.81528,48.99463,22476,6
45.07480,-4.32452,-58.82970,4.29826,58.82970,22476,6
45.51680,-4.76632,-67.92640,4.74006,67.92640,22476,6
45.90980,-4.56809,-61.76973,4.54183,61.76973,22412,6
46.31420,-4.15926,-51.46961,4.13300,51.46960,22412,6
46.76880,-3.70408,-41.18324,3.67782,41.18324,22412,6
47.24080,-3.23226,-31.05428,3.20600,31.05428,22412,6
47.80480,-2.66799,-20.94793,2.64173,20.94793,22412,6
48.48980,-1.98308,-11.81933,1.95682,11.81933,22412,6
49.02080,-1.82381,-10.83855,1.79755,10.83855,22412,6
49.61420,-2.42686,-20.58443,2.40060,20.58443,22476,7
50.14880,-2.96217,-30.56751,2.93591,30.56751,22476,7
50.59380,-3.40708,-39.90687,3.38082,39.90687,22476,7
51.00180,-3.81527,-48.40432,3.78901,48.40432,22476,7
51.44580,-4.25929,-57.45945,4.23303,57.45945,22476,7
51.90080,-4.71424,-66.75679,4.68798,66.75679,22476,7
52.26980,-4.66592,-64.23149,4.63966,64.23149,22476,7
52.63080,-4.29692,-54.71522,4.27066,54.71522,22412,7
53.08480,-3.84221,-44.07232,3.81595,44.07232,22412,7
53.52080,-3.40598,-34.64811,3.37972,34.64811,22412,7
53.97280,-2.95401,-25.68655,2.92775,25.68655,22412,7
54.60980,-2.31718,-15.95278,2.29092,15.95278,22412,7
55.26180,-1.66491,-7.34598,1.63865,7.34598,22412,7
55.81420,-2.17399,-16.41798,2.14773,16.41798,22604,7
56.31680,-2.67805,-24.93149,2.65179,24.93149,22604,8
56.81420,-3.17503,-34.97209,3.14877,34.97210,22604,8
57.31420,-3.67511,-45.35437,3.64885,45.35437,22604,8
57.80580,-4.16707,-55.40171,4.14081,55.40171,22604,8
58.21420,-4.57501,-63.82213,4.54875,63.82213,22604,8
58.61780,-4.77223,-67.01798,4.74597,67.01798,22604,8
59.01420,-4.36034,-56.23762,4.33408,56.23762,22540,8
59.39180,-3.98115,-47.24054,3.95489,47.24054,22540,8
59.77580,-3.59698,-38.70305,3.57072,38.70305,22540,8
60.13580,-3.23715,-30.94714,3.21089,30.94714,22540,8
60.63380,-2.73897,-21.93317,2.71271,21.93317,22540,8
61.31420,-2.05883,-12.56019,2.03257,12.56019,22540,8
61.90380,-1.81172,-10.50622,1.78546,10.50622,22540,8
62.49180,-2.41078,-20.07049,2.38452,20.07049,22604,9
63.01280,-2.93212,-29.78633,2.90586,29.78633,22604,9
63.44380,-3.36319,-38.86928,3.33693,38.86928,22604,9
63.85180,-3.77115,-47.41811,3.74488,47.41811,22604,9
64.34480,-4.26425,-57.32192,4.23799,57.32193,22604,9
64.80080,-4.72018,-66.69036,4.69392,66.69036,22604,9
65.11880,-4.71192,-65.30154,4.68566,65.30154,22604,9
65.49380,-4.32607,-55.23055,4.29981,55.23055,22540,9
65.81420,-4.00504,-47.70033,3.97878,47.70033,22540,9
66.21420,-3.60495,-38.80809,3.57869,38.80809,22540,9
66.50080,-3.31814,-32.64601,3.29188,32.64601,22540,9
66.96980,-2.84898,-23.67771,2.82272,23.67771,22540,9
67.61420,-2.20496,-14.35894,2.17870,14.35894,22540,9
68.31420,-1.64740,-7.36862,1.62114,7.36862,22540,9
69.01420,-2.12553,-15.71309,2.09927,15.71309,22476,9
69.58980,-2.70230,-25.40712,2.67604,25.40712,22476,10
69.98780,-3.10013,-33.37486,3.07387,33.37487,22476,10
70.19780,-3.31042,-37.77644,3.28416,37.77644,22476,10
70.59180,-3.70433,-45.94038,3.67807,45.94038,22476,10
71.00580,-4.11826,-54.33379,4.09200,54.33379,22476,10
71.44780,-4.56011,-63.44045,4.53385,63.44045,22476,10
71.87880,-4.76959,-66.79147,4.74333,66.79147,22476,10
72.26780,-4.36552,-56.20169,4.33926,56.20169,22412,10
72.70580,-3.92626,-45.76978,3.90000,45.76978,22412,10
73.17280,-3.45909,-35.53016,3.43283,35.53017,22412,10
73.67580,-2.95612,-25.50644,2.92986,25.50644,22412,10
74.31280,-2.31927,-15.81481,2.29301,15.81481,22412,10
74.98980,-1.67246,-7.44933,1.64620,7.44933,22412,10
75.52280,-2.23239,-17.06052,2.20613,17.06052,22476,10
76.08080,-2.79113,-26.73124,2.76487,26.73124,22476,11
76.56780,-3.27833,-36.84426,3.25207,36.84426,22476,11
77.04080,-3.75122,-46.79999,3.72495,46.79999,22476,11
77.51420,-4.22430,-56.43100,4.19804,56.43100,22476,11
77.94180,-4.65214,-65.24627,4.62588,65.24627,22476,11
78.31580,-4.72915,-65.68193,4.70289,65.68193,22476,11
78.61420,-4.41990,-57.50742,4.39364,57.50742,22412,11
79.04180,-3.99018,-47.22802,3.96392,47.22802,22412,11
79.47680,-3.55492,-37.52949,3.52866,37.52949,22412,11
79.86980,-3.16189,-29.27028,3.13563,29.27028,22412,11
80.44480,-2.58699,-19.39611,2.56073,19.39611,22412,11
81.12680,-1.90512,-10.50150,1.87886,10.50150,22412,11
81.70880,-2.01130,-13.49551,1.98504,13.49551,22476,11
82.28380,-2.58994,-23.00916,2.56368,23.00916,22476,12
82.78280,-3.08890,-32.77840,3.06264,32.77840,22476,12
83.16980,-3.47595,-40.87559,3.44969,40.87559,22476,12
83.62280,-3.92912,-50.33524,3.90286,50.33524,22476,12
84.04380,-4.35023,-58.94263,4.32397,58.94263,22476,12
84.41420,-4.72013,-66.56788,4.69387,66.56788,22476,12
84.77280,-4.68035,-64.27811,4.65409,64.27811,22476,12
85.17480,-4.26954,-53.62176,4.24328,53.62176,22412,12
85.61420,-3.83005,-43.47776,3.80379,43.47776,22412,12
86.09180,-3.35201,-33.17257,3.32575,33.17257,22412,12
86.55980,-2.88387,-24.09639,2.85760,24.09639,22412,12
87.21420,-2.22996,-14.50719,2.20370,14.50719,22412,12
87.81420,-1.69910,-7.83639,1.67284,7.83639,22412,12
88.38680,-2.30046,-18.05533,2.27420,18.05533,22476,12
88.92680,-2.84104,-27.50179,2.81478,27.50179,22476,13
89.41420,-3.32811,-37.74892,3.30185,37.74892,22476,13
89.84380,-3.75808,-46.78959,3.73182,46.78959,22476,13
90.34280,-4.25716,-56.96916,4.23090,56.96916,22476,13
90.79880,-4.71306,-66.33694,4.68680,66.33694,22476,13
91.19180,-4.66185,-63.71843,4.63559,63.71843,22476,13
91.58880,-4.25731,-53.25159,4.23105,53.25159,22412,13
92.00880,-3.83691,-43.50904,3.81065,43.50904,22412,13
92.33780,-3.50761,-36.31407,3.48135,36.31407,22412,13
92.75780,-3.08757,-27.57163,3.06131,27.57163,22412,13
93.35180,-2.49358,-18.04404,2.46732,18.04403,22412,13
94.03480,-1.81077,-9.02452,1.78451,9.02452,22412,13
94.57280,-2.08218,-14.52028,2.05592,14.52028,22476,13
95.14280,-2.65470,-23.99665,2.62844,23.99665,22476,14
95.63480,-3.14668,-33.88305,3.12042,33.88305,22476,14
96.03880,-3.55062,-42.34064,3.52436,42.34064,22476,14
96.41420,-3.92583,-50.15135,3.89957,50.15135,22476,14
96.81780,-4.32994,-58.39878,4.30368,58.39878,22476,14
97.27380,-4.78570,-67.81963,4.75944,67.81963,22476,14
97.65480,-4.61237,-62.32489,4.58611,62.32489,22412,14
98.00580,-4.25626,-53.17304,4.23000,53.17304,22412,14
98.44680,-3.81478,-43.03319,3.78852,43.03319,22412,14
98.87780,-3.38370,-33.74196,3.35744,33.74196,22412,14
99.34680,-2.91465,-24.53595,2.88839,24.53595,22412,14
99.98780,-2.27374,-15.01276,2.24747,15.01276,22412,14
100.61420,-1.69429,-7.51774,1.66803,7.51774,22412,14
101.16180,-2.27110,-17.42534,2.24484,17.42534,22476,14
101.71420,-2.82373,-27.00155,2.79747,27.00155,22476,15
102.16480,-3.27492,-36.43665,3.24866,36.43665,22476,15
102.60880,-3.71882,-45.78366,3.69256,45.78366,22476,15
103.05180,-4.16172,-54.90807,4.13546,54.90807,22476,15
103.50680,-4.61674,-64.29089,4.59048,64.29089,22476,15
103.92280,-4.76071,-66.17293,4.73445,66.17293,22476,15
104.31420,-4.35671,-55.65436,4.33045,55.65436,22412,15
104.75280,-3.91662,-45.19774,3.89036,45.19774,22412,15
105.21980,-3.44949,-35.04056,3.42323,35.04056,22412,15
105.68980,-2.97949,-25.61656,2.95323,25.61656,22412,15
106.31180,-2.35763,-16.06347,2.33137,16.06347,22412,15
106.96280,-1.70653,-7.45810,1.68027,7.45810,22412,15
107.51380,-2.21456,-16.47918,2.18830,16.47918,22476,15
108.06080,-2.76258,-25.88699,2.73632,25.88699,22476,16
108.54080,-3.24276,-35.67381,3.21650,35.67381,22476,16
108.91420,-3.61563,-43.59453,3.58937,43.59453,22476,16
109.36280,-4.06446,-52.84622,4.03820,52.84622,22476,16
109.72780,-4.42958,-60.34914,4.40332,60.34914,22476,16
110.16280,-4.86460,-69.39114,4.83834,69.39114,22476,16
110.52980,-4.54296,-60.35218,4.51670,60.35218,22412,16
110.95480,-4.11458,-49.66445,4.08832,49.66445,22412,16
111.33180,-3.73741,-41.20894,3.71115,41.20894,22412,16
111.81420,-3.25559,-30.84389,3.22932,30.84389,22412,16
112.36580,-2.70341,-20.97757,2.67715,20.97757,22412,16
113.03880,-2.03033,-11.86503,2.00407,11.86504,22412,16
113.60480,-1.90415,-11.50515,1.87789,11.50515,22412,16
114.18080,-2.48823,-20.88930,2.46197,20.88931,22476,17
114.70480,-3.01243,-30.79612,2.98617,30.79612,22476,17
115.10580,-3.41339,-39.30232,3.38713,39.30232,22476,17
115.58580,-3.89361,-49.26819,3.86735,49.26819,22476,17
116.07780,-4.38562,-59.47503,4.35935,59.47503,22476,17
116.51580,-4.82344,-68.46557,4.79718,68.46557,22476,17
116.89480,-4.57474,-61.15757,4.54848,61.15757,22412,17
117.30280,-4.16241,-50.79165,4.13615,50.79165,22412,17
117.71420,-3.75124,-41.41886,3.72498,41.41886,22412,17
118.19780,-3.26743,-31.08424,3.24117,31.08424,22412,17
118.73180,-2.73329,-21.42650,2.70703,21.42650,22412,17
119.41420,-2.05118,-12.09727,2.02491,12.09727,22412,17
119.98880,-1.88309,-11.07127,1.85683,11.07127,22412,17
120.56480,-2.46804,-20.46155,2.44178,20.46155,22604,18
121.09480,-2.99828,-30.42067,2.97202,30.42067,22604,18
121.49380,-3.39730,-38.90960,3.37104,38.90960,22604,18
121.97680,-3.88049,-49.02453,3.85423,49.02453,22604,18
122.45680,-4.36050,-58.86805,4.33423,58.86805,22604,18
122.94180,-4.84532,-68.96099,4.81906,68.96099,22604,18
123.31420,-4.55905,-60.73415,4.53278,60.73415,22540,18
123.71420,-4.15523,-50.59687,4.12897,50.59687,22540,18
124.12980,-3.73910,-41.20312,3.71284,41.20311,22540,18
124.61420,-3.25526,-30.76991,3.22900,30.76991,22540,18
125.16180,-2.70708,-20.96522,2.68082,20.96522,22540,18
125.83080,-2.03801,-11.92830,2.01175,11.92830,22540,18
126.39780,-1.90272,-11.43457,1.87646,11.43457,22540,18
126.92980,-2.44292,-20.01566,2.41666,20.01566,22604,19
127.38680,-2.90029,-28.36629,2.87403,28.36629,22604,19
127.86080,-3.37432,-38.39378,3.34806,38.39378,22604,19
128.25780,-3.77132,-46.73805,3.74506,46.73806,22604,19
128.67580,-4.18924,-55.36441,4.16298,55.36441,22604,19
129.04180,-4.55508,-62.89627,4.52882,62.89627,22604,19
129.35680,-4.87028,-69.40210,4.84402,69.40210,22604,19
129.63880,-4.63658,-62.73762,4.61032,62.73762,22604,19
129.91420,-4.35630,-55.51752,4.33004,55.51752,22540,19
130.20980,-4.05909,-48.28474,4.03283,48.28474,22540,19
130.54579,-3.72315,-40.72202,3.69689,40.72202,22540,19
130.91420,-3.35527,-32.86338,3.32901,32.86338,22540,19
131.44280,-2.82618,-22.88493,2.79992,22.88493,22540,19
132.10080,-2.16803,-13.43366,2.14177,13.43366,22540,19
132.61420,-1.68986,-7.15298,1.66360,7.15298,22540,19
133.31419,-2.08184,-14.37988,2.05558,14.37988,22476,19
133.91420,-2.68339,-24.39612,2.65713,24.39612,22476,20
134.40780,-3.17735,-34.28013,3.15109,34.28013,22476,20
134.70080,-3.47033,-40.36550,3.44406,40.36550,22476,20
135.16180,-3.93152,-50.10357,3.90525,50.10358,22476,20
135.47380,-4.24361,-56.47412,4.21735,56.47412,22476,20
135.84080,-4.61038,-64.09303,4.58412,64.09303,22476,20
136.19880,-4.82407,-67.89960,4.79781,67.89960,22476,20
136.50180,-4.50205,-59.24302,4.47579,59.24302,22412,20
136.75380,-4.24785,-52.83052,4.22159,52.83052,22412,20
137.09780,-3.90339,-44.75465,3.87713,44.75465,22412,20
137.44680,-3.55415,-37.16121,3.52789,37.16121,22412,20
137.89580,-3.10516,-27.71392,3.07890,27.71392,22412,20
138.49380,-2.50713,-18.03285,2.48087,18.03284,22412,20
139.17980,-1.82133,-8.93529,1.79507,8.93529,22412,20
139.71080,-2.09991,-14.48588,2.07365,14.48588,22476,20
140.21980,-2.61136,-22.91486,2.58510,22.91486,22476,21
140.72380,-3.11536,-32.82179,3.08910,32.82179,22476,21
141.21420,-3.60544,-43.14580,3.57918,43.14580,22476,21
141.61420,-4.00542,-51.55266,3.97916,51.55266,22476,21
142.06280,-4.45446,-60.71255,4.42820,60.71255,22476,21
142.50480,-4.89227,-69.88234,4.86601,69.88234,22476,21
142.82680,-4.56636,-60.80456,4.54010,60.80457,22412,21
143.21420,-4.17549,-51.01231,4.14923,51.01231,22412,21
143.66178,-3.72729,-40.79701,3.70103,40.79701,22412,21
144.11280,-3.27641,-31.12926,3.25015,31.12926,22412,21
144.63880,-2.75031,-21.55066,2.72405,21.55066,22412,21
145.31419,-2.07525,-12.28718,2.04899,12.28718,22412,21
145.88480,-1.88641,-11.01244,1.86015,11.01244,22412,21
146.45480,-2.46612,-20.28937,2.43986,20.28937,22476,22
146.98480,-2.99638,-30.24703,2.97012,30.24703,22476,22
147.41480,-3.42628,-39.36203,3.40001,39.36203,22476,22
147.91178,-3.92348,-49.70938,3.89722,49.70938,22476,22
148.31419,-4.32557,-58.05471,4.29931,58.05471,22476,22
148.77180,-4.78334,-67.48149,4.75708,67.48149,22476,22
149.11420,-4.67520,-63.62908,4.64894,63.62907,22476,22
149.51419,-4.26779,-53.19043,4.24153,53.19043,22412,22
149.96680,-3.81433,-42.67879,3.78807,42.67879,22412,22
150.43080,-3.35034,-32.65409,3.32408,32.65409,22412,22
150.97280,-2.80817,-22.53230,2.78191,22.53230,22412,22
151.57480,-2.20626,-13.83772,2.18000,13.83772,22412,22
152.18580,-1.78067,-9.01725,1.75441,9.01725,22412,22
152.74380,-2.35698,-18.55640,2.33072,18.55640,22476,23
153.28880,-2.90237,-28.26579,2.87611,28.26579,22476,23
153.76280,-3.37639,-38.29385,3.35013,38.29385,22476,23
154.21420,-3.82747,-47.85972,3.80121,47.85973,22476,23
154.70580,-4.31950,-57.88328,4.29324,57.88328,22476,23
155.17880,-4.79232,-67.69295,4.76606,67.69295,22476,23
155.55780,-4.62088,-62.18539,4.59461,62.18539,22476,23
155.84480,-4.32912,-54.69764,4.30286,54.69764,22412,23
156.27180,-3.90125,-44.53168,3.87499,44.53168,22412,23
156.69980,-3.47311,-35.26057,3.44685,35.26057,22412,23
157.20980,-2.96311,-25.09897,2.93685,25.09897,22412,23
157.81680,-2.35626,-15.83927,2.32999,15.83927,22412,23
158.47380,-1.70279,-7.13351,1.67653,7.13351,22412,23
158.96778,-2.20202,-16.00779,2.17576,16.00779,22476,23
159.48780,-2.72338,-24.84670,2.69712,24.84669,22476,24
159.86480,-3.10019,-32.35424,3.07393,32.35424,22476,24
160.21980,-3.45522,-39.84632,3.42896,39.84632,22476,24
160.58980,-3.82548,-47.75795,3.79922,47.75795,22476,24
161.02980,-4.26549,-56.82125,4.23923,56.82125,22476,24
161.48480,-4.72042,-66.18093,4.69416,66.18093,22476,24
161.81419,-4.75219,-65.70492,4.72593,65.70492,22476,24
162.11420,-4.44092,-57.48790,4.41465,57.48790,22412,24
162.51380,-4.03909,-47.76875,4.01283,47.76875,22412,24
162.79880,-3.75410,-41.23721,3.72784,41.23721,22412,24
163.09278,-3.46007,-34.95998,3.43381,34.95998,22412,24
163.56680,-2.98606,-25.51994,2.95980,25.51994,22412,24
164.18080,-2.37213,-16.04293,2.34587,16.04293,22412,24
164.75580,-1.79710,-8.47157,1.77084,8.47157,22412,24
165.27580,-2.13918,-14.98346,2.11292,14.98346,22476,24
165.83980,-2.70528,-24.42484,2.67902,24.42484,22476,25
166.32780,-3.19326,-34.34548,3.16700,34.34548,22476,25
166.73480,-3.60025,-42.85444,3.57399,42.85443,22476,25
167.11420,-3.97927,-50.90808,3.95301,50.90808,22476,25
167.50980,-4.37537,-59.06857,4.34911,59.06857,22476,25
167.83880,-4.70434,-65.84179,4.67808,65.84180,22476,25
168.10280,-4.84804,-68.29617,4.82178,68.29617,22476,25
168.38080,-4.54947,-60.27878,4.52320,60.27879,22412,25
168.68780,-4.23951,-52.43478,4.21325,52.43478,22412,25
169.02378,-3.90311,-44.50362,3.87685,44.50362,22412,25
169.31180,-3.61500,-38.28485,3.58874,38.28485,22412,25
169.59380,-3.33320,-32.22454,3.30694,32.22454,22412,25
169.85080,-3.07585,-26.94828,3.04959,26.94828,22412,25
170.30680,-2.61996,-19.40996,2.59370,19.40996,22412,25
170.91420,-2.01297,-11.35859,1.98671,11.35859,22412,25
171.41420,-1.90752,-11.15374,1.88125,11.15374,22412,25
171.94980,-2.45284,-19.93976,2.42658,19.93976,22476,26
172.48180,-2.98518,-29.82503,2.95892,29.82503,22476,26
172.87880,-3.38223,-38.26931,3.35597,38.26931,22476,26
173.35380,-3.85735,-48.33113,3.83109,48.33113,22476,26
173.66680,-4.17016,-54.75836,4.14389,54.75836,22476,26
174.06080,-4.56402,-62.88359,4.53776,62.88359,22476,26
174.44180,-4.89238,-69.53372,4.86612,69.53372,22476,26
174.81419,-4.49329,-58.73562,4.46703,58.73561,22412,26
175.17380,-4.13107,-49.65197,4.10481,49.65197,22412,26
175.55780,-3.74700,-41.09037,3.72074,41.09037,22412,26
176.00080,-3.30412,-31.48670,3.27786,31.48670,22412,26
176.48680,-2.81799,-22.58128,2.79173,22.58128,22412,26
177.07580,-2.22910,-14.02781,2.20284,14.02781,22412,26
177.67980,-1.77806,-8.78082,1.75180,8.78082,22412,26
178.24180,-2.36075,-18.50191,2.33449,18.50191,22476,27
178.79380,-2.91317,-28.25725,2.88691,28.25725,22476,27
179.14878,-3.26833,-35.70044,3.24207,35.70044,22476,27
179.41280,-3.53204,-41.33204,3.50577,41.33204,22476,27
179.83880,-3.95822,-50.37133,3.93196,50.37133,22476,27
180.24780,-4.36728,-58.78931,4.34102,58.78931,22476,27
180.65480,-4.77414,-67.18571,4.74788,67.18571,22476,27
180.93380,-4.74568,-65.48563,4.71942,65.48563,22476,27
181.17980,-4.48940,-58.62282,4.46314,58.62282,22412,27
181.45580,-4.21138,-51.71505,4.18512,51.71505,22412,27
181.70980,-3.95711,-45.69395,3.93085,45.69395,22412,27
181.97080,-3.69595,-39.88374,3.66969,39.88374,22412,27
182.21480,-3.45192,-34.69884,3.42566,34.69884,22412,27
182.61480,-3.05177,-26.53933,3.02551,26.53933,22412,27
183.17780,-2.48884,-17.53741,2.46258,17.53741,22412,27
183.81419,-1.85308,-9.14168,1.82682,9.14168,22412,27
184.31419,-2.10014,-14.16042,2.07388,14.16042,22604,27
184.89580,-2.68518,-23.95165,2.65892,23.95165,22604,28
185.31419,-3.10307,-32.23963,3.07681,32.23964,22604,28
185.71420,-3.50313,-40.66703,3.47686,40.66703,22604,28
186.07280,-3.86238,-48.38980,3.83612,48.38980,22604,28
186.43280,-4.22240,-55.81256,4.19614,55.81256,22604,28
186.81419,-4.60316,-63.66174,4.57690,63.66174,22604,28
187.08980,-4.87920,-69.40045,4.85294,69.40045,22604,28
187.44178,-4.57304,-60.84929,4.54678,60.84929,22540,28
187.81419,-4.19737,-51.36428,4.17111,51.36428,22540,28
188.07380,-3.93716,-45.23031,3.91090,45.23031,22540,28
188.51380,-3.49696,-35.63170,3.47070,35.63170,22540,28
189.01419,-2.99699,-25.59802,2.97073,25.59802,22540,28
189.61420,-2.39700,-16.26833,2.37074,16.26833,22540,28
190.27180,-1.73909,-7.51443,1.71283,7.51443,22540,28
190.81419,-2.23818,-16.42005,2.21192,16.42005,22604,28
191.31580,-2.74126,-25.00741,2.71500,25.00741,22604,29
191.77880,-3.20429,-34.42694,3.17803,34.42694,22604,29
192.10778,-3.53311,-41.24570,3.50685,41.24570,22604,29
192.38578,-3.81132,-47.30695,3.78506,47.30695,22604,29
192.69880,-4.12421,-53.72886,4.09794,53.72886,22604,29
193.01419,-4.43918,-60.25176,4.41292,60.25177,22604,29
193.44680,-4.87222,-69.30676,4.84596,69.30676,22604,29
193.68880,-4.68462,-63.74685,4.65836,63.74685,22604,29
193.91420,-4.45299,-57.68043,4.42673,57.68043,22540,29
194.31419,-4.05102,-47.94693,4.02476,47.94693,22540,29
194.61420,-3.75101,-41.09998,3.72475,41.09998,22540,29
194.91420,-3.45099,-34.63334,3.42473,34.63334,22540,29
195.15380,-3.21115,-29.60709,3.18489,29.60709,22540,29
195.61420,-2.75105,-21.41768,2.72479,21.41768,22540,29
196.30980,-2.05497,-11.88610,2.02871,11.88610,22540,29
197.04780,-1.71911,-7.71167,1.69285,7.71167,22540,29
197.51419,-2.18789,-15.79395,2.16163,15.79395,22476,29
198.08380,-2.75873,-25.45593,2.73247,25.45593,22476,30
198.42380,-3.09858,-32.28352,3.07232,32.28352,22476,30
198.85180,-3.52660,-41.26618,3.50034,41.26618,22476,30
199.11080,-3.78575,-46.83679,3.75949,46.83678,22476,30
199.42880,-4.10367,-53.35727,4.07741,53.35727,22476,30
199.78580,-4.46070,-60.78304,4.43444,60.78304,22476,30
200.20380,-4.87870,-69.46197,4.85244,69.46198,22476,30
200.51419,-4.61590,-61.96884,4.58964,61.96884,22412,30
200.90480,-4.22000,-51.93295,4.19374,51.93295,22412,30
201.16480,-3.95968,-45.71856,3.93341,45.71856,22412,30
201.43480,-3.68953,-39.78057,3.66327,39.78057,22412,30
201.71978,-3.40449,-33.68935,3.37823,33.68935,22412,30
202.03980,-3.08439,-27.06638,3.05813,27.06638,22412,30
202.60580,-2.51840,-18.02158,2.49214,18.02158,22412,30
203.27180,-1.85266,-9.07590,1.82640,9.07590,22412,30
203.73080,-2.05758,-13.41198,2.03132,13.41198,22476,30
204.26580,-2.59656,-22.30252,2.57030,22.30252,22476,31
204.66680,-2.99768,-29.98831,2.97142,29.98831,22476,31
204.84980,-3.18064,-33.85439,3.15438,33.85439,22476,31
205.20080,-3.53159,-41.20228,3.50533,41.20228,22476,31
205.48380,-3.81481,-47.41232,3.78855,47.41232,22476,31
205.81419,-4.14470,-54.14660,4.11844,54.14660,22476,31
206.11180,-4.44270,-60.30637,4.41644,60.30637,22476,31
206.47480,-4.80572,-67.87404,4.77946,67.87404,22476,31
206.74578,-4.73389,-65.08425,4.70763,65.08425,22476,31
207.08780,-4.38171,-55.91828,4.35545,55.91828,22412,31
207.33580,-4.13257,-49.70077,4.10631,49.70077,22412,31
207.58580,-3.88263,-43.98694,3.85637,43.98694,22412,31
207.90078,-3.56738,-37.07078,3.54112,37.07078,22412,31
208.18480,-3.28361,-30.98460,3.25735,30.98460,22412,31
208.59278,-2.87551,-23.38106,2.84925,23.38106,22412,31
209.11420,-2.35460,-15.64052,2.32834,15.64052,22412,31
209.72380,-1.74453,-7.52988,1.71827,7.52988,22412,31
210.20380,-2.17687,-15.39524,2.15061,15.39524,22476,31
210.71419,-2.68865,-23.93560,2.66239,23.93560,22476,32
211.13378,-3.10858,-32.22579,3.08232,32.22579,22476,32
211.46580,-3.44059,-39.33579,3.41433,39.33579,22476,32
211.80080,-3.77573,-46.40696,3.74947,46.40696,22476,32
212.12580,-4.10062,-53.21992,4.07436,53.21992,22476,32
212.44178,-4.41671,-59.75552,4.39044,59.75552,22476,32
212.71180,-4.68670,-65.38360,4.66044,65.38360,22476,32
212.97680,-4.88012,-69.16041,4.85386,69.16041,22476,32
213.22280,-4.61063,-61.81656,4.58437,61.81656,22476,32
213.51419,-4.31533,-54.13096,4.28907,54.13095,22412,32
213.78480,-4.04343,-47.66032,4.01717,47.66032,22412,32
213.99680,-3.83166,-42.76132,3.80540,42.76132,22412,32
214.21419,-3.61448,-38.07041,3.58822,38.07042,22412,32
214.46880,-3.35959,-32.66742,3.33333,32.66742,22412,32
214.81419,-3.01440,-25.82137,2.98814,25.82137,22412,32
215.27080,-2.55730,-18.52588,2.53104,18.52588,22412,32
215.80080,-2.02742,-11.40207,2.00116,11.40207,22412,32
216.30080,-1.90964,-11.01078,1.88337,11.01079,22412,32
216.87680,-2.49537,-20.49804,2.46911,20.49804,22476,33
217.28480,-2.90373,-27.88773,2.87747,27.88773,22476,33
217.56180,-3.18055,-33.80124,3.15429,33.80124,22476,33
217.91980,-3.53859,-41.30561,3.51233,41.30561,22476,33
218.24578,-3.86488,-48.29112,3.83861,48.29112,22476,33
218.73580,-4.35486,-58.44618,4.32860,58.44617,22476,33
219.14080,-4.75968,-66.86342,4.73342,66.86342,22476,33
219.41480,-4.78048,-66.25018,4.75422,66.25018,22476,33
219.72380,-4.45845,-57.73968,4.43219,57.73968,22412,33
220.01419,-4.16665,-50.49533,4.14039,50.49533,22412,33
220.46180,-3.71852,-40.25777,3.69226,40.25777,22412,33
220.85778,-3.32268,-31.73922,3.29642,31.73922,22412,33
221.26078,-2.91944,-24.11751,2.89318,24.11751,22412,33
221.79380,-2.38647,-16.03635,2.36021,16.03635,22412,33
222.36280,-1.81756,-8.57487,1.79130,8.57487,22412,33
222.85180,-2.10186,-14.04837,2.07560,14.04837,22476,33
223.41680,-2.66960,-23.55475,2.64334,23.55475,22476,34
223.77680,-3.02966,-30.55321,3.00340,30.55321,22476,34
223.96778,-3.22082,-34.66668,3.19456,34.66668,22476,34
224.11420,-3.36678,-37.73439,3.34052,37.73439,22476,34
224.31380,-3.56660,-41.86793,3.54033,41.86794,22476,34
224.54780,-3.80076,-46.89807,3.77450,46.89807,22476,34
224.84980,-4.10260,-53.20670,4.07634,53.20670,22476,34
225.06580,-4.31882,-57.69849,4.29256,57.69849,22476,34
225.23580,-4.48862,-61.27039,4.46236,61.27039,22476,34
225.50580,-4.75868,-66.87281,4.73242,66.87281,22476,34
225.70980,-4.87588,-68.99017,4.84962,68.99017,22476,34
225.98580,-4.57643,-60.79530,4.55017,60.79530,22412,34
226.18480,-4.37462,-55.65843,4.34836,55.65843,22412,34
226.43080,-4.12760,-49.51411,4.10134,49.51411,22412,34
226.67080,-3.88761,-44.01798,3.86135,44.01798,22412,34
226.94080,-3.61746,-38.14282,3.59120,38.14282,22412,34
227.29780,-3.26064,-30.45893,3.23438,30.45893,22412,34
227.76278,-2.79544,-22.02746,2.76918,22.02746,22412,34
228.40980,-2.14843,-12.87678,2.12217,12.87678,22412,34
228.93180,-1.81195,-9.11546,1.78568,9.11546,22412,34
229.51419,-2.41226,-19.10059,2.38600,19.10059,22476,35
229.92780,-2.82666,-26.37940,2.80040,26.37940,22476,35
230.29980,-3.19868,-34.21830,3.17242,34.21830,22476,35
230.52378,-3.42259,-38.84521,3.39633,38.84521,22476,35
230.75380,-3.65273,-43.76110,3.62647,43.76110,22476,35
230.89780,-3.79673,-46.92508,3.77047,46.92508,22476,35
231.18680,-4.08556,-52.77787,4.05930,52.77787,22476,35
231.50980,-4.40874,-59.49152,4.38247,59.49152,22476,35
231.68978,-4.58854,-63.32654,4.56228,63.32654,22476,35
231.95478,-4.85369,-68.83992,4.82743,68.83991,22476,35
232.21419,-4.70584,-64.22734,4.67958,64.22734,22476,35
232.41420,-4.49891,-58.75891,4.47265,58.75891,22412,35
232.63480,-4.27611,-53.16492,4.24985,53.16492,22412,35
232.85880,-4.05149,-47.76799,4.02523,47.76799,22412,35
233.04980,-3.86074,-43.42444,3.83448,43.42444,22412,35
233.26980,-3.64049,-38.65889,3.61422,38.65889,22412,35
233.42380,-3.48651,-35.24342,3.46024,35.24342,22412,35
233.68180,-3.22871,-29.84931,3.20245,29.84931,22412,35
234.05178,-2.85858,-23.09738,2.83232,23.09739,22412,35
234.53678,-2.37359,-15.79506,2.34733,15.79506,22412,35
235.16280,-1.74760,-7.43910,1.72134,7.43910,22412,35
235.62078,-2.15772,-15.03018,2.13146,15.03018,22476,35
236.20180,-2.74082,-24.81967,2.71456,24.81967,22476,36
236.48080,-3.01975,-30.29857,2.99349,30.29857,22476,36
236.78580,-3.32490,-36.74520,3.29864,36.74520,22476,36
237.15078,-3.68982,-44.49696,3.66356,44.49696,22476,36
237.51419,-4.05269,-52.16792,4.02643,52.16792,22476,36
237.91420,-4.45279,-60.42667,4.42653,60.42667,22476,36
238.21419,-4.75280,-66.67747,4.72654,66.67747,22476,36
238.51580,-4.78271,-66.25190,4.75645,66.25190,22476,36
238.80580,-4.48062,-58.24148,4.45436,58.24148,22412,36
239.12780,-4.15666,-50.25981,4.13040,50.25982,22412,36
239.38980,-3.89465,-44.06444,3.86838,44.06444,22412,36
239.64380,-3.64049,-38.56479,3.61423,38.56479,22412,36
239.84180,-3.44250,-34.22129,3.41624,34.22129,22412,36
240.06478,-3.21969,-29.64041,3.19343,29.64041,22412,36
240.42380,-2.86058,-23.04463,2.83432,23.04463,22412,36
241.07978,-2.20464,-13.57614,2.17838,13.57614,22412,36
241.63280,-1.77161,-8.32809,1.74535,8.32809,22412,36
242.17580,-2.33817,-17.86343,2.31191,17.86343,22476,36
242.67080,-2.83373,-26.47030,2.80747,26.47030,22476,37
243.07880,-3.24192,-35.00928,3.21566,35.00928,22476,37
243.51419,-3.67675,-44.16702,3.65049,44.16702,22476,37
243.90180,-4.06460,-52.38167,4.03834,52.38167,22476,37
244.28580,-4.44873,-60.34553,4.42247,60.34553,22476,37
244.74778,-4.90459,-69.88087,4.87833,69.88087,22476,37
245.08580,-4.55806,-60.24443,4.53180,60.24443,22412,37
245.45980,-4.18076,-50.82365,4.15450,50.82365,22412,37
245.83080,-3.80962,-42.21395,3.78336,42.21395,22412,37
246.26780,-3.37259,-32.75487,3.34633,32.75487,22412,37
246.74778,-2.89251,-23.55998,2.86625,23.55998,22412,37
247.41378,-2.22665,-13.81009,2.20039,13.81009,22412,37
247.93880,-1.75240,-7.71997,1.72614,7.71997,22412,37
248.50280,-2.34519,-17.88170,2.31893,17.88170,22604,37
249.04380,-2.88682,-27.43940,2.86055,27.43940,22604,38
249.48780,-3.33087,-36.80018,3.30461,36.80018,22604,38
249.91420,-3.75685,-45.81401,3.73059,45.81401,22604,38
250.41420,-4.25695,-56.43044,4.23069,56.43044,22604,38
250.89080,-4.73384,-66.26310,4.70758,66.26310,22604,38
251.22080,-4.76265,-65.70565,4.73639,65.70565,22604,38
251.54780,-4.42413,-56.80384,4.39787,56.80384,22540,38
251.91420,-4.05664,-47.88380,4.03038,47.88380,22540,38
252.32180,-3.64861,-38.70641,3.62235,38.70641,22540,38
252.61420,-3.35682,-32.41946,3.33056,32.41946,22540,38
252.95780,-3.01259,-25.68458,2.98633,25.68458,22540,38
253.51419,-2.45663,-16.92145,2.43037,16.92145,22540,38
254.14580,-1.82477,-8.53708,1.79851,8.53708,22540,38
254.66578,-2.16068,-14.93742,2.13442,14.93742,22604,38
255.22280,-2.71986,-24.34545,2.69360,24.34545,22604,39
255.61420,-3.11071,-32.09709,3.08445,32.09709,22604,39
256.04581,-3.54270,-41.25671,3.51644,41.25671,22604,39
256.49578,-3.99283,-50.84763,3.96657,50.84763,22604,39
256.80881,-4.30598,-57.38236,4.27972,57.38236,22604,39
257.11420,-4.61078,-63.69028,4.58451,63.69028,22604,39
257.35880,-4.85586,-68.82376,4.82960,68.82376,22604,39
257.65180,-4.65757,-62.93681,4.63131,62.93681,22604,39
257.93078,-4.37283,-55.56485,4.34657,55.56485,22540,39
258.25681,-4.04559,-47.61590,4.01933,47.61591,22540,39
258.49578,-3.80670,-42.19583,3.78044,42.19583,22540,39
258.69980,-3.60263,-37.60854,3.57637,37.60854,22540,39
258.84778,-3.45463,-34.55630,3.42836,34.55630,22540,39
259.10380,-3.19870,-29.17999,3.17244,29.17999,22540,39
259.53281,-2.76964,-21.56039,2.74338,21.56039,22540,39
260.10278,-2.19973,-13.41842,2.17347,13.41842,22540,39
260.54780,-1.75467,-7.47439,1.72841,7.47439,22540,39
261.00681,-1.73979,-7.86657,1.71353,7.86657,22540,39
261.51419,-2.25904,-16.73317,2.23278,16.73317,22476,39
262.00281,-2.74847,-25.07844,2.72221,25.07844,22476,40
262.38278,-3.12834,-32.60453,3.10208,32.60453,22476,40
262.65578,-3.40143,-38.45438,3.37516,38.45438,22476,40
262.97478,-3.72052,-45.14512,3.69426,45.14511,22476,40
263.21978,-3.96550,-50.38217,3.93924,50.38218,22476,40
263.62178,-4.36759,-58.69869,4.34133,58.69869,22476,40
263.91678,-4.66245,-64.90568,4.63619,64.90568,22476,40
264.24578,-4.84278,-67.96887,4.81652,67.96886,22476,40
264.57378,-4.49566,-58.69629,4.46940,58.69629,22412,40
264.85981,-4.20772,-51.46072,4.18146,51.46072,22412,40
265.19681,-3.87051,-43.49010,3.84425,43.49010,22412,40
265.53378,-3.53315,-36.16164,3.50689,36.16164,22412,40
265.93781,-3.12918,-27.75256,3.10292,27.75256,22412,40
266.39081,-2.67624,-20.03059,2.64998,20.03059,22412,40
267.05178,-2.01525,-11.17700,1.98899,11.17700,22412,40
267.51419,-1.90233,-10.74031,1.87607,10.74031,22412,40
268.10481,-2.50421,-20.46172,2.47795,20.46172,22476,41
268.57378,-2.97348,-29.24641,2.94722,29.24641,22476,41
269.01419,-3.41344,-38.63151,3.38718,38.63152,22476,41
269.44981,-3.84967,-47.90322,3.82341,47.90322,22476,41
269.85678,-4.25667,-56.38492,4.23041,56.38493,22476,41
270.19078,-4.59038,-63.29411,4.56412,63.29411,22476,41
270.51278,-4.90564,-69.86886,4.87938,69.86886,22476,41
270.81419,-4.59599,-61.27885,4.56973,61.27885,22412,41
271.09078,-4.31520,-54.10295,4.28894,54.10295,22412,41
271.41278,-3.99248,-46.30591,3.96621,46.30591,22412,41
271.63581,-3.76936,-41.28351,3.74310,41.28352,22412,41
271.94478,-3.46034,-34.59287,3.43408,34.59287,22412,41
272.21419,-3.19137,-28.99886,3.16511,28.99887,22412,41
272.69378,-2.71135,-20.56460,2.68509,20.56460,22412,41
273.31419,-2.09140,-12.13544,2.06514,12.13544,22412,41
273.79581,-1.86059,-9.98342,1.83433,9.98342,22412,41
274.33781,-2.41714,-19.02164,2.39088,19.02164,22476,42
274.80578,-2.88567,-27.31553,2.85941,27.31553,22476,42
275.01981,-3.09947,-31.74772,3.07321,31.74772,22476,42
275.32378,-3.40359,-38.38500,3.37732,38.38499,22476,42
275.65878,-3.73870,-45.37413,3.71244,45.37413,22476,42
275.98881,-4.06849,-52.40109,4.04223,52.40109,22476,42
276.41981,-4.49954,-61.39127,4.47328,61.39127,22476,42
276.80381,-4.88358,-69.38260,4.85732,69.38260,22476,42
277.07081,-4.66970,-63.20536,4.64344,63.20536,22476,42
277.44681,-4.28710,-53.27883,4.26084,53.27883,22412,42
277.73981,-3.99359,-46.22447,3.96733,46.22447,22412,42
278.01678,-3.71652,-39.99799,3.69026,39.99799,22412,42
278.33978,-3.39348,-33.19659,3.36722,33.19659,22412,42
278.65978,-3.07330,-26.64704,3.04704,26.64705,22412,42
279.21419,-2.51932,-17.76568,2.49306,17.76568,22412,42
279.82581,-1.90751,-9.59721,1.88125,9.59721,22412,42
280.33881,-2.10718,-13.93366,2.08092,13.93366,22476,42
280.91419,-2.68559,-23.61278,2.65933,23.61278,22476,43
281.29981,-3.07150,-31.12941,3.04524,31.12941,22476,43
281.61419,-3.38567,-37.89954,3.35940,37.89954,22476,43
282.03978,-3.81173,-47.01149,3.78547,47.01149,22476,43
282.41581,-4.18762,-54.82933,4.16136,54.82933,22476,43
282.82181,-4.59352,-63.30744,4.56726,63.30744,22476,43
283.08178,-4.85365,-68.74199,4.82739,68.74199,22476,43
283.38878,-4.65510,-62.81744,4.62884,62.81744,22412,43
283.75978,-4.27807,-53.09147,4.25181,53.09146,22412,43
284.06478,-3.97260,-45.74274,3.94634,45.74274,22412,43
284.47581,-3.56138,-36.70058,3.53512,36.70058,22412,43
284.91419,-3.12336,-27.52212,3.09709,27.52212,22412,43
285.51419,-2.52333,-17.81367,2.49707,17.81367,22412,43
286.20481,-1.83261,-8.55775,1.80635,8.55775,22412,43
286.71419,-2.14934,-14.67671,2.12308,14.67671,22476,43
287.29278,-2.73070,-24.41548,2.70444,24.41548,22476,44
287.78478,-3.22281,-34.41381,3.19654,34.41381,22476,44
288.17481,-3.61272,-42.71764,3.58646,42.71764,22476,44
288.61419,-4.05157,-52.03379,4.02531,52.03379,22476,44
289.01419,-4.45162,-60.40954,4.42536,60.40954,22476,44
289.46478,-4.90109,-69.74524,4.87483,69.74524,22476,44
289.79278,-4.57868,-60.81402,4.55242,60.81401,22412,44
290.06778,-4.30028,-53.69789,4.27402,53.69789,22412,44
290.41419,-3.95368,-45.19837,3.92742,45.19837,22412,44
290.74078,-3.62650,-38.15360,3.60024,38.15359,22412,44
291.14178,-3.22573,-29.60552,3.19946,29.60552,22412,44
291.56378,-2.80352,-22.03563,2.77726,22.03563,22412,44
292.21419,-2.15348,-12.80204,2.12722,12.80204,22412,44
292.80578,-1.90444,-10.64158,1.87817,10.64158,22412,44
293.37078,-2.48052,-19.93906,2.45426,19.93906,22476,45
293.84378,-2.95384,-28.69274,2.92758,28.69274,22476,45
294.31419,-3.42373,-38.70184,3.39747,38.70184,22476,45
294.64778,-3.75789,-45.72224,3.73163,45.72224,22476,45
295.09878,-4.20889,-55.30713,4.18263,55.30714,22476,45
295.51378,-4.62380,-63.95064,4.59754,63.95064,22476,45
295.91778,-4.80623,-66.86711,4.77997,66.86711,22476,45
296.21419,-4.49599,-58.58247,4.46972,58.58247,22412,45
296.60181,-4.10576,-48.90769,4.07950,48.90769,22412,45
297.01578,-3.69164,-39.51835,3.66538,39.51834,22412,45
297.40378,-3.30380,-31.11130,3.27754,31.11130,22412,45
297.91419,-2.79360,-21.85591,2.76734,21.85591,22412,45
298.51419,-2.19372,-13.25879,2.16746,13.25879,22412,45
299.06281,-1.81734,-8.98947,1.79108,8.98947,22412,45
299.55978,-2.33325,-17.60289,2.30699,17.60288,22476,45
300.01278,-2.78687,-25.45452,2.76061,25.45452,22476,46
300.41419,-3.18789,-33.66257,3.16163,33.66257,22476,46
300.78778,-3.56178,-41.50137,3.53552,41.50137,22476,46
301.05178,-3.82605,-47.30543,3.79979,47.30543,22476,46
301.32481,-4.09884,-52.92144,4.07258,52.92144,22476,46
301.65178,-4.42585,-59.77110,4.39959,59.77110,22476,46
301.98981,-4.76390,-66.85997,4.73764,66.85997,22476,46
302.25281,-4.78424,-66.31216,4.75798,66.31216,22476,46
302.61419,-4.40911,-56.43184,4.38284,56.43184,22412,46
302.92578,-4.09583,-48.71399,4.06957,48.71399,22412,46
303.21178,-3.80982,-42.04817,3.78356,42.04817,22412,46
303.51419,-3.50762,-35.43434,3.48136,35.43434,22412,46
303.81281,-3.20882,-29.28540,3.18256,29.28540,22412,46
304.31419,-2.70772,-20.46043,2.68146,20.46043,22412,46
305.01178,-2.00968,-10.95129,1.98341,10.95129,22412,46
305.54378,-1.98931,-12.09767,1.96304,12.09767,22412,46
306.11481,-2.56671,-21.47670,2.54045,21.47670,22476,47
306.60678,-3.05883,-30.84644,3.03257,30.84645,22476,47
306.87778,-3.33006,-36.62963,3.30380,36.62963,22476,47
307.24878,-3.70100,-44.43342,3.67474,44.43342,22476,47
307.48981,-3.94199,-49.61379,3.91573,49.61379,22476,47
307.92178,-4.37409,-58.70247,4.34783,58.70247,22476,47
308.19678,-4.64892,-64.45363,4.62266,64.45363,22476,47
308.50581,-4.89486,-69.41578,4.86860,69.41578,22476,47
308.78378,-4.59195,-61.05172,4.56569,61.05172,22412,47
309.09378,-4.27824,-53.14674,4.25198,53.14674,22412,47
309.48278,-3.88882,-43.78034,3.86256,43.78034,22412,47
309.83078,-3.54056,-36.11589,3.51430,36.11589,22412,47
310.21419,-3.15755,-28.17562,3.13129,28.17562,22412,47
310.68781,-2.68366,-20.07502,2.65740,20.07502,22412,47
311.27478,-2.09672,-12.09176,2.07046,12.09176,22412,47
311.81419,-1.91300,-10.73695,1.88674,10.73695,22412,47
312.34181,-2.45157,-19.46957,2.42531,19.46957,22604,47
312.81078,-2.92098,-27.92155,2.89472,27.92155,22604,48
313.11419,-3.22407,-34.42175,3.19781,34.42175,22604,48
313.44778,-3.55785,-41.45571,3.53159,41.45571,22604,48
313.81419,-3.92401,-49.22530,3.89775,49.22530,22604,48
314.16678,-4.27713,-56.66915,4.25087,56.66915,22604,48
314.53478,-4.64496,-64.40153,4.61870,64.40153,22604,48
314.88278,-4.83776,-67.70689,4.81150,67.70689,22604,48
315.20081,-4.50125,-58.73426,4.47499,58.73426,22540,48
315.51778,-4.18207,-50.78993,4.15581,50.78992,22540,48
315.81378,-3.88595,-43.73436,3.85969,43.73436,22540,48
316.01419,-3.68584,-39.35659,3.65957,39.35659,22540,48
316.25778,-3.44179,-34.11027,3.41553,34.11027,22540,48
316.57378,-3.12569,-27.48342,3.09943,27.48342,22540,48
316.98378,-2.71584,-20.58449,2.68958,20.58449,22540,48
317.41581,-2.28389,-14.39761,2.25763,14.39761,22540,48
318.00681,-1.75806,-7.68780,1.73180,7.68780,22540,48
318.51419,-2.29322,-16.89315,2.26696,16.89315,22604,48
318.90681,-2.68700,-23.57904,2.66074,23.57904,22604,49
319.27381,-3.05395,-30.74932,3.02769,30.74932,22604,49
319.56078,-3.34116,-36.83012,3.31490,36.83012,22604,49
319.80781,-3.58799,-42.08796,3.56173,42.08796,22604,49
320.01419,-3.79411,-46.50805,3.76785,46.50805,22604,49
320.38278,-4.16304,-54.25707,4.13678,54.25706,22604,49
320.63081,-4.41108,-59.49028,4.38481,59.49028,22604,49
320.96878,-4.74909,-66.55133,4.72283,66.55133,22604,49
321.27781,-4.76732,-65.73095,4.74106,65.73095,22604,49
321.59281,-4.44060,-57.16933,4.41434,57.16933,22540,49
321.83178,-4.20024,-51.19546,4.17397,51.19546,22540,49
322.12778,-3.90400,-44.01712,3.87774,44.01712,22540,49
322.41419,-3.61786,-37.87197,3.59160,37.87197,22540,49
322.81419,-3.21803,-29.42086,3.19177,29.42086,22540,49
323.31478,-2.71690,-20.56655,2.69064,20.56655,22540,49
323.97581,-2.05581,-11.49219,2.02955,11.49219,22540,49
324.51419,-1.74047,-7.50195,1.71421,7.50195,22540,49
325.13081,-2.22850,-16.09405,2.20223,16.09405,22476,49
325.61419,-2.71221,-24.16807,2.68595,24.16807,22476,50
325.97078,-3.06902,-31.08748,3.04276,31.08748,22476,50
326.20778,-3.30627,-36.12350,3.28001,36.12350,22476,50
326.41419,-3.51205,-40.51293,3.48578,40.51293,22476,50
326.64978,-3.74825,-45.53021,3.72199,45.53021,22476,50
326.86978,-3.96819,-50.22935,3.94193,50.22935,22476,50
327.08381,-4.18212,-54.74200,4.15586,54.74200,22476,50
327.35981,-4.45815,-60.50387,4.43189,60.50387,22476,50
327.58178,-4.68013,-65.24245,4.65387,65.24245,22476,50
327.83881,-4.89614,-69.51341,4.86988,69.51341,22476,50
328.03281,-4.68106,-63.50682,4.65480,63.50682,22476,50
328.23678,-4.47115,-57.96598,4.44489,57.96598,22412,50
328.44278,-4.26358,-52.82885,4.23732,52.82885,22412,50
328.60981,-4.09616,-48.70895,4.06990,48.70895,22412,50
328.84378,-3.86219,-43.12343,3.83593,43.12343,22412,50
329.03078,-3.67500,-39.08293,3.64874,39.08293,22412,50
329.28378,-3.42196,-33.68821,3.39570,33.68821,22412,50
329.62281,-3.08289,-26.77164,3.05663,26.77164,22412,50
330.16478,-2.54086,-18.03600,2.51460,18.03600,22412,50
330.83781,-1.86814,-8.98419,1.84188,8.98419,22412,50
331.36781,-2.14377,-14.46037,2.11751,14.46037,22476,50
331.90781,-2.68623,-23.53295,2.65997,23.53295,22476,51
332.35278,-3.13120,-32.33959,3.10493,32.33959,22476,51
332.70278,-3.48119,-39.78147,3.45493,39.78147,22476,51
333.01278,-3.79134,-46.49013,3.76508,46.49013,22476,51
333.28878,-4.06715,-52.28883,4.04088,52.28883,22476,51
333.62978,-4.40833,-59.37859,4.38207,59.37859,22476,51
333.93781,-4.71634,-65.86477,4.69008,65.86477,22476,51
334.24578,-4.80693,-66.87600,4.78066,66.87600,22476,51
334.63478,-4.40239,-56.24486,4.37613,56.24486,22412,51
334.92678,-4.10923,-48.98104,4.08297,48.98104,22412,51
335.26981,-3.76611,-40.98604,3.73985,40.98604,22412,51
335.59578,-3.44006,-34.11896,3.41380,34.11896,22412,51
336.04678,-2.98907,-25.07920,2.96281,25.07920,22412,51
336.61419,-2.42206,-16.33685,2.39579,16.33685,22412,51
337.27178,-1.76415,-7.42793,1.73789,7.42793,22412,51
337.81419,-2.26334,-16.40283,2.23708,16.40283,22476,51
338.31419,-2.76436,-24.95571,2.73810,24.95571,22476,52
338.65478,-3.10524,-31.70905,3.07898,31.70905,22476,52
338.98378,-3.43426,-38.83332,3.40800,38.83332,22476,52
339.31419,-3.76442,-45.80043,3.73816,45.80043,22476,52
339.66981,-4.12033,-53.31513,4.09407,53.31513,22476,52
340.02781,-4.47837,-60.89097,4.45211,60.89097,22476,52
340.45978,-4.90558,-69.81144,4.87932,69.81144,22476,52
340.80381,-4.55570,-60.17717,4.52944,60.17717,22412,52
341.11419,-4.24272,-52.25478,4.21646,52.25478,22412,52
341.45778,-3.89832,-43.88770,3.87206,43.88770,22412,52
341.81578,-3.54006,-36.05257,3.51380,36.05257,22412,52
342.15281,-3.20330,-29.05566,3.17703,29.05566,22412,52
342.57981,-2.77619,-21.53342,2.74993,21.53342,22412,52
343.19181,-2.16416,-12.84147,2.13790,12.84147,22412,52
343.71419,-1.84270,-9.36737,1.81644,9.36737,22412,52
344.27578,-2.42192,-18.93545,2.39566,18.93545,22476,53
344.77278,-2.91943,-27.77408,2.89317,27.77408,22476,53
345.00978,-3.15633,-32.88519,3.13007,32.88519,22476,53
345.31578,-3.46232,-39.38979,3.43606,39.38979,22476,53
345.61881,-3.76547,-45.81691,3.73921,45.81691,22476,53
346.00378,-4.15039,-53.93025,4.12413,53.93024,22476,53
346.40478,-4.55121,-62.41620,4.52495,62.41620,22476,53
346.79178,-4.91112,-69.85433,4.88486,69.85433,22476,53
346.97078,-4.71463,-64.28284,4.68837,64.28284,22476,53
347.30781,-4.36927,-55.35271,4.34301,55.35271,22412,53
347.61278,-4.06315,-47.88928,4.03689,47.88928,22412,53
347.91778,-3.75817,-40.75113,3.73191,40.75113,22412,53
348.21419,-3.46218,-34.45118,3.43592,34.45118,22412,53
348.49281,-3.18313,-28.58232,3.15687,28.58232,22412,53
349.03078,-2.64509,-19.40816,2.61883,19.40816,22412,53
349.64778,-2.02810,-11.09006,2.00184,11.09006,22412,53
350.20178,-2.02652,-12.56225,2.00026,12.56225,22412,53
350.77178,-2.60225,-21.97887,2.57599,21.97887,22476,54
351.23978,-3.07028,-30.95919,3.04402,30.95918,22476,54
351.51419,-3.34450,-36.82551,3.31824,36.82551,22476,54
351.84778,-3.67841,-43.91275,3.65215,43.91275,22476,54
352.21419,-4.04431,-51.76007,4.01805,51.76007,22476,54
352.64978,-4.48039,-60.90587,4.45413,60.90586,22476,54
353.04778,-4.87839,-69.21709,4.85213,69.21709,22476,54
353.38378,-4.59272,-61.11378,4.56646,61.11378,22412,54
353.71419,-4.25870,-52.57788,4.23244,52.57788,22412,54
354.03581,-3.93628,-44.74027,3.91002,44.74027,22412,54
354.31419,-3.65807,-38.64801,3.63181,38.64801,22412,54
354.71681,-3.25531,-30.09127,3.22905,30.09127,22412,54
355.18781,-2.78413,-21.60657,2.75786,21.60657,22412,54
355.84078,-2.13114,-12.45217,2.10487,12.45217,22412,54
356.28778,-1.79096,-8.25683,1.76470,8.25683,22412,54
356.83381,-2.36186,-17.90830,2.33560,17.90830,22476,55
357.31419,-2.84241,-26.35525,2.81615,26.35525,22476,55
357.62578,-3.15432,-32.78472,3.12806,32.78471,22476,55
357.88878,-3.41733,-38.37975,3.39107,38.37975,22476,55
358.24781,-3.77645,-45.99986,3.75019,45.99986,22476,55
358.64578,-4.17439,-54.43389,4.14813,54.43389,22476,55
358.97478,-4.50333,-61.38835,4.47706,61.38836,22476,55
359.35581,-4.88438,-69.34842,4.85812,69.34843,22476,55
359.70578,-4.58030,-60.75511,4.55404,60.75511,22412,55
359.96781,-4.31503,-53.96695,4.28877,53.96695,22412,55
360.36381,-3.91828,-44.24191,3.89202,44.24191,22412,55
360.71419,-3.56811,-36.61748,3.54185,36.61748,22412,55
361.11978,-3.16205,-28.17309,3.13579,28.17309,22412,55
361.61419,-2.66813,-19.74005,2.64187,19.74005,22412,55
362.30178,-1.98024,-10.45201,1.95398,10.45201,22412,55
362.76178,-1.99076,-11.94834,1.96450,11.94834,22412,55
363.34281,-2.57912,-21.53648,2.55286,21.53647,22476,56
363.78681,-3.02331,-29.97839,2.99705,29.97839,22476,56
364.18281,-3.41927,-38.41362,3.39301,38.41362,22476,56
364.49978,-3.73647,-45.06241,3.71021,45.06241,22476,56
364.85581,-4.09227,-52.65410,4.06601,52.65410,22476,56
365.22078,-4.45733,-60.40568,4.43107,60.40568,22476,56
365.64278,-4.87935,-69.26519,4.85309,69.26519,22476,56
365.95678,-4.61441,-61.69038,4.58815,61.69038,22412,56
366.36381,-4.20253,-51.26539,4.17627,51.26538,22412,56
366.71781,-3.84836,-42.74558,3.82210,42.74558,22412,56
367.11881,-3.44713,-34.11198,3.42087,34.11198,22412,56
367.63581,-2.93015,-23.99919,2.90389,23.99919,22412,56
368.21419,-2.35231,-15.25601,2.32605,15.25601,22412,56
368.85178,-1.74991,-7.25304,1.72365,7.25304,22412,56
369.41419,-2.33974,-17.50680,2.31348,17.50680,22476,56
369.94878,-2.87543,-26.88895,2.84917,26.88895,22476,57
370.41778,-3.34449,-36.77053,3.31823,36.77053,22476,57
370.86781,-3.79443,-46.42120,3.76817,46.42120,22476,57
371.21978,-4.14638,-53.77657,4.12012,53.77657,22476,57
371.57778,-4.50431,-61.37379,4.47805,61.37379,22476,57
371.91419,-4.84042,-68.42532,4.81416,68.42532,22476,57
372.24178,-4.65467,-62.70256,4.62841,62.70256,22476,57
372.46578,-4.42569,-56.72999,4.39943,56.73000,22412,57
372.74781,-4.14236,-49.69134,4.11610,49.69134,22412,57
372.98278,-3.90728,-44.03941,3.88102,44.03941,22412,57
373.26081,-3.62918,-38.00915,3.60292,38.00915,22412,57
373.57981,-3.31037,-31.07100,3.28411,31.07100,22412,57
374.11419,-2.77621,-21.42533,2.74995,21.42533,22412,57
374.67278,-2.21735,-13.49008,2.19109,13.49008,22412,57
375.22478,-1.79856,-8.44431,1.77230,8.44431,22412,57
375.73378,-2.32971,-17.35700,2.30345,17.35700,22604,57
376.30478,-2.90146,-27.40658,2.87520,27.40658,22604,58
376.72278,-3.31951,-36.21028,3.29325,36.21029,22604,58
377.17178,-3.76846,-45.79243,3.74220,45.79243,22604,58
377.57481,-4.17140,-54.33157,4.14514,54.33157,22604,58
378.01419,-4.61036,-63.62516,4.58410,63.62516,22604,58
378.35378,-4.88532,-69.08763,4.85905,69.08763,22604,58
378.67178,-4.54136,-59.75866,4.51510,59.75866,22540,58
379.02978,-4.18043,-50.69040,4.15417,50.69040,22540,58
379.43781,-3.77221,-40.99539,3.74595,40.99538,22540,58
379.84378,-3.36632,-32.29484,3.34006,32.29484,22540,58
380.31419,-2.89621,-23.36636,2.86994,23.36636,22540,58
380.95481,-2.25534,-13.93670,2.22908,13.93670,22540,58
381.51378,-1.79189,-8.17030,1.76563,8.17031,22540,58
382.06681,-2.37090,-18.03135,2.34464,18.03135,22604,58
382.51419,-2.81841,-25.92531,2.79215,25.92531,22604,59
382.90178,-3.20646,-33.86782,3.18020,33.86782,22604,59
383.30878,-3.61346,-42.47895,3.58720,42.47895,22604,59
383.73081,-4.03538,-51.46481,4.00912,51.46481,22604,59
384.06078,-4.36558,-58.39980,4.33932,58.39980,22604,59
384.39778,-4.70245,-65.55092,4.67619,65.55093,22604,59
384.69581,-4.81709,-67.13805,4.79083,67.13805,22604,59
385.06778,-4.42785,-56.84991,4.40159,56.84991,22540,59
385.41778,-4.07625,-48.21897,4.04999,48.21896,22540,59
385.83381,-3.66013,-38.70470,3.63387,38.70470,22540,59
386.11678,-3.37725,-32.55994,3.35099,32.55994,22540,59
386.61419,-2.88022,-23.12940,2.85396,23.12940,22540,59
387.23578,-2.25832,-13.97851,2.23205,13.97851,22540,59
387.71978,-1.77419,-7.46752,1.74793,7.46752,22540,59