File: data-raw/Experiment 2/Results/INSTRON data/Experiment 2.is_ccyclic_RawData/Specimen_RawData_3.csv
Text Inputs : Specimen label,"Short Plate 1 Test 1"

Time,Extension,Load,Compressive extension,Compressive load,Segment ID,Total Cycle Count
(sec),(mm),(N),(mm),(N),,
0.00000,-0.02542,0.08190,0.00000,-0.08190,12835,0
0.81120,-0.02542,0.06882,0.00000,-0.06882,12835,0
1.71120,-0.33134,0.03911,0.30592,-0.03911,3220,0
2.31120,-0.63145,0.06873,0.60603,-0.06873,3220,0
3.51120,-1.23162,0.02589,1.20620,-0.02589,3220,0
4.31120,-1.63141,-5.88523,1.60599,5.88523,3220,0
4.81120,-2.08630,-13.82324,2.06088,13.82324,22476,0
5.32480,-2.60081,-22.00931,2.57539,22.00931,22476,0
5.81120,-3.08687,-30.92681,3.06145,30.92681,22476,0
6.21380,-3.48991,-39.28401,3.46449,39.28401,22476,0
6.61120,-3.88719,-47.54367,3.86176,47.54367,22476,0
7.05980,-4.33607,-56.50495,4.31065,56.50495,22476,0
7.51120,-4.78707,-65.52601,4.76165,65.52601,22476,0
7.81120,-4.95115,-67.26767,4.92573,67.26767,22476,0
8.08880,-4.65415,-57.38240,4.62873,57.38240,22412,0
8.40080,-4.33926,-48.07896,4.31384,48.07896,22412,0
8.64080,-4.09877,-41.27287,4.07335,41.27287,22412,0
8.94080,-3.79892,-33.93304,3.77350,33.93304,22412,0
9.36080,-3.37888,-24.77800,3.35345,24.77800,22412,0
9.84180,-2.89783,-16.91917,2.87241,16.91917,22412,0
10.44080,-2.29878,-8.95369,2.27336,8.95369,22412,0
10.85780,-2.44632,-13.57669,2.42090,13.57669,22476,0
11.31120,-2.90469,-22.14726,2.87927,22.14726,22476,1
11.69880,-3.29279,-30.40721,3.26737,30.40722,22476,1
12.09980,-3.69393,-39.51416,3.66851,39.51416,22476,1
12.41120,-4.00482,-46.55970,3.97940,46.55970,22476,1
12.78980,-4.38401,-54.80536,4.35859,54.80536,22476,1
13.16780,-4.76189,-63.02189,4.73647,63.02189,22476,1
13.49880,-5.08213,-69.71797,5.05670,69.71796,22476,1
13.73480,-4.83557,-61.02722,4.81015,61.02722,22476,1
14.01120,-4.55354,-52.27429,4.52811,52.27430,22412,1
14.33480,-4.22861,-42.88837,4.20319,42.88837,22412,1
14.63580,-3.92757,-35.22367,3.90215,35.22367,22412,1
15.01120,-3.55231,-26.76408,3.52689,26.76408,22412,1
15.45580,-3.10750,-19.10761,3.08208,19.10761,22412,1
16.00980,-2.55340,-11.56620,2.52798,11.56620,22412,1
16.41180,-2.30048,-9.31027,2.27506,9.31027,22412,1
16.86180,-2.77074,-18.50676,2.74532,18.50676,22476,1
17.25980,-3.16970,-26.39031,3.14428,26.39031,22476,2
17.61280,-3.52263,-34.48848,3.49721,34.48848,22476,2
17.91120,-3.82088,-41.17178,3.79545,41.17178,22476,2
18.27980,-4.18973,-49.50323,4.16431,49.50323,22476,2
18.61120,-4.52071,-56.80864,4.49529,56.80864,22476,2
18.98080,-4.89083,-64.98324,4.86541,64.98324,22476,2
19.24180,-5.10253,-69.08018,5.07711,69.08018,22476,2
19.43380,-4.88947,-61.62954,4.86405,61.62954,22476,2
19.65980,-4.65705,-54.30705,4.63163,54.30705,22412,2
19.91120,-4.40477,-47.02836,4.37935,47.02836,22412,2
20.12380,-4.19134,-40.82661,4.16592,40.82661,22412,2
20.40680,-3.90847,-34.01262,3.88305,34.01262,22412,2
20.61180,-3.70331,-29.28281,3.67789,29.28281,22412,2
20.89080,-3.42432,-23.68556,3.39890,23.68556,22412,2
21.23580,-3.07925,-18.20514,3.05383,18.20514,22412,2
21.79380,-2.52133,-10.64153,2.49591,10.64153,22412,2
22.21680,-2.43502,-11.58878,2.40960,11.58878,22412,2
22.69180,-2.92111,-20.57934,2.89569,20.57934,22476,3
23.07280,-3.30246,-28.55028,3.27704,28.55028,22476,3
23.41580,-3.64556,-36.46737,3.62014,36.46737,22476,3
23.71120,-3.94056,-43.30302,3.91514,43.30302,22476,3
23.99780,-4.22761,-49.69415,4.20219,49.69415,22476,3
24.21480,-4.44462,-54.47068,4.41920,54.47068,22476,3
24.55080,-4.78061,-61.93792,4.75519,61.93792,22476,3
24.78280,-5.01244,-66.98605,4.98702,66.98605,22476,3
24.99080,-5.07372,-67.01849,5.04830,67.01849,22476,3
25.21120,-4.83727,-59.15954,4.81185,59.15954,22412,3
25.46480,-4.57909,-51.32330,4.55367,51.32330,22412,3
25.75680,-4.28647,-42.79247,4.26104,42.79247,22412,3
26.01120,-4.03227,-36.34979,4.00685,36.34979,22412,3
26.26980,-3.77343,-30.29883,3.74801,30.29883,22412,3
26.68780,-3.35537,-22.17628,3.32995,22.17628,22412,3
27.23380,-2.80933,-14.04914,2.78391,14.04914,22412,3
27.78880,-2.30538,-7.75877,2.27996,7.75877,22412,3
28.20780,-2.75182,-17.00988,2.72640,17.00988,22476,3
28.63580,-3.18147,-25.45632,3.15604,25.45632,22476,4
29.00780,-3.55338,-33.90653,3.52795,33.90653,22476,4
29.29780,-3.84366,-40.46449,3.81824,40.46449,22476,4
29.50780,-4.05339,-45.26086,4.02797,45.26086,22476,4
29.83480,-4.38064,-52.61503,4.35522,52.61503,22476,4
30.12380,-4.66946,-58.97194,4.64404,58.97194,22476,4
30.41280,-4.95847,-65.43095,4.93305,65.43095,22476,4
30.67780,-5.10994,-67.68181,5.08452,67.68181,22476,4
30.95380,-4.81312,-57.83759,4.78769,57.83759,22412,4
31.23580,-4.52792,-49.28256,4.50250,49.28256,22412,4
31.52580,-4.23743,-40.96812,4.21201,40.96812,22412,4
31.84280,-3.92043,-33.24970,3.89501,33.24970,22412,4
32.27480,-3.48830,-24.15932,3.46288,24.15932,22412,4
32.81120,-2.95226,-15.74900,2.92684,15.74900,22412,4
33.38780,-2.37540,-8.10600,2.34998,8.10600,22412,4
33.74880,-2.60931,-14.00250,2.58389,14.00250,22476,4
34.21120,-3.07612,-22.84771,3.05070,22.84771,22476,5
34.61120,-3.47631,-31.57797,3.45089,31.57797,22476,5
34.97280,-3.83858,-39.97999,3.81316,39.97999,22476,5
35.29680,-4.16249,-47.53193,4.13707,47.53193,22476,5
35.70180,-4.56736,-56.40185,4.54194,56.40184,22476,5
36.10780,-4.97342,-65.40342,4.94800,65.40343,22476,5
36.34280,-5.16161,-69.19048,5.13619,69.19048,22476,5
36.52780,-4.95575,-62.01902,4.93033,62.01902,22476,5
36.71120,-4.76688,-55.93956,4.74145,55.93956,22412,5
36.98480,-4.49077,-47.81553,4.46534,47.81553,22412,5
37.22180,-4.25344,-40.98609,4.22802,40.98609,22412,5
37.52480,-3.95038,-33.62327,3.92496,33.62327,22412,5
37.78680,-3.68823,-27.61771,3.66281,27.61771,22412,5
38.21180,-3.26336,-20.01355,3.23794,20.01355,22412,5
38.81120,-2.66415,-11.79910,2.63872,11.79910,22412,5
39.27980,-2.44232,-10.48271,2.41690,10.48271,22412,5
39.71380,-2.89072,-18.99304,2.86530,18.99304,22476,5
40.11280,-3.29035,-26.97134,3.26493,26.97134,22476,6
40.48080,-3.65851,-35.52402,3.63309,35.52402,22476,6
40.82080,-3.99845,-43.35603,3.97302,43.35603,22476,6
41.22980,-4.40757,-52.56181,4.38215,52.56181,22476,6
41.60180,-4.77956,-60.82587,4.75414,60.82587,22476,6
41.99180,-5.16945,-69.55532,5.14403,69.55532,22476,6
42.22780,-4.98420,-62.46018,4.95878,62.46018,22476,6
42.52280,-4.68147,-52.91208,4.65605,52.91208,22412,6
42.81680,-4.38663,-44.33378,4.36121,44.33378,22412,6
43.18880,-4.01437,-34.78903,3.98895,34.78903,22412,6
43.55980,-3.64334,-26.54360,3.61792,26.54360,22412,6
44.05380,-3.14937,-18.16777,3.12395,18.16777,22412,6
44.66080,-2.54228,-9.96791,2.51686,9.96791,22412,6
45.10080,-2.56069,-12.64067,2.53527,12.64067,22412,6
45.54580,-3.01312,-21.09216,2.98770,21.09216,22476,7
45.96980,-3.43745,-30.11318,3.41203,30.11318,22476,7
46.34680,-3.81469,-38.91481,3.78927,38.91481,22476,7
46.74380,-4.21158,-48.00276,4.18616,48.00276,22476,7
47.11120,-4.57845,-56.14414,4.55303,56.14414,22476,7
47.51120,-4.97845,-64.98778,4.95303,64.98778,22476,7
47.82780,-5.11222,-66.44406,5.08680,66.44406,22476,7
48.11120,-4.81332,-56.70485,4.78790,56.70485,22412,7
48.42680,-4.49482,-47.32508,4.46940,47.32508,22412,7
48.77480,-4.14638,-37.74082,4.12096,37.74082,22412,7
49.16480,-3.75655,-28.64892,3.73113,28.64892,22412,7
49.63780,-3.28339,-20.02634,3.25797,20.02634,22412,7
50.17880,-2.74241,-12.46813,2.71699,12.46813,22412,7
50.65980,-2.42350,-9.35591,2.39808,9.35591,22412,7
51.10680,-2.88969,-18.50094,2.86427,18.50094,22604,7
51.52380,-3.30751,-26.90986,3.28209,26.90986,22604,8
51.89080,-3.67466,-35.35312,3.64923,35.35312,22604,8
52.21880,-4.00262,-42.96742,3.97720,42.96741,22604,8
52.56980,-4.35375,-50.94612,4.32833,50.94613,22604,8
52.93480,-4.71858,-58.97385,4.69316,58.97385,22604,8
53.31180,-5.09539,-67.44740,5.06997,67.44740,22604,8
53.56480,-5.07656,-64.94281,5.05114,64.94282,22604,8
53.81580,-4.81423,-56.49615,4.78881,56.49615,22540,8
54.13380,-4.49387,-47.06734,4.46845,47.06734,22540,8
54.49180,-4.13546,-37.21863,4.11004,37.21864,22540,8
54.83980,-3.78759,-29.13277,3.76217,29.13277,22540,8
55.31120,-3.31647,-20.36138,3.29105,20.36138,22540,8
55.90980,-2.71736,-12.06385,2.69194,12.06385,22540,8
56.37580,-2.45006,-9.85776,2.42464,9.85776,22540,8
56.81120,-2.90181,-18.57751,2.87639,18.57751,22604,8
57.25480,-3.34662,-27.48608,3.32120,27.48608,22604,9
57.63280,-3.72473,-36.32299,3.69931,36.32299,22604,9
58.02980,-4.12165,-45.37644,4.09623,45.37644,22604,9
58.43180,-4.52376,-54.47859,4.49834,54.47859,22604,9
58.81080,-4.90282,-62.94261,4.87740,62.94261,22604,9
59.14280,-5.22003,-69.99247,5.19461,69.99247,22604,9
59.41120,-4.93614,-60.02950,4.91072,60.02950,22540,9
59.71120,-4.63130,-50.69124,4.60588,50.69123,22540,9
60.03680,-4.30466,-41.25882,4.27923,41.25882,22540,9
60.38380,-3.95764,-32.77651,3.93222,32.77651,22540,9
60.81120,-3.53044,-23.86001,3.50502,23.86001,22540,9
61.34580,-2.99553,-15.55880,2.97010,15.55880,22540,9
61.95080,-2.39063,-7.46110,2.36520,7.46110,22540,9
62.60880,-2.61946,-13.65133,2.59404,13.65133,22476,9
63.04980,-3.06386,-21.89206,3.03844,21.89206,22476,9
63.42980,-3.44404,-29.99580,3.41862,29.99580,22476,10
63.70980,-3.72415,-36.40202,3.69873,36.40202,22476,10
64.04580,-4.06006,-44.08273,4.03464,44.08273,22476,10
64.43780,-4.45221,-52.88304,4.42679,52.88304,22476,10
64.81120,-4.82521,-61.24051,4.79979,61.24051,22476,10
65.17580,-5.19016,-69.34480,5.16474,69.34480,22476,10
65.39080,-5.03123,-63.07357,5.00581,63.07357,22476,10
65.63380,-4.78007,-55.16345,4.75465,55.16346,22412,10
65.83980,-4.57236,-48.95207,4.54694,48.95206,22412,10
66.09480,-4.31706,-41.54477,4.29164,41.54477,22412,10
66.38480,-4.02693,-34.37483,4.00150,34.37483,22412,10
66.71120,-3.70088,-27.03049,3.67546,27.03049,22412,10
67.17080,-3.24097,-19.04810,3.21555,19.04810,22412,10
67.71120,-2.70077,-11.67827,2.67535,11.67827,22412,10
68.12080,-2.44219,-9.24559,2.41677,9.24559,22412,10
68.57780,-2.91926,-18.64374,2.89384,18.64374,22476,10
68.96780,-3.31006,-26.46011,3.28464,26.46011,22476,11
69.31580,-3.65822,-34.55727,3.63280,34.55727,22476,11
69.60980,-3.95216,-41.24856,3.92674,41.24856,22476,11
69.96580,-4.30834,-49.38075,4.28292,49.38075,22476,11
70.26380,-4.60605,-56.05183,4.58063,56.05183,22476,11
70.61180,-4.95410,-63.85955,4.92868,63.85955,22476,11
70.91120,-5.21933,-69.52298,5.19391,69.52299,22476,11
71.14380,-4.96446,-60.57565,4.93904,60.57565,22412,11
71.40080,-4.70205,-52.50445,4.67662,52.50445,22412,11
71.71120,-4.39128,-43.39442,4.36585,43.39442,22412,11
71.94280,-4.15898,-37.33294,4.13356,37.33294,22412,11
72.31120,-3.79115,-28.75644,3.76573,28.75644,22412,11
72.77380,-3.32802,-20.14759,3.30260,20.14759,22412,11
73.31120,-2.79108,-12.66269,2.76566,12.66269,22412,11
73.81080,-2.45967,-9.45101,2.43425,9.45101,22412,11
74.22980,-2.89719,-18.02362,2.87177,18.02362,22476,11
74.67580,-3.34415,-26.98286,3.31873,26.98286,22476,12
75.05180,-3.72033,-35.75686,3.69491,35.75686,22476,12
75.45380,-4.12225,-44.99660,4.09683,44.99660,22476,12
75.81120,-4.47936,-53.05027,4.45394,53.05027,22476,12
76.13880,-4.80738,-60.34993,4.78196,60.34993,22476,12
76.53680,-5.20533,-69.36865,5.17991,69.36865,22476,12
76.78080,-5.01158,-61.92336,4.98615,61.92336,22476,12
77.06480,-4.72038,-52.85969,4.69496,52.85969,22412,12
77.37380,-4.41042,-43.71266,4.38500,43.71266,22412,12
77.70180,-4.08202,-35.22395,4.05660,35.22395,22412,12
77.95980,-3.82433,-29.34340,3.79891,29.34340,22412,12
78.43080,-3.35324,-20.53780,3.32782,20.53781,22412,12
79.01120,-2.77323,-12.37972,2.74781,12.37971,22412,12
79.49280,-2.48761,-9.91496,2.46219,9.91496,22412,12
79.91580,-2.92734,-18.42825,2.90192,18.42825,22476,12
80.35980,-3.37232,-27.41055,3.34690,27.41055,22476,13
80.74680,-3.75953,-36.50116,3.73411,36.50116,22476,13
81.11120,-4.12330,-44.82968,4.09788,44.82968,22476,13
81.51120,-4.52343,-53.83142,4.49801,53.83142,22476,13
81.79580,-4.80846,-60.23544,4.78304,60.23544,22476,13
82.11980,-5.13227,-67.52544,5.10685,67.52544,22476,13
82.39980,-5.06535,-63.51769,5.03993,63.51769,22476,13
82.69380,-4.76190,-53.87637,4.73648,53.87637,22412,13
83.01120,-4.44348,-44.48735,4.41806,44.48735,22412,13
83.36380,-4.09010,-35.29227,4.06468,35.29227,22412,13
83.78380,-3.67018,-26.09570,3.64476,26.09570,22412,13
84.19780,-3.25626,-18.96830,3.23084,18.96830,22412,13
84.77480,-2.67905,-10.99012,2.65363,10.99012,22412,13
85.21120,-2.54256,-11.03911,2.51714,11.03911,22412,13
85.67280,-3.01685,-19.99417,2.99143,19.99417,22476,14
86.09980,-3.44440,-29.00152,3.41898,29.00152,22476,14
86.41120,-3.75563,-36.26814,3.73021,36.26814,22476,14
86.64380,-3.98852,-41.63918,3.96310,41.63918,22476,14
87.01120,-4.35567,-50.00915,4.33025,50.00916,22476,14
87.41180,-4.75657,-58.99924,4.73115,58.99924,22476,14
87.78980,-5.13437,-67.51688,5.10895,67.51688,22476,14
88.06180,-5.08860,-64.17055,5.06318,64.17056,22476,14
88.32180,-4.81859,-55.53755,4.79317,55.53755,22412,14
88.61380,-4.52472,-46.83143,4.49929,46.83143,22412,14
88.92580,-4.21236,-38.23826,4.18694,38.23826,22412,14
89.23780,-3.90049,-30.74902,3.87507,30.74902,22412,14
89.65580,-3.48233,-22.53119,3.45691,22.53119,22412,14
90.10980,-3.02831,-15.54599,3.00289,15.54599,22412,14
90.70280,-2.43536,-7.55708,2.40994,7.55708,22412,14
91.02780,-2.70953,-14.08520,2.68411,14.08520,22412,14
91.48580,-3.17234,-23.00132,3.14692,23.00132,22476,15
91.88280,-3.56937,-31.73550,3.54395,31.73550,22476,15
92.28280,-3.96947,-41.03674,3.94405,41.03674,22476,15
92.62680,-4.31360,-48.99955,4.28818,48.99955,22476,15
93.02880,-4.71549,-57.97476,4.69007,57.97476,22476,15
93.36880,-5.05522,-65.62460,5.02980,65.62460,22476,15
93.66780,-5.14772,-66.01659,5.12230,66.01659,22476,15
93.95180,-4.84905,-56.36058,4.82363,56.36058,22412,15
94.23580,-4.56258,-47.87843,4.53716,47.87843,22412,15
94.54180,-4.25637,-39.23783,4.23095,39.23783,22412,15
94.78780,-4.01030,-33.23177,3.98487,33.23177,22412,15
95.20880,-3.58909,-24.26730,3.56367,24.26730,22412,15
95.71880,-3.07916,-16.21398,3.05374,16.21398,22412,15
96.32980,-2.46823,-7.99417,2.44281,7.99417,22412,15
96.71780,-2.73225,-14.46451,2.70683,14.46451,22476,15
97.18780,-3.20628,-23.61054,3.18086,23.61054,22476,16
97.51120,-3.52932,-30.73478,3.50390,30.73479,22476,16
97.90480,-3.92340,-39.90066,3.89798,39.90067,22476,16
98.24780,-4.26650,-47.92238,4.24108,47.92237,22476,16
98.61120,-4.62935,-55.98605,4.60393,55.98605,22476,16
98.91120,-4.92944,-62.68556,4.90402,62.68556,22476,16
99.26880,-5.24086,-69.33097,5.21544,69.33097,22476,16
99.51120,-4.97505,-60.10057,4.94963,60.10057,22476,16
99.79180,-4.68901,-51.33789,4.66359,51.33789,22412,16
100.01120,-4.46951,-44.82013,4.44409,44.82013,22412,16
100.28280,-4.19722,-37.54380,4.17180,37.54380,22412,16
100.61120,-3.86950,-29.83047,3.84408,29.83047,22412,16
101.03480,-3.44520,-21.70995,3.41977,21.70995,22412,16
101.61120,-2.86935,-13.26379,2.84393,13.26379,22412,16
102.12380,-2.44346,-8.22165,2.41804,8.22165,22412,16
102.55580,-2.90114,-17.51796,2.87572,17.51796,22476,16
102.95280,-3.29929,-25.53179,3.27387,25.53179,22476,17
103.27980,-3.62640,-32.95334,3.60098,32.95334,22476,17
103.59980,-3.94644,-40.33371,3.92102,40.33371,22476,17
103.94180,-4.28860,-48.32520,4.26317,48.32520,22476,17
104.24780,-4.59436,-55.03479,4.56894,55.03479,22476,17
104.50380,-4.85056,-60.85770,4.82514,60.85770,22476,17
104.81780,-5.16437,-67.84620,5.13895,67.84620,22476,17
105.09080,-5.06970,-63.11594,5.04428,63.11594,22476,17
105.32380,-4.82862,-55.43614,4.80320,55.43614,22412,17
105.61180,-4.53866,-46.92532,4.51324,46.92532,22412,17
105.85380,-4.29643,-39.96833,4.27101,39.96833,22412,17
106.20780,-3.94237,-31.28306,3.91695,31.28306,22412,17
106.61120,-3.53922,-23.22825,3.51380,23.22825,22412,17
107.13580,-3.01430,-15.14755,2.98888,15.14755,22412,17
107.71120,-2.43929,-7.38058,2.41387,7.38058,22412,17
108.11380,-2.80383,-15.60637,2.77841,15.60637,22604,17
108.56180,-3.25434,-24.42345,3.22892,24.42345,22604,18
108.95180,-3.64452,-33.25985,3.61910,33.25985,22604,18
109.27580,-3.96851,-40.67771,3.94309,40.67771,22604,18
109.51380,-4.20663,-46.25275,4.18121,46.25275,22604,18
109.85680,-4.54956,-53.96638,4.52414,53.96638,22604,18
110.19580,-4.88869,-61.58348,4.86327,61.58348,22604,18
110.56780,-5.25794,-69.94177,5.23252,69.94177,22604,18
110.81580,-5.01336,-61.09029,4.98794,61.09029,22540,18
111.10980,-4.71332,-51.85654,4.68790,51.85654,22540,18
111.39780,-4.42462,-43.41201,4.39920,43.41201,22540,18
111.71120,-4.11137,-35.23260,4.08595,35.23260,22540,18
112.12380,-3.69838,-26.09158,3.67296,26.09158,22540,18
112.63880,-3.18343,-17.49342,3.15801,17.49342,22540,18
113.22680,-2.59524,-9.52621,2.56982,9.52621,22540,18
113.64180,-2.67762,-13.10146,2.65220,13.10146,22540,18
114.10580,-3.14832,-22.12378,3.12290,22.12378,22604,19
114.50380,-3.54647,-30.80542,3.52105,30.80542,22604,19
114.89780,-3.94052,-39.97296,3.91510,39.97297,22604,19
115.29180,-4.33478,-49.03661,4.30936,49.03661,22604,19
115.64580,-4.68856,-56.99382,4.66314,56.99382,22604,19
116.04580,-5.08825,-66.02664,5.06283,66.02664,22604,19
116.32280,-5.14612,-65.58675,5.12070,65.58675,22604,19
116.61120,-4.84394,-55.80915,4.81852,55.80915,22540,19
116.87380,-4.57865,-47.94759,4.55323,47.94759,22540,19
117.18080,-4.27148,-39.19339,4.24606,39.19339,22540,19
117.55380,-3.89850,-30.26342,3.87308,30.26342,22540,19
118.01120,-3.44130,-21.45209,3.41588,21.45209,22540,19
118.57980,-2.87245,-13.08068,2.84703,13.08068,22540,19
119.13580,-2.43404,-7.79139,2.40862,7.79139,22540,19
119.65480,-2.68029,-13.60341,2.65487,13.60341,22540,19
120.11120,-3.13999,-22.34351,3.11456,22.34351,22476,19
120.49480,-3.52405,-30.59193,3.49863,30.59193,22476,20
120.77180,-3.80129,-37.04328,3.77587,37.04328,22476,20
121.15780,-4.18716,-45.85556,4.16174,45.85556,22476,20
121.52280,-4.55209,-53.97439,4.52667,53.97439,22476,20
121.90480,-4.93407,-62.65283,4.90865,62.65282,22476,20
122.21120,-5.24009,-69.53566,5.21467,69.53566,22476,20
122.43380,-5.06022,-62.59655,5.03480,62.59655,22476,20
122.71780,-4.76846,-53.36854,4.74304,53.36854,22412,20
122.91680,-4.56820,-47.63763,4.54278,47.63763,22412,20
123.16380,-4.32103,-40.35202,4.29561,40.35202,22412,20
123.37280,-4.11190,-35.18094,4.08648,35.18094,22412,20
123.56180,-3.92304,-30.73506,3.89762,30.73506,22412,20
123.90780,-3.57675,-23.73414,3.55133,23.73413,22412,20
124.40080,-3.08391,-15.99120,3.05849,15.99120,22412,20
124.98680,-2.49801,-8.13610,2.47259,8.13610,22412,20
125.37380,-2.75295,-14.45218,2.72753,14.45218,22476,20
125.79380,-3.17701,-22.63865,3.15159,22.63865,22476,21
126.15180,-3.53503,-30.45021,3.50961,30.45021,22476,21
126.47180,-3.85541,-38.00525,3.82999,38.00525,22476,21
126.71180,-4.09501,-43.53857,4.06959,43.53857,22476,21
127.03680,-4.42032,-50.91125,4.39490,50.91125,22476,21
127.37380,-4.75732,-58.43831,4.73190,58.43831,22476,21
127.73580,-5.11900,-66.55627,5.09358,66.55627,22476,21
128.01579,-5.13150,-64.89346,5.10608,64.89346,22476,21
128.24980,-4.88631,-56.88130,4.86089,56.88131,22412,21
128.56279,-4.57030,-47.53321,4.54488,47.53321,22412,21
128.91080,-4.22209,-37.77115,4.19667,37.77115,22412,21
129.26979,-3.86329,-29.32794,3.83787,29.32794,22412,21
129.71120,-3.42208,-20.93994,3.39666,20.93994,22412,21
130.30480,-2.82804,-12.47204,2.80262,12.47204,22412,21
130.79080,-2.50843,-9.35828,2.48301,9.35828,22412,21
131.21120,-2.94706,-18.05575,2.92164,18.05575,22476,21
131.64880,-3.38626,-26.90669,3.36084,26.90669,22476,22
132.03480,-3.77247,-35.93610,3.74705,35.93610,22476,22
132.40480,-4.14225,-44.51019,4.11683,44.51019,22476,22
132.80680,-4.54435,-53.55220,4.51893,53.55220,22476,22
133.14980,-4.88740,-61.29036,4.86198,61.29036,22476,22
133.50878,-5.24636,-69.47180,5.22094,69.47180,22476,22
133.76780,-5.03461,-61.47407,5.00919,61.47407,22476,22
134.07080,-4.72516,-51.90247,4.69974,51.90247,22412,22
134.32380,-4.47141,-44.37809,4.44599,44.37809,22412,22
134.65280,-4.14215,-35.66974,4.11673,35.66974,22412,22
134.96980,-3.82531,-28.32681,3.79989,28.32681,22412,22
135.41119,-3.38431,-20.23911,3.35889,20.23911,22412,22
135.99780,-2.79723,-12.06955,2.77181,12.06955,22412,22
136.45480,-2.53213,-9.77466,2.50671,9.77466,22412,22
136.91119,-3.00536,-19.01462,2.97994,19.01462,22476,22
137.32580,-3.42124,-27.56864,3.39582,27.56864,22476,23
137.71120,-3.80639,-36.65000,3.78097,36.65000,22476,23
138.11119,-4.20633,-45.85694,4.18091,45.85694,22476,23
138.51120,-4.60621,-54.89054,4.58079,54.89054,22476,23
138.86280,-4.95814,-62.83473,4.93272,62.83473,22476,23
139.17580,-5.26867,-69.90798,5.24325,69.90798,22476,23
139.42480,-5.02305,-61.01208,4.99763,61.01208,22476,23
139.72380,-4.71806,-51.55984,4.69264,51.55984,22412,23
140.00380,-4.43736,-43.33470,4.41194,43.33470,22412,23
140.28580,-4.15513,-35.84692,4.12971,35.84692,22412,23
140.52480,-3.91627,-30.27230,3.89085,30.27230,22412,23
141.00180,-3.43915,-21.09400,3.41373,21.09400,22412,23
141.56380,-2.87727,-12.94801,2.85185,12.94801,22412,23
142.07280,-2.50160,-8.93727,2.47618,8.93727,22412,23
142.51080,-2.96102,-18.14466,2.93560,18.14466,22476,23
142.92380,-3.37518,-26.54257,3.34975,26.54257,22476,24
143.31120,-3.76233,-35.51189,3.73691,35.51189,22476,24
143.71120,-4.16218,-44.80877,4.13676,44.80877,22476,24
144.11119,-4.56221,-53.86187,4.53679,53.86187,22476,24
144.51120,-4.96209,-62.90273,4.93667,62.90273,22476,24
144.86480,-5.26586,-69.36707,5.24044,69.36707,22476,24
145.12780,-4.97808,-59.39113,4.95266,59.39112,22412,24
145.41119,-4.69071,-50.66261,4.66529,50.66261,22412,24
145.72780,-4.37329,-41.32697,4.34787,41.32697,22412,24
146.07680,-4.02410,-32.66994,3.99868,32.66994,22412,24
146.51080,-3.58997,-23.61303,3.56454,23.61303,22412,24
147.02480,-3.07603,-15.61060,3.05061,15.61060,22412,24
147.61880,-2.48216,-7.58671,2.45674,7.58671,22412,24
148.01380,-2.80393,-15.11788,2.77851,15.11788,22476,24
148.47180,-3.26491,-24.13299,3.23949,24.13299,22476,25
148.85680,-3.65013,-32.88458,3.62471,32.88458,22476,25
149.24780,-4.04110,-41.94643,4.01568,41.94643,22476,25
149.63980,-4.43325,-50.95818,4.40783,50.95818,22476,25
150.04580,-4.83925,-60.01285,4.81383,60.01286,22476,25
150.44080,-5.23416,-68.95182,5.20874,68.95182,22476,25
150.70880,-5.05811,-62.01243,5.03269,62.01243,22476,25
151.00980,-4.75014,-52.29037,4.72472,52.29037,22412,25
151.31980,-4.43916,-43.23594,4.41374,43.23594,22412,25
151.68680,-4.07185,-33.76875,4.04643,33.76875,22412,25
152.10780,-3.65098,-24.67983,3.62556,24.67983,22412,25
152.61680,-3.14207,-16.50034,3.11665,16.50035,22412,25
153.21120,-2.54799,-8.47395,2.52257,8.47395,22412,25
153.61119,-2.76545,-14.28804,2.74003,14.28804,22476,25
154.05680,-3.21582,-23.03794,3.19039,23.03794,22476,26
154.45480,-3.61394,-31.90734,3.58852,31.90734,22476,26
154.84480,-4.00403,-41.02289,3.97861,41.02289,22476,26
155.23680,-4.39617,-49.97043,4.37075,49.97043,22476,26
155.63180,-4.79117,-58.81355,4.76575,58.81355,22476,26
156.03880,-5.19802,-68.03624,5.17260,68.03624,22476,26
156.31120,-5.10453,-63.37126,5.07911,63.37126,22476,26
156.61119,-4.79548,-53.54977,4.77006,53.54977,22412,26
156.92480,-4.48023,-44.30081,4.45481,44.30080,22412,26
157.28580,-4.11893,-34.80420,4.09351,34.80420,22412,26
157.69380,-3.71099,-25.77759,3.68557,25.77759,22412,26
158.21120,-3.19400,-17.17597,3.16858,17.17597,22412,26
158.81120,-2.59387,-9.06530,2.56844,9.06530,22412,26
159.21120,-2.71364,-13.26173,2.68822,13.26173,22412,26
159.66380,-3.17287,-22.13315,3.14745,22.13315,22476,27
160.06680,-3.57595,-30.95833,3.55053,30.95833,22476,27
160.41119,-3.92018,-39.12131,3.89476,39.12132,22476,27
160.81120,-4.32019,-48.31962,4.29476,48.31961,22476,27
161.21120,-4.72013,-57.21513,4.69471,57.21513,22476,27
161.61119,-5.11995,-66.20830,5.09453,66.20830,22476,27
161.89878,-5.15293,-65.04490,5.12751,65.04490,22476,27
162.18180,-4.85738,-55.46917,4.83196,55.46917,22412,27
162.49980,-4.53716,-45.98910,4.51174,45.98910,22412,27
162.77378,-4.26304,-38.34511,4.23762,38.34510,22412,27
163.15280,-3.88412,-29.26548,3.85870,29.26548,22412,27
163.61119,-3.42590,-20.59462,3.40048,20.59462,22412,27
164.21120,-2.82595,-12.12670,2.80053,12.12670,22412,27
164.70280,-2.55348,-9.97906,2.52806,9.97906,22412,27
165.13080,-2.99708,-18.63564,2.97166,18.63564,22604,27
165.56180,-3.42900,-27.51124,3.40358,27.51124,22604,28
165.94580,-3.81320,-36.62117,3.78778,36.62117,22604,28
166.33080,-4.19815,-45.44028,4.17273,45.44028,22604,28
166.73380,-4.60098,-54.46324,4.57555,54.46324,22604,28
167.13378,-5.00087,-63.49453,4.97545,63.49453,22604,28
167.47780,-5.24553,-68.20669,5.22011,68.20669,22604,28
167.74380,-4.95727,-58.46671,4.93185,58.46671,22540,28
168.06080,-4.63655,-48.78120,4.61112,48.78120,22540,28
168.39080,-4.30616,-39.29825,4.28074,39.29825,22540,28
168.76380,-3.93316,-30.27610,3.90774,30.27610,22540,28
169.21280,-3.48406,-21.56043,3.45864,21.56043,22540,28
169.79480,-2.90211,-13.04779,2.87669,13.04779,22540,28
170.27780,-2.47001,-7.60212,2.44459,7.60212,22540,28
170.70280,-2.92265,-17.14716,2.89723,17.14716,22604,28
171.11580,-3.33709,-25.47778,3.31167,25.47778,22604,29
171.51120,-3.73233,-34.65392,3.70691,34.65392,22604,29
171.91119,-4.13213,-43.95194,4.10671,43.95194,22604,29
172.31120,-4.53237,-52.92787,4.50695,52.92787,22604,29
172.71120,-4.93220,-61.93912,4.90678,61.93912,22604,29
173.08380,-5.28301,-69.74621,5.25759,69.74621,22604,29
173.34580,-5.00078,-59.86219,4.97536,59.86219,22540,29
173.64878,-4.69285,-50.43092,4.66743,50.43092,22540,29
173.95080,-4.39044,-41.54259,4.36502,41.54259,22540,29
174.31120,-4.03020,-32.45869,4.00478,32.45869,22540,29
174.73380,-3.60722,-23.60457,3.58180,23.60457,22540,29
175.30080,-3.04014,-14.88392,3.01472,14.88392,22540,29
175.85580,-2.48523,-7.34821,2.45981,7.34821,22540,29
176.54680,-2.70849,-13.55030,2.68307,13.55030,22540,29
177.01120,-3.17600,-22.47560,3.15058,22.47560,22476,29
177.41119,-3.57594,-31.20962,3.55052,31.20962,22476,30
177.80178,-3.96712,-40.28886,3.94170,40.28886,22476,30
178.20580,-4.37129,-49.48433,4.34587,49.48433,22476,30
178.61080,-4.77620,-58.50511,4.75078,58.50512,22476,30
179.01120,-5.17609,-67.51218,5.15067,67.51218,22476,30
179.27080,-5.12468,-64.11001,5.09926,64.11001,22476,30
179.56180,-4.82293,-54.37411,4.79751,54.37411,22412,30
179.84380,-4.53931,-46.00332,4.51389,46.00331,22412,30
180.19180,-4.19100,-36.39024,4.16558,36.39024,22412,30
180.59080,-3.79218,-27.12046,3.76676,27.12046,22412,30
181.09780,-3.28509,-18.47432,3.25966,18.47432,22412,30
181.67480,-2.70802,-10.47057,2.68260,10.47057,22412,30
182.10778,-2.65507,-12.03858,2.62965,12.03858,22412,30
182.54680,-3.10374,-20.52972,3.07831,20.52972,22476,31
182.96180,-3.51920,-29.56168,3.49378,29.56168,22476,31
183.33980,-3.89742,-38.53390,3.87200,38.53391,22476,31
183.72980,-4.28744,-47.55130,4.26201,47.55130,22476,31
184.13880,-4.69629,-56.61901,4.67087,56.61901,22476,31
184.53480,-5.09201,-65.51116,5.06659,65.51116,22476,31
184.83680,-5.18786,-66.03352,5.16244,66.03352,22476,31
185.11380,-4.89628,-56.50348,4.87086,56.50348,22412,31
185.41119,-4.59663,-47.64929,4.57121,47.64929,22412,31
185.73080,-4.27643,-38.48323,4.25101,38.48323,22412,31
186.11119,-3.89647,-29.26743,3.87105,29.26743,22412,31
186.58980,-3.41736,-20.25544,3.39194,20.25544,22412,31
187.18180,-2.82538,-12.05997,2.79996,12.05997,22412,31
187.63980,-2.56763,-9.94452,2.54221,9.94452,22412,31
188.09080,-3.03541,-19.18681,3.00999,19.18681,22476,31
188.51120,-3.45626,-27.97818,3.43084,27.97818,22476,32
188.89580,-3.84148,-37.06992,3.81606,37.06992,22476,32
189.27880,-4.22454,-45.95693,4.19912,45.95693,22476,32
189.63880,-4.58428,-54.01064,4.55886,54.01064,22476,32
190.01120,-4.95618,-62.38658,4.93076,62.38658,22476,32
190.35080,-5.28964,-69.96401,5.26422,69.96401,22476,32
190.60880,-5.02444,-60.42607,4.99902,60.42607,22476,32
190.91119,-4.71701,-50.99459,4.69159,50.99459,22412,32
191.22180,-4.40545,-41.82728,4.38003,41.82728,22412,32
191.59680,-4.03025,-32.23618,4.00482,32.23618,22412,32
191.97780,-3.64926,-24.22066,3.62384,24.22066,22412,32
192.51120,-3.11632,-15.82430,3.09090,15.82430,22412,32
193.11119,-2.51632,-7.72647,2.49089,7.72647,22412,32
193.50380,-2.82393,-15.09647,2.79851,15.09647,22476,32
193.92980,-3.25304,-23.54040,3.22762,23.54040,22476,33
194.31980,-3.64338,-32.41518,3.61796,32.41518,22476,33
194.71120,-4.03433,-41.50807,4.00891,41.50808,22476,33
195.11119,-4.43443,-50.65407,4.40901,50.65407,22476,33
195.48380,-4.80744,-58.95315,4.78202,58.95316,22476,33
195.88180,-5.20538,-67.97945,5.17996,67.97945,22476,33
196.13578,-5.11674,-63.47955,5.09132,63.47955,22476,33
196.42880,-4.81395,-53.85556,4.78853,53.85556,22412,33
196.71180,-4.52954,-45.37546,4.50412,45.37546,22412,33
197.06580,-4.17522,-35.70049,4.14980,35.70049,22412,33
197.41119,-3.83043,-27.65601,3.80501,27.65601,22412,33
197.91119,-3.33029,-18.91368,3.30487,18.91368,22412,33
198.51120,-2.73033,-10.62235,2.70491,10.62235,22412,33
198.95080,-2.64322,-11.61264,2.61780,11.61264,22412,33
199.40680,-3.10985,-20.51840,3.08443,20.51840,22476,34
199.81119,-3.51426,-29.26241,3.48884,29.26241,22476,34
200.19980,-3.90346,-38.47783,3.87803,38.47783,22476,34
200.58980,-4.29361,-47.56652,4.26819,47.56652,22476,34
200.99880,-4.70241,-56.58222,4.67698,56.58222,22476,34
201.39280,-5.09612,-65.44492,5.07070,65.44492,22476,34
201.70380,-5.19644,-66.03163,5.17102,66.03162,22476,34
201.98480,-4.90102,-56.40873,4.87560,56.40873,22412,34
202.29680,-4.58639,-47.08330,4.56097,47.08330,22412,34
202.62078,-4.26226,-37.83652,4.23684,37.83652,22412,34
202.97580,-3.90729,-29.28799,3.88187,29.28799,22412,34
203.43580,-3.44711,-20.63229,3.42169,20.63229,22412,34
204.01120,-2.87224,-12.47347,2.84682,12.47347,22412,34
204.51120,-2.57257,-9.85542,2.54715,9.85542,22412,34
204.93580,-3.01424,-18.61631,2.98882,18.61631,22476,34
205.36180,-3.44116,-27.44338,3.41574,27.44338,22476,35
205.71120,-3.79056,-35.72141,3.76514,35.72141,22476,35
206.05680,-4.13638,-43.81065,4.11096,43.81065,22476,35
206.46380,-4.54345,-52.94875,4.51803,52.94875,22476,35
206.86480,-4.94424,-62.03371,4.91882,62.03371,22476,35
207.22880,-5.29384,-69.90741,5.26842,69.90741,22476,35
207.49180,-5.01489,-59.93576,4.98947,59.93576,22476,35
207.79880,-4.70282,-50.42068,4.67740,50.42068,22412,35
208.08680,-4.41436,-41.94976,4.38894,41.94976,22412,35
208.41119,-4.09008,-33.50845,4.06466,33.50845,22412,35
208.74180,-3.75934,-26.16927,3.73392,26.16927,22412,35
209.21120,-3.29020,-18.20543,3.26478,18.20543,22412,35
209.73780,-2.76336,-11.00661,2.73794,11.00661,22412,35
210.19380,-2.64778,-11.53433,2.62236,11.53433,22412,35
210.63378,-3.09870,-20.11577,3.07328,20.11577,22476,36
211.04480,-3.51023,-29.00165,3.48481,29.00165,22476,36
211.39780,-3.86358,-37.45938,3.83816,37.45938,22476,36
211.78780,-4.25345,-46.47480,4.22803,46.47480,22476,36
212.19280,-4.65842,-55.60986,4.63300,55.60986,22476,36
212.58480,-5.04999,-64.34491,5.02457,64.34491,22476,36
212.91119,-5.23683,-67.36038,5.21141,67.36038,22476,36
213.15780,-4.97149,-58.44981,4.94606,58.44981,22412,36
213.46978,-4.65569,-48.89005,4.63026,48.89005,22412,36
213.75780,-4.36744,-40.49873,4.34202,40.49873,22412,36
214.02378,-4.10116,-33.71140,4.07574,33.71140,22412,36
214.38578,-3.73937,-25.75050,3.71395,25.75050,22412,36
214.87380,-3.25133,-17.59842,3.22591,17.59842,22412,36
215.46080,-2.66421,-9.59314,2.63879,9.59314,22412,36
215.89380,-2.72863,-13.07403,2.70320,13.07403,22412,36
216.32680,-3.16824,-21.61227,3.14282,21.61227,22476,37
216.72980,-3.57134,-30.46288,3.54592,30.46288,22476,37
217.09180,-3.93352,-39.09086,3.90810,39.09086,22476,37
217.48278,-4.32471,-48.08010,4.29929,48.08010,22476,37
217.88180,-4.72359,-56.98130,4.69816,56.98130,22476,37
218.28380,-5.12546,-66.01375,5.10003,66.01375,22476,37
218.58080,-5.18849,-65.66106,5.16307,65.66106,22476,37
218.86780,-4.88801,-55.85075,4.86259,55.85075,22412,37
219.18180,-4.57164,-46.41124,4.54622,46.41124,22412,37
219.51120,-4.24251,-37.13331,4.21709,37.13330,22412,37
219.86480,-3.88860,-28.64913,3.86318,28.64913,22412,37
220.33178,-3.42145,-20.04674,3.39603,20.04674,22412,37
220.91480,-2.83854,-11.95751,2.81312,11.95751,22412,37
221.39780,-2.60215,-10.41390,2.57673,10.41390,22412,37
221.82880,-3.04767,-19.12376,3.02225,19.12376,22604,37
222.24480,-3.46440,-27.86257,3.43898,27.86257,22604,38
222.62680,-3.84669,-36.97797,3.82127,36.97797,22604,38
223.01180,-4.23161,-45.86834,4.20619,45.86834,22604,38
223.41880,-4.63857,-55.01519,4.61314,55.01519,22604,38
223.81580,-5.03527,-63.96095,5.00985,63.96095,22604,38
224.14180,-5.24862,-67.76986,5.22320,67.76986,22604,38
224.41680,-4.95230,-57.82778,4.92687,57.82778,22540,38
224.72980,-4.63592,-48.35981,4.61050,48.35981,22540,38
225.01880,-4.34661,-39.81369,4.32119,39.81369,22540,38
225.36180,-4.00355,-31.21554,3.97813,31.21554,22540,38
225.81119,-3.55433,-22.30433,3.52891,22.30433,22540,38
226.36380,-3.00144,-13.95919,2.97602,13.95919,22540,38
226.91119,-2.50128,-7.62431,2.47586,7.62431,22540,38
227.31119,-2.92857,-16.79699,2.90315,16.79699,22604,38
227.73980,-3.35939,-25.56580,3.33397,25.56580,22604,39
228.05780,-3.67758,-32.93999,3.65216,32.93999,22604,39
228.43480,-4.05442,-41.75643,4.02900,41.75643,22604,39
228.83880,-4.45875,-50.96813,4.43333,50.96813,22604,39
229.21120,-4.83060,-59.27555,4.80518,59.27555,22604,39
229.61119,-5.23057,-68.33074,5.20515,68.33074,22604,39
229.86980,-5.11582,-63.06108,5.09040,63.06108,22604,39
230.11119,-4.86674,-55.06060,4.84132,55.06060,22540,39
230.41980,-4.55566,-45.79967,4.53024,45.79967,22540,39
230.71778,-4.25756,-37.39940,4.23214,37.39940,22540,39
231.07380,-3.90159,-28.85722,3.87617,28.85722,22540,39
231.54180,-3.43344,-20.16508,3.40802,20.16508,22540,39
232.08580,-2.88957,-12.50037,2.86415,12.50037,22540,39
232.81119,-2.49122,-8.07907,2.46580,8.07907,22540,39
233.23080,-2.89133,-16.52336,2.86591,16.52337,22476,39
233.67780,-3.33945,-25.48567,3.31402,25.48567,22476,39
234.00380,-3.66557,-33.00720,3.64015,33.00720,22476,40
234.34380,-4.00552,-40.87428,3.98010,40.87428,22476,40
234.74180,-4.40370,-49.94269,4.37828,49.94269,22476,40
235.08480,-4.74664,-57.53250,4.72122,57.53250,22476,40
235.43380,-5.09526,-65.40246,5.06984,65.40246,22476,40
235.75280,-5.17846,-65.40144,5.15304,65.40144,22476,40
236.03480,-4.88317,-55.74582,4.85775,55.74582,22412,40
236.34180,-4.57372,-46.50640,4.54830,46.50640,22412,40
236.64680,-4.26863,-37.81036,4.24321,37.81036,22412,40
237.01980,-3.89566,-28.80082,3.87024,28.80082,22412,40
237.51120,-3.40461,-19.73868,3.37919,19.73868,22412,40
238.10480,-2.81058,-11.52163,2.78516,11.52163,22412,40
238.54580,-2.61196,-10.45690,2.58654,10.45690,22412,40
238.99578,-3.07678,-19.62495,3.05136,19.62495,22476,40
239.40780,-3.48955,-28.42212,3.46413,28.42212,22476,41
239.78380,-3.86572,-37.43664,3.84030,37.43664,22476,41
240.12980,-4.21169,-45.36838,4.18626,45.36838,22476,41
240.53380,-4.61563,-54.46946,4.59021,54.46946,22476,41
240.93978,-5.02141,-63.57042,4.99599,63.57042,22476,41
241.27480,-5.26604,-68.40856,5.24062,68.40855,22476,41
241.53678,-4.98109,-58.64381,4.95567,58.64381,22412,41
241.84980,-4.66410,-49.01417,4.63868,49.01417,22412,41
242.17780,-4.33577,-39.45537,4.31035,39.45536,22412,41
242.49578,-4.01771,-31.40645,3.99229,31.40645,22412,41
242.87580,-3.63770,-23.60649,3.61228,23.60649,22412,41
243.41119,-3.10266,-15.29169,3.07724,15.29169,22412,41
243.98680,-2.52662,-7.51161,2.50120,7.51161,22412,41
244.37180,-2.86669,-15.53273,2.84126,15.53273,22476,41
244.81119,-3.30868,-24.35065,3.28326,24.35065,22476,42
245.20180,-3.69978,-33.50461,3.67436,33.50461,22476,42
245.53980,-4.03778,-41.37792,4.01236,41.37792,22476,42
245.91119,-4.40906,-49.81875,4.38364,49.81875,22476,42
246.23080,-4.72889,-56.99969,4.70347,56.99969,22476,42
246.61119,-5.10865,-65.50191,5.08323,65.50191,22476,42
246.89878,-5.22452,-66.68972,5.19910,66.68972,22476,42
247.16578,-4.94104,-57.28799,4.91562,57.28799,22412,42
247.47680,-4.62706,-47.92741,4.60164,47.92741,22412,42
247.80780,-4.29578,-38.33270,4.27036,38.33270,22412,42
248.11180,-3.99176,-30.77715,3.96633,30.77715,22412,42
248.55178,-3.55156,-22.05393,3.52614,22.05393,22412,42
249.11119,-2.99261,-13.75248,2.96719,13.75248,22412,42
249.63578,-2.52034,-7.80768,2.49492,7.80768,22412,42
250.04180,-2.95384,-17.14045,2.92842,17.14045,22476,42
250.46680,-3.38067,-25.93160,3.35525,25.93160,22476,43
250.81119,-3.72468,-34.08368,3.69926,34.08368,22476,43
251.20580,-4.11962,-43.26416,4.09420,43.26416,22476,43
251.52280,-4.43696,-50.44344,4.41154,50.44344,22476,43
251.93180,-4.84581,-59.53204,4.82039,59.53204,22476,43
252.31580,-5.22981,-68.17631,5.20439,68.17631,22476,43
252.55980,-5.13931,-63.72062,5.11389,63.72062,22476,43
252.81119,-4.87893,-55.34159,4.85351,55.34159,22412,43
253.02578,-4.66194,-48.86559,4.63652,48.86559,22412,43
253.27680,-4.41071,-41.49163,4.38529,41.49163,22412,43
253.49978,-4.18745,-35.42055,4.16203,35.42055,22412,43
253.71680,-3.97059,-30.24765,3.94517,30.24765,22412,43
254.19178,-3.49549,-21.11666,3.47006,21.11666,22412,43
254.73780,-2.94942,-13.14414,2.92400,13.14414,22412,43
255.25580,-2.55814,-8.87913,2.53272,8.87913,22412,43
255.67580,-3.00022,-18.01726,2.97480,18.01726,22476,43
256.10778,-3.43359,-26.93158,3.40817,26.93158,22476,44
256.43280,-3.75877,-34.78705,3.73335,34.78705,22476,44
256.71780,-4.04362,-41.45183,4.01820,41.45183,22476,44
257.08578,-4.41185,-49.78825,4.38643,49.78825,22476,44
257.38480,-4.71060,-56.51248,4.68518,56.51248,22476,44
257.78680,-5.11244,-65.56929,5.08702,65.56929,22476,44
258.08178,-5.22027,-66.45499,5.19485,66.45499,22476,44
258.34878,-4.93771,-57.09237,4.91229,57.09237,22412,44
258.66778,-4.61582,-47.55268,4.59040,47.55267,22412,44
258.96680,-4.31657,-38.79442,4.29115,38.79442,22412,44
259.30780,-3.97556,-30.29541,3.95014,30.29541,22412,44
259.71119,-3.57237,-22.36973,3.54695,22.36973,22412,44
260.21119,-3.07243,-14.76129,3.04701,14.76129,22412,44
260.78778,-2.50236,-7.14677,2.47694,7.14677,22412,44
261.17780,-2.90322,-16.13890,2.87780,16.13890,22476,44
261.61120,-3.33847,-24.94095,3.31305,24.94095,22476,45
261.95081,-3.67872,-32.85227,3.65330,32.85227,22476,45
262.27478,-4.00267,-40.42526,3.97725,40.42526,22476,45
262.66981,-4.39786,-49.49175,4.37244,49.49175,22476,45
263.07378,-4.80178,-58.52094,4.77636,58.52094,22476,45
263.35678,-5.08440,-64.98194,5.05898,64.98194,22476,45
263.67778,-5.22477,-66.61236,5.19935,66.61236,22476,45
263.95178,-4.93468,-56.99980,4.90926,56.99980,22412,45
264.21119,-4.67297,-49.11467,4.64755,49.11467,22412,45
264.50978,-4.37375,-40.30249,4.34833,40.30249,22412,45
264.81778,-4.06544,-32.34262,4.04002,32.34262,22412,45
265.26778,-3.61554,-23.06500,3.59012,23.06499,22412,45
265.81119,-3.07249,-14.78688,3.04707,14.78688,22412,45
266.39081,-2.50501,-7.14699,2.47959,7.14699,22412,45
266.77078,-2.90215,-16.07983,2.87673,16.07983,22476,45
267.20778,-3.34152,-24.94404,3.31610,24.94404,22476,46
267.58578,-3.71962,-33.84838,3.69420,33.84837,22476,46
267.92778,-4.06160,-41.83434,4.03618,41.83434,22476,46
268.33578,-4.46979,-51.08177,4.44437,51.08177,22476,46
268.66378,-4.79777,-58.36114,4.77235,58.36114,22476,46
269.07378,-5.20771,-67.59906,5.18229,67.59906,22476,46
269.31119,-5.17709,-64.96061,5.15167,64.96061,22476,46
269.60481,-4.87085,-55.04518,4.84543,55.04519,22412,46
269.89178,-4.58178,-46.41883,4.55636,46.41883,22412,46
270.09578,-4.37777,-40.39877,4.35235,40.39877,22412,46
270.41181,-4.06147,-32.21522,4.03605,32.21521,22412,46
270.71381,-3.75972,-25.69439,3.73430,25.69439,22412,46
271.22581,-3.24763,-17.11471,3.22221,17.11471,22412,46
271.81378,-2.65953,-9.17870,2.63411,9.17870,22412,46
272.15178,-2.70173,-11.99067,2.67631,11.99067,22412,46
272.59181,-3.15146,-20.99558,3.12604,20.99558,22476,47
272.95578,-3.51578,-28.86123,3.49036,28.86123,22476,47
273.22581,-3.78602,-35.41036,3.76060,35.41036,22476,47
273.54881,-4.10876,-42.96844,4.08333,42.96844,22476,47
273.75078,-4.31104,-47.60226,4.28562,47.60226,22476,47
274.10778,-4.66796,-55.46147,4.64254,55.46147,22476,47
274.42978,-4.98971,-62.66903,4.96429,62.66903,22476,47
274.75878,-5.30557,-69.83523,5.28015,69.83523,22476,47
274.99281,-5.05769,-60.91308,5.03227,60.91308,22476,47
275.29178,-4.75286,-51.41949,4.72744,51.41949,22412,47
275.51119,-4.53307,-44.91518,4.50765,44.91518,22412,47
275.76081,-4.28297,-37.78952,4.25755,37.78952,22412,47
276.01378,-4.02982,-31.44988,4.00440,31.44988,22412,47
276.33178,-3.71185,-24.70548,3.68643,24.70548,22412,47
276.81119,-3.23288,-16.83821,3.20745,16.83821,22412,47
277.31119,-2.73298,-10.22032,2.70756,10.22032,22412,47
277.71578,-2.69974,-11.96750,2.67431,11.96749,22412,47
278.16378,-3.15777,-21.08987,3.13234,21.08987,22604,47
278.52381,-3.51810,-28.93780,3.49268,28.93780,22604,48
278.91119,-3.90537,-38.20489,3.87995,38.20489,22604,48
279.26881,-4.26343,-46.40377,4.23801,46.40377,22604,48
279.63181,-4.62620,-54.50281,4.60078,54.50281,22604,48
279.92381,-4.91821,-61.05233,4.89279,61.05233,22604,48
280.28778,-5.28227,-69.32025,5.25685,69.32024,22604,48
280.53078,-5.09355,-62.09873,5.06813,62.09874,22604,48
280.78281,-4.83474,-53.84019,4.80932,53.84019,22540,48
281.10181,-4.51430,-44.32096,4.48888,44.32096,22540,48
281.40078,-4.21506,-35.85762,4.18964,35.85762,22540,48
281.65578,-3.96008,-29.81609,3.93466,29.81609,22540,48
282.09778,-3.51799,-21.24434,3.49257,21.24434,22540,48
282.61078,-3.00508,-13.68654,2.97966,13.68654,22540,48
283.11122,-2.51452,-7.22776,2.48910,7.22776,22540,48
283.51119,-2.92897,-16.47688,2.90355,16.47688,22604,48
283.91778,-3.33807,-24.87300,3.31265,24.87300,22604,49
284.21119,-3.63125,-31.61261,3.60583,31.61261,22604,49
284.48778,-3.90846,-38.34160,3.88304,38.34160,22604,49
284.78078,-4.20133,-45.01971,4.17591,45.01971,22604,49
285.02678,-4.44749,-50.52546,4.42207,50.52546,22604,49
285.21119,-4.63127,-54.54709,4.60585,54.54709,22604,49
285.53878,-4.95912,-61.97092,4.93370,61.97092,22604,49
285.73778,-5.15816,-66.37425,5.13274,66.37425,22604,49
285.95978,-5.24292,-67.23924,5.21750,67.23924,22604,49
286.15578,-5.03000,-59.95093,5.00458,59.95093,22540,49
286.41119,-4.77029,-51.89377,4.74487,51.89377,22540,49
286.69778,-4.48237,-43.44284,4.45695,43.44284,22540,49
287.00978,-4.17009,-34.80700,4.14467,34.80700,22540,49
287.35878,-3.82129,-26.70494,3.79587,26.70494,22540,49
287.81119,-3.36928,-18.83380,3.34386,18.83380,22540,49
288.41119,-2.76933,-10.62717,2.74391,10.62717,22540,49
289.10081,-2.58625,-9.90191,2.56083,9.90191,22540,49
289.51578,-3.01293,-18.59187,2.98751,18.59187,22476,49
289.94181,-3.43957,-27.47478,3.41415,27.47478,22476,50
290.29981,-3.79782,-35.91519,3.77240,35.91519,22476,50
290.61122,-4.10849,-43.15912,4.08307,43.15912,22476,50
290.91119,-4.40877,-49.80719,4.38335,49.80719,22476,50
291.31119,-4.80877,-58.69700,4.78335,58.69699,22476,50
291.63581,-5.13345,-66.01632,5.10803,66.01633,22476,50
291.94278,-5.16250,-64.59130,5.13708,64.59129,22476,50
292.23081,-4.86272,-54.80502,4.83730,54.80502,22412,50
292.46578,-4.62588,-47.79670,4.60046,47.79670,22412,50
292.69181,-4.39965,-41.08512,4.37423,41.08512,22412,50
292.91119,-4.18041,-35.10984,4.15499,35.10984,22412,50
293.19678,-3.89465,-28.30331,3.86923,28.30331,22412,50
293.58781,-3.50347,-21.00424,3.47804,21.00424,22412,50
294.12378,-2.96735,-13.19994,2.94192,13.19994,22412,50
294.61122,-2.53133,-7.72256,2.50591,7.72256,22412,50
295.01119,-2.95877,-17.08552,2.93335,17.08552,22476,50
295.43978,-3.38973,-26.08734,3.36431,26.08734,22476,51
295.82278,-3.77289,-35.07209,3.74747,35.07209,22476,51
296.13778,-4.08749,-42.42469,4.06207,42.42469,22476,51
296.47181,-4.42190,-50.03322,4.39648,50.03322,22476,51
296.80578,-4.75584,-57.41479,4.73042,57.41479,22476,51
297.16081,-5.11063,-65.45334,5.08521,65.45335,22476,51
297.45081,-5.22850,-66.64041,5.20308,66.64041,22476,51
297.71119,-4.95210,-57.45996,4.92668,57.45996,22412,51
298.01119,-4.64902,-48.34128,4.62360,48.34128,22412,51
298.27978,-4.37981,-40.40045,4.35439,40.40044,22412,51
298.56181,-4.09753,-32.94539,4.07211,32.94539,22412,51
298.99381,-3.66558,-23.69438,3.64016,23.69439,22412,51
299.51481,-3.14474,-15.46430,3.11932,15.46430,22412,51
300.11122,-2.54861,-7.57902,2.52319,7.57902,22412,51
300.50878,-2.88787,-15.66453,2.86245,15.66453,22476,51
300.91378,-3.29563,-23.88797,3.27021,23.88797,22476,52
301.31119,-3.69285,-33.18577,3.66743,33.18576,22476,52
301.66081,-4.04285,-41.42934,4.01743,41.42934,22476,52
301.91119,-4.29309,-47.21835,4.26767,47.21835,22476,52
302.24281,-4.62488,-54.48308,4.59945,54.48308,22476,52
302.61122,-4.99269,-62.74348,4.96727,62.74348,22476,52
302.85378,-5.23598,-68.22576,5.21056,68.22576,22476,52
303.05381,-5.18510,-65.08013,5.15968,65.08013,22476,52
303.24381,-4.98421,-58.41392,4.95879,58.41391,22412,52
303.51119,-4.71349,-50.13821,4.68807,50.13821,22412,52
303.73778,-4.48606,-43.51566,4.46064,43.51566,22412,52
303.98481,-4.23891,-36.41051,4.21349,36.41051,22412,52
304.32581,-3.89801,-28.25001,3.87259,28.25001,22412,52
304.75978,-3.46379,-20.14399,3.43837,20.14399,22412,52
305.22581,-2.99784,-13.52664,2.97242,13.52664,22412,52
305.76378,-2.54659,-8.18907,2.52117,8.18907,22412,52
306.18281,-2.99140,-17.61539,2.96598,17.61539,22476,52
306.60481,-3.41492,-26.51496,3.38950,26.51496,22476,53
306.98178,-3.79214,-35.45690,3.76672,35.45689,22476,53
307.37778,-4.18807,-44.63387,4.16265,44.63387,22476,53
307.77878,-4.58898,-53.57788,4.56356,53.57788,22476,53
308.16581,-4.97582,-62.36835,4.95040,62.36835,22476,53
308.50978,-5.31067,-69.91321,5.28525,69.91321,22476,53
308.75581,-5.05428,-60.69376,5.02886,60.69376,22476,53
309.06478,-4.73968,-50.96144,4.71426,50.96144,22412,53
309.38581,-4.41799,-41.45143,4.39257,41.45143,22412,53
309.72778,-4.07569,-32.29472,4.05027,32.29472,22412,53
310.17081,-3.63286,-23.05684,3.60744,23.05684,22412,53
310.71119,-3.09283,-14.78447,3.06741,14.78447,22412,53
311.28281,-2.52620,-7.22950,2.50078,7.22950,22412,53
311.66778,-2.91931,-16.15498,2.89389,16.15498,22476,53
312.04581,-3.29963,-23.87918,3.27421,23.87918,22476,54
312.42978,-3.68391,-32.80574,3.65849,32.80574,22476,54
312.75478,-4.00888,-40.41149,3.98346,40.41149,22476,54
313.07778,-4.33208,-47.95605,4.30666,47.95605,22476,54
313.44378,-4.69793,-56.00514,4.67251,56.00514,22476,54
313.84281,-5.09665,-64.96516,5.07123,64.96516,22476,54
314.11122,-5.28943,-68.71971,5.26401,68.71970,22476,54
314.33978,-5.03735,-60.00336,5.01193,60.00336,22412,54
314.56181,-4.81106,-52.92979,4.78564,52.92979,22412,54
314.88581,-4.48595,-43.35666,4.46053,43.35666,22412,54
315.17178,-4.19971,-35.27847,4.17429,35.27847,22412,54
315.51119,-3.86095,-27.34079,3.83553,27.34079,22412,54
316.01119,-3.36086,-18.59473,3.33544,18.59473,22412,54
316.60378,-2.76795,-10.52285,2.74253,10.52285,22412,54
317.00978,-2.66079,-10.93780,2.63537,10.93779,22412,54
317.43378,-3.09715,-19.58146,3.07173,19.58146,22476,54
317.84078,-3.50488,-28.41703,3.47946,28.41703,22476,55
318.21878,-3.88308,-37.50785,3.85766,37.50785,22476,55
318.58178,-4.24600,-45.92473,4.22057,45.92473,22476,55
318.98081,-4.64500,-54.81593,4.61958,54.81593,22476,55
319.31119,-4.97478,-62.29145,4.94936,62.29145,22476,55
319.67978,-5.31035,-69.60025,5.28493,69.60026,22476,55
319.93178,-5.03534,-59.93540,5.00992,59.93540,22412,55
320.23178,-4.73057,-50.54897,4.70514,50.54897,22412,55
320.52781,-4.43395,-41.82823,4.40853,41.82824,22412,55
320.81119,-4.15076,-34.12447,4.12534,34.12447,22412,55
321.18781,-3.77392,-25.66176,3.74850,25.66176,22412,55
321.69778,-3.26385,-17.15385,3.23843,17.15385,22412,55
322.30178,-2.65977,-9.02071,2.63435,9.02071,22412,55
322.69478,-2.79488,-13.59171,2.76946,13.59171,22412,55
323.11122,-3.21660,-22.04604,3.19118,22.04604,22476,56
323.48178,-3.58779,-30.34623,3.56237,30.34623,22476,56
323.81878,-3.92504,-38.45878,3.89962,38.45878,22476,56
324.20578,-4.31220,-47.55607,4.28678,47.55607,22476,56
324.51119,-4.61698,-54.16584,4.59156,54.16584,22476,56
324.91119,-5.01676,-63.12799,4.99134,63.12799,22476,56
325.23678,-5.31448,-69.75540,5.28906,69.75539,22476,56
325.47581,-5.05409,-60.51162,5.02867,60.51162,22412,56
325.71781,-4.80721,-52.75702,4.78179,52.75703,22412,56
326.00181,-4.52216,-44.33518,4.49674,44.33518,22412,56
326.24578,-4.27803,-37.30362,4.25261,37.30362,22412,56
326.54581,-3.97802,-29.90704,3.95260,29.90704,22412,56
327.01119,-3.51291,-20.91327,3.48748,20.91327,22412,56
327.52178,-3.00196,-13.47074,2.97654,13.47074,22412,56
328.05578,-2.56125,-8.36371,2.53583,8.36371,22412,56
328.46478,-2.99541,-17.52328,2.96999,17.52328,22476,56
328.89381,-3.42599,-26.53367,3.40057,26.53366,22476,57
329.27078,-3.80322,-35.47976,3.77780,35.47976,22476,57
329.64881,-4.18116,-44.41871,4.15574,44.41871,22476,57
330.04481,-4.57706,-53.35776,4.55164,53.35776,22476,57
330.45278,-4.98489,-62.43520,4.95947,62.43520,22476,57
330.76481,-5.29710,-69.53721,5.27168,69.53721,22476,57
331.01119,-5.08267,-61.46953,5.05725,61.46953,22476,57
331.31119,-4.77608,-51.88736,4.75066,51.88736,22412,57
331.54178,-4.54418,-44.94917,4.51876,44.94917,22412,57
331.84281,-4.24305,-36.33927,4.21763,36.33927,22412,57
332.19181,-3.89415,-27.95156,3.86873,27.95156,22412,57
332.68978,-3.39611,-19.03852,3.37069,19.03852,22412,57
333.26981,-2.81608,-11.09773,2.79066,11.09773,22412,57
333.71178,-2.66871,-11.00540,2.64328,11.00540,22412,57
334.15781,-3.12744,-20.08239,3.10202,20.08239,22604,57
334.56378,-3.53396,-29.04544,3.50854,29.04544,22604,58
334.88581,-3.85619,-36.77027,3.83077,36.77026,22604,58
335.19378,-4.16410,-43.97827,4.13868,43.97828,22604,58
335.47681,-4.44720,-50.38061,4.42177,50.38062,22604,58
335.84181,-4.81210,-58.46010,4.78668,58.46010,22604,58
336.24078,-5.21104,-67.48764,5.18562,67.48764,22604,58
336.51081,-5.14885,-63.68806,5.12343,63.68806,22604,58
336.73978,-4.91067,-55.96523,4.88525,55.96523,22540,58
337.05478,-4.59320,-46.45264,4.56778,46.45264,22540,58
337.38181,-4.26607,-36.95637,4.24065,36.95638,22540,58
337.69378,-3.95404,-29.34454,3.92862,29.34454,22540,58
338.14881,-3.49899,-20.65156,3.47357,20.65156,22540,58
338.67678,-2.97091,-13.03417,2.94549,13.03417,22540,58
339.18378,-2.58165,-8.78864,2.55623,8.78864,22540,58
339.60181,-3.02267,-18.05821,2.99725,18.05821,22604,58
340.01119,-3.43302,-26.62341,3.40760,26.62341,22604,59
340.40078,-3.82321,-35.93192,3.79779,35.93192,22604,59
340.79378,-4.21617,-45.07439,4.19075,45.07439,22604,59
341.14978,-4.57208,-53.08976,4.54666,53.08976,22604,59
341.54778,-4.96992,-62.08646,4.94449,62.08646,22604,59
341.91119,-5.32625,-70.10686,5.30083,70.10686,22604,59
342.15781,-5.07250,-61.01378,5.04708,61.01378,22604,59
342.46178,-4.76288,-51.36370,4.73746,51.36370,22540,59
342.74978,-4.47412,-42.89852,4.44870,42.89852,22540,59
343.09878,-4.12489,-33.31204,4.09947,33.31204,22540,59
343.46478,-3.75906,-25.21710,3.73364,25.21710,22540,59
343.92481,-3.29893,-17.53711,3.27351,17.53711,22540,59
344.52078,-2.70294,-9.52620,2.67752,9.52620,22540,59
344.71119,-2.51986,-6.96403,2.49444,6.96403,22540,59