File: data-raw/Experiment 2/Results/INSTRON data/Experiment 2.is_ccyclic_RawData/Specimen_RawData_18.csv
Text Inputs : Specimen label,"Short Plate 5 T1"

Time,Extension,Load,Compressive extension,Compressive load,Segment ID,Total Cycle Count
(sec),(mm),(N),(mm),(N),,
0.00000,-0.02488,-0.03217,0.00000,0.03217,12835,0
1.49120,-0.20350,-0.01928,0.17862,0.01928,3220,0
3.16380,-1.04096,-2.79628,1.01608,2.79628,3220,0
3.84780,-1.44602,-8.74192,1.42114,8.74191,3220,0
4.49120,-2.09241,-16.60654,2.06753,16.60654,22476,0
5.09120,-2.69238,-24.43852,2.66750,24.43852,22476,0
5.59380,-3.19537,-32.58626,3.17049,32.58626,22476,0
6.09120,-3.69233,-41.20067,3.66745,41.20067,22476,0
6.54780,-4.14954,-49.18142,4.12466,49.18142,22476,0
7.04580,-4.64744,-57.70501,4.62256,57.70501,22476,0
7.53180,-5.13354,-66.10551,5.10866,66.10551,22476,0
7.90780,-5.23748,-65.83285,5.21260,65.83285,22476,0
8.25480,-4.87781,-56.40549,4.85293,56.40549,22412,0
8.63380,-4.49769,-47.23227,4.47281,47.23227,22412,0
9.02480,-4.10652,-38.32604,4.08164,38.32604,22412,0
9.47980,-3.65123,-29.16399,3.62635,29.16399,22412,0
9.99120,-3.14034,-20.98004,3.11546,20.98004,22412,0
10.64180,-2.48944,-12.97383,2.46456,12.97383,22412,0
11.24580,-2.02550,-8.63313,2.00062,8.63313,22412,0
11.76280,-2.56381,-17.18051,2.53893,17.18051,22476,0
12.27180,-3.07344,-25.53039,3.04856,25.53039,22476,1
12.69120,-3.49255,-33.46818,3.46766,33.46818,22476,1
13.13680,-3.93854,-42.00303,3.91366,42.00303,22476,1
13.59120,-4.39267,-50.76144,4.36779,50.76144,22476,1
14.07080,-4.87256,-59.74324,4.84768,59.74324,22476,1
14.52880,-5.33039,-68.19969,5.30551,68.19969,22476,1
14.84280,-5.21277,-63.42638,5.18789,63.42638,22476,1
15.19120,-4.85722,-54.29630,4.83234,54.29630,22412,1
15.58680,-4.46053,-44.72378,4.43565,44.72377,22412,1
15.99120,-4.05637,-35.78475,4.03149,35.78476,22412,1
16.43780,-3.60931,-27.07876,3.58443,27.07876,22412,1
16.99280,-3.05430,-18.91166,3.02942,18.91166,22412,1
17.66280,-2.38435,-11.09776,2.35947,11.09776,22412,1
18.18880,-2.23003,-11.10641,2.20515,11.10641,22412,1
18.70780,-2.75925,-19.22025,2.73437,19.22025,22476,2
19.20180,-3.25344,-27.54078,3.22856,27.54078,22476,2
19.66780,-3.71943,-36.70882,3.69454,36.70882,22476,2
20.10680,-4.15860,-45.14537,4.13372,45.14537,22476,2
20.56380,-4.61553,-53.97044,4.59064,53.97044,22476,2
21.01980,-5.07160,-62.71724,5.04672,62.71724,22476,2
21.45380,-5.41867,-68.63072,5.39379,68.63071,22476,2
21.77880,-5.06945,-58.91912,5.04457,58.91912,22412,2
22.14480,-4.70059,-49.82262,4.67570,49.82262,22412,2
22.51680,-4.32839,-40.97367,4.30350,40.97367,22412,2
22.95380,-3.89158,-31.79657,3.86670,31.79657,22412,2
23.45680,-3.38856,-23.08533,3.36368,23.08533,22412,2
24.07180,-2.77344,-14.93204,2.74856,14.93204,22412,2
24.72480,-2.12051,-7.60724,2.09563,7.60724,22412,2
25.19120,-2.52672,-15.15775,2.50184,15.15775,22476,2
25.69380,-3.03162,-23.06876,3.00674,23.06876,22476,3
26.18080,-3.51878,-31.91784,3.49390,31.91784,22476,3
26.62380,-3.96171,-40.90508,3.93682,40.90508,22476,3
27.07280,-4.41087,-49.45944,4.38599,49.45944,22476,3
27.51780,-4.85575,-58.05357,4.83087,58.05357,22476,3
27.99080,-5.32857,-67.13759,5.30369,67.13759,22476,3
28.31780,-5.30861,-64.73140,5.28373,64.73140,22476,3
28.67880,-4.93762,-55.22589,4.91274,55.22589,22412,3
29.04980,-4.56566,-46.16136,4.54078,46.16136,22412,3
29.43480,-4.18048,-37.11125,4.15560,37.11125,22412,3
29.88480,-3.73055,-28.24979,3.70567,28.24979,22412,3
30.40680,-3.20842,-20.10027,3.18354,20.10027,22412,3
31.09080,-2.52466,-11.98003,2.49977,11.98003,22412,3
31.63180,-2.21354,-9.61605,2.18866,9.61604,22412,3
32.14480,-2.74216,-18.10667,2.71728,18.10667,22476,4
32.66480,-3.26265,-26.62769,3.23777,26.62769,22476,4
33.10380,-3.70158,-35.39434,3.67670,35.39434,22476,4
33.55980,-4.15776,-44.00538,4.13288,44.00537,22476,4
33.99120,-4.58864,-52.48337,4.56376,52.48337,22476,4
34.45380,-5.05184,-61.43287,5.02696,61.43287,22476,4
34.89120,-5.48840,-69.98709,5.46352,69.98709,22476,4
35.19120,-5.20368,-61.54062,5.17880,61.54062,22412,4
35.57280,-4.81705,-51.84020,4.79216,51.84021,22412,4
35.95080,-4.43882,-42.73619,4.41394,42.73619,22412,4
36.36480,-4.02481,-33.73829,3.99993,33.73829,22412,4
36.82580,-3.56368,-25.19842,3.53880,25.19842,22412,4
37.40980,-2.97972,-17.04841,2.95484,17.04841,22412,4
38.09120,-2.29850,-9.14052,2.27362,9.14052,22412,4
38.56480,-2.44437,-13.15456,2.41949,13.15456,22412,4
39.09120,-2.97475,-21.47412,2.94987,21.47412,22476,5
39.57280,-3.45698,-30.01709,3.43210,30.01709,22476,5
40.00380,-3.88803,-38.62148,3.86315,38.62148,22476,5
40.46480,-4.34894,-47.66994,4.32406,47.66994,22476,5
40.90280,-4.78696,-56.07982,4.76208,56.07982,22476,5
41.36080,-5.24472,-65.04239,5.21984,65.04239,22476,5
41.75180,-5.36608,-65.71691,5.34120,65.71690,22476,5
42.09120,-5.01450,-56.40014,4.98962,56.40014,22412,5
42.45480,-4.64893,-47.67866,4.62405,47.67866,22412,5
42.84980,-4.25378,-38.29025,4.22890,38.29025,22412,5
43.29120,-3.81280,-29.24797,3.78792,29.24797,22412,5
43.80480,-3.29869,-21.00891,3.27381,21.00891,22412,5
44.44780,-2.65577,-12.89911,2.63089,12.89911,22412,5
45.04380,-2.20216,-8.63175,2.17728,8.63175,22412,5
45.54780,-2.72727,-17.26069,2.70239,17.26069,22476,5
46.06580,-3.24594,-25.86209,3.22106,25.86209,22476,6
46.49580,-3.67588,-34.19651,3.65100,34.19651,22476,6
46.95280,-4.13311,-43.09929,4.10823,43.09929,22476,6
47.39120,-4.57101,-51.70616,4.54613,51.70616,22476,6
47.85180,-5.03221,-60.55134,5.00733,60.55134,22476,6
48.29120,-5.47117,-69.40360,5.44629,69.40359,22476,6
48.60380,-5.25624,-62.41342,5.23136,62.41343,22412,6
48.97080,-4.88370,-52.83045,4.85882,52.83046,22412,6
49.34780,-4.50636,-43.81691,4.48148,43.81691,22412,6
49.75680,-4.09721,-34.74062,4.07233,34.74062,22412,6
50.21180,-3.64197,-26.12781,3.61709,26.12781,22412,6
50.79120,-3.06304,-17.63228,3.03816,17.63228,22412,6
51.45980,-2.39411,-9.98404,2.36923,9.98404,22412,6
51.95980,-2.39768,-12.24816,2.37280,12.24816,22412,6
52.49120,-2.93506,-20.36630,2.91018,20.36630,22476,7
52.98980,-3.43437,-29.10515,3.40949,29.10515,22476,7
53.41680,-3.86138,-37.51942,3.83650,37.51942,22476,7
53.86780,-4.31226,-46.43447,4.28738,46.43447,22476,7
54.31780,-4.76231,-55.13999,4.73743,55.13999,22476,7
54.77480,-5.21906,-64.08678,5.19418,64.08678,22476,7
55.14980,-5.46773,-68.14308,5.44285,68.14308,22476,7
55.49120,-5.10583,-58.18806,5.08094,58.18806,22412,7
55.80480,-4.78960,-50.30175,4.76472,50.30175,22412,7
56.19480,-4.39952,-41.31119,4.37464,41.31118,22412,7
56.60180,-3.99255,-32.18929,3.96767,32.18929,22412,7
57.11280,-3.48151,-23.47698,3.45663,23.47698,22412,7
57.71680,-2.87738,-15.48448,2.85249,15.48448,22412,7
58.39080,-2.20316,-7.60159,2.17828,7.60159,22412,7
58.83180,-2.58404,-14.69100,2.55916,14.69100,22604,7
59.36480,-3.11935,-23.19864,3.09447,23.19864,22604,8
59.81980,-3.57441,-31.55063,3.54953,31.55063,22604,8
60.22880,-3.98352,-39.73059,3.95864,39.73059,22604,8
60.68580,-4.44059,-48.70991,4.41571,48.70992,22604,8
61.12380,-4.87855,-57.23691,4.85367,57.23691,22604,8
61.57280,-5.32734,-66.01171,5.30246,66.01171,22604,8
61.88880,-5.41145,-66.32219,5.38657,66.32219,22604,8
62.20680,-5.07957,-57.40950,5.05469,57.40950,22540,8
62.58280,-4.70158,-48.21060,4.67670,48.21060,22540,8
62.93880,-4.34556,-39.70131,4.32068,39.70131,22540,8
63.36980,-3.91462,-30.68014,3.88974,30.68014,22540,8
63.87980,-3.40459,-22.13488,3.37971,22.13488,22540,8
64.49120,-2.79345,-14.34478,2.76857,14.34478,22540,8
65.12580,-2.17839,-7.08975,2.15351,7.08975,22540,8
65.59120,-2.66608,-15.99490,2.64120,15.99490,22604,8
66.11080,-3.18737,-24.22763,3.16249,24.22763,22604,9
66.57780,-3.65442,-32.90358,3.62954,32.90358,22604,9
67.02180,-4.09855,-41.72288,4.07367,41.72288,22604,9
67.46580,-4.54265,-50.79291,4.51777,50.79292,22604,9
67.90480,-4.98167,-59.24221,4.95679,59.24221,22604,9
68.36080,-5.43764,-68.02623,5.41276,68.02623,22604,9
68.69120,-5.31523,-63.43308,5.29035,63.43308,22604,9
69.03480,-4.96432,-54.18804,4.93944,54.18803,22540,9
69.41180,-4.58650,-45.19880,4.56162,45.19880,22540,9
69.80180,-4.19628,-36.22823,4.17140,36.22823,22540,9
70.25880,-3.73943,-27.22277,3.71455,27.22277,22540,9
70.80480,-3.19325,-19.13612,3.16837,19.13612,22540,9
71.47780,-2.52048,-11.10080,2.49559,11.10079,22540,9
72.21880,-2.24145,-8.96032,2.21657,8.96032,22540,9
72.73980,-2.77584,-17.65813,2.75096,17.65813,22476,9
73.26280,-3.29918,-26.26604,3.27430,26.26604,22476,10
73.69380,-3.73015,-34.60279,3.70527,34.60279,22476,10
74.15580,-4.19211,-43.61300,4.16723,43.61300,22476,10
74.59480,-4.63113,-52.24765,4.60625,52.24765,22476,10
75.00780,-5.04436,-60.26782,5.01948,60.26782,22476,10
75.45280,-5.48936,-69.08796,5.46448,69.08796,22476,10
75.71280,-5.31554,-63.38055,5.29066,63.38055,22476,10
76.07680,-4.94402,-53.79498,4.91914,53.79498,22412,10
76.44480,-4.57531,-44.88336,4.55043,44.88335,22412,10
76.79280,-4.22715,-36.89345,4.20227,36.89345,22412,10
77.20080,-3.81920,-28.63418,3.79432,28.63418,22412,10
77.74580,-3.27411,-20.03329,3.24923,20.03329,22412,10
78.39120,-2.62926,-12.31196,2.60438,12.31196,22412,10
78.93080,-2.30647,-9.66137,2.28159,9.66137,22412,10
79.43480,-2.82650,-18.09516,2.80162,18.09516,22476,11
79.95180,-3.34415,-26.70474,3.31927,26.70474,22476,11
80.35480,-3.74717,-34.65693,3.72229,34.65693,22476,11
80.79120,-4.18315,-43.25379,4.15827,43.25380,22476,11
81.23480,-4.62709,-51.98088,4.60221,51.98088,22476,11
81.69120,-5.08323,-60.90940,5.05835,60.90940,22476,11
82.09120,-5.48330,-68.82853,5.45842,68.82853,22476,11
82.39120,-5.29199,-62.58860,5.26711,62.58860,22476,11
82.69680,-4.98018,-54.50561,4.95530,54.50561,22412,11
83.01380,-4.66213,-46.94683,4.63725,46.94683,22412,11
83.37580,-4.30000,-38.38781,4.27512,38.38781,22412,11
83.70980,-3.96627,-31.30009,3.94139,31.30009,22412,11
84.11280,-3.56313,-24.18896,3.53825,24.18896,22412,11
84.71280,-2.96314,-16.08039,2.93826,16.08039,22412,11
85.39120,-2.28498,-8.14199,2.26010,8.14198,22412,11
85.82680,-2.58807,-14.18900,2.56319,14.18900,22476,11
86.35280,-3.11710,-22.63177,3.09222,22.63177,22476,12
86.81680,-3.58119,-31.06725,3.55631,31.06725,22476,12
87.21580,-3.98027,-39.16087,3.95539,39.16087,22476,12
87.66780,-4.43238,-48.11439,4.40750,48.11439,22476,12
88.10680,-4.87132,-56.59113,4.84644,56.59113,22476,12
88.56680,-5.33114,-65.62739,5.30626,65.62739,22476,12
88.90680,-5.43692,-66.42589,5.41204,66.42589,22476,12
89.21380,-5.11632,-57.76199,5.09144,57.76199,22412,12
89.56080,-4.76728,-49.20863,4.74240,49.20863,22412,12
89.94380,-4.38423,-40.05016,4.35935,40.05016,22412,12
90.35280,-3.97524,-31.36714,3.95036,31.36714,22412,12
90.86380,-3.46419,-22.57707,3.43931,22.57707,22412,12
91.48480,-2.84305,-14.54605,2.81817,14.54605,22412,12
92.09120,-2.23701,-7.39045,2.21213,7.39045,22412,12
92.58180,-2.69048,-15.73350,2.66559,15.73350,22476,12
93.09120,-3.20099,-23.96190,3.17611,23.96190,22476,13
93.54780,-3.65803,-32.55395,3.63315,32.55395,22476,13
93.99120,-4.10118,-41.37434,4.07630,41.37434,22476,13
94.39120,-4.50130,-49.23900,4.47642,49.23900,22476,13
94.83880,-4.94926,-58.01751,4.92438,58.01751,22476,13
95.25080,-5.36116,-66.12936,5.33628,66.12936,22476,13
95.59780,-5.38411,-64.90803,5.35923,64.90803,22476,13
95.94480,-5.02636,-55.49702,5.00148,55.49702,22412,13
96.32280,-4.64706,-46.33165,4.62218,46.33165,22412,13
96.68680,-4.28291,-37.74258,4.25802,37.74258,22412,13
97.06780,-3.90219,-29.91667,3.87731,29.91667,22412,13
97.59120,-3.37913,-21.30256,3.35424,21.30256,22412,13
98.20080,-2.76903,-13.58823,2.74415,13.58823,22412,13
98.79880,-2.24914,-7.98100,2.22426,7.98100,22412,13
99.29120,-2.76815,-16.85140,2.74327,16.85140,22476,13
99.80280,-3.28104,-25.23904,3.25616,25.23904,22476,14
100.25980,-3.73808,-34.09620,3.71320,34.09620,22476,14
100.69120,-4.16912,-42.63515,4.14424,42.63515,22476,14
101.07680,-4.55514,-50.26144,4.53026,50.26144,22476,14
101.48580,-4.96422,-58.15404,4.93934,58.15404,22476,14
101.88180,-5.36012,-66.04476,5.33524,66.04476,22476,14
102.20180,-5.43113,-66.04520,5.40625,66.04520,22476,14
102.51980,-5.09998,-57.21370,5.07510,57.21370,22412,14
102.89120,-4.72710,-48.17580,4.70222,48.17580,22412,14
103.19280,-4.42509,-40.82726,4.40021,40.82726,22412,14
103.59120,-4.02711,-32.24958,4.00223,32.24958,22412,14
104.01380,-3.60396,-24.57516,3.57908,24.57516,22412,14
104.60280,-3.01503,-16.50043,2.99015,16.50043,22412,14
105.27480,-2.34299,-8.56186,2.31811,8.56186,22412,14
105.69120,-2.51401,-12.85555,2.48913,12.85555,22476,14
106.22480,-3.05293,-21.26243,3.02805,21.26243,22476,15
106.66180,-3.49014,-29.03270,3.46526,29.03270,22476,15
107.01780,-3.84610,-36.15245,3.82122,36.15245,22476,15
107.46380,-4.29201,-44.90533,4.26713,44.90533,22476,15
107.87480,-4.70287,-53.01965,4.67799,53.01965,22476,15
108.28280,-5.11109,-61.03689,5.08620,61.03689,22476,15
108.63880,-5.46716,-68.12972,5.44228,68.12971,22476,15
108.94580,-5.33625,-63.37329,5.31137,63.37329,22476,15
109.29120,-4.98392,-54.17145,4.95904,54.17146,22412,15
109.61080,-4.66291,-46.51971,4.63803,46.51971,22412,15
109.94980,-4.32388,-38.48163,4.29899,38.48163,22412,15
110.29580,-3.97810,-31.16924,3.95322,31.16924,22412,15
110.79880,-3.47509,-22.58120,3.45021,22.58120,22412,15
111.41780,-2.85593,-14.48011,2.83105,14.48011,22412,15
112.05180,-2.23439,-7.25421,2.20951,7.25421,22412,15
112.50680,-2.70737,-15.72325,2.68249,15.72325,22476,15
113.02480,-3.22696,-24.11178,3.20208,24.11178,22476,16
113.49120,-3.69293,-33.01278,3.66805,33.01278,22476,16
113.91780,-4.12015,-41.47875,4.09527,41.47875,22476,16
114.33080,-4.53326,-49.61156,4.50838,49.61156,22476,16
114.79120,-4.99324,-58.61722,4.96836,58.61721,22476,16
115.18980,-5.39220,-66.58003,5.36732,66.58003,22476,16
115.51080,-5.41812,-65.49167,5.39324,65.49167,22476,16
115.85780,-5.05931,-56.02925,5.03443,56.02925,22412,16
116.23580,-4.67987,-46.84532,4.65499,46.84532,22412,16
116.59080,-4.32485,-38.42233,4.29997,38.42234,22412,16
117.00980,-3.90609,-29.73248,3.88121,29.73248,22412,16
117.53680,-3.37902,-21.10407,3.35414,21.10407,22412,16
118.17780,-2.73796,-13.03811,2.71308,13.03811,22412,16
118.74180,-2.28963,-8.47292,2.26475,8.47292,22412,16
119.23380,-2.80515,-17.09216,2.78027,17.09216,22476,16
119.74780,-3.31994,-25.68994,3.29506,25.68994,22476,17
120.19120,-3.76306,-34.33024,3.73818,34.33024,22476,17
120.63180,-4.20388,-43.09363,4.17899,43.09362,22476,17
121.06180,-4.63400,-51.59733,4.60912,51.59734,22476,17
121.49120,-5.06312,-59.91694,5.03824,59.91693,22476,17
121.91680,-5.48917,-68.43854,5.46429,68.43854,22476,17
122.19580,-5.36316,-63.91951,5.33828,63.91951,22476,17
122.50680,-5.04407,-55.57174,5.01919,55.57174,22412,17
122.86180,-4.68777,-46.89985,4.66288,46.89985,22412,17
123.17880,-4.37097,-39.40003,4.34609,39.40003,22412,17
123.51380,-4.03593,-32.22038,4.01105,32.22038,22412,17
123.89880,-3.65072,-25.15395,3.62583,25.15395,22412,17
124.49120,-3.05881,-16.84831,3.03393,16.84831,22412,17
125.15280,-2.39690,-9.03151,2.37202,9.03151,22412,17
125.62780,-2.55960,-13.24034,2.53472,13.24034,22604,17
126.15780,-3.09376,-21.71334,3.06888,21.71334,22604,18
126.61980,-3.55594,-30.08079,3.53106,30.08079,22604,18
126.99120,-3.92701,-37.51462,3.90213,37.51461,22604,18
127.42180,-4.35801,-46.04585,4.33313,46.04586,22604,18
127.87980,-4.81596,-55.06662,4.79108,55.06662,22604,18
128.28279,-5.21869,-62.99585,5.19381,62.99585,22604,18
128.67380,-5.54658,-69.14566,5.52170,69.14567,22604,18
128.99120,-5.20384,-59.53219,5.17896,59.53219,22540,18
129.31580,-4.87616,-51.44105,4.85128,51.44106,22540,18
129.63680,-4.55477,-43.66550,4.52988,43.66550,22540,18
130.03479,-4.15670,-34.67444,4.13182,34.67443,22540,18
130.44879,-3.74273,-26.58929,3.71785,26.58929,22540,18
130.99680,-3.19455,-18.54972,3.16967,18.54972,22540,18
131.67880,-2.51281,-10.44227,2.48793,10.44227,22540,18
132.12880,-2.39936,-10.63554,2.37448,10.63554,22540,18
132.66780,-2.94946,-19.25232,2.92458,19.25232,22604,19
133.15280,-3.43489,-27.56719,3.41001,27.56719,22604,19
133.59120,-3.87291,-36.28858,3.84803,36.28858,22604,19
134.02780,-4.30981,-44.99491,4.28492,44.99491,22604,19
134.43180,-4.71368,-52.96288,4.68880,52.96288,22604,19
134.80080,-5.08286,-60.20062,5.05798,60.20062,22604,19
135.24280,-5.52496,-69.01496,5.50008,69.01496,22604,19
135.57380,-5.27471,-61.41515,5.24983,61.41515,22540,19
135.87880,-4.96536,-53.44731,4.94048,53.44731,22540,19
136.19180,-4.65159,-45.96936,4.62670,45.96936,22540,19
136.56880,-4.27445,-37.07857,4.24957,37.07857,22540,19
136.90680,-3.93664,-30.13857,3.91176,30.13857,22540,19
137.37580,-3.46770,-22.21859,3.44282,22.21859,22540,19
137.99120,-2.85255,-14.25881,2.82767,14.25881,22540,19
138.65680,-2.25075,-7.42117,2.22587,7.42117,22540,19
139.20580,-2.50545,-12.68596,2.48057,12.68596,22476,19
139.74780,-3.05095,-21.17305,3.02607,21.17305,22476,19
140.23280,-3.53608,-29.75183,3.51120,29.75183,22476,20
140.65080,-3.95404,-38.12401,3.92916,38.12401,22476,20
141.07580,-4.37916,-46.50047,4.35428,46.50047,22476,20
141.48780,-4.79105,-54.51473,4.76617,54.51473,22476,20
141.92480,-5.22776,-63.18439,5.20288,63.18439,22476,20
142.24580,-5.54897,-69.61525,5.52409,69.61525,22476,20
142.53080,-5.29161,-61.86482,5.26673,61.86482,22476,20
142.85780,-4.95952,-53.33501,4.93464,53.33501,22412,20
143.19119,-4.62585,-45.25414,4.60097,45.25415,22412,20
143.56080,-4.25570,-36.62372,4.23082,36.62372,22412,20
143.90180,-3.91490,-29.71929,3.89002,29.71929,22412,20
144.42880,-3.38785,-21.09675,3.36297,21.09675,22412,20
144.99120,-2.82567,-13.90695,2.80079,13.90695,22412,20
145.59120,-2.27270,-7.75973,2.24782,7.75973,22412,20
146.07580,-2.78577,-16.63994,2.76089,16.63994,22476,20
146.58780,-3.29885,-25.10364,3.27397,25.10364,22476,21
146.99120,-3.70174,-32.81589,3.67686,32.81589,22476,21
147.39119,-4.10190,-40.74917,4.07701,40.74917,22476,21
147.83080,-4.54202,-49.49098,4.51714,49.49098,22476,21
148.24780,-4.95901,-57.64405,4.93413,57.64405,22476,21
148.65280,-5.36388,-65.74097,5.33900,65.74097,22476,21
148.98980,-5.44564,-65.97161,5.42076,65.97160,22476,21
149.32680,-5.09542,-56.64062,5.07054,56.64062,22412,21
149.69180,-4.72878,-47.73543,4.70390,47.73544,22412,21
150.08280,-4.33767,-38.43055,4.31279,38.43055,22412,21
150.50280,-3.91784,-29.68729,3.89296,29.68729,22412,21
150.99120,-3.42975,-21.59347,3.40487,21.59347,22412,21
151.59120,-2.82961,-13.87941,2.80473,13.87941,22412,21
152.19119,-2.28045,-7.78917,2.25557,7.78917,22412,21
152.67980,-2.79763,-16.71198,2.77275,16.71198,22476,21
153.18880,-3.30767,-25.16360,3.28279,25.16360,22476,22
153.62380,-3.74271,-33.65897,3.71783,33.65897,22476,22
154.07980,-4.19865,-42.64731,4.17377,42.64731,22476,22
154.42880,-4.54781,-49.55003,4.52293,49.55003,22476,22
154.79120,-4.90987,-56.70408,4.88498,56.70408,22476,22
155.15980,-5.27859,-63.99525,5.25371,63.99525,22476,22
155.49380,-5.55166,-69.02286,5.52678,69.02287,22476,22
155.76880,-5.25186,-60.51558,5.22698,60.51558,22412,22
156.05680,-4.96028,-53.15502,4.93540,53.15503,22412,22
156.36380,-4.65254,-45.73827,4.62766,45.73827,22412,22
156.73680,-4.27943,-37.00095,4.25455,37.00095,22412,22
157.14480,-3.87169,-28.70124,3.84681,28.70124,22412,22
157.69119,-3.32543,-19.99972,3.30055,19.99972,22412,22
158.30680,-2.70951,-12.53334,2.68463,12.53334,22412,22
158.85580,-2.36312,-9.53530,2.33824,9.53530,22412,22
159.36780,-2.89202,-18.17396,2.86714,18.17396,22476,23
159.87078,-3.39573,-26.59747,3.37085,26.59747,22476,23
160.27280,-3.79763,-34.64727,3.77275,34.64727,22476,23
160.67180,-4.19652,-42.53432,4.17164,42.53432,22476,23
161.07780,-4.60259,-50.62433,4.57770,50.62433,22476,23
161.48680,-5.01179,-58.56445,4.98691,58.56445,22476,23
161.84380,-5.36862,-65.67790,5.34374,65.67790,22476,23
162.09120,-5.56061,-69.23749,5.53573,69.23750,22476,23
162.35380,-5.27311,-61.08942,5.24822,61.08942,22476,23
162.66880,-4.95401,-52.93060,4.92913,52.93060,22412,23
162.99120,-4.63143,-45.10497,4.60655,45.10497,22412,23
163.39119,-4.23131,-35.83896,4.20643,35.83896,22412,23
163.81680,-3.80531,-27.35107,3.78043,27.35107,22412,23
164.39119,-3.23125,-18.78633,3.20637,18.78633,22412,23
165.04580,-2.57638,-10.96066,2.55150,10.96066,22412,23
165.53080,-2.45070,-11.09681,2.42581,11.09681,22412,23
166.07580,-3.00615,-19.83232,2.98127,19.83232,22476,24
166.50180,-3.43247,-27.18356,3.40759,27.18357,22476,24
166.94680,-3.87749,-36.06287,3.85261,36.06287,22476,24
167.29780,-4.22822,-43.13571,4.20334,43.13571,22476,24
167.70080,-4.63135,-51.18554,4.60647,51.18554,22476,24
168.13680,-5.06744,-59.69207,5.04256,59.69207,22476,24
168.55480,-5.48544,-67.93226,5.46056,67.93226,22476,24
168.89119,-5.31989,-62.26747,5.29501,62.26747,22412,24
169.24080,-4.96392,-53.13098,4.93904,53.13098,22412,24
169.58780,-4.61629,-44.74575,4.59141,44.74575,22412,24
169.92480,-4.27906,-36.93084,4.25418,36.93084,22412,24
170.37580,-3.82820,-27.72589,3.80332,27.72589,22412,24
170.89780,-3.30602,-19.63257,3.28113,19.63257,22412,24
171.56980,-2.63424,-11.61606,2.60936,11.61606,22412,24
172.08580,-2.42357,-10.59989,2.39869,10.59988,22412,24
172.59120,-2.94076,-18.84532,2.91588,18.84532,22476,25
173.09120,-3.44130,-27.30721,3.41642,27.30721,22476,25
173.49120,-3.84127,-35.32158,3.81639,35.32158,22476,25
173.89119,-4.24108,-43.35568,4.21620,43.35569,22476,25
174.32680,-4.67713,-51.97303,4.65225,51.97303,22476,25
174.79120,-5.14123,-61.09500,5.11635,61.09500,22476,25
175.20478,-5.55526,-69.40954,5.53038,69.40954,22476,25
175.48980,-5.31823,-62.19572,5.29335,62.19572,22476,25
175.82280,-4.97980,-53.46400,4.95492,53.46400,22412,25
176.09880,-4.70296,-46.86606,4.67807,46.86605,22412,25
176.46280,-4.33899,-38.23212,4.31411,38.23212,22412,25
176.76880,-4.03308,-31.63206,4.00820,31.63206,22412,25
177.26078,-3.54103,-23.03708,3.51615,23.03708,22412,25
177.86680,-2.93492,-15.04140,2.91004,15.04140,22412,25
178.50780,-2.29376,-7.43440,2.26888,7.43440,22412,25
178.99120,-2.70302,-15.16800,2.67814,15.16800,22476,25
179.49120,-3.20486,-23.16321,3.17998,23.16321,22476,26
179.97080,-3.68487,-32.19220,3.65999,32.19220,22476,26
180.39180,-4.10601,-40.58956,4.08113,40.58956,22476,26
180.84180,-4.55610,-49.52919,4.53122,49.52919,22476,26
181.29120,-5.00518,-58.32278,4.98030,58.32278,22476,26
181.69119,-5.40511,-66.30165,5.38023,66.30165,22476,26
182.01380,-5.43930,-65.44957,5.41442,65.44956,22476,26
182.36280,-5.07813,-55.93535,5.05325,55.93534,22412,26
182.69880,-4.74085,-47.71951,4.71597,47.71951,22412,26
183.08880,-4.35084,-38.44249,4.32596,38.44249,22412,26
183.42380,-4.01589,-31.25614,3.99101,31.25614,22412,26
183.91680,-3.52287,-22.76169,3.49799,22.76169,22412,26
184.54480,-2.89475,-14.52718,2.86987,14.52718,22412,26
185.13378,-2.30553,-7.53957,2.28065,7.53957,22412,26
185.59120,-2.71264,-15.20602,2.68776,15.20602,22476,26
186.09480,-3.21859,-23.29016,3.19371,23.29016,22476,27
186.55880,-3.68264,-31.97693,3.65776,31.97693,22476,27
186.99120,-4.11482,-40.67004,4.08994,40.67004,22476,27
187.39119,-4.51497,-48.71780,4.49009,48.71780,22476,27
187.84380,-4.96794,-57.61395,4.94306,57.61395,22476,27
188.29120,-5.41488,-66.47624,5.39000,66.47624,22476,27
188.59120,-5.45746,-65.91196,5.43258,65.91196,22476,27
188.89119,-5.14465,-57.50913,5.11976,57.50913,22412,27
189.26880,-4.76465,-48.21055,4.73977,48.21055,22412,27
189.63480,-4.39864,-39.46554,4.37376,39.46554,22412,27
190.01680,-4.01665,-31.18683,3.99177,31.18683,22412,27
190.50480,-3.52862,-22.77739,3.50374,22.77739,22412,27
191.12980,-2.90353,-14.58159,2.87865,14.58159,22412,27
191.66880,-2.36459,-8.23551,2.33971,8.23551,22412,27
192.13780,-2.65451,-14.23255,2.62963,14.23255,22604,27
192.66280,-3.18235,-22.67378,3.15747,22.67378,22604,28
193.11780,-3.63745,-31.08032,3.61257,31.08032,22604,28
193.56880,-4.08848,-40.13223,4.06360,40.13223,22604,28
193.96480,-4.48470,-48.15587,4.45982,48.15587,22604,28
194.39878,-4.91863,-56.57031,4.89375,56.57031,22604,28
194.85180,-5.37151,-65.61260,5.34663,65.61260,22604,28
195.13780,-5.53751,-68.13516,5.51263,68.13516,22604,28
195.43480,-5.21938,-59.37269,5.19450,59.37268,22540,28
195.77680,-4.87472,-50.77856,4.84983,50.77856,22540,28
196.14480,-4.50659,-41.92098,4.48171,41.92098,22540,28
196.51280,-4.13843,-33.72915,4.11355,33.72915,22540,28
196.94080,-3.71022,-25.58824,3.68534,25.58824,22540,28
197.50680,-3.14432,-17.44949,3.11944,17.44949,22540,28
198.16580,-2.48553,-9.70604,2.46065,9.70604,22540,28
198.59120,-2.50635,-11.90146,2.48147,11.90145,22540,28
199.11380,-3.03718,-20.13240,3.01230,20.13240,22604,29
199.59478,-3.51851,-28.68697,3.49363,28.68697,22604,29
200.03980,-3.96343,-37.70152,3.93855,37.70152,22604,29
200.46480,-4.38860,-46.09843,4.36372,46.09843,22604,29
200.89119,-4.81440,-54.44898,4.78952,54.44898,22604,29
201.29120,-5.21409,-62.44173,5.18921,62.44173,22604,29
201.68780,-5.58561,-69.72024,5.56073,69.72024,22604,29
201.99120,-5.26024,-60.37660,5.23535,60.37660,22540,29
202.33480,-4.91262,-51.64777,4.88774,51.64777,22540,29
202.68978,-4.55715,-43.11022,4.53227,43.11022,22540,29
203.03080,-4.21605,-35.26337,4.19117,35.26337,22540,29
203.49120,-3.75612,-26.33517,3.73124,26.33517,22540,29
204.05780,-3.18896,-18.05007,3.16408,18.05007,22540,29
204.69119,-2.55619,-10.52595,2.53131,10.52595,22540,29
205.42380,-2.33233,-9.06180,2.30745,9.06180,22540,29
205.93480,-2.85627,-17.57940,2.83139,17.57940,22476,29
206.44580,-3.36776,-26.10191,3.34288,26.10191,22476,30
206.85778,-3.77976,-34.19035,3.75487,34.19035,22476,30
207.29120,-4.21253,-42.77622,4.18765,42.77621,22476,30
207.73480,-4.65663,-51.53882,4.63175,51.53882,22476,30
208.09980,-5.02186,-58.61194,4.99698,58.61194,22476,30
208.48278,-5.40477,-66.25835,5.37989,66.25835,22476,30
208.79280,-5.45732,-65.86097,5.43244,65.86097,22476,30
209.13980,-5.09698,-56.27461,5.07210,56.27461,22412,30
209.48780,-4.74750,-47.82800,4.72262,47.82800,22412,30
209.86680,-4.36852,-38.74407,4.34363,38.74407,22412,30
210.29120,-3.94449,-29.77273,3.91960,29.77273,22412,30
210.79120,-3.44443,-21.44878,3.41955,21.44878,22412,30
211.42080,-2.81430,-13.45438,2.78942,13.45438,22412,30
212.00580,-2.30521,-7.92694,2.28033,7.92694,22412,30
212.49180,-2.81839,-16.76470,2.79351,16.76470,22476,30
213.00280,-3.33040,-25.17836,3.30552,25.17836,22476,31
213.38280,-3.71036,-32.52701,3.68548,32.52702,22476,31
213.80980,-4.13752,-41.09165,4.11264,41.09165,22476,31
214.26180,-4.58945,-50.05867,4.56457,50.05867,22476,31
214.62580,-4.95362,-57.18873,4.92874,57.18873,22476,31
215.07280,-5.40053,-66.07244,5.37565,66.07244,22476,31
215.39119,-5.46331,-65.90941,5.43843,65.90941,22476,31
215.74480,-5.09577,-56.16336,5.07089,56.16336,22412,31
216.10080,-4.73834,-47.52917,4.71346,47.52917,22412,31
216.46480,-4.37438,-38.81568,4.34950,38.81568,22412,31
216.89119,-3.94837,-29.77514,3.92349,29.77514,22412,31
217.39119,-3.44831,-21.44618,3.42343,21.44618,22412,31
217.95580,-2.88329,-14.18044,2.85841,14.18044,22412,31
218.57080,-2.30026,-7.50525,2.27538,7.50525,22412,31
219.03180,-2.78776,-16.12793,2.76288,16.12793,22476,31
219.54780,-3.30507,-24.69485,3.28018,24.69485,22476,32
219.99120,-3.74814,-33.28627,3.72326,33.28627,22476,32
220.44178,-4.19902,-42.24854,4.17414,42.24854,22476,32
220.89119,-4.64811,-51.20974,4.62323,51.20974,22476,32
221.32380,-5.08120,-59.65482,5.05632,59.65482,22476,32
221.76180,-5.51930,-68.44838,5.49442,68.44838,22476,32
222.07080,-5.35544,-62.86999,5.33056,62.86999,22476,32
222.39119,-5.02894,-54.34481,5.00406,54.34481,22412,32
222.75580,-4.66288,-45.50154,4.63800,45.50154,22412,32
223.14480,-4.27383,-36.33582,4.24895,36.33582,22412,32
223.59120,-3.82791,-27.34461,3.80303,27.34461,22412,32
224.13480,-3.28381,-19.14140,3.25893,19.14140,22412,32
224.79120,-2.62798,-11.28674,2.60310,11.28674,22412,32
225.29580,-2.44483,-10.66436,2.41995,10.66436,22412,32
225.83380,-2.99465,-19.34070,2.96977,19.34070,22476,33
226.30880,-3.47004,-27.56384,3.44516,27.56384,22476,33
226.74880,-3.91002,-36.43906,3.88514,36.43906,22476,33
227.10778,-4.26887,-43.64883,4.24398,43.64883,22476,33
227.56180,-4.72284,-52.59042,4.69796,52.59042,22476,33
227.99778,-5.15887,-61.15507,5.13399,61.15507,22476,33
228.41680,-5.57787,-69.57109,5.55299,69.57108,22476,33
228.70080,-5.34213,-62.41526,5.31724,62.41526,22476,33
228.96480,-5.07291,-55.41527,5.04803,55.41527,22412,33
229.29480,-4.74184,-47.42234,4.71696,47.42234,22412,33
229.54580,-4.49100,-41.35530,4.46612,41.35530,22412,33
229.90078,-4.13584,-33.46287,4.11095,33.46287,22412,33
230.33880,-3.69758,-25.20177,3.67270,25.20177,22412,33
230.91578,-3.12075,-17.04909,3.09587,17.04909,22412,33
231.58080,-2.45582,-9.19250,2.43094,9.19250,22412,33
232.04980,-2.59787,-13.16499,2.57299,13.16499,22476,33
232.58080,-3.13353,-21.62699,3.10865,21.62699,22476,34
233.04180,-3.59461,-30.09181,3.56973,30.09181,22476,34
233.49120,-4.04369,-39.15253,4.01881,39.15253,22476,34
233.91780,-4.47082,-47.69972,4.44594,47.69972,22476,34
234.37680,-4.92975,-56.59583,4.90487,56.59583,22476,34
234.77578,-5.32851,-64.53175,5.30362,64.53175,22476,34
235.09580,-5.56186,-68.71758,5.53698,68.71758,22476,34
235.42580,-5.20708,-58.82002,5.18219,58.82001,22412,34
235.79280,-4.83770,-49.68087,4.81282,49.68087,22412,34
236.09278,-4.53753,-42.49220,4.51265,42.49220,22412,34
236.47580,-4.15445,-33.84921,4.12957,33.84921,22412,34
236.84580,-3.78438,-26.52956,3.75950,26.52956,22412,34
237.39119,-3.23932,-18.54358,3.21444,18.54358,22412,34
238.06080,-2.56945,-10.53110,2.54457,10.53110,22412,34
238.56180,-2.50208,-11.66437,2.47720,11.66437,22412,34
239.09119,-3.03925,-19.98645,3.01437,19.98644,22476,35
239.57680,-3.52558,-28.61982,3.50070,28.61982,22476,35
239.99880,-3.94754,-37.18572,3.92266,37.18573,22476,35
240.44680,-4.39565,-46.08141,4.37077,46.08141,22476,35
240.85680,-4.80549,-54.11425,4.78061,54.11425,22476,35
241.29120,-5.23916,-62.73656,5.21428,62.73656,22476,35
241.69780,-5.55746,-68.55437,5.53258,68.55437,22476,35
241.99120,-5.24075,-59.68911,5.21587,59.68911,22412,35
242.32480,-4.90366,-51.24479,4.87878,51.24479,22412,35
242.62780,-4.60029,-43.89214,4.57541,43.89214,22412,35
242.90180,-4.32616,-37.48205,4.30128,37.48205,22412,35
243.27980,-3.94832,-29.61303,3.92344,29.61303,22412,35
243.79078,-3.43727,-21.11300,3.41239,21.11300,22412,35
244.39119,-2.83717,-13.52035,2.81228,13.52035,22412,35
244.97280,-2.30005,-7.46976,2.27517,7.46976,22412,35
245.44178,-2.79695,-16.20062,2.77207,16.20062,22476,35
245.95180,-3.30814,-24.62264,3.28326,24.62264,22476,36
246.39119,-3.74722,-33.13335,3.72234,33.13335,22476,36
246.79180,-4.14827,-41.12125,4.12339,41.12125,22476,36
247.17180,-4.52838,-48.68614,4.50350,48.68614,22476,36
247.59678,-4.95336,-57.04746,4.92848,57.04745,22476,36
247.92280,-5.27903,-63.48292,5.25414,63.48292,22476,36
248.29580,-5.56546,-68.75213,5.54058,68.75213,22476,36
248.56678,-5.27108,-60.43680,5.24620,60.43680,22412,36
248.89119,-4.94354,-52.14554,4.91865,52.14555,22412,36
249.28080,-4.55305,-42.81243,4.52817,42.81243,22412,36
249.65680,-4.17693,-34.22246,4.15205,34.22246,22412,36
250.09119,-3.74297,-25.88069,3.71809,25.88069,22412,36
250.65580,-3.17787,-17.64540,3.15299,17.64540,22412,36
251.30880,-2.52508,-10.05818,2.50020,10.05818,22412,36
251.77980,-2.51027,-11.73689,2.48539,11.73689,22412,36
252.29120,-3.02884,-19.77071,3.00396,19.77071,22476,37
252.78180,-3.52016,-28.53183,3.49528,28.53183,22476,37
253.18480,-3.92311,-36.60730,3.89823,36.60730,22476,37
253.61680,-4.35511,-45.18550,4.33023,45.18549,22476,37
254.06478,-4.80309,-54.03527,4.77821,54.03527,22476,37
254.51078,-5.24877,-62.63784,5.22389,62.63784,22476,37
254.93280,-5.57548,-68.88785,5.55060,68.88786,22476,37
255.24978,-5.23475,-59.39797,5.20987,59.39796,22412,37
255.60480,-4.87719,-50.49463,4.85231,50.49463,22412,37
255.99120,-4.49109,-41.22522,4.46621,41.22522,22412,37
256.38880,-4.09297,-32.37038,4.06809,32.37038,22412,37
256.83481,-3.64676,-24.21258,3.62188,24.21258,22412,37
257.43478,-3.04685,-15.99650,3.02197,15.99650,22412,37
258.09119,-2.39092,-8.28649,2.36604,8.28649,22412,37
258.54581,-2.66853,-14.10210,2.64365,14.10210,22604,37
259.07080,-3.19661,-22.56335,3.17173,22.56335,22604,38
259.53080,-3.65670,-31.11644,3.63181,31.11644,22604,38
259.92578,-4.05187,-39.19085,4.02699,39.19085,22604,38
260.31778,-4.44397,-47.06538,4.41909,47.06538,22604,38
260.75878,-4.88494,-55.62330,4.86006,55.62329,22604,38
261.17578,-5.30166,-63.94850,5.27678,63.94850,22604,38
261.56878,-5.52454,-67.32448,5.49966,67.32448,22604,38
261.86178,-5.21431,-58.84396,5.18943,58.84396,22540,38
262.21681,-4.85697,-49.93841,4.83209,49.93841,22540,38
262.53378,-4.53976,-42.37122,4.51488,42.37122,22540,38
262.89381,-4.17958,-34.17388,4.15470,34.17389,22540,38
263.19078,-3.88281,-28.14615,3.85793,28.14615,22540,38
263.69981,-3.37372,-20.06233,3.34884,20.06233,22540,38
264.36978,-2.70362,-12.02066,2.67874,12.02066,22540,38
264.89122,-2.40418,-9.60683,2.37930,9.60683,22540,38
265.39778,-2.92700,-18.20157,2.90212,18.20157,22604,38
265.86178,-3.39169,-26.02735,3.36681,26.02735,22604,39
266.26481,-3.79462,-34.02479,3.76974,34.02480,22604,39
266.69119,-4.22041,-42.56110,4.19553,42.56110,22604,39
267.14481,-4.67448,-51.49949,4.64960,51.49949,22604,39
267.59119,-5.12054,-60.24961,5.09566,60.24961,22604,39
267.99119,-5.52072,-68.22906,5.49584,68.22906,22604,39
268.29119,-5.37248,-63.10874,5.34760,63.10874,22604,39
268.60481,-5.05137,-54.76771,5.02649,54.76771,22540,39
268.95081,-4.70427,-46.33151,4.67939,46.33151,22540,39
269.33078,-4.32423,-37.29130,4.29935,37.29130,22540,39
269.71578,-3.93940,-29.23514,3.91452,29.23514,22540,39
270.24478,-3.41034,-20.59571,3.38546,20.59571,22540,39
270.89122,-2.76434,-12.64219,2.73945,12.64219,22540,39
271.59119,-2.30203,-7.74362,2.27715,7.74362,22540,39
272.09078,-2.67970,-14.61646,2.65482,14.61646,22476,39
272.59281,-3.18324,-22.59608,3.15836,22.59608,22476,40
273.07981,-3.67021,-31.62070,3.64533,31.62070,22476,40
273.51178,-4.10238,-40.21718,4.07750,40.21717,22476,40
273.89578,-4.48650,-48.01914,4.46162,48.01914,22476,40
274.36481,-4.95547,-57.04904,4.93058,57.04904,22476,40
274.79678,-5.38738,-65.64517,5.36250,65.64517,22476,40
275.13981,-5.46476,-65.73460,5.43988,65.73460,22476,40
275.47681,-5.11481,-56.43208,5.08993,56.43208,22412,40
275.84281,-4.74723,-47.51039,4.72234,47.51039,22412,40
276.23278,-4.35723,-38.19113,4.33235,38.19113,22412,40
276.64678,-3.94321,-29.36938,3.91833,29.36938,22412,40
277.17881,-3.41119,-20.64806,3.38631,20.64806,22412,40
277.79119,-2.79905,-13.01551,2.77417,13.01551,22412,40
278.37078,-2.38516,-9.07218,2.36028,9.07218,22412,40
278.87078,-2.90433,-17.72904,2.87945,17.72904,22476,40
279.36178,-3.39615,-26.04762,3.37127,26.04762,22476,41
279.76881,-3.80307,-34.16139,3.77818,34.16139,22476,41
280.16581,-4.19997,-42.08339,4.17509,42.08339,22476,41
280.57378,-4.60800,-50.18188,4.58312,50.18188,22476,41
280.92678,-4.96118,-57.06050,4.93630,57.06049,22476,41
281.32481,-5.35900,-65.05830,5.33412,65.05830,22476,41
281.65781,-5.54337,-67.77087,5.51849,67.77087,22476,41
281.96178,-5.22050,-58.94485,5.19562,58.94485,22412,41
282.32878,-4.85111,-49.72911,4.82623,49.72911,22412,41
282.70481,-4.47506,-40.69476,4.45018,40.69476,22412,41
283.10981,-4.06989,-31.72394,4.04501,31.72394,22412,41
283.59119,-3.58883,-23.17659,3.56395,23.17659,22412,41
284.20881,-2.97088,-15.00145,2.94600,15.00145,22412,41
284.85081,-2.32871,-7.37945,2.30383,7.37945,22412,41
285.30881,-2.74276,-15.21373,2.71788,15.21373,22476,41
285.82878,-3.26471,-23.68498,3.23983,23.68498,22476,42
286.29119,-3.72674,-32.51446,3.70185,32.51447,22476,42
286.71681,-4.15287,-41.05320,4.12799,41.05320,22476,42
287.11881,-4.55489,-49.10273,4.53001,49.10273,22476,42
287.53378,-4.96996,-57.17589,4.94508,57.17589,22476,42
287.97981,-5.41589,-66.11164,5.39101,66.11164,22476,42
288.32878,-5.44297,-64.96124,5.41809,64.96124,22476,42
288.67678,-5.08400,-55.50431,5.05912,55.50431,22412,42
289.04881,-4.71073,-46.45303,4.68585,46.45303,22412,42
289.43781,-4.32167,-37.15408,4.29679,37.15408,22412,42
289.86481,-3.89485,-28.23456,3.86997,28.23456,22412,42
290.39122,-3.36876,-19.76996,3.34388,19.76995,22412,42
291.04081,-2.71870,-12.12142,2.69382,12.12142,22412,42
291.59119,-2.40708,-9.64052,2.38220,9.64052,22412,42
292.10081,-2.93208,-18.19044,2.90720,18.19044,22476,42
292.60181,-3.43371,-26.68520,3.40883,26.68520,22476,43
292.99781,-3.82964,-34.66627,3.80476,34.66627,22476,43
293.44278,-4.27457,-43.53807,4.24969,43.53807,22476,43
293.84578,-4.67753,-51.51581,4.65265,51.51581,22476,43
294.20678,-5.03876,-58.52674,5.01388,58.52674,22476,43
294.58881,-5.42072,-66.20052,5.39584,66.20052,22476,43
294.86881,-5.53036,-67.36246,5.50548,67.36246,22476,43
295.19119,-5.19065,-58.13801,5.16577,58.13801,22412,43
295.56378,-4.81568,-48.85845,4.79080,48.85845,22412,43
295.94678,-4.43258,-39.68757,4.40770,39.68756,22412,43
296.28378,-4.09562,-32.21776,4.07074,32.21775,22412,43
296.75778,-3.62145,-23.62670,3.59657,23.62670,22412,43
297.36381,-3.01555,-15.50795,2.99066,15.50795,22412,43
298.00181,-2.37755,-8.00239,2.35267,8.00239,22412,43
298.46478,-2.71168,-14.66611,2.68680,14.66611,22476,43
298.98678,-3.23621,-23.13636,3.21133,23.13636,22476,44
299.38081,-3.63033,-30.50637,3.60544,30.50637,22476,44
299.79119,-4.04043,-38.85017,4.01555,38.85017,22476,44
300.22778,-4.47757,-47.61534,4.45269,47.61534,22476,44
300.63878,-4.88851,-55.58264,4.86363,55.58264,22476,44
301.04581,-5.29522,-63.62925,5.27034,63.62925,22476,44
301.40978,-5.58348,-68.98049,5.55860,68.98049,22476,44
301.71381,-5.25456,-59.73517,5.22968,59.73517,22412,44
302.00778,-4.95774,-52.28306,4.93286,52.28305,22412,44
302.35081,-4.61422,-43.95355,4.58933,43.95355,22412,44
302.63678,-4.32811,-37.28992,4.30323,37.28992,22412,44
303.01578,-3.94924,-29.23757,3.92436,29.23757,22412,44
303.54981,-3.41520,-20.52489,3.39032,20.52489,22412,44
304.19119,-2.77415,-12.62993,2.74927,12.62993,22412,44
304.69378,-2.34470,-7.99449,2.31982,7.99449,22412,44
305.19119,-2.86915,-17.05598,2.84427,17.05598,22476,44
305.69119,-3.37017,-25.49068,3.34529,25.49068,22476,45
306.12681,-3.80614,-34.14977,3.78126,34.14977,22476,45
306.57878,-4.25803,-43.13584,4.23315,43.13584,22476,45
307.00478,-4.68400,-51.57822,4.65912,51.57822,22476,45
307.46078,-5.14010,-60.53458,5.11522,60.53458,22476,45
307.81478,-5.49425,-67.58534,5.46936,67.58534,22476,45
308.12681,-5.40544,-63.84113,5.38056,63.84113,22476,45
308.48481,-5.03884,-54.24212,5.01396,54.24212,22412,45
308.84181,-4.68079,-45.54311,4.65591,45.54311,22412,45
309.19581,-4.32686,-37.25958,4.30198,37.25958,22412,45
309.56681,-3.95601,-29.33767,3.93112,29.33767,22412,45
310.06578,-3.45695,-21.14311,3.43207,21.14311,22412,45
310.69119,-2.83184,-13.24960,2.80696,13.24960,22412,45
311.28281,-2.35981,-8.38848,2.33493,8.38848,22412,45
311.77478,-2.87495,-17.15890,2.85007,17.15890,22476,45
312.27978,-3.38093,-25.66118,3.35605,25.66118,22476,46
312.68578,-3.78688,-33.72137,3.76200,33.72137,22476,46
313.09978,-4.20071,-41.97830,4.17583,41.97830,22476,46
313.50581,-4.60679,-50.02034,4.58191,50.02034,22476,46
313.96978,-5.07087,-59.14737,5.04599,59.14737,22476,46
314.39122,-5.49196,-67.51727,5.46707,67.51727,22476,46
314.70378,-5.41247,-63.98483,5.38759,63.98483,22476,46
315.06478,-5.04260,-54.33369,5.01772,54.33369,22412,46
315.43078,-4.67557,-45.41865,4.65068,45.41865,22412,46
315.79081,-4.31558,-36.92441,4.29070,36.92441,22412,46
316.19981,-3.90682,-28.36495,3.88194,28.36494,22412,46
316.75681,-3.34966,-19.55763,3.32478,19.55763,22412,46
317.39122,-2.71566,-11.97167,2.69078,11.97167,22412,46
317.92278,-2.44098,-10.03820,2.41610,10.03820,22412,46
318.44181,-2.97424,-18.72249,2.94936,18.72249,22476,47
318.92578,-3.45879,-27.01755,3.43391,27.01755,22476,47
319.32778,-3.86081,-35.16985,3.83593,35.16985,22476,47
319.69119,-4.22356,-42.42238,4.19868,42.42238,22476,47
320.04778,-4.58069,-49.45474,4.55581,49.45475,22476,47
320.38278,-4.91586,-56.03460,4.89098,56.03460,22476,47
320.80781,-5.34063,-64.49922,5.31575,64.49922,22476,47
321.14078,-5.54930,-67.92717,5.52442,67.92718,22476,47
321.47181,-5.19690,-58.22035,5.17202,58.22035,22412,47
321.79678,-4.86991,-50.13922,4.84502,50.13922,22412,47
322.13778,-4.52870,-41.93167,4.50382,41.93167,22412,47
322.53478,-4.13170,-32.86944,4.10682,32.86943,22412,47
323.00878,-3.65744,-24.07314,3.63255,24.07314,22412,47
323.59119,-3.07555,-16.08110,3.05067,16.08110,22412,47
324.26881,-2.39762,-8.10829,2.37274,8.10829,22412,47
324.73178,-2.69144,-14.21185,2.66656,14.21185,22604,47
325.24978,-3.21230,-22.64022,3.18742,22.64022,22604,48
325.70481,-3.66736,-31.17905,3.64248,31.17905,22604,48
326.15578,-4.11856,-40.22634,4.09368,40.22634,22604,48
326.59119,-4.55358,-48.98677,4.52870,48.98677,22604,48
327.03281,-4.99566,-57.56005,4.97078,57.56005,22604,48
327.39122,-5.35345,-64.81819,5.32857,64.81819,22604,48
327.69119,-5.59461,-69.27347,5.56973,69.27347,22604,48
327.99119,-5.26898,-60.05946,5.24410,60.05946,22540,48
328.35481,-4.90171,-50.83911,4.87683,50.83912,22540,48
328.67178,-4.58436,-43.21900,4.55948,43.21901,22540,48
329.02478,-4.23124,-34.90987,4.20636,34.90987,22540,48
329.40478,-3.85139,-27.21821,3.82651,27.21821,22540,48
329.97478,-3.28116,-18.70888,3.25628,18.70888,22540,48
330.62578,-2.63035,-10.91711,2.60547,10.91711,22540,48
331.14078,-2.50977,-11.25709,2.48489,11.25709,22540,48
331.66678,-3.04505,-19.76337,3.02017,19.76337,22604,49
332.13678,-3.51544,-28.09940,3.49056,28.09940,22604,49
332.52878,-3.90740,-36.03603,3.88252,36.03603,22604,49
332.93078,-4.30928,-44.07689,4.28440,44.07689,22604,49
333.29119,-4.66924,-51.26204,4.64436,51.26204,22604,49
333.74678,-5.12529,-60.16628,5.10041,60.16628,22604,49
334.14578,-5.52441,-68.12968,5.49953,68.12968,22604,49
334.43378,-5.40345,-63.68203,5.37857,63.68203,22604,49
334.76278,-5.06621,-54.88001,5.04133,54.88001,22540,49
335.13478,-4.69304,-45.79593,4.66816,45.79593,22540,49
335.51178,-4.31602,-36.85210,4.29114,36.85210,22540,49
335.82378,-4.00427,-30.19331,3.97939,30.19331,22540,49
336.34078,-3.48728,-21.45729,3.46240,21.45729,22540,49
336.89122,-2.93706,-14.39054,2.91218,14.39054,22540,49
337.59119,-2.31304,-7.36327,2.28816,7.36327,22540,49
338.23881,-2.67160,-14.20627,2.64672,14.20627,22476,49
338.76178,-3.19635,-22.63968,3.17147,22.63968,22476,49
339.21878,-3.65341,-31.05789,3.62853,31.05789,22476,50
339.66278,-4.09751,-39.97948,4.07263,39.97948,22476,50
340.06281,-4.49771,-48.05434,4.47283,48.05434,22476,50
340.48178,-4.91662,-56.12366,4.89174,56.12366,22476,50
340.88081,-5.31539,-63.99789,5.29051,63.99789,22476,50
341.23578,-5.55492,-68.11989,5.53004,68.11989,22476,50
341.53478,-5.23444,-59.21203,5.20956,59.21203,22412,50
341.83478,-4.93176,-51.64564,4.90688,51.64565,22412,50
342.17881,-4.58741,-43.34375,4.56253,43.34375,22412,50
342.49119,-4.27518,-35.92385,4.25030,35.92385,22412,50
342.89122,-3.87545,-27.67786,3.85057,27.67786,22412,50
343.40281,-3.36336,-19.70124,3.33848,19.70124,22412,50
344.07581,-2.69023,-11.64451,2.66535,11.64451,22412,50
344.59119,-2.47441,-10.52364,2.44952,10.52364,22412,50
345.09119,-2.98691,-18.89283,2.96203,18.89283,22476,51
345.59078,-3.48745,-27.55854,3.46257,27.55854,22476,51
345.98578,-3.88245,-35.53256,3.85757,35.53256,22476,51
346.38778,-4.28431,-43.56149,4.25943,43.56149,22476,51
346.80878,-4.70525,-51.90159,4.68036,51.90158,22476,51
347.22181,-5.11837,-60.01578,5.09349,60.01577,22476,51
347.59119,-5.48749,-67.37987,5.46260,67.37987,22476,51
347.89178,-5.43119,-64.43771,5.40631,64.43771,22476,51
348.20778,-5.10567,-55.92641,5.08079,55.92641,22412,51
348.55781,-4.75432,-47.32590,4.72944,47.32590,22412,51
348.89122,-4.42132,-39.37007,4.39644,39.37007,22412,51
349.27978,-4.03234,-30.68087,4.00746,30.68087,22412,51
349.67778,-3.63418,-23.63945,3.60930,23.63945,22412,51
350.27781,-3.03426,-15.53279,3.00938,15.53279,22412,51
350.91378,-2.39827,-8.07905,2.37339,8.07905,22412,51
351.38278,-2.71850,-14.59664,2.69362,14.59664,22476,51
351.89122,-3.22901,-22.92174,3.20413,22.92174,22476,52
352.30381,-3.64216,-30.67431,3.61728,30.67431,22476,52
352.74978,-4.08824,-39.71295,4.06336,39.71296,22476,52
353.19119,-4.52942,-48.45799,4.50454,48.45799,22476,52
353.63581,-4.97435,-57.10517,4.94947,57.10517,22476,52
354.07981,-5.41829,-65.99854,5.39341,65.99854,22476,52
354.40578,-5.48917,-66.03164,5.46428,66.03164,22476,52
354.75478,-5.12661,-56.34519,5.10173,56.34519,22412,52
355.09119,-4.78909,-48.15718,4.76421,48.15718,22412,52
355.48578,-4.39414,-38.73613,4.36926,38.73613,22412,52
355.79178,-4.08814,-31.76097,4.06326,31.76097,22412,52
356.29119,-3.58899,-22.90384,3.56411,22.90384,22412,52
356.89122,-2.98908,-15.00395,2.96420,15.00395,22412,52
357.52278,-2.35706,-7.51756,2.33218,7.51756,22412,52
357.99119,-2.78122,-15.52124,2.75634,15.52124,22476,52
358.49119,-3.28306,-23.80315,3.25818,23.80315,22476,53
358.90178,-3.69399,-31.58551,3.66910,31.58551,22476,53
359.30078,-4.09315,-39.66112,4.06827,39.66112,22476,53
359.69878,-4.49134,-47.73498,4.46646,47.73498,22476,53
360.10481,-4.89725,-55.61651,4.87237,55.61651,22476,53
360.56281,-5.35507,-64.68949,5.33019,64.68949,22476,53
360.91081,-5.54794,-67.63268,5.52306,67.63268,22476,53
361.24781,-5.19200,-57.92798,5.16712,57.92798,22412,53
361.61278,-4.82517,-48.90453,4.80029,48.90453,22412,53
361.99678,-4.44108,-39.51709,4.41620,39.51709,22412,53
362.40478,-4.03305,-30.57189,4.00817,30.57190,22412,53
362.91378,-3.52409,-21.94942,3.49921,21.94942,22412,53
363.52078,-2.91694,-14.06400,2.89206,14.06400,22412,53
364.12978,-2.33849,-7.61375,2.31361,7.61375,22412,53
364.60981,-2.84477,-16.47783,2.81989,16.47783,22476,53
365.10278,-3.33903,-24.78337,3.31415,24.78337,22476,54
365.55278,-3.78912,-33.59861,3.76424,33.59861,22476,54
365.94778,-4.18401,-41.45782,4.15913,41.45782,22476,54
366.39122,-4.62706,-50.30935,4.60217,50.30935,22476,54
366.83578,-5.07212,-59.01596,5.04724,59.01596,22476,54
367.29119,-5.52720,-68.16018,5.50232,68.16018,22476,54
367.58278,-5.42052,-64.00014,5.39564,64.00014,22476,54
367.89122,-5.10424,-55.73863,5.07936,55.73863,22412,54
368.24078,-4.75299,-47.19486,4.72811,47.19486,22412,54
368.61478,-4.37905,-38.30982,4.35417,38.30981,22412,54
368.99119,-4.00310,-30.09039,3.97822,30.09039,22412,54
369.45378,-3.53997,-22.14104,3.51509,22.14104,22412,54
370.07878,-2.91490,-14.00111,2.89002,14.00111,22412,54
370.68178,-2.34247,-7.43980,2.31759,7.43980,22412,54
371.14178,-2.82857,-16.24697,2.80369,16.24697,22476,54
371.64078,-3.32896,-24.62258,3.30408,24.62258,22476,55
372.04881,-3.73700,-32.61972,3.71212,32.61972,22476,55
372.49119,-4.17902,-41.40723,4.15414,41.40723,22476,55
372.85378,-4.54218,-48.60089,4.51730,48.60089,22476,55
373.27678,-4.96518,-56.92808,4.94030,56.92808,22476,55
373.67078,-5.35902,-64.78469,5.33414,64.78469,22476,55
374.00978,-5.54287,-67.53193,5.51799,67.53193,22476,55
374.30278,-5.23174,-58.99747,5.20686,58.99747,22412,55
374.68681,-4.84518,-49.35978,4.82030,49.35978,22412,55
374.99119,-4.54093,-42.05960,4.51604,42.05960,22412,55
375.38878,-4.14295,-32.89447,4.11807,32.89447,22412,55
375.85581,-3.67572,-24.17565,3.65084,24.17565,22412,55
376.44278,-3.08885,-16.13815,3.06397,16.13815,22412,55
377.09119,-2.44090,-8.49587,2.41602,8.49587,22412,55
377.58678,-2.69978,-14.20983,2.67490,14.20983,22476,55
378.09119,-3.20665,-22.36042,3.18177,22.36042,22476,56
378.55178,-3.66776,-31.04042,3.64288,31.04041,22476,56
378.89381,-4.00998,-38.06204,3.98510,38.06204,22476,56
379.29119,-4.40707,-46.00598,4.38219,46.00597,22476,56
379.70378,-4.81993,-54.05426,4.79505,54.05426,22476,56
380.08781,-5.20361,-61.65426,5.17873,61.65426,22476,56
380.49119,-5.60580,-69.74290,5.58092,69.74290,22476,56
380.80678,-5.29909,-60.74935,5.27421,60.74935,22412,56
381.16678,-4.93509,-51.56377,4.91021,51.56377,22412,56
381.50278,-4.59873,-43.44032,4.57385,43.44032,22412,56
381.89178,-4.20953,-34.34111,4.18465,34.34111,22412,56
382.36078,-3.74062,-25.20394,3.71574,25.20394,22412,56
382.93578,-3.16557,-17.05122,3.14069,17.05122,22412,56
383.59119,-2.51078,-9.37372,2.48590,9.37372,22412,56
383.99119,-2.53392,-11.56307,2.50904,11.56307,22412,56
384.50181,-3.05341,-19.77049,3.02853,19.77049,22476,57
384.99119,-3.54273,-28.49076,3.51785,28.49076,22476,57
385.41181,-3.96368,-37.07881,3.93880,37.07881,22476,57
385.80878,-4.36074,-44.99386,4.33586,44.99386,22476,57
386.27381,-4.82569,-54.14936,4.80081,54.14936,22476,57
386.70278,-5.25443,-62.67874,5.22954,62.67874,22476,57
387.11278,-5.57785,-68.64186,5.55297,68.64185,22476,57
387.43781,-5.22829,-58.91242,5.20341,58.91242,22412,57
387.79678,-4.86679,-49.87071,4.84191,49.87071,22412,57
388.18681,-4.47668,-40.47965,4.45180,40.47965,22412,57
388.59119,-4.07253,-31.30017,4.04764,31.30017,22412,57
389.08978,-3.57343,-22.53244,3.54855,22.53244,22412,57
389.69119,-2.97250,-14.67092,2.94762,14.67092,22412,57
390.30078,-2.36250,-7.49714,2.33762,7.49714,22412,57
390.78681,-2.80493,-15.76541,2.78005,15.76541,22604,57
391.29119,-3.31051,-24.11816,3.28563,24.11816,22604,58
391.71781,-3.73759,-32.39517,3.71271,32.39516,22604,58
392.16878,-4.18855,-41.50119,4.16366,41.50119,22604,58
392.52578,-4.54575,-48.69216,4.52087,48.69216,22604,58
392.93078,-4.95072,-56.60546,4.92584,56.60546,22604,58
393.33278,-5.35256,-64.63613,5.32768,64.63613,22604,58
393.63878,-5.59773,-69.19614,5.57285,69.19614,22604,58
393.91678,-5.29465,-60.56606,5.26977,60.56606,22540,58
394.25278,-4.95498,-52.00377,4.93010,52.00378,22540,58
394.57481,-4.63250,-44.17964,4.60762,44.17965,22540,58
394.89122,-4.31636,-36.74461,4.29147,36.74461,22540,58
395.20078,-4.00668,-29.99562,3.98180,29.99562,22540,58
395.72378,-3.48362,-21.18561,3.45874,21.18561,22540,58
396.37281,-2.83438,-13.01536,2.80950,13.01536,22540,58
396.92381,-2.39488,-8.52345,2.37000,8.52345,22540,58
397.40378,-2.89873,-17.19564,2.87385,17.19564,22604,58
397.89178,-3.38782,-25.54376,3.36294,25.54376,22604,59
398.34878,-3.84476,-34.62929,3.81988,34.62929,22604,59
398.79119,-4.28666,-43.50029,4.26178,43.50029,22604,59
399.14478,-4.64066,-50.55948,4.61578,50.55948,22604,59
399.59119,-5.08671,-59.29254,5.06183,59.29254,22604,59
400.03878,-5.53480,-68.19057,5.50992,68.19057,22604,59
400.31681,-5.42030,-63.97768,5.39542,63.97768,22604,59
400.61781,-5.11092,-55.86404,5.08604,55.86404,22540,59
400.94581,-4.78158,-47.83818,4.75670,47.83818,22540,59
401.19119,-4.53661,-41.86903,4.51173,41.86903,22540,59
401.59119,-4.13662,-32.66577,4.11174,32.66577,22540,59
402.00478,-3.72246,-24.85191,3.69758,24.85192,22540,59
402.59119,-3.13651,-16.58687,3.11163,16.58687,22540,59
403.27078,-2.45661,-8.67033,2.43173,8.67033,22540,59
403.39122,-2.33761,-7.14204,2.31273,7.14204,22540,59