File: data-raw/Experiment 2/Results/INSTRON data/Experiment 2.is_ccyclic_RawData/Specimen_RawData_19.csv
Text Inputs : Specimen label,"Long Plate 1 Test 5"

Time,Extension,Load,Compressive extension,Compressive load,Segment ID,Total Cycle Count
(sec),(mm),(N),(mm),(N),,
0.00000,-0.02626,-0.02170,0.00000,0.02170,12835,0
2.02580,-0.47286,-0.15647,0.44660,0.15647,3220,0
2.71580,-0.81770,-6.63926,0.79144,6.63926,3220,0
3.19080,-1.28177,-14.66389,1.25551,14.66389,22476,0
3.66820,-1.75933,-23.03865,1.73306,23.03865,22476,0
4.06080,-2.15234,-31.36135,2.12608,31.36135,22476,0
4.38480,-2.47619,-38.99805,2.44993,38.99805,22476,0
4.74580,-2.83724,-47.46336,2.81098,47.46336,22476,0
5.10080,-3.19240,-55.40979,3.16614,55.40979,22476,0
5.45080,-3.54236,-63.46659,3.51609,63.46659,22476,0
5.77580,-3.80405,-69.05996,3.77779,69.05996,22476,0
6.05480,-3.50042,-59.55285,3.47416,59.55285,22412,0
6.36820,-3.18374,-50.35064,3.15748,50.35064,22412,0
6.68380,-2.86705,-41.76678,2.84079,41.76678,22412,0
7.04780,-2.50315,-32.68252,2.47689,32.68252,22412,0
7.42780,-2.12317,-24.02784,2.09691,24.02784,22412,0
7.87680,-1.67430,-16.04305,1.64804,16.04305,22412,0
8.38680,-1.16421,-8.05786,1.13795,8.05785,22412,0
8.76820,-1.43516,-13.96504,1.40890,13.96504,22412,0
9.21280,-1.88390,-22.56735,1.85764,22.56735,22476,1
9.56080,-2.23225,-30.23849,2.20599,30.23849,22476,1
9.91580,-2.58732,-38.96738,2.56106,38.96738,22476,1
10.23680,-2.90818,-46.85555,2.88192,46.85555,22476,1
10.59780,-3.26921,-55.58175,3.24295,55.58175,22476,1
10.95280,-3.62433,-64.23036,3.59807,64.23036,22476,1
11.26820,-3.79699,-67.64767,3.77073,67.64767,22476,1
11.55480,-3.49128,-58.29072,3.46502,58.29072,22412,1
11.82980,-3.21358,-50.31843,3.18732,50.31844,22412,1
12.13480,-2.90810,-42.10413,2.88184,42.10413,22412,1
12.42880,-2.61410,-34.73031,2.58784,34.73031,22412,1
12.76980,-2.27316,-26.54118,2.24690,26.54119,22412,1
13.21780,-1.82495,-18.10485,1.79869,18.10485,22412,1
13.72780,-1.31497,-10.12802,1.28871,10.12802,22412,1
14.12780,-1.35077,-12.03893,1.32451,12.03893,22412,1
14.56820,-1.79881,-20.29880,1.77255,20.29880,22476,2
14.96820,-2.19927,-28.91412,2.17301,28.91412,22476,2
15.26820,-2.49923,-36.23794,2.47297,36.23794,22476,2
15.64480,-2.87614,-45.40493,2.84988,45.40493,22476,2
15.98180,-3.21330,-53.67050,3.18704,53.67049,22476,2
16.31580,-3.54734,-61.85418,3.52108,61.85418,22476,2
16.66820,-3.88420,-70.06685,3.85794,70.06686,22476,2
16.94180,-3.59420,-60.88613,3.56794,60.88613,22412,2
17.24980,-3.28165,-51.73703,3.25539,51.73703,22412,2
17.56820,-2.96287,-43.14478,2.93660,43.14478,22412,2
17.91580,-2.61493,-34.33702,2.58867,34.33702,22412,2
18.28680,-2.24393,-25.62519,2.21767,25.62519,22412,2
18.75580,-1.77507,-17.02062,1.74881,17.02062,22412,2
19.26820,-1.26288,-9.00238,1.23662,9.00238,22412,2
19.66820,-1.42356,-13.04091,1.39730,13.04091,22476,2
20.09180,-1.85261,-21.11755,1.82635,21.11755,22476,3
20.47480,-2.23609,-29.43292,2.20983,29.43292,22476,3
20.84180,-2.60321,-38.49284,2.57695,38.49284,22476,3
21.17680,-2.93812,-46.67310,2.91186,46.67310,22476,3
21.54880,-3.31011,-55.73895,3.28385,55.73895,22476,3
21.90380,-3.66524,-64.43474,3.63898,64.43474,22476,3
22.22180,-3.81903,-67.44200,3.79277,67.44200,22476,3
22.46180,-3.56301,-59.60032,3.53675,59.60032,22412,3
22.72080,-3.30068,-51.96431,3.27442,51.96431,22412,3
23.02180,-2.99902,-43.76001,2.97276,43.76001,22412,3
23.26820,-2.75299,-37.55500,2.72673,37.55500,22412,3
23.60080,-2.41996,-29.31641,2.39370,29.31641,22412,3
23.99880,-2.02204,-21.04678,1.99578,21.04678,22412,3
24.49580,-1.52493,-12.88907,1.49867,12.88907,22412,3
24.94680,-1.22301,-8.84991,1.19675,8.84991,22412,3
25.36820,-1.66411,-17.30618,1.63785,17.30618,22476,3
25.77380,-2.07128,-25.50002,2.04502,25.50002,22476,4
26.14580,-2.44318,-34.32752,2.41692,34.32752,22476,4
26.49280,-2.79022,-42.78036,2.76396,42.78036,22476,4
26.82680,-3.12434,-50.98125,3.09808,50.98125,22476,4
27.17480,-3.47228,-59.43698,3.44602,59.43699,22476,4
27.53880,-3.83621,-68.33869,3.80995,68.33869,22476,4
27.80780,-3.69210,-63.33488,3.66584,63.33488,22476,4
28.10380,-3.38822,-54.26577,3.36196,54.26577,22412,4
28.36820,-3.12323,-46.87070,3.09697,46.87070,22412,4
28.70380,-2.78698,-38.26343,2.76071,38.26342,22412,4
28.97980,-2.51100,-31.26024,2.48474,31.26024,22412,4
29.30780,-2.18300,-23.99646,2.15674,23.99646,22412,4
29.76820,-1.72308,-15.86663,1.69682,15.86663,22412,4
30.26820,-1.22283,-7.99673,1.19657,7.99673,22412,4
30.66820,-1.49942,-14.07323,1.47316,14.07323,22476,4
31.10680,-1.94200,-22.54700,1.91574,22.54700,22476,5
31.47880,-2.31422,-30.84563,2.28796,30.84563,22476,5
31.76820,-2.60332,-38.06724,2.57706,38.06724,22476,5
32.09380,-2.92921,-46.01456,2.90295,46.01456,22476,5
32.38480,-3.22028,-53.04784,3.19402,53.04784,22476,5
32.70180,-3.53735,-60.87376,3.51109,60.87376,22476,5
33.04980,-3.88516,-69.41828,3.85890,69.41828,22476,5
33.31780,-3.66215,-62.13765,3.63589,62.13765,22476,5
33.56820,-3.40634,-54.51149,3.38008,54.51149,22412,5
33.86180,-3.11118,-46.38202,3.08492,46.38203,22412,5
34.16820,-2.80497,-38.53004,2.77870,38.53004,22412,5
34.40980,-2.56301,-32.44990,2.53675,32.44990,22412,5
34.68080,-2.29196,-26.08516,2.26570,26.08516,22412,5
35.13580,-1.83679,-17.62730,1.81053,17.62729,22412,5
35.64580,-1.32682,-9.65885,1.30055,9.65885,22412,5
36.05780,-1.42460,-12.62291,1.39834,12.62291,22476,5
36.47680,-1.84961,-20.55259,1.82335,20.55259,22476,6
36.86820,-2.24113,-29.00528,2.21487,29.00528,22476,6
37.23180,-2.60527,-37.96460,2.57901,37.96460,22476,6
37.57780,-2.95114,-46.36972,2.92488,46.36972,22476,6
37.90480,-3.27813,-54.36119,3.25187,54.36119,22476,6
38.23280,-3.60620,-62.46692,3.57994,62.46692,22476,6
38.56880,-3.91318,-69.96043,3.88692,69.96043,22476,6
38.82380,-3.63671,-61.17518,3.61045,61.17518,22412,6
39.08680,-3.36892,-53.29575,3.34266,53.29575,22412,6
39.37180,-3.08321,-45.47148,3.05695,45.47148,22412,6
39.69980,-2.75503,-37.11995,2.72877,37.11995,22412,6
39.97680,-2.47798,-30.24770,2.45171,30.24770,22412,6
40.39080,-2.06409,-21.49594,2.03783,21.49594,22412,6
40.87080,-1.58396,-13.51222,1.55770,13.51222,22412,6
41.32880,-1.22421,-8.29311,1.19795,8.29311,22412,6
41.75780,-1.67797,-17.16614,1.65171,17.16614,22476,6
42.11580,-2.03718,-24.31748,2.01092,24.31748,22476,7
42.48280,-2.40416,-32.81431,2.37790,32.81431,22476,7
42.81480,-2.73623,-40.93682,2.70997,40.93682,22476,7
43.14080,-3.06236,-48.99767,3.03610,48.99767,22476,7
43.48580,-3.40721,-57.37064,3.38095,57.37064,22476,7
43.85880,-3.78021,-66.54195,3.75395,66.54195,22476,7
44.14780,-3.78251,-65.53947,3.75625,65.53947,22476,7
44.44180,-3.47683,-56.32598,3.45057,56.32598,22412,7
44.76480,-3.15227,-47.30926,3.12601,47.30927,22412,7
45.08880,-2.82788,-38.88199,2.80162,38.88199,22412,7
45.41280,-2.50394,-30.69515,2.47768,30.69515,22412,7
45.81480,-2.10194,-22.12582,2.07568,22.12582,22412,7
46.29680,-1.61990,-13.97509,1.59364,13.97509,22412,7
46.76820,-1.19226,-7.34209,1.16600,7.34209,22412,7
47.17480,-1.62623,-16.14776,1.59997,16.14776,22604,7
47.59880,-2.05215,-24.52363,2.02589,24.52363,22604,8
47.96820,-2.42109,-33.20037,2.39483,33.20037,22604,8
48.33280,-2.78609,-42.07624,2.75983,42.07624,22604,8
48.65680,-3.11021,-50.01716,3.08395,50.01715,22604,8
49.00380,-3.45714,-58.45957,3.43088,58.45957,22604,8
49.36480,-3.81804,-67.40829,3.79178,67.40829,22604,8
49.63680,-3.78070,-65.34530,3.75444,65.34530,22604,8
49.92480,-3.48185,-56.32274,3.45558,56.32274,22540,8
50.25480,-3.15033,-47.10421,3.12407,47.10421,22540,8
50.58480,-2.81997,-38.60167,2.79371,38.60167,22540,8
50.94480,-2.45992,-29.60484,2.43366,29.60484,22540,8
51.35380,-2.05106,-21.05863,2.02480,21.05863,22540,8
51.84480,-1.55995,-12.99973,1.53369,12.99973,22540,8
52.26980,-1.23975,-8.43560,1.21349,8.43560,22540,8
52.68380,-1.67776,-17.00212,1.65150,17.00212,22604,8
53.10880,-2.10409,-25.53821,2.07783,25.53821,22604,9
53.43380,-2.42912,-33.25289,2.40286,33.25290,22604,9
53.78580,-2.78112,-41.82130,2.75486,41.82130,22604,9
54.11080,-3.10623,-49.83078,3.07997,49.83078,22604,9
54.46820,-3.46315,-58.58113,3.43689,58.58113,22604,9
54.82280,-3.81806,-67.22982,3.79180,67.22982,22604,9
55.07980,-3.78219,-65.33552,3.75593,65.33552,22604,9
55.36820,-3.48277,-56.28091,3.45651,56.28091,22540,9
55.68180,-3.16720,-47.46868,3.14094,47.46868,22540,9
56.00180,-2.84674,-39.14241,2.82047,39.14241,22540,9
56.31480,-2.53386,-31.24671,2.50760,31.24671,22540,9
56.66820,-2.18088,-23.49669,2.15462,23.49669,22540,9
57.16080,-1.68795,-14.94851,1.66169,14.94851,22540,9
57.62580,-1.22270,-7.56655,1.19644,7.56655,22540,9
58.28780,-1.45990,-13.10846,1.43364,13.10846,22540,9
58.73280,-1.90795,-21.53432,1.88169,21.53432,22476,9
59.07380,-2.24917,-28.91148,2.22291,28.91148,22476,10
59.37680,-2.55230,-36.30834,2.52604,36.30834,22476,10
59.69680,-2.87213,-44.06452,2.84587,44.06452,22476,10
60.05580,-3.23119,-52.84591,3.20493,52.84591,22476,10
60.40480,-3.58024,-61.49585,3.55398,61.49585,22476,10
60.76780,-3.93079,-70.12855,3.90453,70.12856,22476,10
61.03080,-3.65398,-61.37260,3.62772,61.37260,22412,10
61.33180,-3.34773,-52.37486,3.32147,52.37486,22412,10
61.66820,-3.01118,-43.30378,2.98492,43.30378,22412,10
62.00880,-2.67020,-34.74277,2.64394,34.74276,22412,10
62.36880,-2.31003,-26.08457,2.28377,26.08457,22412,10
62.83280,-1.84590,-17.46098,1.81964,17.46098,22412,10
63.34080,-1.33789,-9.46103,1.31163,9.46103,22412,10
63.75380,-1.44685,-12.70437,1.42059,12.70437,22412,10
64.16820,-1.86659,-20.45663,1.84033,20.45663,22476,11
64.56820,-2.26717,-29.18099,2.24091,29.18099,22476,11
64.92280,-2.62222,-37.98884,2.59596,37.98884,22476,11
65.27680,-2.97611,-46.63385,2.94985,46.63385,22476,11
65.63680,-3.33606,-55.33319,3.30980,55.33319,22476,11
65.99580,-3.69526,-64.18933,3.66900,64.18933,22476,11
66.28180,-3.87863,-68.32644,3.85237,68.32645,22476,11
66.56880,-3.56953,-58.60643,3.54327,58.60643,22412,11
66.86880,-3.26647,-49.83708,3.24021,49.83708,22412,11
67.21180,-2.92293,-41.03841,2.89667,41.03841,22412,11
67.56820,-2.56702,-32.02695,2.54076,32.02695,22412,11
67.96780,-2.16706,-23.07801,2.14080,23.07801,22412,11
68.44880,-1.68607,-14.90754,1.65981,14.90754,22412,11
68.91180,-1.22284,-7.48392,1.19658,7.48392,22412,11
69.31280,-1.57911,-15.00051,1.55285,15.00051,22476,11
69.74580,-2.01493,-23.46933,1.98867,23.46933,22476,12
70.12380,-2.39299,-32.12870,2.36673,32.12870,22476,12
70.47180,-2.74104,-40.55734,2.71478,40.55734,22476,12
70.83280,-3.10214,-49.51388,3.07588,49.51388,22476,12
71.17580,-3.44507,-57.89348,3.41881,57.89348,22476,12
71.54080,-3.81000,-66.92710,3.78374,66.92710,22476,12
71.81980,-3.78367,-65.17868,3.75741,65.17868,22476,12
72.13080,-3.46141,-55.49219,3.43515,55.49219,22412,12
72.43780,-3.15314,-46.76844,3.12688,46.76844,22412,12
72.76820,-2.82276,-38.45855,2.79650,38.45855,22412,12
73.13380,-2.45673,-29.07020,2.43047,29.07020,22412,12
73.55280,-2.03788,-20.68365,2.01162,20.68365,22412,12
74.05680,-1.53379,-12.46851,1.50753,12.46851,22412,12
74.46820,-1.28893,-9.30141,1.26267,9.30141,22412,12
74.88880,-1.72867,-17.67781,1.70241,17.67781,22476,12
75.28580,-2.12674,-25.74730,2.10047,25.74730,22476,13
75.66820,-2.50883,-34.83247,2.48257,34.83247,22476,13
76.01080,-2.85169,-43.27192,2.82543,43.27192,22476,13
76.36980,-3.21081,-52.03091,3.18455,52.03091,22476,13
76.73580,-3.57681,-61.10430,3.55055,61.10430,22476,13
77.06980,-3.91063,-69.29750,3.88437,69.29750,22476,13
77.35180,-3.67715,-61.81913,3.65088,61.81913,22412,13
77.65080,-3.37231,-52.82506,3.34605,52.82506,22412,13
77.96880,-3.05372,-44.21600,3.02745,44.21600,22412,13
78.32380,-2.69857,-35.19627,2.67231,35.19627,22412,13
78.67880,-2.34341,-26.56906,2.31715,26.56906,22412,13
79.13380,-1.88840,-18.03903,1.86213,18.03903,22412,13
79.63780,-1.38439,-10.12744,1.35813,10.12744,22412,13
80.02280,-1.42688,-12.04804,1.40062,12.04804,22412,13
80.46180,-1.87384,-20.34862,1.84758,20.34862,22476,14
80.85180,-2.26447,-28.81810,2.23821,28.81810,22476,14
81.19580,-2.60850,-37.24233,2.58224,37.24233,22476,14
81.56820,-2.98043,-46.39982,2.95417,46.39982,22476,14
81.91580,-3.32839,-54.89732,3.30213,54.89732,22476,14
82.26820,-3.68059,-63.66286,3.65433,63.66286,22476,14
82.57780,-3.89915,-68.75192,3.87289,68.75192,22476,14
82.86820,-3.58597,-59.02756,3.55970,59.02756,22412,14
83.16820,-3.28285,-50.19926,3.25659,50.19926,22412,14
83.50780,-2.94222,-41.37836,2.91596,41.37836,22412,14
83.86820,-2.58234,-32.26718,2.55608,32.26718,22412,14
84.25180,-2.19832,-23.73148,2.17206,23.73148,22412,14
84.72380,-1.72642,-15.50578,1.70016,15.50578,22412,14
85.21180,-1.23819,-7.47849,1.21193,7.47849,22412,14
85.61780,-1.54915,-14.30003,1.52289,14.30003,22476,14
86.06080,-1.99529,-22.92934,1.96903,22.92934,22476,15
86.44280,-2.37739,-31.46397,2.35113,31.46397,22476,15
86.79280,-2.72746,-39.95671,2.70120,39.95671,22476,15
87.15180,-3.08662,-48.94079,3.06036,48.94079,22476,15
87.49980,-3.43452,-57.46872,3.40826,57.46872,22476,15
87.86580,-3.80039,-66.68875,3.77413,66.68874,22476,15
88.15580,-3.79765,-65.25043,3.77139,65.25043,22476,15
88.45280,-3.48917,-56.31821,3.46290,56.31821,22412,15
88.76820,-3.17262,-47.36547,3.14636,47.36547,22412,15
89.08880,-2.85118,-39.09013,2.82492,39.09013,22412,15
89.46480,-2.47523,-29.76398,2.44897,29.76398,22412,15
89.86820,-2.07232,-21.11227,2.04606,21.11227,22412,15
90.36820,-1.57227,-12.86626,1.54601,12.86626,22412,15
90.78280,-1.25968,-8.42887,1.23341,8.42887,22412,15
91.19580,-1.69688,-16.92956,1.67062,16.92957,22476,15
91.62680,-2.12922,-25.62921,2.10296,25.62921,22476,16
91.97080,-2.47327,-33.77420,2.44701,33.77420,22476,16
92.34180,-2.84424,-42.86550,2.81798,42.86551,22476,16
92.68580,-3.18839,-51.36324,3.16213,51.36324,22476,16
93.05580,-3.55835,-60.55173,3.53209,60.55172,22476,16
93.40380,-3.90614,-69.15057,3.87988,69.15057,22476,16
93.66820,-3.70774,-62.59903,3.68148,62.59903,22476,16
93.96820,-3.40100,-53.45023,3.37474,53.45023,22412,16
94.28980,-3.07811,-44.61359,3.05185,44.61359,22412,16
94.64280,-2.72494,-35.63223,2.69868,35.63223,22412,16
94.98980,-2.37787,-27.15828,2.35161,27.15828,22412,16
95.43680,-1.93082,-18.47731,1.90456,18.47731,22412,16
95.94480,-1.42288,-10.44556,1.39662,10.44556,22412,16
96.36780,-1.40262,-11.49408,1.37636,11.49408,22412,16
96.78880,-1.83228,-19.65054,1.80602,19.65054,22476,17
97.19080,-2.23492,-27.77925,2.20866,27.77925,22476,17
97.56780,-2.61202,-37.09980,2.58575,37.09980,22476,17
97.90480,-2.94896,-45.51777,2.92270,45.51777,22476,17
98.26820,-3.31193,-54.30931,3.28567,54.30931,22476,17
98.60680,-3.65110,-62.79286,3.62484,62.79286,22476,17
98.94580,-3.92256,-69.21985,3.89630,69.21985,22476,17
99.22680,-3.61695,-59.77350,3.59069,59.77350,22412,17
99.52880,-3.31125,-50.87904,3.28498,50.87904,22412,17
99.86820,-2.97169,-41.85946,2.94543,41.85946,22412,17
100.20480,-2.63484,-33.40929,2.60858,33.40929,22412,17
100.58780,-2.25176,-24.56816,2.22550,24.56816,22412,17
101.05680,-1.78284,-16.15957,1.75658,16.15957,22412,17
101.56180,-1.27770,-8.18988,1.25144,8.18988,22412,17
101.96480,-1.54699,-14.09387,1.52073,14.09387,22604,17
102.37580,-1.96154,-22.04967,1.93527,22.04967,22604,17
102.76820,-2.35375,-30.81983,2.32749,30.81983,22604,18
103.11980,-2.70589,-39.50282,2.67963,39.50282,22604,18
103.46820,-3.05401,-48.14282,3.02775,48.14282,22604,18
103.83180,-3.41786,-56.98834,3.39160,56.98834,22604,18
104.17980,-3.76586,-65.62077,3.73960,65.62077,22604,18
104.48180,-3.83549,-66.44567,3.80923,66.44567,22604,18
104.76820,-3.53607,-57.33682,3.50981,57.33682,22540,18
105.08980,-3.21184,-48.14792,3.18558,48.14792,22540,18
105.42580,-2.87547,-39.39676,2.84921,39.39676,22540,18
105.74980,-2.55164,-31.16748,2.52538,31.16748,22540,18
106.14480,-2.15670,-22.60981,2.13044,22.60981,22540,18
106.61880,-1.68269,-14.52570,1.65643,14.52570,22540,18
107.09080,-1.21817,-7.11074,1.19191,7.11074,22540,18
107.48480,-1.62412,-15.54088,1.59786,15.54088,22604,18
107.92480,-2.06654,-24.18391,2.04028,24.18391,22604,19
108.28480,-2.42657,-32.48917,2.40031,32.48917,22604,19
108.65080,-2.79254,-41.49637,2.76628,41.49637,22604,19
108.99380,-3.13566,-49.95957,3.10940,49.95957,22604,19
109.35280,-3.49459,-58.78820,3.46833,58.78820,22604,19
109.69280,-3.83446,-67.28839,3.80820,67.28839,22604,19
109.97980,-3.77886,-64.62654,3.75260,64.62653,22604,19
110.28280,-3.46588,-55.24345,3.43962,55.24345,22540,19
110.59780,-3.14971,-46.47237,3.12345,46.47237,22540,19
110.93180,-2.81537,-37.80819,2.78911,37.80819,22540,19
111.23980,-2.50742,-30.16168,2.48115,30.16167,22540,19
111.64080,-2.10640,-21.62744,2.08014,21.62745,22540,19
112.12880,-1.61836,-13.47797,1.59210,13.47797,22540,19
112.56280,-1.20510,-6.89524,1.17884,6.89524,22540,19
113.16680,-1.45002,-12.52914,1.42376,12.52914,22540,19
113.59980,-1.88660,-20.57472,1.86034,20.57472,22476,19
113.98580,-2.27296,-28.91347,2.24670,28.91347,22476,20
114.35080,-2.63801,-37.85771,2.61175,37.85771,22476,20
114.69080,-2.97791,-46.19893,2.95165,46.19893,22476,20
115.06820,-3.35483,-55.45084,3.32857,55.45084,22476,20
115.40680,-3.69403,-63.86771,3.66777,63.86771,22476,20
115.75580,-3.84873,-66.76502,3.82247,66.76501,22476,20
116.03480,-3.55469,-57.75470,3.52843,57.75470,22412,20
116.35980,-3.22705,-48.68480,3.20079,48.68480,22412,20
116.66980,-2.91676,-40.20344,2.89050,40.20344,22412,20
117.02980,-2.55685,-31.16324,2.53058,31.16324,22412,20
117.43780,-2.14890,-22.61792,2.12264,22.61792,22412,20
117.89880,-1.68788,-14.63540,1.66162,14.63540,22412,20
118.37880,-1.20779,-7.00361,1.18153,7.00361,22412,20
118.76820,-1.57401,-14.62268,1.54775,14.62268,22476,20
119.20480,-2.01385,-23.04368,1.98759,23.04368,22476,21
119.58180,-2.39093,-31.63851,2.36467,31.63851,22476,21
119.94280,-2.75196,-40.40677,2.72569,40.40678,22476,21
120.29080,-3.10007,-48.87593,3.07381,48.87593,22476,21
120.64380,-3.45298,-57.76852,3.42672,57.76852,22476,21
120.99880,-3.80784,-66.55309,3.78158,66.55309,22476,21
121.28380,-3.79804,-65.19390,3.77178,65.19390,22476,21
121.57180,-3.49872,-56.14114,3.47246,56.14114,22412,21
121.88480,-3.18405,-47.24045,3.15779,47.24045,22412,21
122.24880,-2.81972,-38.04871,2.79346,38.04871,22412,21
122.57380,-2.49476,-30.00714,2.46850,30.00714,22412,21
122.98680,-2.08178,-21.03923,2.05552,21.03923,22412,21
123.49180,-1.57669,-12.96089,1.55043,12.96089,22412,21
123.95680,-1.29295,-9.18261,1.26668,9.18261,22412,21
124.36820,-1.72164,-17.25446,1.69538,17.25446,22476,21
124.77780,-2.13273,-25.48264,2.10647,25.48264,22476,22
125.14380,-2.49878,-34.35466,2.47252,34.35466,22476,22
125.49880,-2.85368,-43.00999,2.82742,43.00999,22476,22
125.85880,-3.21382,-51.99404,3.18756,51.99405,22476,22
126.20180,-3.55679,-60.40600,3.53053,60.40600,22476,22
126.56820,-3.92266,-69.34294,3.89640,69.34294,22476,22
126.86280,-3.68775,-61.67027,3.66149,61.67027,22412,22
127.16280,-3.38220,-52.73939,3.35594,52.73939,22412,22
127.46980,-3.07459,-44.33444,3.04833,44.33444,22412,22
127.82980,-2.71444,-35.18577,2.68818,35.18576,22412,22
128.18480,-2.35930,-26.65544,2.33304,26.65544,22412,22
128.64479,-1.89934,-17.96681,1.87308,17.96681,22412,22
129.14780,-1.39642,-10.04858,1.37016,10.04858,22412,22
129.53580,-1.43789,-11.94566,1.41163,11.94566,22412,22
129.96820,-1.87785,-20.13079,1.85159,20.13078,22476,22
130.36820,-2.27840,-28.76483,2.25214,28.76483,22476,23
130.71379,-2.62449,-37.28144,2.59823,37.28144,22476,23
131.06820,-2.97840,-45.94424,2.95214,45.94424,22476,23
131.38580,-3.29640,-53.79830,3.27014,53.79830,22476,23
131.75180,-3.66251,-62.88727,3.63625,62.88727,22476,23
132.07080,-3.93060,-69.39638,3.90434,69.39638,22476,23
132.35280,-3.62356,-59.82285,3.59730,59.82285,22412,23
132.65980,-3.31264,-50.75496,3.28638,50.75496,22412,23
132.97680,-2.99513,-42.26566,2.96887,42.26566,22412,23
133.32580,-2.64621,-33.52463,2.61995,33.52463,22412,23
133.70980,-2.26213,-24.58113,2.23587,24.58113,22412,23
134.17080,-1.80108,-16.48105,1.77482,16.48105,22412,23
134.66820,-1.30408,-8.57597,1.27782,8.57597,22412,23
135.09380,-1.53414,-13.69063,1.50788,13.69063,22476,23
135.53080,-1.97494,-22.19691,1.94868,22.19691,22476,24
135.89180,-2.33616,-30.30792,2.30990,30.30792,22476,24
136.26820,-2.71222,-39.35297,2.68596,39.35297,22476,24
136.62180,-3.06638,-48.14409,3.04011,48.14409,22476,24
136.96820,-3.41219,-56.71571,3.38593,56.71571,22476,24
137.32480,-3.76915,-65.51941,3.74289,65.51942,22476,24
137.61980,-3.83413,-66.26631,3.80787,66.26630,22476,24
137.90380,-3.53654,-57.17599,3.51028,57.17599,22412,24
138.21980,-3.21828,-48.16875,3.19202,48.16875,22412,24
138.56780,-2.86992,-39.07817,2.84366,39.07817,22412,24
138.89380,-2.54408,-30.87698,2.51782,30.87698,22412,24
139.29580,-2.14212,-22.22313,2.11586,22.22313,22412,24
139.78580,-1.65221,-13.88842,1.62595,13.88842,22412,24
140.26480,-1.25109,-7.86797,1.22483,7.86797,22412,24
140.66820,-1.68055,-16.43175,1.65429,16.43176,22476,24
141.06880,-2.08314,-24.34838,2.05688,24.34838,22476,25
141.45280,-2.46715,-33.35951,2.44089,33.35951,22476,25
141.76980,-2.78416,-41.10939,2.75790,41.10939,22476,25
142.13180,-3.14630,-50.02767,3.12003,50.02767,22476,25
142.47080,-3.48517,-58.34781,3.45891,58.34781,22476,25
142.83280,-3.84702,-67.40519,3.82076,67.40519,22476,25
143.11180,-3.78352,-64.62299,3.75726,64.62299,22476,25
143.41680,-3.46847,-55.16389,3.44221,55.16389,22412,25
143.73980,-3.14427,-46.13890,3.11801,46.13890,22412,25
144.06819,-2.81595,-37.68165,2.78969,37.68165,22412,25
144.43180,-2.45191,-28.67096,2.42565,28.67096,22412,25
144.85080,-2.03306,-20.10481,2.00680,20.10481,22412,25
145.35480,-1.52907,-12.08576,1.50281,12.08576,22412,25
145.76820,-1.32702,-9.65420,1.30076,9.65420,22412,25
146.19280,-1.76821,-18.01278,1.74195,18.01278,22476,25
146.61880,-2.19515,-26.71535,2.16889,26.71535,22476,26
146.96820,-2.54422,-35.18039,2.51796,35.18039,22476,26
147.32680,-2.90304,-43.96078,2.87678,43.96078,22476,26
147.66820,-3.24406,-52.49248,3.21780,52.49249,22476,26
148.03380,-3.61001,-61.48008,3.58375,61.48008,22476,26
148.36780,-3.94134,-69.76175,3.91508,69.76175,22476,26
148.63080,-3.68133,-61.48387,3.65507,61.48387,22476,26
148.94380,-3.36255,-52.14896,3.33629,52.14896,22412,26
149.26820,-3.03806,-43.27681,3.01180,43.27681,22412,26
149.60880,-2.69694,-34.68667,2.67068,34.68666,22412,26
149.98080,-2.32479,-25.96915,2.29853,25.96915,22412,26
150.43180,-1.87373,-17.43103,1.84747,17.43103,22412,26
150.92980,-1.37577,-9.53231,1.34951,9.53231,22412,26
151.32880,-1.48433,-12.67018,1.45807,12.67018,22412,26
151.76820,-1.92966,-21.12956,1.90340,21.12956,22476,27
152.15680,-2.31899,-29.65320,2.29273,29.65320,22476,27
152.48880,-2.65110,-37.79884,2.62484,37.79884,22476,27
152.84680,-3.00908,-46.68928,2.98282,46.68928,22476,27
153.21180,-3.37393,-55.56050,3.34767,55.56050,22476,27
153.56819,-3.73003,-64.49685,3.70377,64.49685,22476,27
153.86819,-3.87695,-67.47801,3.85069,67.47801,22476,27
154.14680,-3.58004,-58.43962,3.55378,58.43962,22412,27
154.45180,-3.27226,-49.48914,3.24600,49.48914,22412,27
154.78880,-2.93471,-40.60864,2.90845,40.60864,22412,27
155.14080,-2.58282,-31.77461,2.55656,31.77461,22412,27
155.53180,-2.19182,-23.08314,2.16556,23.08315,22412,27
155.99280,-1.73092,-15.11836,1.70466,15.11836,22412,27
156.46980,-1.25384,-7.47279,1.22758,7.47278,22412,27
156.87880,-1.61829,-15.13842,1.59203,15.13842,22604,27
157.30980,-2.05202,-23.60920,2.02576,23.60920,22604,28
157.66880,-2.41107,-31.82788,2.38481,31.82788,22604,28
158.03180,-2.77404,-40.75556,2.74778,40.75556,22604,28
158.38378,-3.12617,-49.44403,3.09991,49.44403,22604,28
158.70880,-3.45108,-57.48610,3.42481,57.48610,22604,28
159.02680,-3.76899,-65.45725,3.74273,65.45724,22604,28
159.30580,-3.87754,-67.41932,3.85128,67.41932,22604,28
159.58080,-3.58590,-58.49754,3.55964,58.49754,22540,28
159.86819,-3.29622,-50.16979,3.26996,50.16979,22540,28
160.16820,-2.99577,-42.17859,2.96951,42.17859,22540,28
160.48180,-2.68184,-34.21756,2.65558,34.21756,22540,28
160.86819,-2.29574,-25.18112,2.26948,25.18112,22540,28
161.30280,-1.86061,-17.14414,1.83435,17.14414,22540,28
161.80780,-1.35561,-9.19682,1.32935,9.19682,22540,28
162.20580,-1.51014,-13.08418,1.48387,13.08418,22540,28
162.63280,-1.94258,-21.33046,1.91632,21.33046,22604,29
163.01680,-2.32686,-29.80361,2.30060,29.80361,22604,29
163.37380,-2.68403,-38.61032,2.65777,38.61032,22604,29
163.66820,-2.97788,-45.80865,2.95162,45.80865,22604,29
164.01880,-3.32885,-54.43441,3.30259,54.43441,22604,29
164.36819,-3.67793,-63.17163,3.65167,63.17162,22604,29
164.69380,-3.92811,-69.06992,3.90185,69.06992,22604,29
164.96880,-3.62887,-59.80322,3.60261,59.80322,22540,29
165.27580,-3.31801,-50.76369,3.29175,50.76369,22540,29
165.57080,-3.02268,-42.83859,2.99642,42.83859,22540,29
165.92380,-2.66969,-33.94241,2.64342,33.94241,22540,29
166.26819,-2.32547,-25.80971,2.29921,25.80972,22540,29
166.71280,-1.88044,-17.43541,1.85418,17.43541,22540,29
167.21280,-1.38051,-9.58119,1.35425,9.58119,22540,29
167.84580,-1.33087,-9.96107,1.30461,9.96107,22540,29
168.26819,-1.76148,-18.03416,1.73522,18.03416,22476,29
168.69280,-2.18695,-26.64134,2.16069,26.64134,22476,30
169.06280,-2.55699,-35.52556,2.53073,35.52556,22476,30
169.40580,-2.89982,-43.96823,2.87356,43.96823,22476,30
169.76819,-3.26184,-52.91939,3.23558,52.91939,22476,30
170.10880,-3.60284,-61.38070,3.57657,61.38070,22476,30
170.46580,-3.95295,-70.03971,3.92669,70.03971,22476,30
170.73580,-3.67549,-61.22003,3.64923,61.22003,22412,30
171.04180,-3.36420,-52.09079,3.33794,52.09079,22412,30
171.36580,-3.03972,-43.26148,3.01346,43.26147,22412,30
171.70180,-2.70360,-34.83488,2.67734,34.83488,22412,30
172.06819,-2.33745,-26.06538,2.31119,26.06538,22412,30
172.53480,-1.87042,-17.34959,1.84416,17.34959,22412,30
173.04380,-1.36145,-9.31010,1.33519,9.31010,22412,30
173.42080,-1.47969,-12.54197,1.45342,12.54197,22412,30
173.85180,-1.91721,-20.78988,1.89095,20.78988,22476,31
174.25280,-2.31862,-29.50986,2.29236,29.50986,22476,31
174.58480,-2.65071,-37.76740,2.62445,37.76740,22476,31
174.95780,-3.02379,-46.98890,2.99753,46.98890,22476,31
175.27780,-3.34357,-54.80861,3.31731,54.80861,22476,31
175.61580,-3.68171,-63.24807,3.65545,63.24807,22476,31
175.93780,-3.91688,-68.72946,3.89062,68.72946,22476,31
176.21480,-3.61637,-59.39727,3.59011,59.39727,22412,31
176.52480,-3.30279,-50.31861,3.27652,50.31861,22412,31
176.79880,-3.02845,-42.95349,3.00219,42.95349,22412,31
177.10280,-2.72429,-35.17385,2.69803,35.17385,22412,31
177.46820,-2.35917,-26.44188,2.33291,26.44188,22412,31
177.91080,-1.91627,-18.09895,1.89000,18.09895,22412,31
178.41980,-1.40734,-10.02669,1.38108,10.02669,22412,31
178.80680,-1.44779,-11.97668,1.42153,11.97668,22412,31
179.25280,-1.90193,-20.43339,1.87567,20.43339,22476,32
179.65080,-2.30035,-29.08847,2.27409,29.08847,22476,32
179.98880,-2.63840,-37.39593,2.61214,37.39593,22476,32
180.35680,-3.00656,-46.53784,2.98030,46.53784,22476,32
180.69980,-3.34932,-54.93165,3.32306,54.93165,22476,32
181.01780,-3.66752,-62.85493,3.64126,62.85493,22476,32
181.34278,-3.92951,-69.10365,3.90324,69.10365,22476,32
181.60880,-3.63900,-60.03812,3.61274,60.03812,22412,32
181.92580,-3.31768,-50.69771,3.29142,50.69772,22412,32
182.18180,-3.06138,-43.76795,3.03512,43.76795,22412,32
182.54280,-2.70023,-34.59240,2.67397,34.59240,22412,32
182.89680,-2.34608,-26.16853,2.31982,26.16854,22412,32
183.35380,-1.88912,-17.56000,1.86286,17.56000,22412,32
183.86280,-1.38016,-9.54572,1.35390,9.54572,22412,32
184.25580,-1.49057,-12.67022,1.46431,12.67022,22412,32
184.66820,-1.90887,-20.52062,1.88261,20.52062,22476,33
185.06819,-2.30933,-29.23696,2.28307,29.23697,22476,33
185.42080,-2.66239,-37.99127,2.63613,37.99127,22476,33
185.76819,-3.00951,-46.64010,2.98325,46.64010,22476,33
186.08580,-3.32733,-54.34357,3.30107,54.34357,22476,33
186.44080,-3.68241,-63.21587,3.65615,63.21587,22476,33
186.76819,-3.92047,-68.72480,3.89421,68.72480,22476,33
187.05980,-3.60474,-59.01322,3.57848,59.01322,22412,33
187.35080,-3.31057,-50.58597,3.28431,50.58597,22412,33
187.67380,-2.98705,-41.84650,2.96079,41.84650,22412,33
188.03980,-2.62112,-32.55991,2.59486,32.55991,22412,33
188.41178,-2.24909,-24.13919,2.22283,24.13919,22412,33
188.86819,-1.79312,-15.99384,1.76686,15.99384,22412,33
189.37078,-1.29015,-8.01238,1.26389,8.01238,22412,33
189.76819,-1.57549,-14.24464,1.54923,14.24464,22476,33
190.18780,-1.99904,-22.42010,1.97278,22.42010,22476,34
190.56880,-2.38015,-30.94760,2.35389,30.94760,22476,34
190.93380,-2.74531,-39.91945,2.71905,39.91946,22476,34
191.27780,-3.08941,-48.51912,3.06315,48.51912,22476,34
191.64280,-3.45417,-57.48272,3.42791,57.48272,22476,34
191.97980,-3.79122,-65.88728,3.76495,65.88728,22476,34
192.29180,-3.81247,-65.38212,3.78621,65.38212,22476,34
192.57580,-3.51703,-56.44455,3.49077,56.44455,22412,34
192.86819,-3.22320,-48.07216,3.19694,48.07216,22412,34
193.21680,-2.87385,-38.94193,2.84759,38.94193,22412,34
193.56819,-2.52301,-30.27518,2.49675,30.27518,22412,34
193.96820,-2.12302,-21.44599,2.09676,21.44599,22412,34
194.45380,-1.63714,-13.42590,1.61088,13.42590,22412,34
194.89780,-1.26229,-7.78213,1.23603,7.78213,22412,34
195.31980,-1.71166,-16.77132,1.68540,16.77132,22476,34
195.73580,-2.12910,-25.14490,2.10284,25.14490,22476,35
196.08780,-2.48109,-33.47216,2.45483,33.47216,22476,35
196.45880,-2.85212,-42.60479,2.82586,42.60479,22476,35
196.79680,-3.19028,-50.95609,3.16402,50.95609,22476,35
197.16820,-3.56098,-60.10243,3.53472,60.10243,22476,35
197.50580,-3.89906,-68.53569,3.87280,68.53569,22476,35
197.78180,-3.73129,-62.80609,3.70503,62.80609,22476,35
198.07680,-3.42912,-53.80061,3.40286,53.80061,22412,35
198.40780,-3.09713,-44.54061,3.07086,44.54062,22412,35
198.75680,-2.74797,-35.66242,2.72171,35.66241,22412,35
199.10880,-2.39593,-27.09453,2.36967,27.09453,22412,35
199.56819,-1.93683,-18.34237,1.91056,18.34237,22412,35
200.05178,-1.45290,-10.57296,1.42664,10.57296,22412,35
200.44580,-1.41837,-11.34253,1.39211,11.34253,22412,35
200.87680,-1.85943,-19.62227,1.83317,19.62227,22476,35
201.26819,-2.25111,-27.83648,2.22485,27.83648,22476,36
201.64580,-2.62924,-37.06111,2.60298,37.06111,22476,36
201.98080,-2.96412,-45.30481,2.93786,45.30481,22476,36
202.34780,-3.33107,-54.35492,3.30481,54.35492,22476,36
202.68380,-3.66707,-62.77864,3.64081,62.77864,22476,36
202.94080,-3.92412,-69.19602,3.89786,69.19602,22476,36
203.16820,-3.75261,-63.41157,3.72635,63.41157,22476,36
203.46978,-3.44221,-54.17204,3.41595,54.17204,22412,36
203.78878,-3.12216,-45.22610,3.09590,45.22610,22412,36
204.14180,-2.76896,-36.18399,2.74270,36.18399,22412,36
204.48580,-2.42491,-27.76066,2.39865,27.76066,22412,36
204.91880,-1.99191,-19.25385,1.96565,19.25385,22412,36
205.44480,-1.46587,-10.86185,1.43961,10.86185,22412,36
205.83780,-1.41576,-11.15842,1.38950,11.15842,22412,36
206.26819,-1.85637,-19.45877,1.83011,19.45877,22476,37
206.66178,-2.25107,-27.71758,2.22481,27.71758,22476,37
207.01480,-2.60423,-36.45767,2.57797,36.45767,22476,37
207.36819,-2.95713,-45.08371,2.93087,45.08371,22476,37
207.72280,-3.31210,-53.86867,3.28584,53.86867,22476,37
208.06819,-3.65712,-62.56224,3.63086,62.56224,22476,37
208.41178,-3.92975,-69.12018,3.90349,69.12018,22476,37
208.67980,-3.63749,-59.99536,3.61123,59.99536,22412,37
208.99180,-3.32135,-50.72755,3.29509,50.72755,22412,37
209.32680,-2.98584,-41.70337,2.95958,41.70337,22412,37
209.66820,-2.64496,-33.09864,2.61870,33.09864,22412,37
210.06580,-2.24687,-24.11654,2.22061,24.11654,22412,37
210.51078,-1.80182,-16.06971,1.77556,16.06971,22412,37
211.01280,-1.29993,-7.94253,1.27367,7.94253,22412,37
211.43080,-1.56431,-13.99293,1.53805,13.99293,22604,37
211.86819,-2.00488,-22.55001,1.97862,22.55000,22604,38
212.24778,-2.38500,-31.00845,2.35874,31.00845,22604,38
212.58880,-2.72604,-39.55420,2.69978,39.55420,22604,38
212.95380,-3.09118,-48.36361,3.06492,48.36361,22604,38
213.30280,-3.44007,-56.98251,3.41381,56.98251,22604,38
213.65780,-3.79498,-65.92893,3.76872,65.92893,22604,38
213.96820,-3.82884,-65.70016,3.80258,65.70016,22604,38
214.25280,-3.53191,-56.78640,3.50565,56.78640,22540,38
214.56678,-3.21599,-47.78577,3.18973,47.78577,22540,38
214.88378,-2.89871,-39.53795,2.87245,39.53795,22540,38
215.24980,-2.53281,-30.13661,2.50655,30.13661,22540,38
215.66820,-2.11480,-21.38315,2.08854,21.38315,22540,38
216.13180,-1.65097,-13.64334,1.62471,13.64334,22540,38
216.59180,-1.26873,-7.89723,1.24247,7.89723,22540,38
217.00480,-1.70839,-16.73187,1.68213,16.73187,22604,38
217.42280,-2.12782,-24.94807,2.10155,24.94807,22604,39
217.77880,-2.48394,-33.54866,2.45768,33.54866,22604,39
218.13880,-2.84390,-42.24633,2.81764,42.24633,22604,39
218.49280,-3.19802,-51.02941,3.17176,51.02941,22604,39
218.85280,-3.55788,-60.07059,3.53162,60.07059,22604,39
219.19380,-3.89876,-68.46768,3.87250,68.46767,22604,39
219.46820,-3.75159,-63.32498,3.72533,63.32498,22604,39
219.77180,-3.43976,-54.14076,3.41349,54.14076,22540,39
220.08980,-3.12081,-45.12795,3.09455,45.12795,22540,39
220.44380,-2.76660,-36.03859,2.74033,36.03859,22540,39
220.78780,-2.42257,-27.68133,2.39631,27.68133,22540,39
221.22980,-1.98053,-18.97849,1.95427,18.97849,22540,39
221.72880,-1.48159,-11.07201,1.45533,11.07201,22540,39
222.41580,-1.25452,-7.87261,1.22826,7.87261,22540,39
222.84780,-1.69968,-16.70196,1.67342,16.70196,22476,39
223.26278,-2.11542,-25.00884,2.08916,25.00884,22476,40
223.62278,-2.47534,-33.46182,2.44908,33.46182,22476,40
223.97080,-2.82338,-41.90862,2.79712,41.90862,22476,40
224.33780,-3.19051,-50.95585,3.16425,50.95585,22476,40
224.66820,-3.52035,-59.11291,3.49409,59.11291,22476,40
225.04480,-3.89717,-68.49419,3.87091,68.49419,22476,40
225.30580,-3.74325,-63.17575,3.71699,63.17575,22476,40
225.60480,-3.43633,-54.12162,3.41007,54.12162,22412,40
225.90580,-3.13437,-45.52691,3.10811,45.52691,22412,40
226.26580,-2.77410,-36.31828,2.74784,36.31828,22412,40
226.62580,-2.41409,-27.48798,2.38783,27.48798,22412,40
227.05680,-1.98301,-19.07218,1.95675,19.07218,22412,40
227.56580,-1.47406,-10.96307,1.44780,10.96307,22412,40
227.96820,-1.39409,-10.79217,1.36783,10.79217,22412,40
228.39878,-1.83652,-19.07785,1.81026,19.07785,22476,41
228.80080,-2.23922,-27.41829,2.21295,27.41829,22476,41
229.16080,-2.59933,-36.26285,2.57307,36.26286,22476,41
229.51980,-2.95828,-45.13635,2.93202,45.13635,22476,41
229.86819,-3.30627,-53.82855,3.28001,53.82855,22476,41
230.21680,-3.65524,-62.37810,3.62898,62.37810,22476,41
230.53678,-3.96382,-70.20180,3.93756,70.20180,22476,41
230.79580,-3.69207,-61.54822,3.66581,61.54822,22476,41
231.10180,-3.38067,-52.27144,3.35441,52.27144,22412,41
231.43080,-3.05110,-43.20099,3.02484,43.20099,22412,41
231.77880,-2.70298,-34.55842,2.67672,34.55842,22412,41
232.16280,-2.31886,-25.48570,2.29260,25.48570,22412,41
232.58980,-1.89186,-17.48836,1.86560,17.48836,22412,41
233.09980,-1.38188,-9.46852,1.35562,9.46852,22412,41
233.47580,-1.50114,-12.82354,1.47488,12.82354,22412,41
233.90780,-1.93974,-20.95976,1.91348,20.95976,22476,42
234.28980,-2.32208,-29.51377,2.29582,29.51377,22476,42
234.66280,-2.69520,-38.61407,2.66894,38.61407,22476,42
234.99280,-3.02526,-46.82044,2.99899,46.82044,22476,42
235.35978,-3.39207,-55.81597,3.36581,55.81597,22476,42
235.70080,-3.73305,-64.36707,3.70679,64.36707,22476,42
235.98478,-3.91944,-68.61752,3.89318,68.61752,22476,42
236.26819,-3.61363,-59.12308,3.58737,59.12309,22412,42
236.56819,-3.31029,-50.34053,3.28403,50.34053,22412,42
236.87180,-3.00589,-42.12593,2.97963,42.12593,22412,42
237.22178,-2.65596,-33.32400,2.62970,33.32400,22412,42
237.59678,-2.28084,-24.61360,2.25458,24.61360,22412,42
238.06819,-1.80975,-16.13126,1.78349,16.13126,22412,42
238.56580,-1.31183,-8.24022,1.28557,8.24022,22412,42
238.96820,-1.56800,-13.96826,1.54174,13.96826,22476,42
239.38480,-1.98881,-22.07436,1.96255,22.07436,22476,43
239.76580,-2.36998,-30.57384,2.34372,30.57384,22476,43
240.07978,-2.68415,-38.33575,2.65789,38.33575,22476,43
240.44178,-3.04623,-47.40085,3.01997,47.40085,22476,43
240.78780,-3.39202,-55.76478,3.36576,55.76477,22476,43
241.15380,-3.75799,-64.94232,3.73173,64.94231,22476,43
241.44680,-3.90461,-67.98040,3.87835,67.98040,22476,43
241.73180,-3.60098,-58.71059,3.57472,58.71059,22412,43
242.03280,-3.29719,-49.93238,3.27093,49.93238,22412,43
242.36819,-2.96164,-40.88553,2.93538,40.88553,22412,43
242.70678,-2.62279,-32.45816,2.59653,32.45816,22412,43
243.09580,-2.23374,-23.63128,2.20748,23.63128,22412,43
243.56819,-1.76190,-15.34442,1.73563,15.34442,22412,43
244.06280,-1.26683,-7.44092,1.24057,7.44092,22412,43
244.46580,-1.62512,-15.00347,1.59886,15.00347,22476,43
244.87380,-2.03591,-23.03831,2.00965,23.03831,22476,44
245.26819,-2.43004,-31.98289,2.40378,31.98289,22476,44
245.61380,-2.77591,-40.48488,2.74965,40.48487,22476,44
245.96820,-3.13010,-49.29755,3.10384,49.29755,22476,44
246.31478,-3.47696,-57.91027,3.45070,57.91027,22476,44
246.66820,-3.82985,-66.74287,3.80359,66.74287,22476,44
246.96580,-3.81020,-65.14755,3.78394,65.14755,22476,44
247.26819,-3.49742,-55.91130,3.47116,55.91130,22412,44
247.56819,-3.19598,-46.91048,3.16972,46.91048,22412,44
247.90780,-2.85561,-38.13428,2.82934,38.13428,22412,44
248.26819,-2.49572,-29.30495,2.46946,29.30495,22412,44
248.66980,-2.09377,-20.92687,2.06750,20.92687,22412,44
249.16880,-1.59481,-12.75562,1.56855,12.75562,22412,44
249.60778,-1.30870,-8.75726,1.28244,8.75726,22412,44
250.03678,-1.75777,-17.54224,1.73151,17.54224,22476,44
250.44980,-2.17188,-26.10772,2.14562,26.10772,22476,45
250.80980,-2.53190,-34.56831,2.50563,34.56831,22476,45
251.16820,-2.88981,-43.41091,2.86355,43.41091,22476,45
251.51780,-3.23986,-52.11081,3.21359,52.11081,22476,45
251.83378,-3.55584,-59.84491,3.52958,59.84491,22476,45
252.17678,-3.89872,-68.49971,3.87246,68.49972,22476,45
252.46820,-3.74588,-63.05060,3.71962,63.05060,22476,45
252.76680,-3.43965,-53.94777,3.41339,53.94777,22412,45
253.07280,-3.13276,-45.27202,3.10650,45.27202,22412,45
253.42180,-2.78355,-36.37246,2.75729,36.37246,22412,45
253.77480,-2.43049,-27.68836,2.40423,27.68836,22412,45
254.21978,-1.98549,-19.05633,1.95922,19.05633,22412,45
254.71778,-1.48747,-11.16131,1.46121,11.16131,22412,45
255.12180,-1.41382,-10.95733,1.38756,10.95733,22412,45
255.56678,-1.86998,-19.50543,1.84372,19.50543,22476,46
255.95780,-2.26166,-27.98292,2.23540,27.98292,22476,46
256.30578,-2.60974,-36.27354,2.58348,36.27354,22476,46
256.66819,-2.97173,-45.35319,2.94547,45.35319,22476,46
257.01678,-3.32067,-53.90662,3.29441,53.90662,22476,46
257.36819,-3.67167,-62.70482,3.64541,62.70482,22476,46
257.70380,-3.94883,-69.61054,3.92257,69.61053,22476,46
257.96820,-3.66020,-60.24545,3.63394,60.24545,22412,46
258.28080,-3.34272,-51.32462,3.31645,51.32462,22412,46
258.60580,-3.01738,-42.32113,2.99112,42.32113,22412,46
258.96820,-2.65535,-33.18344,2.62909,33.18344,22412,46
259.29380,-2.32916,-25.56512,2.30290,25.56512,22412,46
259.74680,-1.87613,-17.14665,1.84987,17.14665,22412,46
260.24978,-1.37318,-9.18291,1.34692,9.18291,22412,46
260.65580,-1.52381,-13.09493,1.49755,13.09493,22476,46
261.06980,-1.94314,-21.08692,1.91688,21.08692,22476,47
261.46820,-2.34142,-29.84090,2.31516,29.84090,22476,47
261.81378,-2.68758,-38.39668,2.66132,38.39668,22476,47
262.16819,-3.04171,-47.17015,3.01544,47.17015,22476,47
262.52578,-3.39948,-55.94955,3.37322,55.94955,22476,47
262.86819,-3.74145,-64.49550,3.71519,64.49551,22476,47
263.18978,-3.87998,-67.20657,3.85372,67.20657,22476,47
263.46819,-3.58609,-58.20611,3.55983,58.20611,22412,47
263.77781,-3.27348,-49.19194,3.24722,49.19194,22412,47
264.11381,-2.93700,-40.17081,2.91073,40.17081,22412,47
264.46819,-2.58310,-31.35683,2.55684,31.35683,22412,47
264.86819,-2.18312,-22.59687,2.15686,22.59687,22412,47
265.33381,-1.71718,-14.58613,1.69092,14.58613,22412,47
265.80578,-1.25461,-7.19082,1.22835,7.19082,22412,47
266.19681,-1.65992,-15.63762,1.63366,15.63762,22604,47
266.61781,-2.08326,-23.97318,2.05700,23.97318,22604,48
266.98778,-2.45331,-32.52079,2.42705,32.52079,22604,48
267.34478,-2.81027,-41.31249,2.78401,41.31248,22604,48
267.69078,-3.15645,-49.86289,3.13018,49.86289,22604,48
268.05178,-3.51730,-58.83800,3.49104,58.83800,22604,48
268.39481,-3.86010,-67.38858,3.83384,67.38858,22604,48
268.67778,-3.77769,-63.98883,3.75143,63.98883,22604,48
268.96819,-3.47844,-55.11682,3.45218,55.11682,22540,48
269.26819,-3.17720,-46.50902,3.15094,46.50902,22540,48
269.61578,-2.82886,-37.53737,2.80260,37.53736,22540,48
269.96978,-2.47484,-28.84695,2.44858,28.84695,22540,48
270.39481,-2.04999,-19.95401,2.02373,19.95401,22540,48
270.89381,-1.55104,-11.98431,1.52478,11.98431,22540,48
271.30381,-1.37088,-9.98245,1.34462,9.98245,22540,48
271.73578,-1.81815,-18.57191,1.79189,18.57191,22604,48
272.14978,-2.23304,-27.11924,2.20678,27.11924,22604,49
272.49381,-2.57714,-35.62108,2.55088,35.62108,22604,49
272.86481,-2.94810,-44.71802,2.92184,44.71803,22604,49
273.19581,-3.27906,-52.79576,3.25280,52.79576,22604,49
273.55478,-3.63806,-62.03321,3.61180,62.03321,22604,49
273.89278,-3.96455,-70.07561,3.93829,70.07561,22604,49
274.16819,-3.67627,-60.70105,3.65001,60.70105,22540,49
274.46381,-3.37537,-51.93658,3.34911,51.93658,22540,49
274.79378,-3.04489,-43.08911,3.01863,43.08912,22540,49
275.14178,-2.69675,-34.13412,2.67049,34.13412,22540,49
275.50778,-2.33061,-25.57233,2.30435,25.57233,22540,49
275.96819,-1.87056,-17.11668,1.84430,17.11668,22540,49
276.46819,-1.37064,-9.12888,1.34438,9.12888,22540,49
277.09578,-1.34965,-9.95024,1.32339,9.95024,22540,49
277.54481,-1.80675,-18.53786,1.78049,18.53786,22476,49
277.95278,-2.21512,-27.05655,2.18886,27.05655,22476,50
278.31281,-2.57520,-35.48317,2.54894,35.48317,22476,50
278.66478,-2.92712,-44.49752,2.90086,44.49752,22476,50
279.02578,-3.28812,-53.06146,3.26185,53.06146,22476,50
279.36781,-3.63007,-61.97920,3.60381,61.97921,22476,50
279.72581,-3.95768,-69.74690,3.93142,69.74690,22476,50
280.00078,-3.65988,-60.67093,3.63362,60.67093,22412,50
280.28978,-3.36645,-51.86074,3.34019,51.86074,22412,50
280.61381,-3.04199,-43.00786,3.01573,43.00786,22412,50
280.96819,-2.68788,-34.00537,2.66162,34.00537,22412,50
281.34478,-2.31074,-25.16654,2.28448,25.16654,22412,50
281.78978,-1.86566,-17.04364,1.83940,17.04364,22412,50
282.30078,-1.35470,-8.84792,1.32844,8.84792,22412,50
282.68078,-1.52929,-13.07256,1.50303,13.07256,22476,50
283.11178,-1.96570,-21.42037,1.93943,21.42037,22476,51
283.50181,-2.35599,-30.09567,2.32973,30.09567,22476,51
283.85081,-2.70509,-38.72338,2.67883,38.72338,22476,51
284.19878,-3.05321,-47.42455,3.02695,47.42455,22476,51
284.56822,-3.42207,-56.52774,3.39581,56.52774,22476,51
284.90078,-3.75497,-64.81410,3.72871,64.81409,22476,51
285.22581,-3.86454,-66.70583,3.83828,66.70583,22476,51
285.49781,-3.57842,-57.96337,3.55216,57.96337,22412,51
285.82181,-3.25194,-48.58723,3.22568,48.58723,22412,51
286.14578,-2.92757,-39.91559,2.90131,39.91559,22412,51
286.49478,-2.57865,-31.18213,2.55239,31.18213,22412,51
286.87781,-2.19561,-22.83047,2.16935,22.83047,22412,51
287.37378,-1.69974,-14.43272,1.67347,14.43272,22412,51
287.86819,-1.25238,-7.30965,1.22611,7.30965,22412,51
288.26819,-1.67995,-16.01021,1.65368,16.01021,22476,51
288.67381,-2.08778,-23.99766,2.06152,23.99766,22476,52
289.05881,-2.47279,-33.06356,2.44653,33.06356,22476,52
289.40681,-2.82077,-41.57246,2.79451,41.57246,22476,52
289.76481,-3.17891,-50.42850,3.15265,50.42850,22476,52
290.11481,-3.52876,-59.16004,3.50250,59.16004,22476,52
290.46819,-3.88158,-67.96360,3.85532,67.96360,22476,52
290.71878,-3.80864,-64.98390,3.78238,64.98389,22476,52
291.01178,-3.50519,-55.80963,3.47893,55.80963,22412,52
291.31181,-3.20366,-47.29400,3.17740,47.29400,22412,52
291.66819,-2.84733,-37.90612,2.82107,37.90612,22412,52
292.01981,-2.49540,-28.99731,2.46914,28.99731,22412,52
292.42178,-2.09344,-20.78606,2.06718,20.78606,22412,52
292.93178,-1.58349,-12.55537,1.55723,12.55537,22412,52
293.36819,-1.33078,-9.07405,1.30452,9.07405,22412,52
293.79378,-1.77463,-17.64021,1.74837,17.64021,22476,52
294.19981,-2.18164,-26.14377,2.15538,26.14377,22476,53
294.56822,-2.54975,-34.96785,2.52349,34.96785,22476,53
294.91378,-2.89554,-43.33345,2.86928,43.33345,22476,53
295.26819,-3.24962,-52.35645,3.22336,52.35645,22476,53
295.62878,-3.61052,-61.02156,3.58425,61.02156,22476,53
295.95678,-3.93851,-69.37547,3.91225,69.37547,22476,53
296.23178,-3.70820,-61.92354,3.68193,61.92354,22476,53
296.53181,-3.40225,-52.87978,3.37599,52.87978,22412,53
296.85081,-3.08249,-43.98912,3.05623,43.98912,22412,53
297.19778,-2.73534,-35.24755,2.70908,35.24755,22412,53
297.56822,-2.36523,-26.16234,2.33897,26.16234,22412,53
298.00078,-1.93225,-18.03117,1.90599,18.03116,22412,53
298.49978,-1.43337,-10.12103,1.40711,10.12103,22412,53
298.89778,-1.46497,-11.96964,1.43871,11.96964,22412,53
299.35481,-1.93020,-20.74508,1.90394,20.74508,22476,54
299.72681,-2.30255,-28.78408,2.27629,28.78408,22476,54
300.08078,-2.65669,-37.47165,2.63043,37.47165,22476,54
300.43978,-3.01566,-46.41049,2.98940,46.41049,22476,54
300.78378,-3.35948,-54.82985,3.33322,54.82985,22476,54
301.14278,-3.71855,-63.92556,3.69229,63.92556,22476,54
301.46281,-3.91194,-68.06637,3.88568,68.06638,22476,54
301.75181,-3.60258,-58.65403,3.57632,58.65403,22412,54
302.05178,-3.29966,-49.87981,3.27339,49.87981,22412,54
302.36819,-2.98318,-41.18417,2.95692,41.18417,22412,54
302.73481,-2.61626,-32.07577,2.59000,32.07577,22412,54
303.10678,-2.24422,-23.69462,2.21796,23.69462,22412,54
303.57581,-1.77536,-15.49735,1.74910,15.49735,22412,54
304.06822,-1.28332,-7.54680,1.25706,7.54680,22412,54
304.45678,-1.62325,-14.91113,1.59698,14.91113,22476,54
304.88581,-2.05542,-23.20771,2.02916,23.20771,22476,55
305.25878,-2.42850,-31.87712,2.40224,31.87712,22476,55
305.61178,-2.78147,-40.47272,2.75521,40.47272,22476,55
305.96819,-3.13759,-49.50403,3.11133,49.50404,22476,55
306.32678,-3.49647,-58.14444,3.47021,58.14444,22476,55
306.66819,-3.83730,-66.74108,3.81104,66.74108,22476,55
306.94778,-3.80792,-65.05601,3.78166,65.05601,22476,55
307.23578,-3.50905,-56.01709,3.48279,56.01709,22412,55
307.54778,-3.19537,-46.75634,3.16911,46.75634,22412,55
307.88378,-2.85900,-38.27367,2.83274,38.27367,22412,55
308.24381,-2.49914,-29.24907,2.47288,29.24907,22412,55
308.66181,-2.08116,-20.52999,2.05490,20.52999,22412,55
309.16581,-1.57721,-12.37356,1.55095,12.37356,22412,55
309.56822,-1.33252,-9.05384,1.30626,9.05384,22412,55
309.98778,-1.77213,-17.65375,1.74587,17.65375,22476,55
310.39778,-2.18335,-26.03078,2.15708,26.03078,22476,56
310.76819,-2.55340,-34.92492,2.52714,34.92492,22476,56
311.10878,-2.89416,-43.31404,2.86790,43.31404,22476,56
311.46819,-3.25324,-52.20989,3.22698,52.20989,22476,56
311.79581,-3.58116,-60.41994,3.55490,60.41994,22476,56
312.13981,-3.92512,-68.93805,3.89886,68.93806,22476,56
312.38278,-3.74285,-62.96714,3.71659,62.96714,22476,56
312.68281,-3.43514,-53.78732,3.40888,53.78732,22412,56
312.99678,-3.12019,-44.83042,3.09393,44.83042,22412,56
313.32778,-2.78899,-36.34442,2.76272,36.34442,22412,56
313.66819,-2.44891,-27.99302,2.42265,27.99302,22412,56
314.09181,-2.02504,-19.47347,1.99878,19.47347,22412,56
314.59681,-1.52002,-11.50156,1.49376,11.50156,22412,56
315.00978,-1.39351,-10.51498,1.36725,10.51498,22412,56
315.44678,-1.84331,-19.04568,1.81705,19.04568,22476,57
315.84978,-2.24705,-27.36658,2.22078,27.36658,22476,57
316.16819,-2.56526,-35.14943,2.53900,35.14943,22476,57
316.52178,-2.91908,-43.92116,2.89282,43.92116,22476,57
316.86819,-3.26508,-52.47510,3.23882,52.47510,22476,57
317.18178,-3.57906,-60.30073,3.55279,60.30073,22476,57
317.53978,-3.93699,-69.33034,3.91073,69.33035,22476,57
317.79581,-3.73283,-62.59333,3.70657,62.59333,22476,57
318.09978,-3.42195,-53.30857,3.39569,53.30857,22412,57
318.36481,-3.15620,-45.83858,3.12994,45.83858,22412,57
318.66819,-2.85278,-37.92838,2.82652,37.92838,22412,57
318.91878,-2.60189,-31.62656,2.57563,31.62656,22412,57
319.30978,-2.21087,-23.01179,2.18460,23.01179,22412,57
319.76981,-1.75104,-15.06293,1.72478,15.06293,22412,57
320.26819,-1.26337,-7.22157,1.23711,7.22157,22412,57
320.64978,-1.66064,-15.51435,1.63438,15.51435,22604,57
321.06822,-2.08112,-23.82062,2.05486,23.82062,22604,57
321.43681,-2.45018,-32.35884,2.42392,32.35884,22604,58
321.78281,-2.79617,-40.80998,2.76991,40.80998,22604,58
322.14778,-3.16132,-49.88831,3.13506,49.88831,22604,58
322.49578,-3.50917,-58.51175,3.48291,58.51175,22604,58
322.80878,-3.82211,-66.36585,3.79585,66.36585,22604,58
323.10081,-3.82746,-65.47873,3.80120,65.47873,22604,58
323.36819,-3.54915,-57.00712,3.52289,57.00711,22540,58
323.66878,-3.24611,-48.37601,3.21985,48.37601,22540,58
323.93378,-2.98074,-41.07929,2.95448,41.07928,22540,58
324.18578,-2.72882,-34.84969,2.70256,34.84969,22540,58
324.56822,-2.34670,-25.78465,2.32044,25.78465,22540,58
325.00181,-1.91276,-17.61183,1.88650,17.61183,22540,58
325.51178,-1.40282,-9.57224,1.37656,9.57224,22540,58
325.89881,-1.49879,-12.52123,1.47253,12.52123,22540,58
326.33781,-1.94468,-20.98217,1.91842,20.98217,22604,59
326.72181,-2.32896,-29.36841,2.30270,29.36841,22604,59
327.06822,-2.67516,-37.92056,2.64890,37.92056,22604,59
327.39278,-3.00005,-45.91473,2.97379,45.91473,22604,59
327.71681,-3.32400,-53.87715,3.29774,53.87715,22604,59
328.02678,-3.63399,-61.72257,3.60773,61.72257,22604,59
328.33678,-3.94389,-69.48376,3.91763,69.48376,22604,59
328.60878,-3.72078,-62.21488,3.69452,62.21488,22604,59
328.86478,-3.45894,-54.35957,3.43268,54.35957,22540,59
329.11381,-3.20893,-47.31231,3.18267,47.31231,22540,59
329.41778,-2.90464,-39.25655,2.87838,39.25655,22540,59
329.73978,-2.58270,-31.12337,2.55644,31.12337,22540,59
330.12578,-2.19669,-22.67962,2.17043,22.67962,22540,59
330.60081,-1.72178,-14.53613,1.69551,14.53613,22540,59
331.06822,-1.25756,-7.05953,1.23130,7.05953,22540,59