File: data-raw/Experiment 2/Results/INSTRON data/Experiment 2.is_ccyclic_RawData/Specimen_RawData_9.csv
Text Inputs : Specimen label,"Long Plate 3 T1"

Time,Extension,Load,Compressive extension,Compressive load,Segment ID,Total Cycle Count
(sec),(mm),(N),(mm),(N),,
0.00000,-0.02552,-0.14035,0.00000,0.14035,12835,0
0.53280,-0.02552,-0.16991,0.00000,0.16991,12835,0
0.99180,-0.02552,-0.14385,0.00000,0.14385,12835,0
1.72520,-0.32984,-5.08832,0.30432,5.08832,3220,0
2.92180,-1.40741,-20.23285,1.38189,20.23285,22476,0
3.60580,-2.09160,-31.83044,2.06608,31.83044,22476,0
4.30980,-2.79547,-44.49847,2.76995,44.49847,22476,0
5.12180,-3.60766,-59.20787,3.58214,59.20787,22476,0
5.71580,-4.19796,-69.78519,4.17244,69.78519,22476,0
6.24880,-3.65948,-56.06170,3.63396,56.06170,22412,0
6.84380,-3.06341,-42.84697,3.03789,42.84697,22412,0
7.46180,-2.44526,-30.59834,2.41974,30.59834,22412,0
7.94080,-1.96626,-21.84601,1.94073,21.84601,22412,0
9.01980,-0.88727,-7.43336,0.86175,7.43336,22412,0
9.84080,-1.66639,-20.40764,1.64087,20.40764,22476,1
10.39080,-2.21668,-30.84974,2.19116,30.84974,22476,1
10.99380,-2.81951,-42.66785,2.79399,42.66785,22476,1
11.38980,-3.21573,-50.07023,3.19021,50.07022,22476,1
11.81980,-3.64567,-58.39523,3.62015,58.39523,22476,1
12.07480,-3.90054,-63.14246,3.87502,63.14246,22476,1
12.35980,-4.18559,-68.63894,4.16007,68.63895,22476,1
12.64580,-4.01730,-63.54028,3.99177,63.54028,22476,1
13.15580,-3.49969,-51.58452,3.47417,51.58451,22412,1
13.56780,-3.08759,-42.65772,3.06207,42.65772,22412,1
13.92520,-2.73063,-35.37703,2.70511,35.37703,22412,1
14.27280,-2.38240,-28.68673,2.35688,28.68673,22412,1
14.74580,-1.90933,-20.32189,1.88381,20.32189,22412,1
16.02520,-1.20108,-12.21817,1.17556,12.21817,22476,1
16.97080,-2.15255,-28.94513,2.12703,28.94513,22476,2
17.58580,-2.76748,-40.87950,2.74196,40.87950,22476,2
18.35580,-3.53745,-55.71324,3.51193,55.71324,22476,2
19.25380,-4.13017,-65.85561,4.10465,65.85561,22476,2
19.98480,-3.38644,-48.42636,3.36092,48.42636,22412,2
20.67380,-2.69747,-34.37910,2.67195,34.37910,22412,2
21.52520,-1.84644,-19.01155,1.82092,19.01155,22412,2
22.83180,-1.33478,-13.98717,1.30926,13.98717,22476,2
23.81680,-2.32242,-31.75332,2.29690,31.75332,22476,3
24.47580,-2.98145,-44.71166,2.95593,44.71166,22476,3
25.27980,-3.78549,-60.23381,3.75997,60.23381,22476,3
25.97980,-4.11574,-65.04922,4.09022,65.04922,22476,3
26.52380,-3.56159,-52.10245,3.53607,52.10245,22412,3
27.12980,-2.95525,-39.11698,2.92973,39.11698,22412,3
27.60180,-2.48326,-29.97231,2.45774,29.97231,22412,3
28.06180,-2.02312,-21.62840,1.99760,21.62840,22412,3
29.32480,-1.11759,-10.34163,1.09207,10.34163,22412,3
30.28380,-2.08744,-26.90493,2.06191,26.90493,22476,4
31.08480,-2.88836,-42.73635,2.86284,42.73635,22476,4
31.80080,-3.60455,-56.46914,3.57903,56.46914,22476,4
32.56180,-4.26512,-68.84313,4.23959,68.84312,22476,4
33.22520,-3.57651,-52.24328,3.55099,52.24328,22412,4
34.09580,-2.70532,-34.01065,2.67980,34.01065,22412,4
34.80580,-1.99505,-20.92732,1.96953,20.92732,22412,4
36.18280,-1.29635,-12.88534,1.27083,12.88534,22476,4
37.21380,-2.33116,-31.43633,2.30564,31.43633,22476,5
38.07280,-3.19030,-48.25075,3.16478,48.25076,22476,5
38.92480,-4.04212,-64.67954,4.01660,64.67954,22476,5
39.70080,-3.79317,-56.98010,3.76765,56.98010,22412,5
40.22520,-3.26798,-45.07231,3.24246,45.07232,22412,5
40.87180,-2.62094,-32.08546,2.59542,32.08546,22412,5
41.52280,-1.96981,-20.37911,1.94429,20.37911,22412,5
42.81180,-1.25378,-12.20177,1.22826,12.20177,22476,5
43.82980,-2.27709,-30.22311,2.25157,30.22311,22476,6
44.62520,-3.07208,-45.81198,3.04656,45.81198,22476,6
45.39680,-3.84400,-60.79343,3.81848,60.79343,22476,6
46.20880,-3.97151,-61.01278,3.94599,61.01278,22412,6
46.82520,-3.35191,-46.93337,3.32639,46.93337,22412,6
47.43480,-2.74191,-34.36438,2.71639,34.36438,22412,6
48.00480,-2.17185,-23.51264,2.14633,23.51264,22412,6
49.09680,-1.07980,-8.41654,1.05428,8.41654,22412,6
50.13880,-1.90979,-22.79921,1.88427,22.79921,22476,7
50.94580,-2.71699,-38.81069,2.69147,38.81069,22476,7
51.85180,-3.62304,-56.36558,3.59752,56.36557,22476,7
52.72520,-4.14267,-65.06627,4.11715,65.06627,22476,7
53.41780,-3.43867,-48.72194,3.41315,48.72194,22412,7
54.04780,-2.80864,-35.50861,2.78312,35.50861,22412,7
54.80980,-2.04653,-21.41022,2.02101,21.41022,22412,7
56.03480,-1.12700,-9.86837,1.10148,9.86837,22412,7
57.16380,-2.26884,-29.79770,2.24332,29.79770,22604,8
58.08180,-3.18687,-47.82623,3.16135,47.82623,22604,8
59.03680,-4.14184,-66.36656,4.11631,66.36656,22604,8
59.81880,-3.72437,-55.03391,3.69884,55.03391,22540,8
60.56980,-2.97258,-38.67759,2.94706,38.67759,22540,8
61.22280,-2.31962,-26.05284,2.29410,26.05284,22540,8
62.49980,-1.04244,-7.80225,1.01692,7.80225,22540,8
63.68480,-2.10166,-26.34018,2.07614,26.34018,22604,9
64.50880,-2.92550,-42.72254,2.89998,42.72254,22604,9
65.38880,-3.80558,-59.76677,3.78005,59.76677,22604,9
66.26380,-3.97783,-60.83922,3.95231,60.83922,22540,9
66.86180,-3.37637,-47.14179,3.35085,47.14179,22540,9
67.58980,-2.64837,-32.13475,2.62285,32.13475,22540,9
68.32520,-1.91320,-19.09898,1.88768,19.09898,22540,9
69.87380,-1.21709,-11.40432,1.19157,11.40432,22540,9
71.02980,-2.37700,-31.79203,2.35148,31.79203,22476,10
72.12520,-3.47207,-53.22499,3.44655,53.22499,22476,10
73.03180,-4.29206,-68.82638,4.26654,68.82639,22476,10
73.82980,-3.46689,-49.12708,3.44137,49.12708,22412,10
74.62520,-2.67182,-32.60342,2.64630,32.60342,22412,10
75.36380,-1.93262,-19.35572,1.90710,19.35572,22412,10
76.66480,-1.39680,-13.88209,1.37128,13.88209,22476,10
77.52180,-2.25691,-29.22003,2.23139,29.22003,22476,11
78.12480,-2.85973,-41.14844,2.83421,41.14844,22476,11
78.61380,-3.34882,-50.75413,3.32330,50.75413,22476,11
79.07980,-3.81481,-59.78568,3.78929,59.78568,22476,11
79.49380,-4.22894,-67.84245,4.20342,67.84245,22476,11
79.84780,-4.06290,-62.72344,4.03738,62.72343,22476,11
80.15780,-3.74744,-55.43330,3.72192,55.43330,22412,11
80.56680,-3.33769,-46.11941,3.31217,46.11941,22412,11
81.04080,-2.86352,-36.10752,2.83800,36.10752,22412,11
81.43780,-2.46655,-28.52572,2.44103,28.52572,22412,11
81.96480,-1.93936,-19.43398,1.91384,19.43398,22412,11
83.22520,-1.34960,-13.01928,1.32408,13.01928,22476,11
84.11280,-2.24171,-28.81970,2.21619,28.81970,22476,12
84.76780,-2.89651,-41.81326,2.87099,41.81326,22476,12
85.66480,-3.79358,-59.31224,3.76806,59.31224,22476,12
86.41380,-4.14181,-64.55339,4.11628,64.55340,22476,12
87.08180,-3.46439,-48.85593,3.43887,48.85593,22412,12
87.66480,-2.88126,-36.43265,2.85574,36.43265,22412,12
88.25980,-2.28636,-25.05602,2.26084,25.05602,22412,12
89.47980,-1.06629,-7.83585,1.04077,7.83585,22412,12
90.61380,-2.08631,-25.60712,2.06079,25.60712,22476,13
91.34580,-2.81824,-40.20170,2.79272,40.20170,22476,13
92.11980,-3.59240,-55.37702,3.56688,55.37702,22476,13
92.92520,-4.29926,-68.72199,4.27374,68.72198,22476,13
93.52180,-3.67660,-53.59225,3.65108,53.59225,22412,13
94.29480,-2.90292,-36.77844,2.87740,36.77844,22412,13
95.18180,-2.01589,-20.43351,1.99037,20.43351,22412,13
96.42520,-1.23749,-11.19823,1.21197,11.19823,22412,13
97.32780,-2.14818,-26.73739,2.12266,26.73739,22476,14
98.11980,-2.93997,-42.65196,2.91445,42.65195,22476,14
98.80280,-3.62318,-55.90975,3.59766,55.90975,22476,14
99.68280,-4.19147,-65.73411,4.16595,65.73411,22476,14
100.43280,-3.42880,-47.94933,3.40328,47.94933,22412,14
101.20080,-2.66080,-31.99141,2.63528,31.99141,22412,14
102.18480,-1.67682,-15.35842,1.65130,15.35842,22412,14
103.30480,-1.47912,-14.92980,1.45360,14.92980,22476,14
104.16780,-2.34389,-30.67921,2.31837,30.67921,22476,15
104.74880,-2.92478,-42.27013,2.89926,42.27013,22476,15
105.34880,-3.52492,-53.89240,3.49940,53.89240,22476,15
106.02520,-4.20100,-67.08936,4.17548,67.08936,22476,15
106.62520,-3.87043,-57.98192,3.84491,57.98192,22412,15
107.15280,-3.34087,-46.03545,3.31535,46.03545,22412,15
107.59680,-2.89660,-36.62436,2.87108,36.62436,22412,15
108.20880,-2.28474,-24.81129,2.25922,24.81129,22412,15
109.42520,-1.06869,-7.71619,1.04317,7.71619,22412,15
110.52520,-2.09282,-25.53089,2.06730,25.53089,22476,16
111.26580,-2.83372,-40.26501,2.80820,40.26501,22476,16
112.30380,-3.87170,-60.70810,3.84617,60.70810,22476,16
112.92580,-4.19882,-65.85462,4.17330,65.85462,22476,16
113.39880,-3.71317,-54.42260,3.68765,54.42260,22412,16
113.92520,-3.18658,-42.48762,3.16106,42.48762,22412,16
114.40080,-2.71062,-32.85117,2.68510,32.85117,22412,16
114.92380,-2.18759,-23.01259,2.16207,23.01259,22412,16
115.93780,-1.17361,-8.87308,1.14808,8.87309,22412,16
116.98980,-1.92135,-22.26652,1.89583,22.26652,22476,17
117.61780,-2.54950,-34.70273,2.52398,34.70273,22476,17
118.19580,-3.12766,-46.11069,3.10214,46.11069,22476,17
118.56380,-3.49553,-53.27501,3.47001,53.27501,22476,17
118.91080,-3.84249,-60.02750,3.81697,60.02750,22476,17
119.46280,-4.32065,-69.12799,4.29513,69.12799,22476,17
119.89180,-3.86485,-57.79171,3.83933,57.79171,22412,17
120.39680,-3.35837,-46.29735,3.33284,46.29735,22412,17
120.92980,-2.82527,-34.99947,2.79975,34.99947,22412,17
121.60780,-2.14734,-22.31495,2.12182,22.31495,22412,17
122.91380,-1.20476,-10.44333,1.17923,10.44333,22412,17
123.86480,-2.16641,-26.92251,2.14089,26.92251,22604,18
124.49080,-2.79233,-39.47235,2.76681,39.47235,22604,18
125.34980,-3.65144,-56.28971,3.62592,56.28971,22604,18
126.15280,-4.25189,-67.20114,4.22637,67.20114,22604,18
126.83180,-3.55539,-50.66838,3.52987,50.66838,22540,18
127.42520,-2.96218,-37.69345,2.93666,37.69345,22540,18
128.10579,-2.28119,-24.55759,2.25567,24.55759,22540,18
129.32520,-1.06214,-7.49985,1.03662,7.49985,22540,18
130.26180,-1.95692,-22.83234,1.93140,22.83234,22604,19
130.98480,-2.68014,-37.11672,2.65462,37.11673,22604,19
131.72080,-3.41602,-51.62700,3.39050,51.62700,22604,19
132.42520,-4.12021,-65.32426,4.09469,65.32426,22604,19
133.15780,-3.85022,-57.31864,3.82470,57.31863,22540,19
133.81080,-3.19596,-42.61892,3.17044,42.61892,22540,19
134.42580,-2.58087,-30.18714,2.55535,30.18714,22540,19
135.22519,-1.78184,-16.60763,1.75632,16.60763,22540,19
136.62520,-1.33822,-12.72380,1.31270,12.72380,22476,19
137.49080,-2.20685,-27.78667,2.18133,27.78667,22476,20
138.19480,-2.91071,-41.79684,2.88519,41.79684,22476,20
138.98680,-3.70288,-57.25683,3.67736,57.25682,22476,20
139.72519,-4.25521,-67.25617,4.22969,67.25616,22476,20
140.22519,-3.73723,-54.83242,3.71171,54.83242,22412,20
140.81280,-3.14854,-41.38792,3.12302,41.38792,22412,20
141.42520,-2.53646,-29.33582,2.51094,29.33582,22412,20
142.09580,-1.86543,-17.88891,1.83991,17.88891,22412,20
143.34280,-1.46417,-14.44761,1.43865,14.44761,22476,20
144.14180,-2.26558,-28.86028,2.24006,28.86028,22476,21
144.76380,-2.88742,-41.22768,2.86190,41.22768,22476,21
145.55680,-3.68061,-56.79234,3.65509,56.79234,22476,21
146.32519,-4.28013,-67.80095,4.25461,67.80095,22476,21
146.99280,-3.59256,-51.44076,3.56704,51.44076,22412,21
147.77680,-2.80823,-34.59559,2.78271,34.59558,22412,21
148.42180,-2.16334,-22.39593,2.13782,22.39593,22412,21
149.72519,-1.21536,-10.44570,1.18984,10.44570,22412,21
150.69280,-2.19430,-27.25692,2.16878,27.25692,22476,22
151.43780,-2.93911,-42.29428,2.91359,42.29428,22476,22
152.16780,-3.66934,-56.47952,3.64382,56.47952,22476,22
152.92780,-4.29789,-68.31846,4.27237,68.31847,22476,22
153.53580,-3.66737,-53.06387,3.64185,53.06387,22412,22
154.23980,-2.96288,-37.48445,2.93736,37.48445,22412,22
155.02519,-2.17793,-22.59403,2.15241,22.59403,22412,22
156.22519,-1.06897,-7.81890,1.04345,7.81890,22412,22
157.32180,-2.19304,-27.20349,2.16752,27.20349,22476,23
158.04280,-2.91385,-41.72188,2.88833,41.72189,22476,23
158.68380,-3.55496,-54.24165,3.52944,54.24165,22476,23
159.23580,-4.10702,-64.89058,4.08149,64.89058,22476,23
159.76780,-4.04149,-61.81050,4.01597,61.81050,22412,23
160.22380,-3.58095,-51.14102,3.55543,51.14102,22412,23
160.74780,-3.05661,-39.40400,3.03109,39.40400,22412,23
161.27580,-2.52863,-29.08541,2.50311,29.08541,22412,23
162.12520,-1.67961,-14.96830,1.65409,14.96830,22412,23
163.32519,-1.60890,-16.66487,1.58338,16.66487,22476,23
164.25780,-2.54265,-34.30639,2.51713,34.30639,22476,24
165.09980,-3.38465,-50.86634,3.35913,50.86634,22476,24
166.07978,-4.35688,-69.93033,4.33136,69.93033,22476,24
166.64380,-3.77920,-55.59681,3.75368,55.59681,22412,24
167.36180,-3.06036,-39.42988,3.03483,39.42988,22412,24
168.21480,-2.20748,-22.94596,2.18196,22.94596,22412,24
169.44880,-1.10214,-8.31319,1.07662,8.31319,22412,24
170.42480,-2.10148,-25.28971,2.07596,25.28971,22476,25
171.12780,-2.80438,-39.42265,2.77886,39.42265,22476,25
171.73380,-3.41033,-51.29745,3.38481,51.29745,22476,25
172.36980,-4.04632,-63.80714,4.02080,63.80714,22476,25
173.00780,-4.01395,-61.01945,3.98843,61.01945,22412,25
173.52480,-3.49323,-49.04687,3.46771,49.04687,22412,25
174.17280,-2.84514,-35.09121,2.81962,35.09121,22412,25
174.77980,-2.23828,-23.46953,2.21276,23.46953,22412,25
175.81080,-1.20731,-9.01953,1.18179,9.01953,22412,25
176.86380,-1.93805,-22.28597,1.91253,22.28597,22476,26
177.65080,-2.72530,-37.81507,2.69978,37.81507,22476,26
178.35680,-3.43114,-51.72595,3.40562,51.72595,22476,26
179.02519,-4.09929,-64.76733,4.07377,64.76733,22476,26
179.65780,-3.98298,-60.26860,3.95746,60.26860,22412,26
180.14280,-3.49504,-49.06411,3.46952,49.06411,22412,26
180.60480,-3.03290,-38.83507,3.00738,38.83507,22412,26
181.02880,-2.60899,-30.44147,2.58347,30.44147,22412,26
181.36780,-2.26998,-24.03967,2.24446,24.03967,22412,26
182.18978,-1.44783,-11.99981,1.42231,11.99981,22412,26
182.92520,-1.37882,-12.86102,1.35330,12.86102,22476,26
183.51980,-1.97770,-22.87754,1.95218,22.87754,22476,27
183.81580,-2.27396,-28.76723,2.24844,28.76723,22476,27
184.11680,-2.57490,-34.85489,2.54938,34.85489,22476,27
184.36480,-2.82285,-39.72959,2.79733,39.72959,22476,27
184.57780,-3.03594,-44.06019,3.01042,44.06019,22476,27
184.82780,-3.28593,-48.91724,3.26041,48.91724,22476,27
185.15380,-3.61200,-55.30871,3.58647,55.30871,22476,27
185.61780,-4.07586,-64.35198,4.05034,64.35197,22476,27
185.99680,-4.25229,-67.07937,4.22676,67.07937,22476,27
186.40680,-3.82578,-56.63697,3.80026,56.63697,22412,27
186.88680,-3.34471,-45.78134,3.31919,45.78135,22412,27
187.35580,-2.87555,-35.56929,2.85003,35.56929,22412,27
187.85080,-2.38053,-26.06771,2.35501,26.06771,22412,27
188.47680,-1.75470,-15.94429,1.72918,15.94429,22412,27
189.70478,-1.56745,-15.85889,1.54193,15.85889,22604,27
190.43580,-2.29960,-29.26248,2.27407,29.26248,22604,28
191.11380,-2.97760,-42.84509,2.95208,42.84509,22604,28
191.74780,-3.61169,-55.24974,3.58617,55.24974,22604,28
192.51480,-4.35121,-69.70103,4.32569,69.70103,22604,28
192.92678,-3.91418,-58.64510,3.88866,58.64510,22540,28
193.36480,-3.47433,-48.63675,3.44881,48.63675,22540,28
193.82480,-3.01423,-38.34905,2.98871,38.34905,22540,28
194.28280,-2.55630,-29.32438,2.53078,29.32438,22540,28
194.82519,-2.01417,-19.82464,1.98865,19.82464,22540,28
195.87880,-1.14349,-8.80489,1.11797,8.80489,22540,28
196.91580,-2.19937,-27.07213,2.17385,27.07213,22604,29
197.41980,-2.70328,-37.29388,2.67776,37.29388,22604,29
197.95180,-3.23545,-47.78783,3.20993,47.78783,22604,29
198.62520,-3.90818,-61.15298,3.88266,61.15298,22604,29
199.22519,-4.21965,-66.02752,4.19413,66.02752,22604,29
199.87078,-3.56021,-50.53599,3.53469,50.53599,22540,29
200.47080,-2.95996,-37.13690,2.93444,37.13690,22540,29
200.90280,-2.52798,-28.79521,2.50246,28.79521,22540,29
201.40380,-2.02681,-20.00621,2.00129,20.00621,22540,29
202.44580,-1.04005,-7.10065,1.01453,7.10065,22540,29
203.56380,-1.88297,-21.39422,1.85745,21.39422,22476,29
203.94880,-2.26816,-28.74000,2.24263,28.74000,22476,30
204.26780,-2.58707,-35.15974,2.56155,35.15974,22476,30
204.52880,-2.84802,-40.24182,2.82250,40.24182,22476,30
204.85778,-3.17719,-46.84296,3.15167,46.84296,22476,30
205.18280,-3.50212,-53.22909,3.47660,53.22909,22476,30
205.46978,-3.78911,-58.77307,3.76359,58.77307,22476,30
206.00680,-4.32603,-69.35118,4.30051,69.35118,22476,30
206.50680,-3.86939,-57.62548,3.84387,57.62548,22412,30
206.99778,-3.37685,-46.54159,3.35133,46.54159,22412,30
207.41780,-2.95676,-37.16184,2.93124,37.16184,22412,30
207.76180,-2.61287,-30.44752,2.58735,30.44752,22412,30
208.32380,-2.05070,-20.35196,2.02518,20.35196,22412,30
209.21580,-1.15884,-8.35375,1.13331,8.35375,22412,30
209.98380,-1.72050,-18.37485,1.69498,18.37485,22476,31
210.61780,-2.35488,-30.33094,2.32936,30.33094,22476,31
211.31580,-3.05295,-44.30735,3.02743,44.30735,22476,31
211.80280,-3.53993,-53.81057,3.51441,53.81057,22476,31
212.31080,-4.04783,-63.74180,4.02231,63.74180,22476,31
212.81780,-4.16242,-64.60164,4.13690,64.60165,22476,31
213.28080,-3.69017,-53.47779,3.66465,53.47779,22412,31
213.67480,-3.29575,-44.68298,3.27023,44.68298,22412,31
214.15780,-2.81265,-34.23396,2.78712,34.23396,22412,31
214.57480,-2.39555,-26.22197,2.37003,26.22197,22412,31
215.47680,-1.49362,-12.44849,1.46810,12.44849,22412,31
216.57880,-1.74551,-18.77402,1.71999,18.77402,22476,32
217.18978,-2.35683,-30.33392,2.33131,30.33392,22476,32
217.62780,-2.79480,-39.12112,2.76928,39.12112,22476,32
218.31880,-3.48583,-52.74784,3.46031,52.74784,22476,32
218.82978,-3.99672,-62.71338,3.97120,62.71339,22476,32
219.42520,-4.12528,-63.57992,4.09976,63.57992,22476,32
220.04180,-3.50067,-49.14990,3.47515,49.14990,22412,32
220.70880,-2.83360,-34.64480,2.80808,34.64481,22412,32
221.14878,-2.39349,-26.12319,2.36797,26.12319,22412,32
221.90480,-1.63766,-14.42746,1.61213,14.42746,22412,32
222.98580,-1.57162,-15.79850,1.54610,15.79850,22476,32
223.75780,-2.34479,-30.08957,2.31927,30.08957,22476,33
224.22519,-2.81175,-39.39784,2.78623,39.39784,22476,33
224.65880,-3.24595,-47.94466,3.22043,47.94466,22476,33
225.07978,-3.66691,-56.34825,3.64139,56.34825,22476,33
225.48478,-4.07175,-64.22802,4.04623,64.22802,22476,33
225.82180,-4.33492,-69.16268,4.30940,69.16268,22476,33
226.09080,-4.04176,-61.58571,4.01624,61.58571,22412,33
226.37780,-3.75119,-54.82444,3.72567,54.82444,22412,33
226.61080,-3.51753,-49.55618,3.49201,49.55618,22412,33
226.93880,-3.18961,-42.24713,3.16409,42.24713,22412,33
227.41680,-2.71161,-32.11705,2.68609,32.11705,22412,33
228.03580,-2.09257,-20.97235,2.06705,20.97235,22412,33
228.82519,-1.30361,-10.03262,1.27808,10.03262,22412,33
229.73680,-1.74535,-18.74795,1.71983,18.74795,22476,34
230.28480,-2.29366,-28.99185,2.26814,28.99185,22476,34
230.65280,-2.66165,-36.35105,2.63613,36.35105,22476,34
231.02519,-3.03375,-43.88869,3.00823,43.88869,22476,34
231.43780,-3.44659,-51.92161,3.42107,51.92161,22476,34
231.70780,-3.71678,-57.30389,3.69126,57.30389,22476,34
232.03878,-4.04758,-63.77177,4.02206,63.77177,22476,34
232.26780,-4.27677,-68.28566,4.25125,68.28566,22476,34
232.62580,-4.06589,-62.15888,4.04036,62.15887,22412,34
232.92520,-3.76229,-55.09683,3.73677,55.09683,22412,34
233.28480,-3.40145,-46.96775,3.37593,46.96775,22412,34
233.62520,-3.06149,-39.33882,3.03597,39.33882,22412,34
233.97780,-2.70860,-32.01902,2.68308,32.01902,22412,34
234.34580,-2.34051,-25.11256,2.31499,25.11256,22412,34
235.18680,-1.49942,-12.44787,1.47390,12.44787,22412,34
236.26180,-1.70009,-17.95389,1.67457,17.95389,22476,35
236.86780,-2.30657,-29.20858,2.28105,29.20858,22476,35
237.41680,-2.85555,-40.19516,2.83003,40.19516,22476,35
237.92520,-3.36366,-50.27991,3.33814,50.27991,22476,35
238.40280,-3.84157,-59.70972,3.81605,59.70972,22476,35
238.92780,-4.36035,-69.85158,4.33483,69.85158,22476,35
239.42280,-3.85457,-57.20450,3.82905,57.20449,22412,35
239.82780,-3.44825,-48.00146,3.42273,48.00146,22412,35
240.25180,-3.02419,-38.42351,2.99866,38.42351,22412,35
240.66980,-2.60632,-30.11278,2.58080,30.11278,22412,35
241.28380,-1.99210,-19.29951,1.96658,19.29951,22412,35
242.56180,-1.39846,-13.05913,1.37294,13.05913,22476,35
243.37980,-2.22046,-27.45788,2.19494,27.45788,22476,36
244.13080,-2.97133,-42.60295,2.94581,42.60295,22476,36
244.72519,-3.56540,-54.25528,3.53988,54.25528,22476,36
245.35978,-4.20045,-66.80525,4.17493,66.80525,22476,36
245.95678,-3.89292,-58.12972,3.86740,58.12972,22412,36
246.65880,-3.18927,-42.23930,3.16375,42.23930,22412,36
247.13880,-2.70926,-31.95776,2.68374,31.95776,22412,36
247.92519,-1.92296,-18.27313,1.89744,18.27313,22412,36
249.09080,-1.36028,-12.38337,1.33476,12.38337,22476,36
249.97380,-2.24836,-28.04402,2.22284,28.04402,22476,37
250.45678,-2.73133,-37.74434,2.70581,37.74434,22476,37
250.77880,-3.05328,-44.18432,3.02776,44.18431,22476,37
251.16280,-3.43716,-51.76713,3.41164,51.76713,22476,37
251.49578,-3.77027,-58.41131,3.74475,58.41131,22476,37
251.92780,-4.20234,-66.84562,4.17682,66.84562,22476,37
252.35778,-4.06746,-62.22696,4.04194,62.22696,22412,37
252.77880,-3.64139,-52.42238,3.61587,52.42238,22412,37
253.23880,-3.18106,-41.98329,3.15554,41.98329,22412,37
253.65980,-2.76001,-32.88919,2.73449,32.88919,22412,37
254.42519,-1.99484,-19.31182,1.96932,19.31182,22412,37
255.72519,-1.43783,-13.65257,1.41231,13.65257,22604,37
256.56778,-2.28413,-28.70788,2.25861,28.70788,22604,38
257.21978,-2.93597,-41.78122,2.91045,41.78122,22604,38
257.82519,-3.54113,-53.77266,3.51561,53.77266,22604,38
258.32519,-4.04100,-63.59500,4.01548,63.59501,22604,38
258.74780,-4.24671,-66.85132,4.22119,66.85132,22604,38
259.02520,-3.95546,-59.56011,3.92994,59.56011,22540,38
259.38880,-3.58912,-51.19671,3.56360,51.19670,22540,38
259.74578,-3.23193,-43.28249,3.20641,43.28249,22540,38
260.10580,-2.87176,-35.17525,2.84624,35.17525,22540,38
260.49578,-2.48184,-27.60162,2.45632,27.60162,22540,38
260.92520,-2.05267,-20.15080,2.02715,20.15080,22540,38
261.51178,-1.46567,-11.91689,1.44015,11.91689,22540,38
262.23081,-1.39857,-12.91476,1.37305,12.91476,22604,38
262.75281,-1.92469,-21.80835,1.89917,21.80835,22604,39
263.02178,-2.19396,-26.91533,2.16844,26.91533,22604,39
263.28181,-2.45375,-32.10783,2.42823,32.10783,22604,39
263.49478,-2.66689,-36.33438,2.64137,36.33438,22604,39
263.73081,-2.90280,-41.09532,2.87728,41.09533,22604,39
263.93681,-3.10907,-45.24605,3.08355,45.24605,22604,39
264.10778,-3.27997,-48.64141,3.25445,48.64141,22604,39
264.25978,-3.43181,-51.70072,3.40629,51.70072,22604,39
264.43078,-3.60305,-55.06806,3.57753,55.06806,22604,39
264.60181,-3.77395,-58.47469,3.74843,58.47469,22604,39
264.75478,-3.92673,-61.47811,3.90121,61.47811,22604,39
264.89178,-4.06381,-64.07134,4.03829,64.07134,22604,39
265.04481,-4.21700,-67.19586,4.19147,67.19586,22604,39
265.23278,-4.32243,-68.93399,4.29690,68.93398,22604,39
265.45778,-4.07542,-62.47169,4.04990,62.47169,22540,39
265.63278,-3.89643,-58.22648,3.87091,58.22648,22540,39
265.85278,-3.67515,-53.16487,3.64963,53.16487,22540,39
266.10481,-3.42263,-47.44420,3.39711,47.44420,22540,39
266.36381,-3.16372,-41.57756,3.13820,41.57756,22540,39
266.67578,-2.85167,-34.74334,2.82615,34.74334,22540,39
266.98578,-2.54165,-28.66806,2.51613,28.66806,22540,39
267.32519,-2.20283,-22.53369,2.17731,22.53369,22540,39
267.80381,-1.72380,-15.26069,1.69828,15.26069,22540,39
268.92578,-1.14119,-8.81730,1.11567,8.81730,22540,39
269.64481,-1.87102,-21.12073,1.84550,21.12073,22476,39
270.01881,-2.24522,-28.08500,2.21970,28.08500,22476,40
270.24978,-2.47602,-32.74463,2.45050,32.74463,22476,40
270.50978,-2.73614,-37.90974,2.71061,37.90974,22476,40
270.72378,-2.95000,-42.18767,2.92447,42.18767,22476,40
270.95378,-3.18023,-46.79532,3.15471,46.79532,22476,40
271.16278,-3.38911,-50.87024,3.36359,50.87024,22476,40
271.38181,-3.60824,-55.19601,3.58272,55.19601,22476,40
271.62978,-3.85606,-60.09081,3.83054,60.09081,22476,40
271.86881,-4.09512,-64.80636,4.06960,64.80637,22476,40
272.15878,-4.34190,-69.48479,4.31638,69.48479,22476,40
272.40978,-4.06718,-62.21077,4.04166,62.21077,22476,40
272.60981,-3.86324,-57.51741,3.83772,57.51741,22412,40
272.87878,-3.59306,-51.30113,3.56753,51.30112,22412,40
273.12519,-3.34687,-45.79567,3.32134,45.79567,22412,40
273.45578,-3.01571,-38.30261,2.99019,38.30261,22412,40
273.83381,-2.63776,-30.58936,2.61224,30.58937,22412,40
274.21478,-2.25681,-23.45836,2.23129,23.45836,22412,40
274.69078,-1.78074,-16.09381,1.75521,16.09381,22412,40
275.32519,-1.14679,-8.00830,1.12127,8.00830,22412,40
276.09778,-1.78357,-19.25719,1.75805,19.25719,22476,41
276.57778,-2.26395,-28.25670,2.23843,28.25670,22476,41
276.96078,-2.64683,-35.93255,2.62131,35.93255,22476,41
277.30178,-2.98791,-42.90523,2.96239,42.90524,22476,41
277.64881,-3.33493,-49.70454,3.30940,49.70454,22476,41
277.97078,-3.65698,-56.14366,3.63146,56.14366,22476,41
278.25581,-3.94169,-61.66439,3.91617,61.66439,22476,41
278.46281,-4.14895,-65.77108,4.12343,65.77108,22476,41
278.70278,-4.33799,-69.30150,4.31247,69.30150,22476,41
279.01778,-3.99701,-60.55743,3.97149,60.55743,22412,41
279.32519,-3.68711,-53.38401,3.66159,53.38401,22412,41
279.71978,-3.29168,-44.50808,3.26616,44.50808,22412,41
280.04278,-2.96858,-37.14565,2.94306,37.14565,22412,41
280.37681,-2.63463,-30.47285,2.60911,30.47285,22412,41
280.69478,-2.31660,-24.45604,2.29108,24.45604,22412,41
281.38081,-1.63062,-14.10673,1.60509,14.10673,22412,41
282.20378,-1.33545,-11.91260,1.30993,11.91260,22412,41
282.85378,-1.99156,-22.90414,1.96604,22.90414,22476,42
283.17778,-2.31568,-29.30672,2.29016,29.30672,22476,42
283.40078,-2.53868,-33.86874,2.51316,33.86874,22476,42
283.62478,-2.76279,-38.27802,2.73727,38.27802,22476,42
283.77978,-2.91764,-41.43464,2.89212,41.43464,22476,42
283.95778,-3.09591,-44.93187,3.07039,44.93187,22476,42
284.13678,-3.27484,-48.48146,3.24931,48.48146,22476,42
284.31078,-3.44866,-51.97282,3.42314,51.97282,22476,42
284.45881,-3.59690,-54.92194,3.57137,54.92194,22476,42
284.59878,-3.73684,-57.70062,3.71132,57.70062,22476,42
284.73278,-3.87069,-60.34325,3.84517,60.34325,22476,42
284.88181,-4.01965,-63.22472,3.99413,63.22472,22476,42
285.02522,-4.16283,-66.01843,4.13731,66.01843,22476,42
285.13181,-4.26985,-68.24105,4.24433,68.24105,22476,42
285.28378,-4.29045,-68.02777,4.26493,68.02777,22476,42
285.42481,-4.13519,-63.94807,4.10967,63.94807,22476,42
285.59681,-3.95717,-59.65098,3.93165,59.65098,22412,42
285.78581,-3.76628,-55.21142,3.74076,55.21143,22412,42
285.96478,-3.58676,-51.15784,3.56124,51.15784,22412,42
286.15781,-3.39344,-46.83699,3.36792,46.83699,22412,42
286.32519,-3.22661,-43.19017,3.20109,43.19017,22412,42
286.46381,-3.08753,-39.97457,3.06201,39.97457,22412,42
286.61978,-2.93130,-36.36039,2.90578,36.36039,22412,42
286.73481,-2.81645,-33.98797,2.79092,33.98797,22412,42
286.85878,-2.69252,-31.46310,2.66700,31.46310,22412,42
286.98378,-2.56751,-29.27177,2.54199,29.27177,22412,42
287.11278,-2.43841,-26.66862,2.41289,26.66862,22412,42
287.23378,-2.31749,-24.52597,2.29197,24.52597,22412,42
287.45881,-2.09252,-20.77840,2.06700,20.77840,22412,42
287.66581,-1.88544,-17.59818,1.85992,17.59818,22412,42
287.94378,-1.60745,-13.76385,1.58193,13.76385,22412,42
288.20778,-1.34350,-10.39673,1.31798,10.39673,22412,42
288.52522,-1.13116,-8.17857,1.10564,8.17857,22412,42
288.77078,-1.39800,-12.86707,1.37247,12.86707,22412,42
289.08978,-1.72130,-18.14999,1.69578,18.14999,22476,42
289.32519,-1.95655,-22.25066,1.93103,22.25066,22476,43
289.45978,-2.09185,-24.80912,2.06633,24.80912,22476,43
289.59978,-2.23195,-27.48732,2.20643,27.48732,22476,43
289.80978,-2.44166,-31.80226,2.41614,31.80226,22476,43
290.01178,-2.64378,-35.77097,2.61826,35.77097,22476,43
290.22519,-2.85679,-40.08068,2.83127,40.08068,22476,43
290.45881,-3.09095,-44.84896,3.06543,44.84896,22476,43
290.75478,-3.38685,-50.67603,3.36133,50.67603,22476,43
291.10181,-3.73392,-57.65611,3.70840,57.65611,22476,43
291.44278,-4.07479,-64.28719,4.04926,64.28719,22476,43
291.77278,-4.32880,-68.99443,4.30328,68.99443,22476,43
292.05078,-4.02648,-61.22565,4.00096,61.22565,22412,43
292.28378,-3.79040,-55.71327,3.76488,55.71327,22412,43
292.50078,-3.57278,-50.82586,3.54726,50.82586,22412,43
292.70881,-3.36462,-46.18912,3.33910,46.18912,22412,43
292.95278,-3.12058,-40.57341,3.09506,40.57341,22412,43
293.11781,-2.95548,-36.89856,2.92996,36.89856,22412,43
293.28681,-2.78647,-33.39733,2.76095,33.39733,22412,43
293.48481,-2.58856,-29.58969,2.56304,29.58969,22412,43
293.61381,-2.45952,-26.98125,2.43399,26.98125,22412,43
293.75281,-2.32054,-24.52191,2.29502,24.52191,22412,43
293.96781,-2.10561,-20.97712,2.08009,20.97713,22412,43
294.20778,-1.86550,-17.34829,1.83998,17.34829,22412,43
294.56778,-1.50546,-12.41553,1.47994,12.41553,22412,43
295.07581,-1.15732,-8.65896,1.13180,8.65896,22412,43
295.36481,-1.46380,-13.97032,1.43828,13.97032,22476,43
295.65178,-1.75356,-18.72517,1.72804,18.72517,22476,44
295.85181,-1.95364,-22.22134,1.92812,22.22134,22476,44
296.05978,-2.16199,-26.10731,2.13647,26.10731,22476,44
296.21578,-2.31784,-29.37123,2.29232,29.37123,22476,44
296.38278,-2.48486,-32.70970,2.45934,32.70970,22476,44
296.51881,-2.62085,-35.40539,2.59533,35.40540,22476,44
296.65781,-2.75994,-38.23402,2.73442,38.23402,22476,44
296.76678,-2.86885,-40.37757,2.84333,40.37757,22476,44
296.88581,-2.98794,-42.98838,2.96242,42.98838,22476,44
297.01081,-3.11309,-45.31756,3.08757,45.31756,22476,44
297.12578,-3.22811,-47.66246,3.20259,47.66246,22476,44
297.28281,-3.38493,-50.71735,3.35941,50.71735,22476,44
297.41981,-3.52194,-53.44978,3.49642,53.44978,22476,44
297.55781,-3.66002,-56.19574,3.63450,56.19574,22476,44
297.75581,-3.85784,-60.10604,3.83232,60.10604,22476,44
297.97878,-4.08088,-64.39731,4.05536,64.39731,22476,44
298.16478,-4.26702,-68.09945,4.24149,68.09945,22476,44
298.34281,-4.25938,-67.22807,4.23386,67.22807,22476,44
298.52578,-4.06315,-62.12779,4.03763,62.12779,22476,44
298.69878,-3.88639,-58.05105,3.86087,58.05105,22412,44
298.90781,-3.67615,-53.19755,3.65063,53.19755,22412,44
299.13678,-3.44666,-47.99099,3.42114,47.99099,22412,44
299.31478,-3.26871,-44.05404,3.24319,44.05404,22412,44
299.50878,-3.07472,-39.62680,3.04920,39.62680,22412,44
299.75281,-2.83067,-34.26699,2.80515,34.26699,22412,44
299.92978,-2.65366,-30.75777,2.62814,30.75777,22412,44
300.11678,-2.46668,-27.15942,2.44116,27.15942,22412,44
300.32519,-2.25873,-23.41027,2.23321,23.41027,22412,44
300.77178,-1.81163,-16.50927,1.78611,16.50927,22412,44
301.30881,-1.27474,-9.44205,1.24922,9.44205,22412,44
302.05078,-1.63612,-16.63275,1.61060,16.63275,22476,44
302.45678,-2.04286,-23.78443,2.01734,23.78443,22476,45
302.83781,-2.42383,-31.32925,2.39831,31.32925,22476,45
303.32278,-2.90887,-41.13566,2.88335,41.13566,22476,45
303.75278,-3.33908,-49.71876,3.31356,49.71876,22476,45
304.13378,-3.72009,-57.38013,3.69457,57.38013,22476,45
304.45278,-4.03889,-63.53894,4.01337,63.53894,22476,45
304.79178,-4.34045,-69.43128,4.31493,69.43128,22476,45
305.11178,-3.99519,-60.53537,3.96967,60.53537,22412,45
305.30078,-3.80373,-56.07337,3.77821,56.07337,22412,45
305.48081,-3.62311,-51.95829,3.59759,51.95829,22412,45
305.71381,-3.38971,-46.73332,3.36419,46.73331,22412,45
305.98081,-3.12278,-40.59235,3.09726,40.59235,22412,45
306.29881,-2.80465,-33.64122,2.77913,33.64122,22412,45
306.60981,-2.49373,-27.63674,2.46821,27.63674,22412,45
306.89881,-2.20484,-22.52291,2.17932,22.52291,22412,45
307.27878,-1.82474,-16.65844,1.79922,16.65844,22412,45
307.85081,-1.25283,-9.15086,1.22731,9.15086,22412,45
308.30881,-1.40203,-12.83213,1.37650,12.83213,22476,45
308.57678,-1.67420,-17.25323,1.64868,17.25323,22476,46
308.78181,-1.87976,-20.81465,1.85424,20.81465,22476,46
308.99781,-2.09603,-24.78715,2.07050,24.78715,22476,46
309.16981,-2.26806,-28.26646,2.24254,28.26646,22476,46
309.36978,-2.46792,-32.21516,2.44240,32.21516,22476,46
309.61178,-2.71000,-37.11408,2.68448,37.11408,22476,46
309.82178,-2.91987,-41.29371,2.89435,41.29371,22476,46
310.01278,-3.11116,-45.16419,3.08564,45.16419,22476,46
310.19078,-3.28905,-48.72750,3.26353,48.72750,22476,46
310.39278,-3.49103,-52.73623,3.46551,52.73623,22476,46
310.57378,-3.67210,-56.30771,3.64658,56.30771,22476,46
310.73178,-3.82996,-59.43267,3.80444,59.43267,22476,46
310.92081,-4.01889,-63.13975,3.99336,63.13975,22476,46
311.08678,-4.18505,-66.50107,4.15953,66.50108,22476,46
311.25581,-4.34914,-69.68697,4.32362,69.68697,22476,46
311.44181,-4.16405,-64.61080,4.13853,64.61080,22476,46
311.64278,-3.95540,-59.60103,3.92988,59.60104,22412,46
311.85481,-3.74150,-54.59863,3.71598,54.59863,22412,46
312.32278,-3.27282,-44.11740,3.24730,44.11740,22412,46
312.67178,-2.92358,-36.10146,2.89806,36.10146,22412,46
313.00778,-2.58781,-29.53626,2.56229,29.53626,22412,46
313.41378,-2.18183,-22.13281,2.15631,22.13281,22412,46
314.11978,-1.47574,-12.03972,1.45021,12.03972,22412,46
314.80478,-1.37170,-12.38091,1.34618,12.38091,22412,46
315.36178,-1.93382,-21.82591,1.90830,21.82591,22476,47
315.70178,-2.27411,-28.37505,2.24859,28.37505,22476,47
316.01678,-2.58908,-34.83317,2.56356,34.83317,22476,47
316.30078,-2.87306,-40.42808,2.84754,40.42808,22476,47
316.55978,-3.13224,-45.61702,3.10672,45.61702,22476,47
316.80381,-3.37613,-50.43196,3.35061,50.43196,22476,47
317.05078,-3.62318,-55.38267,3.59766,55.38267,22476,47
317.27678,-3.84905,-59.80244,3.82353,59.80244,22476,47
317.74178,-4.31399,-69.01214,4.28847,69.01214,22476,47
318.16181,-3.98282,-60.22662,3.95730,60.22662,22412,47
318.44981,-3.69236,-53.44947,3.66684,53.44947,22412,47
318.77278,-3.36887,-46.20761,3.34335,46.20761,22412,47
319.03681,-3.10491,-40.22585,3.07939,40.22585,22412,47
319.33781,-2.80377,-33.62660,2.77825,33.62660,22412,47
319.60678,-2.53477,-28.42695,2.50925,28.42695,22412,47
319.90281,-2.23897,-23.00236,2.21345,23.00236,22412,47
320.45178,-1.68987,-14.81718,1.66435,14.81718,22412,47
321.12978,-1.14299,-8.32229,1.11747,8.32229,22412,47
321.64381,-1.67932,-17.36240,1.65380,17.36240,22604,47
322.02519,-2.06088,-24.08561,2.03536,24.08561,22604,48
322.25181,-2.28802,-28.60849,2.26250,28.60849,22604,48
322.50978,-2.54596,-33.87071,2.52044,33.87071,22604,48
322.74281,-2.77903,-38.56450,2.75351,38.56450,22604,48
323.02678,-3.06306,-44.36071,3.03754,44.36071,22604,48
323.28681,-3.32307,-49.41858,3.29755,49.41858,22604,48
323.51378,-3.55006,-53.88054,3.52454,53.88054,22604,48
323.70578,-3.74211,-57.75696,3.71659,57.75696,22604,48
324.04981,-4.08600,-64.45590,4.06047,64.45589,22604,48
324.43681,-4.26186,-67.16389,4.23634,67.16389,22604,48
324.76981,-3.91346,-58.52813,3.88794,58.52813,22540,48
325.04278,-3.63908,-52.24589,3.61356,52.24588,22540,48
325.37281,-3.30877,-44.78305,3.28325,44.78305,22540,48
325.62281,-3.05869,-39.17921,3.03317,39.17921,22540,48
326.00278,-2.67869,-31.06318,2.65317,31.06318,22540,48
326.34378,-2.33770,-24.72539,2.31218,24.72539,22540,48
326.72981,-1.95157,-18.47070,1.92605,18.47070,22540,48
327.59578,-1.08672,-7.17450,1.06120,7.17450,22540,48
328.47581,-1.96161,-22.33302,1.93608,22.33302,22604,49
328.95278,-2.43871,-31.65970,2.41318,31.65970,22604,49
329.30978,-2.79585,-38.89321,2.77033,38.89321,22604,49
329.70178,-3.18800,-46.78375,3.16248,46.78375,22604,49
330.04081,-3.52686,-53.44341,3.50134,53.44341,22604,49
330.32519,-3.81086,-59.13044,3.78534,59.13044,22604,49
330.66081,-4.14693,-65.68336,4.12141,65.68336,22604,49
331.03778,-4.20187,-65.53879,4.17635,65.53880,22604,49
331.43281,-3.79546,-55.81077,3.76994,55.81077,22540,49
331.78778,-3.43956,-47.73289,3.41404,47.73289,22540,49
332.10181,-3.12562,-40.66612,3.10010,40.66612,22540,49
332.47981,-2.74765,-32.40041,2.72213,32.40041,22540,49
332.85081,-2.37653,-25.37940,2.35100,25.37940,22540,49
333.57481,-1.65261,-14.25597,1.62709,14.25597,22540,49
334.45778,-1.09217,-7.67661,1.06665,7.67661,22540,49
334.96178,-1.53214,-15.09282,1.50662,15.09282,22476,49
335.41981,-1.99099,-22.87134,1.96547,22.87134,22476,50
335.67678,-2.24822,-27.95383,2.22270,27.95383,22476,50
335.88278,-2.45397,-32.12997,2.42845,32.12997,22476,50
336.16181,-2.73314,-37.75676,2.70762,37.75676,22476,50
336.61178,-3.18322,-46.77327,3.15770,46.77327,22476,50
336.97181,-3.54309,-53.80169,3.51757,53.80169,22476,50
337.24781,-3.81909,-59.32621,3.79356,59.32621,22476,50
337.58278,-4.15416,-65.87295,4.12864,65.87296,22476,50
338.00378,-4.12489,-63.63624,4.09937,63.63623,22476,50
338.40378,-3.71744,-54.06832,3.69192,54.06832,22412,50
338.72878,-3.39177,-46.83676,3.36625,46.83677,22412,50
339.04378,-3.07683,-39.65744,3.05131,39.65744,22412,50
339.29378,-2.82676,-34.09913,2.80124,34.09913,22412,50
339.51981,-2.60083,-29.68833,2.57531,29.68833,22412,50
339.78478,-2.33581,-24.67930,2.31029,24.67930,22412,50
340.15178,-1.96872,-18.70797,1.94320,18.70797,22412,50
340.63181,-1.48869,-12.13084,1.46317,12.13084,22412,50
341.27781,-1.34198,-11.81321,1.31646,11.81321,22412,50
341.90378,-1.97470,-22.46037,1.94918,22.46037,22476,51
342.15681,-2.22804,-27.37745,2.20251,27.37745,22476,51
342.53378,-2.60484,-35.07096,2.57932,35.07096,22476,51
342.97181,-3.04295,-44.02298,3.01743,44.02298,22476,51
343.25078,-3.32199,-49.48131,3.29646,49.48131,22476,51
343.51981,-3.59105,-54.76472,3.56553,54.76472,22476,51
343.90478,-3.97579,-62.34042,3.95027,62.34042,22476,51
344.26578,-4.33682,-69.48994,4.31130,69.48994,22476,51
344.56578,-4.08447,-62.53478,4.05895,62.53478,22412,51
344.82519,-3.82071,-56.42157,3.79519,56.42157,22412,51
345.10581,-3.53882,-49.99568,3.51330,49.99568,22412,51
345.28581,-3.35876,-45.96528,3.33324,45.96528,22412,51
345.45978,-3.18478,-42.07994,3.15926,42.07994,22412,51
345.61578,-3.02863,-38.59681,3.00311,38.59681,22412,51
345.76378,-2.88060,-35.26380,2.85508,35.26379,22412,51
345.89578,-2.74877,-32.42410,2.72325,32.42410,22412,51
346.04578,-2.59873,-29.56520,2.57321,29.56520,22412,51
346.19478,-2.44966,-26.66004,2.42414,26.66004,22412,51
346.32581,-2.31868,-24.29860,2.29316,24.29860,22412,51
346.55478,-2.08979,-20.54871,2.06427,20.54871,22412,51
346.82581,-1.81867,-16.42175,1.79315,16.42175,22412,51
347.03878,-1.60568,-13.55640,1.58016,13.55640,22412,51
347.31778,-1.32667,-10.01830,1.30115,10.01830,22412,51
347.69278,-1.22373,-9.67802,1.19821,9.67803,22412,51
347.98481,-1.52785,-14.81780,1.50233,14.81780,22476,51
348.24281,-1.78754,-19.19902,1.76202,19.19902,22476,52
348.47478,-2.01972,-23.30871,1.99420,23.30871,22476,52
348.67481,-2.21996,-27.31069,2.19444,27.31069,22476,52
348.85981,-2.40475,-31.04573,2.37923,31.04573,22476,52
349.01881,-2.56387,-34.30232,2.53835,34.30232,22476,52
349.19878,-2.74393,-37.87071,2.71841,37.87071,22476,52
349.34978,-2.89477,-40.94485,2.86925,40.94485,22476,52
349.50278,-3.04793,-44.05524,3.02241,44.05524,22476,52
349.73978,-3.28496,-48.68344,3.25944,48.68344,22476,52
349.92078,-3.46586,-52.30718,3.44034,52.30718,22476,52
350.14778,-3.69298,-56.83118,3.66746,56.83118,22476,52
350.30078,-3.84584,-59.80956,3.82032,59.80956,22476,52
350.47778,-4.02277,-63.21171,3.99725,63.21171,22476,52
350.67881,-4.22402,-67.31737,4.19850,67.31737,22476,52
350.89178,-4.28158,-67.78349,4.25606,67.78349,22476,52
351.08278,-4.07543,-62.38087,4.04991,62.38087,22412,52
351.23778,-3.91662,-58.67963,3.89110,58.67963,22412,52
351.41278,-3.74041,-54.53481,3.71489,54.53481,22412,52
351.58381,-3.56892,-50.63958,3.54340,50.63958,22412,52
351.77178,-3.38072,-46.53450,3.35520,46.53450,22412,52
352.01278,-3.13974,-40.99810,3.11422,40.99810,22412,52
352.22378,-2.92853,-36.24294,2.90301,36.24294,22412,52
352.41278,-2.73980,-32.25550,2.71428,32.25550,22412,52
352.60278,-2.54969,-28.57990,2.52417,28.57990,22412,52
352.80978,-2.34272,-24.64205,2.31719,24.64205,22412,52
353.13581,-2.01651,-19.33528,1.99099,19.33528,22412,52
353.75378,-1.39857,-10.93119,1.37305,10.93119,22412,52
354.46281,-1.50551,-14.48818,1.47999,14.48818,22476,52
354.85081,-1.89571,-21.08345,1.87019,21.08345,22476,53
355.11781,-2.16305,-26.16463,2.13753,26.16463,22476,53
355.41081,-2.45582,-32.07300,2.43030,32.07300,22476,53
355.72181,-2.76696,-38.39434,2.74144,38.39434,22476,53
355.96281,-3.00793,-43.37038,2.98241,43.37038,22476,53
356.27278,-3.31799,-49.38881,3.29247,49.38881,22476,53
356.61781,-3.66303,-56.20113,3.63751,56.20113,22476,53
356.89578,-3.94073,-61.64223,3.91521,61.64223,22476,53
357.25478,-4.29993,-68.75065,4.27441,68.75065,22476,53
357.49381,-4.17326,-64.85356,4.14774,64.85355,22476,53
357.72519,-3.93382,-59.03228,3.90830,59.03228,22412,53
357.99781,-3.65905,-52.71017,3.63353,52.71017,22412,53
358.21478,-3.44164,-47.82950,3.41612,47.82950,22412,53
358.39278,-3.26369,-43.93554,3.23817,43.93554,22412,53
358.60378,-3.05259,-39.11470,3.02707,39.11470,22412,53
358.77578,-2.88053,-35.24861,2.85501,35.24861,22412,53
359.01178,-2.64464,-30.31489,2.61912,30.31489,22412,53
359.22078,-2.43556,-26.31387,2.41004,26.31387,22412,53
359.48978,-2.16673,-21.66312,2.14121,21.66312,22412,53
360.01378,-1.64265,-13.98455,1.61712,13.98455,22412,53
360.70178,-1.23306,-9.80440,1.20754,9.80440,22412,53
361.19278,-1.73742,-18.34552,1.71190,18.34552,22476,54
361.46578,-2.01073,-23.15147,1.98521,23.15147,22476,54
361.62078,-2.16600,-26.28531,2.14047,26.28531,22476,54
361.82481,-2.36983,-30.41892,2.34431,30.41892,22476,54
362.11881,-2.66385,-36.28421,2.63833,36.28421,22476,54
362.36978,-2.91479,-41.38025,2.88927,41.38025,22476,54
362.71978,-3.26502,-48.35552,3.23950,48.35552,22476,54
362.94778,-3.49293,-52.84407,3.46741,52.84407,22476,54
363.20578,-3.75097,-58.01482,3.72545,58.01482,22476,54
363.43178,-3.97673,-62.30015,3.95121,62.30014,22476,54
363.61278,-4.15796,-65.96513,4.13244,65.96513,22476,54
363.86381,-4.31305,-68.63994,4.28753,68.63994,22476,54
364.00878,-4.15101,-64.25612,4.12549,64.25612,22476,54
364.18681,-3.96640,-59.85732,3.94088,59.85732,22412,54
364.31578,-3.83584,-56.85842,3.81032,56.85842,22412,54
364.48778,-3.66301,-52.88474,3.63749,52.88474,22412,54
364.65281,-3.49765,-49.08094,3.47213,49.08094,22412,54
364.80578,-3.34470,-45.68622,3.31918,45.68622,22412,54
364.96978,-3.18068,-42.05282,3.15516,42.05282,22412,54
365.14481,-3.00555,-38.04008,2.98003,38.04008,22412,54
365.36478,-2.78556,-33.15125,2.76004,33.15125,22412,54
365.53581,-2.61464,-29.73972,2.58912,29.73972,22412,54
365.72519,-2.42549,-26.17916,2.39996,26.17916,22412,54
365.94378,-2.20675,-22.27365,2.18123,22.27365,22412,54
366.28681,-1.86361,-17.05561,1.83809,17.05561,22412,54
366.61678,-1.53347,-12.57486,1.50795,12.57486,22412,54
367.13278,-1.15096,-8.32789,1.12544,8.32789,22412,54
367.52078,-1.56013,-15.33843,1.53461,15.33843,22476,54
367.82519,-1.86555,-20.55378,1.84003,20.55378,22476,55
368.01981,-2.06068,-24.13958,2.03516,24.13959,22476,55
368.16581,-2.20687,-26.96834,2.18135,26.96834,22476,55
368.31478,-2.35573,-30.13696,2.33021,30.13696,22476,55
368.46681,-2.50777,-33.10825,2.48225,33.10825,22476,55
368.62578,-2.66676,-36.17609,2.64124,36.17609,22476,55
368.76378,-2.80474,-39.15177,2.77922,39.15177,22476,55
368.89078,-2.93167,-41.68081,2.90615,41.68081,22476,55
369.03681,-3.07785,-44.59840,3.05233,44.59840,22476,55
369.17481,-3.21595,-47.29548,3.19043,47.29549,22476,55
369.40578,-3.44671,-51.93688,3.42119,51.93688,22476,55
369.59378,-3.63492,-55.68784,3.60940,55.68784,22476,55
369.76678,-3.80779,-59.08267,3.78227,59.08267,22476,55
369.93378,-3.97463,-62.33392,3.94911,62.33392,22476,55
370.10878,-4.14986,-65.82406,4.12434,65.82406,22476,55
370.24078,-4.28187,-68.42596,4.25635,68.42596,22476,55
370.40281,-4.26469,-67.32992,4.23917,67.32992,22476,55
370.58381,-4.07022,-62.31356,4.04470,62.31356,22476,55
370.74578,-3.90441,-58.44973,3.87889,58.44973,22412,55
370.93178,-3.71720,-54.04876,3.69168,54.04876,22412,55
371.11578,-3.53263,-49.84238,3.50711,49.84238,22412,55
371.27578,-3.37256,-46.32403,3.34704,46.32402,22412,55
371.42578,-3.22268,-43.08785,3.19716,43.08785,22412,55
371.59478,-3.05348,-39.21760,3.02796,39.21760,22412,55
371.79278,-2.85550,-34.72828,2.82998,34.72829,22412,55
372.01178,-2.63656,-30.20795,2.61104,30.20795,22412,55
372.20178,-2.44651,-26.51296,2.42099,26.51296,22412,55
372.36678,-2.28152,-23.54103,2.25600,23.54103,22412,55
372.72478,-1.92336,-17.91968,1.89784,17.91968,22412,55
373.04278,-1.60551,-13.47202,1.57999,13.47202,22412,55
373.60178,-1.13119,-7.91372,1.10567,7.91372,22412,55
374.14678,-1.70312,-17.80001,1.67760,17.80001,22476,56
374.50378,-2.06069,-24.16623,2.03517,24.16623,22476,56
374.67778,-2.23490,-27.58839,2.20938,27.58839,22476,56
374.91581,-2.47278,-32.38981,2.44726,32.38981,22476,56
375.13378,-2.69076,-36.76880,2.66524,36.76880,22476,56
375.35081,-2.90768,-41.20549,2.88216,41.20549,22476,56
375.57581,-3.13294,-45.64270,3.10742,45.64270,22476,56
375.73178,-3.28882,-48.72880,3.26330,48.72880,22476,56
375.90578,-3.46275,-52.27128,3.43723,52.27128,22476,56
376.06378,-3.62092,-55.37055,3.59540,55.37055,22476,56
376.21578,-3.77284,-58.41907,3.74732,58.41908,22476,56
376.33078,-3.88775,-60.76744,3.86223,60.76744,22476,56
376.46978,-4.02669,-63.42931,4.00117,63.42931,22476,56
376.61978,-4.17685,-66.41618,4.15133,66.41618,22476,56
376.75778,-4.31474,-69.07676,4.28922,69.07676,22476,56
376.93978,-4.22069,-66.14589,4.19517,66.14589,22476,56
377.05678,-4.09603,-62.92840,4.07051,62.92840,22412,56
377.19378,-3.95502,-59.56063,3.92950,59.56063,22412,56
377.32481,-3.82260,-56.53269,3.79708,56.53269,22412,56
377.45481,-3.69201,-53.44494,3.66649,53.44494,22412,56
377.58381,-3.56270,-50.59636,3.53718,50.59636,22412,56
377.70278,-3.44352,-47.93371,3.41800,47.93371,22412,56
377.84478,-3.30158,-44.76139,3.27606,44.76139,22412,56
377.95978,-3.18662,-42.20140,3.16110,42.20140,22412,56
378.09578,-3.05046,-39.11147,3.02494,39.11147,22412,56
378.24781,-2.89837,-35.59821,2.87285,35.59821,22412,56
378.40578,-2.74062,-32.16700,2.71510,32.16700,22412,56
378.54278,-2.60354,-29.50336,2.57801,29.50336,22412,56
378.68578,-2.46053,-26.74727,2.43501,26.74727,22412,56
378.84578,-2.30054,-23.84962,2.27502,23.84962,22412,56
379.08478,-2.06142,-19.91117,2.03590,19.91117,22412,56
379.31578,-1.83051,-16.46536,1.80499,16.46536,22412,56
379.67678,-1.46940,-11.72052,1.44388,11.72052,22412,56
379.99381,-1.15255,-7.86195,1.12703,7.86195,22412,56
380.26378,-1.35110,-11.70735,1.32558,11.70735,22412,56
380.61578,-1.71005,-17.80172,1.68453,17.80172,22476,56
380.84478,-1.93949,-21.87427,1.91397,21.87427,22476,57
380.99478,-2.08976,-24.67544,2.06424,24.67544,22476,57
381.15578,-2.25087,-27.87359,2.22535,27.87359,22476,57
381.27278,-2.36771,-30.24489,2.34219,30.24489,22476,57
381.42519,-2.51976,-33.32682,2.49424,33.32682,22476,57
381.54778,-2.64271,-35.75119,2.61719,35.75119,22476,57
381.70578,-2.80073,-39.02271,2.77521,39.02271,22476,57
381.91378,-3.00881,-43.30840,2.98329,43.30840,22476,57
382.09878,-3.19388,-46.92837,3.16836,46.92837,22476,57
382.32081,-3.41571,-51.27405,3.39019,51.27406,22476,57
382.51378,-3.60889,-55.09343,3.58337,55.09343,22476,57
382.72378,-3.81877,-59.26051,3.79325,59.26051,22476,57
382.89278,-3.98761,-62.60733,3.96209,62.60733,22476,57
383.10481,-4.19986,-66.81960,4.17434,66.81960,22476,57
383.29178,-4.33587,-69.27498,4.31035,69.27499,22476,57
383.45678,-4.15097,-64.34606,4.12545,64.34606,22476,57
383.66678,-3.93373,-59.06925,3.90820,59.06924,22412,57
383.88278,-3.71614,-54.00505,3.69062,54.00505,22412,57
384.11078,-3.48757,-48.83193,3.46205,48.83193,22412,57
384.29481,-3.30356,-44.75230,3.27804,44.75230,22412,57
384.51481,-3.08354,-39.81618,3.05802,39.81618,22412,57
384.78778,-2.81046,-33.75491,2.78494,33.75491,22412,57
384.98178,-2.61655,-29.75678,2.59103,29.75678,22412,57
385.21281,-2.38540,-25.39882,2.35988,25.39882,22412,57
385.59478,-2.00341,-19.06661,1.97789,19.06661,22412,57
385.94981,-1.64850,-14.07489,1.62298,14.07489,22412,57
386.47981,-1.11857,-7.40407,1.09305,7.40407,22412,57
386.96478,-1.57618,-15.51678,1.55065,15.51678,22604,57
387.34181,-1.95447,-22.16411,1.92895,22.16411,22604,58
387.61881,-2.23186,-27.45761,2.20634,27.45761,22604,58
387.85581,-2.46870,-32.30486,2.44318,32.30486,22604,58
388.03078,-2.64369,-35.73508,2.61817,35.73508,22604,58
388.23178,-2.84469,-39.84784,2.81917,39.84784,22604,58
388.41981,-3.03281,-43.77035,3.00729,43.77035,22604,58
388.62578,-3.23894,-47.82125,3.21342,47.82125,22604,58
388.89278,-3.50577,-53.06954,3.48025,53.06954,22604,58
389.13181,-3.74481,-57.89366,3.71929,57.89366,22604,58
389.40078,-4.01363,-63.06733,3.98811,63.06733,22604,58
389.60778,-4.22085,-67.30967,4.19533,67.30967,22604,58
389.81078,-4.29255,-68.11030,4.26703,68.11031,22604,58
389.97478,-4.11306,-63.35299,4.08754,63.35299,22604,58
390.14478,-3.93783,-59.22482,3.91231,59.22482,22540,58
390.29378,-3.78741,-55.68843,3.76188,55.68843,22540,58
390.45978,-3.62091,-51.93853,3.59539,51.93853,22540,58
390.62978,-3.45056,-48.04898,3.42504,48.04898,22540,58
390.82378,-3.25660,-43.84575,3.23108,43.84575,22540,58
390.98278,-3.09759,-40.15587,3.07207,40.15587,22540,58
391.16981,-2.91036,-35.90700,2.88484,35.90701,22540,58
391.39881,-2.68156,-30.93429,2.65604,30.93429,22540,58
391.63478,-2.44551,-26.42835,2.41999,26.42835,22540,58
391.84681,-2.23365,-22.66128,2.20813,22.66128,22540,58
392.07678,-2.00344,-19.01712,1.97791,19.01712,22540,58
392.32178,-1.75858,-15.47129,1.73305,15.47129,22540,58
392.70078,-1.37942,-10.53599,1.35390,10.53599,22540,58
393.11678,-1.23980,-9.76849,1.21428,9.76849,22540,58
393.54578,-1.68194,-17.34362,1.65642,17.34362,22604,58
393.83878,-1.97550,-22.48110,1.94998,22.48110,22604,59
394.03978,-2.17679,-26.32798,2.15127,26.32797,22604,59
394.22519,-2.36170,-30.12178,2.33618,30.12178,22604,59
394.35778,-2.49469,-32.80705,2.46917,32.80705,22604,59
394.54981,-2.68669,-36.52920,2.66117,36.52920,22604,59
394.70978,-2.84668,-39.86041,2.82116,39.86041,22604,59
394.87578,-3.01281,-43.31132,2.98729,43.31132,22604,59
395.02978,-3.16688,-46.32001,3.14136,46.32001,22604,59
395.18978,-3.32678,-49.45149,3.30126,49.45148,22604,59
395.33781,-3.47470,-52.43764,3.44918,52.43764,22604,59
395.51978,-3.65686,-56.06092,3.63133,56.06092,22604,59
395.69678,-3.83371,-59.55520,3.80819,59.55520,22604,59
395.90578,-4.04261,-63.68513,4.01709,63.68513,22604,59
396.09578,-4.23284,-67.51134,4.20732,67.51134,22604,59
396.28078,-4.29758,-68.32331,4.27206,68.32330,22604,59
396.46878,-4.09209,-62.83391,4.06657,62.83391,22604,59
396.62078,-3.93580,-59.17576,3.91028,59.17576,22540,59
396.80978,-3.74523,-54.75240,3.71970,54.75240,22540,59
397.04378,-3.51060,-49.36692,3.48508,49.36692,22540,59
397.24781,-3.30660,-44.82201,3.28108,44.82201,22540,59
397.41778,-3.13659,-40.99575,3.11107,40.99575,22540,59
397.58381,-2.97047,-37.29879,2.94495,37.29879,22540,59
397.77278,-2.78148,-33.12846,2.75596,33.12846,22540,59
397.96781,-2.58655,-29.11268,2.56103,29.11268,22540,59
398.12978,-2.42444,-26.07712,2.39892,26.07712,22540,59
398.45578,-2.09859,-20.48816,2.07307,20.48816,22540,59
399.12519,-1.42929,-11.14655,1.40377,11.14655,22540,59
399.44181,-1.11264,-7.34896,1.08712,7.34896,22540,59