File: data-raw/Experiment 2/Results/INSTRON data/Experiment 2.is_ccyclic_RawData/Specimen_RawData_25.csv
Text Inputs : Specimen label,"Short Plate 1 Video"

Time,Extension,Load,Compressive extension,Compressive load,Segment ID,Total Cycle Count
(sec),(mm),(N),(mm),(N),,
0.00000,-0.02606,0.05628,0.00000,-0.05628,12835,0
0.22280,-0.02606,0.02076,0.00000,-0.02076,12835,0
0.61580,-0.02606,0.01263,0.00000,-0.01263,12835,0
0.78380,-0.02606,0.01124,0.00000,-0.01124,12835,0
1.01280,-0.02606,-0.03150,0.00000,0.03150,12835,0
1.15880,-0.02606,0.02989,0.00000,-0.02989,3220,0
1.26680,-0.05629,-0.00629,0.03023,0.00629,3220,0
1.44680,-0.15079,-0.00532,0.12473,0.00532,3220,0
1.76880,-0.31341,-0.03326,0.28735,0.03326,3220,0
1.94280,-0.40046,0.02636,0.37440,-0.02636,3220,0
2.16920,-0.51366,0.04610,0.48760,-0.04610,3220,0
2.32680,-0.59277,-0.03015,0.56671,0.03015,3220,0
2.49380,-0.67610,0.01418,0.65004,-0.01418,3220,0
2.59080,-0.72464,-0.02407,0.69858,0.02407,3220,0
2.72780,-0.79308,0.01655,0.76702,-0.01655,3220,0
2.88280,-0.87050,0.00812,0.84444,-0.00812,3220,0
3.04280,-0.95058,0.02471,0.92452,-0.02471,3220,0
3.19680,-1.02767,-0.01382,1.00161,0.01382,3220,0
3.25880,-1.05874,0.02775,1.03268,-0.02775,3220,0
3.40880,-1.13368,-0.01821,1.10762,0.01821,3220,0
3.53880,-1.19868,0.01408,1.17262,-0.01408,3220,0
3.62980,-1.24408,-0.02605,1.21802,0.02605,3220,0
3.71280,-1.28556,-0.00588,1.25950,0.00588,3220,0
3.81680,-1.33754,0.01618,1.31148,-0.01618,3220,0
4.02680,-1.44257,0.00089,1.41651,-0.00089,3220,0
4.36580,-1.61207,0.01323,1.58601,-0.01323,3220,0
4.45880,-1.65862,-0.00534,1.63255,0.00534,3220,0
4.55280,-1.70574,0.00693,1.67968,-0.00693,3220,0
4.76880,-1.81357,0.03048,1.78751,-0.03048,3220,0
4.93580,-1.89693,-0.00062,1.87087,0.00062,3220,0
5.34380,-2.10129,0.06562,2.07523,-0.06562,3220,0
5.57480,-2.21680,0.00416,2.19074,-0.00416,3220,0
5.73480,-2.29661,0.01758,2.27055,-0.01758,3220,0
5.96920,-2.41335,0.02885,2.38729,-0.02885,3220,0
6.10680,-2.48256,0.03126,2.45649,-0.03126,3220,0
6.30980,-2.58431,-0.00421,2.55825,0.00421,3220,0
6.42680,-2.64273,0.00301,2.61667,-0.00301,3220,0
6.56920,-2.71377,0.01065,2.68771,-0.01065,3220,0
6.69480,-2.77665,0.00123,2.75058,-0.00123,3220,0
6.86480,-2.86156,-0.02393,2.83550,0.02393,3220,0
7.02680,-2.94266,0.04186,2.91660,-0.04186,3220,0
7.25280,-3.05570,-0.01854,3.02964,0.01854,3220,0
7.36920,-3.11374,0.00622,3.08768,-0.00622,3220,0
7.58780,-3.22323,-2.24857,3.19717,2.24857,3220,0
7.93580,-3.39708,-5.83811,3.37102,5.83811,3220,0
8.14580,-3.55949,-9.26220,3.53343,9.26220,3220,0
8.36880,-3.78535,-13.24789,3.75929,13.24789,22476,0
8.57880,-3.99591,-16.80397,3.96984,16.80397,22476,0
8.76920,-4.18616,-20.09348,4.16010,20.09348,22476,0
8.96920,-4.38606,-24.05587,4.36000,24.05587,22476,0
9.13880,-4.55621,-27.58778,4.53015,27.58778,22476,0
9.26780,-4.68534,-30.64066,4.65928,30.64066,22476,0
9.36580,-4.78299,-32.95284,4.75693,32.95284,22476,0
9.49080,-4.90795,-35.89548,4.88189,35.89548,22476,0
9.62680,-5.04416,-39.04668,5.01810,39.04668,22476,0
9.78480,-5.20240,-42.61399,5.17634,42.61399,22476,0
9.89880,-5.31618,-45.06870,5.29012,45.06870,22476,0
10.05980,-5.47714,-48.63081,5.45108,48.63081,22476,0
10.25080,-5.66826,-52.78575,5.64220,52.78576,22476,0
10.38480,-5.80220,-55.67956,5.77614,55.67956,22476,0
10.54680,-5.96409,-59.13781,5.93803,59.13781,22476,0
10.68480,-6.10229,-62.22018,6.07623,62.22018,22476,0
10.83980,-6.25728,-65.56256,6.23122,65.56256,22476,0
10.98080,-6.39798,-68.62386,6.37192,68.62386,22476,0
11.10080,-6.40445,-67.56704,6.37839,67.56704,22476,0
11.21580,-6.27574,-62.79403,6.24968,62.79403,22476,0
11.34280,-6.14265,-58.16193,6.11659,58.16193,22412,0
11.46920,-6.01380,-53.98164,5.98774,53.98164,22412,0
11.59080,-5.89073,-50.10825,5.86467,50.10825,22412,0
11.71280,-5.76837,-46.38606,5.74231,46.38606,22412,0
11.80480,-5.67623,-43.54385,5.65017,43.54385,22412,0
11.91680,-5.56411,-40.12112,5.53805,40.12112,22412,0
12.03380,-5.44695,-36.63570,5.42089,36.63570,22412,0
12.17480,-5.30606,-32.54255,5.28000,32.54255,22412,0
12.31480,-5.16609,-29.02765,5.14003,29.02765,22412,0
12.47880,-5.00181,-25.37807,4.97575,25.37807,22412,0
12.66920,-4.81193,-21.59706,4.78587,21.59706,22412,0
12.88980,-4.59106,-17.78818,4.56500,17.78818,22412,0
13.08680,-4.39377,-14.80469,4.36771,14.80470,22412,0
13.36920,-4.11203,-10.82874,4.08597,10.82874,22412,0
13.58680,-3.89382,-7.80186,3.86776,7.80186,22412,0
13.70780,-3.90425,-8.97042,3.87819,8.97042,22412,0
13.86920,-4.08067,-13.05941,4.05461,13.05941,22476,0
14.04580,-4.26271,-16.71871,4.23665,16.71871,22476,0
14.16920,-4.38695,-19.25525,4.36089,19.25525,22476,0
14.34980,-4.56880,-23.21639,4.54274,23.21639,22476,1
14.52880,-4.74792,-27.25568,4.72186,27.25568,22476,1
14.67880,-4.89778,-31.00154,4.87172,31.00154,22476,1
14.86580,-5.08516,-35.80217,5.05910,35.80217,22476,1
14.96920,-5.18819,-38.47490,5.16213,38.47490,22476,1
15.11780,-5.33708,-42.06827,5.31102,42.06826,22476,1
15.23980,-5.45903,-44.97570,5.43297,44.97570,22476,1
15.31680,-5.53607,-46.96900,5.51001,46.96900,22476,1
15.43880,-5.65814,-49.75466,5.63208,49.75466,22476,1
15.60380,-5.82315,-53.63052,5.79709,53.63052,22476,1
15.75680,-5.97605,-57.23836,5.94999,57.23835,22476,1
15.86080,-6.08015,-59.65210,6.05409,59.65210,22476,1
15.96480,-6.18418,-62.06711,6.15812,62.06711,22476,1
16.06920,-6.28796,-64.43733,6.26190,64.43733,22476,1
16.20980,-6.42899,-67.63808,6.40293,67.63808,22476,1
16.35080,-6.49401,-68.45885,6.46795,68.45885,22476,1
16.42980,-6.40205,-64.95902,6.37599,64.95902,22476,1
16.50480,-6.32123,-62.10679,6.29517,62.10679,22476,1
16.57080,-6.25194,-59.65161,6.22587,59.65161,22476,1
16.67080,-6.14903,-56.24884,6.12297,56.24884,22412,1
16.75780,-6.06062,-53.28737,6.03456,53.28737,22412,1
16.84280,-5.97473,-50.71304,5.94867,50.71304,22412,1
16.95680,-5.86027,-47.23636,5.83421,47.23636,22412,1
17.06920,-5.74811,-43.72757,5.72205,43.72757,22412,1
17.16920,-5.64799,-40.71073,5.62193,40.71073,22412,1
17.28080,-5.53591,-37.40890,5.50984,37.40890,22412,1
17.40080,-5.41581,-33.86097,5.38975,33.86097,22412,1
17.54980,-5.26690,-29.88974,5.24084,29.88974,22412,1
17.72580,-5.09092,-25.85371,5.06486,25.85371,22412,1
17.93280,-4.88368,-21.76532,4.85762,21.76532,22412,1
18.16280,-4.65403,-17.86779,4.62797,17.86779,22412,1
18.39680,-4.41978,-14.27263,4.39372,14.27263,22412,1
18.66920,-4.14793,-10.53220,4.12187,10.53220,22412,1
18.91480,-3.91318,-7.27720,3.88712,7.27720,22412,1
19.06480,-4.06964,-11.61482,4.04358,11.61482,22412,1
19.25280,-4.26625,-15.71185,4.24019,15.71185,22476,1
19.44480,-4.46086,-19.64961,4.43480,19.64961,22476,1
19.62280,-4.63955,-23.65404,4.61349,23.65404,22476,2
19.79080,-4.80755,-27.48046,4.78149,27.48046,22476,2
19.94480,-4.96166,-31.44607,4.93560,31.44607,22476,2
20.03980,-5.05675,-33.95399,5.03069,33.95399,22476,2
20.17680,-5.19392,-37.31369,5.16786,37.31369,22476,2
20.32580,-5.34282,-40.97192,5.31676,40.97192,22476,2
20.46080,-5.47779,-44.37222,5.45173,44.37222,22476,2
20.53580,-5.55284,-46.20932,5.52678,46.20932,22476,2
20.65280,-5.66992,-49.03421,5.64386,49.03421,22476,2
20.76920,-5.78587,-51.87603,5.75981,51.87603,22476,2
20.89280,-5.90976,-54.74809,5.88370,54.74809,22476,2
20.98780,-6.00478,-57.06323,5.97872,57.06323,22476,2
21.11680,-6.13389,-60.07208,6.10783,60.07208,22476,2
21.22580,-6.24290,-62.58065,6.21684,62.58065,22476,2
21.33380,-6.35064,-65.11062,6.32458,65.11063,22476,2
21.39980,-6.41661,-66.55914,6.39055,66.55914,22476,2
21.53880,-6.55030,-69.73399,6.52424,69.73399,22476,2
21.59380,-6.51062,-67.88830,6.48456,67.88831,22476,2
21.67880,-6.41323,-64.21538,6.38717,64.21538,22476,2
21.76920,-6.31714,-60.79663,6.29108,60.79663,22476,2
21.82880,-6.25466,-58.68364,6.22860,58.68364,22412,2
21.95480,-6.12576,-54.38870,6.09970,54.38870,22412,2
22.09280,-5.98628,-50.05209,5.96022,50.05209,22412,2
22.23280,-5.84590,-45.73262,5.81984,45.73262,22412,2
22.30480,-5.77377,-43.61975,5.74771,43.61975,22412,2
22.36920,-5.70979,-41.57978,5.68372,41.57978,22412,2
22.48080,-5.59762,-38.32634,5.57156,38.32634,22412,2
22.55080,-5.52755,-36.16902,5.50149,36.16902,22412,2
22.64480,-5.43353,-33.54450,5.40747,33.54450,22412,2
22.70680,-5.37145,-31.68992,5.34539,31.68992,22412,2
22.79480,-5.28360,-29.47758,5.25754,29.47758,22412,2
22.92380,-5.15467,-26.42550,5.12861,26.42550,22412,2
23.10480,-4.97347,-22.79259,4.94741,22.79259,22412,2
23.28080,-4.79753,-19.60958,4.77147,19.60958,22412,2
23.42380,-4.65470,-17.28023,4.62864,17.28023,22412,2
23.61880,-4.45955,-14.34985,4.43349,14.34985,22412,2
23.84580,-4.23257,-11.23643,4.20651,11.23643,22412,2
23.99380,-4.08467,-9.14088,4.05861,9.14088,22412,2
24.19680,-3.98165,-8.47641,3.95559,8.47641,22412,2
24.32780,-4.12863,-12.22526,4.10257,12.22526,22412,2
24.51180,-4.31955,-16.22429,4.29349,16.22429,22476,2
24.69880,-4.50879,-20.03648,4.48272,20.03648,22476,2
24.85680,-4.66739,-23.59830,4.64132,23.59830,22476,3
25.02480,-4.83538,-27.50159,4.80932,27.50159,22476,3
25.16880,-4.97955,-31.15144,4.95349,31.15144,22476,3
25.25880,-5.06961,-33.64351,5.04355,33.64351,22476,3
25.35880,-5.16968,-36.00607,5.14362,36.00607,22476,3
25.47480,-5.28556,-39.00097,5.25950,39.00097,22476,3
25.66080,-5.47162,-43.60634,5.44555,43.60634,22476,3
25.75680,-5.56771,-45.93529,5.54165,45.93529,22476,3
25.88880,-5.69971,-49.12794,5.67365,49.12794,22476,3
26.06920,-5.87961,-53.50561,5.85354,53.50561,22476,3
26.20080,-6.01158,-56.69459,5.98551,56.69459,22476,3
26.36920,-6.17972,-60.57893,6.15365,60.57893,22476,3
26.55980,-6.37038,-65.02599,6.34432,65.02599,22476,3
26.72280,-6.53348,-68.91819,6.50742,68.91819,22476,3
26.82680,-6.53768,-68.01511,6.51162,68.01511,22476,3
26.92680,-6.42393,-63.78604,6.39787,63.78604,22476,3
27.03680,-6.30750,-59.76961,6.28144,59.76961,22476,3
27.14480,-6.19654,-56.03915,6.17048,56.03915,22412,3
27.26920,-6.07078,-52.04847,6.04472,52.04847,22412,3
27.40980,-5.92888,-47.69645,5.90282,47.69645,22412,3
27.55780,-5.78069,-43.14111,5.75462,43.14111,22412,3
27.69680,-5.64156,-38.98499,5.61550,38.98499,22412,3
27.81080,-5.52745,-35.53756,5.50139,35.53756,22412,3
27.93080,-5.40737,-32.03778,5.38131,32.03778,22412,3
28.09880,-5.23959,-27.78760,5.21353,27.78760,22412,3
28.28480,-5.05349,-23.90060,5.02743,23.90060,22412,3
28.51080,-4.82744,-19.67996,4.80137,19.67996,22412,3
28.68680,-4.65161,-16.91228,4.62555,16.91228,22412,3
28.89280,-4.44546,-13.73823,4.41940,13.73823,22412,3
29.16920,-4.16957,-10.00071,4.14351,10.00071,22412,3
29.39780,-3.96929,-7.39105,3.94322,7.39105,22412,3
29.56480,-4.15356,-12.22462,4.12749,12.22462,22412,3
29.74480,-4.34044,-16.22281,4.31438,16.22281,22476,3
29.93780,-4.53570,-20.19468,4.50964,20.19468,22476,3
30.11180,-4.71040,-24.11326,4.68434,24.11326,22476,4
30.27380,-4.87227,-27.89761,4.84621,27.89761,22476,4
30.41280,-5.01147,-31.51760,4.98541,31.51760,22476,4
30.56920,-5.16760,-35.46838,5.14154,35.46838,22476,4
30.70580,-5.30448,-38.99208,5.27842,38.99208,22476,4
30.84980,-5.44848,-42.58963,5.42242,42.58963,22476,4
30.97680,-5.57564,-45.63882,5.54958,45.63882,22476,4
31.15480,-5.75367,-50.04455,5.72761,50.04455,22476,4
31.32280,-5.92146,-54.05536,5.89540,54.05536,22476,4
31.48580,-6.08463,-57.94770,6.05857,57.94770,22476,4
31.66920,-6.26752,-62.29550,6.24146,62.29550,22476,4
31.83080,-6.42933,-66.04716,6.40326,66.04716,22476,4
31.94080,-6.53944,-68.73985,6.51338,68.73985,22476,4
32.02680,-6.56891,-68.88013,6.54285,68.88013,22476,4
32.13080,-6.44924,-64.26603,6.42318,64.26604,22476,4
32.24980,-6.32266,-59.78482,6.29660,59.78482,22412,4
32.37080,-6.19831,-55.68596,6.17225,55.68596,22412,4
32.47880,-6.08879,-52.12962,6.06273,52.12962,22412,4
32.59280,-5.97389,-48.62104,5.94782,48.62104,22412,4
32.74280,-5.82365,-43.96719,5.79759,43.96719,22412,4
32.86920,-5.69755,-40.11871,5.67149,40.11871,22412,4
33.02580,-5.54040,-35.48598,5.51434,35.48598,22412,4
33.16920,-5.39723,-31.30613,5.37117,31.30613,22412,4
33.35680,-5.20950,-26.78916,5.18344,26.78916,22412,4
33.54780,-5.01820,-22.91491,4.99214,22.91491,22412,4
33.76920,-4.79734,-18.94002,4.77128,18.94002,22412,4
34.00280,-4.56344,-15.29096,4.53738,15.29096,22412,4
34.26920,-4.29726,-11.53819,4.27120,11.53819,22412,4
34.49280,-4.07353,-8.36417,4.04747,8.36417,22412,4
34.66080,-4.06066,-9.46183,4.03460,9.46183,22412,4
34.82980,-4.24380,-13.68453,4.21774,13.68453,22412,4
35.00980,-4.42833,-17.64381,4.40227,17.64381,22476,4
35.19880,-4.61894,-21.74058,4.59288,21.74058,22476,5
35.36920,-4.78915,-25.60647,4.76308,25.60647,22476,5
35.55480,-4.97535,-30.16263,4.94929,30.16263,22476,5
35.70380,-5.12443,-34.05405,5.09837,34.05405,22476,5
35.86920,-5.28940,-38.23768,5.26334,38.23768,22476,5
36.00880,-5.42932,-41.67314,5.40326,41.67314,22476,5
36.16920,-5.58958,-45.67508,5.56352,45.67508,22476,5
36.34680,-5.76754,-50.02570,5.74148,50.02570,22476,5
36.51280,-5.93335,-54.02015,5.90729,54.02015,22476,5
36.68880,-6.10954,-58.22884,6.08348,58.22884,22476,5
36.86920,-6.28925,-62.49915,6.26318,62.49915,22476,5
37.04280,-6.46333,-66.58952,6.43726,66.58952,22476,5
37.19880,-6.60111,-69.69879,6.57505,69.69879,22476,5
37.30280,-6.48924,-65.28512,6.46318,65.28512,22476,5
37.41680,-6.36674,-60.92407,6.34068,60.92407,22476,5
37.55880,-6.22034,-55.99622,6.19428,55.99622,22412,5
37.67480,-6.10264,-52.18825,6.07658,52.18825,22412,5
37.78780,-5.98875,-48.68183,5.96269,48.68183,22412,5
37.90280,-5.87351,-45.05552,5.84744,45.05552,22412,5
38.01680,-5.75944,-41.65987,5.73338,41.65987,22412,5
38.13380,-5.64235,-38.19676,5.61629,38.19676,22412,5
38.26920,-5.50720,-34.23420,5.48114,34.23420,22412,5
38.39480,-5.38116,-30.57126,5.35509,30.57126,22412,5
38.54480,-5.23139,-26.96855,5.20533,26.96855,22412,5
38.75280,-5.02316,-22.74399,4.99709,22.74399,22412,5
38.89780,-4.87810,-19.99889,4.85204,19.99889,22412,5
39.16480,-4.61131,-15.76318,4.58525,15.76318,22412,5
39.40280,-4.37316,-12.34933,4.34710,12.34933,22412,5
39.66920,-4.10740,-8.64586,4.08134,8.64586,22412,5
39.82980,-4.04400,-8.53723,4.01794,8.53723,22412,5
39.98080,-4.21239,-12.68223,4.18633,12.68223,22412,5
40.16920,-4.40660,-16.93066,4.38054,16.93066,22476,5
40.36080,-4.60065,-21.03582,4.57459,21.03582,22476,5
40.53980,-4.77996,-25.10052,4.75390,25.10052,22476,6
40.70380,-4.94411,-29.08411,4.91805,29.08411,22476,6
40.80280,-5.04321,-31.54362,5.01715,31.54362,22476,6
40.93680,-5.17738,-35.04322,5.15132,35.04322,22476,6
41.09380,-5.33422,-39.05088,5.30816,39.05088,22476,6
41.19380,-5.43413,-41.49494,5.40807,41.49494,22476,6
41.30180,-5.54227,-44.22124,5.51621,44.22124,22476,6
41.42780,-5.66838,-47.47992,5.64232,47.47992,22476,6
41.60780,-5.84831,-51.70450,5.82225,51.70450,22476,6
41.72480,-5.96523,-54.55279,5.93917,54.55279,22476,6
41.85280,-6.09338,-57.59549,6.06732,57.59549,22476,6
41.96280,-6.20335,-60.20415,6.17729,60.20415,22476,6
42.08180,-6.32207,-63.03460,6.29601,63.03460,22476,6
42.23180,-6.47214,-66.53608,6.44608,66.53609,22476,6
42.34480,-6.58524,-69.29255,6.55918,69.29254,22476,6
42.44980,-6.53953,-66.81480,6.51347,66.81480,22476,6
42.52480,-6.45580,-63.68836,6.42974,63.68836,22476,6
42.60480,-6.37043,-60.72441,6.34437,60.72441,22476,6
42.70480,-6.26688,-57.23129,6.24082,57.23129,22412,6
42.81080,-6.15902,-53.63718,6.13296,53.63718,22412,6
42.88880,-6.08021,-51.24234,6.05414,51.24234,22412,6
42.97780,-5.99055,-48.39931,5.96448,48.39931,22412,6
43.06880,-5.89930,-45.58909,5.87324,45.58908,22412,6
43.16920,-5.79930,-42.60163,5.77323,42.60163,22412,6
43.28980,-5.67823,-38.95098,5.65217,38.95098,22412,6
43.40580,-5.56214,-35.42943,5.53608,35.42942,22412,6
43.52080,-5.44704,-32.15908,5.42098,32.15908,22412,6
43.59980,-5.36798,-30.01438,5.34192,30.01438,22412,6
43.68080,-5.28712,-27.91473,5.26106,27.91473,22412,6
43.86920,-5.09912,-23.94401,5.07306,23.94401,22412,6
44.05780,-4.90989,-20.32295,4.88383,20.32295,22412,6
44.28080,-4.68730,-16.74176,4.66124,16.74176,22412,6
44.54280,-4.42504,-12.85046,4.39898,12.85046,22412,6
44.80380,-4.16426,-9.22553,4.13820,9.22553,22412,6
44.99780,-4.05029,-8.28990,4.02423,8.28990,22412,6
45.15080,-4.22189,-12.63336,4.19583,12.63336,22412,6
45.30280,-4.37966,-16.08473,4.35360,16.08473,22476,6
45.46920,-4.54807,-19.56042,4.52200,19.56042,22476,6
45.64280,-4.72292,-23.53455,4.69686,23.53455,22476,7
45.81480,-4.89489,-27.51123,4.86883,27.51123,22476,7
45.96380,-5.04411,-31.31017,5.01805,31.31017,22476,7
46.10680,-5.18728,-35.05780,5.16121,35.05780,22476,7
46.26920,-5.34914,-39.16427,5.32308,39.16428,22476,7
46.44380,-5.52413,-43.54241,5.49807,43.54241,22476,7
46.60680,-5.68729,-47.64725,5.66123,47.64725,22476,7
46.77480,-5.85520,-51.68609,5.82914,51.68609,22476,7
46.91280,-5.99316,-54.97929,5.96710,54.97929,22476,7
47.06680,-6.14727,-58.62536,6.12121,58.62536,22476,7
47.18180,-6.26214,-61.34919,6.23608,61.34919,22476,7
47.33680,-6.41692,-65.01316,6.39086,65.01315,22476,7
47.46920,-6.54910,-68.16921,6.52303,68.16920,22476,7
47.59780,-6.58057,-68.00899,6.55451,68.00899,22476,7
47.71180,-6.45151,-63.19800,6.42545,63.19800,22476,7
47.83280,-6.32407,-58.73409,6.29801,58.73409,22412,7
47.96920,-6.18513,-54.20511,6.15907,54.20511,22412,7
48.09680,-6.05579,-50.15695,6.02973,50.15695,22412,7
48.23980,-5.91216,-45.64195,5.88610,45.64195,22412,7
48.35580,-5.79614,-42.18009,5.77008,42.18009,22412,7
48.49380,-5.65802,-38.07279,5.63196,38.07279,22412,7
48.64880,-5.50285,-33.52343,5.47679,33.52343,22412,7
48.76920,-5.38281,-30.11074,5.35675,30.11074,22412,7
48.94880,-5.20309,-25.86510,5.17703,25.86510,22412,7
49.15780,-4.99381,-21.71637,4.96775,21.71637,22412,7
49.36920,-4.78292,-18.10530,4.75686,18.10530,22412,7
49.60780,-4.54394,-14.36521,4.51787,14.36521,22412,7
49.87680,-4.27484,-10.61727,4.24878,10.61727,22412,7
50.13880,-4.02329,-7.12603,3.99723,7.12603,22412,7
50.27680,-4.16575,-11.16449,4.13969,11.16449,22412,7
50.46920,-4.36721,-15.64175,4.34115,15.64175,22604,7
50.65680,-4.55803,-19.69250,4.53196,19.69250,22604,7
50.83480,-4.73681,-23.71441,4.71075,23.71441,22604,7
50.99880,-4.90079,-27.56331,4.87473,27.56331,22604,7
51.16920,-5.07112,-31.85908,5.04506,31.85908,22604,8
51.29180,-5.19419,-35.05356,5.16813,35.05356,22604,8
51.46920,-5.37092,-39.54152,5.34486,39.54152,22604,8
51.62280,-5.52500,-43.46276,5.49894,43.46276,22604,8
51.73080,-5.63313,-46.09190,5.60707,46.09190,22604,8
51.86780,-5.77012,-49.45514,5.74406,49.45514,22604,8
51.99480,-5.89698,-52.48011,5.87092,52.48011,22604,8
52.16920,-6.07111,-56.66413,6.04504,56.66413,22604,8
52.32080,-6.22312,-60.22615,6.19706,60.22615,22604,8
52.46780,-6.36976,-63.71262,6.34370,63.71262,22604,8
52.63580,-6.53796,-67.66259,6.51190,67.66259,22604,8
52.74180,-6.63361,-69.96272,6.60755,69.96272,22604,8
52.83680,-6.53867,-66.04385,6.51261,66.04385,22604,8
52.95780,-6.40769,-61.32095,6.38163,61.32095,22604,8
53.07180,-6.28950,-57.28141,6.26344,57.28141,22540,8
53.21280,-6.14624,-52.69021,6.12018,52.69021,22540,8
53.32880,-6.02931,-49.02018,6.00325,49.02018,22540,8
53.43680,-5.92099,-45.64717,5.89493,45.64717,22540,8
53.56980,-5.78793,-41.65257,5.76187,41.65257,22540,8
53.72380,-5.63382,-37.07974,5.60776,37.07974,22540,8
53.83880,-5.51872,-33.73329,5.49265,33.73329,22540,8
53.98280,-5.37465,-29.67173,5.34859,29.67173,22540,8
54.16920,-5.18892,-25.41202,5.16286,25.41202,22540,8
54.37880,-4.97867,-21.32124,4.95261,21.32124,22540,8
54.61880,-4.73885,-17.24747,4.71279,17.24747,22540,8
54.86920,-4.48870,-13.44625,4.46264,13.44625,22540,8
55.14080,-4.21693,-9.72931,4.19087,9.72931,22540,8
55.35280,-4.05568,-7.85903,4.02962,7.85903,22540,8
55.49780,-4.21921,-12.14798,4.19315,12.14798,22540,8
55.67180,-4.40045,-16.15604,4.37439,16.15604,22604,8
55.86920,-4.60016,-20.35609,4.57410,20.35609,22604,8
56.04980,-4.78160,-24.47893,4.75554,24.47893,22604,9
56.17580,-4.90770,-27.41391,4.88164,27.41391,22604,9
56.35680,-5.08907,-32.01928,5.06301,32.01928,22604,9
56.51080,-5.24309,-36.01961,5.21702,36.01961,22604,9
56.67880,-5.41079,-40.18873,5.38473,40.18873,22604,9
56.85380,-5.58605,-44.64741,5.55999,44.64741,22604,9
57.00380,-5.73605,-48.47638,5.70999,48.47638,22604,9
57.17880,-5.91089,-52.61976,5.88483,52.61975,22604,9
57.34280,-6.07504,-56.58857,6.04898,56.58857,22604,9
57.49580,-6.22805,-60.15841,6.20199,60.15841,22604,9
57.66920,-6.40070,-64.30026,6.37464,64.30026,22604,9
57.78680,-6.51887,-67.08334,6.49281,67.08334,22604,9
57.91480,-6.63748,-69.86137,6.61142,69.86137,22604,9
58.01080,-6.54268,-65.96524,6.51662,65.96523,22604,9
58.13080,-6.41275,-61.27387,6.38669,61.27387,22604,9
58.23080,-6.30892,-57.73287,6.28286,57.73287,22540,9
58.36920,-6.16848,-53.16574,6.14242,53.16574,22540,9
58.49480,-6.04139,-49.20447,6.01533,49.20447,22540,9
58.63280,-5.90292,-44.85522,5.87686,44.85522,22540,9
58.75380,-5.78190,-41.24447,5.75584,41.24447,22540,9
58.81880,-5.71693,-39.32527,5.69087,39.32527,22540,9
58.89580,-5.63982,-37.03775,5.61376,37.03775,22540,9
59.01180,-5.52374,-33.65947,5.49768,33.65947,22540,9
59.13780,-5.39763,-30.01583,5.37157,30.01583,22540,9
59.26920,-5.26677,-26.83319,5.24071,26.83319,22540,9
59.46920,-5.06679,-22.82435,5.04073,22.82435,22540,9
59.66680,-4.86864,-19.18647,4.84258,19.18646,22540,9
59.87280,-4.66291,-15.94129,4.63685,15.94129,22540,9
60.16880,-4.36667,-11.72055,4.34061,11.72055,22540,9
60.41680,-4.11891,-8.16995,4.09284,8.16995,22540,9
60.63980,-4.04900,-7.81571,4.02294,7.81571,22540,9
60.86280,-4.05476,-8.49838,4.02870,8.49838,22540,9
61.01880,-4.20265,-12.17475,4.17659,12.17475,22540,9
61.19880,-4.38723,-16.14121,4.36117,16.14121,22476,9
61.38980,-4.57988,-20.25759,4.55382,20.25759,22476,9
61.53880,-4.72927,-23.58124,4.70321,23.58124,22476,9
61.71280,-4.90316,-27.52268,4.87709,27.52268,22476,9
61.84580,-5.03633,-30.99200,5.01027,30.99200,22476,10
61.96920,-5.15946,-34.20733,5.13339,34.20733,22476,10
62.10280,-5.29338,-37.51932,5.26732,37.51932,22476,10
62.26920,-5.45926,-41.67180,5.43320,41.67180,22476,10
62.36920,-5.55940,-44.17481,5.53334,44.17481,22476,10
62.46920,-5.65945,-46.69687,5.63339,46.69687,22476,10
62.54080,-5.73143,-48.45621,5.70537,48.45621,22476,10
62.67380,-5.86437,-51.63769,5.83831,51.63770,22476,10
62.86080,-6.05139,-56.03784,6.02533,56.03784,22476,10
62.99180,-6.18248,-59.10648,6.15642,59.10648,22476,10
63.07180,-6.26236,-60.99388,6.23630,60.99388,22476,10
63.20080,-6.39109,-64.05701,6.36503,64.05701,22476,10
63.31080,-6.50128,-66.69322,6.47521,66.69322,22476,10
63.45080,-6.63517,-69.85717,6.60911,69.85717,22476,10
63.55280,-6.53878,-65.82016,6.51272,65.82016,22476,10
63.66920,-6.41326,-61.27623,6.38720,61.27623,22476,10
63.78580,-6.29190,-57.17780,6.26584,57.17780,22412,10
63.92680,-6.14863,-52.55363,6.12256,52.55363,22412,10
64.06920,-6.00554,-48.13216,5.97948,48.13216,22412,10
64.16920,-5.90531,-44.88958,5.87925,44.88958,22412,10
64.27880,-5.79532,-41.65229,5.76926,41.65229,22412,10
64.42879,-5.64518,-37.19692,5.61912,37.19692,22412,10
64.56920,-5.50506,-33.09833,5.47900,33.09833,22412,10
64.69880,-5.37502,-29.42806,5.34896,29.42805,22412,10
64.79480,-5.27917,-27.03648,5.25311,27.03648,22412,10
65.00080,-5.07317,-22.83964,5.04711,22.83964,22412,10
65.16920,-4.90496,-19.67042,4.87890,19.67043,22412,10
65.36920,-4.70536,-16.50981,4.67929,16.50981,22412,10
65.62680,-4.44712,-12.67689,4.42106,12.67689,22412,10
65.87480,-4.19934,-9.20365,4.17328,9.20365,22412,10
66.07380,-4.08936,-8.45903,4.06330,8.45903,22412,10
66.24880,-4.28346,-13.20408,4.25740,13.20408,22412,10
66.42280,-4.46293,-17.17966,4.43687,17.17966,22476,10
66.59880,-4.64069,-21.11849,4.61463,21.11849,22476,10
66.77580,-4.81806,-25.15195,4.79200,25.15195,22476,11
66.96280,-5.00533,-29.69588,4.97927,29.69588,22476,11
67.07180,-5.11444,-32.48256,5.08837,32.48256,22476,11
67.20480,-5.24747,-35.89725,5.22141,35.89725,22476,11
67.30380,-5.34633,-38.53668,5.32027,38.53667,22476,11
67.46920,-5.51129,-42.62192,5.48523,42.62192,22476,11
67.64580,-5.68850,-47.09730,5.66243,47.09730,22476,11
67.77280,-5.81549,-50.13408,5.78943,50.13408,22476,11
67.92080,-5.96337,-53.72234,5.93731,53.72234,22476,11
68.06180,-6.10451,-57.08996,6.07845,57.08996,22476,11
68.16480,-6.20750,-59.53186,6.18144,59.53186,22476,11
68.33280,-6.37513,-63.46844,6.34907,63.46844,22476,11
68.44580,-6.48831,-66.17769,6.46225,66.17769,22476,11
68.54680,-6.58933,-68.58011,6.56327,68.58012,22476,11
68.65180,-6.61658,-68.51216,6.59052,68.51215,22476,11
68.76480,-6.48746,-63.61341,6.46140,63.61341,22476,11
68.87280,-6.37304,-59.64429,6.34697,59.64429,22412,11
68.97080,-6.27223,-56.29750,6.24617,56.29750,22412,11
69.11480,-6.12637,-51.57809,6.10031,51.57809,22412,11
69.25480,-5.98548,-47.28190,5.95942,47.28190,22412,11
69.39080,-5.84934,-43.03218,5.82328,43.03218,22412,11
69.54080,-5.69931,-38.62064,5.67325,38.62064,22412,11
69.60380,-5.63621,-36.66177,5.61015,36.66177,22412,11
69.73880,-5.50107,-32.68257,5.47501,32.68257,22412,11
69.89280,-5.34713,-28.46268,5.32107,28.46268,22412,11
70.07680,-5.16329,-24.48254,5.13723,24.48254,22412,11
70.29080,-4.94910,-20.36202,4.92304,20.36202,22412,11
70.52480,-4.71537,-16.50070,4.68931,16.50070,22412,11
70.78280,-4.45718,-12.68322,4.43112,12.68322,22412,11
71.02480,-4.21536,-9.27353,4.18930,9.27353,22412,11
71.16920,-4.07753,-7.35290,4.05147,7.35290,22412,11
71.31780,-4.22564,-11.62077,4.19958,11.62077,22412,11
71.49280,-4.40933,-15.69102,4.38327,15.69102,22476,11
71.65080,-4.57011,-19.24760,4.54405,19.24760,22476,11
71.81780,-4.73808,-23.09624,4.71202,23.09624,22476,12
71.99280,-4.91319,-27.11373,4.88712,27.11373,22476,12
72.16920,-5.08957,-31.63427,5.06351,31.63427,22476,12
72.27480,-5.19561,-34.46403,5.16955,34.46403,22476,12
72.41880,-5.33946,-38.11095,5.31340,38.11095,22476,12
72.51480,-5.43532,-40.44819,5.40926,40.44819,22476,12
72.61480,-5.53541,-43.08831,5.50935,43.08831,22476,12
72.74880,-5.66952,-46.48907,5.64346,46.48907,22476,12
72.87480,-5.79554,-49.49016,5.76948,49.49016,22476,12
73.02280,-5.94341,-53.05273,5.91735,53.05273,22476,12
73.18580,-6.10659,-57.05599,6.08053,57.05600,22476,12
73.35780,-6.27839,-61.10177,6.25233,61.10177,22476,12
73.50480,-6.42524,-64.60270,6.39918,64.60270,22476,12
73.65280,-6.57342,-68.10597,6.54736,68.10596,22476,12
73.76680,-6.63280,-69.02103,6.60674,69.02103,22476,12
73.86920,-6.51534,-64.46053,6.48927,64.46053,22476,12
73.96920,-6.40837,-60.66742,6.38231,60.66742,22476,12
74.07680,-6.29674,-56.96344,6.27068,56.96344,22412,12
74.22280,-6.14852,-52.13332,6.12246,52.13332,22412,12
74.36580,-6.00453,-47.72697,5.97847,47.72697,22412,12
74.49780,-5.87233,-43.56245,5.84627,43.56245,22412,12
74.65080,-5.71933,-39.04122,5.69327,39.04122,22412,12
74.78380,-5.58623,-35.03354,5.56017,35.03354,22412,12
74.93780,-5.43210,-30.53905,5.40604,30.53905,22412,12
75.10380,-5.26617,-26.45793,5.24011,26.45793,22412,12
75.31180,-5.05816,-22.27477,5.03210,22.27477,22412,12
75.54680,-4.82314,-18.17510,4.79708,18.17510,22412,12
75.76920,-4.60117,-14.71531,4.57511,14.71531,22412,12
76.04480,-4.32518,-10.76350,4.29912,10.76350,22412,12
76.28280,-4.08734,-7.37218,4.06128,7.37218,22412,12
76.41580,-4.16113,-10.07978,4.13507,10.07978,22412,12
76.58780,-4.34477,-14.24676,4.31871,14.24676,22476,12
76.76920,-4.52972,-18.36216,4.50365,18.36216,22476,12
76.95480,-4.71705,-22.64010,4.69099,22.64010,22476,13
77.12280,-4.88511,-26.57855,4.85905,26.57855,22476,13
77.23580,-4.99834,-29.40998,4.97228,29.40998,22476,13
77.32880,-5.09149,-31.70859,5.06543,31.70859,22476,13
77.45880,-5.22155,-35.09920,5.19549,35.09920,22476,13
77.61780,-5.38035,-39.13029,5.35429,39.13029,22476,13
77.77080,-5.53342,-43.01596,5.50736,43.01596,22476,13
77.91480,-5.67746,-46.65322,5.65140,46.65322,22476,13
78.01680,-5.77943,-49.14691,5.75337,49.14691,22476,13
78.16580,-5.92831,-52.64971,5.90225,52.64971,22476,13
78.33280,-6.09551,-56.68445,6.06945,56.68444,22476,13
78.49480,-6.25742,-60.48713,6.23136,60.48713,22476,13
78.58280,-6.34520,-62.58446,6.31914,62.58446,22476,13
78.71080,-6.47331,-65.62483,6.44725,65.62483,22476,13
78.85580,-6.61831,-69.10981,6.59225,69.10981,22476,13
78.95680,-6.61064,-67.88119,6.58458,67.88119,22476,13
79.06780,-6.48550,-63.23029,6.45944,63.23029,22476,13
79.18080,-6.36636,-59.06691,6.34030,59.06691,22412,13
79.30880,-6.23545,-54.72114,6.20939,54.72114,22412,13
79.45380,-6.08899,-50.06843,6.06293,50.06843,22412,13
79.56080,-5.98141,-46.82013,5.95535,46.82013,22412,13
79.66920,-5.87326,-43.47414,5.84720,43.47414,22412,13
79.78280,-5.75925,-39.96461,5.73319,39.96460,22412,13
79.93280,-5.60918,-35.55607,5.58312,35.55607,22412,13
80.07080,-5.47107,-31.49089,5.44501,31.49089,22412,13
80.24480,-5.29717,-26.87934,5.27111,26.87934,22412,13
80.44680,-5.09515,-22.83768,5.06909,22.83768,22412,13
80.66920,-4.87299,-18.81994,4.84693,18.81994,22412,13
80.90880,-4.63315,-15.08610,4.60709,15.08610,22412,13
81.16920,-4.37303,-11.41067,4.34697,11.41067,22412,13
81.43280,-4.10928,-7.63979,4.08322,7.63979,22412,13
81.56920,-4.16950,-10.10766,4.14344,10.10766,22412,13
81.75280,-4.36599,-14.59605,4.33993,14.59605,22476,13
81.93480,-4.55183,-18.70604,4.52577,18.70604,22476,13
82.10180,-4.72002,-22.55599,4.69396,22.55599,22476,14
82.28780,-4.90608,-26.74943,4.88002,26.74943,22476,14
82.42180,-5.04032,-30.12024,5.01426,30.12024,22476,14
82.55680,-5.17548,-33.61816,5.14942,33.61816,22476,14
82.70680,-5.32536,-37.43404,5.29930,37.43404,22476,14
82.86980,-5.48840,-41.55514,5.46234,41.55514,22476,14
83.04480,-5.66349,-45.99066,5.63743,45.99066,22476,14
83.15080,-5.76951,-48.64460,5.74345,48.64460,22476,14
83.26920,-5.88736,-51.54109,5.86130,51.54109,22476,14
83.38380,-6.00240,-54.25886,5.97634,54.25887,22476,14
83.55880,-6.17754,-58.44035,6.15148,58.44035,22476,14
83.72680,-6.34521,-62.46929,6.31915,62.46929,22476,14
83.86920,-6.48728,-65.86371,6.46122,65.86372,22476,14
83.98880,-6.60734,-68.70226,6.58128,68.70226,22476,14
84.08280,-6.64064,-68.89006,6.61458,68.89007,22476,14
84.19080,-6.51651,-64.20170,6.49045,64.20170,22476,14
84.31180,-6.38798,-59.66292,6.36192,59.66292,22476,14
84.41380,-6.28312,-56.15385,6.25706,56.15385,22412,14
84.54880,-6.14636,-51.76614,6.12030,51.76614,22412,14
84.68680,-6.00746,-47.53244,5.98140,47.53244,22412,14
84.82880,-5.86525,-43.15310,5.83919,43.15310,22412,14
84.94880,-5.74524,-39.52592,5.71918,39.52592,22412,14
85.08180,-5.61217,-35.56184,5.58611,35.56184,22412,14
85.16920,-5.52507,-33.01989,5.49901,33.01989,22412,14
85.32680,-5.36703,-28.52654,5.34097,28.52654,22412,14
85.51280,-5.18128,-24.43304,5.15522,24.43304,22412,14
85.72280,-4.97104,-20.38028,4.94498,20.38028,22412,14
85.96920,-4.72526,-16.40844,4.69920,16.40844,22412,14
86.22080,-4.47307,-12.69908,4.44701,12.69908,22412,14
86.46920,-4.22532,-9.19882,4.19926,9.19882,22412,14
86.67880,-4.11546,-8.57065,4.08940,8.57065,22412,14
86.84780,-4.30239,-13.10887,4.27633,13.10887,22412,14
87.02580,-4.48602,-17.15259,4.45996,17.15259,22476,14
87.20080,-4.66272,-21.12294,4.63666,21.12294,22476,14
87.35180,-4.81403,-24.63207,4.78797,24.63207,22476,15
87.47680,-4.93916,-27.48965,4.91310,27.48965,22476,15
87.62280,-5.08547,-31.17187,5.05941,31.17187,22476,15
87.72580,-5.18850,-33.89409,5.16243,33.89409,22476,15
87.83480,-5.29736,-36.63297,5.27130,36.63297,22476,15
87.94680,-5.40914,-39.50149,5.38308,39.50149,22476,15
88.06920,-5.53136,-42.63833,5.50530,42.63833,22476,15
88.15580,-5.61847,-44.74365,5.59241,44.74365,22476,15
88.30580,-5.76846,-48.56202,5.74240,48.56202,22476,15
88.46920,-5.93136,-52.46010,5.90530,52.46010,22476,15
88.61180,-6.07448,-55.97591,6.04842,55.97591,22476,15
88.76680,-6.22950,-59.65325,6.20344,59.65325,22476,15
88.88680,-6.34918,-62.46559,6.32312,62.46559,22476,15
88.99580,-6.45824,-65.10059,6.43218,65.10059,22476,15
89.14080,-6.60334,-68.49135,6.57728,68.49136,22476,15
89.25080,-6.63766,-68.65542,6.61160,68.65542,22476,15
89.35880,-6.51385,-63.85905,6.48779,63.85905,22476,15
89.46920,-6.39709,-59.80970,6.37102,59.80970,22476,15
89.60580,-6.25652,-55.12982,6.23046,55.12982,22412,15
89.74680,-6.11401,-50.62699,6.08795,50.62699,22412,15
89.87480,-5.98532,-46.66925,5.95926,46.66925,22412,15
89.99580,-5.86418,-42.91924,5.83812,42.91924,22412,15
90.10780,-5.75218,-39.57539,5.72612,39.57539,22412,15
90.22180,-5.63809,-36.10949,5.61203,36.10949,22412,15
90.36920,-5.49099,-31.84601,5.46493,31.84601,22412,15
90.53480,-5.32511,-27.34763,5.29905,27.34763,22412,15
90.73380,-5.12610,-23.25393,5.10004,23.25393,22412,15
90.94880,-4.91092,-19.24706,4.88486,19.24706,22412,15
91.16920,-4.69128,-15.74244,4.66522,15.74244,22412,15
91.44780,-4.41196,-11.77492,4.38590,11.77492,22412,15
91.69780,-4.16223,-8.21349,4.13617,8.21349,22412,15
91.86920,-4.17037,-9.86161,4.14431,9.86161,22412,15
92.04280,-4.35731,-14.14891,4.33125,14.14891,22412,15
92.21280,-4.53143,-18.05540,4.50537,18.05540,22476,15
92.38580,-4.70588,-22.06403,4.67982,22.06403,22476,15
92.54280,-4.86306,-25.68373,4.83700,25.68373,22476,16
92.69880,-5.01930,-29.48273,4.99324,29.48273,22476,16
92.83580,-5.15644,-32.99249,5.13037,32.99249,22476,16
92.99780,-5.31835,-37.04342,5.29229,37.04342,22476,16
93.16920,-5.48939,-41.32984,5.46333,41.32984,22476,16
93.29880,-5.61947,-44.71489,5.59341,44.71489,22476,16
93.46920,-5.78945,-48.93495,5.76339,48.93495,22476,16
93.63380,-5.95433,-52.88530,5.92827,52.88530,22476,16
93.76920,-6.08950,-56.17826,6.06344,56.17826,22476,16
93.92980,-6.25046,-60.00794,6.22440,60.00794,22476,16
94.08680,-6.40712,-63.72780,6.38106,63.72779,22476,16
94.26920,-6.58932,-68.07919,6.56326,68.07919,22476,16
94.34680,-6.66538,-69.96253,6.63932,69.96253,22476,16
94.42480,-6.61000,-67.32016,6.58394,67.32016,22476,16
94.53680,-6.48557,-62.78152,6.45951,62.78152,22476,16
94.66380,-6.35252,-58.16263,6.32646,58.16262,22412,16
94.78380,-6.23024,-54.06899,6.20417,54.06899,22412,16
94.89080,-6.12211,-50.72343,6.09605,50.72343,22412,16
95.03480,-5.97739,-46.25188,5.95133,46.25188,22412,16
95.14880,-5.86326,-42.76430,5.83719,42.76430,22412,16
95.26920,-5.74325,-39.20582,5.71719,39.20581,22412,16
95.37080,-5.64118,-36.08537,5.61512,36.08537,22412,16
95.48580,-5.52609,-32.76632,5.50003,32.76632,22412,16
95.65980,-5.35209,-27.97417,5.32603,27.97417,22412,16
95.80280,-5.20928,-24.86034,5.18322,24.86034,22412,16
96.00880,-5.00301,-20.88961,4.97695,20.88961,22412,16
96.25880,-4.75314,-16.71010,4.72708,16.71010,22412,16
96.48680,-4.52505,-13.24272,4.49899,13.24272,22412,16
96.76920,-4.24325,-9.31570,4.21719,9.31570,22412,16
96.97080,-4.10664,-7.98963,4.08058,7.98963,22412,16
97.13280,-4.28818,-12.61029,4.26211,12.61029,22412,16
97.30480,-4.46656,-16.58650,4.44050,16.58650,22476,16
97.48680,-4.65065,-20.60140,4.62459,20.60140,22476,16
97.66920,-4.83312,-24.88681,4.80706,24.88681,22476,17
97.83480,-4.99938,-28.82606,4.97332,28.82606,22476,17
97.99680,-5.16156,-33.00134,5.13550,33.00134,22476,17
98.11380,-5.27838,-35.93367,5.25232,35.93367,22476,17
98.21480,-5.37936,-38.57647,5.35330,38.57647,22476,17
98.36920,-5.53344,-42.47045,5.50738,42.47045,22476,17
98.49380,-5.65854,-45.53881,5.63248,45.53881,22476,17
98.66920,-5.83354,-49.91205,5.80748,49.91206,22476,17
98.83580,-6.00044,-54.02121,5.97438,54.02121,22476,17
99.01180,-6.17660,-58.14636,6.15054,58.14636,22476,17
99.17280,-6.33730,-62.07804,6.31124,62.07804,22476,17
99.32280,-6.48731,-65.67189,6.46125,65.67189,22476,17
99.47380,-6.63838,-69.29754,6.61232,69.29754,22476,17
99.56920,-6.60917,-67.34814,6.58311,67.34814,22476,17
99.67980,-6.48509,-62.76957,6.45903,62.76957,22476,17
99.80880,-6.34975,-58.05333,6.32368,58.05333,22412,17
99.94280,-6.21324,-53.58386,6.18718,53.58386,22412,17
100.06980,-6.08505,-49.55222,6.05899,49.55222,22412,17
100.21280,-5.94143,-45.07888,5.91537,45.07888,22412,17
100.36280,-5.79137,-40.52834,5.76531,40.52834,22412,17
100.46280,-5.69137,-37.60572,5.66531,37.60572,22412,17
100.57980,-5.57430,-34.21520,5.54824,34.21520,22412,17
100.74280,-5.41114,-29.47891,5.38507,29.47891,22412,17
100.86920,-5.28525,-26.38250,5.25919,26.38250,22412,17
101.06920,-5.08526,-22.35090,5.05920,22.35090,22412,17
101.30480,-4.84912,-18.21102,4.82306,18.21102,22412,17
101.55080,-4.60326,-14.35849,4.57720,14.35849,22412,17
101.80780,-4.34622,-10.74372,4.32016,10.74372,22412,17
102.06920,-4.09159,-7.19220,4.06553,7.19220,22412,17
102.20880,-4.22999,-11.22150,4.20393,11.22150,22412,17
102.37580,-4.40591,-15.15614,4.37985,15.15614,22604,17
102.56920,-4.60236,-19.45083,4.57630,19.45083,22604,17
102.71080,-4.74509,-22.74401,4.71903,22.74401,22604,17
102.87780,-4.91220,-26.64407,4.88614,26.64407,22604,17
103.05880,-5.09363,-31.11990,5.06757,31.11990,22604,18
103.21980,-5.25453,-35.32790,5.22847,35.32790,22604,18
103.37080,-5.40538,-39.16784,5.37932,39.16784,22604,18
103.54480,-5.57959,-43.52534,5.55353,43.52534,22604,18
103.64280,-5.67759,-45.98255,5.65152,45.98255,22604,18
103.80780,-5.84259,-50.04939,5.81653,50.04939,22604,18
103.95480,-5.98951,-53.62659,5.96345,53.62659,22604,18
104.05480,-6.08966,-56.10457,6.06360,56.10457,22604,18
104.15880,-6.19364,-58.50646,6.16758,58.50645,22604,18
104.29080,-6.32537,-61.66187,6.29931,61.66187,22604,18
104.43480,-6.46939,-65.15771,6.44333,65.15771,22604,18
104.59680,-6.63150,-69.00784,6.60544,69.00784,22604,18
104.69380,-6.62859,-67.95829,6.60253,67.95829,22604,18
104.80880,-6.49862,-63.08705,6.47256,63.08705,22604,18
104.89880,-6.40337,-59.77561,6.37731,59.77561,22540,18
105.03580,-6.26273,-55.10975,6.23666,55.10975,22540,18
105.16920,-6.12828,-50.80528,6.10222,50.80528,22540,18
105.26980,-6.02664,-47.70958,6.00058,47.70958,22540,18
105.36920,-5.92745,-44.54109,5.90139,44.54110,22540,18
105.45480,-5.84142,-41.97641,5.81536,41.97641,22540,18
105.58480,-5.71140,-38.13350,5.68534,38.13350,22540,18
105.74280,-5.55329,-33.51926,5.52723,33.51926,22540,18
105.87580,-5.42019,-29.61736,5.39413,29.61736,22540,18
106.03280,-5.26327,-25.86819,5.23721,25.86819,22540,18
106.22980,-5.06629,-21.92183,5.04023,21.92183,22540,18
106.45280,-4.84320,-18.04138,4.81714,18.04138,22540,18
106.66280,-4.63329,-14.81086,4.60723,14.81086,22540,18
106.90880,-4.38719,-11.33566,4.36112,11.33566,22540,18
107.16920,-4.12740,-7.55865,4.10134,7.55865,22540,18
107.31880,-4.20758,-10.54283,4.18152,10.54283,22540,18
107.48880,-4.38827,-14.58893,4.36221,14.58893,22604,18
107.66920,-4.57206,-18.69013,4.54600,18.69013,22604,18
107.81780,-4.72215,-22.11618,4.69609,22.11618,22604,18
107.98580,-4.89025,-25.97904,4.86419,25.97904,22604,19
108.08880,-4.99348,-28.41320,4.96742,28.41320,22604,19
108.19980,-5.10472,-31.26135,5.07866,31.26135,22604,19
108.36480,-5.26956,-35.53513,5.24350,35.53513,22604,19
108.52080,-5.42549,-39.54951,5.39943,39.54951,22604,19
108.68080,-5.58569,-43.60531,5.55962,43.60530,22604,19
108.81480,-5.71973,-47.04232,5.69367,47.04232,22604,19
108.92380,-5.82868,-49.64639,5.80262,49.64639,22604,19
109.08880,-5.99363,-53.69091,5.96757,53.69091,22604,19
109.23480,-6.13971,-57.23895,6.11365,57.23895,22604,19
109.35580,-6.26064,-60.11642,6.23458,60.11642,22604,19
109.43780,-6.34243,-62.10925,6.31637,62.10925,22604,19
109.56920,-6.47348,-65.24757,6.44742,65.24757,22604,19
109.68780,-6.59254,-68.02876,6.56648,68.02876,22604,19
109.81880,-6.63479,-68.17290,6.60872,68.17290,22604,19
109.92080,-6.51808,-63.77141,6.49202,63.77141,22604,19
110.04080,-6.39094,-59.35133,6.36488,59.35133,22540,19
110.16920,-6.25973,-54.94634,6.23367,54.94634,22540,19
110.29280,-6.13437,-50.93425,6.10830,50.93425,22540,19
110.36920,-6.05790,-48.61771,6.03184,48.61771,22540,19
110.50080,-5.92548,-44.42221,5.89942,44.42221,22540,19
110.63280,-5.79344,-40.44986,5.76738,40.44986,22540,19
110.76280,-5.66339,-36.63334,5.63733,36.63334,22540,19
110.85080,-5.57537,-34.09475,5.54931,34.09475,22540,19
110.93880,-5.48723,-31.41585,5.46117,31.41585,22540,19
111.08480,-5.34131,-27.41497,5.31525,27.41497,22540,19
111.27680,-5.14938,-23.39554,5.12332,23.39554,22540,19
111.49780,-4.92819,-19.33277,4.90213,19.33277,22540,19
111.75780,-4.66844,-15.24929,4.64238,15.24929,22540,19
112.01180,-4.41428,-11.65295,4.38822,11.65295,22540,19
112.26920,-4.15744,-7.94405,4.13138,7.94405,22540,19
112.59680,-4.09311,-8.02480,4.06704,8.02480,22540,19
112.78580,-4.18462,-10.66343,4.15856,10.66343,22540,19
112.96920,-4.37460,-14.83078,4.34853,14.83078,22476,19
113.16920,-4.57692,-19.24655,4.55085,19.24655,22476,19
113.33780,-4.74643,-23.05472,4.72037,23.05472,22476,19
113.51280,-4.92143,-27.07386,4.89537,27.07386,22476,19
113.67280,-5.08172,-31.10884,5.05566,31.10884,22476,20
113.84680,-5.25571,-35.54503,5.22965,35.54502,22476,20
114.01280,-5.42152,-39.74513,5.39546,39.74512,22476,20
114.16920,-5.57768,-43.68956,5.55162,43.68956,22476,20
114.30380,-5.71273,-47.09157,5.68667,47.09157,22476,20
114.44280,-5.85162,-50.46790,5.82556,50.46790,22476,20
114.61080,-6.01960,-54.47436,5.99354,54.47436,22476,20
114.71680,-6.12576,-56.99622,6.09970,56.99622,22476,20
114.88680,-6.29550,-60.98646,6.26944,60.98646,22476,20
115.06920,-6.47751,-65.32952,6.45145,65.32952,22476,20
115.19780,-6.60655,-68.38020,6.58049,68.38020,22476,20
115.30980,-6.64298,-68.55968,6.61692,68.55968,22476,20
115.41880,-6.51804,-63.83397,6.49198,63.83397,22476,20
115.53880,-6.39094,-59.34760,6.36488,59.34760,22476,20
115.66920,-6.25773,-54.96446,6.23167,54.96446,22412,20
115.77080,-6.15458,-51.66323,6.12852,51.66323,22412,20
115.88680,-6.03778,-48.10593,6.01172,48.10593,22412,20
116.02780,-5.89644,-43.61227,5.87038,43.61227,22412,20
116.11480,-5.80950,-41.00910,5.78344,41.00910,22412,20
116.26180,-5.66243,-36.65824,5.63637,36.65824,22412,20
116.40080,-5.52329,-32.52139,5.49722,32.52139,22412,20
116.56280,-5.36125,-27.95069,5.33519,27.95069,22412,20
116.74280,-5.18150,-24.05258,5.15544,24.05258,22412,20
116.96920,-4.95528,-19.77000,4.92922,19.77000,22412,20
117.18480,-4.73939,-16.31852,4.71333,16.31852,22412,20
117.45880,-4.46527,-12.30595,4.43921,12.30595,22412,20
117.71580,-4.20857,-8.68851,4.18251,8.68851,22412,20
117.88680,-4.15107,-8.86197,4.12501,8.86197,22412,20
118.06920,-4.35070,-13.67819,4.32464,13.67819,22476,20
118.24580,-4.53256,-17.74195,4.50650,17.74195,22476,20
118.40980,-4.69805,-21.48934,4.67199,21.48934,22476,20
118.56380,-4.85234,-25.09608,4.82628,25.09608,22476,21
118.65080,-4.93946,-27.03583,4.91340,27.03583,22476,21
118.78680,-5.07574,-30.59036,5.04968,30.59036,22476,21
118.84880,-5.13776,-32.22149,5.11170,32.22149,22476,21
118.97780,-5.26673,-35.48381,5.24067,35.48381,22476,21
119.05480,-5.34368,-37.47896,5.31761,37.47896,22476,21
119.17480,-5.46362,-40.42656,5.43756,40.42656,22476,21
119.27080,-5.55969,-42.98560,5.53363,42.98560,22476,21
119.37880,-5.66773,-45.62053,5.64167,45.62053,22476,21
119.52280,-5.81175,-49.17976,5.78569,49.17976,22476,21
119.63880,-5.92765,-52.04444,5.90159,52.04444,22476,21
119.78280,-6.07175,-55.54429,6.04569,55.54430,22476,21
119.95280,-6.24180,-59.58822,6.21574,59.58822,22476,21
120.09280,-6.38142,-62.87719,6.35536,62.87719,22476,21
120.16280,-6.45152,-64.64855,6.42546,64.64855,22476,21
120.27280,-6.56159,-67.13718,6.53553,67.13718,22476,21
120.39880,-6.66359,-69.40273,6.63753,69.40273,22476,21
120.48880,-6.56457,-65.42896,6.53851,65.42896,22476,21
120.58280,-6.46264,-61.74069,6.43658,61.74069,22476,21
120.67880,-6.36210,-58.23994,6.33604,58.23994,22412,21
120.81780,-6.22042,-53.57251,6.19436,53.57251,22412,21
120.95580,-6.08116,-49.18712,6.05510,49.18712,22412,21
121.02480,-6.01168,-47.13560,5.98562,47.13559,22412,21
121.15180,-5.88448,-43.13137,5.85842,43.13137,22412,21
121.29080,-5.74547,-39.00570,5.71941,39.00570,22412,21
121.43680,-5.59939,-34.65150,5.57333,34.65150,22412,21
121.57280,-5.46330,-30.69185,5.43724,30.69185,22412,21
121.76480,-5.27137,-25.84827,5.24531,25.84827,22412,21
121.96080,-5.07542,-21.91785,5.04936,21.91785,22412,21
122.16920,-4.86722,-18.24955,4.84116,18.24955,22412,21
122.36920,-4.66748,-15.12020,4.64142,15.12020,22412,21
122.63680,-4.39926,-11.31251,4.37320,11.31251,22412,21
122.85380,-4.18258,-8.26046,4.15652,8.26046,22412,21
122.98480,-4.13633,-8.32673,4.11027,8.32673,22412,21
123.15980,-4.33072,-13.12986,4.30466,13.12986,22412,21
123.33380,-4.51024,-17.15061,4.48418,17.15061,22476,21
123.50680,-4.68500,-21.08775,4.65894,21.08775,22476,21
123.68080,-4.85936,-25.23337,4.83330,25.23337,22476,22
123.86280,-5.04163,-29.63069,5.01557,29.63070,22476,22
123.97480,-5.15375,-32.55984,5.12769,32.55984,22476,22
124.11480,-5.29361,-36.07889,5.26755,36.07889,22476,22
124.26920,-5.44766,-40.03787,5.42160,40.03787,22476,22
124.40180,-5.58082,-43.42224,5.55476,43.42225,22476,22
124.53980,-5.71887,-46.95704,5.69281,46.95704,22476,22
124.71280,-5.89163,-51.19004,5.86557,51.19004,22476,22
124.87680,-6.05573,-55.06410,6.02966,55.06411,22476,22
125.02680,-6.20585,-58.57543,6.17979,58.57543,22476,22
125.15780,-6.33655,-61.84082,6.31049,61.84082,22476,22
125.33080,-6.50961,-65.94792,6.48354,65.94792,22476,22
125.46680,-6.64559,-69.11222,6.61953,69.11222,22476,22
125.56880,-6.62117,-67.39797,6.59511,67.39797,22476,22
125.67180,-6.50582,-63.07171,6.47975,63.07170,22476,22
125.79280,-6.37837,-58.64273,6.35231,58.64273,22412,22
125.92380,-6.24456,-54.25304,6.21850,54.25304,22412,22
126.06680,-6.10026,-49.65575,6.07420,49.65575,22412,22
126.16920,-5.99771,-46.49318,5.97165,46.49318,22412,22
126.30880,-5.85757,-42.19460,5.83151,42.19460,22412,22
126.46480,-5.70159,-37.61034,5.67553,37.61034,22412,22
126.57080,-5.59548,-34.46700,5.56942,34.46700,22412,22
126.72580,-5.44040,-29.96348,5.41434,29.96348,22412,22
126.86580,-5.30050,-26.32074,5.27444,26.32074,22412,22
127.05280,-5.11349,-22.53322,5.08743,22.53322,22412,22
127.26920,-4.89729,-18.71572,4.87123,18.71572,22412,22
127.51880,-4.64747,-14.75699,4.62141,14.75699,22412,22
127.77080,-4.39533,-11.22659,4.36927,11.22659,22412,22
128.02480,-4.14156,-7.58844,4.11550,7.58844,22412,22
128.15180,-4.20873,-10.14671,4.18267,10.14671,22412,22
128.31279,-4.38140,-14.10472,4.35534,14.10472,22476,22
128.48979,-4.56282,-18.17489,4.53676,18.17489,22476,22
128.66919,-4.74322,-22.34812,4.71716,22.34812,22476,23
128.84880,-4.92342,-26.61349,4.89736,26.61349,22476,23
129.00279,-5.07778,-30.49914,5.05172,30.49914,22476,23
129.16919,-5.24376,-34.79506,5.21770,34.79506,22476,23
129.26920,-5.34372,-37.31356,5.31766,37.31356,22476,23
129.36920,-5.44370,-39.85904,5.41764,39.85904,22476,23
129.49680,-5.57183,-43.08686,5.54577,43.08686,22476,23
129.63380,-5.70888,-46.60529,5.68282,46.60529,22476,23
129.79080,-5.86574,-50.44287,5.83968,50.44287,22476,23
129.88280,-5.95770,-52.63523,5.93164,52.63523,22476,23
130.00080,-6.07583,-55.48595,6.04976,55.48595,22476,23
130.11280,-6.18786,-58.13337,6.16180,58.13337,22476,23
130.26380,-6.33859,-61.68211,6.31253,61.68211,22476,23
130.42580,-6.50067,-65.58020,6.47461,65.58021,22476,23
130.55480,-6.62959,-68.70388,6.60353,68.70388,22476,23
130.64580,-6.66821,-69.08489,6.64215,69.08489,22476,23
130.75279,-6.54528,-64.31986,6.51922,64.31986,22476,23
130.84880,-6.44271,-60.65660,6.41665,60.65660,22476,23
130.92980,-6.35854,-57.76896,6.33248,57.76896,22412,23
131.02780,-6.25860,-54.47957,6.23254,54.47956,22412,23
131.13580,-6.14949,-51.09572,6.12343,51.09573,22412,23
131.24480,-6.03982,-47.70191,6.01376,47.70192,22412,23
131.34280,-5.94158,-44.53200,5.91552,44.53200,22412,23
131.43780,-5.84654,-41.66656,5.82048,41.66656,22412,23
131.52780,-5.75649,-38.99810,5.73043,38.99810,22412,23
131.60480,-5.67951,-36.75666,5.65345,36.75666,22412,23
131.69580,-5.58844,-34.05617,5.56238,34.05617,22412,23
131.81480,-5.46933,-30.58790,5.44327,30.58790,22412,23
131.88378,-5.40029,-28.59430,5.37423,28.59430,22412,23
132.02280,-5.26139,-25.47643,5.23533,25.47643,22412,23
132.15080,-5.13345,-22.83226,5.10739,22.83226,22412,23
132.36920,-4.91529,-18.91267,4.88923,18.91267,22412,23
132.55880,-4.72553,-15.91289,4.69947,15.91289,22412,23
132.80980,-4.47430,-12.27184,4.44824,12.27184,22412,23
133.05880,-4.22559,-8.76507,4.19953,8.76507,22412,23
133.20880,-4.14952,-8.25046,4.12346,8.25046,22412,23
133.33780,-4.29552,-12.12856,4.26946,12.12856,22412,23
133.46919,-4.43305,-15.18075,4.40699,15.18075,22476,23
133.61680,-4.58407,-18.55190,4.55801,18.55190,22476,23
133.76920,-4.73720,-22.04591,4.71114,22.04591,22476,23
133.90480,-4.87334,-25.33212,4.84728,25.33212,22476,24
134.02680,-4.99558,-28.21236,4.96952,28.21235,22476,24
134.11680,-5.08580,-30.55036,5.05974,30.55036,22476,24
134.24380,-5.21274,-33.84143,5.18668,33.84143,22476,24
134.35280,-5.32174,-36.52936,5.29567,36.52936,22476,24
134.46380,-5.43267,-39.39560,5.40661,39.39560,22476,24
134.53580,-5.50474,-41.25980,5.47868,41.25980,22476,24
134.62480,-5.59384,-43.56749,5.56778,43.56749,22476,24
134.74280,-5.71188,-46.55806,5.68581,46.55806,22476,24
134.86480,-5.83386,-49.50486,5.80780,49.50486,22476,24
135.02880,-5.99775,-53.52028,5.97169,53.52028,22476,24
135.13080,-6.09990,-55.98943,6.07384,55.98943,22476,24
135.23780,-6.20690,-58.48752,6.18084,58.48752,22476,24
135.34480,-6.31361,-61.02354,6.28755,61.02354,22476,24
135.50780,-6.47664,-64.95918,6.45058,64.95918,22476,24
135.59480,-6.56368,-67.02051,6.53762,67.02052,22476,24
135.73180,-6.67524,-69.44171,6.64918,69.44170,22476,24
135.82880,-6.56778,-65.15862,6.54172,65.15862,22476,24
135.92480,-6.46413,-61.39787,6.43807,61.39787,22476,24
136.05680,-6.32707,-56.75964,6.30101,56.75964,22412,24
136.18280,-6.19914,-52.53798,6.17308,52.53798,22412,24
136.29680,-6.08421,-48.94727,6.05815,48.94727,22412,24
136.40680,-5.97368,-45.54337,5.94762,45.54337,22412,24