File: data-raw/Experiment 2/Results/INSTRON data/Experiment 2.is_ccyclic_RawData/Specimen_RawData_13.csv
Text Inputs : Specimen label,"Long Plate 4 T1"

Time,Extension,Load,Compressive extension,Compressive load,Segment ID,Total Cycle Count
(sec),(mm),(N),(mm),(N),,
0.00000,-0.02614,0.03505,0.00000,-0.03505,12835,0
0.15180,-0.02614,-0.00178,0.00000,0.00178,12835,0
0.31680,-0.02614,-0.00578,0.00000,0.00578,12835,0
0.63380,-0.02614,0.04117,0.00000,-0.04117,12835,0
0.85680,-0.02614,0.07837,0.00000,-0.07837,12835,0
1.06180,-0.02614,0.03546,0.00000,-0.03546,3220,0
1.28680,-0.12574,0.03015,0.09960,-0.03015,3220,0
1.50880,-0.23870,0.00040,0.21256,-0.00040,3220,0
1.70980,-0.33962,0.00190,0.31348,-0.00190,3220,0
1.92980,-0.44980,0.04089,0.42366,-0.04089,3220,0
2.11080,-0.54019,0.05698,0.51405,-0.05698,3220,0
2.31780,-0.64369,0.01904,0.61755,-0.01904,3220,0
2.51780,-0.74365,0.01542,0.71751,-0.01542,3220,0
2.71580,-0.84265,0.00755,0.81651,-0.00755,3220,0
2.94580,-0.95780,-0.89291,0.93166,0.89291,3220,0
3.15980,-1.06475,-2.50999,1.03861,2.50999,3220,0
3.43880,-1.20415,-4.57314,1.17801,4.57314,3220,0
3.75880,-1.38245,-7.16274,1.35631,7.16274,3220,0
4.39580,-2.02627,-16.03805,2.00013,16.03805,22476,0
5.00880,-2.63932,-25.13133,2.61318,25.13133,22476,0
5.30480,-2.93524,-30.32593,2.90910,30.32593,22476,0
5.52380,-3.15425,-34.51914,3.12811,34.51914,22476,0
5.72380,-3.35433,-38.31995,3.32819,38.31995,22476,0
5.91480,-3.54532,-41.87708,3.51918,41.87708,22476,0
6.08180,-3.71228,-45.06233,3.68614,45.06233,22476,0
6.22780,-3.85820,-48.04791,3.83206,48.04791,22476,0
6.36080,-3.99144,-50.45255,3.96529,50.45255,22476,0
6.52180,-4.15226,-53.39621,4.12612,53.39621,22476,0
6.64380,-4.27415,-55.84369,4.24801,55.84369,22476,0
6.77380,-4.40430,-58.29161,4.37816,58.29161,22476,0
6.90780,-4.53825,-60.86235,4.51210,60.86235,22476,0
7.05380,-4.68426,-63.66839,4.65812,63.66839,22476,0
7.20380,-4.83418,-66.39956,4.80804,66.39956,22476,0
7.35880,-4.98945,-69.30396,4.96331,69.30396,22476,0
7.53180,-4.86733,-65.67624,4.84118,65.67624,22476,0
7.70080,-4.68962,-61.21239,4.66348,61.21239,22412,0
7.84580,-4.54190,-57.52867,4.51576,57.52868,22412,0
7.97580,-4.41097,-54.33253,4.38483,54.33253,22412,0
8.14480,-4.24141,-50.33460,4.21527,50.33460,22412,0
8.32980,-4.05641,-45.93704,4.03027,45.93704,22412,0
8.49680,-3.88913,-42.33861,3.86299,42.33861,22412,0
8.66780,-3.71830,-38.75358,3.69216,38.75358,22412,0
8.89080,-3.49531,-34.18766,3.46917,34.18766,22412,0
9.05380,-3.33225,-30.76459,3.30611,30.76459,22412,0
9.23980,-3.14627,-27.17613,3.12013,27.17613,22412,0
9.54280,-2.84321,-22.29085,2.81707,22.29085,22412,0
9.85680,-2.52924,-17.71905,2.50310,17.71905,22412,0
10.23980,-2.14615,-12.79009,2.12001,12.79009,22412,0
10.64080,-1.74515,-7.88328,1.71901,7.88328,22412,0
11.00380,-2.03236,-13.04969,2.00622,13.04969,22476,0
11.39680,-2.42903,-19.11172,2.40289,19.11172,22476,1
11.59480,-2.62743,-22.38445,2.60129,22.38445,22476,1
11.83780,-2.87034,-26.63671,2.84420,26.63671,22476,1
11.96380,-2.99643,-28.97811,2.97029,28.97811,22476,1
12.13680,-3.16937,-32.35099,3.14323,32.35099,22476,1
12.28080,-3.31334,-35.27525,3.28720,35.27525,22476,1
12.43180,-3.46450,-38.40138,3.43836,38.40138,22476,1
12.57880,-3.61153,-41.23554,3.58539,41.23553,22476,1
12.72680,-3.75938,-44.26811,3.73324,44.26810,22476,1
12.84180,-3.87437,-46.56381,3.84823,46.56381,22476,1
12.99080,-4.02354,-49.41943,3.99740,49.41943,22476,1
13.15780,-4.19034,-52.77685,4.16420,52.77685,22476,1
13.29080,-4.32339,-55.32483,4.29725,55.32483,22476,1
13.44880,-4.48139,-58.40467,4.45525,58.40467,22476,1
13.60880,-4.64151,-61.65886,4.61537,61.65886,22476,1
13.76980,-4.80224,-64.79919,4.77610,64.79919,22476,1
13.92880,-4.96159,-67.88176,4.93545,67.88175,22476,1
14.17220,-4.90749,-65.72968,4.88135,65.72968,22476,1
14.33380,-4.73689,-61.45781,4.71075,61.45781,22412,1
14.49280,-4.57515,-57.50713,4.54901,57.50713,22412,1
14.64080,-4.42609,-53.85538,4.39995,53.85538,22412,1
14.77080,-4.29567,-50.81943,4.26953,50.81943,22412,1
14.89280,-4.17358,-47.96905,4.14744,47.96905,22412,1
15.01880,-4.04759,-44.96425,4.02145,44.96425,22412,1
15.13980,-3.92648,-42.42732,3.90034,42.42731,22412,1
15.26680,-3.79935,-39.72120,3.77321,39.72120,22412,1
15.39180,-3.67451,-37.20930,3.64837,37.20930,22412,1
15.49880,-3.56759,-35.02172,3.54145,35.02172,22412,1
15.60680,-3.45955,-32.85259,3.43341,32.85258,22412,1
15.73480,-3.33146,-30.27648,3.30532,30.27648,22412,1
15.87080,-3.19544,-27.55038,3.16930,27.55038,22412,1
16.05480,-3.01148,-24.37541,2.98534,24.37541,22412,1
16.27220,-2.79434,-20.95737,2.76820,20.95737,22412,1
16.50680,-2.55956,-17.66246,2.53342,17.66246,22412,1
16.90680,-2.15935,-12.60874,2.13321,12.60874,22412,1
17.38980,-1.75267,-7.90218,1.72653,7.90218,22412,1
18.03480,-2.42521,-18.65438,2.39907,18.65438,22476,2
18.48480,-2.87561,-26.15401,2.84947,26.15401,22476,2
18.77220,-3.16264,-31.56474,3.13650,31.56474,22476,2
18.94480,-3.33558,-35.16133,3.30944,35.16133,22476,2
19.10580,-3.49668,-38.51666,3.47054,38.51666,22476,2
19.32680,-3.71766,-42.84085,3.69152,42.84085,22476,2
19.49580,-3.88657,-46.22131,3.86043,46.22131,22476,2
19.69080,-4.08178,-49.98927,4.05564,49.98927,22476,2
19.88280,-4.27354,-53.78895,4.24740,53.78895,22476,2
20.01980,-4.41065,-56.49408,4.38451,56.49408,22476,2
20.14980,-4.54065,-59.11798,4.51451,59.11798,22476,2
20.26580,-4.65670,-61.47009,4.63056,61.47009,22476,2
20.36780,-4.75858,-63.49412,4.73244,63.49412,22476,2
20.50880,-4.89970,-66.22159,4.87356,66.22160,22476,2
20.61980,-5.01080,-68.50572,4.98466,68.50572,22476,2
20.74880,-5.01727,-68.19879,4.99113,68.19878,22476,2
20.87980,-4.87195,-64.40432,4.84581,64.40433,22476,2
21.00280,-4.74370,-61.23479,4.71755,61.23479,22412,2
21.11380,-4.63067,-58.32066,4.60453,58.32066,22412,2
21.21980,-4.52352,-55.89220,4.49738,55.89220,22412,2
21.31780,-4.42515,-53.50287,4.39900,53.50287,22412,2
21.43280,-4.30986,-50.81930,4.28372,50.81930,22412,2
21.52380,-4.21872,-48.58040,4.19258,48.58040,22412,2
21.60780,-4.13468,-46.62885,4.10854,46.62885,22412,2
21.70680,-4.03568,-44.38376,4.00954,44.38376,22412,2
21.80480,-3.93765,-42.26682,3.91150,42.26682,22412,2
21.90580,-3.83656,-40.15072,3.81042,40.15072,22412,2
22.03980,-3.70264,-37.41597,3.67650,37.41597,22412,2
22.15680,-3.58571,-34.95943,3.55956,34.95943,22412,2
22.25680,-3.48567,-33.03780,3.45953,33.03780,22412,2
22.36080,-3.38153,-30.84081,3.35539,30.84081,22412,2
22.47280,-3.26945,-28.67208,3.24331,28.67208,22412,2
22.61080,-3.13164,-26.18045,3.10550,26.18045,22412,2
22.77080,-2.97161,-23.43979,2.94547,23.43979,22412,2
23.00780,-2.73456,-19.78729,2.70841,19.78729,22412,2
23.24380,-2.49859,-16.63083,2.47245,16.63083,22412,2
23.61480,-2.12755,-12.07788,2.10141,12.07788,22412,2
23.90280,-1.83950,-8.46682,1.81336,8.46682,22412,2
24.14180,-1.92465,-10.64246,1.89851,10.64246,22412,2
24.60880,-2.40298,-17.91574,2.37684,17.91574,22476,3
24.92780,-2.72251,-23.17966,2.69637,23.17966,22476,3
25.20080,-2.99561,-27.98072,2.96947,27.98072,22476,3
25.37220,-3.16650,-31.34517,3.14036,31.34517,22476,3
25.51380,-3.30850,-34.27970,3.28236,34.27971,22476,3
25.71080,-3.50565,-38.31148,3.47951,38.31148,22476,3
25.87220,-3.66662,-41.44011,3.64048,41.44011,22476,3
26.05180,-3.84650,-44.97094,3.82036,44.97094,22476,3
26.19080,-3.98575,-47.90376,3.95961,47.90376,22476,3
26.38580,-4.18054,-51.75363,4.15440,51.75363,22476,3
26.56780,-4.36265,-55.28332,4.33651,55.28332,22476,3
26.71780,-4.51257,-58.33576,4.48643,58.33576,22476,3
26.87980,-4.67462,-61.57179,4.64848,61.57179,22476,3
27.12880,-4.92366,-66.44843,4.89752,66.44843,22476,3
27.29680,-5.07937,-69.55691,5.05323,69.55691,22476,3
27.45880,-4.90880,-65.08862,4.88266,65.08862,22476,3
27.59980,-4.76087,-61.39211,4.73473,61.39211,22412,3
27.73680,-4.62149,-57.90091,4.59535,57.90091,22412,3
27.92480,-4.43219,-53.27183,4.40605,53.27183,22412,3
28.09480,-4.26171,-49.25319,4.23557,49.25319,22412,3
28.27220,-4.08482,-45.11855,4.05868,45.11855,22412,3
28.44080,-3.91557,-41.49568,3.88943,41.49568,22412,3
28.60080,-3.75559,-38.29043,3.72945,38.29042,22412,3
28.81080,-3.54567,-33.95502,3.51953,33.95502,22412,3
29.00880,-3.34764,-29.92207,3.32149,29.92207,22412,3
29.41080,-2.94565,-22.82413,2.91951,22.82413,22412,3
30.06980,-2.28641,-13.73902,2.26027,13.73902,22412,3
30.84480,-2.00291,-11.76445,1.97677,11.76445,22412,3
31.67220,-2.83662,-24.95557,2.81048,24.95556,22476,4
32.05080,-3.21570,-32.14744,3.18956,32.14745,22476,4
32.24480,-3.40969,-36.02545,3.38355,36.02544,22476,4
32.62480,-3.78963,-43.74153,3.76349,43.74153,22476,4
32.94480,-4.10984,-50.05608,4.08370,50.05608,22476,4
33.31380,-4.47869,-57.46598,4.45255,57.46598,22476,4
33.66280,-4.82763,-64.41332,4.80149,64.41332,22476,4
33.96680,-5.07489,-69.16099,5.04875,69.16099,22476,4
34.25880,-4.75755,-61.12350,4.73140,61.12350,22412,4
34.49980,-4.51349,-55.09323,4.48735,55.09323,22412,4
34.78180,-4.23084,-48.45648,4.20470,48.45648,22412,4
35.06180,-3.95079,-42.08467,3.92465,42.08467,22412,4
35.33780,-3.67477,-36.32066,3.64863,36.32066,22412,4
35.61280,-3.39967,-30.75997,3.37353,30.75997,22412,4
36.05780,-2.95474,-22.73295,2.92859,22.73295,22412,4
36.57220,-2.44072,-15.60290,2.41458,15.60290,22412,4
37.24080,-1.77635,-7.37713,1.75021,7.37713,22412,4
38.04980,-2.59470,-20.60965,2.56856,20.60965,22476,5
38.53080,-3.07583,-29.14302,3.04969,29.14302,22476,5
38.87680,-3.42179,-36.13396,3.39565,36.13396,22476,5
39.29480,-3.83965,-44.44163,3.81351,44.44162,22476,5
39.72280,-4.26764,-53.05275,4.24150,53.05275,22476,5
40.22080,-4.76567,-62.96716,4.73953,62.96716,22476,5
40.58280,-5.09735,-69.57565,5.07120,69.57565,22476,5
40.86280,-4.79427,-61.79417,4.76813,61.79417,22412,5
41.13580,-4.51750,-54.99827,4.49136,54.99827,22412,5
41.41180,-4.24084,-48.47579,4.21470,48.47579,22412,5
41.65680,-3.99588,-42.95224,3.96974,42.95224,22412,5
41.89880,-3.75374,-37.79803,3.72760,37.79803,22412,5
42.19280,-3.45985,-31.78616,3.43370,31.78616,22412,5
42.59980,-3.05283,-24.30763,3.02668,24.30763,22412,5
43.77280,-1.87969,-8.56788,1.85355,8.56787,22412,5
44.66680,-2.58171,-20.19323,2.55557,20.19323,22476,6
45.33780,-3.25273,-32.62638,3.22658,32.62638,22476,6
45.97080,-3.88574,-45.28972,3.85960,45.28972,22476,6
46.41080,-4.32581,-54.05447,4.29967,54.05447,22476,6
46.87680,-4.79168,-63.34864,4.76554,63.34864,22476,6
47.47280,-4.83961,-62.75038,4.81347,62.75039,22476,6
48.11080,-4.19594,-47.30107,4.16980,47.30107,22412,6
48.53980,-3.76677,-37.97782,3.74063,37.97782,22412,6
49.07220,-3.23474,-27.24445,3.20860,27.24445,22412,6
49.99680,-2.30966,-13.71113,2.28352,13.71113,22412,6
51.05180,-2.33377,-16.35292,2.30763,16.35292,22476,6
51.86680,-3.14993,-30.39540,3.12379,30.39540,22476,7
52.25280,-3.53597,-38.23349,3.50983,38.23349,22476,7
52.59680,-3.87985,-45.03270,3.85370,45.03270,22476,7
52.96880,-4.25185,-52.51122,4.22571,52.51122,22476,7
53.38080,-4.66392,-60.70064,4.63778,60.70065,22476,7
53.75180,-5.03504,-68.24318,5.00890,68.24319,22476,7
54.00780,-4.92536,-64.87125,4.89922,64.87125,22476,7
54.28980,-4.63454,-57.60086,4.60840,57.60086,22412,7
54.61980,-4.30304,-49.73500,4.27690,49.73500,22412,7
54.91880,-4.00396,-42.81396,3.97782,42.81396,22412,7
55.28080,-3.64190,-35.18051,3.61576,35.18050,22412,7
55.60580,-3.31682,-28.74341,3.29068,28.74341,22412,7
56.67220,-2.25074,-12.93976,2.22460,12.93976,22412,7
57.79180,-2.45458,-18.15455,2.42844,18.15455,22604,7
58.57280,-3.23590,-31.99546,3.20976,31.99546,22604,8
58.94980,-3.61307,-39.64165,3.58693,39.64165,22604,8
59.26280,-3.92592,-45.91775,3.89978,45.91775,22604,8
59.62280,-4.28585,-53.07465,4.25970,53.07465,22604,8
59.86880,-4.53195,-58.02276,4.50580,58.02276,22604,8
60.17220,-4.83489,-64.13363,4.80875,64.13363,22604,8
60.51380,-5.07246,-68.56433,5.04632,68.56432,22604,8
60.82680,-4.73689,-60.00354,4.71075,60.00354,22540,8
61.17220,-4.38930,-51.64077,4.36316,51.64077,22540,8
61.54180,-4.01903,-43.05919,3.99289,43.05919,22540,8
61.89880,-3.66197,-35.52052,3.63583,35.52052,22540,8
62.18280,-3.37790,-29.88586,3.35176,29.88586,22540,8
62.49280,-3.06805,-24.23788,3.04191,24.23788,22540,8
62.90580,-2.65496,-18.05283,2.62882,18.05283,22540,8
63.46280,-2.09805,-11.08803,2.07191,11.08803,22540,8
63.92180,-1.93810,-10.13184,1.91196,10.13184,22540,8
64.35580,-2.38423,-16.96891,2.35809,16.96891,22604,8
64.70980,-2.73887,-22.67905,2.71273,22.67905,22604,9
65.00380,-3.03304,-27.87115,3.00690,27.87115,22604,9
65.21380,-3.24292,-32.07128,3.21677,32.07128,22604,9
65.44880,-3.47809,-36.87009,3.45195,36.87009,22604,9
65.77220,-3.80093,-43.42873,3.77479,43.42873,22604,9
66.07680,-4.10617,-49.40846,4.08003,49.40846,22604,9
66.45180,-4.48099,-56.87461,4.45485,56.87461,22604,9
66.95880,-4.98816,-67.15919,4.96202,67.15919,22604,9
67.36480,-4.82955,-62.35263,4.80341,62.35263,22540,9
67.69680,-4.49265,-54.07263,4.46651,54.07262,22540,9
67.99080,-4.19819,-47.20028,4.17205,47.20028,22540,9
68.28480,-3.90397,-40.46464,3.87783,40.46464,22540,9
68.61080,-3.57818,-33.84683,3.55204,33.84683,22540,9
68.88280,-3.30598,-28.37799,3.27984,28.37799,22540,9
69.47220,-2.71707,-18.83931,2.69093,18.83931,22540,9
70.27220,-1.91713,-8.76932,1.89099,8.76932,22540,9
70.75080,-1.80821,-7.83223,1.78207,7.83223,22540,9
71.53280,-2.58037,-20.03554,2.55423,20.03554,22476,9
71.97220,-3.01941,-27.69656,2.99327,27.69657,22476,10
72.28180,-3.32935,-33.95146,3.30321,33.95146,22476,10
72.57220,-3.61954,-39.75091,3.59340,39.75091,22476,10
72.81880,-3.86633,-44.68451,3.84019,44.68451,22476,10
73.04480,-4.09255,-49.24544,4.06641,49.24544,22476,10
73.24380,-4.29130,-53.13813,4.26516,53.13813,22476,10
73.43480,-4.48238,-57.05029,4.45623,57.05029,22476,10
73.64480,-4.69237,-61.23796,4.66623,61.23796,22476,10
73.86580,-4.91341,-65.66496,4.88727,65.66496,22476,10
74.17680,-5.01761,-67.04285,4.99147,67.04285,22476,10
74.43480,-4.74541,-60.20922,4.71927,60.20922,22412,10
74.77480,-4.40270,-51.90566,4.37656,51.90566,22412,10
75.12480,-4.05247,-43.62398,4.02633,43.62398,22412,10
75.54380,-3.63340,-34.85765,3.60726,34.85765,22412,10
76.04180,-3.13538,-25.28363,3.10924,25.28363,22412,10
76.61380,-2.56346,-16.73976,2.53732,16.73976,22412,10
77.17220,-2.00551,-9.86153,1.97937,9.86153,22412,10
77.78080,-2.20974,-14.17532,2.18360,14.17532,22476,10
78.30480,-2.73620,-22.54749,2.71006,22.54749,22476,11
78.63080,-3.06233,-28.35692,3.03619,28.35692,22476,11
78.90680,-3.33822,-33.99076,3.31208,33.99076,22476,11
79.23180,-3.66334,-40.40719,3.63720,40.40719,22476,11
79.49280,-3.92429,-45.71873,3.89815,45.71873,22476,11
79.78180,-4.21327,-51.53652,4.18713,51.53652,22476,11
80.16080,-4.59238,-59.04314,4.56624,59.04314,22476,11
80.57980,-5.01143,-67.49216,4.98529,67.49216,22476,11
80.91180,-4.89934,-63.92461,4.87319,63.92461,22476,11
81.17220,-4.63276,-57.31149,4.60662,57.31149,22412,11
81.55380,-4.24932,-48.25503,4.22318,48.25503,22412,11
81.97580,-3.82719,-38.74396,3.80105,38.74396,22412,11
82.37220,-3.43128,-30.60640,3.40514,30.60640,22412,11
83.23680,-2.56637,-16.71260,2.54023,16.71260,22412,11
84.26880,-2.08247,-12.17519,2.05633,12.17519,22476,11
85.17780,-2.99730,-26.98867,2.97116,26.98867,22476,12
85.52880,-3.34824,-34.16697,3.32210,34.16697,22476,12
85.80380,-3.62337,-39.64612,3.59723,39.64611,22476,12
86.07480,-3.89423,-45.03729,3.86809,45.03729,22476,12
86.35080,-4.17026,-50.64449,4.14412,50.64449,22476,12
86.64480,-4.46425,-56.52324,4.43811,56.52324,22476,12
87.01380,-4.83320,-63.90425,4.80706,63.90425,22476,12
87.47180,-4.97563,-65.77948,4.94949,65.77949,22476,12
88.07180,-4.36353,-50.86309,4.33739,50.86309,22412,12
88.44980,-3.98535,-41.92446,3.95921,41.92446,22412,12
88.84580,-3.58936,-33.82491,3.56322,33.82491,22412,12
89.47680,-2.95826,-22.24179,2.93212,22.24179,22412,12
90.55680,-1.87819,-8.09788,1.85205,8.09788,22412,12
91.49380,-2.69910,-21.70931,2.67296,21.70931,22476,13
92.04480,-3.25003,-31.95283,3.22389,31.95283,22476,13
92.50980,-3.71521,-41.33244,3.68907,41.33244,22476,13
92.95780,-4.16322,-50.45071,4.13708,50.45071,22476,13
93.37880,-4.58425,-58.77787,4.55811,58.77787,22476,13
93.78980,-4.99536,-67.08626,4.96922,67.08626,22476,13
94.15080,-4.89374,-63.70490,4.86760,63.70490,22476,13
94.46880,-4.56916,-55.69218,4.54302,55.69218,22412,13
94.80980,-4.22724,-47.71766,4.20110,47.71766,22412,13
95.22680,-3.81003,-38.22983,3.78388,38.22983,22412,13
95.57180,-3.46522,-31.11582,3.43908,31.11582,22412,13
96.16880,-2.86805,-20.73975,2.84191,20.73975,22412,13
97.36180,-1.93031,-9.62551,1.90417,9.62551,22412,13
98.48580,-3.06916,-28.29749,3.04302,28.29749,22476,14
98.94480,-3.52820,-37.62921,3.50206,37.62921,22476,14
99.45080,-4.03427,-47.87280,4.00813,47.87280,22476,14
99.86980,-4.45316,-56.18927,4.42702,56.18927,22476,14
100.37220,-4.95527,-66.29530,4.92913,66.29530,22476,14
100.81480,-4.87014,-62.96421,4.84400,62.96421,22476,14
101.31680,-4.36228,-50.76068,4.33614,50.76068,22412,14
101.82980,-3.84896,-38.99734,3.82281,38.99734,22412,14
102.34080,-3.33801,-28.61442,3.31186,28.61442,22412,14
103.44080,-2.23796,-12.52409,2.21182,12.52409,22412,14
104.58080,-2.55188,-19.13719,2.52574,19.13719,22476,15
105.42080,-3.39211,-34.87939,3.36596,34.87939,22476,15
106.02580,-3.99728,-47.01894,3.97114,47.01894,22476,15
106.69280,-4.66409,-60.42421,4.63795,60.42421,22476,15
107.37220,-4.93626,-64.69955,4.91012,64.69955,22476,15
107.90880,-4.39023,-51.42965,4.36409,51.42965,22412,15
108.34680,-3.95206,-41.02483,3.92592,41.02483,22412,15
108.71780,-3.58108,-33.43914,3.55494,33.43914,22412,15
109.11680,-3.18197,-25.83822,3.15583,25.83822,22412,15
109.93280,-2.36581,-13.97954,2.33967,13.97954,22412,15
110.74580,-2.12367,-12.53318,2.09753,12.53318,22476,15
111.45580,-2.83901,-23.96839,2.81287,23.96839,22476,16
111.75880,-3.14211,-29.69065,3.11597,29.69065,22476,16
111.99580,-3.37912,-34.52638,3.35298,34.52638,22476,16
112.17220,-3.55520,-38.11805,3.52906,38.11805,22476,16
112.34980,-3.73314,-41.62468,3.70700,41.62468,22476,16
112.54180,-3.92512,-45.49529,3.89898,45.49529,22476,16
112.72580,-4.10927,-49.21424,4.08313,49.21424,22476,16
112.96780,-4.35119,-53.95984,4.32505,53.95984,22476,16
113.13980,-4.52309,-57.50547,4.49695,57.50547,22476,16
113.28880,-4.67209,-60.50696,4.64595,60.50696,22476,16
113.40680,-4.79005,-62.96300,4.76390,62.96300,22476,16
113.54580,-4.92921,-65.72824,4.90307,65.72824,22476,16
113.70980,-5.09328,-69.06503,5.06714,69.06503,22476,16
113.87580,-4.99558,-66.21622,4.96944,66.21622,22476,16
114.06980,-4.79091,-61.01179,4.76477,61.01179,22412,16
114.25380,-4.60439,-56.51012,4.57825,56.51012,22412,16
114.46180,-4.39537,-51.51765,4.36923,51.51765,22412,16
114.64180,-4.21520,-47.34537,4.18906,47.34537,22412,16
114.82380,-4.03315,-42.94322,4.00701,42.94323,22412,16
115.03880,-3.81799,-38.23954,3.79185,38.23954,22412,16
115.21280,-3.64412,-34.74741,3.61798,34.74741,22412,16
115.40280,-3.45413,-30.83913,3.42799,30.83913,22412,16
115.67220,-3.18506,-25.80688,3.15891,25.80688,22412,16
116.13380,-2.72306,-18.60432,2.69692,18.60432,22412,16
116.67220,-2.18504,-11.81762,2.15890,11.81762,22412,16
117.51380,-2.30339,-15.29337,2.27725,15.29338,22476,16
118.14080,-2.93200,-25.63664,2.90586,25.63664,22476,17
118.48280,-3.27389,-32.32664,3.24775,32.32664,22476,17
118.82380,-3.61518,-39.29534,3.58904,39.29534,22476,17
119.37080,-4.16206,-50.21903,4.13592,50.21902,22476,17
119.74180,-4.53303,-57.63488,4.50689,57.63488,22476,17
120.17780,-4.96922,-66.50054,4.94308,66.50053,22476,17
120.58080,-4.86653,-62.91054,4.84038,62.91054,22412,17
120.99180,-4.44937,-52.72911,4.42323,52.72911,22412,17
121.40180,-4.03897,-43.08476,4.01283,43.08476,22412,17
121.86180,-3.57902,-33.32232,3.55288,33.32232,22412,17
122.34480,-3.09601,-24.22330,3.06987,24.22330,22412,17
123.10280,-2.33778,-13.55122,2.31164,13.55122,22412,17
124.07220,-2.26893,-14.76579,2.24279,14.76579,22604,17
124.92680,-3.12584,-29.33246,3.09970,29.33246,22604,18
125.41980,-3.61902,-39.34170,3.59288,39.34170,22604,18
125.79480,-3.99409,-46.87181,3.96795,46.87181,22604,18
126.14780,-4.34693,-53.94516,4.32079,53.94516,22604,18
126.35880,-4.55786,-58.15104,4.53172,58.15104,22604,18
126.60480,-4.80374,-63.18562,4.77760,63.18562,22604,18
126.84580,-5.04500,-68.03257,5.01886,68.03257,22604,18
127.00280,-5.06196,-67.87720,5.03582,67.87720,22604,18
127.17220,-4.87768,-63.21507,4.85154,63.21507,22604,18
127.36080,-4.68380,-58.32753,4.65766,58.32753,22540,18
127.50280,-4.54055,-54.91249,4.51441,54.91249,22540,18
127.69880,-4.34406,-50.24926,4.31792,50.24926,22540,18
127.91880,-4.12388,-45.00487,4.09774,45.00487,22540,18
128.16080,-3.88166,-39.43136,3.85552,39.43136,22540,18
128.45680,-3.58594,-33.41658,3.55980,33.41658,22540,18
128.68680,-3.35578,-28.80955,3.32964,28.80955,22540,18
129.06279,-2.97984,-22.33199,2.95370,22.33199,22540,18
129.87220,-2.17071,-11.59606,2.14457,11.59606,22540,18
130.73580,-2.36985,-16.25235,2.34371,16.25235,22604,18
131.41180,-3.04696,-27.63678,3.02082,27.63678,22604,19
131.71880,-3.35402,-33.91963,3.32788,33.91963,22604,19
131.97680,-3.61209,-39.19196,3.58595,39.19196,22604,19
132.21080,-3.84590,-43.86473,3.81976,43.86473,22604,19
132.47380,-4.10913,-49.11428,4.08299,49.11428,22604,19
132.77080,-4.40603,-55.11471,4.37989,55.11471,22604,19
133.13080,-4.76590,-62.37823,4.73976,62.37823,22604,19
133.50380,-5.12658,-69.61431,5.10044,69.61431,22604,19
133.79880,-4.81643,-61.60976,4.79029,61.60976,22540,19
134.13880,-4.47239,-53.26243,4.44625,53.26244,22540,19
134.42180,-4.18899,-46.59247,4.16285,46.59247,22540,19
134.68080,-3.92989,-40.38578,3.90375,40.38578,22540,19
134.98380,-3.62696,-34.24947,3.60082,34.24947,22540,19
135.27480,-3.33588,-28.38918,3.30974,28.38918,22540,19
135.57280,-3.03793,-23.21930,3.01178,23.21930,22540,19
136.09680,-2.51393,-15.73952,2.48779,15.73952,22540,19
136.77220,-1.83951,-7.30786,1.81337,7.30786,22540,19
137.78980,-2.48706,-18.20513,2.46092,18.20513,22476,19
138.34480,-3.04221,-27.62667,3.01607,27.62667,22476,20
138.56180,-3.25903,-32.06144,3.23289,32.06144,22476,20
138.81180,-3.50925,-37.13465,3.48311,37.13465,22476,20
139.02180,-3.71921,-41.29713,3.69307,41.29713,22476,20
139.27780,-3.97532,-46.51586,3.94918,46.51586,22476,20
139.56180,-4.25908,-52.14784,4.23294,52.14784,22476,20
139.88180,-4.57916,-58.57543,4.55302,58.57543,22476,20
140.20780,-4.90514,-65.28443,4.87900,65.28443,22476,20
140.51680,-5.05028,-67.60880,5.02414,67.60880,22476,20
140.77880,-4.77137,-60.54601,4.74523,60.54601,22412,20
140.98180,-4.56601,-55.51177,4.53987,55.51177,22412,20
141.22080,-4.32623,-49.82764,4.30008,49.82764,22412,20
141.48480,-4.06218,-43.59324,4.03604,43.59324,22412,20
141.71280,-3.83399,-38.45619,3.80785,38.45619,22412,20
142.01480,-3.53206,-32.25278,3.50592,32.25278,22412,20
142.20280,-3.34402,-28.58468,3.31788,28.58468,22412,20
142.60080,-2.94604,-21.76150,2.91990,21.76150,22412,20
143.23980,-2.30687,-13.12491,2.28073,13.12491,22412,20
143.86880,-1.96260,-9.93100,1.93646,9.93100,22412,20
144.42480,-2.53186,-18.76768,2.50572,18.76768,22476,21
145.16880,-3.27595,-32.25642,3.24980,32.25642,22476,21
145.65580,-3.76311,-42.13536,3.73697,42.13536,22476,21
146.17480,-4.28202,-52.52459,4.25588,52.52459,22476,21
146.67220,-4.77896,-62.61317,4.75282,62.61317,22476,21
147.07219,-5.09902,-68.81390,5.07288,68.81390,22476,21
147.49480,-4.64957,-57.50148,4.62343,57.50148,22412,21
147.87680,-4.26606,-48.42206,4.23992,48.42207,22412,21
148.25878,-3.88390,-39.40210,3.85776,39.40210,22412,21
148.69880,-3.44406,-30.42056,3.41792,30.42056,22412,21
149.57219,-2.57113,-16.39033,2.54499,16.39033,22412,21
150.66178,-2.18143,-13.19521,2.15529,13.19521,22476,21
151.60280,-3.12612,-29.12403,3.09998,29.12403,22476,22
152.12480,-3.64826,-39.73588,3.62212,39.73588,22476,22
152.62078,-4.14425,-49.69735,4.11811,49.69735,22476,22
153.03580,-4.55917,-58.06907,4.53303,58.06907,22476,22
153.45480,-4.97828,-66.64298,4.95214,66.64298,22476,22
153.87480,-4.85402,-62.60958,4.82788,62.60958,22412,22
154.35180,-4.37141,-50.88890,4.34527,50.88890,22412,22
154.84278,-3.87999,-39.25518,3.85385,39.25518,22412,22
155.32080,-3.40208,-29.50233,3.37594,29.50233,22412,22
156.37219,-2.35098,-13.53031,2.32484,13.53031,22412,22
157.55180,-2.49293,-18.08543,2.46679,18.08543,22476,23
158.35380,-3.29506,-32.62724,3.26892,32.62724,22476,23
158.92480,-3.86619,-44.13949,3.84005,44.13948,22476,23
159.38680,-4.32817,-53.37780,4.30203,53.37780,22476,23
159.88480,-4.82608,-63.54819,4.79994,63.54819,22476,23
160.52280,-4.82220,-61.60404,4.79605,61.60404,22412,23
161.02680,-4.31416,-49.46602,4.28802,49.46602,22412,23
161.70380,-3.63703,-34.26760,3.61089,34.26760,22412,23
162.38080,-2.96003,-21.82246,2.93389,21.82246,22412,23
163.57219,-1.89562,-8.48222,1.86948,8.48222,22412,23
164.63378,-2.98118,-26.32124,2.95504,26.32124,22476,24
165.12480,-3.47224,-36.12097,3.44610,36.12097,22476,24
165.74280,-4.09029,-48.63140,4.06414,48.63140,22476,24
166.33380,-4.68110,-60.56510,4.65496,60.56510,22476,24
166.85680,-5.07321,-68.14016,5.04707,68.14016,22476,24
167.25480,-4.65360,-57.47545,4.62746,57.47545,22412,24
167.59480,-4.31218,-49.43857,4.28604,49.43857,22412,24
167.97480,-3.93205,-40.36538,3.90591,40.36538,22412,24
168.28080,-3.62610,-34.01387,3.59996,34.01387,22412,24
168.65580,-3.25093,-26.61515,3.22479,26.61515,22412,24
169.19180,-2.71508,-18.29048,2.68894,18.29048,22412,24
170.02680,-1.88001,-7.73995,1.85387,7.73995,22412,24
170.62580,-2.39829,-16.50849,2.37215,16.50849,22476,24
171.08580,-2.85914,-24.06409,2.83300,24.06409,22476,25
171.39480,-3.16805,-29.92893,3.14191,29.92893,22476,25
171.66080,-3.43425,-35.38955,3.40811,35.38955,22476,25
171.98680,-3.76022,-41.99895,3.73408,41.99895,22476,25
172.28980,-4.06335,-48.22009,4.03721,48.22009,22476,25
172.75380,-4.52715,-57.42467,4.50101,57.42467,22476,25
173.25480,-5.02828,-67.62569,5.00214,67.62569,22476,25
173.56680,-4.92101,-64.21784,4.89487,64.21784,22476,25
173.88480,-4.59527,-56.12015,4.56913,56.12015,22412,25
174.17220,-4.30721,-49.28255,4.28107,49.28255,22412,25
174.49880,-3.98016,-41.52740,3.95402,41.52740,22412,25
174.83380,-3.64511,-34.34539,3.61897,34.34539,22412,25
175.10380,-3.37504,-28.86184,3.34890,28.86184,22412,25
175.47180,-3.00708,-22.52053,2.98093,22.52053,22412,25
176.12480,-2.35396,-13.58628,2.32782,13.58628,22412,25
177.35480,-2.57012,-19.11687,2.54398,19.11687,22476,26
178.10180,-3.31717,-32.96263,3.29103,32.96263,22476,26
178.62280,-3.83820,-43.53864,3.81206,43.53864,22476,26
179.16980,-4.38537,-54.50820,4.35923,54.50820,22476,26
179.57380,-4.78911,-62.86588,4.76297,62.86588,22476,26
180.07219,-4.98001,-65.68278,4.95387,65.68278,22476,26
180.49080,-4.54901,-55.03350,4.52287,55.03350,22412,26
180.87480,-4.16431,-45.97160,4.13817,45.97160,22412,26
181.35980,-3.67929,-34.89646,3.65315,34.89646,22412,26
181.89180,-3.14720,-24.82561,3.12106,24.82561,22412,26
182.68180,-2.35713,-13.58279,2.33099,13.58279,22412,26
183.71580,-2.38631,-16.24226,2.36017,16.24226,22476,26
184.66980,-3.34135,-33.51862,3.31521,33.51862,22476,27
185.37980,-4.05153,-48.07503,4.02539,48.07503,22476,27
185.97220,-4.64333,-59.83409,4.61719,59.83408,22476,27
186.66480,-4.95029,-64.93497,4.92415,64.93497,22476,27
187.34278,-4.26229,-48.26608,4.23615,48.26608,22412,27
188.22480,-3.38024,-28.92390,3.35410,28.92389,22412,27
189.24480,-2.36016,-13.59611,2.33402,13.59611,22412,27
190.57080,-2.66037,-20.52092,2.63423,20.52092,22604,27
191.46880,-3.55857,-37.88305,3.53243,37.88305,22604,28
192.05080,-4.14059,-49.64566,4.11445,49.64566,22604,28
192.62280,-4.71238,-61.21536,4.68624,61.21535,22604,28
193.17080,-5.00960,-66.44037,4.98346,66.44038,22604,28
193.50080,-4.66612,-57.78045,4.63998,57.78045,22540,28
193.92380,-4.24148,-47.85544,4.21534,47.85545,22540,28
194.27780,-3.88730,-39.36993,3.86116,39.36993,22540,28
194.71280,-3.45244,-30.30284,3.42630,30.30284,22540,28
195.29180,-2.87331,-20.35221,2.84717,20.35221,22540,28
196.20280,-1.96264,-8.72406,1.93650,8.72406,22540,28
196.97680,-2.54227,-18.68565,2.51613,18.68565,22604,29
197.68580,-3.25151,-31.46885,3.22537,31.46885,22604,29
198.12480,-3.69069,-40.45859,3.66455,40.45859,22604,29
198.58580,-4.15165,-49.80714,4.12551,49.80714,22604,29
198.91378,-4.47958,-56.50264,4.45344,56.50264,22604,29
199.27220,-4.83753,-63.78675,4.81139,63.78674,22604,29
199.66480,-5.05172,-67.51937,5.02558,67.51937,22604,29
200.02880,-4.67017,-57.90018,4.64402,57.90018,22540,29
200.34478,-4.35272,-50.40056,4.32658,50.40056,22540,29
200.70380,-3.99359,-41.83677,3.96745,41.83677,22540,29
201.05980,-3.63751,-34.07983,3.61137,34.07983,22540,29
201.44780,-3.24934,-26.45092,3.22320,26.45092,22540,29
201.98278,-2.71449,-18.10716,2.68835,18.10716,22540,29
202.44980,-2.24741,-12.27532,2.22127,12.27532,22540,29
202.82480,-1.87244,-7.51163,1.84630,7.51163,22540,29
203.11880,-1.85322,-7.62401,1.82707,7.62401,22540,29
203.54180,-2.16551,-12.98429,2.13937,12.98429,22476,29
203.97220,-2.59802,-19.64907,2.57188,19.64907,22476,29
204.30178,-2.92794,-25.36768,2.90179,25.36768,22476,30
204.52578,-3.15201,-29.66133,3.12586,29.66133,22476,30
204.75980,-3.38601,-34.52405,3.35987,34.52405,22476,30
205.08080,-3.70703,-40.91752,3.68089,40.91752,22476,30
205.45380,-4.08013,-48.52242,4.05399,48.52242,22476,30
205.88378,-4.50993,-57.10449,4.48378,57.10450,22476,30
206.31980,-4.94603,-66.01983,4.91989,66.01983,22476,30
206.63280,-4.99963,-66.26391,4.97349,66.26392,22476,30
206.97280,-4.64636,-57.37536,4.62022,57.37536,22412,30
207.32180,-4.29588,-49.06224,4.26974,49.06224,22412,30
207.77220,-3.84577,-38.51267,3.81963,38.51266,22412,30
208.37680,-3.24072,-26.31432,3.21458,26.31432,22412,30
209.46480,-2.15277,-11.12671,2.12663,11.12671,22412,30
210.17480,-2.27851,-14.50486,2.25237,14.50486,22476,30
211.11780,-3.22394,-30.92021,3.19780,30.92021,22476,31
211.67220,-3.77791,-42.35419,3.75177,42.35419,22476,31
212.16580,-4.27184,-52.25000,4.24570,52.25000,22476,31
212.56678,-4.67284,-60.44966,4.64670,60.44966,22476,31
212.88578,-4.99207,-66.90669,4.96593,66.90669,22476,31
213.18480,-4.96903,-65.46143,4.94289,65.46143,22476,31
213.51280,-4.63016,-56.99334,4.60402,56.99334,22412,31
213.80880,-4.33299,-49.95350,4.30685,49.95350,22412,31
214.03580,-4.10592,-44.57648,4.07978,44.57648,22412,31
214.27220,-3.86969,-39.02344,3.84355,39.02344,22412,31
214.48080,-3.66081,-34.43429,3.63467,34.43428,22412,31
214.82480,-3.31671,-27.60592,3.29057,27.60592,22412,31
215.37219,-2.76965,-18.88560,2.74351,18.88560,22412,31
216.37219,-1.92495,-8.79213,1.89881,8.79213,22412,31
217.20080,-2.77472,-22.45311,2.74858,22.45311,22476,32
217.71880,-3.29271,-32.40108,3.26657,32.40108,22476,32
218.06980,-3.64396,-39.55939,3.61782,39.55939,22476,32
218.40078,-3.97506,-46.28288,3.94891,46.28288,22476,32
218.93380,-4.50785,-56.97257,4.48171,56.97258,22476,32
219.52280,-5.09690,-68.99995,5.07075,68.99995,22476,32
220.10180,-4.57672,-55.74335,4.55058,55.74335,22412,32
220.62380,-4.05376,-43.44240,4.02762,43.44240,22412,32
221.03180,-3.64568,-34.16283,3.61954,34.16283,22412,32
222.07219,-2.60576,-16.60987,2.57962,16.60987,22412,32
223.37219,-2.38475,-16.16985,2.35861,16.16985,22476,32
224.23080,-3.24474,-31.35465,3.21860,31.35465,22476,33
224.82680,-3.84072,-43.58977,3.81458,43.58977,22476,33
225.31580,-4.32982,-53.32896,4.30368,53.32896,22476,33
225.76680,-4.78063,-62.67162,4.75449,62.67162,22476,33
226.11680,-5.12896,-69.74449,5.10282,69.74449,22476,33
226.57219,-4.67544,-58.00179,4.64930,58.00179,22412,33
226.97220,-4.27372,-48.54871,4.24758,48.54871,22412,33
227.33080,-3.91460,-39.99462,3.88846,39.99463,22412,33
227.68880,-3.55675,-32.25337,3.53061,32.25336,22412,33
228.18180,-3.06379,-23.26043,3.03765,23.26043,22412,33
229.34880,-1.89661,-7.73004,1.87047,7.73004,22412,33
230.26880,-2.73872,-21.75615,2.71258,21.75615,22476,34
230.92580,-3.39584,-34.50497,3.36970,34.50497,22476,34
231.47280,-3.94290,-45.49104,3.91676,45.49104,22476,34
232.04280,-4.51279,-57.06316,4.48665,57.06316,22476,34
232.76880,-5.03003,-66.98667,5.00389,66.98666,22476,34
233.43280,-4.34899,-50.30115,4.32285,50.30116,22412,34
233.97380,-3.80761,-37.52968,3.78147,37.52968,22412,34
234.53480,-3.24663,-26.27511,3.22048,26.27511,22412,34
235.65680,-2.12477,-10.66877,2.09863,10.66877,22412,34
236.78780,-2.73383,-21.64502,2.70769,21.64502,22476,35
237.60680,-3.55300,-37.71382,3.52686,37.71382,22476,35
238.24180,-4.18797,-50.54352,4.16183,50.54352,22476,35
238.87219,-4.81781,-63.36883,4.79167,63.36883,22476,35
239.37478,-4.93899,-64.68754,4.91285,64.68755,22476,35
239.71480,-4.59004,-56.02097,4.56390,56.02097,22412,35
240.07880,-4.22500,-47.48525,4.19886,47.48525,22412,35
240.51880,-3.78475,-36.97986,3.75861,36.97986,22412,35
240.91680,-3.38682,-28.81226,3.36068,28.81226,22412,35
241.50080,-2.80274,-19.21877,2.77660,19.21877,22412,35
242.35180,-1.95208,-8.44159,1.92594,8.44159,22412,35
243.37278,-2.78682,-22.56927,2.76068,22.56927,22476,36
244.03780,-3.45214,-35.53186,3.42600,35.53186,22476,36
244.81280,-4.22703,-51.36583,4.20089,51.36583,22476,36
245.35778,-4.77178,-62.45033,4.74564,62.45033,22476,36
245.82680,-5.02802,-66.95018,5.00188,66.95018,22476,36
246.27219,-4.56686,-55.46135,4.54072,55.46135,22412,36
246.77880,-4.05902,-43.49902,4.03288,43.49902,22412,36
247.26380,-3.57400,-32.48802,3.54786,32.48802,22412,36
247.92678,-2.91077,-20.78907,2.88463,20.78907,22412,36
248.82780,-2.01004,-9.14403,1.98390,9.14403,22412,36
249.72178,-2.64387,-20.03252,2.61773,20.03252,22476,37
250.40180,-3.32394,-32.93589,3.29780,32.93589,22476,37
250.92380,-3.84599,-43.61384,3.81985,43.61384,22476,37
251.34478,-4.26693,-52.14820,4.24079,52.14820,22476,37
251.81580,-4.73791,-61.79432,4.71177,61.79432,22476,37
252.17480,-5.09711,-69.10087,5.07097,69.10087,22476,37
252.58980,-4.75075,-59.89989,4.72461,59.89989,22412,37
252.97220,-4.36618,-50.78050,4.34004,50.78050,22412,37
253.36480,-3.97303,-41.41270,3.94688,41.41270,22412,37
253.87580,-3.46202,-30.18880,3.43588,30.18880,22412,37
254.87219,-2.46600,-14.76256,2.43986,14.76256,22412,37
256.00281,-2.38792,-16.07188,2.36178,16.07188,22604,37
256.82181,-3.20796,-30.54293,3.18182,30.54293,22604,38
257.25980,-3.64613,-39.58765,3.61999,39.58765,22604,38
257.64481,-4.03121,-47.48187,4.00507,47.48187,22604,38
257.97580,-4.36213,-54.08061,4.33599,54.08060,22604,38
258.29380,-4.67988,-60.55292,4.65374,60.55293,22604,38
258.61078,-4.99714,-67.06230,4.97100,67.06229,22604,38
258.93978,-4.93158,-64.48632,4.90544,64.48633,22604,38
259.36380,-4.49840,-53.82818,4.47226,53.82818,22540,38
259.76780,-4.09402,-44.30311,4.06788,44.30311,22540,38
260.10278,-3.75881,-36.32956,3.73267,36.32956,22540,38
260.61178,-3.24973,-26.23274,3.22358,26.23274,22540,38
261.52478,-2.33678,-13.10869,2.31064,13.10870,22540,38
262.19378,-2.06244,-11.08209,2.03630,11.08209,22540,38
262.87178,-2.74986,-21.91431,2.72372,21.91431,22604,39
263.32378,-3.20191,-30.40480,3.17577,30.40480,22604,39
263.67219,-3.55001,-37.54533,3.52387,37.54533,22604,39
264.15178,-4.03018,-47.51786,4.00404,47.51786,22604,39
264.56281,-4.44103,-55.71638,4.41489,55.71638,22604,39
264.96978,-4.84795,-64.04402,4.82181,64.04402,22604,39
265.46381,-4.91034,-63.99621,4.88420,63.99621,22604,39
266.07222,-4.29386,-48.97688,4.26772,48.97688,22540,39
266.67219,-3.69382,-34.89261,3.66768,34.89262,22540,39
267.27219,-3.09388,-23.57946,3.06774,23.57946,22540,39
268.38478,-1.98099,-8.73490,1.95485,8.73490,22540,39
269.46781,-2.47684,-17.58879,2.45070,17.58879,22476,39
270.09978,-3.10911,-28.61287,3.08297,28.61287,22476,40
270.55678,-3.56604,-38.04578,3.53990,38.04578,22476,40
271.11978,-4.12914,-49.38696,4.10300,49.38696,22476,40
271.69278,-4.70185,-61.00544,4.67571,61.00544,22476,40
272.28878,-4.99060,-65.99079,4.96446,65.99079,22476,40
272.85081,-4.41613,-51.94666,4.38999,51.94666,22412,40
273.38181,-3.88465,-39.33129,3.85851,39.33129,22412,40
273.97219,-3.29466,-27.03308,3.26852,27.03308,22412,40
275.29481,-1.97200,-8.62065,1.94586,8.62065,22412,40
276.43078,-2.90183,-24.55323,2.87569,24.55323,22476,41
277.17481,-3.64602,-39.53207,3.61988,39.53207,22476,41
277.93281,-4.40394,-54.91105,4.37780,54.91106,22476,41
278.67578,-5.14324,-70.02324,5.11710,70.02324,22476,41
279.20778,-4.60588,-56.30101,4.57974,56.30101,22412,41
279.88278,-3.92972,-40.33951,3.90358,40.33951,22412,41
280.31778,-3.49481,-30.75782,3.46867,30.75782,22412,41
281.07222,-2.74069,-18.32944,2.71455,18.32944,22412,41
282.11381,-2.01667,-10.25231,1.99053,10.25231,22412,41
283.27278,-3.18775,-30.12270,3.16161,30.12270,22476,42
283.80381,-3.71890,-40.97479,3.69275,40.97479,22476,42
284.14678,-4.06199,-48.12514,4.03585,48.12514,22476,42
284.53078,-4.44587,-55.76914,4.41973,55.76914,22476,42
284.89078,-4.80562,-63.16007,4.77948,63.16007,22476,42
285.24078,-5.13992,-69.86891,5.11378,69.86891,22476,42
285.57181,-4.79002,-60.87542,4.76388,60.87542,22412,42
285.97581,-4.38284,-51.04158,4.35670,51.04158,22412,42
286.26678,-4.09177,-44.18426,4.06563,44.18427,22412,42
286.64578,-3.71266,-35.28424,3.68652,35.28424,22412,42
287.10378,-3.25446,-26.25775,3.22832,26.25775,22412,42
288.22981,-2.12860,-10.55118,2.10246,10.55118,22412,42
289.21281,-2.59359,-19.23434,2.56745,19.23434,22476,43
289.67978,-3.06079,-27.41437,3.03465,27.41437,22476,43
289.93681,-3.31764,-32.74728,3.29149,32.74728,22476,43
290.31078,-3.69179,-40.45103,3.66565,40.45103,22476,43
290.80678,-4.18774,-50.55207,4.16160,50.55207,22476,43
291.34181,-4.72262,-61.43093,4.69647,61.43093,22476,43
291.72681,-5.10782,-69.28055,5.08168,69.28055,22476,43
291.99078,-4.89291,-63.49867,4.86677,63.49867,22476,43
292.30578,-4.57160,-55.56165,4.54546,55.56165,22412,43
292.62978,-4.24665,-47.89390,4.22051,47.89391,22412,43
292.94278,-3.93362,-40.37846,3.90748,40.37846,22412,43
293.19778,-3.67864,-34.51999,3.65250,34.51999,22412,43
293.44581,-3.43062,-29.50056,3.40448,29.50056,22412,43
293.83078,-3.04565,-22.76471,3.01951,22.76472,22412,43
294.40478,-2.47167,-14.74087,2.44553,14.74087,22412,43
295.45481,-2.33182,-15.09639,2.30568,15.09639,22476,43
296.23481,-3.11376,-28.55934,3.08762,28.55934,22476,44
296.79178,-3.67077,-39.97548,3.64463,39.97548,22476,44
297.27219,-4.15082,-49.78330,4.12468,49.78330,22476,44
297.77478,-4.65370,-60.02396,4.62756,60.02396,22476,44
298.14278,-5.02188,-67.51852,4.99574,67.51852,22476,44
298.49281,-4.90312,-63.76373,4.87698,63.76373,22476,44
298.83078,-4.55839,-55.20685,4.53225,55.20686,22412,44
299.12781,-4.26057,-48.24820,4.23443,48.24820,22412,44
299.43381,-3.95464,-40.95967,3.92850,40.95967,22412,44
299.82081,-3.56766,-32.10951,3.54152,32.10950,22412,44
300.39978,-2.98858,-21.84435,2.96244,21.84435,22412,44
301.69878,-2.04690,-10.70204,2.02076,10.70204,22412,44
302.67219,-3.03070,-26.86037,3.00456,26.86037,22476,45
303.22181,-3.58073,-38.25244,3.55459,38.25244,22476,45
303.67978,-4.03882,-47.69750,4.01268,47.69750,22476,45
304.11078,-4.46965,-56.29343,4.44351,56.29343,22476,45
304.43878,-4.79744,-62.99101,4.77130,62.99101,22476,45
304.83478,-5.10268,-68.91168,5.07654,68.91168,22476,45
305.17081,-4.74212,-59.69606,4.71598,59.69606,22412,45
305.56378,-4.34675,-50.18452,4.32061,50.18452,22412,45
306.09878,-3.81141,-37.56429,3.78527,37.56429,22412,45
306.57222,-3.33850,-27.57029,3.31236,27.57029,22412,45
307.85181,-2.05864,-9.66698,2.03250,9.66698,22412,45
308.94778,-2.79647,-22.62177,2.77033,22.62177,22476,46
309.43381,-3.28253,-31.94847,3.25639,31.94847,22476,46
309.81681,-3.66572,-39.93121,3.63958,39.93121,22476,46
310.31778,-4.16666,-50.10465,4.14052,50.10465,22476,46
310.80781,-4.65652,-60.08625,4.63038,60.08625,22476,46
311.22478,-5.07378,-68.62999,5.04764,68.63000,22476,46
311.55978,-4.84807,-62.51128,4.82192,62.51128,22412,46
312.05881,-4.34369,-50.20029,4.31755,50.20029,22412,46
312.73678,-3.66547,-34.23151,3.63933,34.23151,22412,46
313.32481,-3.07757,-23.16722,3.05143,23.16722,22412,46
314.62978,-1.95798,-9.02906,1.93184,9.02906,22412,46
315.77219,-3.11864,-28.54502,3.09250,28.54502,22476,47
316.35678,-3.70359,-40.66521,3.67745,40.66521,22476,47
316.81281,-4.15957,-50.03929,4.13343,50.03929,22476,47
317.30178,-4.64849,-59.95510,4.62235,59.95510,22476,47
317.77219,-5.11858,-69.55866,5.09244,69.55865,22476,47
318.16878,-4.74817,-59.90366,4.72203,59.90366,22412,47
318.62878,-4.28546,-48.76764,4.25932,48.76765,22412,47
318.99678,-3.91737,-40.06230,3.89123,40.06230,22412,47
319.46978,-3.44449,-29.64311,3.41835,29.64311,22412,47
320.48178,-2.43242,-14.10729,2.40628,14.10729,22412,47
321.57222,-2.41746,-16.36072,2.39132,16.36072,22604,47
322.42881,-3.27541,-31.80069,3.24927,31.80069,22604,48
322.91778,-3.76458,-42.05880,3.73844,42.05880,22604,48
323.54378,-4.39061,-54.62337,4.36447,54.62337,22604,48
324.27219,-5.11853,-69.52181,5.09239,69.52181,22604,48
324.92178,-4.48896,-53.55771,4.46282,53.55770,22540,48
325.55878,-3.85136,-38.62799,3.82522,38.62799,22540,48
326.37219,-3.03846,-22.50351,3.01232,22.50351,22540,48
327.76278,-2.10165,-11.57221,2.07551,11.57221,22540,48
328.91081,-3.25734,-31.42216,3.23120,31.42216,22604,49
329.55978,-3.90655,-44.85719,3.88041,44.85719,22604,49
330.26378,-4.61068,-59.18175,4.58454,59.18176,22604,49
330.87378,-5.08082,-68.36464,5.05468,68.36463,22604,49
331.31778,-4.61561,-56.69870,4.58947,56.69870,22540,49
331.88181,-4.05052,-43.27542,4.02438,43.27542,22540,49
332.72181,-3.21037,-25.34175,3.18423,25.34175,22540,49
334.24078,-1.87458,-7.37695,1.84844,7.37695,22540,49
335.39481,-2.84871,-23.70289,2.82257,23.70289,22476,50
336.11478,-3.56882,-38.12486,3.54268,38.12486,22476,50
336.57222,-4.02598,-47.51510,3.99983,47.51510,22476,50
337.15078,-4.60484,-59.19028,4.57870,59.19028,22476,50
337.70978,-5.12997,-69.78205,5.10383,69.78205,22476,50
338.02678,-4.78797,-60.94183,4.76183,60.94183,22412,50
338.36078,-4.45094,-52.68382,4.42480,52.68382,22412,50
338.73481,-4.07669,-43.92340,4.05055,43.92340,22412,50
339.08978,-3.72158,-35.53557,3.69544,35.53557,22412,50
339.52781,-3.28340,-26.53974,3.25726,26.53974,22412,50
340.37219,-2.43953,-14.18431,2.41339,14.18431,22412,50
341.56078,-2.52825,-18.17951,2.50211,18.17951,22476,51
342.27219,-3.23945,-31.13718,3.21331,31.13718,22476,51
342.75478,-3.72274,-41.24445,3.69660,41.24445,22476,51
343.06378,-4.03186,-47.57514,4.00572,47.57514,22476,51
343.34778,-4.31563,-53.23026,4.28949,53.23026,22476,51
343.73578,-4.70349,-61.08119,4.67734,61.08119,22476,51
344.07481,-5.04268,-67.95854,5.01654,67.95854,22476,51
344.33881,-4.94945,-65.01976,4.92331,65.01976,22476,51
344.58781,-4.69153,-58.54466,4.66539,58.54466,22412,51
344.82678,-4.45088,-52.72209,4.42474,52.72209,22412,51
345.04278,-4.23453,-47.76923,4.20839,47.76923,22412,51
345.28078,-3.99654,-42.01913,3.97040,42.01913,22412,51
345.53281,-3.74448,-36.13517,3.71833,36.13517,22412,51
345.84681,-3.43048,-29.28779,3.40434,29.28779,22412,51
346.48578,-2.79127,-18.76994,2.76513,18.76994,22412,51
347.34478,-1.93252,-7.86552,1.90638,7.86552,22412,51
348.13878,-2.65825,-20.19218,2.63211,20.19218,22476,52
348.76881,-3.28825,-32.12354,3.26211,32.12354,22476,52
349.17219,-3.69151,-40.44269,3.66537,40.44270,22476,52
349.48578,-4.00573,-47.01223,3.97959,47.01223,22476,52
349.81378,-4.33350,-53.51384,4.30736,53.51384,22476,52
350.13181,-4.65145,-59.96668,4.62531,59.96667,22476,52
350.47878,-4.99854,-67.06207,4.97240,67.06207,22476,52
350.83381,-4.91365,-64.07662,4.88750,64.07661,22476,52
351.17481,-4.56526,-55.44915,4.53912,55.44915,22412,52
351.50078,-4.23837,-47.81479,4.21223,47.81479,22412,52
351.76678,-3.97241,-41.45297,3.94627,41.45297,22412,52
352.13181,-3.60744,-32.92103,3.58130,32.92103,22412,52
352.50478,-3.23421,-25.72990,3.20807,25.72990,22412,52
353.37478,-2.36419,-13.26843,2.33805,13.26843,22412,52
354.26578,-2.30693,-14.67169,2.28079,14.67169,22476,52
354.93578,-2.97946,-25.98370,2.95332,25.98370,22476,53
355.27219,-3.31524,-32.75131,3.28910,32.75131,22476,53
355.64481,-3.68845,-40.40181,3.66231,40.40181,22476,53
355.96178,-4.00564,-47.06973,3.97950,47.06973,22476,53
356.27219,-4.31538,-53.16218,4.28924,53.16218,22476,53
356.63478,-4.67829,-60.57892,4.65215,60.57891,22476,53
357.05678,-5.10049,-69.21824,5.07434,69.21824,22476,53
357.41581,-4.78694,-60.90930,4.76080,60.90931,22412,53
357.77278,-4.42660,-52.13711,4.40046,52.13711,22412,53
358.16181,-4.03731,-43.01431,4.01117,43.01431,22412,53
358.50878,-3.69027,-34.90226,3.66413,34.90226,22412,53
358.79578,-3.40319,-28.76133,3.37705,28.76133,22412,53
359.44078,-2.75812,-18.33544,2.73198,18.33545,22412,53
360.35278,-1.90714,-7.79727,1.88099,7.79727,22412,53
361.07222,-2.65518,-20.12716,2.62904,20.12716,22476,54
361.51178,-3.09544,-28.18311,3.06930,28.18311,22476,54
361.86881,-3.45242,-35.51504,3.42628,35.51504,22476,54
362.20178,-3.78533,-42.51228,3.75919,42.51228,22476,54
362.69981,-4.28327,-52.59588,4.25713,52.59588,22476,54
363.15778,-4.74117,-61.90568,4.71502,61.90568,22476,54
363.57378,-5.12001,-69.48375,5.09387,69.48375,22476,54
364.01778,-4.64868,-57.48365,4.62254,57.48365,22412,54
364.50378,-4.16119,-45.87157,4.13505,45.87157,22412,54
364.97181,-3.69317,-34.93553,3.66703,34.93553,22412,54
365.53978,-3.12518,-23.76718,3.09904,23.76718,22412,54
366.62778,-2.03724,-9.14684,2.01110,9.14684,22412,54
367.44078,-2.56381,-18.73208,2.53767,18.73208,22476,55
368.19981,-3.32301,-32.89752,3.29687,32.89753,22476,55
368.68681,-3.81011,-42.89994,3.78397,42.89994,22476,55
369.17219,-4.29512,-52.79604,4.26898,52.79604,22476,55
369.65878,-4.78195,-62.79952,4.75581,62.79952,22476,55
370.15178,-5.00951,-66.46259,4.98337,66.46259,22476,55
370.54178,-4.60619,-56.44468,4.58005,56.44468,22412,55
370.92381,-4.22307,-47.49548,4.19692,47.49548,22412,55
371.33878,-3.80787,-37.63686,3.78173,37.63686,22412,55
371.62078,-3.52602,-31.06705,3.49988,31.06705,22412,55
372.10581,-3.04103,-22.33724,3.01489,22.33724,22412,55
373.11478,-2.03208,-9.09887,2.00594,9.09887,22412,55
374.04081,-2.66187,-20.27100,2.63573,20.27100,22476,56
374.57222,-3.19306,-30.15155,3.16692,30.15155,22476,56
374.89178,-3.51311,-36.84861,3.48697,36.84861,22476,56
375.23481,-3.85603,-43.94811,3.82989,43.94811,22476,56
375.61881,-4.24004,-51.73768,4.21390,51.73768,22476,56
376.03181,-4.65297,-60.12180,4.62683,60.12180,22476,56
376.43378,-5.05521,-68.30621,5.02907,68.30621,22476,56
376.80278,-4.83509,-62.13856,4.80895,62.13857,22412,56
377.11578,-4.51756,-54.27605,4.49142,54.27605,22412,56
377.39881,-4.23405,-47.70556,4.20791,47.70556,22412,56
377.70378,-3.92896,-40.38611,3.90282,40.38611,22412,56
377.96478,-3.66802,-34.41504,3.64188,34.41504,22412,56
378.19778,-3.43501,-29.28034,3.40887,29.28034,22412,56
378.50478,-3.12801,-23.73423,3.10187,23.73423,22412,56
378.87478,-2.75788,-18.23655,2.73174,18.23655,22412,56
379.26778,-2.36483,-13.20947,2.33869,13.20947,22412,56
379.69478,-1.93809,-7.88200,1.91195,7.88200,22412,56
380.11078,-2.25477,-13.81742,2.22863,13.81742,22476,56
380.57222,-2.71894,-21.30860,2.69279,21.30860,22476,57
380.91181,-3.05913,-27.41919,3.03299,27.41920,22476,57
381.12281,-3.26987,-31.66213,3.24373,31.66212,22476,57
381.29981,-3.44715,-35.38830,3.42101,35.38830,22476,57
381.52078,-3.66814,-39.99245,3.64200,39.99245,22476,57
381.85278,-4.00031,-46.90011,3.97417,46.90011,22476,57
382.25581,-4.40309,-55.01209,4.37695,55.01209,22476,57
382.79881,-4.94621,-66.06308,4.92007,66.06309,22476,57
383.21281,-4.91600,-64.10480,4.88985,64.10480,22476,57
383.66778,-4.45319,-52.68755,4.42705,52.68755,22412,57
384.17278,-3.94784,-40.84205,3.92170,40.84205,22412,57
384.57222,-3.54883,-31.51776,3.52269,31.51776,22412,57
384.99478,-3.12582,-23.73042,3.09968,23.73042,22412,57
385.64178,-2.47883,-14.63772,2.45268,14.63772,22412,57
386.19478,-1.92583,-7.64622,1.89969,7.64622,22412,57
386.88478,-2.53749,-18.31351,2.51135,18.31351,22604,57
387.46681,-3.11994,-28.72011,3.09380,28.72011,22604,58
387.74281,-3.39587,-34.42635,3.36973,34.42635,22604,58
388.08478,-3.73792,-41.44180,3.71178,41.44180,22604,58
388.34578,-3.99913,-46.88023,3.97299,46.88023,22604,58
388.53181,-4.18488,-50.63774,4.15874,50.63774,22604,58
388.73578,-4.38892,-54.77482,4.36278,54.77482,22604,58
388.93578,-4.58890,-58.77378,4.56276,58.77378,22604,58
389.09181,-4.74471,-62.03851,4.71856,62.03851,22604,58
389.29678,-4.95003,-66.18223,4.92389,66.18223,22604,58
389.51578,-5.10180,-69.03930,5.07566,69.03930,22604,58
389.68781,-4.90926,-64.08688,4.88312,64.08688,22604,58
389.88178,-4.70904,-58.98989,4.68290,58.98989,22540,58
390.04981,-4.53946,-54.89701,4.51332,54.89701,22540,58
390.27381,-4.31487,-49.55675,4.28872,49.55676,22540,58
390.46878,-4.11982,-44.91403,4.09368,44.91403,22540,58
390.60878,-3.97983,-41.70790,3.95369,41.70790,22540,58
390.75678,-3.83163,-38.29546,3.80549,38.29546,22540,58
390.93781,-3.65075,-34.02380,3.62461,34.02380,22540,58
391.09478,-3.49382,-30.42728,3.46768,30.42728,22540,58
391.40378,-3.18470,-24.75562,3.15855,24.75562,22540,58
391.67678,-2.91160,-20.35364,2.88546,20.35364,22540,58
392.07222,-2.51673,-15.05318,2.49059,15.05318,22540,58
392.58478,-2.00385,-8.66415,1.97771,8.66415,22540,58
392.85981,-2.05488,-10.67251,2.02874,10.67251,22540,58
393.24078,-2.44689,-16.87316,2.42075,16.87316,22604,58
393.55781,-2.76465,-22.10639,2.73851,22.10639,22604,59
393.86881,-3.07589,-27.71118,3.04975,27.71118,22604,59
394.05878,-3.26559,-31.57762,3.23945,31.57762,22604,59
394.31878,-3.52585,-37.04431,3.49971,37.04431,22604,59
394.54178,-3.74886,-41.70654,3.72272,41.70654,22604,59
394.72778,-3.93487,-45.47770,3.90873,45.47770,22604,59
394.96878,-4.17581,-50.41848,4.14967,50.41848,22604,59
395.17578,-4.38286,-54.59215,4.35672,54.59215,22604,59
395.37219,-4.57885,-58.63175,4.55271,58.63175,22604,59
395.55678,-4.76360,-62.44357,4.73746,62.44357,22604,59
395.78478,-4.99198,-66.98352,4.96584,66.98352,22604,59
396.05178,-4.98890,-66.08649,4.96276,66.08649,22604,59
396.25778,-4.77206,-60.59078,4.74592,60.59078,22540,59
396.47278,-4.55442,-55.23279,4.52828,55.23279,22540,59
396.68078,-4.34578,-50.32616,4.31964,50.32616,22540,59
396.91181,-4.11465,-44.86243,4.08851,44.86243,22540,59
397.12281,-3.90341,-39.92161,3.87727,39.92161,22540,59
397.42078,-3.60565,-32.97717,3.57950,32.97717,22540,59
397.77978,-3.24642,-25.84029,3.22028,25.84029,22540,59
398.26881,-2.75742,-18.24792,2.73128,18.24792,22540,59
398.65578,-2.37039,-13.21477,2.34425,13.21477,22540,59
399.02178,-2.00468,-8.67636,1.97854,8.67636,22540,59
399.17381,-1.88945,-7.32000,1.86331,7.32000,22540,59