File: data-raw/Experiment 2/Results/INSTRON data/Experiment 2.is_ccyclic_RawData/Specimen_RawData_8.csv
Text Inputs : Specimen label,"Short Plate 1 T2"

Time,Extension,Load,Compressive extension,Compressive load,Segment ID,Total Cycle Count
(sec),(mm),(N),(mm),(N),,
0.00000,-0.02558,-0.05749,0.00000,0.05749,12835,0
2.06620,-0.47861,-0.10054,0.45303,0.10054,3220,0
2.93580,-0.91354,-6.19155,0.88796,6.19155,3220,0
3.42180,-1.35844,-13.50863,1.33286,13.50863,22476,0
3.97280,-1.91012,-21.14396,1.88454,21.14396,22476,0
4.45280,-2.39000,-29.44438,2.36442,29.44438,22476,0
4.86580,-2.80310,-37.80941,2.77752,37.80941,22476,0
5.23380,-3.17126,-45.41266,3.14568,45.41266,22476,0
5.59780,-3.53521,-53.01258,3.50963,53.01258,22476,0
6.00080,-3.93809,-61.36591,3.91251,61.36591,22476,0
6.39180,-4.32918,-69.42793,4.30360,69.42793,22476,0
6.63480,-4.13647,-61.61609,4.11089,61.61609,22476,0
6.91480,-3.84939,-52.37527,3.82381,52.37527,22412,0
7.18280,-3.58035,-44.18519,3.55477,44.18519,22412,0
7.48080,-3.28207,-36.20879,3.25649,36.20879,22412,0
7.81680,-2.94592,-28.17412,2.92033,28.17412,22412,0
8.23080,-2.53200,-20.43595,2.50642,20.43595,22412,0
8.76620,-1.99697,-12.65208,1.97139,12.65208,22412,0
9.21880,-1.65113,-8.69652,1.62555,8.69652,22412,0
9.63680,-2.09275,-17.51594,2.06717,17.51594,22476,0
10.05080,-2.50821,-25.91437,2.48263,25.91437,22476,1
10.41680,-2.87414,-34.36201,2.84855,34.36201,22476,1
10.75880,-3.21636,-42.36448,3.19077,42.36448,22476,1
11.08780,-3.54530,-49.93123,3.51972,49.93123,22476,1
11.46620,-3.92315,-58.52393,3.89757,58.52393,22476,1
11.85180,-4.30926,-67.30404,4.28368,67.30405,22476,1
12.08780,-4.31705,-65.49527,4.29147,65.49527,22476,1
12.35880,-4.03240,-55.94994,4.00682,55.94994,22412,1
12.65180,-3.73726,-46.89185,3.71168,46.89185,22412,1
12.96620,-3.42269,-38.01713,3.39711,38.01713,22412,1
13.32480,-3.06380,-29.35768,3.03821,29.35768,22412,1
13.76620,-2.62281,-20.90907,2.59723,20.90907,22412,1
14.30680,-2.08177,-12.88205,2.05619,12.88205,22412,1
14.76620,-1.69677,-8.10859,1.67119,8.10859,22412,1
15.17580,-2.13327,-17.08467,2.10769,17.08467,22476,1
15.58780,-2.54683,-25.45621,2.52125,25.45621,22476,2
15.96620,-2.92476,-34.24519,2.89918,34.24519,22476,2
16.32780,-3.28691,-42.72923,3.26133,42.72923,22476,2
16.69780,-3.65706,-51.39286,3.63148,51.39286,22476,2
17.07180,-4.03089,-59.98333,4.00531,59.98333,22476,2
17.45580,-4.41472,-68.88555,4.38914,68.88555,22476,2
17.70180,-4.27661,-62.74417,4.25103,62.74417,22476,2
17.97280,-3.99714,-53.59524,3.97156,53.59524,22412,2
18.26620,-3.70287,-44.65717,3.67729,44.65717,22412,2
18.59980,-3.36861,-35.62205,3.34303,35.62205,22412,2
18.97480,-2.99357,-27.04312,2.96799,27.04312,22412,2
19.46280,-2.50556,-18.49386,2.47998,18.49386,22412,2
19.99580,-1.97248,-10.94104,1.94690,10.94104,22412,2
20.39980,-1.84907,-10.96097,1.82349,10.96097,22412,2
20.83780,-2.29992,-19.53465,2.27434,19.53465,22476,2
21.23180,-2.69466,-27.81484,2.66908,27.81484,22476,3
21.58880,-3.05170,-36.36701,3.02612,36.36702,22476,3
21.96620,-3.42859,-45.27698,3.40301,45.27699,22476,3
22.33280,-3.79576,-53.88128,3.77018,53.88128,22476,3
22.69780,-4.16085,-62.41827,4.13527,62.41827,22476,3
23.05080,-4.48482,-69.66289,4.45924,69.66289,22476,3
23.28580,-4.22915,-60.36295,4.20357,60.36295,22476,3
23.56780,-3.94142,-51.24640,3.91584,51.24640,22412,3
23.86620,-3.64280,-42.28785,3.61722,42.28785,22412,3
24.22480,-3.28357,-33.02797,3.25799,33.02797,22412,3
24.62180,-2.88639,-24.54922,2.86081,24.54922,22412,3
25.11380,-2.39441,-16.42308,2.36883,16.42308,22412,3
25.66620,-1.84252,-8.66828,1.81694,8.66828,22412,3
26.05780,-2.00294,-13.42907,1.97736,13.42907,22476,3
26.46620,-2.41627,-21.43466,2.39069,21.43467,22476,4
26.86620,-2.81658,-30.18812,2.79100,30.18812,22476,4
27.22380,-3.17479,-38.86274,3.14921,38.86274,22476,4
27.57780,-3.52879,-47.29856,3.50321,47.29856,22476,4
27.96620,-3.91672,-56.20820,3.89114,56.20820,22476,4
28.33680,-4.28779,-64.88229,4.26221,64.88229,22476,4
28.63080,-4.43729,-67.09035,4.41171,67.09035,22476,4
28.86620,-4.18520,-58.31797,4.15962,58.31797,22412,4
29.15680,-3.89027,-49.16175,3.86469,49.16175,22412,4
29.42180,-3.62491,-41.30336,3.59933,41.30336,22412,4
29.76620,-3.28068,-32.49883,3.25510,32.49883,22412,4
30.14180,-2.90445,-24.50172,2.87887,24.50172,22412,4
30.63380,-2.41250,-16.37372,2.38692,16.37372,22412,4
31.16620,-1.88059,-8.91555,1.85501,8.91555,22412,4
31.55980,-2.02678,-13.48119,2.00120,13.48119,22412,4
31.96620,-2.43834,-21.48053,2.41275,21.48053,22476,5
32.36620,-2.83874,-30.29036,2.81316,30.29036,22476,5
32.71880,-3.19188,-38.85461,3.16630,38.85461,22476,5
33.07180,-3.54491,-47.26471,3.51933,47.26471,22476,5
33.46620,-3.93870,-56.39817,3.91312,56.39817,22476,5
33.82880,-4.30178,-64.90040,4.27620,64.90040,22476,5
34.12780,-4.45425,-67.16958,4.42867,67.16959,22476,5
34.38380,-4.18064,-57.74698,4.15506,57.74697,22412,5
34.67780,-3.88326,-48.57428,3.85768,48.57428,22412,5
34.97780,-3.58286,-39.69769,3.55728,39.69769,22412,5
35.34980,-3.21086,-30.54238,3.18528,30.54238,22412,5
35.76620,-2.79462,-22.27678,2.76904,22.27678,22412,5
36.27380,-2.28665,-14.34696,2.26107,14.34696,22412,5
36.78780,-1.77639,-7.20511,1.75081,7.20511,22412,5
37.16620,-2.15808,-15.68390,2.13250,15.68390,22476,5
37.57780,-2.57273,-23.89983,2.54715,23.89983,22476,6
37.95680,-2.95177,-32.66481,2.92619,32.66481,22476,6
38.32280,-3.31790,-41.39248,3.29232,41.39248,22476,6
38.67580,-3.67104,-49.79464,3.64546,49.79464,22476,6
39.03980,-4.03484,-58.27862,4.00926,58.27862,22476,6
39.38480,-4.37975,-66.39847,4.35417,66.39847,22476,6
39.66620,-4.41169,-65.22238,4.38611,65.22238,22476,6
39.93380,-4.13129,-55.81238,4.10571,55.81238,22412,6
40.22180,-3.84107,-46.95446,3.81549,46.95446,22412,6
40.53980,-3.52260,-37.81078,3.49702,37.81078,22412,6
40.89980,-3.16268,-29.15143,3.13710,29.15143,22412,6
41.34980,-2.71274,-20.54430,2.68716,20.54430,22412,6
41.87880,-2.18365,-12.75261,2.15806,12.75261,22412,6
42.34380,-1.83677,-8.75194,1.81119,8.75194,22412,6
42.75080,-2.26630,-17.46335,2.24072,17.46335,22476,6
43.15880,-2.67560,-25.94377,2.65002,25.94377,22476,7
43.51280,-3.02971,-34.31577,3.00413,34.31577,22476,7
43.86880,-3.38575,-42.82248,3.36017,42.82248,22476,7
44.25580,-3.77275,-51.93169,3.74717,51.93169,22476,7
44.61580,-4.13287,-60.35082,4.10729,60.35081,22476,7
44.97780,-4.49470,-68.96164,4.46912,68.96164,22476,7
45.21980,-4.34019,-62.44066,4.31461,62.44066,22476,7
45.49080,-4.06105,-53.27619,4.03547,53.27619,22412,7
45.79080,-3.75984,-44.18155,3.73426,44.18155,22412,7
46.12480,-3.42546,-35.08365,3.39988,35.08365,22412,7
46.50480,-3.04548,-26.49633,3.01990,26.49633,22412,7
46.96620,-2.58458,-18.42434,2.55900,18.42434,22412,7
47.52480,-2.02539,-10.42556,1.99981,10.42556,22412,7
47.92280,-1.95990,-11.44937,1.93432,11.44937,22412,7
48.35480,-2.40298,-19.92386,2.37740,19.92386,22604,7
48.74980,-2.79858,-28.41346,2.77300,28.41346,22604,8
49.09680,-3.14574,-36.79421,3.12016,36.79421,22604,8
49.46620,-3.51476,-45.58035,3.48918,45.58035,22604,8
49.83780,-3.88675,-54.34676,3.86117,54.34676,22604,8
50.20280,-4.25185,-62.95200,4.22627,62.95200,22604,8
50.53480,-4.53498,-69.28730,4.50940,69.28730,22604,8
50.76980,-4.27664,-59.91375,4.25106,59.91375,22604,8
51.06620,-3.97543,-50.43706,3.94985,50.43706,22540,8
51.36620,-3.67476,-41.37683,3.64918,41.37683,22540,8
51.71180,-3.32869,-32.54189,3.30311,32.54189,22540,8
52.11580,-2.92438,-23.94082,2.89880,23.94082,22540,8
52.61180,-2.42848,-15.88211,2.40290,15.88211,22540,8
53.16620,-1.87459,-8.09338,1.84901,8.09338,22540,8
53.53680,-2.10284,-13.97483,2.07726,13.97483,22604,8
53.96380,-2.53447,-22.47730,2.50889,22.47730,22604,9
54.34280,-2.91358,-30.93796,2.88800,30.93796,22604,9
54.68980,-3.26073,-39.40785,3.23514,39.40784,22604,9
55.06620,-3.63684,-48.41556,3.61126,48.41556,22604,9
55.42380,-3.99469,-56.75866,3.96911,56.75866,22604,9
55.78980,-4.36053,-65.41557,4.33495,65.41557,22604,9
56.08080,-4.46622,-66.31780,4.44064,66.31779,22604,9
56.34380,-4.18789,-56.86206,4.16231,56.86206,22540,9
56.64280,-3.88596,-47.62367,3.86038,47.62367,22540,9
56.94380,-3.58468,-38.72223,3.55910,38.72223,22540,9
57.29780,-3.23066,-30.07561,3.20508,30.07561,22540,9
57.73680,-2.79143,-21.45332,2.76585,21.45332,22540,9
58.26620,-2.26255,-13.38646,2.23697,13.38646,22540,9
58.86620,-1.80862,-7.62405,1.78304,7.62405,22540,9
59.38180,-2.10836,-14.47673,2.08278,14.47673,22476,9
59.82180,-2.55085,-23.05249,2.52527,23.05249,22476,9
60.19780,-2.92684,-31.43120,2.90126,31.43120,22476,10
60.56620,-3.29494,-40.22279,3.26936,40.22279,22476,10
60.93180,-3.66106,-48.96042,3.63548,48.96042,22476,10
61.29680,-4.02594,-57.45574,4.00036,57.45574,22476,10
61.66620,-4.39467,-66.09000,4.36909,66.09000,22476,10
61.94680,-4.44373,-65.49937,4.41815,65.49937,22476,10
62.19980,-4.17783,-56.46750,4.15225,56.46750,22412,10
62.49380,-3.88119,-47.35944,3.85561,47.35944,22412,10
62.80580,-3.56884,-38.23290,3.54326,38.23289,22412,10
63.16620,-3.20890,-29.48846,3.18332,29.48846,22412,10
63.60380,-2.77073,-21.00875,2.74515,21.00875,22412,10
64.15080,-2.22382,-12.82263,2.19824,12.82263,22412,10
64.61480,-1.84912,-8.22626,1.82354,8.22626,22412,10
65.01580,-2.27521,-17.04486,2.24963,17.04486,22476,10
65.41680,-2.67775,-25.30872,2.65216,25.30872,22476,11
65.77380,-3.03486,-33.64361,3.00928,33.64361,22476,11
66.15880,-3.41971,-42.89379,3.39413,42.89379,22476,11
66.51080,-3.77194,-51.23850,3.74636,51.23850,22476,11
66.87280,-4.13401,-59.75017,4.10843,59.75017,22476,11
67.25580,-4.51682,-68.87840,4.49124,68.87840,22476,11
67.49280,-4.37983,-62.85761,4.35425,62.85761,22476,11
67.76620,-4.09831,-53.54797,4.07273,53.54797,22412,11
68.06620,-3.79677,-44.47010,3.77119,44.47010,22412,11
68.38680,-3.47554,-35.54046,3.44996,35.54046,22412,11
68.72780,-3.13460,-27.58058,3.10902,27.58058,22412,11
69.18380,-2.67851,-19.32158,2.65293,19.32158,22412,11
69.73680,-2.12562,-11.38965,2.10004,11.38965,22412,11
70.15980,-1.94739,-10.44856,1.92181,10.44856,22412,11
70.56620,-2.36766,-18.68335,2.34208,18.68335,22476,11
70.96620,-2.76867,-27.03434,2.74309,27.03434,22476,12
71.33480,-3.13780,-35.89233,3.11222,35.89233,22476,12
71.68880,-3.49173,-44.38113,3.46615,44.38113,22476,12
72.06620,-3.86879,-53.34946,3.84321,53.34946,22476,12
72.42580,-4.22887,-61.81660,4.20329,61.81660,22476,12
72.76780,-4.56585,-69.86099,4.54027,69.86098,22476,12
73.00580,-4.32574,-60.87377,4.30016,60.87376,22476,12
73.28680,-4.03842,-51.69207,4.01284,51.69207,22412,12
73.57580,-3.74865,-42.91301,3.72307,42.91301,22412,12
73.92380,-3.40033,-33.59012,3.37475,33.59012,22412,12
74.31480,-3.00939,-25.01938,2.98381,25.01937,22412,12
74.80080,-2.52339,-16.85646,2.49780,16.85646,22412,12
75.35180,-1.97233,-9.06527,1.94675,9.06527,22412,12
75.73680,-2.08674,-13.09069,2.06116,13.09069,22412,12
76.15980,-2.51621,-21.47489,2.49063,21.47489,22476,12
76.53580,-2.89240,-29.83846,2.86682,29.83846,22476,13
76.88480,-3.24165,-38.34523,3.21607,38.34523,22476,13
77.26180,-3.61864,-47.47897,3.59306,47.47897,22476,13
77.62280,-3.97954,-55.85069,3.95396,55.85069,22476,13
77.98180,-4.33843,-64.31174,4.31285,64.31174,22476,13
78.29080,-4.51867,-67.46232,4.49309,67.46232,22476,13
78.55080,-4.23941,-57.74132,4.21383,57.74132,22412,13
78.83980,-3.94674,-48.67261,3.92116,48.67261,22412,13
79.14280,-3.64348,-39.62630,3.61790,39.62630,22412,13
79.47980,-3.30634,-31.10920,3.28076,31.10920,22412,13
79.91080,-2.87521,-22.45632,2.84963,22.45632,22412,13
80.42180,-2.36426,-14.42377,2.33868,14.42377,22412,13
80.96620,-1.86168,-7.65003,1.83610,7.65003,22412,13
81.35280,-2.27521,-16.62616,2.24963,16.62616,22476,13
81.75980,-2.68415,-24.94287,2.65857,24.94287,22476,14
82.12080,-3.04546,-33.41885,3.01988,33.41885,22476,14
82.47080,-3.39533,-41.83877,3.36975,41.83877,22476,14
82.84180,-3.76648,-50.70921,3.74090,50.70921,22476,14
83.20780,-4.13256,-59.32568,4.10698,59.32568,22476,14
83.56880,-4.49328,-67.86869,4.46770,67.86870,22476,14
83.82280,-4.40442,-63.24047,4.37884,63.24047,22476,14
84.08080,-4.13724,-54.38204,4.11166,54.38204,22412,14
84.38080,-3.83543,-45.15099,3.80985,45.15099,22412,14
84.69480,-3.52109,-36.16654,3.49551,36.16654,22412,14
85.06680,-3.14917,-27.45826,3.12359,27.45826,22412,14
85.53880,-2.67711,-19.04427,2.65153,19.04428,22412,14
86.07280,-2.14314,-11.32909,2.11756,11.32909,22412,14
86.49080,-1.96787,-10.43065,1.94229,10.43064,22412,14
86.90880,-2.40030,-18.93926,2.37472,18.93926,22476,14
87.30680,-2.79917,-27.32200,2.77359,27.32200,22476,15
87.66620,-3.15844,-36.01725,3.13286,36.01725,22476,15
88.03380,-3.52630,-44.82932,3.50072,44.82932,22476,15
88.38780,-3.88045,-53.21901,3.85487,53.21901,22476,15
88.72980,-4.22251,-61.31222,4.19693,61.31223,22476,15
89.06780,-4.56026,-69.41200,4.53468,69.41200,22476,15
89.32180,-4.35597,-61.37578,4.33039,61.37578,22476,15
89.59480,-4.07636,-52.29698,4.05078,52.29698,22412,15
89.89480,-3.77526,-43.28377,3.74968,43.28377,22412,15
90.22680,-3.44302,-34.18753,3.41744,34.18753,22412,15
90.60980,-3.06007,-25.72809,3.03449,25.72809,22412,15
91.09180,-2.57810,-17.34830,2.55252,17.34830,22412,15
91.64780,-2.02192,-9.49082,1.99634,9.49082,22412,15
92.03980,-2.07199,-12.55657,2.04641,12.55657,22412,15
92.46620,-2.50585,-20.95780,2.48027,20.95780,22476,16
92.84480,-2.88509,-29.27795,2.85951,29.27795,22476,16
93.19980,-3.24032,-37.95913,3.21474,37.95913,22476,16
93.56620,-3.60648,-46.83151,3.58090,46.83151,22476,16
93.93680,-3.97722,-55.47242,3.95164,55.47242,22476,16
94.29680,-4.33711,-63.98093,4.31153,63.98093,22476,16
94.61380,-4.54324,-67.89431,4.51766,67.89431,22476,16
94.86380,-4.27265,-58.38267,4.24707,58.38267,22412,16
95.15780,-3.97468,-49.04909,3.94910,49.04909,22412,16
95.45880,-3.67322,-40.05962,3.64764,40.05962,22412,16
95.78180,-3.35014,-31.75129,3.32456,31.75129,22412,16
96.20780,-2.92386,-23.00052,2.89828,23.00052,22412,16
96.71780,-2.41397,-14.90596,2.38839,14.90596,22412,16
97.24180,-1.89002,-7.45717,1.86443,7.45717,22412,16
97.60780,-2.21062,-15.03245,2.18504,15.03245,22476,16
98.02180,-2.62793,-23.43555,2.60235,23.43555,22476,17
98.38780,-2.99412,-31.75837,2.96853,31.75837,22476,17
98.76080,-3.36726,-40.80560,3.34167,40.80560,22476,17
99.12280,-3.72939,-49.53287,3.70381,49.53287,22476,17
99.48580,-4.09230,-58.05140,4.06672,58.05140,22476,17
99.85780,-4.46396,-66.87111,4.43838,66.87111,22476,17
100.11980,-4.47096,-65.09131,4.44538,65.09131,22476,17
100.36580,-4.21313,-56.39507,4.18755,56.39507,22412,17
100.65480,-3.92129,-47.42796,3.89571,47.42796,22412,17
100.95980,-3.61620,-38.35608,3.59062,38.35608,22412,17
101.31580,-3.26005,-29.59148,3.23447,29.59148,22412,17
101.70580,-2.86996,-21.98961,2.84438,21.98961,22412,17
102.22080,-2.35497,-13.94059,2.32939,13.94059,22412,17
102.73080,-1.86934,-7.28969,1.84376,7.28969,22412,17
103.09780,-2.25953,-15.88871,2.23395,15.88871,22604,17
103.51880,-2.68284,-24.50555,2.65725,24.50555,22604,17
103.87280,-3.03717,-32.73314,3.01159,32.73314,22604,18
104.24980,-3.41402,-41.91827,3.38844,41.91827,22604,18
104.60080,-3.76517,-50.30468,3.73959,50.30468,22604,18
104.96620,-4.13029,-58.92875,4.10471,58.92875,22604,18
105.34880,-4.51303,-67.98159,4.48745,67.98158,22604,18
105.59180,-4.44863,-64.17714,4.42305,64.17714,22604,18
105.86620,-4.16405,-54.65379,4.13847,54.65379,22540,18
106.16620,-3.86228,-45.40137,3.83670,45.40137,22540,18
106.44880,-3.57906,-37.21178,3.55348,37.21178,22540,18
106.80480,-3.22307,-28.72129,3.19749,28.72129,22540,18
107.21080,-2.81687,-20.93865,2.79129,20.93865,22540,18
107.75180,-2.27586,-12.83768,2.25028,12.83768,22540,18
108.19880,-1.90505,-8.15685,1.87947,8.15685,22540,18
108.59080,-2.32306,-17.00744,2.29748,17.00744,22604,18
108.99580,-2.72982,-25.43295,2.70424,25.43295,22604,19
109.36620,-3.10013,-34.33398,3.07455,34.33398,22604,19
109.72180,-3.45595,-42.84165,3.43037,42.84166,22604,19
110.08280,-3.81707,-51.43220,3.79148,51.43221,22604,19
110.46180,-4.19616,-60.33769,4.17058,60.33769,22604,19
110.81980,-4.55393,-68.86240,4.52835,68.86240,22604,19
111.04080,-4.42796,-63.29537,4.40238,63.29537,22604,19
111.30380,-4.15582,-54.30518,4.13024,54.30518,22540,19
111.59680,-3.86115,-45.31248,3.83557,45.31248,22540,19
111.91480,-3.54281,-36.16371,3.51723,36.16371,22540,19
112.27580,-3.18190,-27.60616,3.15632,27.60616,22540,19
112.75680,-2.70087,-19.00252,2.67529,19.00252,22540,19
113.27780,-2.17985,-11.47276,2.15427,11.47276,22540,19
113.97180,-1.88432,-8.35277,1.85874,8.35277,22540,19
114.37680,-2.29911,-17.00431,2.27353,17.00431,22476,19
114.78880,-2.71216,-25.44283,2.68657,25.44283,22476,20
115.16580,-3.08937,-34.30649,3.06379,34.30649,22476,20
115.52580,-3.44921,-42.86626,3.42363,42.86626,22476,20
115.88380,-3.80732,-51.40662,3.78174,51.40662,22476,20
116.26620,-4.18943,-60.26649,4.16385,60.26649,22476,20
116.62480,-4.54820,-68.83994,4.52262,68.83994,22476,20
116.86620,-4.40504,-62.61981,4.37946,62.61980,22476,20
117.14080,-4.12185,-53.28523,4.09627,53.28522,22412,20
117.44180,-3.81939,-44.16835,3.79381,44.16835,22412,20
117.76480,-3.49615,-35.01536,3.47057,35.01536,22412,20
118.13680,-3.12423,-26.53369,3.09865,26.53369,22412,20
118.59880,-2.66212,-18.38479,2.63654,18.38479,22412,20
119.15780,-2.10324,-10.40856,2.07766,10.40856,22412,20
119.54580,-2.03721,-11.42975,2.01163,11.42975,22412,20
119.96620,-2.46861,-19.79814,2.44303,19.79814,22476,20
120.35680,-2.86020,-28.32167,2.83462,28.32167,22476,21
120.70880,-3.21250,-36.90494,3.18692,36.90494,22476,21
121.06620,-3.56945,-45.47087,3.54387,45.47087,22476,21
121.44580,-3.94935,-54.47853,3.92377,54.47853,22476,21
121.79580,-4.29930,-62.77002,4.27372,62.77002,22476,21
122.14080,-4.59001,-69.19303,4.56443,69.19303,22476,21
122.37480,-4.33224,-59.89260,4.30666,59.89260,22412,21
122.66620,-4.03601,-50.49594,4.01043,50.49594,22412,21
122.96620,-3.73548,-41.39969,3.70989,41.39969,22412,21
123.29280,-3.40818,-32.70960,3.38260,32.70960,22412,21
123.70180,-2.99930,-23.93495,2.97372,23.93495,22412,21
124.19380,-2.50730,-15.91882,2.48172,15.91882,22412,21
124.74980,-1.95119,-8.05316,1.92561,8.05316,22412,21
125.11680,-2.17551,-14.02374,2.14993,14.02374,22476,21
125.53180,-2.59511,-22.40034,2.56953,22.40034,22476,22
125.90580,-2.96941,-30.85469,2.94383,30.85469,22476,22
126.26620,-3.32949,-39.69272,3.30391,39.69272,22476,22
126.63080,-3.69462,-48.46563,3.66904,48.46563,22476,22
126.98980,-4.05350,-56.88865,4.02792,56.88866,22476,22
127.33280,-4.39613,-64.96969,4.37055,64.96969,22476,22
127.62880,-4.53739,-66.97921,4.51181,66.97922,22476,22
127.88080,-4.26826,-57.65123,4.24268,57.65123,22412,22
128.16879,-3.97685,-48.56915,3.95127,48.56915,22412,22
128.46620,-3.67945,-39.69989,3.65387,39.69989,22412,22
128.81980,-3.32537,-30.56848,3.29979,30.56848,22412,22
129.25180,-2.89315,-21.97673,2.86757,21.97673,22412,22
129.76619,-2.37923,-14.01151,2.35365,14.01151,22412,22
130.26180,-1.89680,-7.28199,1.87122,7.28199,22412,22
130.62979,-2.28257,-15.97365,2.25699,15.97365,22476,22
131.03479,-2.69013,-24.28692,2.66455,24.28692,22476,23
131.40180,-3.05727,-32.91596,3.03169,32.91597,22476,23
131.76580,-3.42123,-41.73890,3.39565,41.73890,22476,23
132.12580,-3.78154,-50.34752,3.75595,50.34752,22476,23
132.48180,-4.13755,-58.73886,4.11197,58.73886,22476,23
132.86480,-4.52030,-67.80338,4.49472,67.80338,22476,23
133.10780,-4.45401,-63.89365,4.42843,63.89365,22476,23
133.36680,-4.18471,-54.94360,4.15913,54.94360,22412,23
133.66620,-3.88364,-45.65356,3.85806,45.65356,22412,23
133.96680,-3.58245,-36.84341,3.55687,36.84341,22412,23
134.35080,-3.19845,-27.63404,3.17287,27.63404,22412,23
134.80580,-2.74344,-19.36523,2.71786,19.36523,22412,23
135.35780,-2.19137,-11.42957,2.16579,11.42957,22412,23
135.76619,-1.99423,-10.12203,1.96865,10.12203,22412,23
136.16620,-2.41007,-18.47944,2.38449,18.47944,22476,23
136.56619,-2.81107,-26.96372,2.78549,26.96372,22476,24
136.93280,-3.17840,-35.86193,3.15282,35.86193,22476,24
137.29180,-3.53754,-44.55548,3.51196,44.55548,22476,24
137.66620,-3.91139,-53.35337,3.88581,53.35337,22476,24
138.02280,-4.26843,-61.83548,4.24285,61.83548,22476,24
138.37580,-4.61467,-70.06379,4.58909,70.06379,22476,24
138.61680,-4.36725,-60.75241,4.34166,60.75241,22476,24
138.89280,-4.08538,-51.70440,4.05980,51.70440,22412,24
139.19080,-3.78643,-42.68863,3.76085,42.68863,22412,24
139.51080,-3.46624,-33.82559,3.44066,33.82560,22412,24
139.91280,-3.06433,-24.94091,3.03874,24.94091,22412,24
140.38580,-2.59133,-16.93206,2.56575,16.93205,22412,24
140.95480,-2.02216,-8.92792,1.99658,8.92792,22412,24
141.32480,-2.13326,-12.99742,2.10768,12.99742,22412,24
141.73680,-2.55189,-21.35787,2.52631,21.35787,22476,25
142.11780,-2.93319,-29.91823,2.90761,29.91823,22476,25
142.46620,-3.28152,-38.41151,3.25594,38.41151,22476,25
142.83080,-3.64656,-47.23275,3.62098,47.23275,22476,25
143.19780,-4.01348,-55.81084,3.98790,55.81084,22476,25
143.56619,-4.38111,-64.44036,4.35553,64.44036,22476,25
143.88180,-4.55777,-67.38826,4.53219,67.38826,22476,25
144.14080,-4.28025,-57.73955,4.25467,57.73955,22412,25
144.42280,-3.99488,-48.81210,3.96930,48.81210,22412,25
144.73080,-3.68644,-39.58094,3.66086,39.58094,22412,25
145.06619,-3.35136,-30.85447,3.32578,30.85448,22412,25
145.48080,-2.93617,-22.45121,2.91059,22.45121,22412,25
146.00380,-2.41323,-14.30408,2.38765,14.30408,22412,25
146.52080,-1.90314,-7.14676,1.87756,7.14676,22412,25
146.87380,-2.26619,-15.50344,2.24061,15.50344,22476,25
147.28678,-2.68216,-24.01227,2.65658,24.01227,22476,26
147.66580,-3.06141,-33.00071,3.03583,33.00071,22476,26
148.01580,-3.41141,-41.41563,3.38583,41.41563,22476,26
148.36980,-3.76553,-49.86227,3.73995,49.86227,22476,26
148.75980,-4.15554,-58.99468,4.12996,58.99468,22476,26
149.11080,-4.50633,-67.29370,4.48075,67.29370,22476,26
149.36620,-4.47293,-64.29160,4.44735,64.29160,22476,26
149.63880,-4.18868,-54.78610,4.16310,54.78610,22412,26
149.92680,-3.89863,-45.85034,3.87305,45.85035,22412,26
150.23680,-3.58848,-36.75655,3.56290,36.75655,22412,26
150.59180,-3.23347,-28.09531,3.20789,28.09531,22412,26
151.06180,-2.76337,-19.43055,2.73779,19.43055,22412,26
151.58180,-2.24344,-11.98514,2.21786,11.98514,22412,26
152.01780,-1.99915,-9.86924,1.97357,9.86924,22412,26
152.42280,-2.42113,-18.54608,2.39555,18.54608,22476,26
152.82080,-2.82022,-26.97194,2.79464,26.97194,22476,27
153.16980,-3.16947,-35.40286,3.14389,35.40286,22476,27
153.53980,-3.53960,-44.36615,3.51402,44.36615,22476,27
153.90180,-3.90142,-52.96770,3.87584,52.96770,22476,27
154.26619,-4.26547,-61.56459,4.23988,61.56459,22476,27
154.61780,-4.61398,-69.91192,4.58840,69.91192,22476,27
154.85780,-4.37465,-60.78233,4.34907,60.78233,22412,27
155.13378,-4.09259,-51.73390,4.06701,51.73390,22412,27
155.42880,-3.79656,-42.80532,3.77098,42.80532,22412,27
155.75780,-3.46738,-33.57647,3.44180,33.57647,22412,27
156.14280,-3.08247,-25.09738,3.05689,25.09738,22412,27
156.63280,-2.59242,-16.88933,2.56684,16.88933,22412,27
157.16620,-2.05944,-9.29685,2.03386,9.29685,22412,27
157.54380,-2.13983,-12.96724,2.11425,12.96724,22412,27
157.96620,-2.56908,-21.47646,2.54350,21.47647,22604,27
158.34180,-2.94532,-29.89092,2.91973,29.89092,22604,28
158.68880,-3.29253,-38.41624,3.26695,38.41624,22604,28
159.05480,-3.65861,-47.31698,3.63303,47.31697,22604,28
159.42180,-4.02561,-55.91994,4.00003,55.91994,22604,28
159.78080,-4.38428,-64.33858,4.35869,64.33858,22604,28
160.08880,-4.56624,-67.51487,4.54066,67.51487,22604,28
160.34780,-4.28754,-57.85498,4.26196,57.85498,22540,28
160.63580,-3.99603,-48.68784,3.97044,48.68784,22540,28
160.92980,-3.70159,-39.86119,3.67601,39.86119,22540,28
161.26619,-3.36546,-30.98950,3.33987,30.98950,22540,28
161.68680,-2.94436,-22.51976,2.91878,22.51976,22540,28
162.19680,-2.43440,-14.52428,2.40882,14.52428,22540,28
162.72580,-1.91222,-7.13801,1.88664,7.13801,22540,28
163.07580,-2.27222,-15.49463,2.24664,15.49463,22604,28
163.48780,-2.68724,-23.95597,2.66166,23.95597,22604,29
163.86620,-3.06552,-32.74925,3.03994,32.74925,22604,29
164.22180,-3.42140,-41.39303,3.39582,41.39303,22604,29
164.57280,-3.77263,-49.83614,3.74705,49.83614,22604,29
164.95780,-4.15765,-58.88579,4.13207,58.88580,22604,29
165.31880,-4.51851,-67.40187,4.49293,67.40187,22604,29
165.56680,-4.48439,-64.45525,4.45880,64.45525,22604,29
165.84480,-4.19482,-54.79379,4.16924,54.79379,22540,29
166.13680,-3.90076,-45.69678,3.87518,45.69678,22540,29
166.44280,-3.59466,-36.70849,3.56907,36.70848,22540,29
166.78678,-3.25060,-28.31305,3.22502,28.31305,22540,29
167.26619,-2.77151,-19.48209,2.74593,19.48210,22540,29
167.78880,-2.24861,-11.93300,2.22303,11.93300,22540,29
168.49980,-1.91886,-8.27627,1.89328,8.27627,22540,29
168.89580,-2.30055,-16.49396,2.27497,16.49396,22476,29
169.30880,-2.71496,-24.92074,2.68938,24.92074,22476,29
169.66880,-3.07506,-33.33169,3.04948,33.33169,22476,30
170.04480,-3.45095,-42.35395,3.42537,42.35395,22476,30
170.40080,-3.80714,-50.85667,3.78156,50.85667,22476,30
170.76680,-4.17316,-59.36907,4.14758,59.36907,22476,30
171.14580,-4.55203,-68.37586,4.52645,68.37585,22476,30
171.38780,-4.44718,-63.27634,4.42160,63.27634,22476,30
171.66480,-4.16079,-53.79051,4.13521,53.79051,22412,30
171.91580,-3.90820,-46.02930,3.88262,46.02930,22412,30
172.22280,-3.60111,-36.98283,3.57553,36.98283,22412,30
172.58180,-3.24208,-28.19069,3.21650,28.19069,22412,30
173.06280,-2.76101,-19.37561,2.73543,19.37561,22412,30
173.57780,-2.24607,-11.92038,2.22049,11.92038,22412,30
174.01180,-2.00369,-9.80766,1.97811,9.80766,22412,30
174.42080,-2.42978,-18.60201,2.40420,18.60201,22476,30
174.81680,-2.82685,-27.00900,2.80127,27.00900,22476,31
175.16620,-3.17602,-35.43253,3.15044,35.43253,22476,31
175.53180,-3.54206,-44.28545,3.51648,44.28545,22476,31
175.89580,-3.90604,-52.93963,3.88046,52.93963,22476,31
176.26619,-4.27605,-61.66940,4.25047,61.66940,22476,31
176.62580,-4.62934,-70.07267,4.60376,70.07266,22476,31
176.86080,-4.38815,-60.98117,4.36257,60.98117,22412,31
177.14180,-4.10110,-51.77729,4.07552,51.77729,22412,31
177.43580,-3.80608,-42.80374,3.78049,42.80374,22412,31
177.76480,-3.47688,-33.61886,3.45130,33.61886,22412,31
178.14980,-3.09203,-25.06714,3.06645,25.06714,22412,31
178.63780,-2.60397,-16.84283,2.57839,16.84283,22412,31
179.16620,-2.07613,-9.36060,2.05055,9.36060,22412,31
179.55080,-2.14926,-12.94790,2.12368,12.94790,22412,31
179.96620,-2.57149,-21.42520,2.54591,21.42520,22476,32
180.33680,-2.94276,-29.72294,2.91718,29.72294,22476,32
180.68580,-3.29199,-38.22915,3.26641,38.22915,22476,32
181.05580,-3.66207,-47.22622,3.63649,47.22622,22476,32
181.42880,-4.03498,-55.91398,4.00940,55.91398,22476,32
181.78280,-4.38870,-64.26056,4.36312,64.26056,22476,32
182.08680,-4.57775,-67.73970,4.55217,67.73970,22476,32
182.34980,-4.29393,-57.79926,4.26835,57.79926,22412,32
182.63880,-4.00138,-48.64375,3.97580,48.64375,22412,32
182.93780,-3.70200,-39.64964,3.67642,39.64964,22412,32
183.26619,-3.37382,-30.97697,3.34824,30.97697,22412,32
183.68780,-2.95179,-22.48534,2.92621,22.48534,22412,32
184.19780,-2.44179,-14.46291,2.41621,14.46291,22412,32
184.73380,-1.91711,-7.05855,1.89153,7.05855,22412,32
185.07880,-2.27755,-15.46378,2.25197,15.46378,22476,32
185.49080,-2.69267,-23.93440,2.66709,23.93440,22476,33
185.86620,-3.06790,-32.75194,3.04232,32.75194,22476,33
186.22380,-3.42574,-41.32975,3.40016,41.32975,22476,33
186.57780,-3.77990,-49.80035,3.75432,49.80035,22476,33
186.96180,-4.16406,-58.85679,4.13848,58.85679,22476,33
187.32080,-4.52282,-67.42493,4.49724,67.42493,22476,33
187.57680,-4.49459,-64.56736,4.46901,64.56736,22476,33
187.85680,-4.20311,-54.80014,4.17753,54.80014,22412,33
188.15080,-3.90705,-45.63149,3.88147,45.63149,22412,33
188.45780,-3.59998,-36.66441,3.57440,36.66441,22412,33
188.81180,-3.24592,-28.08786,3.22034,28.08786,22412,33
189.26619,-2.79179,-19.65129,2.76621,19.65129,22412,33
189.80178,-2.25587,-11.84876,2.23029,11.84876,22412,33
190.21880,-2.01964,-9.76528,1.99406,9.76528,22412,33
190.61280,-2.43122,-18.45269,2.40564,18.45269,22476,33
191.01680,-2.83644,-27.04170,2.81086,27.04170,22476,34
191.36620,-3.18573,-35.49190,3.16015,35.49190,22476,34
191.73580,-3.55585,-44.43542,3.53027,44.43542,22476,34
192.09180,-3.91175,-52.85244,3.88617,52.85244,22476,34
192.46620,-4.28565,-61.69368,4.26007,61.69368,22476,34
192.81980,-4.63293,-69.99296,4.60735,69.99296,22476,34
193.05280,-4.39378,-60.96936,4.36820,60.96936,22476,34
193.33480,-4.10567,-51.69356,4.08009,51.69356,22412,34
193.62480,-3.81466,-42.87366,3.78908,42.87366,22412,34
193.91178,-3.52747,-34.68835,3.50189,34.68835,22412,34
194.28980,-3.14957,-26.08925,3.12399,26.08925,22412,34
194.76619,-2.67351,-17.78770,2.64793,17.78770,22412,34
195.31678,-2.12275,-9.90742,2.09717,9.90742,22412,34
195.68680,-2.10130,-11.80197,2.07572,11.80198,22412,34
196.10580,-2.53079,-20.37892,2.50521,20.37893,22476,34
196.49080,-2.91615,-28.97548,2.89057,28.97548,22476,35
196.85580,-3.28147,-37.84168,3.25589,37.84168,22476,35
197.20880,-3.63450,-46.30084,3.60892,46.30083,22476,35
197.56880,-3.99438,-54.79039,3.96880,54.79039,22476,35
197.95280,-4.37809,-63.84938,4.35251,63.84938,22476,35
198.26380,-4.59649,-68.20919,4.57091,68.20918,22476,35
198.50280,-4.33540,-58.92195,4.30982,58.92195,22412,35
198.78380,-4.04993,-49.88131,4.02435,49.88131,22412,35
199.06619,-3.76741,-41.44683,3.74183,41.44683,22412,35
199.37278,-3.46023,-32.91152,3.43465,32.91152,22412,35
199.78580,-3.04726,-24.04231,3.02168,24.04231,22412,35
200.27980,-2.55328,-15.89591,2.52770,15.89591,22412,35
200.84278,-1.99034,-7.92693,1.96476,7.92693,22412,35
201.17880,-2.21685,-14.04455,2.19127,14.04455,22476,35
201.58680,-2.62993,-22.47143,2.60435,22.47143,22476,36
201.96620,-3.00926,-31.14995,2.98368,31.14995,22476,36
202.32280,-3.36634,-39.81963,3.34076,39.81963,22476,36
202.67580,-3.71939,-48.33334,3.69381,48.33334,22476,36
203.06380,-4.10744,-57.38503,4.08186,57.38503,22476,36
203.41980,-4.46321,-65.81087,4.43763,65.81087,22476,36
203.69280,-4.53827,-65.99368,4.51269,65.99368,22476,36
203.96180,-4.25439,-56.29819,4.22881,56.29818,22412,36
204.25080,-3.96263,-47.37590,3.93705,47.37590,22412,36
204.55480,-3.65836,-38.19093,3.63278,38.19093,22412,36
204.88680,-3.32631,-29.66022,3.30073,29.66022,22412,36
205.33080,-2.88212,-21.05712,2.85654,21.05712,22412,36
205.86620,-2.34722,-12.94095,2.32164,12.94095,22412,36
206.32978,-1.95654,-8.00355,1.93096,8.00355,22412,36
206.71080,-2.36412,-17.00197,2.33854,17.00197,22476,36
207.10980,-2.76508,-25.43103,2.73950,25.43103,22476,37
207.42878,-3.08421,-33.09161,3.05863,33.09161,22476,37
207.73380,-3.38918,-40.31598,3.36360,40.31598,22476,37
208.02480,-3.68031,-47.46412,3.65473,47.46412,22476,37
208.38880,-4.04422,-55.88515,4.01864,55.88515,22476,37
208.72380,-4.37896,-63.82508,4.35338,63.82508,22476,37
209.03080,-4.60222,-68.38045,4.57664,68.38046,22476,37
209.27180,-4.33835,-58.92200,4.31277,58.92200,22412,37
209.56619,-4.03974,-49.52561,4.01416,49.52561,22412,37
209.84080,-3.76430,-41.16536,3.73872,41.16536,22412,37
210.15980,-3.44507,-32.41363,3.41949,32.41363,22412,37
210.46680,-3.13824,-25.67341,3.11265,25.67341,22412,37
210.96480,-2.64014,-17.10623,2.61456,17.10623,22412,37
211.50980,-2.09532,-9.43533,2.06974,9.43533,22412,37
211.86880,-2.14314,-12.49045,2.11756,12.49045,22412,37
212.27480,-2.55766,-20.88956,2.53208,20.88956,22604,37
212.66620,-2.94904,-29.65773,2.92346,29.65773,22604,38
213.02480,-3.30830,-38.39019,3.28272,38.39019,22604,38
213.37278,-3.65635,-46.77338,3.63077,46.77338,22604,38
213.75680,-4.04034,-55.72367,4.01476,55.72367,22604,38
214.12278,-4.40594,-64.39583,4.38036,64.39583,22604,38
214.42580,-4.58526,-67.61130,4.55968,67.61130,22604,38
214.65480,-4.33721,-58.83917,4.31163,58.83917,22540,38
214.93580,-4.05185,-49.84022,4.02627,49.84022,22540,38
215.20380,-3.78334,-41.74456,3.75776,41.74456,22540,38
215.48680,-3.50016,-33.81985,3.47458,33.81985,22540,38
215.76619,-3.22136,-27.23073,3.19578,27.23073,22540,38
216.22480,-2.76224,-18.94965,2.73666,18.94965,22540,38
216.76619,-2.22134,-11.13732,2.19576,11.13732,22540,38
217.16880,-2.05641,-10.45946,2.03083,10.45946,22540,38
217.56619,-2.46816,-19.09678,2.44258,19.09678,22604,38
217.96620,-2.86908,-27.58544,2.84350,27.58544,22604,39
218.32280,-3.22635,-36.38924,3.20077,36.38924,22604,39
218.67080,-3.57443,-44.76704,3.54884,44.76704,22604,39
219.06080,-3.96433,-53.93833,3.93875,53.93833,22604,39
219.41580,-4.31905,-62.37387,4.29347,62.37387,22604,39
219.73680,-4.63570,-69.91848,4.61012,69.91848,22604,39
219.96620,-4.40485,-61.09852,4.37927,61.09852,22604,39
220.25180,-4.11247,-51.65501,4.08689,51.65501,22540,39
220.54180,-3.82142,-42.90878,3.79584,42.90878,22540,39
220.86480,-3.49820,-33.70118,3.47262,33.70118,22540,39
221.24778,-3.11539,-25.13859,3.08981,25.13859,22540,39
221.72280,-2.64022,-16.98983,2.61464,16.98983,22540,39
222.26619,-2.09757,-9.39182,2.07199,9.39182,22540,39
222.88180,-2.05239,-10.94133,2.02681,10.94133,22540,39
223.29580,-2.47472,-19.56069,2.44914,19.56069,22476,39
223.67580,-2.85504,-27.76785,2.82946,27.76785,22476,39
224.04680,-3.22633,-36.77563,3.20075,36.77563,22476,40
224.41080,-3.59045,-45.37557,3.56487,45.37557,22476,40
224.78080,-3.96025,-53.98919,3.93467,53.98919,22476,40
225.15780,-4.33698,-62.89915,4.31140,62.89915,22476,40
225.48580,-4.62994,-69.56360,4.60436,69.56361,22476,40
225.72380,-4.36920,-59.97116,4.34362,59.97116,22476,40
226.00080,-4.08705,-50.98956,4.06147,50.98956,22412,40
226.30680,-3.78017,-41.70030,3.75459,41.70030,22412,40
226.58880,-3.49802,-33.72974,3.47244,33.72974,22412,40
226.97780,-3.10916,-24.99460,3.08358,24.99460,22412,40
227.46620,-2.62107,-16.71960,2.59549,16.71960,22412,40
228.01680,-2.07015,-8.93942,2.04457,8.93942,22412,40
228.37780,-2.17356,-13.01897,2.14798,13.01897,22412,40
228.77378,-2.57657,-21.40497,2.55099,21.40497,22476,40
229.12880,-2.93184,-29.38458,2.90626,29.38458,22476,41
229.47180,-3.27520,-37.76339,3.24962,37.76339,22476,41
229.84880,-3.65222,-46.86658,3.62664,46.86658,22476,41
230.21380,-4.01719,-55.20597,3.99161,55.20597,22476,41
230.58178,-4.38485,-63.77958,4.35926,63.77958,22476,41
230.89780,-4.59941,-68.13411,4.57383,68.13412,22476,41
231.15280,-4.32259,-58.26801,4.29701,58.26801,22412,41
231.43580,-4.03563,-49.21839,4.01005,49.21840,22412,41
231.69980,-3.77123,-41.31589,3.74565,41.31589,22412,41
232.02378,-3.44702,-32.23442,3.42144,32.23442,22412,41
232.43080,-3.04007,-23.52843,3.01449,23.52843,22412,41
232.92480,-2.54609,-15.47820,2.52051,15.47820,22412,41
233.46619,-2.00505,-7.94364,1.97947,7.94364,22412,41
233.81280,-2.24304,-14.42701,2.21746,14.42701,22476,41
234.22280,-2.65772,-22.93877,2.63214,22.93877,22476,42
234.58780,-3.02314,-31.34968,2.99756,31.34968,22476,42
234.95980,-3.39507,-40.28721,3.36949,40.28721,22476,42
235.32280,-3.75829,-48.97290,3.73271,48.97290,22476,42
235.68580,-4.12131,-57.44320,4.09573,57.44320,22476,42
236.05880,-4.49402,-66.31507,4.46844,66.31507,22476,42
236.32680,-4.53016,-65.43814,4.50458,65.43813,22476,42
236.57780,-4.26622,-56.40529,4.24064,56.40530,22412,42
236.86620,-3.97544,-47.44892,3.94986,47.44892,22412,42
237.17280,-3.66814,-38.29043,3.64256,38.29042,22412,42
237.48478,-3.35607,-30.18799,3.33048,30.18799,22412,42
237.92080,-2.91987,-21.48448,2.89428,21.48448,22412,42
238.43680,-2.40398,-13.47734,2.37840,13.47734,22412,42
238.92280,-1.96086,-7.62721,1.93528,7.62721,22412,42
239.28380,-2.34850,-16.56412,2.32292,16.56412,22476,42
239.68180,-2.74898,-24.89109,2.72340,24.89109,22476,43
240.05378,-3.12122,-33.83740,3.09564,33.83740,22476,43
240.41378,-3.48113,-42.32657,3.45555,42.32657,22476,43
240.74578,-3.81326,-50.28097,3.78768,50.28097,22476,43
241.11080,-4.17834,-58.74286,4.15276,58.74286,22476,43
241.46978,-4.53720,-67.38994,4.51162,67.38995,22476,43
241.72680,-4.49524,-64.11837,4.46966,64.11837,22476,43
241.96619,-4.24593,-55.72471,4.22035,55.72471,22412,43
242.23580,-3.97348,-47.36548,3.94790,47.36548,22412,43
242.54280,-3.66618,-38.20864,3.64060,38.20864,22412,43
242.87078,-3.33812,-29.72439,3.31254,29.72439,22412,43
243.30980,-2.89892,-21.03090,2.87334,21.03090,22412,43
243.84380,-2.36506,-12.96660,2.33948,12.96660,22412,43
244.30280,-1.98169,-8.18245,1.95611,8.18245,22412,43
244.66620,-2.37085,-16.92022,2.34527,16.92022,22476,43
245.06619,-2.77307,-25.41841,2.74749,25.41841,22476,44
245.44780,-3.15525,-34.58417,3.12967,34.58417,22476,44
245.79280,-3.50021,-42.81560,3.47463,42.81560,22476,44
246.16620,-3.87331,-51.62658,3.84773,51.62658,22476,44
246.53878,-4.24631,-60.35771,4.22073,60.35771,22476,44
246.88980,-4.59722,-68.83097,4.57164,68.83097,22476,44
247.13880,-4.44964,-62.41281,4.42406,62.41281,22476,44
247.40278,-4.17776,-53.41795,4.15218,53.41795,22412,44
247.70780,-3.87129,-44.11445,3.84571,44.11445,22412,44
248.01480,-3.56413,-35.15432,3.53855,35.15432,22412,44
248.38480,-3.19420,-26.46736,3.16862,26.46736,22412,44
248.86580,-2.71317,-18.01583,2.68759,18.01583,22412,44
249.39480,-2.18417,-10.46597,2.15859,10.46597,22412,44
249.78980,-2.10481,-11.39103,2.07923,11.39103,22412,44
250.20080,-2.52746,-20.00044,2.50188,20.00044,22476,45
250.57880,-2.90595,-28.41520,2.88037,28.41520,22476,45
250.94880,-3.27628,-37.43747,3.25070,37.43747,22476,45
251.29880,-3.62642,-45.72196,3.60084,45.72195,22476,45
251.66620,-3.99322,-54.38510,3.96764,54.38510,22476,45
252.04680,-4.37397,-63.38882,4.34839,63.38882,22476,45
252.36620,-4.62852,-68.95882,4.60294,68.95882,22476,45
252.60280,-4.36766,-59.51758,4.34208,59.51758,22412,45
252.88578,-4.07991,-50.37311,4.05433,50.37311,22412,45
253.18680,-3.77819,-41.22977,3.75261,41.22977,22412,45
253.51580,-3.44901,-32.17519,3.42343,32.17519,22412,45
253.92480,-3.04000,-23.45532,3.01442,23.45532,22412,45
254.42780,-2.53706,-15.35085,2.51148,15.35085,22412,45
254.91880,-2.04610,-8.43508,2.02052,8.43508,22412,45
255.26680,-2.20765,-13.49330,2.18207,13.49330,22476,45
255.67080,-2.61770,-21.97058,2.59212,21.97058,22476,46
256.01981,-2.96708,-29.85261,2.94150,29.85261,22476,46
256.30881,-3.25633,-36.91286,3.23075,36.91286,22476,46
256.66620,-3.61343,-45.41439,3.58785,45.41439,22476,46
257.04678,-3.99425,-54.30987,3.96867,54.30987,22476,46
257.40580,-4.35300,-62.85564,4.32742,62.85564,22476,46
257.73278,-4.62988,-69.09896,4.60430,69.09896,22476,46
257.96619,-4.37307,-59.75467,4.34749,59.75467,22412,46
258.24978,-4.08397,-50.52090,4.05839,50.52090,22412,46
258.55178,-3.78120,-41.35345,3.75562,41.35345,22412,46
258.86619,-3.46700,-32.66645,3.44142,32.66645,22412,46
259.26620,-3.06710,-23.94420,3.04152,23.94420,22412,46
259.76620,-2.56705,-15.73936,2.54147,15.73936,22412,46
260.31378,-2.01908,-8.03707,1.99350,8.03707,22412,46
260.66378,-2.25609,-14.46952,2.23051,14.46952,22476,46
261.06180,-2.65874,-22.78030,2.63316,22.78030,22476,47
261.39081,-2.98808,-30.39686,2.96250,30.39686,22476,47
261.71478,-3.31223,-38.32211,3.28665,38.32211,22476,47
262.00878,-3.60636,-45.21527,3.58078,45.21527,22476,47
262.37478,-3.97212,-53.78154,3.94654,53.78154,22476,47
262.75878,-4.35592,-62.89697,4.33034,62.89697,22476,47
263.06878,-4.64219,-69.58526,4.61661,69.58526,22476,47
263.31281,-4.37799,-59.85447,4.35241,59.85447,22476,47
263.58978,-4.09582,-50.82934,4.07024,50.82933,22412,47
263.86619,-3.81896,-42.46233,3.79338,42.46233,22412,47
264.17178,-3.51276,-33.76528,3.48718,33.76527,22412,47
264.52678,-3.15786,-25.67486,3.13228,25.67486,22412,47
264.99381,-2.69088,-17.49239,2.66530,17.49239,22412,47
265.49781,-2.18696,-10.42710,2.16137,10.42710,22412,47
265.88581,-2.10835,-11.29631,2.08277,11.29631,22412,47
266.28681,-2.52120,-19.86333,2.49562,19.86333,22604,47
266.65978,-2.89476,-28.04249,2.86918,28.04249,22604,48
267.00078,-3.23604,-36.34506,3.21046,36.34506,22604,48
267.33678,-3.57221,-44.38431,3.54663,44.38431,22604,48
267.58881,-3.82412,-50.31891,3.79853,50.31891,22604,48
267.88678,-4.12215,-57.30876,4.09657,57.30876,22604,48
268.22278,-4.45784,-65.34804,4.43226,65.34805,22604,48
268.47878,-4.60096,-67.75614,4.57538,67.75614,22604,48
268.67778,-4.38293,-60.01174,4.35735,60.01174,22604,48
268.90681,-4.14914,-52.38103,4.12356,52.38103,22540,48
269.11678,-3.93800,-45.95386,3.91242,45.95386,22540,48
269.30278,-3.75192,-40.36482,3.72634,40.36482,22540,48
269.56619,-3.48872,-33.13786,3.46314,33.13786,22540,48
269.88778,-3.16681,-25.82769,3.14123,25.82769,22540,48
270.36481,-2.68979,-17.49031,2.66420,17.49031,22540,48
270.89178,-2.16294,-10.04497,2.13736,10.04497,22540,48
271.26881,-2.13499,-11.85478,2.10941,11.85478,22540,48
271.67081,-2.54730,-20.24871,2.52172,20.24871,22604,48
272.06578,-2.94275,-29.22042,2.91717,29.22042,22604,49
272.35481,-3.23217,-36.22483,3.20658,36.22483,22604,49
272.68681,-3.56422,-44.27427,3.53864,44.27427,22604,49
273.05578,-3.93305,-52.86308,3.90747,52.86308,22604,49
273.36678,-4.24415,-60.20139,4.21857,60.20139,22604,49
273.66619,-4.54294,-67.35913,4.51736,67.35913,22604,49
273.93478,-4.50063,-63.99980,4.47505,63.99980,22604,49
274.16619,-4.25983,-55.81542,4.23425,55.81542,22540,49
274.40781,-4.01540,-48.33078,3.98982,48.33078,22540,49
274.67081,-3.75212,-40.31738,3.72654,40.31738,22540,49
274.98081,-3.44187,-31.79654,3.41629,31.79654,22540,49
275.36881,-3.05398,-23.59918,3.02840,23.59918,22540,49
275.87281,-2.54996,-15.42862,2.52438,15.42862,22540,49
276.42481,-1.99803,-7.59670,1.97245,7.59670,22540,49
276.97478,-2.11039,-11.80873,2.08480,11.80873,22540,49
277.39081,-2.53311,-20.42184,2.50753,20.42184,22476,49
277.76622,-2.90836,-28.73921,2.88278,28.73921,22476,50
278.09978,-3.24262,-36.84329,3.21704,36.84329,22476,50
278.39481,-3.53756,-43.84207,3.51198,43.84207,22476,50
278.76622,-3.90856,-52.47429,3.88298,52.47429,22476,50
279.06619,-4.20863,-59.43032,4.18305,59.43032,22476,50
279.39678,-4.53937,-67.36582,4.51379,67.36581,22476,50
279.62781,-4.52377,-65.04709,4.49819,65.04710,22476,50
279.83781,-4.30218,-57.35880,4.27660,57.35880,22412,50
280.01178,-4.12559,-51.83424,4.10001,51.83424,22412,50
280.25681,-3.87958,-44.29931,3.85400,44.29931,22412,50
280.49678,-3.63950,-37.21670,3.61391,37.21671,22412,50
280.76881,-3.36737,-30.11497,3.34179,30.11497,22412,50
281.06619,-3.07039,-23.88955,3.04481,23.88955,22412,50
281.51178,-2.62435,-16.54918,2.59877,16.54918,22412,50
281.91278,-2.22347,-10.89617,2.19789,10.89617,22412,50
282.26881,-2.04633,-9.64830,2.02075,9.64830,22412,50
282.66619,-2.46124,-18.59881,2.43566,18.59881,22476,50
283.06619,-2.86244,-27.29206,2.83686,27.29206,22476,51
283.32481,-3.12176,-33.71605,3.09618,33.71605,22476,51
283.53681,-3.33353,-38.81801,3.30795,38.81801,22476,51
283.86619,-3.66276,-46.59265,3.63718,46.59264,22476,51
284.20278,-3.99958,-54.40249,3.97400,54.40248,22476,51
284.53778,-4.33443,-62.34199,4.30885,62.34199,22476,51
284.85981,-4.65052,-69.95326,4.62494,69.95326,22476,51
285.08078,-4.42523,-61.31811,4.39965,61.31811,22476,51
285.35581,-4.14364,-52.21178,4.11806,52.21178,22412,51
285.63581,-3.86258,-43.65759,3.83700,43.65759,22412,51
285.87281,-3.62547,-36.65547,3.59989,36.65547,22412,51
286.23481,-3.26339,-27.68417,3.23781,27.68417,22412,51
286.64678,-2.85136,-19.93753,2.82578,19.93753,22412,51
287.16619,-2.33234,-12.38837,2.30676,12.38837,22412,51
287.62178,-2.02926,-9.21640,2.00368,9.21640,22412,51
287.99478,-2.42174,-17.80814,2.39616,17.80814,22476,51
288.39578,-2.82440,-26.41326,2.79882,26.41326,22476,52
288.71478,-3.14366,-34.14636,3.11808,34.14636,22476,52
288.97478,-3.40342,-40.25043,3.37784,40.25043,22476,52
289.26622,-3.69468,-47.35098,3.66910,47.35098,22476,52
289.55381,-3.98254,-53.97392,3.95696,53.97392,22476,52
289.90281,-4.33140,-62.29139,4.30582,62.29139,22476,52
290.22681,-4.65193,-69.99116,4.62634,69.99116,22476,52
290.44078,-4.43992,-61.85242,4.41434,61.85242,22476,52
290.66181,-4.21248,-54.26784,4.18690,54.26784,22412,52
290.89381,-3.97873,-47.18803,3.95315,47.18803,22412,52
291.13678,-3.73550,-39.84851,3.70992,39.84851,22412,52
291.42481,-3.44726,-31.90925,3.42168,31.90925,22412,52
291.71281,-3.15937,-25.60053,3.13379,25.60053,22412,52
292.16678,-2.70547,-17.61159,2.67989,17.61159,22412,52
292.73678,-2.13558,-9.58155,2.11000,9.58155,22412,52
293.12378,-2.16564,-12.47237,2.14006,12.47237,22412,52
293.52781,-2.57792,-20.92992,2.55234,20.92992,22476,53
293.86619,-2.91637,-28.48609,2.89079,28.48609,22476,53
294.18078,-3.23159,-36.18197,3.20601,36.18197,22476,53
294.51081,-3.56167,-44.12309,3.53609,44.12309,22476,53
294.88878,-3.93949,-52.97516,3.91391,52.97515,22476,53
295.26481,-4.31535,-61.82124,4.28977,61.82124,22476,53
295.61178,-4.65575,-69.96723,4.63017,69.96722,22476,53
295.84078,-4.42081,-61.07477,4.39523,61.07478,22476,53
296.06619,-4.19016,-53.52173,4.16458,53.52173,22412,53
296.30178,-3.95263,-46.27854,3.92705,46.27854,22412,53
296.55278,-3.70152,-38.84274,3.67594,38.84274,22412,53
296.80781,-3.44632,-31.74214,3.42074,31.74214,22412,53
297.22581,-3.02835,-23.00543,3.00277,23.00543,22412,53
297.72478,-2.52938,-14.99840,2.50380,14.99840,22412,53
298.24978,-2.00442,-7.62931,1.97884,7.62931,22412,53
298.56681,-2.24197,-13.93533,2.21639,13.93533,22476,53
298.97278,-2.65320,-22.55419,2.62762,22.55420,22476,54
299.35481,-3.03556,-31.36912,3.00998,31.36912,22476,54
299.66619,-3.34656,-39.02884,3.32098,39.02884,22476,54
300.03778,-3.71873,-47.90294,3.69315,47.90294,22476,54
300.40781,-4.08867,-56.43810,4.06309,56.43810,22476,54
300.76622,-4.44633,-64.94271,4.42075,64.94271,22476,54
301.05978,-4.57480,-66.62250,4.54922,66.62251,22476,54
301.30781,-4.31038,-57.37948,4.28480,57.37948,22412,54
301.56778,-4.04705,-49.15824,4.02147,49.15824,22412,54
301.86619,-3.74863,-40.14122,3.72305,40.14122,22412,54
302.19278,-3.42137,-31.15478,3.39579,31.15478,22412,54
302.60778,-3.00651,-22.58251,2.98093,22.58251,22412,54
303.12281,-2.49149,-14.43981,2.46591,14.43981,22412,54
303.64381,-1.97416,-7.20350,1.94858,7.20350,22412,54
303.97681,-2.30971,-15.37691,2.28413,15.37691,22476,54
304.37878,-2.71543,-23.87515,2.68985,23.87515,22476,55
304.75181,-3.08882,-32.71012,3.06324,32.71012,22476,55
305.11578,-3.45262,-41.38659,3.42704,41.38659,22476,55
305.41278,-3.74978,-48.50680,3.72420,48.50681,22476,55
305.75581,-4.09278,-56.46127,4.06720,56.46127,22476,55
306.10181,-4.43843,-64.75554,4.41285,64.75555,22476,55
306.39381,-4.58902,-67.12394,4.56344,67.12394,22476,55
306.65281,-4.31155,-57.41641,4.28597,57.41641,22412,55
306.87281,-4.08856,-50.34722,4.06298,50.34723,22412,55
307.15478,-3.80580,-41.83839,3.78022,41.83839,22412,55
307.36619,-3.59479,-35.62535,3.56921,35.62535,22412,55
307.65478,-3.30574,-28.47603,3.28016,28.47603,22412,55
308.01378,-2.94660,-21.46958,2.92102,21.46958,22412,55
308.53078,-2.42963,-13.56955,2.40405,13.56954,22412,55
308.96619,-1.99483,-7.44532,1.96924,7.44532,22412,55
309.33578,-2.34544,-16.01513,2.31985,16.01513,22476,55
309.72878,-2.74162,-24.34387,2.71604,24.34387,22476,56
310.08178,-3.09476,-32.85689,3.06918,32.85689,22476,56
310.41678,-3.42955,-40.80541,3.40397,40.80542,22476,56
310.77078,-3.78387,-49.21078,3.75829,49.21078,22476,56
311.11881,-4.13192,-57.39163,4.10634,57.39163,22476,56
311.47478,-4.48768,-65.82693,4.46210,65.82693,22476,56
311.70978,-4.60313,-67.57780,4.57755,67.57780,22476,56
311.96619,-4.32692,-57.84731,4.30134,57.84731,22412,56
312.25681,-4.03218,-48.63776,4.00660,48.63776,22412,56
312.50978,-3.77879,-40.93315,3.75321,40.93315,22412,56
312.80078,-3.48766,-32.82825,3.46208,32.82825,22412,56
313.12178,-3.16676,-25.54977,3.14118,25.54977,22412,56
313.58178,-2.70682,-17.50590,2.68124,17.50590,22412,56
314.15178,-2.13694,-9.45800,2.11136,9.45800,22412,56
314.52878,-2.17279,-12.45732,2.14721,12.45732,22412,56
314.92881,-2.58117,-20.87238,2.55559,20.87238,22476,57
315.29481,-2.94761,-29.21555,2.92203,29.21555,22476,57
315.58678,-3.23985,-36.33582,3.21427,36.33582,22476,57
315.81778,-3.47072,-41.87173,3.44513,41.87173,22476,57
316.11078,-3.76392,-48.89040,3.73834,48.89040,22476,57
316.45378,-4.10694,-56.84233,4.08136,56.84233,22476,57
316.80878,-4.46156,-65.31553,4.43598,65.31553,22476,57
317.09778,-4.57850,-66.62669,4.55292,66.62669,22476,57
317.36178,-4.29809,-56.89871,4.27251,56.89871,22412,57
317.56619,-4.09156,-50.39906,4.06598,50.39906,22412,57
317.86078,-3.79577,-41.45177,3.77019,41.45177,22412,57
318.14881,-3.50759,-33.27628,3.48201,33.27628,22412,57
318.41181,-3.24476,-26.99325,3.21918,26.99325,22412,57
318.86619,-2.79059,-18.75536,2.76501,18.75536,22412,57
319.40878,-2.24780,-11.05943,2.22222,11.05943,22412,57
319.80878,-2.10708,-10.82942,2.08150,10.82942,22412,57
320.20378,-2.51576,-19.46322,2.49018,19.46322,22604,57
320.58178,-2.89462,-27.82251,2.86904,27.82252,22604,58
320.83078,-3.14388,-34.03607,3.11830,34.03607,22604,58
321.13478,-3.44763,-41.24007,3.42205,41.24007,22604,58
321.43781,-3.75092,-48.50344,3.72534,48.50344,22604,58
321.79881,-4.11191,-56.88769,4.08633,56.88769,22604,58
322.11478,-4.42742,-64.37910,4.40184,64.37910,22604,58
322.36619,-4.65643,-69.74006,4.63085,69.74007,22604,58
322.55781,-4.44745,-61.86840,4.42187,61.86840,22604,58
322.76622,-4.23308,-54.75434,4.20750,54.75434,22540,58
322.97681,-4.02012,-48.18490,3.99454,48.18490,22540,58
323.22278,-3.77379,-40.69815,3.74821,40.69815,22540,58
323.52678,-3.46963,-32.25625,3.44405,32.25624,22540,58
323.90478,-3.09176,-23.96139,3.06618,23.96139,22540,58
324.39278,-2.60369,-15.99506,2.57811,15.99506,22540,58
324.96478,-2.03166,-7.91553,2.00608,7.91553,22540,58
325.27878,-2.24769,-13.85098,2.22211,13.85098,22604,58
325.68078,-2.65533,-22.46338,2.62975,22.46338,22604,59
326.01081,-2.98569,-30.06114,2.96011,30.06113,22604,59
326.31078,-3.28576,-37.32330,3.26018,37.32330,22604,59
326.64678,-3.62193,-45.30007,3.59635,45.30007,22604,59
327.01378,-3.98886,-53.87119,3.96328,53.87119,22604,59
327.26881,-4.24392,-59.91824,4.21834,59.91824,22604,59
327.56619,-4.54080,-67.13581,4.51522,67.13581,22604,59
327.76622,-4.57281,-66.42838,4.54722,66.42838,22604,59
328.02381,-4.29826,-56.92803,4.27268,56.92804,22540,59
328.31281,-4.00610,-47.88949,3.98052,47.88949,22540,59
328.58078,-3.73784,-39.73993,3.71226,39.73993,22540,59
328.81078,-3.50760,-33.30673,3.48202,33.30672,22540,59
329.20481,-3.11375,-24.42614,3.08817,24.42614,22540,59
329.67978,-2.63869,-16.46722,2.61311,16.46722,22540,59
330.17881,-2.13985,-9.45715,2.11427,9.45715,22540,59
330.39678,-1.96691,-7.17846,1.94133,7.17846,22540,59