File: data-raw/Experiment 2/Results/INSTRON data/Experiment 2.is_ccyclic_RawData/Specimen_RawData_10.csv
Text Inputs : Specimen label,"Short Plate 3 T1"

Time,Extension,Load,Compressive extension,Compressive load,Segment ID,Total Cycle Count
(sec),(mm),(N),(mm),(N),,
0.00000,-0.02622,0.14455,0.00000,-0.14455,12835,0
0.35580,-0.02622,0.08004,0.00000,-0.08004,12835,0
1.11680,-0.02622,0.09348,0.00000,-0.09348,3220,0
1.55620,-0.22708,0.09508,0.20086,-0.09508,3220,0
1.85620,-0.37775,0.09056,0.35152,-0.09056,3220,0
2.35620,-0.62767,0.12595,0.60145,-0.12595,3220,0
3.09680,-0.99830,-2.05352,0.97208,2.05352,3220,0
3.87880,-1.51116,-10.51368,1.48494,10.51368,22476,0
4.82680,-2.46099,-23.27696,2.43477,23.27696,22476,0
5.35620,-2.98994,-32.05670,2.96371,32.05670,22476,0
5.68080,-3.31502,-38.23848,3.28880,38.23848,22476,0
5.95480,-3.58885,-43.35205,3.56263,43.35205,22476,0
6.13980,-3.77396,-46.99440,3.74774,46.99440,22476,0
6.40280,-4.03684,-51.84780,4.01062,51.84781,22476,0
6.60180,-4.23601,-55.55921,4.20978,55.55921,22476,0
6.85620,-4.49000,-60.25928,4.46378,60.25927,22476,0
7.15680,-4.79095,-65.81452,4.76473,65.81452,22476,0
7.42480,-4.96514,-67.96391,4.93892,67.96391,22476,0
7.70380,-4.66350,-57.85852,4.63728,57.85852,22412,0
7.98880,-4.37535,-49.29490,4.34913,49.29490,22412,0
8.20780,-4.15574,-43.13688,4.12952,43.13688,22412,0
8.50080,-3.86274,-36.14543,3.83652,36.14544,22412,0
8.83180,-3.53176,-29.01888,3.50554,29.01888,22412,0
9.30380,-3.05971,-21.01755,3.03349,21.01755,22412,0
9.88880,-2.47472,-13.35991,2.44850,13.35991,22412,0
10.45620,-2.01033,-8.53075,1.98411,8.53075,22412,0
11.14480,-2.72467,-20.90802,2.69845,20.90802,22476,1
11.68480,-3.26484,-31.25466,3.23862,31.25466,22476,1
12.12980,-3.70990,-40.81519,3.68368,40.81519,22476,1
12.50380,-4.08388,-48.83009,4.05766,48.83009,22476,1
12.78580,-4.36605,-54.73384,4.33983,54.73384,22476,1
13.14780,-4.72794,-62.33507,4.70172,62.33507,22476,1
13.66180,-4.96979,-64.88375,4.94356,64.88374,22476,1
13.99780,-4.62113,-53.87475,4.59491,53.87475,22412,1
14.35180,-4.26580,-43.74185,4.23958,43.74185,22412,1
14.66780,-3.94985,-36.17183,3.92363,36.17183,22412,1
15.06580,-3.55176,-27.67060,3.52554,27.67060,22412,1
15.72280,-2.89470,-17.44365,2.86848,17.44365,22412,1
16.55620,-2.06275,-7.19478,2.03653,7.19478,22412,1
17.36080,-2.86280,-21.97500,2.83658,21.97500,22476,2
17.97380,-3.47599,-34.39615,3.44977,34.39615,22476,2
18.52380,-4.02592,-46.24741,3.99970,46.24741,22476,2
18.98880,-4.49098,-56.18317,4.46476,56.18317,22476,2
19.55620,-5.05780,-68.17231,5.03158,68.17231,22476,2
19.85980,-4.92615,-62.08118,4.89993,62.08118,22476,2
20.19380,-4.58454,-51.64444,4.55832,51.64444,22412,2
20.55480,-4.22271,-41.52888,4.19649,41.52888,22412,2
20.95620,-3.82167,-32.30758,3.79545,32.30758,22412,2
21.64780,-3.12948,-20.01847,3.10325,20.01847,22412,2
22.64380,-2.13347,-7.48079,2.10725,7.48079,22412,2
23.34880,-2.79242,-19.85184,2.76620,19.85184,22476,3
23.83180,-3.27568,-29.09369,3.24946,29.09369,22476,3
24.20080,-3.64460,-37.10439,3.61838,37.10439,22476,3
24.59680,-4.04073,-45.77220,4.01451,45.77220,22476,3
25.01380,-4.45791,-54.69896,4.43169,54.69896,22476,3
25.37680,-4.82079,-62.57039,4.79456,62.57039,22476,3
25.76380,-5.14651,-68.81720,5.12029,68.81720,22476,3
26.07680,-4.80795,-57.51046,4.78173,57.51046,22412,3
26.30780,-4.57421,-50.59838,4.54799,50.59838,22412,3
26.57980,-4.30163,-42.79542,4.27541,42.79542,22412,3
26.79680,-4.08446,-37.52482,4.05824,37.52482,22412,3
26.96480,-3.91659,-33.78324,3.89037,33.78324,22412,3
27.18080,-3.70049,-29.15276,3.67427,29.15276,22412,3
27.45280,-3.42862,-24.15650,3.40240,24.15650,22412,3
27.72580,-3.15528,-19.86422,3.12906,19.86422,22412,3
28.12880,-2.75240,-14.64835,2.72618,14.64835,22412,3
28.59580,-2.28545,-8.96908,2.25923,8.96908,22412,3
29.07080,-2.49477,-14.37692,2.46855,14.37692,22476,3
29.45620,-2.88323,-20.96410,2.85701,20.96410,22476,4
29.78980,-3.21739,-27.17775,3.19117,27.17776,22476,4
29.97280,-3.40057,-31.09572,3.37435,31.09571,22476,4
30.10880,-3.53646,-34.23169,3.51024,34.23169,22476,4
30.27980,-3.70748,-37.94744,3.68126,37.94744,22476,4
30.43280,-3.86048,-41.24804,3.83426,41.24804,22476,4
30.64280,-4.07045,-45.78724,4.04423,45.78724,22476,4
30.82180,-4.24954,-49.67305,4.22332,49.67305,22476,4
31.04980,-4.47763,-54.61896,4.45141,54.61896,22476,4
31.27080,-4.69845,-59.41250,4.67223,59.41250,22476,4
31.55620,-4.98343,-65.55112,4.95721,65.55112,22476,4
31.83480,-5.11139,-66.84346,5.08517,66.84346,22476,4
32.13680,-4.79102,-56.48150,4.76479,56.48150,22412,4
32.37380,-4.55182,-49.41769,4.52560,49.41769,22412,4
32.59880,-4.32641,-42.96566,4.30019,42.96566,22412,4
32.78180,-4.14309,-38.35104,4.11687,38.35104,22412,4
32.95880,-3.96627,-34.33404,3.94005,34.33404,22412,4
33.17880,-3.74619,-29.62118,3.71997,29.62118,22412,4
33.46980,-3.45532,-24.20549,3.42910,24.20549,22412,4
33.91980,-3.00521,-17.50239,2.97899,17.50239,22412,4
34.41380,-2.51129,-11.47274,2.48507,11.47274,22412,4
34.87280,-2.31789,-10.81211,2.29167,10.81211,22412,4
35.37180,-2.83085,-19.50193,2.80463,19.50193,22476,5
35.74180,-3.20119,-26.42559,3.17497,26.42559,22476,5
36.01380,-3.47341,-32.24791,3.44719,32.24791,22476,5
36.21980,-3.67925,-36.79192,3.65303,36.79192,22476,5
36.44480,-3.90437,-41.72635,3.87815,41.72635,22476,5
36.59980,-4.05933,-45.11972,4.03310,45.11972,22476,5
36.79380,-4.25337,-49.35449,4.22715,49.35449,22476,5
37.01180,-4.47146,-54.07108,4.44524,54.07108,22476,5
37.20980,-4.66925,-58.35493,4.64303,58.35493,22476,5
37.59880,-5.05824,-66.78253,5.03202,66.78253,22476,5
37.87180,-5.07388,-65.01576,5.04766,65.01576,22476,5
38.07180,-4.86307,-58.12268,4.83685,58.12268,22412,5
38.26480,-4.66702,-52.27322,4.64080,52.27322,22412,5
38.44780,-4.48341,-47.04397,4.45719,47.04397,22412,5
38.66380,-4.26707,-40.76222,4.24085,40.76222,22412,5
38.92280,-4.00799,-34.83829,3.98177,34.83828,22412,5
39.19380,-3.73704,-28.99306,3.71082,28.99306,22412,5
39.55620,-3.37510,-22.57300,3.34888,22.57300,22412,5
40.13380,-2.79700,-14.61748,2.77078,14.61748,22412,5
40.71680,-2.21404,-7.45317,2.18782,7.45317,22412,5
41.33380,-2.80858,-18.92207,2.78236,18.92207,22476,5
41.85280,-3.32828,-28.70052,3.30206,28.70053,22476,6
42.19480,-3.67006,-36.21771,3.64384,36.21771,22476,6
42.59180,-4.06711,-44.89335,4.04089,44.89335,22476,6
43.08280,-4.55824,-55.75840,4.53202,55.75840,22476,6
43.55680,-5.03208,-65.92220,5.00586,65.92220,22476,6
43.86080,-5.10179,-65.44989,5.07557,65.44988,22476,6
44.20880,-4.73941,-53.96503,4.71319,53.96503,22412,6
44.55620,-4.39114,-43.92134,4.36492,43.92134,22412,6
44.90380,-4.04290,-35.15841,4.01668,35.15841,22412,6
45.19180,-3.75490,-29.05668,3.72868,29.05667,22412,6
45.78980,-3.15671,-18.96857,3.13049,18.96857,22412,6
46.47180,-2.47501,-10.49186,2.44879,10.49187,22412,6
47.08480,-2.56051,-14.49309,2.53429,14.49309,22476,6
47.63780,-3.11695,-24.22172,3.09073,24.22172,22476,7
47.88480,-3.36424,-29.26399,3.33802,29.26399,22476,7
48.08180,-3.56113,-33.62669,3.53491,33.62669,22476,7
48.26580,-3.74514,-37.62410,3.71892,37.62410,22476,7
48.49480,-3.97419,-42.67150,3.94797,42.67150,22476,7
48.69280,-4.17207,-47.10138,4.14585,47.10138,22476,7
48.95620,-4.43532,-52.75024,4.40910,52.75024,22476,7
49.17280,-4.65203,-57.45653,4.62581,57.45653,22476,7
49.41680,-4.89609,-62.86761,4.86987,62.86761,22476,7
49.73480,-5.21040,-69.53073,5.18418,69.53072,22476,7
49.97380,-4.97220,-61.02390,4.94597,61.02390,22476,7
50.21880,-4.72118,-53.23032,4.69496,53.23032,22412,7
50.44080,-4.49822,-46.88295,4.47200,46.88295,22412,7
50.71680,-4.22187,-39.06531,4.19565,39.06531,22412,7
50.95620,-3.98287,-33.61578,3.95665,33.61578,22412,7
51.18780,-3.75086,-28.67374,3.72464,28.67374,22412,7
51.70080,-3.23765,-19.95139,3.21143,19.95139,22412,7
52.35620,-2.58277,-11.68457,2.55655,11.68457,22412,7
52.85620,-2.36109,-10.71909,2.33487,10.71909,22412,7
53.62580,-3.14478,-24.40963,3.11856,24.40963,22604,8
54.07580,-3.59486,-34.11841,3.56864,34.11841,22604,8
54.47680,-3.99597,-42.92954,3.96975,42.92954,22604,8
54.93580,-4.45512,-52.93139,4.42890,52.93139,22604,8
55.23180,-4.75090,-59.46416,4.72468,59.46416,22604,8
55.52580,-5.04486,-65.86679,5.01864,65.86679,22604,8
55.81280,-5.14849,-66.45268,5.12226,66.45268,22604,8
56.13580,-4.80901,-55.52968,4.78279,55.52968,22540,8
56.53280,-4.41001,-43.92452,4.38379,43.92452,22540,8
56.94880,-3.99370,-33.55646,3.96748,33.55646,22540,8
57.62480,-3.31782,-21.01425,3.29160,21.01425,22540,8
58.59580,-2.34681,-8.58281,2.32059,8.58281,22540,8
59.35620,-2.89433,-19.59825,2.86811,19.59825,22604,9
59.96680,-3.50575,-31.78336,3.47953,31.78337,22604,9
60.50780,-4.04675,-43.79928,4.02053,43.79929,22604,9
61.05380,-4.59278,-55.79139,4.56656,55.79139,22604,9
61.67780,-5.21672,-69.41234,5.19050,69.41235,22604,9
62.05080,-4.88913,-57.72641,4.86290,57.72641,22540,9
62.35280,-4.58398,-48.76381,4.55776,48.76381,22540,9
62.65620,-4.28064,-40.06713,4.25442,40.06712,22540,9
62.94180,-3.99451,-33.37416,3.96829,33.37416,22540,9
63.25620,-3.68054,-26.78247,3.65432,26.78247,22540,9
63.86680,-3.06949,-17.35018,3.04327,17.35018,22540,9
64.54780,-2.38858,-8.98895,2.36236,8.98895,22540,9
65.25620,-2.43254,-12.21521,2.40632,12.21521,22540,9
65.82280,-3.00461,-21.91283,2.97839,21.91283,22476,9
66.20480,-3.38683,-29.31815,3.36061,29.31815,22476,10
66.48080,-3.66262,-35.44066,3.63640,35.44066,22476,10
66.75620,-3.93780,-41.50070,3.91158,41.50070,22476,10
66.94680,-4.12867,-45.71119,4.10245,45.71119,22476,10
67.13780,-4.31990,-49.83396,4.29367,49.83396,22476,10
67.33180,-4.51379,-54.03769,4.48757,54.03769,22476,10
67.49280,-4.67466,-57.63207,4.64844,57.63207,22476,10
67.67180,-4.85370,-61.56989,4.82748,61.56989,22476,10
67.88480,-5.06665,-66.15740,5.04043,66.15740,22476,10
68.11180,-5.21992,-68.66873,5.19370,68.66873,22476,10
68.38780,-4.91974,-58.52077,4.89352,58.52077,22412,10
68.64080,-4.66315,-50.92632,4.63692,50.92632,22412,10
68.88580,-4.41774,-43.83919,4.39152,43.83919,22412,10
69.19280,-4.11036,-35.68950,4.08414,35.68950,22412,10
69.42280,-3.88046,-30.67136,3.85424,30.67136,22412,10
69.80280,-3.50044,-23.59805,3.47421,23.59805,22412,10
70.40480,-2.89848,-15.07197,2.87226,15.07197,22412,10
71.18780,-2.40200,-10.87337,2.37578,10.87337,22412,10
71.86880,-3.09633,-23.00010,3.07011,23.00010,22476,11
72.37880,-3.60642,-33.86508,3.58020,33.86508,22476,11
72.88980,-4.11745,-44.94474,4.09123,44.94474,22476,11
73.45620,-4.68347,-57.49259,4.65725,57.49259,22476,11
73.89180,-5.11942,-66.96993,5.09320,66.96993,22476,11
74.27480,-5.01755,-61.31290,4.99133,61.31290,22476,11
74.56780,-4.71825,-52.20558,4.69203,52.20558,22412,11
75.03680,-4.24827,-38.85898,4.22205,38.85897,22412,11
75.41380,-3.87130,-30.26025,3.84508,30.26025,22412,11
76.18280,-3.10222,-17.52234,3.07600,17.52234,22412,11
77.04180,-2.26890,-7.32937,2.24268,7.32937,22412,11
77.75620,-3.00913,-21.31925,2.98291,21.31925,22476,12
78.28380,-3.53737,-31.96219,3.51115,31.96219,22476,12
78.72680,-3.98047,-41.87366,3.95425,41.87366,22476,12
79.15880,-4.41258,-51.35411,4.38636,51.35411,22476,12
79.50880,-4.76240,-59.06453,4.73618,59.06453,22476,12
79.85380,-5.10734,-66.63569,5.08112,66.63569,22476,12
80.08180,-5.17566,-66.73679,5.14944,66.73679,22476,12
80.26780,-4.97509,-59.99815,4.94887,59.99815,22412,12
80.48380,-4.75447,-53.25462,4.72825,53.25462,22412,12
80.79580,-4.44142,-44.22366,4.41520,44.22366,22412,12
81.04480,-4.19212,-37.29230,4.16590,37.29230,22412,12
81.36580,-3.87111,-30.09556,3.84489,30.09556,22412,12
81.87580,-3.36122,-21.03990,3.33500,21.03990,22412,12
82.57880,-2.65798,-11.99127,2.63176,11.99127,22412,12
83.11280,-2.45037,-11.39993,2.42415,11.39993,22412,12
83.61680,-2.96593,-20.21293,2.93971,20.21293,22476,13
83.94080,-3.29026,-26.48415,3.26404,26.48415,22476,13
84.16880,-3.51824,-31.36894,3.49202,31.36894,22476,13
84.33880,-3.68824,-35.19202,3.66202,35.19202,22476,13
84.59680,-3.94635,-40.87379,3.92013,40.87379,22476,13
84.81580,-4.16521,-45.76264,4.13899,45.76263,22476,13
85.14980,-4.49936,-53.10268,4.47314,53.10268,22476,13
85.37980,-4.72932,-58.20501,4.70310,58.20501,22476,13
85.56380,-4.91325,-62.30363,4.88703,62.30363,22476,13
85.84880,-5.19816,-68.43921,5.17194,68.43921,22476,13
86.10680,-5.07212,-62.88021,5.04590,62.88021,22476,13
86.34280,-4.82823,-55.21205,4.80201,55.21206,22412,13
86.60080,-4.56851,-47.76222,4.54229,47.76221,22412,13
86.89280,-4.27611,-39.33911,4.24989,39.33911,22412,13
87.16280,-4.00608,-32.87933,3.97986,32.87933,22412,13
87.51880,-3.64999,-25.66298,3.62377,25.66298,22412,13
87.94180,-3.22688,-18.94020,3.20066,18.94020,22412,13
88.36180,-2.80712,-13.52794,2.78090,13.52794,22412,13
88.84880,-2.32014,-7.60959,2.29392,7.60959,22412,13
89.35620,-2.79384,-17.15898,2.76762,17.15898,22476,13
89.80380,-3.24307,-25.45851,3.21685,25.45851,22476,14
90.12280,-3.56217,-32.21345,3.53595,32.21345,22476,14
90.39280,-3.83215,-38.29559,3.80593,38.29559,22476,14
90.77680,-4.21628,-46.72861,4.19006,46.72861,22476,14
91.15280,-4.59222,-54.98185,4.56600,54.98185,22476,14
91.52780,-4.96714,-63.30258,4.94092,63.30258,22476,14
91.88980,-5.22684,-67.96470,5.20062,67.96471,22476,14
92.28080,-4.81184,-54.55779,4.78562,54.55779,22412,14
92.59680,-4.49422,-45.32830,4.46800,45.32830,22412,14
92.87680,-4.21397,-37.51334,4.18775,37.51334,22412,14
93.12680,-3.96405,-31.76081,3.93783,31.76081,22412,14
93.38880,-3.70200,-26.45461,3.67578,26.45461,22412,14
93.93580,-3.15477,-17.91394,3.12854,17.91394,22412,14
94.48780,-2.60285,-11.08684,2.57663,11.08684,22412,14
94.89380,-2.39098,-9.75391,2.36476,9.75391,22412,14
95.55620,-3.07086,-21.93836,3.04464,21.93836,22476,15
95.85480,-3.37019,-27.78068,3.34397,27.78068,22476,15
96.07680,-3.59206,-32.71425,3.56584,32.71425,22476,15
96.40880,-3.92414,-40.18784,3.89792,40.18784,22476,15
96.65080,-4.16603,-45.57049,4.13981,45.57049,22476,15
96.86380,-4.37924,-50.28618,4.35302,50.28619,22476,15
97.25180,-4.76711,-58.70071,4.74089,58.70071,22476,15
97.57780,-5.09302,-65.92684,5.06680,65.92684,22476,15
97.85380,-5.19655,-66.65389,5.17033,66.65389,22476,15
98.05980,-4.97597,-59.42662,4.94975,59.42662,22412,15
98.31280,-4.71876,-51.66205,4.69254,51.66205,22412,15
98.62180,-4.40917,-42.78104,4.38295,42.78104,22412,15
98.95780,-4.07291,-34.13269,4.04669,34.13269,22412,15
99.22980,-3.80097,-28.22839,3.77475,28.22839,22412,15
99.58180,-3.44903,-22.06135,3.42281,22.06135,22412,15
100.55620,-2.47499,-9.37517,2.44877,9.37517,22412,15
101.24480,-2.82097,-17.42644,2.79475,17.42644,22476,15
101.86880,-3.44619,-29.39896,3.41997,29.39896,22476,16
102.19680,-3.77404,-36.83620,3.74782,36.83620,22476,16
102.44380,-4.02106,-42.21195,3.99484,42.21194,22476,16
102.85620,-4.43327,-51.28903,4.40705,51.28903,22476,16
103.28380,-4.86110,-60.77827,4.83488,60.77827,22476,16
103.73780,-5.26627,-69.20640,5.24004,69.20640,22476,16
104.01580,-4.96349,-58.93437,4.93727,58.93437,22412,16
104.35180,-4.62325,-48.73453,4.59703,48.73453,22412,16
104.68880,-4.28598,-39.27853,4.25976,39.27853,22412,16
105.09080,-3.88394,-29.79714,3.85772,29.79714,22412,16
105.55620,-3.41906,-21.40352,3.39284,21.40351,22412,16
106.47880,-2.49592,-9.54309,2.46970,9.54309,22412,16
107.21780,-2.85835,-18.03627,2.83213,18.03627,22476,16
107.79880,-3.44034,-29.22688,3.41412,29.22688,22476,17
108.18680,-3.82817,-37.99982,3.80195,37.99982,22476,17
108.56180,-4.20330,-46.18676,4.17708,46.18676,22476,17
109.06680,-4.70825,-57.24754,4.68203,57.24754,22476,17
109.45620,-5.09716,-65.80961,5.07094,65.80962,22476,17
109.85620,-5.07183,-62.26059,5.04561,62.26059,22476,17
110.17080,-4.74899,-52.27925,4.72277,52.27924,22412,17
110.48280,-4.43624,-43.29977,4.41002,43.29977,22412,17
110.85280,-4.06606,-33.69516,4.03984,33.69516,22412,17
111.26480,-3.65394,-25.27324,3.62772,25.27324,22412,17
112.05580,-2.86298,-13.88869,2.83676,13.88869,22412,17
112.75620,-2.47065,-11.09723,2.44443,11.09723,22412,17
113.32180,-3.04897,-21.26325,3.02274,21.26324,22604,17
113.74280,-3.47037,-29.82595,3.44414,29.82595,22604,18
113.98880,-3.71628,-35.30238,3.69006,35.30238,22604,18
114.34280,-4.07026,-43.27729,4.04404,43.27729,22604,18
114.61280,-4.34046,-49.12457,4.31424,49.12457,22604,18
114.96980,-4.69729,-56.99163,4.67107,56.99163,22604,18
115.35620,-5.08323,-65.50822,5.05700,65.50822,22604,18
115.64680,-5.19516,-66.40803,5.16894,66.40803,22604,18
115.92480,-4.90108,-56.84423,4.87486,56.84423,22540,18
116.19680,-4.62638,-48.74346,4.60016,48.74347,22540,18
116.50780,-4.31513,-39.88406,4.28891,39.88406,22540,18
116.95080,-3.87199,-29.34259,3.84577,29.34259,22540,18
117.64380,-3.17886,-17.80576,3.15264,17.80576,22540,18
118.56880,-2.36758,-8.66973,2.34136,8.66973,22540,18
119.25380,-3.07701,-21.66450,3.05079,21.66450,22604,19
119.60080,-3.42436,-28.60465,3.39814,28.60465,22604,19
119.85080,-3.67417,-34.29576,3.64795,34.29576,22604,19
120.06080,-3.88420,-38.95380,3.85798,38.95380,22604,19
120.22980,-4.05326,-42.76759,4.02704,42.76759,22604,19
120.38780,-4.21138,-46.24541,4.18516,46.24541,22604,19
120.58580,-4.40945,-50.56167,4.38323,50.56167,22604,19
120.79180,-4.61520,-55.05305,4.58898,55.05305,22604,19
121.05620,-4.87928,-60.95006,4.85306,60.95006,22604,19
121.28680,-5.11014,-66.03710,5.08392,66.03709,22604,19
121.63880,-5.11522,-63.52675,5.08900,63.52675,22604,19
121.85180,-4.89379,-56.46073,4.86757,56.46074,22540,19
122.16880,-4.57437,-47.23885,4.54815,47.23885,22540,19
122.38080,-4.36213,-41.09889,4.33591,41.09889,22540,19
122.55080,-4.19205,-36.44720,4.16583,36.44720,22540,19
122.75780,-3.98506,-31.63687,3.95884,31.63687,22540,19
123.05980,-3.68301,-25.55835,3.65679,25.55835,22540,19
123.54880,-3.19386,-18.00468,3.16764,18.00468,22540,19
124.33980,-2.40310,-8.21307,2.37688,8.21307,22540,19
124.58380,-2.32689,-7.82225,2.30067,7.82225,22540,19
124.75980,-2.33115,-8.29955,2.30493,8.29955,22540,19
125.12280,-2.67139,-14.97295,2.64517,14.97295,22476,19
125.49080,-3.04128,-21.30535,3.01506,21.30535,22476,19
125.74980,-3.30047,-26.33652,3.27425,26.33652,22476,20
125.91080,-3.46156,-29.68457,3.43534,29.68457,22476,20
126.08380,-3.63427,-33.57653,3.60805,33.57653,22476,20
126.23080,-3.78141,-36.84660,3.75519,36.84660,22476,20
126.41980,-3.97048,-40.97127,3.94426,40.97127,22476,20
126.55620,-4.10643,-44.03428,4.08021,44.03428,22476,20
126.69480,-4.24552,-47.24915,4.21930,47.24915,22476,20
126.83980,-4.39061,-50.30112,4.36439,50.30112,22476,20
126.99080,-4.54154,-53.52689,4.51531,53.52689,22476,20
127.12280,-4.67341,-56.44956,4.64719,56.44956,22476,20
127.23380,-4.78448,-58.91003,4.75826,58.91003,22476,20
127.40380,-4.95442,-62.67092,4.92819,62.67093,22476,20
127.50080,-5.05136,-64.84020,5.02514,64.84019,22476,20
127.63580,-5.18632,-67.75900,5.16010,67.75900,22476,20
127.78180,-5.24561,-68.23360,5.21939,68.23360,22476,20
127.89680,-5.11498,-63.68668,5.08876,63.68668,22476,20
128.04779,-4.95666,-58.48528,4.93044,58.48528,22412,20
128.18180,-4.82006,-54.37541,4.79384,54.37541,22412,20
128.35880,-4.64166,-49.15571,4.61544,49.15571,22412,20
128.55080,-4.44950,-43.67155,4.42328,43.67155,22412,20
128.78680,-4.21324,-37.12486,4.18702,37.12486,22412,20
129.02680,-3.97328,-31.38237,3.94706,31.38237,22412,20
129.34180,-3.65823,-25.13314,3.63201,25.13314,22412,20
129.84079,-3.15903,-17.52064,3.13281,17.52064,22412,20
130.62280,-2.37724,-7.83592,2.35101,7.83592,22412,20
131.21480,-2.90249,-18.40515,2.87627,18.40515,22476,20
131.75619,-3.44451,-28.90448,3.41829,28.90448,22476,21
132.18580,-3.87436,-38.70004,3.84814,38.70004,22476,21
132.55620,-4.24446,-46.93360,4.21824,46.93360,22476,21
132.97480,-4.66334,-56.10143,4.63712,56.10143,22476,21
133.30480,-4.99333,-63.38819,4.96711,63.38819,22476,21
133.63780,-5.26761,-68.85181,5.24139,68.85181,22476,21
133.96880,-4.91039,-56.91104,4.88417,56.91105,22412,21
134.21980,-4.65677,-49.38298,4.63055,49.38298,22412,21
134.45080,-4.42551,-42.85763,4.39929,42.85763,22412,21
134.76580,-4.11019,-34.33130,4.08396,34.33130,22412,21
135.02280,-3.85321,-28.67202,3.82699,28.67202,22412,21
135.60580,-3.27013,-18.99043,3.24391,18.99043,22412,21
136.20580,-2.67021,-11.42963,2.64399,11.42963,22412,21
136.85780,-2.66824,-14.29830,2.64202,14.29830,22476,21
137.55620,-3.37068,-27.11182,3.34446,27.11182,22476,22
137.90980,-3.72456,-35.14431,3.69834,35.14431,22476,22
138.24280,-4.05755,-42.61646,4.03133,42.61646,22476,22
138.56880,-4.38373,-49.79894,4.35751,49.79893,22476,22
138.76580,-4.58061,-54.17997,4.55439,54.17997,22476,22
139.05180,-4.86657,-60.57002,4.84035,60.57002,22476,22
139.24880,-5.06349,-64.93252,5.03727,64.93252,22476,22
139.45619,-5.27043,-69.45857,5.24421,69.45857,22476,22
139.65619,-5.10285,-63.03676,5.07663,63.03676,22476,22
139.80680,-4.94530,-57.88503,4.91908,57.88503,22412,22
140.01780,-4.73120,-51.55238,4.70498,51.55238,22412,22
140.19680,-4.55173,-46.40330,4.52551,46.40331,22412,22
140.49780,-4.25031,-37.93829,4.22409,37.93829,22412,22
140.67180,-4.07634,-33.47853,4.05012,33.47853,22412,22
140.84780,-3.90041,-29.56652,3.87419,29.56652,22412,22
141.10880,-3.63924,-24.54782,3.61302,24.54782,22412,22
141.65780,-3.09028,-16.47357,3.06405,16.47357,22412,22
142.38280,-2.36534,-7.53941,2.33912,7.53941,22412,22
142.89680,-2.83626,-17.07628,2.81004,17.07628,22476,22
143.38480,-3.32570,-26.22815,3.29948,26.22815,22476,23
143.78080,-3.72163,-34.94774,3.69540,34.94774,22476,23
144.23680,-4.17758,-45.25392,4.15136,45.25392,22476,23
144.62180,-4.56270,-53.69906,4.53648,53.69907,22476,23
144.96680,-4.90760,-61.31186,4.88137,61.31186,22476,23
145.30280,-5.24351,-68.79994,5.21729,68.79994,22476,23
145.52180,-5.09700,-62.84241,5.07078,62.84241,22476,23
145.84480,-4.76460,-52.43114,4.73838,52.43114,22412,23
146.07480,-4.53373,-45.79034,4.50751,45.79034,22412,23
146.33880,-4.26941,-38.44450,4.24319,38.44450,22412,23
146.60580,-4.00237,-31.67166,3.97615,31.67166,22412,23
146.87980,-3.72840,-26.11749,3.70218,26.11749,22412,23
147.32680,-3.28136,-18.95955,3.25514,18.95955,22412,23
147.75619,-2.85240,-13.41863,2.82617,13.41863,22412,23
148.38280,-2.45565,-10.18418,2.42943,10.18418,22412,23
149.09080,-3.17933,-23.25911,3.15311,23.25911,22476,24
149.35880,-3.44770,-28.77764,3.42148,28.77764,22476,24
149.59880,-3.68759,-34.23846,3.66137,34.23846,22476,24
149.85080,-3.93969,-39.82704,3.91347,39.82704,22476,24
150.11280,-4.20165,-45.71438,4.17543,45.71438,22476,24
150.34780,-4.43681,-50.92483,4.41059,50.92483,22476,24
150.57080,-4.65953,-55.85488,4.63331,55.85488,22476,24
150.78380,-4.87258,-60.52860,4.84636,60.52859,22476,24
150.93080,-5.01948,-63.78984,4.99326,63.78984,22476,24
151.11180,-5.20048,-67.80265,5.17426,67.80265,22476,24
151.29880,-5.20213,-66.19962,5.17591,66.19962,22476,24
151.44980,-5.03935,-60.80626,5.01313,60.80626,22476,24
151.65080,-4.83327,-54.35165,4.80705,54.35165,22412,24
151.85620,-4.62671,-48.41912,4.60049,48.41912,22412,24
152.05620,-4.42666,-42.71939,4.40044,42.71939,22412,24
152.28980,-4.19241,-36.22141,4.16619,36.22141,22412,24
152.53580,-3.94653,-30.35151,3.92031,30.35151,22412,24
152.83980,-3.64229,-24.46498,3.61607,24.46498,22412,24
153.25619,-3.22622,-18.20550,3.20000,18.20550,22412,24
153.62780,-2.85440,-13.39211,2.82818,13.39211,22412,24
154.14880,-2.36083,-7.56465,2.33461,7.56465,22412,24
154.76180,-3.00008,-19.79413,2.97386,19.79413,22476,25
155.13080,-3.36970,-26.95936,3.34348,26.95936,22476,25
155.39780,-3.63644,-32.88246,3.61022,32.88246,22476,25
155.63080,-3.86958,-38.23888,3.84336,38.23888,22476,25
155.85080,-4.08956,-43.22756,4.06334,43.22756,22476,25
156.04280,-4.28167,-47.60600,4.25545,47.60600,22476,25
156.24980,-4.48870,-51.99942,4.46248,51.99942,22476,25
156.50680,-4.74563,-57.67818,4.71941,57.67818,22476,25
156.70980,-4.94859,-62.20356,4.92237,62.20356,22476,25
156.92280,-5.16144,-66.86140,5.13522,66.86140,22476,25
157.15180,-5.20933,-66.38697,5.18311,66.38697,22476,25
157.32180,-5.02653,-60.31016,5.00031,60.31016,22476,25
157.47580,-4.86861,-55.38907,4.84239,55.38906,22412,25
157.71180,-4.63065,-48.46900,4.60443,48.46900,22412,25
157.89680,-4.44558,-43.19275,4.41936,43.19275,22412,25
158.10180,-4.24030,-37.47496,4.21408,37.47496,22412,25
158.25980,-4.08231,-33.34013,4.05609,33.34013,22412,25
158.44280,-3.89939,-29.26488,3.87317,29.26488,22412,25
158.67180,-3.67035,-24.83884,3.64413,24.83884,22412,25
159.04480,-3.29737,-19.09467,3.27115,19.09467,22412,25
159.64878,-2.69334,-11.51295,2.66712,11.51295,22412,25
160.29280,-2.66679,-13.91969,2.64057,13.91969,22476,25
160.95619,-3.33470,-26.22548,3.30848,26.22548,22476,26
161.45580,-3.83452,-37.32953,3.80830,37.32953,22476,26
161.87680,-4.25561,-46.97761,4.22939,46.97761,22476,26
162.27280,-4.65149,-55.63514,4.62527,55.63514,22476,26
162.59880,-4.97751,-62.76861,4.95129,62.76861,22476,26
163.04380,-5.19052,-65.52529,5.16430,65.52529,22476,26
163.36680,-4.85344,-54.76582,4.82721,54.76582,22412,26
163.64980,-4.56876,-46.55749,4.54254,46.55749,22412,26
163.96080,-4.25744,-37.78802,4.23122,37.78802,22412,26
164.21480,-4.00343,-31.38568,3.97721,31.38568,22412,26
164.75080,-3.46752,-21.49087,3.44130,21.49087,22412,26
165.52180,-2.69645,-11.46119,2.67023,11.46119,22412,26
166.14080,-2.64004,-13.41782,2.61382,13.41782,22476,26
166.65980,-3.16443,-22.85803,3.13821,22.85803,22476,27
166.96880,-3.47383,-29.06639,3.44761,29.06639,22476,27
167.27280,-3.77775,-35.87281,3.75153,35.87281,22476,27
167.63980,-4.14463,-44.25600,4.11841,44.25600,22476,27
168.04480,-4.54983,-53.23950,4.52361,53.23950,22476,27
168.39680,-4.90172,-61.04151,4.87550,61.04151,22476,27
168.88080,-5.23263,-66.96401,5.20641,66.96400,22476,27
169.19980,-4.89509,-56.00225,4.86887,56.00225,22412,27
169.47580,-4.61682,-47.92191,4.59060,47.92191,22412,27
169.68978,-4.40276,-41.77470,4.37654,41.77470,22412,27
170.00980,-4.08251,-33.20076,4.05629,33.20076,22412,27
170.40280,-3.68957,-25.12744,3.66335,25.12744,22412,27
171.14680,-2.94562,-14.40108,2.91940,14.40108,22412,27
171.71180,-2.38060,-7.43415,2.35438,7.43415,22412,27
172.04480,-2.66494,-13.81214,2.63872,13.81214,22604,27
172.41280,-3.03732,-20.33439,3.01110,20.33439,22604,27
172.79080,-3.41581,-27.76358,3.38959,27.76357,22604,28
172.96280,-3.58769,-31.54100,3.56147,31.54100,22604,28
173.16380,-3.78873,-36.08997,3.76251,36.08997,22604,28
173.53280,-4.15763,-44.32281,4.13141,44.32281,22604,28
173.82780,-4.45290,-51.03416,4.42668,51.03416,22604,28
174.12880,-4.75372,-57.73224,4.72750,57.73223,22604,28
174.39878,-5.02360,-63.71463,4.99738,63.71463,22604,28
174.77280,-5.22080,-66.50273,5.19458,66.50273,22604,28
174.94580,-5.03468,-60.31342,5.00846,60.31342,22540,28
175.16280,-4.81302,-53.43211,4.78680,53.43211,22540,28
175.43180,-4.54284,-45.70955,4.51661,45.70955,22540,28
175.65619,-4.31866,-39.41412,4.29244,39.41412,22540,28
175.85620,-4.11839,-34.02590,4.09217,34.02591,22540,28
176.06478,-3.90960,-29.21975,3.88338,29.21975,22540,28
176.46680,-3.50754,-22.02917,3.48132,22.02917,22540,28
176.82080,-3.15331,-16.93593,3.12709,16.93593,22540,28
177.45680,-2.51754,-9.11973,2.49132,9.11973,22540,28
177.92780,-2.67618,-13.93616,2.64996,13.93616,22604,28
178.28678,-3.03936,-20.35288,3.01314,20.35288,22604,29
178.64878,-3.40185,-27.47327,3.37563,27.47326,22604,29
178.94880,-3.70175,-34.24221,3.67553,34.24221,22604,29
179.21680,-3.96981,-40.26410,3.94358,40.26410,22604,29
179.47480,-4.22782,-46.14155,4.20160,46.14155,22604,29
179.71580,-4.46892,-51.38471,4.44270,51.38471,22604,29
180.00980,-4.76277,-57.86419,4.73655,57.86419,22604,29
180.29380,-5.04665,-64.14797,5.02043,64.14797,22604,29
180.70180,-5.16196,-64.48925,5.13574,64.48925,22604,29
181.00780,-4.84450,-54.41194,4.81828,54.41195,22540,29
181.37280,-4.47785,-43.89789,4.45163,43.89788,22540,29
181.76580,-4.08462,-33.12660,4.05840,33.12660,22540,29
182.14280,-3.70770,-25.24830,3.68147,25.24830,22540,29
182.65619,-3.19451,-17.40192,3.16829,17.40192,22540,29
183.37480,-2.47573,-8.55644,2.44951,8.55644,22540,29
183.84680,-2.37095,-8.26608,2.34473,8.26608,22540,29
184.30580,-2.80132,-16.52602,2.77510,16.52602,22476,29
184.71380,-3.21018,-23.91929,3.18396,23.91929,22476,30
185.09480,-3.59125,-31.82876,3.56503,31.82876,22476,30
185.45280,-3.94939,-39.87887,3.92317,39.87887,22476,30
185.87680,-4.37346,-49.26636,4.34724,49.26636,22476,30
186.24380,-4.74034,-57.45347,4.71412,57.45347,22476,30
186.65619,-5.15216,-66.65453,5.12594,66.65453,22476,30
186.93978,-5.15791,-64.59370,5.13169,64.59370,22476,30
187.17880,-4.90796,-56.52824,4.88174,56.52824,22412,30
187.50480,-4.57936,-46.97557,4.55314,46.97557,22412,30
187.75878,-4.32517,-39.72962,4.29895,39.72962,22412,30
188.00380,-4.07999,-33.16282,4.05377,33.16282,22412,30
188.50780,-3.57601,-23.03113,3.54979,23.03113,22412,30
189.05620,-3.02798,-15.31631,3.00176,15.31631,22412,30
189.85580,-2.50001,-10.68324,2.47379,10.68324,22412,30
190.35620,-3.01363,-19.77995,2.98741,19.77995,22476,31
190.85620,-3.51412,-29.89670,3.48790,29.89670,22476,31
191.11880,-3.77715,-35.77096,3.75093,35.77097,22476,31
191.40380,-4.06213,-42.26328,4.03591,42.26328,22476,31
191.60480,-4.26318,-46.89412,4.23696,46.89412,22476,31
191.92880,-4.58721,-53.88508,4.56099,53.88508,22476,31
192.17480,-4.83323,-59.40385,4.80701,59.40385,22476,31
192.59780,-5.25608,-68.85836,5.22986,68.85836,22476,31
192.89380,-5.05498,-60.99379,5.02876,60.99379,22476,31
193.15619,-4.78725,-52.70035,4.76103,52.70035,22412,31
193.46480,-4.47717,-43.86432,4.45095,43.86432,22412,31
193.75580,-4.18601,-35.75032,4.15979,35.75032,22412,31
193.98680,-3.95516,-30.12314,3.92893,30.12314,22412,31
194.30480,-3.63688,-23.98332,3.61066,23.98332,22412,31
194.85480,-3.08692,-16.04942,3.06069,16.04942,22412,31
195.59680,-2.38436,-7.66023,2.35814,7.66023,22412,31
196.30680,-3.12283,-21.83635,3.09661,21.83635,22476,32
196.69780,-3.51408,-29.82020,3.48786,29.82020,22476,32
197.01580,-3.83207,-37.02166,3.80585,37.02166,22476,32
197.33080,-4.14702,-44.06338,4.12079,44.06338,22476,32
197.65680,-4.47329,-51.40841,4.44707,51.40841,22476,32
197.97680,-4.79322,-58.53477,4.76700,58.53477,22476,32
198.26078,-5.07702,-64.82377,5.05080,64.82377,22476,32
198.62880,-5.17740,-64.94187,5.15118,64.94187,22476,32
199.01980,-4.77309,-52.22697,4.74687,52.22697,22412,32
199.36480,-4.42725,-42.32536,4.40103,42.32536,22412,32
199.83380,-3.95813,-30.08310,3.93191,30.08310,22412,32
200.65619,-3.13581,-16.60197,3.10959,16.60197,22412,32
201.55620,-2.49552,-10.46062,2.46930,10.46062,22412,32
202.30580,-3.26002,-24.34109,3.23380,24.34109,22476,33
202.65619,-3.61010,-31.88034,3.58388,31.88034,22476,33
203.00380,-3.95827,-39.75153,3.93205,39.75153,22476,33
203.32380,-4.27825,-47.08679,4.25203,47.08680,22476,33
203.55620,-4.51028,-52.11125,4.48406,52.11124,22476,33
203.94178,-4.89621,-60.80402,4.86999,60.80402,22476,33
204.33580,-5.29014,-69.47209,5.26391,69.47209,22476,33
204.61180,-5.04651,-60.52889,5.02029,60.52889,22476,33
204.96080,-4.69161,-49.78400,4.66539,49.78400,22412,33
205.27880,-4.37313,-40.74463,4.34691,40.74463,22412,33
205.56678,-4.08499,-33.01926,4.05877,33.01926,22412,33
205.83680,-3.81505,-26.99957,3.78883,26.99957,22412,33
206.23278,-3.41913,-20.39457,3.39290,20.39457,22412,33
206.66880,-2.98299,-14.63636,2.95677,14.63636,22412,33
207.16280,-2.48906,-8.58566,2.46284,8.58566,22412,33
207.55620,-2.67272,-13.58091,2.64650,13.58091,22476,33
207.91178,-3.03369,-19.90643,3.00747,19.90643,22476,33
208.26280,-3.38523,-26.79430,3.35901,26.79430,22476,34
208.47180,-3.59408,-31.44921,3.56786,31.44921,22476,34
208.66080,-3.78313,-35.76354,3.75691,35.76353,22476,34
208.87980,-4.00209,-40.75311,3.97587,40.75311,22476,34
209.03980,-4.16207,-44.33227,4.13585,44.33227,22476,34
209.18780,-4.31034,-47.82756,4.28412,47.82756,22476,34
209.37580,-4.49824,-51.89474,4.47202,51.89474,22476,34
209.56280,-4.68513,-56.10898,4.65891,56.10898,22476,34
209.76180,-4.88415,-60.56996,4.85793,60.56997,22476,34
209.92480,-5.04701,-64.18546,5.02079,64.18546,22476,34
210.12078,-5.24304,-68.41407,5.21682,68.41407,22476,34
210.32480,-5.16260,-64.43062,5.13638,64.43063,22476,34
210.53980,-4.93733,-57.16327,4.91111,57.16327,22412,34
210.81678,-4.65739,-48.80346,4.63117,48.80346,22412,34
211.07480,-4.39917,-41.54597,4.37295,41.54597,22412,34
211.33680,-4.13679,-34.40501,4.11057,34.40501,22412,34
211.65619,-3.81802,-27.00131,3.79180,27.00131,22412,34
212.41178,-3.06190,-15.52255,3.03568,15.52255,22412,34
213.09880,-2.38113,-7.17510,2.35490,7.17510,22412,34
213.75619,-3.04963,-20.18358,3.02341,20.18358,22476,35
214.15980,-3.45414,-28.24360,3.42792,28.24360,22476,35
214.50980,-3.80404,-36.16945,3.77782,36.16945,22476,35
214.77980,-4.07402,-42.31008,4.04780,42.31008,22476,35
215.05620,-4.35025,-48.55539,4.32403,48.55539,22476,35
215.33780,-4.63199,-54.84134,4.60577,54.84134,22476,35
215.64878,-4.94303,-61.85147,4.91681,61.85147,22476,35
215.95619,-5.24997,-68.53388,5.22375,68.53388,22476,35
216.11380,-5.23124,-66.65620,5.20502,66.65620,22476,35
216.28380,-5.04825,-60.54506,5.02203,60.54506,22412,35
216.47780,-4.84972,-54.34219,4.82350,54.34219,22412,35
216.67980,-4.64630,-48.44006,4.62008,48.44006,22412,35
216.95619,-4.37010,-40.54267,4.34388,40.54267,22412,35
217.19280,-4.13285,-34.24716,4.10663,34.24716,22412,35
217.43480,-3.89101,-28.42023,3.86479,28.42023,22412,35
217.99778,-3.32805,-19.01725,3.30183,19.01725,22412,35
218.65619,-2.66992,-10.81296,2.64370,10.81296,22412,35
219.35620,-2.81409,-16.05014,2.78787,16.05014,22476,35
219.91580,-3.37631,-26.60430,3.35009,26.60430,22476,36
220.30780,-3.76819,-35.35290,3.74197,35.35290,22476,36
220.69480,-4.15514,-44.14004,4.12892,44.14005,22476,36
221.01880,-4.47939,-51.42504,4.45317,51.42504,22476,36
221.39480,-4.85526,-59.84195,4.82904,59.84195,22476,36
221.67380,-5.13406,-66.01329,5.10784,66.01329,22476,36
221.91178,-5.26343,-67.85175,5.23721,67.85175,22476,36
222.14180,-5.01325,-59.45974,4.98703,59.45974,22412,36
222.32978,-4.82165,-53.49282,4.79543,53.49282,22412,36
222.47780,-4.67260,-49.21355,4.64638,49.21355,22412,36
222.59278,-4.55744,-45.93484,4.53122,45.93484,22412,36
222.70780,-4.44236,-42.72168,4.41614,42.72168,22412,36
222.85978,-4.29022,-38.54584,4.26400,38.54584,22412,36
222.97180,-4.17812,-35.36498,4.15190,35.36498,22412,36
223.08680,-4.06314,-32.33333,4.03692,32.33332,22412,36
223.28980,-3.86009,-27.72541,3.83387,27.72541,22412,36
223.48780,-3.66208,-24.16672,3.63586,24.16672,22412,36
223.81880,-3.33125,-19.00510,3.30503,19.00510,22412,36
224.45619,-2.69411,-11.02399,2.66789,11.02399,22412,36
224.97280,-2.60669,-12.31620,2.58047,12.31620,22412,36
225.44580,-3.08803,-20.91313,3.06181,20.91313,22476,37
225.87380,-3.51640,-29.68118,3.49018,29.68118,22476,37
226.07580,-3.71838,-34.27355,3.69216,34.27355,22476,37
226.26278,-3.90531,-38.65126,3.87909,38.65126,22476,37
226.55620,-4.19856,-44.99947,4.17234,44.99947,22476,37
226.76480,-4.40760,-49.78684,4.38138,49.78683,22476,37
226.98680,-4.62936,-54.86718,4.60314,54.86718,22476,37
227.22180,-4.86445,-60.17558,4.83823,60.17558,22476,37
227.49578,-5.13825,-66.04326,5.11203,66.04326,22476,37
227.71280,-5.29270,-68.88580,5.26648,68.88580,22476,37
227.93380,-5.04867,-60.45164,5.02245,60.45164,22476,37
228.15980,-4.81781,-53.33590,4.79159,53.33590,22412,37
228.37880,-4.59761,-47.10912,4.57139,47.10912,22412,37
228.67580,-4.30047,-38.65984,4.27425,38.65984,22412,37
228.93280,-4.04341,-31.68099,4.01719,31.68099,22412,37
229.47580,-3.50033,-21.55323,3.47411,21.55323,22412,37
230.29078,-2.68536,-10.81300,2.65914,10.81300,22412,37
230.93680,-2.76634,-15.08103,2.74012,15.08103,22604,37
231.60280,-3.43567,-27.79752,3.40945,27.79752,22604,38
232.02680,-3.85945,-37.53306,3.83323,37.53306,22604,38
232.44080,-4.27367,-46.82052,4.24745,46.82052,22604,38
232.94178,-4.77464,-57.99562,4.74842,57.99562,22604,38
233.32280,-5.15543,-66.26675,5.12921,66.26675,22604,38
233.60380,-5.19614,-65.28182,5.16992,65.28181,22604,38
233.95080,-4.83512,-53.69494,4.80890,53.69495,22540,38
234.23680,-4.54779,-45.36771,4.52157,45.36771,22540,38
234.55280,-4.23146,-36.60063,4.20524,36.60063,22540,38
234.85680,-3.92767,-29.05460,3.90145,29.05460,22540,38
235.45380,-3.33061,-18.98254,3.30439,18.98254,22540,38
236.08780,-2.69653,-10.95355,2.67031,10.95356,22540,38
236.85620,-2.88320,-17.02734,2.85698,17.02734,22604,38
237.45619,-3.48478,-28.79102,3.45856,28.79102,22604,39
237.82978,-3.85864,-37.35067,3.83242,37.35067,22604,39
238.23278,-4.26180,-46.52010,4.23558,46.52010,22604,39
238.63180,-4.66067,-55.32871,4.63445,55.32871,22604,39
239.01278,-5.04162,-63.78943,5.01540,63.78943,22604,39
239.32180,-5.30227,-69.05703,5.27605,69.05703,22604,39
239.56280,-5.03746,-59.88910,5.01124,59.88910,22540,39
239.85880,-4.73639,-50.84883,4.71017,50.84883,22540,39
240.29880,-4.29577,-38.37041,4.26955,38.37041,22540,39
240.85620,-3.73864,-25.31685,3.71242,25.31685,22540,39
241.72280,-2.87165,-13.02642,2.84543,13.02642,22540,39
242.65619,-2.44315,-9.38743,2.41693,9.38743,22540,39
243.32680,-3.12707,-21.90992,3.10085,21.90992,22476,39
243.66680,-3.46737,-28.74005,3.44115,28.74005,22476,40
244.04480,-3.84520,-37.29058,3.81898,37.29058,22476,40
244.31180,-4.11221,-43.41162,4.08599,43.41162,22476,40
244.55680,-4.35743,-48.96031,4.33121,48.96031,22476,40
244.77880,-4.57933,-53.87572,4.55311,53.87572,22476,40
245.09180,-4.89228,-60.79148,4.86606,60.79148,22476,40
245.37980,-5.18008,-66.98386,5.15386,66.98386,22476,40
245.62478,-5.19956,-65.60296,5.17334,65.60296,22476,40
245.80280,-5.01025,-59.27154,4.98402,59.27154,22412,40
245.99080,-4.81868,-53.37091,4.79246,53.37091,22412,40
246.23680,-4.57146,-46.26200,4.54524,46.26200,22412,40
246.47178,-4.33629,-39.63211,4.31006,39.63211,22412,40
246.70280,-4.10507,-33.39290,4.07885,33.39290,22412,40
246.96680,-3.84116,-27.24169,3.81494,27.24169,22412,40
247.50878,-3.29919,-18.57888,3.27297,18.57888,22412,40
248.39580,-2.41229,-7.38407,2.38607,7.38407,22412,40
249.09278,-3.06694,-20.40243,3.04072,20.40243,22476,41
249.57978,-3.55435,-30.31784,3.52813,30.31784,22476,41
249.92580,-3.90035,-38.28551,3.87413,38.28551,22476,41
250.30480,-4.27947,-46.86327,4.25325,46.86327,22476,41
250.72280,-4.69735,-56.15272,4.67113,56.15273,22476,41
251.22980,-5.20425,-67.28400,5.17803,67.28400,22476,41
251.59780,-5.06916,-60.89247,5.04294,60.89247,22476,41
252.09478,-4.56560,-45.82093,4.53938,45.82093,22412,41
252.55480,-4.10520,-33.17666,4.07898,33.17666,22412,41
253.08680,-3.57331,-22.57263,3.54709,22.57263,22412,41
254.11180,-2.54831,-9.00832,2.52209,9.00832,22412,41
254.85880,-2.99498,-18.99915,2.96876,18.99915,22476,41
255.50680,-3.64349,-32.16421,3.61727,32.16421,22476,42
256.09878,-4.23570,-45.74127,4.20947,45.74127,22476,42
256.65878,-4.79570,-58.23795,4.76948,58.23795,22476,42
257.20678,-5.31817,-69.69906,5.29195,69.69907,22476,42
257.62280,-4.87750,-54.87832,4.85128,54.87832,22412,42
257.95620,-4.54277,-45.22364,4.51655,45.22364,22412,42
258.33078,-4.16744,-34.88076,4.14122,34.88076,22412,42
258.69080,-3.80757,-26.54712,3.78135,26.54712,22412,42
259.56080,-2.93761,-13.66799,2.91139,13.66799,22412,42
260.35380,-2.66010,-13.03359,2.63388,13.03359,22412,42
261.06778,-3.38082,-26.45669,3.35460,26.45669,22476,43
261.52478,-3.83766,-36.60135,3.81144,36.60135,22476,43
261.81680,-4.12964,-43.35263,4.10342,43.35263,22476,43
262.14280,-4.45596,-50.74923,4.42974,50.74923,22476,43
262.47278,-4.78580,-58.23306,4.75958,58.23306,22476,43
262.74578,-5.05861,-64.19160,5.03239,64.19160,22476,43
262.95778,-5.27068,-68.80046,5.24446,68.80046,22476,43
263.19681,-5.13384,-63.01408,5.10762,63.01408,22476,43
263.42778,-4.89493,-55.38034,4.86871,55.38034,22412,43
263.68781,-4.63290,-47.80202,4.60667,47.80202,22412,43
263.94778,-4.37277,-40.37369,4.34655,40.37369,22412,43
264.28878,-4.03166,-31.08482,4.00544,31.08482,22412,43
264.95081,-3.36975,-19.35203,3.34353,19.35203,22412,43
265.88981,-2.43085,-7.41651,2.40463,7.41651,22412,43
266.63378,-3.12864,-21.47456,3.10242,21.47456,22476,44
267.14578,-3.64084,-31.98607,3.61462,31.98607,22476,44
267.65619,-4.15092,-43.80007,4.12470,43.80007,22476,44
268.16678,-4.66190,-55.27828,4.63568,55.27828,22476,44
268.70678,-5.20185,-67.30919,5.17563,67.30919,22476,44
269.02178,-5.12246,-62.63158,5.09624,62.63158,22476,44
269.35778,-4.77789,-52.02300,4.75167,52.02300,22412,44
269.77178,-4.36297,-40.09679,4.33675,40.09679,22412,44
270.33578,-3.79890,-26.27249,3.77268,26.27249,22412,44
271.30781,-2.82692,-12.39300,2.80070,12.39300,22412,44
272.15619,-2.82292,-15.98503,2.79670,15.98503,22476,44
272.89778,-3.56701,-30.34261,3.54079,30.34262,22476,45
273.44181,-4.11104,-42.88508,4.08482,42.88507,22476,45
273.99978,-4.66900,-55.36745,4.64278,55.36745,22476,45
274.55881,-5.22796,-67.78579,5.20174,67.78579,22476,45
274.97278,-4.99618,-58.47007,4.96996,58.47007,22412,45
275.55578,-4.40912,-41.33446,4.38290,41.33446,22412,45
276.00681,-3.95803,-29.29904,3.93181,29.29904,22412,45
276.85619,-3.10877,-15.81562,3.08255,15.81562,22412,45
277.76881,-2.63161,-12.41774,2.60539,12.41774,22412,45
278.48378,-3.35525,-25.75462,3.32903,25.75462,22476,46
278.94878,-3.82015,-35.99213,3.79393,35.99213,22476,46
279.37078,-4.24222,-45.75968,4.21600,45.75968,22476,46
279.74381,-4.61515,-54.15415,4.58893,54.15416,22476,46
280.16678,-5.03807,-63.68386,5.01185,63.68386,22476,46
280.43681,-5.30820,-69.54172,5.28198,69.54173,22476,46
280.75078,-5.03324,-59.55429,5.00701,59.55429,22476,46
281.06478,-4.71463,-49.88440,4.68841,49.88440,22412,46
281.35619,-4.42331,-41.63375,4.39709,41.63375,22412,46
281.65619,-4.12292,-33.51636,4.09670,33.51636,22412,46
281.95978,-3.81911,-26.59400,3.79289,26.59400,22412,46
282.45881,-3.32020,-18.64869,3.29398,18.64869,22412,46
283.25619,-2.52307,-8.52155,2.49685,8.52155,22412,46
283.86781,-2.94828,-18.02416,2.92206,18.02416,22476,46
284.35678,-3.43847,-27.37326,3.41225,27.37326,22476,47
284.79278,-3.87429,-37.26823,3.84807,37.26823,22476,47
285.09978,-4.18137,-44.38648,4.15515,44.38648,22476,47
285.40378,-4.48553,-51.29198,4.45931,51.29198,22476,47
285.65619,-4.73742,-56.89382,4.71120,56.89382,22476,47
285.92178,-5.00331,-62.87687,4.97709,62.87687,22476,47
286.25619,-5.31195,-69.32557,5.28573,69.32558,22476,47
286.47078,-5.07782,-61.08415,5.05160,61.08415,22476,47
286.79481,-4.74708,-51.01345,4.72086,51.01345,22412,47
287.15378,-4.38745,-40.64601,4.36123,40.64601,22412,47
287.45881,-4.08228,-32.44891,4.05606,32.44891,22412,47
287.99478,-3.54633,-21.94981,3.52011,21.94981,22412,47
288.75478,-2.78630,-11.85705,2.76007,11.85705,22412,47
289.32278,-2.61279,-11.99275,2.58657,11.99275,22412,47
289.88081,-3.18019,-22.26299,3.15397,22.26299,22604,47
290.34478,-3.64439,-31.93555,3.61817,31.93555,22604,48
290.71381,-4.01346,-40.49355,3.98724,40.49355,22604,48
291.17678,-4.47674,-51.35066,4.45052,51.35067,22604,48
291.67978,-4.97952,-62.43082,4.95330,62.43082,22604,48
292.03378,-5.31906,-69.59132,5.29284,69.59132,22604,48
292.40281,-4.93141,-56.40650,4.90519,56.40650,22540,48
292.82878,-4.50266,-43.92113,4.47644,43.92113,22540,48
293.25581,-4.07544,-32.31751,4.04922,32.31751,22540,48
293.95622,-3.37555,-19.22462,3.34933,19.22462,22540,48
294.84478,-2.48650,-8.03186,2.46028,8.03186,22540,48
295.55619,-3.07934,-20.27094,3.05312,20.27094,22604,49
296.16878,-3.69287,-33.15331,3.66665,33.15331,22604,49
296.60378,-4.12777,-43.17596,4.10155,43.17596,22604,49
297.18878,-4.71287,-56.36277,4.68665,56.36277,22604,49
297.72478,-5.24873,-68.19297,5.22251,68.19296,22604,49
298.05278,-5.07771,-61.02935,5.05149,61.02935,22604,49
298.40978,-4.71433,-49.92629,4.68811,49.92629,22540,49
298.78681,-4.33691,-39.34890,4.31069,39.34890,22540,49
299.35619,-3.76781,-25.54332,3.74159,25.54332,22540,49
300.39678,-2.72671,-11.00346,2.70049,11.00346,22540,49
301.30781,-2.64710,-13.02086,2.62088,13.02086,22540,49
302.08881,-3.43255,-27.48938,3.40633,27.48938,22476,50
302.50778,-3.85132,-37.07171,3.82510,37.07171,22476,50
302.79278,-4.13631,-43.57860,4.11009,43.57860,22476,50
303.39278,-4.73646,-57.12021,4.71024,57.12021,22476,50
303.83578,-5.17925,-66.87917,5.15303,66.87917,22476,50
304.18681,-5.11528,-62.31010,5.08906,62.31010,22476,50
304.53378,-4.76015,-51.38434,4.73393,51.38434,22412,50
305.00378,-4.28940,-38.17174,4.26318,38.17174,22412,50
305.63981,-3.65325,-23.58038,3.62702,23.58038,22412,50
306.56878,-2.72421,-10.98829,2.69799,10.98829,22412,50
307.35619,-2.90822,-17.26548,2.88200,17.26548,22476,50
308.05478,-3.60855,-31.16710,3.58233,31.16710,22476,51
308.49281,-4.04658,-41.16192,4.02036,41.16192,22476,51
308.91678,-4.47089,-51.06852,4.44467,51.06852,22476,51
309.29081,-4.84472,-59.41128,4.81850,59.41128,22476,51
309.74281,-5.29668,-69.20425,5.27046,69.20425,22476,51
310.02781,-5.06005,-60.46523,5.03383,60.46523,22476,51
310.33881,-4.74334,-50.85342,4.71712,50.85342,22412,51
310.67081,-4.41086,-41.34643,4.38464,41.34644,22412,51
311.01378,-4.06761,-31.97300,4.04139,31.97300,22412,51
311.61078,-3.47069,-20.66855,3.44447,20.66855,22412,51
312.35619,-2.72553,-10.90792,2.69931,10.90792,22412,51
313.19181,-2.94286,-17.95657,2.91663,17.95657,22476,51
313.82178,-3.57388,-30.37621,3.54766,30.37621,22476,52
314.30078,-4.05278,-41.29091,4.02656,41.29091,22476,52
314.85619,-4.60788,-53.99816,4.58166,53.99817,22476,52
315.42978,-5.18174,-66.76143,5.15552,66.76144,22476,52
315.84578,-5.05592,-60.34220,5.02970,60.34220,22476,52
316.25619,-4.64013,-47.93720,4.61391,47.93720,22412,52
316.56681,-4.32902,-39.18803,4.30280,39.18803,22412,52
316.84778,-4.04791,-31.53704,4.02169,31.53704,22412,52
317.20678,-3.68894,-24.06507,3.66272,24.06507,22412,52
317.95778,-2.93801,-13.44487,2.91179,13.44487,22412,52
318.75619,-2.72305,-13.79308,2.69683,13.79308,22476,52
319.48178,-3.45434,-27.71019,3.42812,27.71019,22476,53
319.92278,-3.89517,-37.75736,3.86895,37.75736,22476,53
320.29378,-4.26624,-46.36027,4.24002,46.36027,22476,53
320.67081,-4.64313,-54.85750,4.61691,54.85749,22476,53
321.11481,-5.08712,-64.71792,5.06090,64.71792,22476,53
321.50378,-5.16473,-64.09420,5.13851,64.09420,22476,53
321.87878,-4.77826,-51.99907,4.75204,51.99907,22412,53
322.25378,-4.40241,-41.26258,4.37619,41.26258,22412,53
322.62878,-4.02718,-31.12768,4.00096,31.12768,22412,53
323.15878,-3.49716,-20.93560,3.47094,20.93560,22412,53
323.95778,-2.69813,-10.51160,2.67191,10.51160,22412,53
324.73778,-2.95349,-18.02533,2.92727,18.02533,22476,53
325.38278,-3.59946,-30.72675,3.57324,30.72675,22476,54
325.96878,-4.18555,-44.35915,4.15933,44.35915,22476,54
326.45619,-4.67252,-55.61315,4.64630,55.61315,22476,54
326.99078,-5.20748,-67.48156,5.18126,67.48155,22476,54
327.35619,-5.05089,-60.38513,5.02467,60.38513,22476,54
327.71478,-4.68595,-49.32394,4.65973,49.32394,22412,54
328.07981,-4.32056,-39.12115,4.29434,39.12115,22412,54
328.38678,-4.01343,-30.83784,3.98721,30.83784,22412,54
328.99281,-3.40757,-19.50745,3.38135,19.50745,22412,54
329.75619,-2.64424,-9.84066,2.61802,9.84066,22412,54
330.35619,-2.84234,-15.97636,2.81612,15.97636,22476,54
330.96281,-3.45200,-27.43904,3.42578,27.43904,22476,55
331.22378,-3.71288,-33.37308,3.68666,33.37309,22476,55
331.56281,-4.05183,-41.18901,4.02561,41.18901,22476,55
331.90478,-4.39406,-49.21529,4.36784,49.21529,22476,55
332.28378,-4.77298,-57.75007,4.74676,57.75007,22476,55
332.64278,-5.13172,-65.81903,5.10550,65.81903,22476,55
332.95278,-5.18257,-64.98248,5.15635,64.98248,22476,55
333.20578,-4.91763,-56.29815,4.89141,56.29815,22412,55
333.49078,-4.63005,-47.95728,4.60383,47.95728,22412,55
333.81681,-4.30390,-38.80673,4.27768,38.80672,22412,55
334.21281,-3.90788,-28.23112,3.88165,28.23112,22412,55
335.12978,-2.99075,-13.95829,2.96453,13.95829,22412,55
335.95619,-2.71947,-13.62644,2.69325,13.62644,22412,55
336.67978,-3.44929,-27.34603,3.42307,27.34603,22476,56
337.06181,-3.83107,-36.16754,3.80485,36.16754,22476,56
337.66478,-4.43442,-50.12105,4.40820,50.12105,22476,56
338.22581,-4.99510,-62.82263,4.96888,62.82263,22476,56
338.68178,-5.16881,-64.44101,5.14259,64.44101,22476,56
339.10081,-4.73677,-50.94099,4.71055,50.94099,22412,56
339.56378,-4.27309,-37.90955,4.24687,37.90955,22412,56
340.10981,-3.72704,-24.44194,3.70082,24.44194,22412,56
341.06681,-2.76995,-11.45330,2.74373,11.45329,22412,56
341.85619,-2.90768,-17.08839,2.88146,17.08839,22476,56
342.49178,-3.54528,-29.55002,3.51906,29.55002,22476,57
342.94778,-4.00137,-39.92228,3.97515,39.92228,22476,57
343.41378,-4.46756,-50.69996,4.44134,50.69996,22476,57
344.05619,-5.10928,-65.24660,5.08306,65.24660,22476,57
344.40078,-5.19506,-65.04528,5.16884,65.04528,22476,57
344.75619,-4.82675,-53.32374,4.80053,53.32374,22412,57
345.15681,-4.42455,-41.78496,4.39833,41.78496,22412,57
345.58781,-3.99328,-30.23758,3.96706,30.23758,22412,57
346.50681,-3.07423,-15.10813,3.04801,15.10813,22412,57
347.36478,-2.65405,-12.38893,2.62783,12.38893,22412,57
348.15281,-3.45071,-27.35071,3.42449,27.35070,22604,58
348.65619,-3.95361,-39.13437,3.92739,39.13437,22604,58
349.15478,-4.45275,-50.36388,4.42653,50.36388,22604,58
349.71878,-5.01652,-62.93351,4.99030,62.93351,22604,58
350.23081,-5.13614,-62.82479,5.10992,62.82479,22604,58
350.55678,-4.80166,-52.36255,4.77544,52.36255,22540,58
350.82278,-4.53479,-44.71809,4.50856,44.71809,22540,58
351.20481,-4.15244,-34.21728,4.12622,34.21728,22540,58
351.80478,-3.55253,-21.71386,3.52630,21.71386,22540,58
352.89481,-2.46258,-7.46952,2.43636,7.46952,22540,58
353.59878,-3.12041,-21.00647,3.09419,21.00647,22604,59
354.23081,-3.75281,-34.22338,3.72659,34.22338,22604,59
354.71078,-4.23296,-45.23857,4.20674,45.23857,22604,59
355.18281,-4.70491,-55.93382,4.67869,55.93382,22604,59
355.78681,-5.30887,-69.45576,5.28265,69.45576,22604,59
356.17381,-4.96717,-57.35383,4.94095,57.35383,22540,59
356.63278,-4.50501,-43.84638,4.47879,43.84638,22540,59
357.06281,-4.07483,-32.15369,4.04861,32.15369,22540,59
357.68378,-3.45397,-20.08979,3.42775,20.08979,22540,59
358.73178,-2.42614,-7.06813,2.39992,7.06813,22540,59