File: data-raw/Experiment 2/Results/INSTRON data/Experiment 2.is_ccyclic_RawData/Specimen_RawData_20.csv
Text Inputs : Specimen label,""

Time,Extension,Load,Compressive extension,Compressive load,Segment ID,Total Cycle Count
(sec),(mm),(N),(mm),(N),,
0.00000,-0.02624,0.02746,0.00000,-0.02746,12835,0
0.63480,-0.02624,0.00670,0.00000,-0.00670,12835,0
1.20380,-0.02624,0.01185,0.00000,-0.01185,3220,0
1.66480,-0.24593,-0.00737,0.21969,0.00737,3220,0
2.30580,-0.56671,0.02574,0.54047,-0.02574,3220,0
2.74680,-0.78735,0.00474,0.76111,-0.00474,3220,0
3.26580,-1.04665,-0.29591,1.02041,0.29591,3220,0
3.90280,-1.36554,-6.80622,1.33930,6.80622,3220,0
4.39120,-1.85109,-15.02723,1.82485,15.02723,22476,0
4.89120,-2.35147,-22.80256,2.32523,22.80256,22476,0
5.33080,-2.79138,-31.12540,2.76514,31.12540,22476,0
5.73180,-3.19223,-39.62552,3.16599,39.62552,22476,0
6.13780,-3.59833,-48.14612,3.57209,48.14613,22476,0
6.56680,-4.02735,-56.69836,4.00111,56.69836,22476,0
6.94280,-4.40357,-64.08428,4.37733,64.08428,22476,0
7.27680,-4.69428,-69.31829,4.66804,69.31829,22476,0
7.51180,-4.43634,-60.11505,4.41010,60.11505,22412,0
7.80280,-4.14004,-50.98901,4.11380,50.98901,22412,0
8.12280,-3.81942,-41.83070,3.79318,41.83070,22412,0
8.47180,-3.47026,-33.05780,3.44402,33.05780,22412,0
8.87380,-3.06801,-24.13797,3.04177,24.13797,22412,0
9.35380,-2.58813,-16.09638,2.56189,16.09638,22412,0
9.89120,-2.05108,-8.50247,2.02484,8.50247,22412,0
10.23880,-2.19632,-13.15711,2.17008,13.15711,22412,0
10.65280,-2.61687,-21.52806,2.59063,21.52806,22476,1
11.02480,-2.98930,-29.91985,2.96306,29.91985,22476,1
11.35880,-3.32339,-38.08856,3.29715,38.08856,22476,1
11.69120,-3.65539,-45.85449,3.62915,45.85449,22476,1
12.07880,-4.04321,-54.60669,4.01697,54.60669,22476,1
12.47580,-4.44036,-63.14844,4.41412,63.14844,22476,1
12.84480,-4.74206,-68.72891,4.71582,68.72891,22476,1
13.09120,-4.47245,-59.26895,4.44621,59.26895,22412,1
13.39080,-4.16778,-49.95777,4.14154,49.95777,22412,1
13.69120,-3.86746,-41.26825,3.84122,41.26825,22412,1
14.03880,-3.51918,-32.43593,3.49294,32.43593,22412,1
14.44280,-3.11513,-23.64378,3.08889,23.64378,22412,1
14.93180,-2.62618,-15.68567,2.59994,15.68567,22412,1
15.49120,-2.06702,-7.78151,2.04078,7.78151,22412,1
15.82380,-2.28671,-13.70337,2.26046,13.70337,22476,1
16.24180,-2.70992,-22.22195,2.68368,22.22195,22476,2
16.60980,-3.07799,-30.65711,3.05175,30.65711,22476,2
16.97580,-3.44429,-39.66596,3.41805,39.66596,22476,2
17.32980,-3.79839,-48.06111,3.77215,48.06111,22476,2
17.70280,-4.17124,-56.43530,4.14500,56.43530,22476,2
18.10980,-4.57813,-65.24322,4.55189,65.24323,22476,2
18.39980,-4.74158,-67.38665,4.71534,67.38665,22476,2
18.66980,-4.45189,-57.60904,4.42565,57.60904,22412,2
18.97580,-4.14253,-48.35013,4.11629,48.35013,22412,2
19.28180,-3.83632,-39.51421,3.81008,39.51421,22412,2
19.55880,-3.55904,-32.50339,3.53280,32.50338,22412,2
19.96280,-3.15500,-23.71040,3.12876,23.71040,22412,2
20.45980,-2.65806,-15.67275,2.63181,15.67275,22412,2
20.99120,-2.12705,-8.08418,2.10081,8.08418,22412,2
21.36080,-2.38062,-14.76203,2.35438,14.76203,22476,2
21.77080,-2.79478,-23.19842,2.76854,23.19842,22476,3
22.11880,-3.14299,-31.33032,3.11675,31.33032,22476,3
22.48980,-3.51408,-40.45102,3.48784,40.45102,22476,3
22.85580,-3.88021,-49.20266,3.85397,49.20266,22476,3
23.23780,-4.26221,-57.74969,4.23597,57.74969,22476,3
23.62380,-4.64812,-66.15144,4.62188,66.15144,22476,3
23.89480,-4.73154,-66.20257,4.70530,66.20258,22476,3
24.17380,-4.43688,-56.43151,4.41063,56.43151,22412,3
24.47480,-4.13328,-47.46040,4.10704,47.46040,22412,3
24.79120,-3.81707,-38.42138,3.79083,38.42138,22412,3
25.12080,-3.48699,-30.11521,3.46075,30.11521,22412,3
25.56380,-3.04382,-21.23464,3.01758,21.23463,22412,3
26.09120,-2.51688,-13.18537,2.49064,13.18537,22412,3
26.59120,-2.11690,-8.43405,2.09066,8.43405,22412,3
26.97580,-2.52592,-17.20262,2.49968,17.20262,22476,3
27.37480,-2.92674,-25.67433,2.90050,25.67433,22476,4
27.71980,-3.27202,-34.07802,3.24578,34.07803,22476,4
28.09120,-3.64287,-43.18896,3.61663,43.18896,22476,4
28.45480,-4.00680,-51.61647,3.98056,51.61647,22476,4
28.83280,-4.38503,-59.97885,4.35879,59.97886,22476,4
29.21680,-4.76895,-68.40987,4.74271,68.40987,22476,4
29.42380,-4.69331,-64.34713,4.66707,64.34713,22476,4
29.70480,-4.40082,-54.84759,4.37458,54.84759,22412,4
29.99880,-4.10484,-46.01483,4.07860,46.01483,22412,4
30.32180,-3.78172,-37.00891,3.75548,37.00891,22412,4
30.69120,-3.41264,-27.95315,3.38640,27.95315,22412,4
31.13780,-2.96565,-19.58302,2.93941,19.58302,22412,4
31.68980,-2.41358,-11.60502,2.38734,11.60502,22412,4
32.10780,-2.20455,-10.16035,2.17831,10.16035,22412,4
32.50580,-2.61846,-18.70395,2.59222,18.70395,22476,4
32.90080,-3.01459,-27.17946,2.98835,27.17946,22476,5
33.21780,-3.33182,-35.15543,3.30558,35.15543,22476,5
33.58480,-3.69871,-44.04917,3.67247,44.04917,22476,5
33.95980,-4.07356,-52.75673,4.04732,52.75673,22476,5
34.33980,-4.45369,-61.13324,4.42745,61.13324,22476,5
34.65180,-4.76582,-68.07751,4.73958,68.07751,22476,5
34.91580,-4.66626,-62.98260,4.64002,62.98260,22476,5
35.19120,-4.38249,-53.87484,4.35625,53.87484,22412,5
35.49180,-4.07972,-44.81710,4.05348,44.81710,22412,5
35.81280,-3.75872,-36.01326,3.73248,36.01326,22412,5
36.19120,-3.38079,-26.91290,3.35455,26.91290,22412,5
36.64680,-2.92467,-18.74183,2.89843,18.74183,22412,5
37.19120,-2.38075,-10.87656,2.35451,10.87656,22412,5
37.60180,-2.26268,-11.18160,2.23643,11.18160,22412,5
38.01180,-2.68487,-19.65952,2.65863,19.65952,22476,5
38.39580,-3.06954,-28.15095,3.04330,28.15095,22476,6
38.74380,-3.41779,-36.93917,3.39155,36.93917,22476,6
39.04180,-3.71575,-44.12967,3.68951,44.12967,22476,6
39.38980,-4.06364,-52.25938,4.03740,52.25938,22476,6
39.77080,-4.44475,-60.70423,4.41850,60.70423,22476,6
40.14780,-4.82174,-69.09768,4.79550,69.09768,22476,6
40.39180,-4.64649,-62.02248,4.62025,62.02248,22476,6
40.68380,-4.34701,-52.50892,4.32077,52.50892,22412,6
40.97980,-4.04968,-43.65425,4.02344,43.65425,22412,6
41.30880,-3.72067,-34.78342,3.69443,34.78342,22412,6
41.69120,-3.33881,-25.86136,3.31256,25.86136,22412,6
42.15980,-2.86976,-17.66036,2.84352,17.66036,22412,6
42.69120,-2.33871,-10.11758,2.31247,10.11758,22412,6
43.09120,-2.32497,-12.24408,2.29873,12.24408,22412,6
43.49580,-2.73906,-20.53594,2.71282,20.53594,22476,6
43.89120,-3.13454,-29.50532,3.10830,29.50532,22476,7
44.22780,-3.47175,-38.05605,3.44550,38.05605,22476,7
44.56280,-3.80681,-46.07208,3.78057,46.07208,22476,7
44.89180,-4.13568,-53.62666,4.10944,53.62666,22476,7
45.29120,-4.53456,-62.47107,4.50832,62.47107,22476,7
45.61280,-4.85670,-69.71284,4.83046,69.71284,22476,7
45.85180,-4.64971,-61.74653,4.62347,61.74652,22476,7
46.13180,-4.36303,-52.63355,4.33679,52.63355,22412,7
46.43780,-4.05563,-43.51629,4.02939,43.51629,22412,7
46.73980,-3.75369,-35.26344,3.72745,35.26344,22412,7
47.09880,-3.39468,-26.74604,3.36844,26.74604,22412,7
47.58180,-2.91166,-18.12556,2.88542,18.12556,22412,7
48.10780,-2.38570,-10.58572,2.35946,10.58572,22412,7
48.51680,-2.30701,-11.60901,2.28077,11.60901,22412,7
48.93780,-2.73896,-20.23843,2.71272,20.23843,22604,7
49.30480,-3.10639,-28.46182,3.08015,28.46181,22604,8
49.66480,-3.46667,-37.58751,3.44043,37.58751,22604,8
50.00680,-3.80875,-45.90861,3.78251,45.90861,22604,8
50.36080,-4.16266,-54.07834,4.13642,54.07834,22604,8
50.75380,-4.55549,-62.74171,4.52925,62.74171,22604,8
51.09120,-4.87924,-69.94400,4.85300,69.94400,22604,8
51.29980,-4.65768,-61.74575,4.63144,61.74575,22604,8
51.59120,-4.35987,-52.34057,4.33363,52.34058,22540,8
51.89120,-4.05854,-43.39276,4.03229,43.39275,22540,8
52.22980,-3.71958,-34.32739,3.69333,34.32739,22540,8
52.59120,-3.35874,-25.89312,3.33250,25.89312,22540,8
53.08580,-2.86364,-17.19921,2.83740,17.19921,22540,8
53.61580,-2.33360,-9.68910,2.30736,9.68910,22540,8
54.00280,-2.36781,-12.63365,2.34157,12.63365,22540,8
54.41980,-2.79297,-21.20414,2.76673,21.20414,22604,9
54.79120,-3.16441,-29.73447,3.13817,29.73447,22604,9
55.14180,-3.51551,-38.61147,3.48927,38.61147,22604,9
55.49120,-3.86466,-47.13934,3.83841,47.13934,22604,9
55.88080,-4.25464,-55.99219,4.22840,55.99220,22604,9
56.26680,-4.64051,-64.51624,4.61427,64.51624,22604,9
56.59120,-4.80934,-66.88607,4.78310,66.88608,22604,9
56.85480,-4.52784,-57.32566,4.50160,57.32566,22540,9
57.14380,-4.23593,-48.54751,4.20969,48.54751,22540,9
57.45680,-3.92252,-39.36761,3.89628,39.36760,22540,9
57.79120,-3.58837,-30.80844,3.56213,30.80844,22540,9
58.19780,-3.18120,-22.26909,3.15496,22.26909,22540,9
58.70880,-2.67029,-14.20232,2.64405,14.20232,22540,9
59.29580,-2.16268,-7.42466,2.13644,7.42466,22540,9
59.86380,-2.45466,-14.74850,2.42842,14.74850,22540,9
60.27780,-2.87152,-23.18310,2.84528,23.18310,22476,9
60.64080,-3.23470,-31.64014,3.20846,31.64014,22476,10
60.99120,-3.58452,-40.34010,3.55828,40.34010,22476,10
61.36380,-3.95764,-49.18849,3.93140,49.18849,22476,10
61.69120,-4.28471,-56.70638,4.25847,56.70638,22476,10
62.09120,-4.68455,-65.41744,4.65831,65.41744,22476,10
62.38580,-4.77717,-65.80522,4.75093,65.80522,22476,10
62.64480,-4.50366,-56.66992,4.47742,56.66993,22412,10
62.94380,-4.20183,-47.60937,4.17559,47.60937,22412,10
63.25680,-3.88867,-38.48970,3.86243,38.48970,22412,10
63.59780,-3.54738,-29.86879,3.52114,29.86879,22412,10
64.01880,-3.12641,-21.20367,3.10017,21.20367,22412,10
64.54580,-2.59942,-13.11145,2.57317,13.11145,22412,10
65.03480,-2.21050,-8.44813,2.18426,8.44813,22412,10
65.39980,-2.59918,-16.99404,2.57294,16.99404,22476,10
65.81080,-3.01225,-25.78131,2.98601,25.78131,22476,11
66.15880,-3.36058,-34.37530,3.33434,34.37529,22476,11
66.49120,-3.69232,-42.62235,3.66608,42.62234,22476,11
66.84280,-4.04436,-51.02580,4.01812,51.02580,22476,11
67.22580,-4.42748,-59.55473,4.40124,59.55473,22476,11
67.60980,-4.81138,-68.12397,4.78514,68.12397,22476,11
67.85280,-4.73043,-63.75860,4.70419,63.75861,22476,11
68.12380,-4.44924,-54.66472,4.42300,54.66471,22412,11
68.42280,-4.14842,-45.62118,4.12218,45.62118,22412,11
68.74580,-3.82535,-36.48416,3.79911,36.48416,22412,11
69.09980,-3.47130,-27.78827,3.44506,27.78827,22412,11
69.55380,-3.01727,-19.15327,2.99102,19.15327,22412,11
70.09120,-2.48023,-11.39791,2.45399,11.39791,22412,11
70.49120,-2.26586,-9.72060,2.23962,9.72060,22412,11
70.89120,-2.68296,-18.55633,2.65672,18.55633,22476,11
71.28780,-3.08100,-27.08477,3.05476,27.08477,22476,12
71.59120,-3.38433,-34.74848,3.35809,34.74848,22476,12
71.94180,-3.73539,-43.48257,3.70915,43.48257,22476,12
72.30280,-4.09617,-52.05955,4.06993,52.05955,22476,12
72.69120,-4.48418,-60.66622,4.45794,60.66622,22476,12
73.03980,-4.83321,-68.51390,4.80697,68.51390,22476,12
73.28880,-4.72495,-63.33862,4.69871,63.33862,22476,12
73.57280,-4.43163,-53.87274,4.40539,53.87274,22412,12
73.86880,-4.13416,-44.97346,4.10791,44.97346,22412,12
74.15280,-3.85017,-36.97031,3.82393,36.97031,22412,12
74.50180,-3.50101,-28.33062,3.47477,28.33062,22412,12
74.95080,-3.05183,-19.59258,3.02559,19.59258,22412,12
75.49120,-2.51192,-11.73908,2.48568,11.73908,22412,12
75.91280,-2.29270,-10.11148,2.26646,10.11147,22412,12
76.30780,-2.70383,-18.74841,2.67759,18.74841,22476,12
76.69380,-3.09081,-27.07186,3.06457,27.07186,22476,13
77.04880,-3.44609,-36.02879,3.41985,36.02879,22476,13
77.39120,-3.78812,-44.56981,3.76187,44.56981,22476,13
77.76880,-4.16612,-53.45436,4.13988,53.45436,22476,13
78.11280,-4.51003,-61.08697,4.48379,61.08697,22476,13
78.46480,-4.86205,-69.13129,4.83581,69.13129,22476,13
78.69480,-4.71833,-62.96914,4.69209,62.96914,22476,13
78.98180,-4.42249,-53.47542,4.39625,53.47542,22412,13
79.27680,-4.12610,-44.61047,4.09986,44.61047,22412,13
79.59120,-3.81201,-35.83002,3.78577,35.83002,22412,13
79.96880,-3.43393,-26.67824,3.40769,26.67824,22412,13
80.39880,-3.00395,-18.77514,2.97771,18.77514,22412,13
80.95580,-2.44685,-10.68032,2.42061,10.68032,22412,13
81.35380,-2.36477,-11.62914,2.33853,11.62914,22412,13
81.76380,-2.78622,-20.15123,2.75998,20.15123,22476,13
82.13480,-3.15787,-28.59199,3.13163,28.59199,22476,14
82.48980,-3.51295,-37.57960,3.48671,37.57960,22476,14
82.82680,-3.85020,-45.90045,3.82396,45.90045,22476,14
83.19280,-4.21608,-54.52049,4.18984,54.52049,22476,14
83.59120,-4.61397,-63.30289,4.58773,63.30289,22476,14
83.91380,-4.89420,-69.37471,4.86796,69.37471,22476,14
84.16980,-4.61413,-59.43738,4.58789,59.43737,22412,14
84.44880,-4.33076,-50.71362,4.30452,50.71362,22412,14
84.74880,-4.02993,-41.73211,4.00369,41.73211,22412,14
85.05480,-3.72393,-33.60208,3.69769,33.60208,22412,14
85.39120,-3.38796,-25.73019,3.36172,25.73019,22412,14
85.86580,-2.91293,-17.14445,2.88669,17.14445,22412,14
86.39280,-2.38597,-9.75169,2.35973,9.75169,22412,14
86.79120,-2.42968,-12.87170,2.40344,12.87170,22412,14
87.19120,-2.83739,-21.18636,2.81115,21.18636,22476,14
87.57180,-3.21890,-30.00298,3.19266,30.00298,22476,15
87.90780,-3.55484,-38.54547,3.52860,38.54548,22476,15
88.27380,-3.92109,-47.61640,3.89485,47.61640,22476,15
88.64480,-4.29206,-56.17311,4.26582,56.17311,22476,15
89.02580,-4.67292,-64.61852,4.64668,64.61852,22476,15
89.32680,-4.85841,-67.87158,4.83217,67.87157,22476,15
89.59080,-4.57358,-58.01817,4.54734,58.01817,22412,15
89.88480,-4.27627,-48.97650,4.25003,48.97650,22412,15
90.14880,-4.01179,-41.04764,3.98555,41.04765,22412,15
90.49120,-3.66961,-32.00098,3.64336,32.00098,22412,15
90.89120,-3.26975,-23.23894,3.24351,23.23894,22412,15
91.37880,-2.78164,-15.12019,2.75540,15.12019,22412,15
91.91180,-2.24883,-7.57204,2.22259,7.57204,22412,15
92.25980,-2.54453,-15.07614,2.51829,15.07614,22476,15
92.67180,-2.96062,-23.73157,2.93438,23.73157,22476,16
93.02080,-3.30995,-32.10112,3.28370,32.10112,22476,16
93.38080,-3.66995,-41.19739,3.64371,41.19739,22476,16
93.72980,-4.01894,-49.64592,3.99270,49.64592,22476,16
94.09480,-4.38409,-58.05717,4.35785,58.05717,22476,16
94.45380,-4.74294,-66.15408,4.71670,66.15408,22476,16
94.73380,-4.79076,-65.34126,4.76451,65.34126,22476,16
95.00180,-4.50935,-56.06915,4.48310,56.06915,22412,16
95.29780,-4.21102,-47.11345,4.18478,47.11345,22412,16
95.60380,-3.90482,-38.06180,3.87858,38.06180,22412,16
95.96380,-3.54455,-29.00349,3.51831,29.00349,22412,16
96.39120,-3.11759,-20.40560,3.09135,20.40560,22412,16
96.89280,-2.61559,-12.67627,2.58935,12.67627,22412,16
97.38380,-2.29529,-9.48645,2.26905,9.48645,22412,16
97.77280,-2.70231,-18.25211,2.67607,18.25211,22476,16
98.15680,-3.08751,-26.49152,3.06127,26.49152,22476,17
98.49980,-3.43074,-35.12434,3.40450,35.12434,22476,17
98.86380,-3.79489,-44.13039,3.76865,44.13039,22476,17
99.21880,-4.14979,-52.69094,4.12355,52.69094,22476,17
99.59120,-4.52170,-61.08876,4.49546,61.08876,22476,17
99.96180,-4.89260,-69.63941,4.86636,69.63941,22476,17
100.19120,-4.69016,-61.79195,4.66392,61.79195,22476,17
100.47580,-4.39799,-52.52105,4.37175,52.52105,22412,17
100.78080,-4.09168,-43.37967,4.06544,43.37967,22412,17
101.09120,-3.78169,-34.74424,3.75545,34.74424,22412,17
101.47680,-3.39569,-25.69637,3.36945,25.69637,22412,17
101.91980,-2.95266,-17.67244,2.92642,17.67244,22412,17
102.46180,-2.41058,-9.78505,2.38434,9.78505,22412,17
102.85980,-2.43397,-12.63250,2.40773,12.63250,22412,17
103.26280,-2.84525,-21.03369,2.81901,21.03369,22604,17
103.63380,-3.21672,-29.60979,3.19048,29.60979,22604,18
103.98180,-3.56472,-38.42649,3.53848,38.42649,22604,18
104.33080,-3.91401,-47.05296,3.88777,47.05296,22604,18
104.69680,-4.27997,-55.59064,4.25373,55.59064,22604,18
105.09120,-4.67380,-64.47148,4.64756,64.47148,22604,18
105.39480,-4.84892,-67.31601,4.82268,67.31601,22604,18
105.66480,-4.55908,-57.45777,4.53284,57.45778,22540,18
105.95680,-4.26408,-48.44949,4.23784,48.44949,22540,18
106.25780,-3.96262,-39.49322,3.93638,39.49322,22540,18
106.59480,-3.62552,-30.73427,3.59928,30.73427,22540,18
106.99780,-3.22257,-22.18766,3.19633,22.18766,22540,18
107.49480,-2.72552,-14.17299,2.69928,14.17299,22540,18
108.02080,-2.23030,-7.27080,2.20406,7.27080,22540,18
108.39120,-2.62516,-16.48460,2.59892,16.48460,22604,18
108.79120,-3.02750,-25.04721,3.00126,25.04721,22604,19
109.13580,-3.37278,-33.54693,3.34654,33.54693,22604,19
109.49120,-3.72791,-42.44397,3.70167,42.44397,22604,19
109.84980,-4.08668,-51.06572,4.06044,51.06572,22604,19
110.21680,-4.45373,-59.47065,4.42749,59.47065,22604,19
110.53380,-4.77075,-66.60700,4.74451,66.60699,22604,19
110.80080,-4.80553,-65.53061,4.77929,65.53062,22604,19
111.07780,-4.51497,-55.89687,4.48873,55.89687,22540,19
111.35080,-4.23990,-47.71153,4.21366,47.71153,22540,19
111.62080,-3.96956,-39.57440,3.94332,39.57439,22540,19
111.96080,-3.62946,-30.75740,3.60322,30.75740,22540,19
112.30180,-3.28851,-23.42109,3.26227,23.42109,22540,19
112.79880,-2.79139,-15.08217,2.76515,15.08217,22540,19
113.33880,-2.25162,-7.28426,2.22538,7.28426,22540,19
113.96980,-2.46697,-13.75631,2.44073,13.75631,22540,19
114.38080,-2.88175,-22.17127,2.85550,22.17127,22476,19
114.74580,-3.24706,-30.63159,3.22082,30.63159,22476,20
115.09120,-3.59184,-39.31103,3.56560,39.31103,22476,20
115.45480,-3.95602,-48.13612,3.92978,48.13612,22476,20
115.82580,-4.32706,-56.75929,4.30082,56.75929,22476,20
116.17480,-4.67588,-64.54720,4.64964,64.54720,22476,20
116.48880,-4.83487,-66.79370,4.80863,66.79369,22476,20
116.71180,-4.59539,-58.59443,4.56915,58.59443,22412,20
117.00580,-4.29744,-49.41686,4.27120,49.41686,22412,20
117.29980,-4.00292,-40.61034,3.97668,40.61034,22412,20
117.64080,-3.66172,-31.55374,3.63548,31.55374,22412,20
118.04880,-3.25386,-22.74873,3.22762,22.74873,22412,20
118.54680,-2.75574,-14.57007,2.72950,14.57007,22412,20
119.06380,-2.24448,-7.25671,2.21824,7.25671,22412,20
119.40580,-2.59344,-15.72069,2.56720,15.72069,22476,20
119.80380,-2.99487,-24.15809,2.96863,24.15809,22476,21
120.17180,-3.36324,-33.15385,3.33699,33.15385,22476,21
120.50980,-3.70115,-41.63102,3.67491,41.63102,22476,21
120.83580,-4.02715,-49.52048,4.00090,49.52048,22476,21
121.18480,-4.37634,-57.58424,4.35010,57.58424,22476,21
121.56280,-4.75414,-66.14804,4.72790,66.14803,22476,21
121.84680,-4.79339,-65.12303,4.76715,65.12303,22476,21
122.10680,-4.52054,-56.05118,4.49430,56.05117,22412,21
122.39120,-4.23431,-47.48622,4.20807,47.48622,22412,21
122.68680,-3.93796,-38.61634,3.91172,38.61634,22412,21
122.99120,-3.63386,-30.69728,3.60762,30.69728,22412,21
123.39480,-3.22994,-22.16295,3.20369,22.16295,22412,21
123.89880,-2.72589,-14.01798,2.69965,14.01798,22412,21
124.41180,-2.24398,-7.37807,2.21773,7.37807,22412,21
124.78680,-2.64393,-16.73000,2.61769,16.73000,22476,21
125.17880,-3.03815,-25.11446,3.01191,25.11446,22476,22
125.52180,-3.38149,-33.57216,3.35525,33.57215,22476,22
125.87980,-3.73953,-42.49541,3.71329,42.49541,22476,22
126.23080,-4.09038,-50.96743,4.06414,50.96743,22476,22
126.60780,-4.46739,-59.51782,4.44115,59.51782,22476,22
126.96180,-4.82132,-67.60737,4.79508,67.60738,22476,22
127.19120,-4.79944,-65.15618,4.77320,65.15618,22476,22
127.41980,-4.55842,-57.08895,4.53218,57.08894,22412,22
127.72080,-4.25470,-47.93100,4.22846,47.93100,22412,22
128.02080,-3.95433,-38.96859,3.92808,38.96859,22412,22
128.32779,-3.64714,-30.87484,3.62090,30.87484,22412,22
128.73480,-3.24029,-22.28034,3.21405,22.28034,22412,22
129.23979,-2.73526,-14.06931,2.70902,14.06931,22412,22
129.75080,-2.25187,-7.40267,2.22563,7.40267,22412,22
130.09979,-2.62452,-16.20662,2.59828,16.20662,22476,22
130.49580,-3.02329,-24.67002,2.99705,24.67002,22476,23
130.85379,-3.38157,-33.51961,3.35533,33.51961,22476,23
131.17580,-3.70365,-41.50841,3.67741,41.50841,22476,23
131.52180,-4.04950,-49.94595,4.02325,49.94595,22476,23
131.89980,-4.42764,-58.57027,4.40140,58.57027,22476,23
132.29120,-4.81847,-67.50380,4.79223,67.50380,22476,23
132.55480,-4.75437,-63.52375,4.72813,63.52375,22476,23
132.82080,-4.47834,-54.59069,4.45210,54.59069,22412,23
133.11580,-4.18147,-45.63330,4.15523,45.63330,22412,23
133.43280,-3.86448,-36.34769,3.83824,36.34769,22412,23
133.79120,-3.50631,-27.46375,3.48007,27.46375,22412,23
134.23080,-3.06615,-19.11714,3.03991,19.11714,22412,23
134.76480,-2.53221,-11.25849,2.50597,11.25849,22412,23
135.19119,-2.38282,-11.03601,2.35658,11.03601,22412,23
135.59120,-2.79570,-19.60010,2.76946,19.60010,22476,23
135.96880,-3.17451,-28.11338,3.14827,28.11338,22476,24
136.29780,-3.50362,-36.47879,3.47738,36.47879,22476,24
136.66580,-3.87192,-45.58661,3.84568,45.58661,22476,24
137.02880,-4.23481,-54.17302,4.20857,54.17302,22476,24
137.40180,-4.60756,-62.60331,4.58132,62.60331,22476,24
137.73880,-4.92067,-69.76692,4.89443,69.76692,22476,24
137.98180,-4.65760,-60.15956,4.63136,60.15956,22412,24
138.26980,-4.36450,-51.08136,4.33826,51.08136,22412,24
138.57480,-4.05839,-41.89100,4.03215,41.89100,22412,24
138.89119,-3.74248,-33.15763,3.71624,33.15763,22412,24
139.27180,-3.36159,-24.50359,3.33535,24.50359,22412,24
139.74980,-2.88354,-16.18426,2.85730,16.18426,22412,24
140.29120,-2.34255,-8.43429,2.31631,8.43429,22412,24
140.65480,-2.52480,-14.00950,2.49856,14.00950,22476,24
141.06380,-2.93940,-22.72581,2.91316,22.72581,22476,25
141.41780,-3.29378,-31.03102,3.26754,31.03102,22476,25
141.77680,-3.65275,-40.06498,3.62651,40.06498,22476,25
142.12380,-3.99988,-48.60974,3.97364,48.60974,22476,25
142.49380,-4.36992,-57.16243,4.34368,57.16243,22476,25
142.89119,-4.76677,-66.19406,4.74052,66.19406,22476,25
143.15180,-4.83597,-66.22852,4.80973,66.22852,22476,25
143.40580,-4.56676,-57.11687,4.54052,57.11687,22412,25
143.70480,-4.26498,-48.03847,4.23874,48.03847,22412,25
144.01080,-3.95859,-38.85504,3.93235,38.85504,22412,25
144.35780,-3.61150,-29.87161,3.58526,29.87161,22412,25
144.71880,-3.25057,-22.31300,3.22433,22.31300,22412,25
145.22880,-2.74048,-13.99611,2.71424,13.99611,22412,25
145.72480,-2.26747,-7.41811,2.24123,7.41811,22412,25
146.08780,-2.65300,-16.57533,2.62676,16.57533,22476,25
146.48380,-3.05153,-25.07678,3.02529,25.07678,22476,26
146.82680,-3.39481,-33.61239,3.36857,33.61238,22476,26
147.18380,-3.75198,-42.52119,3.72574,42.52119,22476,26
147.53980,-4.10777,-51.10006,4.08153,51.10006,22476,26
147.91380,-4.48176,-59.61039,4.45551,59.61039,22476,26
148.26280,-4.83074,-67.62139,4.80450,67.62139,22476,26
148.52280,-4.75846,-63.45294,4.73222,63.45295,22476,26
148.79120,-4.48050,-54.38879,4.45426,54.38879,22412,26
149.09120,-4.17867,-45.29431,4.15243,45.29431,22412,26
149.39880,-3.87071,-36.27939,3.84447,36.27939,22412,26
149.76580,-3.50355,-27.21578,3.47731,27.21578,22412,26
150.19280,-3.07636,-19.12128,3.05012,19.12128,22412,26
150.73680,-2.53246,-11.10546,2.50622,11.10546,22412,26
151.15380,-2.39823,-11.11668,2.37199,11.11668,22412,26
151.55480,-2.81188,-19.71559,2.78564,19.71559,22476,26
151.92180,-3.17969,-28.03524,3.15345,28.03524,22476,27
152.27080,-3.52878,-36.91246,3.50254,36.91246,22476,27
152.62180,-3.88003,-45.56673,3.85379,45.56673,22476,27
152.99120,-4.24905,-54.32166,4.22281,54.32166,22476,27
153.38280,-4.64072,-63.18712,4.61448,63.18712,22476,27
153.70080,-4.93017,-69.79079,4.90393,69.79079,22476,27
153.94780,-4.66153,-60.02624,4.63529,60.02624,22476,27
154.23380,-4.37067,-50.97404,4.34443,50.97404,22412,27
154.49780,-4.10571,-43.00451,4.07947,43.00451,22412,27
154.79580,-3.80768,-34.55440,3.78144,34.55440,22412,27
155.17180,-3.43164,-25.75298,3.40540,25.75298,22412,27
155.61880,-2.98470,-17.59826,2.95846,17.59826,22412,27
156.16178,-2.44163,-9.77840,2.41539,9.77840,22412,27
156.54680,-2.47594,-12.72435,2.44970,12.72435,22412,27
156.93978,-2.87736,-21.16285,2.85112,21.16285,22604,27
157.29880,-3.23697,-29.46114,3.21073,29.46114,22604,28
157.65280,-3.59076,-38.44683,3.56452,38.44683,22604,28
157.99980,-3.93806,-47.04006,3.91182,47.04006,22604,28
158.38480,-4.32307,-55.92808,4.29683,55.92808,22604,28
158.72580,-4.66376,-63.63916,4.63752,63.63916,22604,28
159.04180,-4.91506,-69.02035,4.88882,69.02035,22604,28
159.29120,-4.64180,-59.27971,4.61556,59.27971,22604,28
159.58580,-4.34252,-49.99027,4.31628,49.99027,22540,28
159.88780,-4.03972,-40.94724,4.01348,40.94724,22540,28
160.19380,-3.73374,-32.63663,3.70750,32.63663,22540,28
160.55980,-3.36787,-24.35840,3.34163,24.35840,22540,28
161.03380,-2.89378,-16.18007,2.86754,16.18007,22540,28
161.58480,-2.34289,-8.27123,2.31665,8.27123,22540,28
161.94580,-2.54223,-14.16750,2.51599,14.16749,22604,28
162.34380,-2.94558,-22.67429,2.91934,22.67429,22604,29
162.69980,-3.30198,-31.01354,3.27574,31.01354,22604,29
163.05880,-3.66096,-40.09770,3.63472,40.09770,22604,29
163.40980,-4.01204,-48.72055,3.98580,48.72055,22604,29
163.75680,-4.35912,-56.75342,4.33288,56.75342,22604,29
164.12580,-4.72792,-65.12507,4.70168,65.12507,22604,29
164.40880,-4.87132,-67.17361,4.84508,67.17361,22604,29
164.67480,-4.58635,-57.51961,4.56011,57.51962,22540,29
164.96880,-4.28930,-48.48352,4.26306,48.48352,22540,29
165.26780,-3.98988,-39.50607,3.96364,39.50607,22540,29
165.59278,-3.66467,-30.79990,3.63843,30.79990,22540,29
166.00180,-3.25585,-22.14966,3.22961,22.14966,22540,29
166.49280,-2.76474,-14.15057,2.73849,14.15057,22540,29
167.01080,-2.25402,-6.95256,2.22778,6.95256,22540,29
167.60280,-2.49330,-13.65184,2.46706,13.65184,22540,29
168.01380,-2.90814,-22.26360,2.88190,22.26360,22476,29
168.39119,-3.28546,-31.00182,3.25922,31.00182,22476,30
168.73480,-3.62925,-39.60016,3.60301,39.60016,22476,30
169.09120,-3.98546,-48.25942,3.95922,48.25942,22476,30
169.43080,-4.32552,-56.13013,4.29928,56.13013,22476,30
169.79080,-4.68522,-64.18761,4.65898,64.18761,22476,30
170.06580,-4.91762,-69.31861,4.89138,69.31861,22476,30
170.29580,-4.66438,-60.13855,4.63814,60.13855,22412,30
170.59120,-4.36412,-50.80131,4.33788,50.80131,22412,30
170.89119,-4.06307,-41.75159,4.03683,41.75159,22412,30
171.19080,-3.76317,-33.42382,3.73693,33.42382,22412,30
171.56780,-3.38623,-24.75705,3.35999,24.75705,22412,30
172.01880,-2.93513,-16.78013,2.90889,16.78013,22412,30
172.58780,-2.36631,-8.58295,2.34007,8.58295,22412,30
172.92880,-2.52244,-13.63801,2.49620,13.63801,22476,30
173.32580,-2.92599,-22.16316,2.89975,22.16316,22476,31
173.69119,-3.29151,-30.70991,3.26527,30.70991,22476,31
174.04380,-3.64448,-39.68345,3.61824,39.68344,22476,31
174.36780,-3.96854,-47.70529,3.94230,47.70529,22476,31
174.69119,-4.29159,-55.22089,4.26535,55.22089,22476,31
175.08480,-4.68530,-64.02416,4.65906,64.02415,22476,31
175.39080,-4.90281,-68.38659,4.87657,68.38659,22476,31
175.62580,-4.64551,-59.35525,4.61927,59.35525,22476,31
175.89380,-4.37335,-50.93802,4.34711,50.93802,22412,31
176.19580,-4.07029,-41.89951,4.04405,41.89951,22412,31
176.43180,-3.83440,-35.05461,3.80815,35.05461,22412,31
176.79120,-3.47533,-26.39966,3.44909,26.39966,22412,31
177.19119,-3.07512,-18.90464,3.04888,18.90464,22412,31
177.72680,-2.53921,-11.05714,2.51297,11.05714,22412,31
178.09980,-2.37339,-10.16124,2.34715,10.16124,22412,31
178.49120,-2.78036,-18.97789,2.75412,18.97789,22476,31
178.87480,-3.16549,-27.45809,3.13925,27.45809,22476,32
179.21080,-3.50162,-36.03014,3.47538,36.03014,22476,32
179.55580,-3.84675,-44.56015,3.82051,44.56015,22476,32
179.89380,-4.18471,-52.66425,4.15847,52.66425,22476,32
180.19780,-4.48859,-59.53128,4.46235,59.53128,22476,32
180.58480,-4.87562,-68.53945,4.84938,68.53945,22476,32
180.81478,-4.77553,-63.67876,4.74929,63.67876,22476,32
181.09120,-4.48945,-54.32035,4.46320,54.32035,22412,32
181.36580,-4.21278,-46.02253,4.18654,46.02253,22412,32
181.63180,-3.94662,-38.17081,3.92038,38.17081,22412,32
181.94980,-3.62853,-29.89455,3.60229,29.89455,22412,32
182.36980,-3.20855,-21.16191,3.18231,21.16191,22412,32
182.88180,-2.69649,-13.11704,2.67025,13.11704,22412,32
183.36780,-2.31089,-8.42294,2.28465,8.42294,22412,32
183.72980,-2.69672,-17.20630,2.67048,17.20630,22476,32
184.11280,-3.08156,-25.58011,3.05532,25.58011,22476,33
184.43080,-3.40004,-33.48239,3.37380,33.48239,22476,33
184.79120,-3.75999,-42.48748,3.73375,42.48748,22476,33
185.14878,-4.11795,-51.10397,4.09171,51.10397,22476,33
185.49120,-4.45992,-58.83537,4.43368,58.83537,22476,33
185.87078,-4.83984,-67.61982,4.81360,67.61981,22476,33
186.09120,-4.82583,-65.36282,4.79958,65.36282,22476,33
186.36180,-4.54122,-55.98919,4.51498,55.98919,22412,33
186.63180,-4.26917,-47.79476,4.24293,47.79475,22412,33
186.92180,-3.97884,-39.05447,3.95260,39.05447,22412,33
187.22780,-3.67264,-30.82039,3.64640,30.82039,22412,33
187.63680,-3.26380,-22.17348,3.23756,22.17348,22412,33
188.12380,-2.77667,-14.24094,2.75043,14.24094,22412,33
188.65380,-2.28258,-7.46619,2.25634,7.46619,22412,33
188.99480,-2.64897,-16.21012,2.62273,16.21012,22476,33
189.39119,-3.04771,-24.73230,3.02147,24.73230,22476,34
189.74080,-3.39806,-33.44933,3.37182,33.44933,22476,34
190.06980,-3.72710,-41.61551,3.70086,41.61551,22476,34
190.41880,-4.07597,-50.07519,4.04973,50.07519,22476,34
190.79380,-4.45099,-58.59504,4.42475,58.59504,22476,34
191.18680,-4.84392,-67.69080,4.81768,67.69080,22476,34
191.42380,-4.80918,-64.73764,4.78294,64.73764,22476,34
191.69119,-4.53015,-55.53354,4.50391,55.53354,22412,34
191.99120,-4.22818,-46.43615,4.20194,46.43615,22412,34
192.29120,-3.92795,-37.49599,3.90171,37.49599,22412,34
192.59980,-3.61885,-29.46419,3.59261,29.46419,22412,34
193.03080,-3.18771,-20.64328,3.16147,20.64328,22412,34
193.54680,-2.67179,-12.75736,2.64555,12.75736,22412,34
194.00980,-2.33579,-8.93554,2.30955,8.93554,22412,34
194.39119,-2.73843,-17.99231,2.71219,17.99231,22476,34
194.78380,-3.13303,-26.65970,3.10678,26.65970,22476,35
195.11580,-3.46518,-35.03539,3.43894,35.03539,22476,35
195.48680,-3.83624,-44.23774,3.81000,44.23774,22476,35
195.84278,-4.19222,-52.67539,4.16598,52.67538,22476,35
196.20880,-4.55793,-60.90685,4.53169,60.90685,22476,35
196.55680,-4.90615,-69.12899,4.87991,69.12899,22476,35
196.78678,-4.75419,-62.70406,4.72795,62.70406,22476,35
197.03080,-4.50193,-54.61279,4.47569,54.61279,22412,35
197.32680,-4.20418,-45.60405,4.17794,45.60405,22412,35
197.58780,-3.94307,-37.86175,3.91683,37.86175,22412,35
197.89119,-3.63997,-29.90316,3.61372,29.90316,22412,35
198.29120,-3.24005,-21.53796,3.21381,21.53796,22412,35
198.79120,-2.73998,-13.54791,2.71374,13.54791,22412,35
199.30380,-2.30093,-8.01503,2.27469,8.01503,22412,35
199.67678,-2.70012,-17.15104,2.67388,17.15104,22476,35
200.06080,-3.08599,-25.63798,3.05975,25.63798,22476,36
200.39480,-3.42042,-33.92856,3.39418,33.92856,22476,36
200.75980,-3.78537,-43.00468,3.75913,43.00468,22476,36
201.09120,-4.11634,-50.96298,4.09010,50.96299,22476,36
201.47580,-4.50127,-59.71929,4.47503,59.71929,22476,36
201.79780,-4.82325,-67.09190,4.79701,67.09190,22476,36
202.05580,-4.80952,-64.67135,4.78328,64.67136,22476,36
202.31880,-4.53452,-55.57198,4.50828,55.57198,22412,36
202.61880,-4.23252,-46.48543,4.20628,46.48543,22412,36
202.91280,-3.93825,-37.71703,3.91201,37.71703,22412,36
203.23980,-3.61118,-29.20876,3.58494,29.20876,22412,36
203.65280,-3.19812,-20.78291,3.17188,20.78291,22412,36
204.17180,-2.67911,-12.74646,2.65287,12.74646,22412,36
204.62980,-2.34577,-8.99883,2.31953,8.99883,22412,36
204.99120,-2.72834,-17.67219,2.70210,17.67219,22476,36
205.39119,-3.13015,-26.53651,3.10391,26.53651,22476,37
205.72980,-3.46939,-35.05300,3.44315,35.05300,22476,37
206.05378,-3.79344,-43.09778,3.76719,43.09777,22476,37
206.40680,-4.14642,-51.58554,4.12018,51.58554,22476,37
206.79120,-4.53025,-60.30242,4.50401,60.30242,22476,37
207.16580,-4.90539,-69.06226,4.87915,69.06226,22476,37
207.39119,-4.75672,-62.81396,4.73048,62.81396,22476,37
207.66480,-4.47392,-53.62868,4.44768,53.62868,22412,37
207.96880,-4.16831,-44.43068,4.14207,44.43068,22412,37
208.27980,-3.85738,-35.31356,3.83114,35.31356,22412,37
208.59120,-3.54613,-27.57181,3.51989,27.57181,22412,37
209.02980,-3.10716,-19.18790,3.08092,19.18790,22412,37
209.57480,-2.56219,-11.11884,2.53595,11.11884,22412,37
209.99120,-2.41006,-10.80948,2.38382,10.80948,22412,37
210.39119,-2.82355,-19.65684,2.79730,19.65685,22604,37
210.75878,-3.19234,-28.09583,3.16610,28.09583,22604,38
211.09880,-3.53238,-36.69124,3.50614,36.69125,22604,38
211.45380,-3.88767,-45.42998,3.86143,45.42998,22604,38
211.82680,-4.26071,-54.20189,4.23447,54.20189,22604,38
212.17480,-4.60840,-62.05971,4.58216,62.05971,22604,38
212.51880,-4.94638,-70.02398,4.92014,70.02398,22604,38
212.75780,-4.70247,-60.91804,4.67623,60.91804,22604,38
213.03678,-4.41748,-51.89729,4.39124,51.89729,22540,38
213.33480,-4.11845,-42.97306,4.09221,42.97306,22540,38
213.65280,-3.80038,-33.78468,3.77414,33.78468,22540,38
214.00680,-3.44633,-25.42720,3.42009,25.42720,22540,38
214.49120,-2.96240,-16.73044,2.93616,16.73044,22540,38
215.01380,-2.43940,-9.22176,2.41316,9.22176,22540,38
215.39680,-2.52690,-13.30131,2.50065,13.30131,22540,38
215.79120,-2.92805,-21.95850,2.90181,21.95850,22604,38
216.16178,-3.29961,-30.71912,3.27337,30.71912,22604,39
216.49120,-3.62859,-39.18669,3.60235,39.18669,22604,39
216.86080,-3.99858,-48.18154,3.97234,48.18154,22604,39
217.23180,-4.36972,-56.72502,4.34348,56.72502,22604,39
217.60580,-4.74353,-65.18462,4.71729,65.18462,22604,39
217.89380,-4.88077,-67.06371,4.85453,67.06371,22604,39
218.15780,-4.59877,-57.42089,4.57253,57.42089,22540,39
218.44680,-4.30671,-48.52530,4.28047,48.52530,22540,39
218.75380,-3.99931,-39.34482,3.97307,39.34482,22540,39
219.04980,-3.70317,-31.18402,3.67693,31.18402,22540,39
219.44178,-3.31132,-22.71006,3.28508,22.71006,22540,39
219.92878,-2.82420,-14.69523,2.79796,14.69523,22540,39
220.49120,-2.28332,-7.08289,2.25708,7.08289,22540,39
220.99120,-2.46438,-12.49720,2.43814,12.49720,22540,39
221.39119,-2.87018,-21.03029,2.84394,21.03029,22476,39
221.75680,-3.23649,-29.45832,3.21025,29.45832,22476,40
222.09278,-3.57241,-37.90810,3.54617,37.90810,22476,40
222.46380,-3.94359,-47.10534,3.91735,47.10534,22476,40
222.83680,-4.31665,-55.75958,4.29041,55.75958,22476,40
223.21280,-4.69245,-64.08815,4.66621,64.08815,22476,40
223.49880,-4.92987,-69.30678,4.90363,69.30679,22476,40
223.74680,-4.65765,-59.50752,4.63141,59.50751,22412,40
224.03280,-4.36719,-50.41984,4.34095,50.41984,22412,40
224.33480,-4.06418,-41.33550,4.03794,41.33550,22412,40
224.64380,-3.75526,-32.57887,3.72902,32.57887,22412,40
225.02880,-3.37036,-23.90000,3.34412,23.90000,22412,40
225.50878,-2.89030,-15.69079,2.86406,15.69079,22412,40
226.05480,-2.34441,-7.80631,2.31817,7.80631,22412,40
226.39280,-2.58505,-14.49742,2.55881,14.49742,22476,40
226.79120,-2.98814,-23.22287,2.96190,23.22287,22476,41
227.16178,-3.35948,-32.08744,3.33324,32.08744,22476,41
227.49778,-3.69555,-40.57766,3.66931,40.57766,22476,41
227.86380,-4.06139,-49.51139,4.03515,49.51139,22476,41
228.19480,-4.39266,-57.13011,4.36642,57.13011,22476,41
228.58580,-4.78350,-66.06907,4.75725,66.06908,22476,41
228.85480,-4.85645,-66.15771,4.83020,66.15771,22476,41
229.10778,-4.58847,-57.11497,4.56223,57.11497,22412,41
229.40280,-4.29065,-48.07628,4.26441,48.07628,22412,41
229.70280,-3.99028,-39.05745,3.96404,39.05745,22412,41
230.05080,-3.64217,-29.72392,3.61593,29.72392,22412,41
230.45780,-3.23527,-21.33082,3.20903,21.33082,22412,41
230.96978,-2.72319,-13.18641,2.69695,13.18641,22412,41
231.42878,-2.29650,-7.32785,2.27026,7.32785,22412,41
231.78780,-2.68064,-16.63742,2.65440,16.63742,22476,41
232.18380,-3.07905,-25.18646,3.05281,25.18646,22476,42
232.52080,-3.41642,-33.54559,3.39018,33.54559,22476,42
232.88378,-3.77950,-42.68815,3.75326,42.68815,22476,42
233.23380,-4.12941,-51.10145,4.10317,51.10145,22476,42
233.60580,-4.50133,-59.56275,4.47509,59.56276,22476,42
233.99120,-4.88632,-68.44007,4.86008,68.44007,22476,42
234.23180,-4.78253,-63.47438,4.75629,63.47438,22476,42
234.49680,-4.50798,-54.51272,4.48174,54.51273,22412,42
234.79780,-4.20525,-45.36063,4.17901,45.36063,22412,42
235.09780,-3.90517,-36.47253,3.87893,36.47253,22412,42
235.45678,-3.54594,-27.32871,3.51970,27.32871,22412,42
235.89119,-3.11199,-19.09778,3.08575,19.09778,22412,42
236.43480,-2.56797,-11.07997,2.54173,11.07997,22412,42
236.84080,-2.43404,-11.05065,2.40780,11.05065,22412,42
237.23380,-2.84026,-19.75361,2.81402,19.75360,22476,42
237.60080,-3.20809,-28.10299,3.18184,28.10299,22476,43
237.94980,-3.55720,-37.04199,3.53096,37.04199,22476,43
238.29280,-3.90039,-45.54143,3.87415,45.54143,22476,43
238.67678,-4.28439,-54.66659,4.25815,54.66660,22476,43
239.01078,-4.61816,-62.19022,4.59192,62.19022,22476,43
239.36980,-4.95617,-70.01143,4.92993,70.01143,22476,43
239.59119,-4.71747,-61.16788,4.69123,61.16788,22476,43
239.89119,-4.41113,-51.47148,4.38489,51.47147,22412,43
240.16080,-4.14018,-43.38882,4.11394,43.38882,22412,43
240.46680,-3.83419,-34.44661,3.80795,34.44661,22412,43
240.82880,-3.47214,-25.76200,3.44590,25.76200,22412,43
241.29120,-3.01015,-17.41032,2.98391,17.41032,22412,43
241.83380,-2.46715,-9.60252,2.44091,9.60252,22412,43
242.18480,-2.48165,-12.14996,2.45541,12.14996,22412,43
242.57580,-2.88262,-20.65190,2.85638,20.65190,22476,43
242.93680,-3.24435,-29.02981,3.21811,29.02981,22476,44
243.29078,-3.59823,-38.03558,3.57199,38.03558,22476,44
243.63578,-3.94337,-46.58902,3.91713,46.58902,22476,44
244.00380,-4.31145,-55.23090,4.28521,55.23090,22476,44
244.39119,-4.69824,-63.98749,4.67200,63.98749,22476,44
244.69119,-4.92474,-68.67803,4.89850,68.67803,22476,44
244.93680,-4.65510,-59.14043,4.62886,59.14043,22412,44
245.22480,-4.36288,-50.02626,4.33664,50.02626,22412,44
245.52480,-4.06195,-41.05527,4.03571,41.05527,22412,44
245.84780,-3.73904,-31.86201,3.71280,31.86201,22412,44
246.23980,-3.34719,-23.25813,3.32095,23.25813,22412,44
246.71880,-2.86810,-15.23263,2.84186,15.23263,22412,44
247.26480,-2.32207,-7.35885,2.29583,7.35885,22412,44
247.60580,-2.61673,-15.12879,2.59049,15.12879,22476,44
248.00580,-3.02088,-23.74095,2.99464,23.74095,22476,45
248.36580,-3.38125,-32.49710,3.35501,32.49710,22476,45
248.70780,-3.72324,-41.09303,3.69700,41.09303,22476,45
249.07380,-4.08912,-50.04705,4.06288,50.04705,22476,45
249.40480,-4.42029,-57.66042,4.39405,57.66042,22476,45
249.79120,-4.80615,-66.49148,4.77991,66.49149,22476,45
250.04980,-4.84580,-65.64572,4.81956,65.64572,22476,45
250.30578,-4.57586,-56.62534,4.54962,56.62534,22412,45
250.60080,-4.27836,-47.57538,4.25212,47.57538,22412,45
250.90780,-3.97100,-38.39862,3.94476,38.39862,22412,45
251.24180,-3.63689,-29.35151,3.61065,29.35151,22412,45
251.65780,-3.22097,-20.85101,3.19473,20.85101,22412,45
252.19080,-2.68783,-12.58957,2.66159,12.58957,22412,45
252.64780,-2.35770,-8.92625,2.33146,8.92625,22412,45
253.00380,-2.73501,-17.62773,2.70877,17.62773,22476,45
253.39380,-3.12687,-26.17633,3.10063,26.17633,22476,46
253.72680,-3.46014,-34.51046,3.43390,34.51046,22476,46
254.07580,-3.80915,-43.24234,3.78291,43.24234,22476,46
254.42080,-4.15416,-51.59166,4.12792,51.59166,22476,46
254.79280,-4.52597,-59.97192,4.49973,59.97192,22476,46
255.17678,-4.91001,-68.96332,4.88377,68.96332,22476,46
255.40078,-4.77696,-63.15679,4.75072,63.15679,22476,46
255.68880,-4.47953,-53.51676,4.45329,53.51677,22412,46
255.98880,-4.17798,-44.36209,4.15173,44.36209,22412,46
256.28878,-3.87804,-35.50303,3.85180,35.50303,22412,46
256.64280,-3.52385,-26.67739,3.49761,26.67739,22412,46
257.09119,-3.07573,-18.41598,3.04949,18.41598,22412,46
257.62580,-2.54087,-10.60491,2.51463,10.60491,22412,46
258.01480,-2.46136,-11.52825,2.43511,11.52825,22412,46
258.40878,-2.86722,-20.24787,2.84098,20.24787,22476,46
258.78378,-3.24309,-28.88321,3.21684,28.88321,22476,47
259.12580,-3.58497,-37.61157,3.55873,37.61156,22476,47
259.48278,-3.94218,-46.52230,3.91594,46.52230,22476,47
259.84878,-4.30821,-55.09218,4.28197,55.09218,22476,47
260.22278,-4.68201,-63.52877,4.65576,63.52877,22476,47
260.51880,-4.95247,-69.79490,4.92623,69.79490,22476,47
260.76581,-4.68479,-60.00628,4.65855,60.00628,22476,47
261.02578,-4.41990,-51.60863,4.39365,51.60863,22412,47
261.31281,-4.13190,-43.02324,4.10566,43.02324,22412,47
261.62180,-3.82288,-34.00056,3.79664,34.00056,22412,47
261.96580,-3.47885,-25.78718,3.45261,25.78718,22412,47
262.40281,-3.04171,-17.77936,3.01547,17.77936,22412,47
262.95981,-2.48491,-9.73652,2.45867,9.73652,22412,47
263.30578,-2.45876,-11.50793,2.43251,11.50793,22412,47
263.69981,-2.86424,-20.16359,2.83800,20.16359,22604,47
264.08178,-3.24708,-29.03482,3.22084,29.03482,22604,48
264.41678,-3.58199,-37.60688,3.55575,37.60688,22604,48
264.73981,-3.90514,-45.53230,3.87890,45.53231,22604,48
265.08278,-4.24815,-53.69875,4.22191,53.69875,22604,48
265.40681,-4.57185,-60.96989,4.54561,60.96989,22604,48
265.77578,-4.94100,-69.61157,4.91476,69.61157,22604,48
266.01178,-4.74960,-62.06900,4.72336,62.06900,22604,48
266.28281,-4.47124,-53.05825,4.44499,53.05825,22540,48
266.57581,-4.17683,-44.25051,4.15059,44.25051,22540,48
266.84181,-3.91090,-36.34076,3.88466,36.34076,22540,48
267.12178,-3.63079,-29.02913,3.60455,29.02913,22540,48
267.53181,-3.22085,-20.72695,3.19461,20.72696,22540,48
268.06378,-2.68874,-12.54378,2.66250,12.54378,22540,48
268.49119,-2.32916,-8.02252,2.30292,8.02252,22540,48
268.85878,-2.72368,-17.30129,2.69744,17.30129,22604,48
269.23981,-3.10669,-25.65654,3.08045,25.65654,22604,49
269.59119,-3.45793,-34.40464,3.43169,34.40464,22604,49
269.93578,-3.80307,-43.03977,3.77683,43.03977,22604,49
270.29481,-4.16203,-51.67641,4.13578,51.67641,22604,49
270.68681,-4.55383,-60.51914,4.52759,60.51914,22604,49
271.05381,-4.92095,-69.10741,4.89471,69.10741,22604,49
271.27678,-4.76408,-62.64404,4.73784,62.64404,22604,49
271.54778,-4.48449,-53.55578,4.45825,53.55578,22540,49
271.81078,-4.22007,-45.57933,4.19383,45.57933,22540,49
272.11578,-3.91490,-36.51629,3.88866,36.51628,22540,49
272.47078,-3.55968,-27.31281,3.53344,27.31281,22540,49
272.89178,-3.13871,-19.25776,3.11247,19.25776,22540,49
273.44278,-2.58770,-11.19129,2.56146,11.19129,22540,49
273.99119,-2.30447,-7.90657,2.27823,7.90657,22540,49
274.33781,-2.53223,-13.61418,2.50599,13.61418,22540,49
274.73578,-2.93418,-22.20236,2.90794,22.20236,22476,49
275.09119,-3.28950,-30.48574,3.26326,30.48574,22476,50
275.41278,-3.61133,-38.62225,3.58509,38.62225,22476,50
275.77978,-3.97847,-47.62702,3.95223,47.62703,22476,50
276.15281,-4.35157,-56.18836,4.32533,56.18836,22476,50
276.52781,-4.72638,-64.66632,4.70014,64.66631,22476,50
276.79581,-4.93368,-69.06606,4.90744,69.06606,22476,50
277.04881,-4.65624,-59.15380,4.63000,59.15380,22412,50
277.28378,-4.41730,-51.62613,4.39106,51.62613,22412,50
277.55278,-4.14725,-43.50122,4.12101,43.50122,22412,50
277.86781,-3.83227,-34.33140,3.80603,34.33140,22412,50
278.13981,-3.56006,-27.40390,3.53381,27.40390,22412,50
278.59119,-3.10913,-18.92233,3.08289,18.92233,22412,50
279.10181,-2.59815,-11.30521,2.57190,11.30521,22412,50
279.53681,-2.44559,-11.13284,2.41935,11.13284,22412,50
279.91778,-2.83935,-19.62445,2.81311,19.62445,22476,50
280.29119,-3.21327,-28.18597,3.18703,28.18597,22476,51
280.63778,-3.56029,-37.02576,3.53405,37.02576,22476,51
280.96978,-3.89251,-45.21675,3.86627,45.21675,22476,51
281.25778,-4.18039,-52.12935,4.15415,52.12935,22476,51
281.59181,-4.51428,-59.71506,4.48803,59.71506,22476,51
281.97181,-4.89431,-68.54115,4.86807,68.54115,22476,51
282.18478,-4.80416,-64.06542,4.77792,64.06542,22476,51
282.44278,-4.53538,-55.19786,4.50914,55.19786,22412,51
282.69181,-4.28459,-47.66924,4.25835,47.66924,22412,51
282.96478,-4.01121,-39.46107,3.98497,39.46107,22412,51
283.24978,-3.72616,-31.25171,3.69992,31.25171,22412,51
283.56378,-3.41216,-24.34148,3.38592,24.34148,22412,51
284.02678,-2.94920,-16.27552,2.92296,16.27552,22412,51
284.58978,-2.38638,-8.20281,2.36014,8.20281,22412,51
284.90078,-2.53345,-13.10075,2.50721,13.10075,22412,51
285.29678,-2.93691,-21.73996,2.91067,21.73996,22476,52
285.66878,-3.30944,-30.45580,3.28320,30.45580,22476,52
286.00181,-3.64246,-39.14516,3.61622,39.14516,22476,52
286.36781,-4.00846,-48.11650,3.98222,48.11650,22476,52
286.73778,-4.37860,-56.63449,4.35236,56.63449,22476,52
287.10378,-4.74440,-64.96482,4.71816,64.96481,22476,52
287.39122,-4.88503,-67.01940,4.85879,67.01939,22476,52
287.61578,-4.64282,-58.61945,4.61657,58.61945,22412,52
287.88478,-4.37005,-50.09606,4.34381,50.09606,22412,52
288.15378,-4.10016,-42.04553,4.07391,42.04553,22412,52
288.45978,-3.79416,-33.11526,3.76792,33.11526,22412,52
288.84378,-3.41015,-24.17445,3.38391,24.17445,22412,52
289.27178,-2.98219,-16.71777,2.95594,16.71777,22412,52
289.80381,-2.45015,-9.17041,2.42391,9.17041,22412,52
290.15681,-2.52046,-12.71404,2.49422,12.71404,22412,52
290.54378,-2.91575,-21.23457,2.88951,21.23457,22476,53
290.89381,-3.26639,-29.42863,3.24015,29.42863,22476,53
291.25281,-3.62529,-38.64075,3.59905,38.64075,22476,53
291.57278,-3.94537,-46.53783,3.91913,46.53783,22476,53
291.89678,-4.26952,-54.09228,4.24327,54.09228,22476,53
292.29119,-4.66331,-63.02292,4.63707,63.02292,22476,53
292.62478,-4.93658,-68.87259,4.91034,68.87260,22476,53
292.84778,-4.69030,-60.08955,4.66406,60.08955,22476,53
293.09778,-4.43523,-51.96868,4.40899,51.96867,22412,53
293.34378,-4.18819,-44.50438,4.16195,44.50438,22412,53
293.65378,-3.87820,-35.41788,3.85196,35.41788,22412,53
293.99119,-3.54096,-26.78843,3.51472,26.78843,22412,53
294.44981,-3.08194,-18.28904,3.05570,18.28904,22412,53
294.99119,-2.54104,-10.45314,2.51480,10.45314,22412,53
295.39122,-2.47145,-11.67580,2.44521,11.67580,22412,53
295.79119,-2.88266,-20.46953,2.85642,20.46953,22476,53
296.15578,-3.24840,-28.94544,3.22216,28.94544,22476,54
296.49119,-3.58327,-37.51346,3.55703,37.51347,22476,54
296.81478,-3.90750,-45.50137,3.88126,45.50137,22476,54
297.19119,-4.28353,-54.46566,4.25729,54.46566,22476,54
297.57678,-4.66934,-63.18276,4.64310,63.18276,22476,54
297.88181,-4.96086,-69.92956,4.93462,69.92957,22476,54
298.10181,-4.72787,-61.26702,4.70163,61.26702,22476,54
298.36578,-4.45743,-52.59676,4.43119,52.59676,22412,54
298.63981,-4.18221,-44.28815,4.15597,44.28815,22412,54
298.94678,-3.87525,-35.25085,3.84901,35.25085,22412,54
299.29119,-3.53104,-26.54016,3.50480,26.54016,22412,54
299.74978,-3.07193,-18.11326,3.04569,18.11326,22412,54
300.29119,-2.53109,-10.32371,2.50485,10.32371,22412,54
300.63181,-2.45997,-11.11938,2.43373,11.11938,22412,54
301.00978,-2.85122,-19.69814,2.82497,19.69814,22476,54
301.39122,-3.23329,-28.51136,3.20705,28.51136,22476,55
301.72278,-3.56529,-36.97687,3.53904,36.97687,22476,55
302.08381,-3.92642,-45.96489,3.90018,45.96489,22476,55
302.44478,-4.28748,-54.44239,4.26124,54.44239,22476,55
302.82178,-4.66426,-62.98666,4.63802,62.98666,22476,55
303.11881,-4.95441,-69.82441,4.92817,69.82441,22476,55
303.35778,-4.70916,-60.64283,4.68292,60.64283,22476,55
303.64178,-4.41915,-51.43310,4.39291,51.43310,22412,55
303.94078,-4.11915,-42.49394,4.09291,42.49394,22412,55
304.24578,-3.81410,-33.52477,3.78786,33.52477,22412,55
304.61278,-3.44708,-24.84047,3.42084,24.84047,22412,55
305.09119,-2.96913,-16.44749,2.94289,16.44749,22412,55
305.62178,-2.43814,-8.83700,2.41190,8.83700,22412,55
305.99119,-2.58871,-14.00177,2.56247,14.00177,22412,55
306.37878,-2.98281,-22.67820,2.95657,22.67820,22476,55
306.72878,-3.33336,-31.08448,3.30711,31.08448,22476,56
307.03878,-3.64330,-39.09489,3.61706,39.09489,22476,56
307.36381,-3.96831,-47.01335,3.94206,47.01335,22476,56
307.69119,-4.29542,-54.64385,4.26918,54.64386,22476,56
308.08978,-4.69421,-63.63848,4.66797,63.63848,22476,56
308.39122,-4.95052,-69.33249,4.92428,69.33249,22476,56
308.64278,-4.67440,-59.42947,4.64816,59.42947,22476,56
308.91878,-4.39397,-50.63934,4.36773,50.63934,22412,56
309.22078,-4.09102,-41.54555,4.06478,41.54556,22412,56
309.49119,-3.82107,-33.70197,3.79483,33.70198,22412,56
309.83278,-3.47905,-25.42215,3.45281,25.42215,22412,56
310.29119,-3.02099,-17.19152,2.99475,17.19152,22412,56
310.84078,-2.47111,-9.34671,2.44486,9.34671,22412,56
311.21978,-2.55642,-13.27583,2.53018,13.27583,22412,56
311.59878,-2.94266,-21.79383,2.91642,21.79383,22476,56
311.97278,-3.31728,-30.67536,3.29104,30.67536,22476,57
312.30878,-3.65324,-39.23482,3.62700,39.23483,22476,57
312.62378,-3.96830,-47.00991,3.94206,47.00991,22476,57
312.99281,-4.33738,-55.56509,4.31114,55.56509,22476,57
313.35081,-4.69521,-63.60942,4.66897,63.60942,22476,57
313.63081,-4.95812,-69.75968,4.93188,69.75968,22476,57
313.87681,-4.69529,-60.12410,4.66904,60.12410,22476,57
314.13878,-4.42807,-51.71475,4.40182,51.71475,22412,57
314.39178,-4.17406,-43.98065,4.14782,43.98065,22412,57
314.66878,-3.89711,-35.82051,3.87087,35.82051,22412,57
314.99119,-3.57489,-27.38268,3.54865,27.38268,22412,57
315.41878,-3.14684,-19.19919,3.12060,19.19919,22412,57
315.96478,-2.60100,-11.18866,2.57476,11.18866,22412,57
316.36881,-2.46693,-11.14410,2.44069,11.14410,22412,57
316.73578,-2.84706,-19.57993,2.82082,19.57993,22604,57
317.10581,-3.21811,-28.05248,3.19187,28.05248,22604,58
317.41981,-3.53227,-36.09610,3.50602,36.09610,22604,58
317.78378,-3.89632,-45.09507,3.87008,45.09507,22604,58
318.11881,-4.23133,-53.08876,4.20508,53.08876,22604,58
318.45178,-4.56403,-60.62071,4.53779,60.62071,22604,58
318.81281,-4.92518,-69.08864,4.89894,69.08864,22604,58
319.02381,-4.80185,-63.61982,4.77561,63.61982,22604,58
319.29119,-4.52491,-54.50258,4.49867,54.50258,22540,58
319.59119,-4.22327,-45.44446,4.19703,45.44446,22540,58
319.84478,-3.96912,-37.94273,3.94288,37.94273,22540,58
320.17081,-3.64300,-28.98491,3.61676,28.98491,22540,58
320.59119,-3.22305,-20.41718,3.19681,20.41718,22540,58
321.09478,-2.71902,-12.72045,2.69278,12.72045,22540,58
321.55578,-2.40479,-9.45681,2.37855,9.45681,22540,58
321.91378,-2.78239,-18.15245,2.75615,18.15244,22604,58
322.29178,-3.16214,-26.72931,3.13590,26.72931,22604,59
322.64481,-3.51538,-35.67884,3.48913,35.67884,22604,59
322.99119,-3.86149,-44.27209,3.83525,44.27209,22604,59
323.36578,-4.23645,-53.19805,4.21021,53.19806,22604,59
323.69678,-4.56713,-60.64600,4.54089,60.64600,22604,59
324.03181,-4.90225,-68.49574,4.87601,68.49574,22604,59
324.26778,-4.79148,-63.28112,4.76524,63.28112,22604,59
324.54481,-4.50484,-53.93118,4.47860,53.93118,22540,59
324.83278,-4.21533,-45.11827,4.18909,45.11827,22540,59
325.13878,-3.90921,-36.06492,3.88297,36.06492,22540,59
325.49119,-3.55698,-26.87106,3.53074,26.87106,22540,59
325.92481,-3.12303,-18.72227,3.09679,18.72227,22540,59
326.48178,-2.56597,-10.64263,2.53973,10.64263,22540,59
326.71681,-2.33126,-7.22571,2.30502,7.22571,22540,59