File: data-raw/Experiment 2/Results/INSTRON data/Experiment 2.is_ccyclic_RawData/Specimen_RawData_5.csv
Text Inputs : Specimen label,"Short plate 2 T1"

Time,Extension,Load,Compressive extension,Compressive load,Segment ID,Total Cycle Count
(sec),(mm),(N),(mm),(N),,
0.00000,-0.02686,0.06051,0.00000,-0.06051,12835,0
0.25980,-0.02686,0.04586,0.00000,-0.04586,12835,0
0.74580,-0.02686,0.02015,0.00000,-0.02015,12835,0
1.03680,-0.02686,-0.01629,0.00000,0.01629,3220,0
1.42880,-0.18636,0.01934,0.15949,-0.01934,3220,0
1.86080,-0.40344,-0.39968,0.37658,0.39968,3220,0
2.35880,-0.65231,-3.94526,0.62544,3.94526,3220,0
2.85080,-0.92960,-7.48909,0.90274,7.48909,3220,0
3.92780,-2.01202,-19.15281,1.98516,19.15281,22476,0
4.80820,-2.89221,-30.38308,2.86535,30.38308,22476,0
5.24580,-3.33011,-37.20911,3.30325,37.20911,22476,0
5.68980,-3.77410,-44.35776,3.74724,44.35776,22476,0
6.05480,-4.13890,-50.35934,4.11204,50.35934,22476,0
6.34080,-4.42524,-55.04734,4.39838,55.04734,22476,0
6.59480,-4.67899,-59.14600,4.65213,59.14600,22476,0
6.82080,-4.90513,-62.89665,4.87827,62.89665,22476,0
7.13180,-5.21619,-67.77407,5.18933,67.77407,22476,0
7.39580,-5.20609,-65.74219,5.17923,65.74220,22476,0
7.59180,-4.99990,-60.50282,4.97304,60.50282,22412,0
7.85180,-4.73660,-54.18842,4.70974,54.18842,22412,0
8.07180,-4.51633,-49.07385,4.48947,49.07385,22412,0
8.33480,-4.25299,-43.48694,4.22613,43.48694,22412,0
8.71180,-3.87617,-36.02438,3.84931,36.02438,22412,0
9.04480,-3.54312,-30.12949,3.51626,30.12949,22412,0
9.69480,-2.89326,-20.57125,2.86640,20.57125,22412,0
10.77480,-1.81311,-9.54672,1.78625,9.54672,22412,0
11.71480,-2.28696,-17.41415,2.26010,17.41415,22476,1
12.40820,-2.98026,-27.42473,2.95340,27.42473,22476,1
12.74680,-3.31927,-33.33946,3.29241,33.33946,22476,1
13.12180,-3.69422,-39.92628,3.66735,39.92628,22476,1
13.42480,-3.99723,-45.26965,3.97037,45.26965,22476,1
13.65880,-4.23128,-49.36270,4.20442,49.36270,22476,1
13.88280,-4.45538,-53.31871,4.42852,53.31871,22476,1
14.11680,-4.68918,-57.39516,4.66232,57.39516,22476,1
14.32580,-4.89830,-61.08829,4.87144,61.08829,22476,1
14.51280,-5.08528,-64.32771,5.05842,64.32771,22476,1
14.73880,-5.31132,-68.22427,5.28446,68.22427,22476,1
14.95380,-5.27315,-66.02126,5.24628,66.02126,22476,1
15.13480,-5.08166,-61.15764,5.05480,61.15764,22412,1
15.34080,-4.87228,-56.06536,4.84542,56.06536,22412,1
15.64880,-4.56357,-48.87322,4.53671,48.87322,22412,1
15.92880,-4.28319,-42.71512,4.25633,42.71512,22412,1
16.21880,-3.99326,-37.00851,3.96640,37.00851,22412,1
16.57980,-3.63203,-30.38947,3.60517,30.38947,22412,1
17.14780,-3.06418,-21.90576,3.03732,21.90576,22412,1
18.19280,-2.01912,-10.82346,1.99226,10.82346,22412,1
18.62080,-1.72456,-8.71723,1.69769,8.71723,22412,1
19.10880,-2.23446,-15.89056,2.20760,15.89056,22476,1
19.40880,-2.53503,-19.79905,2.50817,19.79905,22476,2
19.58380,-2.71022,-22.43447,2.68336,22.43447,22476,2
19.77280,-2.89933,-25.26601,2.87247,25.26601,22476,2
19.93480,-3.06121,-27.81370,3.03435,27.81370,22476,2
20.07680,-3.20320,-30.29154,3.17634,30.29154,22476,2
20.19280,-3.31928,-32.34138,3.29241,32.34138,22476,2
20.31080,-3.43732,-34.52023,3.41046,34.52023,22476,2
20.45680,-3.58324,-37.04436,3.55638,37.04436,22476,2
20.59980,-3.72622,-39.59017,3.69936,39.59016,22476,2
20.79080,-3.91741,-42.97435,3.89055,42.97435,22476,2
20.98080,-4.10709,-46.36018,4.08022,46.36018,22476,2
21.22780,-4.35435,-50.75444,4.32749,50.75444,22476,2
21.53880,-4.66510,-56.30907,4.63824,56.30907,22476,2
21.75780,-4.88426,-60.11746,4.85740,60.11746,22476,2
22.10380,-5.23034,-66.20402,5.20348,66.20402,22476,2
22.33880,-5.42776,-69.40067,5.40090,69.40067,22476,2
22.52380,-5.22281,-63.85013,5.19595,63.85013,22476,2
22.66480,-5.07654,-60.16218,5.04968,60.16218,22412,2
22.80980,-4.92958,-56.64333,4.90272,56.64333,22412,2
22.92880,-4.80978,-53.85987,4.78292,53.85987,22412,2
23.08280,-4.65544,-50.28676,4.62858,50.28676,22412,2
23.21880,-4.51941,-47.24343,4.49255,47.24343,22412,2
23.38080,-4.35722,-43.49128,4.33036,43.49128,22412,2
23.53080,-4.20714,-40.34622,4.18028,40.34622,22412,2
23.67480,-4.06318,-37.64515,4.03632,37.64515,22412,2
23.82880,-3.90938,-34.80931,3.88251,34.80931,22412,2
23.94080,-3.79724,-32.75090,3.77038,32.75090,22412,2
24.06580,-3.67218,-30.44892,3.64532,30.44892,22412,2
24.17780,-3.56024,-28.59421,3.53338,28.59421,22412,2
24.29380,-3.44430,-26.69921,3.41744,26.69921,22412,2
24.46180,-3.27617,-24.26573,3.24931,24.26573,22412,2
24.66080,-3.07710,-21.64131,3.05024,21.64131,22412,2
24.91080,-2.82725,-18.58111,2.80039,18.58111,22412,2
25.30180,-2.43620,-14.39591,2.40933,14.39592,22412,2
25.83480,-1.90326,-9.30092,1.87640,9.30093,22412,2
26.12380,-1.77815,-9.01162,1.75129,9.01162,22412,2
26.48780,-2.16045,-14.44739,2.13359,14.44739,22476,2
26.90280,-2.57704,-19.83830,2.55018,19.83830,22476,3
27.39680,-3.07118,-27.36041,3.04432,27.36041,22476,3
27.67680,-3.35131,-32.28015,3.32445,32.28016,22476,3
27.97280,-3.64710,-37.53494,3.62024,37.53495,22476,3
28.34280,-4.01719,-44.13065,3.99033,44.13065,22476,3
28.64480,-4.31935,-49.60040,4.29249,49.60040,22476,3
29.03280,-4.70716,-56.57605,4.68029,56.57605,22476,3
29.31080,-4.98529,-61.52888,4.95843,61.52888,22476,3
29.54980,-5.22432,-65.73512,5.19746,65.73512,22476,3
29.82480,-5.41669,-68.53854,5.38983,68.53854,22476,3
30.04980,-5.16985,-62.09796,5.14299,62.09796,22476,3
30.28880,-4.92645,-56.15375,4.89959,56.15375,22412,3
30.58980,-4.62435,-49.15871,4.59749,49.15871,22412,3
30.87980,-4.33426,-42.59627,4.30740,42.59627,22412,3
31.35180,-3.86227,-33.48922,3.83541,33.48922,22412,3
31.72380,-3.49021,-27.00015,3.46335,27.00015,22412,3
32.31780,-2.89638,-19.05578,2.86952,19.05578,22412,3
33.27980,-1.93429,-9.34849,1.90743,9.34849,22412,3
34.36980,-2.59404,-19.77794,2.56718,19.77794,22476,4
34.99180,-3.21620,-29.51968,3.18934,29.51968,22476,4
35.33580,-3.56024,-35.59547,3.53338,35.59547,22476,4
35.67780,-3.90235,-41.71705,3.87549,41.71704,22476,4
35.95480,-4.17918,-46.78338,4.15232,46.78338,22476,4
36.38280,-4.60732,-54.36581,4.58045,54.36581,22476,4
36.65680,-4.88124,-59.35185,4.85438,59.35185,22476,4
36.93480,-5.15924,-64.33465,5.13237,64.33465,22476,4
37.30280,-5.42700,-68.34955,5.40014,68.34955,22476,4
37.62280,-5.08401,-59.61636,5.05715,59.61636,22412,4
38.00180,-4.70238,-50.55135,4.67552,50.55135,22412,4
38.38080,-4.32325,-41.95253,4.29638,41.95253,22412,4
38.80820,-3.89630,-33.80316,3.86944,33.80316,22412,4
39.40580,-3.29817,-23.98418,3.27131,23.98418,22412,4
40.80820,-1.89623,-8.76255,1.86937,8.76255,22412,4
42.16180,-2.93422,-24.53225,2.90736,24.53225,22476,5
42.99080,-3.76308,-38.98015,3.73622,38.98015,22476,5
43.82380,-4.59624,-53.84276,4.56938,53.84276,22476,5
44.29480,-5.06721,-62.43609,5.04035,62.43608,22476,5
44.74980,-5.47497,-69.37911,5.44811,69.37910,22476,5
45.24880,-4.94804,-55.99153,4.92118,55.99154,22412,5
45.63980,-4.55625,-46.91657,4.52939,46.91657,22412,5
46.03180,-4.16393,-38.52593,4.13707,38.52593,22412,5
46.32480,-3.87106,-33.06343,3.84420,33.06343,22412,5
46.63180,-3.56400,-27.65017,3.53714,27.65017,22412,5
47.07480,-3.12080,-21.45731,3.09394,21.45731,22412,5
47.74880,-2.44700,-13.89009,2.42013,13.89009,22412,5
48.69680,-2.01649,-11.87607,1.98963,11.87607,22412,5
49.62180,-2.94809,-24.53241,2.92122,24.53241,22476,6
50.22080,-3.54701,-34.74714,3.52015,34.74714,22476,6
50.80480,-4.13085,-45.26993,4.10399,45.26993,22476,6
51.17680,-4.50311,-52.01259,4.47625,52.01259,22476,6
51.59280,-4.91912,-59.48347,4.89226,59.48347,22476,6
51.98680,-5.31312,-66.61385,5.28625,66.61385,22476,6
52.23180,-5.43327,-67.91554,5.40641,67.91554,22476,6
52.52080,-5.12403,-60.02716,5.09717,60.02716,22412,6
52.80680,-4.83526,-53.10392,4.80840,53.10392,22412,6
53.12280,-4.51899,-45.85773,4.49213,45.85773,22412,6
53.38880,-4.25276,-40.01040,4.22590,40.01040,22412,6
53.69580,-3.94600,-34.26555,3.91914,34.26555,22412,6
54.04480,-3.59678,-28.03918,3.56992,28.03918,22412,6
54.72180,-2.92003,-18.89106,2.89317,18.89106,22412,6
55.80820,-1.83390,-7.81788,1.80704,7.81788,22412,6
56.76480,-2.69292,-20.42803,2.66606,20.42803,22476,7
57.49180,-3.42012,-32.20671,3.39326,32.20671,22476,7
57.93080,-3.85908,-40.12882,3.83222,40.12882,22476,7
58.38480,-4.31311,-48.41132,4.28625,48.41132,22476,7
58.71380,-4.64191,-54.29580,4.61505,54.29580,22476,7
59.02280,-4.95114,-59.92075,4.92428,59.92075,22476,7
59.37480,-5.30309,-66.30180,5.27623,66.30180,22476,7
59.72580,-5.34239,-65.33130,5.31553,65.33130,22476,7
60.09980,-4.95689,-55.86986,4.93003,55.86986,22412,7
60.34180,-4.71399,-50.18356,4.68713,50.18356,22412,7
60.62480,-4.43103,-43.72014,4.40417,43.72014,22412,7
60.84880,-4.20683,-38.96966,4.17997,38.96966,22412,7
61.10820,-3.94804,-34.13047,3.92118,34.13047,22412,7
61.29380,-3.76176,-30.74218,3.73490,30.74218,22412,7
61.45980,-3.59580,-27.83782,3.56894,27.83782,22412,7
61.71580,-3.33988,-24.07327,3.31302,24.07327,22412,7
61.94980,-3.10570,-20.99609,3.07884,20.99609,22412,7
62.18280,-2.87293,-18.19632,2.84607,18.19632,22412,7
62.35380,-2.70177,-16.28023,2.67491,16.28023,22412,7
62.56780,-2.48771,-14.04932,2.46085,14.04932,22412,7
62.91880,-2.13680,-10.70440,2.10994,10.70440,22412,7
63.25280,-1.80355,-7.39496,1.77669,7.39496,22412,7
64.04880,-2.59075,-18.94679,2.56389,18.94679,22604,7
64.89480,-3.43715,-32.31839,3.41028,32.31839,22604,8
65.42280,-3.96515,-41.87347,3.93829,41.87347,22604,8
65.83380,-4.37615,-49.32558,4.34929,49.32558,22604,8
66.20820,-4.74990,-56.15081,4.72304,56.15081,22604,8
66.45880,-5.00109,-60.72119,4.97423,60.72119,22604,8
66.71280,-5.25514,-65.32611,5.22828,65.32611,22604,8
66.99980,-5.48279,-69.03433,5.45593,69.03433,22604,8
67.24380,-5.21528,-61.90544,5.18842,61.90544,22540,8
67.44080,-5.01440,-57.02923,4.98754,57.02923,22540,8
67.64380,-4.81032,-52.27947,4.78346,52.27947,22540,8
67.86180,-4.59213,-47.31138,4.56527,47.31138,22540,8
68.06980,-4.38398,-42.45049,4.35712,42.45049,22540,8
68.30180,-4.15185,-37.72476,4.12499,37.72476,22540,8
68.49680,-3.95702,-34.14103,3.93016,34.14103,22540,8
68.71180,-3.74175,-30.21707,3.71488,30.21707,22540,8
69.00180,-3.45198,-25.57522,3.42512,25.57522,22540,8
69.58080,-2.87296,-18.12379,2.84610,18.12379,22540,8
70.59280,-1.86092,-7.87212,1.83406,7.87212,22540,8
71.58680,-2.74509,-20.89627,2.71823,20.89627,22604,9
72.06380,-3.22207,-28.34723,3.19521,28.34723,22604,9
72.30820,-3.46622,-32.72916,3.43936,32.72916,22604,9
72.70680,-3.86520,-39.83853,3.83834,39.83853,22604,9
73.05080,-4.20913,-46.16328,4.18227,46.16328,22604,9
73.58180,-4.74001,-55.78407,4.71315,55.78407,22604,9
74.05380,-5.21219,-64.41457,5.18533,64.41457,22604,9
74.52480,-5.34866,-65.14084,5.32180,65.14084,22604,9
75.00980,-4.85233,-53.01012,4.82547,53.01012,22540,9
75.50780,-4.35401,-41.64251,4.32715,41.64251,22540,9
75.89480,-3.96707,-34.13422,3.94021,34.13422,22540,9
76.20820,-3.65387,-28.49979,3.62701,28.49979,22540,9
76.84880,-3.01301,-19.51371,2.98615,19.51371,22540,9
77.84480,-2.01689,-9.36238,1.99003,9.36238,22540,9
78.39780,-1.81458,-8.07266,1.78772,8.07266,22540,9
78.97680,-2.39172,-16.27676,2.36486,16.27676,22476,9
79.42680,-2.84240,-22.51334,2.81554,22.51334,22476,10
79.85180,-3.26725,-29.19296,3.24039,29.19296,22476,10
80.06780,-3.48335,-33.07457,3.45649,33.07457,22476,10
80.33180,-3.74726,-37.84539,3.72040,37.84539,22476,10
80.60820,-4.02326,-42.79314,3.99639,42.79314,22476,10
81.00980,-4.42542,-50.02777,4.39856,50.02777,22476,10
81.50820,-4.92338,-59.07883,4.89652,59.07883,22476,10
81.80880,-5.22435,-64.55180,5.19749,64.55180,22476,10
82.12780,-5.50901,-69.46307,5.48215,69.46307,22476,10
82.48080,-5.13084,-59.59346,5.10398,59.59346,22412,10
82.81880,-4.79040,-51.51037,4.76353,51.51037,22412,10
83.22680,-4.38215,-42.08890,4.35529,42.08891,22412,10
83.54180,-4.06703,-35.83478,4.04017,35.83478,22412,10
83.78180,-3.82715,-31.37326,3.80029,31.37326,22412,10
84.05080,-3.55811,-26.92636,3.53125,26.92636,22412,10
84.33280,-3.27605,-22.91619,3.24919,22.91619,22412,10
84.74080,-2.86816,-17.81734,2.84130,17.81734,22412,10
85.12380,-2.48495,-13.73983,2.45809,13.73983,22412,10
85.64280,-1.96604,-8.76566,1.93918,8.76566,22412,10
86.06280,-2.11889,-12.42079,2.09203,12.42079,22476,10
86.47480,-2.53593,-17.74210,2.50907,17.74210,22476,11
86.84080,-2.90247,-22.99832,2.87561,22.99832,22476,11
87.19480,-3.25634,-28.65237,3.22947,28.65237,22476,11
87.39080,-3.45249,-32.20391,3.42563,32.20391,22476,11
87.58280,-3.64427,-35.68850,3.61741,35.68850,22476,11
87.78280,-3.84448,-39.32685,3.81762,39.32685,22476,11
87.95080,-4.01238,-42.37755,3.98551,42.37755,22476,11
88.14980,-4.21141,-45.99200,4.18455,45.99200,22476,11
88.32180,-4.38346,-49.11194,4.35660,49.11194,22476,11
88.48980,-4.55148,-52.23547,4.52462,52.23547,22476,11
88.62480,-4.68627,-54.63157,4.65941,54.63157,22476,11
88.76380,-4.82543,-57.18230,4.79857,57.18230,22476,11
88.94080,-5.00243,-60.33332,4.97557,60.33332,22476,11
89.09280,-5.15438,-63.15347,5.12752,63.15347,22476,11
89.25480,-5.31650,-66.10357,5.28964,66.10357,22476,11
89.40820,-5.46944,-68.85093,5.44258,68.85093,22476,11
89.52880,-5.45028,-67.65174,5.42341,67.65174,22476,11
89.68680,-5.27779,-63.12878,5.25093,63.12878,22476,11
89.84880,-5.11069,-59.01911,5.08383,59.01911,22412,11
89.97980,-4.97828,-55.85514,4.95142,55.85514,22412,11
90.11880,-4.83862,-52.54330,4.81176,52.54330,22412,11
90.29680,-4.66042,-48.49983,4.63356,48.49982,22412,11
90.43480,-4.52241,-45.22773,4.49555,45.22773,22412,11
90.57880,-4.37828,-41.91888,4.35142,41.91888,22412,11
90.71480,-4.24214,-39.22271,4.21528,39.22271,22412,11
90.85280,-4.10408,-36.45198,4.07722,36.45198,22412,11
90.99580,-3.96133,-33.87605,3.93447,33.87605,22412,11
91.12180,-3.83529,-31.44620,3.80843,31.44620,22412,11
91.25480,-3.70218,-29.20472,3.67531,29.20472,22412,11
91.44680,-3.51025,-26.14601,3.48339,26.14601,22412,11
91.67380,-3.28321,-22.84385,3.25635,22.84385,22412,11
91.93680,-3.02029,-19.52112,2.99343,19.52112,22412,11
92.20820,-2.74911,-16.43486,2.72225,16.43486,22412,11
92.70820,-2.24925,-11.50443,2.22239,11.50443,22412,11
93.18380,-1.88035,-8.40635,1.85349,8.40635,22412,11
93.59580,-2.31592,-14.80750,2.28906,14.80750,22476,11
93.95280,-2.67433,-19.51334,2.64746,19.51334,22476,12
94.36680,-3.08841,-25.79991,3.06155,25.79991,22476,12
94.60780,-3.32954,-29.93671,3.30268,29.93671,22476,12
94.78280,-3.50453,-33.07715,3.47767,33.07716,22476,12
94.99180,-3.71348,-36.84797,3.68662,36.84797,22476,12
95.18780,-3.90963,-40.35421,3.88277,40.35421,22476,12
95.36380,-4.08540,-43.67588,4.05854,43.67588,22476,12
95.53980,-4.26155,-46.91474,4.23469,46.91474,22476,12
95.71280,-4.43465,-49.95089,4.40779,49.95089,22476,12
95.86680,-4.58858,-52.75439,4.56172,52.75439,22476,12
96.06680,-4.78841,-56.40835,4.76155,56.40835,22476,12
96.20180,-4.92360,-58.83432,4.89674,58.83432,22476,12
96.34680,-5.06851,-61.51592,5.04165,61.51591,22476,12
96.49680,-5.21858,-64.25337,5.19172,64.25336,22476,12
96.66480,-5.38659,-67.22637,5.35973,67.22636,22476,12
96.80180,-5.51730,-69.61985,5.49044,69.61985,22476,12
96.95480,-5.36483,-65.32638,5.33797,65.32638,22476,12
97.07980,-5.23274,-61.95296,5.20587,61.95296,22476,12
97.19680,-5.11268,-58.91063,5.08582,58.91063,22412,12
97.33680,-4.97126,-55.56284,4.94440,55.56284,22412,12
97.45680,-4.85067,-52.74813,4.82381,52.74813,22412,12
97.55980,-4.74735,-50.39674,4.72049,50.39674,22412,12
97.66980,-4.63737,-47.92346,4.61051,47.92346,22412,12
97.76980,-4.53752,-45.45638,4.51065,45.45638,22412,12
97.88780,-4.41947,-42.75909,4.39261,42.75909,22412,12
97.99180,-4.31538,-40.47731,4.28852,40.47731,22412,12
98.09880,-4.20825,-38.46571,4.18139,38.46571,22412,12
98.23180,-4.07524,-35.70445,4.04838,35.70445,22412,12
98.34480,-3.96241,-33.76320,3.93555,33.76320,22412,12
98.47580,-3.83137,-31.27459,3.80451,31.27459,22412,12
98.58880,-3.71818,-29.37898,3.69132,29.37898,22412,12
98.72280,-3.58426,-27.08777,3.55739,27.08777,22412,12
98.87580,-3.43141,-24.88421,3.40454,24.88421,22412,12
99.01980,-3.28727,-22.77294,3.26041,22.77294,22412,12
99.15980,-3.14715,-21.00517,3.12029,21.00517,22412,12
99.30980,-2.99734,-19.24201,2.97048,19.24201,22412,12
99.42780,-2.87939,-17.78169,2.85253,17.78169,22412,12
99.58980,-2.71717,-16.05784,2.69031,16.05784,22412,12
99.73080,-2.57615,-14.54686,2.54929,14.54686,22412,12
99.94280,-2.36424,-12.52323,2.33738,12.52323,22412,12
100.27580,-2.03125,-9.24204,2.00439,9.24204,22412,12
100.54080,-1.94353,-9.33104,1.91667,9.33104,22412,12
100.87380,-2.29339,-14.34982,2.26653,14.34982,22476,12
101.14080,-2.56205,-17.86042,2.53519,17.86042,22476,13
101.39180,-2.81359,-21.43467,2.78673,21.43467,22476,13
101.58980,-3.01150,-24.39655,2.98464,24.39655,22476,13
101.76480,-3.18644,-27.20984,3.15958,27.20984,22476,13
101.90980,-3.33158,-29.83147,3.30471,29.83147,22476,13
102.06380,-3.48560,-32.55817,3.45874,32.55817,22476,13
102.19180,-3.61346,-34.87046,3.58660,34.87046,22476,13
102.32980,-3.75149,-37.45898,3.72463,37.45898,22476,13
102.46280,-3.88462,-39.79610,3.85776,39.79610,22476,13
102.57180,-3.99353,-41.84083,3.96667,41.84083,22476,13
102.70080,-4.12236,-44.14891,4.09550,44.14891,22476,13
102.81280,-4.23457,-46.22032,4.20771,46.22032,22476,13
102.97280,-4.39460,-49.14740,4.36774,49.14740,22476,13
103.12880,-4.55061,-52.03193,4.52375,52.03193,22476,13
103.29180,-4.71344,-54.91101,4.68658,54.91101,22476,13
103.44980,-4.87156,-57.77399,4.84469,57.77399,22476,13
103.69080,-5.11248,-62.20301,5.08562,62.20301,22476,13
103.88180,-5.30362,-65.69998,5.27676,65.69998,22476,13
104.05280,-5.47458,-68.85194,5.44772,68.85194,22476,13
104.31980,-5.29350,-63.30588,5.26664,63.30589,22476,13
104.58480,-5.02181,-56.67871,4.99495,56.67871,22412,13
104.84080,-4.76453,-50.62760,4.73767,50.62761,22412,13
105.08980,-4.51554,-44.82454,4.48867,44.82454,22412,13
105.30820,-4.29744,-39.99242,4.27058,39.99242,22412,13
105.56380,-4.04140,-35.06231,4.01454,35.06231,22412,13
105.83380,-3.77132,-30.11157,3.74446,30.11157,22412,13
106.23280,-3.37240,-23.91010,3.34554,23.91010,22412,13
106.88480,-2.72024,-15.96571,2.69338,15.96571,22412,13
107.91580,-1.96790,-9.87854,1.94104,9.87854,22412,13
108.94280,-3.00863,-24.26521,2.98177,24.26521,22476,14
109.33180,-3.39774,-30.86974,3.37088,30.86974,22476,14
109.70680,-3.77264,-37.69499,3.74578,37.69500,22476,14
110.04480,-4.11051,-43.83171,4.08365,43.83171,22476,14
110.39980,-4.46580,-50.38669,4.43893,50.38669,22476,14
110.75680,-4.82273,-56.78467,4.79587,56.78467,22476,14
111.18880,-5.25474,-64.73531,5.22788,64.73531,22476,14
111.49380,-5.52373,-69.39375,5.49687,69.39375,22476,14
111.80780,-5.18519,-60.46394,5.15833,60.46394,22412,14
112.16480,-4.82486,-51.92676,4.79800,51.92676,22412,14
112.47880,-4.51067,-44.60526,4.48381,44.60526,22412,14
112.87680,-4.11236,-36.32066,4.08550,36.32066,22412,14
113.34380,-3.64541,-27.82433,3.61855,27.82433,22412,14
114.08680,-2.90272,-17.92634,2.87586,17.92634,22412,14
115.20820,-1.89308,-8.34304,1.86622,8.34304,22412,14
116.21480,-2.92491,-22.87761,2.89805,22.87761,22476,15
116.69980,-3.40991,-30.93991,3.38305,30.93991,22476,15
117.02180,-3.73178,-36.84193,3.70492,36.84193,22476,15
117.31080,-4.02079,-42.13651,3.99393,42.13651,22476,15
117.70480,-4.41492,-49.32899,4.38806,49.32899,22476,15
118.09680,-4.80682,-56.45708,4.77996,56.45708,22476,15
118.55680,-5.26689,-64.89982,5.24003,64.89983,22476,15
119.12780,-5.23042,-61.58356,5.20356,61.58356,22412,15
119.80820,-4.54585,-45.34655,4.51898,45.34655,22412,15
120.37680,-3.97667,-33.72332,3.94981,33.72332,22412,15
121.30820,-3.04564,-19.44823,3.01878,19.44823,22412,15
122.78580,-2.12615,-12.05727,2.09929,12.05727,22476,15
123.92980,-3.27588,-28.41662,3.24901,28.41662,22476,16
124.73180,-4.07778,-43.12664,4.05092,43.12664,22476,16
125.39480,-4.74079,-55.20061,4.71393,55.20061,22476,16
126.08880,-5.43500,-67.75141,5.40814,67.75140,22476,16
126.62380,-5.10767,-58.39278,5.08081,58.39278,22412,16
127.16780,-4.56193,-45.61076,4.53507,45.61076,22412,16
127.51580,-4.21364,-38.14808,4.18678,38.14808,22412,16
127.86980,-3.85974,-31.38631,3.83288,31.38631,22412,16
128.16180,-3.56769,-26.52995,3.54083,26.52995,22412,16
128.53479,-3.19458,-21.31560,3.16772,21.31561,22412,16
129.20279,-2.52661,-13.76040,2.49975,13.76040,22412,16
129.88480,-1.87891,-7.67261,1.85205,7.67261,22412,16
130.50479,-2.52630,-17.02465,2.49944,17.02464,22476,17
131.25180,-3.27387,-28.26909,3.24701,28.26909,22476,17
131.81480,-3.83699,-38.60168,3.81013,38.60168,22476,17
132.20819,-4.22993,-45.73872,4.20307,45.73872,22476,17
132.53180,-4.55398,-51.78829,4.52712,51.78829,22476,17
133.05680,-5.07891,-61.27321,5.05205,61.27321,22476,17
133.70380,-5.36027,-64.63484,5.33341,64.63484,22476,17
134.24680,-4.80702,-51.25131,4.78016,51.25131,22412,17
134.79980,-4.25360,-38.95995,4.22674,38.95995,22412,17
135.35480,-3.69857,-28.59735,3.67171,28.59735,22412,17
136.32280,-2.73051,-15.80350,2.70365,15.80350,22412,17
137.76880,-2.44613,-15.92719,2.41927,15.92719,22604,17
138.87380,-3.55193,-33.27830,3.52507,33.27830,22604,18
139.59680,-4.27499,-46.59310,4.24813,46.59310,22604,18
140.51480,-5.19298,-63.27865,5.16612,63.27865,22604,18
141.37580,-5.03908,-56.59790,5.01222,56.59790,22540,18
141.95780,-4.45594,-43.05553,4.42908,43.05553,22540,18
142.60080,-3.81288,-30.41654,3.78602,30.41654,22540,18
143.58380,-2.82983,-16.86582,2.80297,16.86582,22540,18
144.48380,-1.92985,-7.84313,1.90299,7.84313,22540,18
145.30820,-2.65770,-18.75620,2.63084,18.75620,22604,19
145.99580,-3.34606,-29.45895,3.31920,29.45896,22604,19
146.53980,-3.89010,-39.42860,3.86324,39.42860,22604,19
147.20819,-4.55808,-51.55851,4.53122,51.55851,22604,19
147.96180,-5.31209,-65.42962,5.28522,65.42962,22604,19
148.65380,-5.11156,-58.19488,5.08469,58.19488,22540,19
149.20819,-4.55600,-45.24978,4.52914,45.24978,22540,19
149.72180,-4.04178,-34.56381,4.01491,34.56381,22540,19
150.40280,-3.36077,-23.31664,3.33391,23.31664,22540,19
151.41880,-2.34475,-11.94630,2.31789,11.94630,22540,19
152.29280,-1.89669,-8.31274,1.86983,8.31274,22540,19
153.25180,-2.86849,-21.93572,2.84163,21.93572,22476,20
154.00819,-3.62438,-34.80311,3.59752,34.80311,22476,20
154.76380,-4.38054,-48.50616,4.35368,48.50616,22476,20
155.41680,-5.03351,-60.36934,5.00665,60.36934,22476,20
155.93480,-5.54197,-69.62422,5.51511,69.62422,22476,20
156.43580,-5.02552,-56.31279,4.99866,56.31279,22412,20
156.96380,-4.49639,-43.94976,4.46953,43.94976,22412,20
157.49780,-3.96238,-33.11385,3.93552,33.11385,22412,20
158.49380,-2.96635,-18.36953,2.93949,18.36953,22412,20
159.72180,-2.01032,-10.00525,1.98346,10.00525,22412,20
160.83680,-3.13933,-25.85877,3.11247,25.85877,22476,21
161.42280,-3.72545,-36.32696,3.69859,36.32696,22476,21
162.18080,-4.48358,-50.28172,4.45671,50.28172,22476,21
163.10820,-5.41060,-67.10371,5.38374,67.10371,22476,21
163.81980,-4.99110,-55.21934,4.96424,55.21934,22412,21
164.38378,-4.42641,-42.14457,4.39955,42.14457,22412,21
164.95380,-3.85629,-30.92694,3.82943,30.92694,22412,21
165.80820,-3.00230,-18.63400,2.97544,18.63400,22412,21
167.18480,-2.10809,-11.48175,2.08123,11.48175,22412,21
168.30780,-3.23832,-27.44837,3.21146,27.44837,22476,22
168.90480,-3.83552,-38.31301,3.80866,38.31301,22476,22
169.50780,-4.43856,-49.31127,4.41170,49.31126,22476,22
170.11280,-5.04341,-60.34410,5.01655,60.34410,22476,22
170.74578,-5.45891,-66.77707,5.43205,66.77707,22476,22
171.19680,-4.99199,-55.21623,4.96513,55.21623,22412,22
171.59780,-4.59031,-45.85227,4.56345,45.85227,22412,22
172.01480,-4.17312,-36.83795,4.14626,36.83795,22412,22
172.42080,-3.76708,-29.34677,3.74022,29.34677,22412,22
172.98880,-3.19903,-21.04364,3.17217,21.04364,22412,22
173.99780,-2.19022,-10.32642,2.16336,10.32642,22412,22
174.98880,-2.57294,-17.29061,2.54608,17.29061,22476,23
175.92380,-3.50843,-32.15905,3.48156,32.15905,22476,23
176.70819,-4.29248,-46.66444,4.26562,46.66444,22476,23
177.60080,-5.18539,-62.93425,5.15852,62.93425,22476,23
178.25180,-5.29422,-62.57498,5.26736,62.57497,22412,23
178.80980,-4.73018,-49.07318,4.70332,49.07318,22412,23
179.48180,-4.05819,-34.65817,4.03132,34.65817,22412,23
180.26280,-3.27715,-22.03460,3.25029,22.03461,22412,23
181.72380,-1.93208,-8.34739,1.90522,8.34739,22412,23
182.95478,-3.18738,-26.52763,3.16052,26.52763,22476,24
183.71880,-3.95160,-40.24086,3.92474,40.24086,22476,24
184.48278,-4.71535,-54.27115,4.68849,54.27115,22476,24
185.14980,-5.38250,-66.42036,5.35564,66.42036,22476,24
185.73980,-5.14243,-58.65199,5.11557,58.65199,22412,24
186.25580,-4.62419,-46.64722,4.59733,46.64722,22412,24
186.97580,-3.90431,-31.65133,3.87745,31.65133,22412,24
187.80880,-3.07110,-19.35851,3.04424,19.35851,22412,24
189.20478,-2.09439,-11.06559,2.06753,11.06559,22412,24
190.42880,-3.32742,-28.79791,3.30055,28.79791,22476,25
191.27480,-4.17334,-44.32792,4.14648,44.32792,22476,25
192.07180,-4.97038,-58.82780,4.94352,58.82780,22476,25
192.88480,-5.37029,-64.27810,5.34343,64.27810,22476,25
193.55280,-4.69323,-48.13919,4.66637,48.13919,22412,25
194.18280,-4.06311,-34.57325,4.03625,34.57325,22412,25
194.92380,-3.32220,-22.48399,3.29534,22.48399,22412,25
196.20819,-2.03810,-8.63720,2.01124,8.63720,22412,25
197.28780,-2.84046,-20.96285,2.81360,20.96285,22476,26
197.90819,-3.46046,-31.14794,3.43360,31.14794,22476,26
198.42678,-3.97946,-40.66211,3.95260,40.66211,22476,26
198.92980,-4.48252,-49.98102,4.45566,49.98103,22476,26
199.39280,-4.94549,-58.34677,4.91863,58.34678,22476,26
200.05178,-5.54959,-69.07259,5.52273,69.07259,22476,26
200.44880,-5.12506,-58.22529,5.09820,58.22528,22412,26
201.03080,-4.54137,-44.61747,4.51451,44.61747,22412,26
201.59180,-3.98024,-33.02122,3.95338,33.02122,22412,26
202.28678,-3.28515,-22.01524,3.25829,22.01524,22412,26
203.30880,-2.26323,-10.83582,2.23637,10.83582,22412,26
204.12480,-2.35968,-14.44772,2.33282,14.44772,22476,26
204.95580,-3.19245,-26.40348,3.16559,26.40348,22476,27
205.70819,-3.94469,-40.02289,3.91783,40.02289,22476,27
206.32280,-4.55958,-51.37520,4.53272,51.37520,22476,27
207.07880,-5.31560,-65.11112,5.28873,65.11111,22476,27
207.75080,-5.14753,-58.61691,5.12067,58.61691,22412,27
208.35778,-4.53851,-44.44463,4.51165,44.44463,22412,27
209.13480,-3.76123,-28.96565,3.73437,28.96565,22412,27
210.50819,-2.38836,-12.10911,2.36150,12.10911,22412,27
211.90819,-2.81865,-20.54112,2.79178,20.54112,22604,28
212.91080,-3.82171,-37.77253,3.79485,37.77253,22604,28
213.68380,-4.59464,-51.98775,4.56778,51.98775,22604,28
214.44480,-5.35568,-65.76463,5.32881,65.76463,22604,28
214.99778,-5.25049,-61.06908,5.22363,61.06908,22540,28
215.41580,-4.82862,-51.08584,4.80175,51.08585,22540,28
216.06478,-4.17937,-36.61905,4.15251,36.61905,22540,28
216.54080,-3.70329,-27.94932,3.67643,27.94932,22540,28
217.88578,-2.35838,-11.77163,2.33152,11.77163,22540,28
219.10680,-2.66338,-18.41677,2.63652,18.41677,22604,29
220.10580,-3.66256,-34.80024,3.63570,34.80024,22604,29
220.98478,-4.54175,-50.95204,4.51488,50.95204,22604,29
221.99578,-5.55260,-69.39185,5.52574,69.39185,22604,29
222.57978,-5.02541,-55.61507,4.99855,55.61507,22540,29
223.11980,-4.48458,-43.07842,4.45772,43.07842,22540,29
223.81280,-3.79152,-29.43805,3.76466,29.43805,22540,29
224.99880,-2.60521,-14.06801,2.57835,14.06801,22540,29
226.25480,-2.06893,-10.83221,2.04207,10.83221,22540,29
227.47880,-3.29913,-28.30324,3.27227,28.30324,22476,30
228.31380,-4.13393,-43.62283,4.10707,43.62283,22476,30
229.08080,-4.90110,-57.49750,4.87424,57.49750,22476,30
229.75080,-5.56975,-69.78269,5.54288,69.78269,22476,30
230.40078,-4.92345,-53.22314,4.89659,53.22314,22412,30
231.01880,-4.30495,-39.15089,4.27809,39.15089,22412,30
231.60680,-3.71675,-28.13060,3.68989,28.13060,22412,30
232.74280,-2.58072,-13.81288,2.55386,13.81288,22412,30
234.10480,-2.59468,-17.36589,2.56782,17.36589,22476,31
235.10820,-3.59811,-33.59051,3.57124,33.59051,22476,31
235.71778,-4.20819,-44.82790,4.18133,44.82790,22476,31
236.50878,-4.99909,-59.18552,4.97223,59.18552,22476,31
237.20180,-5.47268,-66.63047,5.44582,66.63047,22476,31
237.70980,-4.94859,-53.73727,4.92172,53.73727,22412,31
238.29980,-4.35806,-40.17967,4.33120,40.17967,22412,31
238.76278,-3.89514,-31.05884,3.86828,31.05884,22412,31
239.63480,-3.02307,-18.58348,2.99621,18.58348,22412,31
240.87078,-2.04239,-9.82293,2.01553,9.82293,22412,31
241.92080,-3.10714,-24.91094,3.08028,24.91094,22476,32
242.55680,-3.74323,-36.16656,3.71637,36.16656,22476,32
243.09678,-4.28337,-46.18741,4.25650,46.18741,22476,32
243.80820,-4.99422,-58.96926,4.96735,58.96926,22476,32
244.49880,-5.50191,-67.34799,5.47505,67.34799,22476,32
244.97178,-5.01094,-55.13830,4.98408,55.13831,22412,32
245.40819,-4.57429,-45.07232,4.54743,45.07232,22412,32
245.80820,-4.17408,-36.36088,4.14721,36.36088,22412,32
246.33080,-3.65104,-26.89714,3.62418,26.89714,22412,32
247.10820,-2.87420,-16.83702,2.84734,16.83702,22412,32
247.89480,-2.08698,-8.94027,2.06012,8.94027,22412,32
248.55178,-2.38678,-14.63992,2.35991,14.63992,22476,32
249.42480,-3.26135,-27.39389,3.23449,27.39389,22476,33
249.95180,-3.78838,-37.09194,3.76152,37.09194,22476,33
250.50680,-4.34347,-47.44680,4.31661,47.44680,22476,33
251.12980,-4.96639,-58.45197,4.93953,58.45197,22476,33
251.87278,-5.46457,-66.37036,5.43771,66.37036,22476,33
252.35680,-4.96573,-54.06043,4.93887,54.06042,22412,33
252.78480,-4.53730,-44.13138,4.51044,44.13137,22412,33
253.17580,-4.14605,-35.67410,4.11918,35.67410,22412,33
253.53678,-3.78513,-29.09316,3.75827,29.09316,22412,33
254.25180,-3.07008,-19.01828,3.04322,19.01828,22412,33
255.37880,-1.94319,-7.44649,1.91633,7.44649,22412,33
256.05078,-2.58488,-17.15914,2.55802,17.15914,22476,34
256.77780,-3.31249,-28.20236,3.28563,28.20236,22476,34
257.19080,-3.72539,-35.82441,3.69853,35.82441,22476,34
257.64680,-4.18146,-44.27129,4.15460,44.27129,22476,34
258.03980,-4.57448,-51.47686,4.54762,51.47686,22476,34
258.41080,-4.94553,-58.11211,4.91867,58.11211,22476,34
258.68878,-5.22346,-63.20591,5.19660,63.20591,22476,34
258.96478,-5.49945,-68.27416,5.47258,68.27416,22476,34
259.20880,-5.41318,-65.12697,5.38632,65.12697,22476,34
259.44378,-5.16869,-58.89512,5.14182,58.89512,22412,34
259.68680,-4.92379,-53.11782,4.89693,53.11782,22412,34
259.92780,-4.68231,-47.65099,4.65545,47.65099,22412,34
260.16678,-4.44338,-42.01619,4.41652,42.01619,22412,34
260.46381,-4.14613,-35.68505,4.11927,35.68505,22412,34
260.81281,-3.79725,-29.34308,3.77039,29.34308,22412,34
261.25580,-3.35423,-22.63126,3.32737,22.63126,22412,34
261.81281,-2.79729,-15.90981,2.77043,15.90981,22412,34
262.46681,-2.14321,-9.46059,2.11635,9.46059,22412,34
263.17178,-2.43111,-15.06513,2.40425,15.06513,22476,34
263.64678,-2.90754,-21.75227,2.88068,21.75227,22476,35
263.94981,-3.21043,-26.50761,3.18357,26.50761,22476,35
264.17481,-3.43558,-30.50442,3.40872,30.50443,22476,35
264.32278,-3.58347,-33.23065,3.55661,33.23065,22476,35
264.49178,-3.75243,-36.35036,3.72557,36.35036,22476,35
264.67278,-3.93363,-39.71084,3.90677,39.71084,22476,35
264.84281,-4.10332,-42.87288,4.07646,42.87288,22476,35
265.10678,-4.36759,-47.79680,4.34073,47.79681,22476,35
265.42678,-4.68735,-53.42786,4.66049,53.42786,22476,35
265.63478,-4.89550,-57.22072,4.86864,57.22072,22476,35
266.07378,-5.33458,-65.21573,5.30772,65.21573,22476,35
266.50819,-5.39678,-64.57569,5.36992,64.57569,22476,35
266.79881,-5.09669,-57.17162,5.06983,57.17162,22412,35
267.06578,-4.82852,-50.88223,4.80166,50.88223,22412,35
267.34181,-4.55250,-44.55486,4.52564,44.55486,22412,35
267.70278,-4.19126,-36.56029,4.16440,36.56029,22412,35
267.99281,-3.90143,-31.03935,3.87457,31.03935,22412,35
268.27878,-3.61516,-26.25862,3.58830,26.25862,22412,35
268.74381,-3.15016,-19.87508,3.12330,19.87508,22412,35
269.46078,-2.43342,-12.27391,2.40656,12.27391,22412,35
270.20819,-2.15492,-11.45430,2.12806,11.45430,22412,35
270.87578,-2.83054,-20.46555,2.80368,20.46556,22476,36
271.51581,-3.47059,-31.00754,3.44373,31.00754,22476,36
271.85678,-3.81163,-37.40910,3.78477,37.40910,22476,36
272.20678,-4.16147,-43.85422,4.13461,43.85422,22476,36
272.51678,-4.47163,-49.51788,4.44477,49.51788,22476,36
272.77878,-4.73342,-54.30852,4.70656,54.30852,22476,36
273.04481,-4.99947,-59.01130,4.97261,59.01130,22476,36
273.30578,-5.26058,-63.86489,5.23372,63.86489,22476,36
273.58781,-5.54249,-69.06453,5.51563,69.06453,22476,36
273.79481,-5.42131,-65.20545,5.39445,65.20544,22476,36
274.01981,-5.18695,-59.26684,5.16009,59.26684,22412,36
274.21478,-4.99001,-54.56518,4.96315,54.56518,22412,36
274.53581,-4.66836,-47.25118,4.64150,47.25117,22412,36
274.90578,-4.29832,-38.77147,4.27145,38.77147,22412,36
275.20819,-3.99633,-32.80555,3.96947,32.80555,22412,36
275.94078,-3.26321,-21.27930,3.23635,21.27930,22412,36
277.25878,-1.94534,-7.37072,1.91848,7.37072,22412,36
278.27381,-2.91856,-21.84840,2.89170,21.84840,22476,37
278.80819,-3.45260,-30.69731,3.42574,30.69731,22476,37
279.15078,-3.79558,-37.05854,3.76872,37.05854,22476,37
279.43478,-4.07943,-42.34108,4.05257,42.34108,22476,37
279.66878,-4.31366,-46.69883,4.28679,46.69883,22476,37
279.89778,-4.54261,-50.81834,4.51575,50.81834,22476,37
280.25778,-4.90256,-57.24985,4.87570,57.24985,22476,37
280.62478,-5.26962,-63.98984,5.24276,63.98984,22476,37
281.06281,-5.46484,-66.24597,5.43798,66.24597,22476,37
281.70678,-4.80557,-50.26382,4.77871,50.26382,22412,37
282.44278,-4.06924,-34.20224,4.04238,34.20224,22412,37
282.91678,-3.59528,-25.95589,3.56842,25.95589,22412,37
284.17481,-2.33737,-11.31153,2.31051,11.31153,22412,37
285.28681,-2.64522,-17.91083,2.61836,17.91083,22604,37
286.20819,-3.56670,-32.77611,3.53984,32.77611,22604,38
286.80819,-4.16663,-43.90291,4.13976,43.90291,22604,38
287.40681,-4.76557,-54.77442,4.73871,54.77442,22604,38
287.90078,-5.25973,-63.82116,5.23287,63.82116,22604,38
288.43681,-5.38262,-64.14010,5.35576,64.14010,22604,38
289.07278,-4.73738,-48.69496,4.71052,48.69496,22540,38
289.56281,-4.24737,-37.51550,4.22051,37.51550,22540,38
290.03778,-3.77237,-28.59595,3.74551,28.59595,22540,38
291.15078,-2.65931,-14.39417,2.63245,14.39417,22540,38
292.45978,-2.51193,-16.05917,2.48507,16.05917,22604,38
293.33178,-3.38484,-29.49039,3.35798,29.49039,22604,39
293.95678,-4.00978,-40.87950,3.98292,40.87950,22604,39
294.41378,-4.46690,-49.31637,4.44003,49.31637,22604,39
295.00819,-5.06076,-60.17087,5.03390,60.17088,22604,39
295.64778,-5.50238,-67.15477,5.47552,67.15477,22604,39
296.11678,-5.01636,-55.09178,4.98950,55.09178,22540,39
296.74478,-4.38759,-40.48273,4.36073,40.48273,22540,39
297.50078,-3.63139,-26.32975,3.60453,26.32975,22540,39
298.50819,-2.62427,-13.96049,2.59741,13.96049,22540,39
299.60819,-1.95847,-8.42147,1.93161,8.42147,22540,39
300.90819,-3.27397,-27.55085,3.24711,27.55085,22476,40
301.70819,-4.07389,-42.32911,4.04703,42.32911,22476,40
302.32278,-4.68883,-53.38717,4.66197,53.38717,22476,40
302.94478,-5.31107,-64.77286,5.28420,64.77286,22476,40
303.49078,-5.32508,-62.63439,5.29822,62.63439,22476,40
303.93578,-4.87403,-51.82915,4.84717,51.82915,22412,40
304.30819,-4.50190,-43.24469,4.47504,43.24469,22412,40
304.76778,-4.04179,-33.58031,4.01492,33.58031,22412,40
305.50819,-3.30179,-21.74116,3.27493,21.74116,22412,40
306.96478,-1.96741,-8.24687,1.94055,8.24687,22412,40
308.11278,-3.13888,-25.31736,3.11202,25.31736,22476,41
308.74281,-3.76906,-36.54011,3.74220,36.54011,22476,41
309.40578,-4.43226,-48.82346,4.40540,48.82346,22476,41
310.03978,-5.06606,-60.25818,5.03920,60.25817,22476,41
310.46281,-5.48910,-67.89154,5.46223,67.89154,22476,41
310.83978,-5.31990,-62.45001,5.29303,62.45001,22476,41
311.20819,-4.94642,-53.39931,4.91956,53.39931,22412,41
311.80819,-4.34595,-39.58016,4.31909,39.58016,22412,41
312.43478,-3.71875,-27.56532,3.69189,27.56532,22412,41
313.79881,-2.35489,-11.36692,2.32803,11.36692,22412,41
315.09181,-2.80020,-19.91683,2.77334,19.91683,22476,42
315.76378,-3.47224,-30.97445,3.44538,30.97445,22476,42
316.34478,-4.05309,-41.78422,4.02623,41.78422,22476,42
316.86078,-4.56921,-51.23283,4.54235,51.23283,22476,42
317.39078,-5.09905,-60.72484,5.07219,60.72484,22476,42
317.76678,-5.47516,-67.61164,5.44830,67.61164,22476,42
318.02478,-5.45691,-65.90616,5.43005,65.90616,22476,42
318.24281,-5.22815,-60.15291,5.20129,60.15291,22412,42
318.40178,-5.06701,-56.24927,5.04015,56.24927,22412,42
318.61481,-4.85306,-51.29712,4.82620,51.29712,22412,42
318.81681,-4.65091,-46.62139,4.62405,46.62140,22412,42
318.99381,-4.47398,-42.56212,4.44712,42.56212,22412,42
319.18578,-4.28190,-38.24759,4.25504,38.24759,22412,42
319.44981,-4.01787,-32.97438,3.99101,32.97438,22412,42
319.69581,-3.77185,-28.50769,3.74499,28.50769,22412,42
320.14481,-3.32292,-21.88608,3.29606,21.88608,22412,42
320.80819,-2.65973,-14.27408,2.63287,14.27408,22412,42
321.82178,-2.24725,-12.48767,2.22039,12.48767,22476,42
322.60678,-3.03709,-23.51841,3.01023,23.51841,22476,43
323.06281,-3.49318,-31.30323,3.46631,31.30323,22476,43
323.42081,-3.85121,-38.08236,3.82435,38.08236,22476,43
323.78581,-4.21616,-44.76317,4.18930,44.76317,22476,43
324.08881,-4.51917,-50.34159,4.49231,50.34159,22476,43
324.48578,-4.91615,-57.44280,4.88929,57.44279,22476,43
324.76481,-5.19512,-62.50694,5.16826,62.50694,22476,43
325.12778,-5.55806,-69.14413,5.53120,69.14413,22476,43
325.40378,-5.34914,-63.14375,5.32228,63.14375,22476,43
325.80478,-4.94139,-53.16059,4.91453,53.16059,22412,43
326.09181,-4.65389,-46.72389,4.62703,46.72389,22412,43
326.42178,-4.32394,-39.10575,4.29708,39.10575,22412,43
326.73578,-4.00989,-32.74762,3.98303,32.74762,22412,43
327.05278,-3.69283,-27.11201,3.66597,27.11201,22412,43
327.70278,-3.04289,-18.42867,3.01603,18.42867,22412,43
328.38478,-2.36086,-11.41407,2.33400,11.41407,22412,43
328.97078,-2.13618,-10.83751,2.10932,10.83751,22412,43
329.74978,-2.92601,-21.85495,2.89915,21.85495,22476,44
330.20278,-3.37905,-29.34609,3.35219,29.34609,22476,44
330.52678,-3.70296,-35.28252,3.67610,35.28252,22476,44
330.83078,-4.00694,-40.87729,3.98007,40.87729,22476,44
331.17381,-4.35008,-47.34087,4.32322,47.34087,22476,44
331.50778,-4.68381,-53.21242,4.65695,53.21242,22476,44
331.83678,-5.01292,-59.11025,4.98606,59.11025,22476,44
332.20819,-5.38402,-65.92212,5.35716,65.92212,22476,44
332.57981,-5.44028,-65.37317,5.41342,65.37317,22476,44
332.83678,-5.17299,-58.62990,5.14613,58.62991,22412,44
333.13581,-4.87204,-51.63380,4.84518,51.63380,22412,44
333.47681,-4.53095,-43.80065,4.50409,43.80065,22412,44
333.82178,-4.18577,-36.11057,4.15891,36.11057,22412,44
334.22878,-3.77878,-28.49704,3.75192,28.49704,22412,44
334.84681,-3.16067,-19.63813,3.13381,19.63813,22412,44
335.74281,-2.26484,-10.40202,2.23798,10.40202,22412,44
336.50378,-2.39408,-14.36924,2.36722,14.36924,22476,44
337.10278,-2.99500,-22.87343,2.96814,22.87343,22476,45
337.60819,-3.50008,-31.45805,3.47322,31.45805,22476,45
338.05078,-3.94322,-39.69957,3.91636,39.69957,22476,45
338.53878,-4.43116,-48.67409,4.40430,48.67409,22476,45
338.96281,-4.85514,-56.29558,4.82828,56.29558,22476,45
339.42178,-5.31414,-64.64712,5.28727,64.64713,22476,45
339.80819,-5.49318,-66.77171,5.46632,66.77171,22476,45
340.12878,-5.15687,-58.33138,5.13001,58.33138,22412,45
340.41478,-4.86907,-51.58573,4.84221,51.58574,22412,45
340.69378,-4.58997,-45.03801,4.56311,45.03801,22412,45
340.91181,-4.37188,-40.04514,4.34502,40.04514,22412,45
341.10081,-4.18283,-36.00589,4.15597,36.00589,22412,45
341.27381,-4.00981,-32.68585,3.98295,32.68585,22412,45
341.39978,-3.88392,-30.37880,3.85706,30.37880,22412,45
341.55078,-3.73271,-27.70505,3.70585,27.70506,22412,45
341.74878,-3.53484,-24.68295,3.50798,24.68295,22412,45
341.93781,-3.34584,-22.07807,3.31897,22.07807,22412,45
342.11278,-3.17073,-19.81515,3.14386,19.81515,22412,45
342.36978,-2.91396,-16.87195,2.88710,16.87195,22412,45
342.71178,-2.57172,-13.27504,2.54485,13.27504,22412,45
343.22981,-2.05379,-8.31946,2.02692,8.31946,22412,45
343.68878,-2.32365,-13.39564,2.29679,13.39565,22476,45
344.04081,-2.67859,-18.23788,2.65173,18.23787,22476,46
344.43478,-3.07288,-24.04554,3.04602,24.04554,22476,46
344.71178,-3.34997,-28.63711,3.32311,28.63711,22476,46
344.92978,-3.56792,-32.75545,3.54106,32.75545,22476,46
345.14578,-3.78391,-36.90790,3.75705,36.90791,22476,46
345.36578,-4.00389,-40.86048,3.97703,40.86048,22476,46
345.56078,-4.19895,-44.47457,4.17209,44.47457,22476,46
345.76778,-4.40599,-48.31295,4.37913,48.31295,22476,46
345.99678,-4.63482,-52.38953,4.60796,52.38953,22476,46
346.21781,-4.85598,-56.33942,4.82912,56.33942,22476,46
346.43281,-5.07089,-60.23168,5.04403,60.23168,22476,46
346.66181,-5.30002,-64.45697,5.27316,64.45697,22476,46
346.88081,-5.51887,-68.40654,5.49201,68.40654,22476,46
347.01378,-5.55610,-68.53487,5.52924,68.53487,22476,46
347.24781,-5.30089,-61.88327,5.27403,61.88327,22412,46
347.43478,-5.10998,-57.17907,5.08312,57.17907,22412,46
347.63878,-4.90503,-52.29940,4.87817,52.29940,22412,46
347.81978,-4.72356,-48.16954,4.69670,48.16954,22412,46
348.01278,-4.53082,-43.73937,4.50396,43.73937,22412,46
348.20881,-4.33468,-39.28825,4.30782,39.28825,22412,46
348.45678,-4.08648,-34.14003,4.05961,34.14003,22412,46
348.67778,-3.86566,-30.01286,3.83880,30.01286,22412,46
349.09181,-3.45172,-23.46393,3.42486,23.46393,22412,46
349.55878,-2.98464,-17.56259,2.95778,17.56259,22412,46
350.80678,-2.18682,-11.51557,2.15996,11.51557,22412,46
351.57378,-2.96182,-22.34330,2.93496,22.34330,22476,47
351.90681,-3.29485,-27.73386,3.26799,27.73386,22476,47
352.07081,-3.45887,-30.78499,3.43201,30.78499,22476,47
352.23678,-3.62468,-33.86778,3.59782,33.86777,22476,47
352.42678,-3.81490,-37.42337,3.78803,37.42337,22476,47
352.62281,-4.01076,-41.03544,3.98390,41.03544,22476,47
352.82778,-4.21584,-44.77770,4.18898,44.77769,22476,47
353.08881,-4.47690,-49.54999,4.45004,49.54999,22476,47
353.41778,-4.80579,-55.45576,4.77893,55.45576,22476,47
353.79081,-5.17879,-62.15852,5.15193,62.15852,22476,47
354.27381,-5.55488,-68.37385,5.52801,68.37385,22476,47
354.66378,-5.14121,-57.82992,5.11435,57.82992,22412,47
355.00819,-4.79567,-49.72118,4.76881,49.72118,22412,47
355.38278,-4.42063,-41.07743,4.39377,41.07743,22412,47
355.76481,-4.03848,-33.15791,4.01162,33.15791,22412,47
356.35278,-3.45055,-23.38335,3.42368,23.38335,22412,47
357.60819,-2.19551,-9.68350,2.16865,9.68351,22412,47
358.34078,-2.49324,-15.53575,2.46637,15.53575,22604,47
358.85081,-3.00446,-22.95259,2.97760,22.95259,22604,48
359.20819,-3.36156,-28.84067,3.33470,28.84067,22604,48
359.50819,-3.66139,-34.53114,3.63452,34.53114,22604,48
359.89078,-4.04442,-41.48371,4.01756,41.48371,22604,48
360.34078,-4.49457,-49.67019,4.46771,49.67019,22604,48
360.90778,-5.06147,-59.90069,5.03461,59.90069,22604,48
361.47981,-5.59585,-69.52319,5.56899,69.52319,22604,48
361.93578,-5.11253,-57.14783,5.08567,57.14783,22540,48
362.40819,-4.63922,-46.07182,4.61236,46.07182,22540,48
362.92078,-4.12608,-34.84303,4.09922,34.84303,22540,48
363.27078,-3.77618,-28.38769,3.74932,28.38769,22540,48
363.93078,-3.11605,-19.00118,3.08919,19.00118,22540,48
365.06878,-1.97811,-7.38858,1.95125,7.38858,22540,48
365.96878,-2.84640,-20.51457,2.81954,20.51457,22604,49
366.55678,-3.43445,-30.20362,3.40759,30.20362,22604,49
366.89078,-3.76833,-36.44520,3.74147,36.44520,22604,49
367.40281,-4.28045,-45.80786,4.25359,45.80786,22604,49
367.77781,-4.65519,-52.61304,4.62833,52.61304,22604,49
368.17678,-5.05434,-59.76595,5.02748,59.76595,22604,49
368.54278,-5.42047,-66.53371,5.39361,66.53371,22604,49
368.79881,-5.53630,-67.79429,5.50944,67.79430,22604,49
369.15778,-5.15707,-58.18161,5.13021,58.18161,22540,49
369.46781,-4.84527,-50.95384,4.81841,50.95383,22540,49
369.73278,-4.58024,-44.73608,4.55338,44.73608,22540,49
369.95578,-4.35714,-39.65165,4.33028,39.65165,22540,49
370.16878,-4.14401,-35.14828,4.11715,35.14828,22540,49
370.37978,-3.93326,-31.11802,3.90640,31.11802,22540,49
370.74381,-3.56913,-25.17656,3.54227,25.17656,22540,49
371.21681,-3.09594,-18.88413,3.06908,18.88413,22540,49
372.03681,-2.27615,-10.38253,2.24929,10.38253,22540,49
373.26678,-2.50992,-16.01096,2.48306,16.01096,22476,49
374.07081,-3.31454,-28.21534,3.28768,28.21534,22476,50
374.47478,-3.71847,-35.53848,3.69161,35.53848,22476,50
374.83978,-4.08339,-42.32673,4.05653,42.32673,22476,50
375.25378,-4.49757,-49.88508,4.47071,49.88507,22476,50
375.63778,-4.88153,-56.80914,4.85467,56.80914,22476,50
375.95278,-5.19651,-62.43999,5.16965,62.43999,22476,50
376.35678,-5.59620,-69.75941,5.56933,69.75941,22476,50
376.63081,-5.32010,-62.33298,5.29324,62.33298,22412,50
377.03078,-4.91471,-52.44856,4.88785,52.44856,22412,50
377.42978,-4.51539,-43.31670,4.48853,43.31670,22412,50
377.83978,-4.10507,-34.43373,4.07821,34.43373,22412,50
378.29178,-3.65318,-26.42535,3.62632,26.42535,22412,50
379.00819,-2.93739,-17.00937,2.91053,17.00937,22412,50
379.99878,-1.96620,-7.40881,1.93934,7.40881,22412,50
380.84281,-2.83437,-20.28197,2.80751,20.28197,22476,51
381.41981,-3.41150,-29.76518,3.38464,29.76518,22476,51
381.69378,-3.68540,-34.79240,3.65854,34.79240,22476,51
382.02178,-4.01339,-40.82390,3.98653,40.82390,22476,51
382.34281,-4.33456,-46.85842,4.30769,46.85842,22476,51
382.76578,-4.75728,-54.41634,4.73042,54.41634,22476,51
383.24878,-5.24046,-63.14667,5.21360,63.14667,22476,51
383.72981,-5.48293,-66.34336,5.45607,66.34336,22476,51
384.04981,-5.14910,-57.97475,5.12224,57.97475,22412,51
384.40281,-4.79445,-49.68120,4.76758,49.68120,22412,51
384.73578,-4.46134,-42.04544,4.43448,42.04544,22412,51
385.11178,-4.08511,-34.05371,4.05825,34.05371,22412,51
385.63678,-3.56033,-24.97814,3.53347,24.97814,22412,51
386.90819,-2.28928,-10.49717,2.26242,10.49717,22412,51
388.03278,-2.76824,-19.34070,2.74138,19.34070,22476,52
389.10819,-3.84353,-37.71760,3.81667,37.71760,22476,52
389.90819,-4.64325,-52.36669,4.61639,52.36669,22476,52
390.72078,-5.45646,-67.11580,5.42960,67.11580,22476,52
391.40819,-5.07817,-56.22102,5.05131,56.22102,22412,52
392.06878,-4.41628,-40.87815,4.38942,40.87815,22412,52
392.63478,-3.85019,-29.55147,3.82333,29.55147,22412,52
393.80819,-2.67701,-14.10079,2.65014,14.10079,22412,52
395.12681,-2.58151,-16.79877,2.55465,16.79877,22476,52
396.14478,-3.60022,-33.28661,3.57336,33.28661,22476,53
397.00878,-4.46433,-49.28317,4.43747,49.28316,22476,53
397.73978,-5.19529,-62.36399,5.16842,62.36399,22476,53
398.44078,-5.31939,-62.13687,5.29253,62.13688,22476,53
399.04678,-4.70790,-47.71284,4.68104,47.71284,22412,53
399.57481,-4.17990,-35.72671,4.15304,35.72671,22412,53
400.18578,-3.56895,-25.09568,3.54209,25.09568,22412,53
401.30819,-2.44703,-12.04666,2.42017,12.04666,22412,53
402.52278,-2.71570,-18.55310,2.68884,18.55310,22476,54
403.50819,-3.70099,-34.91753,3.67413,34.91753,22476,54
404.23578,-4.42916,-48.42758,4.40230,48.42758,22476,54
404.92381,-5.11686,-60.84724,5.09000,60.84724,22476,54
405.45678,-5.57830,-68.88765,5.55144,68.88765,22476,54
405.76778,-5.24212,-60.23661,5.21526,60.23661,22412,54
406.19181,-4.81500,-50.06143,4.78814,50.06143,22412,54
406.61781,-4.38885,-40.25395,4.36199,40.25395,22412,54
407.03978,-3.96685,-31.61673,3.93999,31.61673,22412,54
407.39881,-3.60767,-25.72270,3.58080,25.72270,22412,54
408.10581,-2.90091,-16.55252,2.87405,16.55252,22412,54
409.20819,-2.15591,-10.73815,2.12905,10.73815,22412,54
410.02678,-2.98576,-22.46499,2.95890,22.46498,22476,55
410.62578,-3.58475,-32.76395,3.55789,32.76395,22476,55
411.06278,-4.02177,-40.80024,3.99491,40.80024,22476,55
411.45481,-4.41390,-48.21883,4.38704,48.21883,22476,55
412.01378,-4.97282,-58.19040,4.94595,58.19040,22476,55
412.60378,-5.56275,-69.05834,5.53589,69.05833,22476,55
413.03181,-5.22534,-59.73336,5.19848,59.73336,22412,55
413.53378,-4.72043,-47.96365,4.69357,47.96365,22412,55
413.90819,-4.34654,-39.30918,4.31968,39.30918,22412,55
414.31181,-3.94266,-31.08557,3.91580,31.08557,22412,55
414.98178,-3.27241,-20.94585,3.24555,20.94584,22412,55
416.17578,-2.07839,-8.31661,2.05153,8.31661,22412,55
417.22878,-2.91564,-21.52539,2.88878,21.52539,22476,56
418.10819,-3.79461,-36.72171,3.76775,36.72171,22476,56
418.63378,-4.32071,-46.34640,4.29385,46.34640,22476,56
419.27381,-4.96066,-57.96869,4.93380,57.96869,22476,56
419.94981,-5.57547,-68.90682,5.54861,68.90682,22476,56
420.44278,-5.05442,-55.67005,5.02756,55.67005,22412,56
420.99478,-4.50142,-42.84081,4.47456,42.84081,22412,56
421.60819,-3.88842,-30.19148,3.86156,30.19147,22412,56
422.69478,-2.80137,-15.33707,2.77451,15.33707,22412,56
423.78681,-2.27389,-12.45129,2.24703,12.45129,22476,56
424.84878,-3.34143,-28.31704,3.31457,28.31704,22476,57
425.26881,-3.76139,-35.86874,3.73453,35.86874,22476,57
425.70819,-4.20047,-44.08466,4.17360,44.08466,22476,57
426.18978,-4.68227,-52.97005,4.65541,52.97005,22476,57
426.80878,-5.30151,-64.24921,5.27465,64.24921,22476,57
427.13178,-5.59700,-69.47154,5.57014,69.47153,22476,57
427.52178,-5.18244,-58.71004,5.15558,58.71004,22412,57
427.82378,-4.87841,-51.53291,4.85155,51.53291,22412,57
428.11278,-4.58931,-44.78141,4.56245,44.78141,22412,57
428.36678,-4.33525,-39.03032,4.30839,39.03032,22412,57
428.72678,-3.97519,-31.75079,3.94833,31.75079,22412,57
429.23678,-3.46526,-23.45231,3.43840,23.45231,22412,57
429.90819,-2.79420,-15.27978,2.76734,15.27978,22412,57
430.93078,-2.22122,-11.59239,2.19436,11.59239,22412,57
432.02078,-3.31917,-27.90577,3.29231,27.90577,22604,58
432.50819,-3.80623,-36.80164,3.77936,36.80164,22604,58
433.00678,-4.30528,-46.03450,4.27842,46.03450,22604,58
433.50478,-4.80318,-55.14104,4.77632,55.14104,22604,58
433.89778,-5.19617,-62.31428,5.16931,62.31428,22604,58
434.28278,-5.58110,-69.40331,5.55424,69.40331,22604,58
434.53778,-5.36964,-63.34074,5.34278,63.34074,22604,58
434.83578,-5.06499,-55.86571,5.03813,55.86571,22540,58
435.22678,-4.67300,-46.82684,4.64614,46.82684,22540,58
435.60378,-4.29598,-38.16241,4.26912,38.16241,22540,58
435.98178,-3.91810,-30.67302,3.89124,30.67302,22540,58
436.73481,-3.16483,-19.43864,3.13797,19.43864,22540,58
437.90819,-1.99216,-7.32934,1.96530,7.32934,22540,58
439.07378,-3.14578,-24.98458,3.11892,24.98458,22604,59
439.72878,-3.80102,-36.74975,3.77416,36.74975,22604,59
440.50378,-4.57603,-51.00290,4.54917,51.00290,22604,59
441.30381,-5.37603,-65.49443,5.34917,65.49443,22604,59
441.80819,-5.33774,-62.47878,5.31088,62.47878,22540,59
442.30819,-4.83187,-50.43561,4.80501,50.43561,22540,59
442.79278,-4.34674,-39.24208,4.31988,39.24208,22540,59
443.25978,-3.87979,-29.97044,3.85293,29.97044,22540,59
444.00819,-3.13149,-19.08168,3.10463,19.08168,22540,59
445.13278,-2.00653,-7.47547,1.97967,7.47547,22540,59
445.21078,-1.97209,-7.30282,1.94523,7.30282,22540,59