File: data-raw/Experiment 2/Results/INSTRON data/Experiment 2.is_ccyclic_RawData/Specimen_RawData_11.csv
Text Inputs : Specimen label,"Long Plate 1 T3"

Time,Extension,Load,Compressive extension,Compressive load,Segment ID,Total Cycle Count
(sec),(mm),(N),(mm),(N),,
0.00000,-0.02560,0.13841,0.00000,-0.13841,12835,0
0.92080,-0.02560,0.19932,0.00000,-0.19932,12835,0
1.92120,-0.37359,0.15388,0.34799,-0.15388,3220,0
3.30480,-1.06585,0.19630,1.04025,-0.19630,3220,0
4.48580,-1.71026,-8.55906,1.68466,8.55906,3220,0
5.71980,-2.94831,-30.12207,2.92271,30.12207,22476,0
6.48380,-3.71221,-47.24148,3.68661,47.24148,22476,0
7.18980,-4.41825,-62.90244,4.39265,62.90244,22476,0
7.87080,-4.39252,-59.27612,4.36692,59.27612,22412,0
8.41280,-3.84695,-44.30268,3.82135,44.30268,22412,0
8.90980,-3.34996,-32.30595,3.32436,32.30595,22412,0
9.82120,-2.43899,-15.45806,2.41339,15.45806,22412,0
11.02120,-2.48846,-18.89902,2.46286,18.89902,22476,1
11.72580,-3.19400,-33.56362,3.16840,33.56362,22476,1
12.38980,-3.85796,-48.72192,3.83236,48.72192,22476,1
12.95280,-4.42105,-61.87225,4.39545,61.87225,22476,1
13.39180,-4.68928,-67.25180,4.66368,67.25180,22476,1
13.83780,-4.22455,-53.78797,4.19895,53.78797,22412,1
14.27480,-3.78665,-42.21421,3.76105,42.21421,22412,1
14.76480,-3.29669,-30.46132,3.27109,30.46132,22412,1
15.59180,-2.46966,-15.56488,2.44406,15.56488,22412,1
16.65180,-2.37843,-16.53307,2.35283,16.53307,22476,1
17.39180,-3.11993,-31.20357,3.09433,31.20357,22476,2
17.87680,-3.60499,-42.46546,3.57939,42.46546,22476,2
18.34380,-4.07211,-53.24353,4.04651,53.24353,22476,2
18.80880,-4.53703,-64.14308,4.51143,64.14308,22476,2
19.29280,-4.55439,-62.80369,4.52879,62.80369,22476,2
19.82120,-4.01898,-47.78181,3.99338,47.78181,22412,2
20.60280,-3.23646,-28.75283,3.21086,28.75283,22412,2
21.67580,-2.16363,-11.03211,2.13803,11.03211,22412,2
22.72120,-2.69070,-21.95701,2.66510,21.95701,22476,3
23.32080,-3.29083,-34.93008,3.26523,34.93008,22476,3
23.69680,-3.66690,-43.65775,3.64130,43.65775,22476,3
24.10380,-4.07401,-53.02713,4.04841,53.02713,22476,3
24.52380,-4.49390,-62.88834,4.46830,62.88834,22476,3
25.03780,-4.58239,-63.25927,4.55679,63.25927,22476,3
25.61580,-3.99588,-47.01308,3.97028,47.01308,22412,3
26.08880,-3.52271,-35.20225,3.49711,35.20225,22412,3
26.65180,-2.95964,-23.03309,2.93404,23.03309,22412,3
27.71580,-1.91574,-7.26736,1.89014,7.26736,22412,3
28.61980,-2.84384,-24.71788,2.81824,24.71788,22476,4
29.20280,-3.42703,-37.86594,3.40143,37.86594,22476,4
29.68980,-3.91399,-49.13752,3.88838,49.13752,22476,4
30.15580,-4.37995,-59.96827,4.35435,59.96827,22476,4
30.61080,-4.78375,-69.20054,4.75815,69.20054,22476,4
31.02120,-4.34647,-56.33276,4.32087,56.33276,22412,4
31.40180,-3.96381,-45.83431,3.93821,45.83431,22412,4
31.77480,-3.59067,-36.59797,3.56507,36.59797,22412,4
32.11980,-3.24544,-28.56059,3.21983,28.56059,22412,4
32.78980,-2.57564,-16.63259,2.55004,16.63259,22412,4
33.72280,-2.19922,-12.78410,2.17362,12.78410,22476,4
34.63280,-3.11498,-30.44655,3.08938,30.44655,22476,5
35.22780,-3.70995,-44.16833,3.68435,44.16833,22476,5
35.76180,-4.24387,-56.70331,4.21827,56.70331,22476,5
36.15280,-4.63488,-65.81295,4.60928,65.81295,22476,5
36.45280,-4.67758,-65.75496,4.65198,65.75496,22476,5
36.83880,-4.27790,-54.22043,4.25230,54.22043,22412,5
37.21680,-3.89881,-44.01766,3.87321,44.01766,22412,5
37.55980,-3.55584,-35.58591,3.53024,35.58591,22412,5
37.87780,-3.23757,-28.25723,3.21197,28.25723,22412,5
38.51580,-2.59972,-16.88543,2.57412,16.88543,22412,5
39.38880,-2.15228,-11.92087,2.12668,11.92087,22412,5
39.83980,-2.61170,-19.98780,2.58610,19.98780,22476,6
40.18980,-2.96212,-26.83291,2.93652,26.83291,22476,6
40.45080,-3.22304,-32.79607,3.19744,32.79607,22476,6
40.67580,-3.44818,-38.06076,3.42258,38.06076,22476,6
40.93680,-3.70906,-44.06178,3.68346,44.06178,22476,6
41.19480,-3.96724,-50.11886,3.94164,50.11886,22476,6
41.44080,-4.21304,-55.88132,4.18744,55.88132,22476,6
41.63980,-4.41211,-60.52060,4.38651,60.52060,22476,6
41.88180,-4.65398,-66.09549,4.62838,66.09550,22476,6
42.09980,-4.76068,-68.17237,4.73507,68.17236,22476,6
42.32380,-4.51724,-60.96386,4.49164,60.96386,22412,6
42.58980,-4.24666,-53.23504,4.22106,53.23504,22412,6
42.90180,-3.93407,-44.72227,3.90847,44.72227,22412,6
43.20580,-3.62990,-37.27534,3.60430,37.27534,22412,6
43.43580,-3.39992,-31.80739,3.37432,31.80739,22412,6
43.93880,-2.89686,-21.59563,2.87126,21.59562,22412,6
44.87580,-1.96007,-7.53455,1.93447,7.53455,22412,6
45.78080,-2.82317,-23.91958,2.79757,23.91958,22476,7
46.36180,-3.40434,-36.83211,3.37874,36.83210,22476,7
46.76380,-3.80617,-46.31380,3.78057,46.31380,22476,7
47.23980,-4.28219,-57.35508,4.25659,57.35508,22476,7
47.62480,-4.66714,-66.37418,4.64154,66.37418,22476,7
48.02120,-4.56213,-62.13389,4.53653,62.13389,22412,7
48.47180,-4.10449,-49.24678,4.07889,49.24678,22412,7
48.92280,-3.65321,-37.79764,3.62761,37.79764,22412,7
49.34980,-3.22600,-27.80198,3.20040,27.80198,22412,7
50.34480,-2.23102,-11.53200,2.20542,11.53201,22412,7
51.19880,-2.50877,-18.04057,2.48317,18.04057,22604,7
51.90080,-3.21148,-32.29161,3.18587,32.29161,22604,8
52.52120,-3.83150,-46.91131,3.80590,46.91131,22604,8
53.33680,-4.64744,-65.83487,4.62183,65.83487,22604,8
54.01380,-4.29163,-54.28205,4.26603,54.28205,22540,8
54.56180,-3.74231,-39.76918,3.71671,39.76918,22540,8
55.13380,-3.17038,-26.56525,3.14478,26.56525,22540,8
56.33180,-1.97259,-7.58500,1.94699,7.58500,22540,8
57.38480,-2.97966,-26.97578,2.95406,26.97578,22604,9
58.00580,-3.60072,-41.31202,3.57512,41.31202,22604,9
58.52180,-4.11667,-53.28412,4.09107,53.28412,22604,9
58.99980,-4.59460,-64.62090,4.56899,64.62090,22604,9
59.41880,-4.62738,-63.92390,4.60178,63.92390,22604,9
59.78580,-4.25123,-53.08045,4.22563,53.08045,22540,9
60.17280,-3.86337,-42.70311,3.83777,42.70311,22540,9
60.57180,-3.46452,-33.05716,3.43891,33.05716,22540,9
61.05480,-2.98147,-22.86754,2.95587,22.86754,22540,9
62.02580,-2.01060,-8.10826,1.98500,8.10826,22540,9
62.77380,-2.24341,-13.41886,2.21780,13.41886,22476,9
63.45680,-2.92918,-26.09736,2.90358,26.09736,22476,10
63.88980,-3.36215,-35.73310,3.33655,35.73310,22476,10
64.38180,-3.85410,-47.43716,3.82850,47.43716,22476,10
65.01780,-4.49003,-62.23267,4.46443,62.23267,22476,10
65.68680,-4.48281,-59.59506,4.45721,59.59505,22412,10
66.13080,-4.03528,-47.27289,4.00968,47.27289,22412,10
66.62980,-3.53609,-34.72416,3.51049,34.72416,22412,10
67.19380,-2.97196,-22.65280,2.94636,22.65280,22412,10
68.02480,-2.14100,-10.03434,2.11540,10.03434,22412,10
68.52120,-2.27056,-13.60617,2.24496,13.60617,22476,10
69.21380,-2.96830,-26.66313,2.94270,26.66313,22476,11
69.46280,-3.21717,-32.28012,3.19156,32.28012,22476,11
69.64580,-3.40032,-36.54047,3.37472,36.54047,22476,11
69.83680,-3.59134,-41.01234,3.56574,41.01234,22476,11
70.06380,-3.81820,-46.38296,3.79260,46.38296,22476,11
70.26280,-4.01741,-51.02165,3.99181,51.02165,22476,11
70.57080,-4.32531,-58.14632,4.29971,58.14632,22476,11
70.77380,-4.52814,-62.96136,4.50254,62.96136,22476,11
71.03280,-4.78717,-69.01702,4.76157,69.01702,22476,11
71.27480,-4.60598,-63.22761,4.58038,63.22761,22476,11
71.44680,-4.42805,-57.99687,4.40245,57.99686,22412,11
71.65680,-4.21576,-52.10678,4.19016,52.10678,22412,11
71.88580,-3.98637,-45.78187,3.96077,45.78186,22412,11
72.09380,-3.77805,-40.34705,3.75245,40.34705,22412,11
72.28280,-3.58919,-35.87130,3.56359,35.87130,22412,11
72.44380,-3.42824,-32.12507,3.40264,32.12508,22412,11
72.65380,-3.21802,-27.31308,3.19242,27.31308,22412,11
72.97280,-2.89915,-21.39107,2.87355,21.39107,22412,11
73.21680,-2.65518,-17.40617,2.62958,17.40617,22412,11
73.72120,-2.15123,-10.13100,2.12563,10.13100,22412,11
74.09380,-2.14170,-11.31631,2.11610,11.31631,22412,11
74.58880,-2.64708,-20.27339,2.62148,20.27339,22476,12
74.94080,-2.99950,-27.23451,2.97390,27.23451,22476,12
75.17680,-3.23534,-32.68956,3.20974,32.68956,22476,12
75.44480,-3.50356,-38.98783,3.47796,38.98783,22476,12
75.79380,-3.85246,-47.19787,3.82686,47.19787,22476,12
76.27880,-4.33752,-58.43777,4.31192,58.43777,22476,12
76.63780,-4.69643,-66.85640,4.67083,66.85640,22476,12
76.94280,-4.63603,-64.07145,4.61043,64.07146,22476,12
77.29180,-4.27741,-53.77470,4.25181,53.77470,22412,12
77.65680,-3.91148,-43.77925,3.88588,43.77925,22412,12
78.23980,-3.32836,-29.77878,3.30276,29.77878,22412,12
79.34980,-2.21829,-11.00733,2.19269,11.00733,22412,12
80.47380,-2.83060,-23.77331,2.80500,23.77331,22476,13
81.22380,-3.58083,-40.61094,3.55523,40.61094,22476,13
82.12120,-4.47754,-61.72803,4.45194,61.72803,22476,13
82.78080,-4.51015,-60.25674,4.48455,60.25674,22412,13
83.42120,-3.86550,-42.52302,3.83990,42.52302,22412,13
84.22080,-3.06568,-24.17997,3.04008,24.17998,22412,13
85.45380,-2.06697,-9.76263,2.04137,9.76263,22412,13
86.47980,-3.10881,-29.72765,3.08321,29.72765,22476,14
87.12120,-3.74985,-44.54653,3.72425,44.54653,22476,14
87.84780,-4.47673,-61.65536,4.45113,61.65536,22476,14
88.50480,-4.53281,-60.86850,4.50721,60.86850,22476,14
89.14080,-3.89177,-43.19494,3.86617,43.19494,22412,14
89.69980,-3.33273,-29.68012,3.30713,29.68012,22412,14
90.48980,-2.54284,-15.59009,2.51724,15.59009,22412,14
91.35480,-2.27496,-13.53327,2.24936,13.53327,22476,14
92.28880,-3.21392,-31.99672,3.18832,31.99672,22476,15
93.05180,-3.97731,-49.87354,3.95171,49.87354,22476,15
93.79380,-4.71902,-67.22093,4.69342,67.22093,22476,15
94.42180,-4.31814,-54.74870,4.29254,54.74870,22412,15
95.09380,-3.64494,-36.91499,3.61934,36.91499,22412,15
96.12120,-2.61790,-16.64337,2.59230,16.64337,22412,15
97.31580,-2.51234,-17.75854,2.48674,17.75854,22476,15
98.08380,-3.28118,-33.67267,3.25558,33.67267,22476,16
98.68780,-3.88526,-47.80310,3.85966,47.80310,22476,16
99.32120,-4.51806,-62.55789,4.49246,62.55789,22476,16
100.01280,-4.44498,-58.28391,4.41938,58.28391,22412,16
100.61080,-3.84398,-41.80009,3.81838,41.80009,22412,16
101.26180,-3.19298,-26.54695,3.16738,26.54695,22412,16
102.52120,-1.97726,-7.42080,1.95166,7.42079,22412,16
103.63980,-3.12521,-29.98052,3.09961,29.98052,22476,17
104.33680,-3.82235,-46.27883,3.79675,46.27883,22476,17
105.22120,-4.70626,-66.94663,4.68066,66.94663,22476,17
105.85780,-4.31649,-54.65808,4.29089,54.65808,22412,17
106.55780,-3.61526,-36.05512,3.58966,36.05512,22412,17
107.48380,-2.68920,-17.67130,2.66360,17.67130,22412,17
108.62680,-2.41667,-16.02503,2.39107,16.02503,22604,17
109.56880,-3.36067,-35.36823,3.33507,35.36823,22604,18
110.27380,-4.06581,-51.85772,4.04021,51.85772,22604,18
111.01180,-4.80358,-69.23940,4.77798,69.23940,22604,18
111.68880,-4.17302,-50.71289,4.14741,50.71289,22540,18
112.43380,-3.42759,-31.52997,3.40199,31.52997,22540,18
113.62120,-2.24035,-11.11915,2.21475,11.11915,22540,18
114.72120,-2.82872,-23.60425,2.80312,23.60425,22604,19
115.48380,-3.59192,-40.77787,3.56632,40.77787,22604,19
116.25180,-4.35990,-58.70654,4.33430,58.70654,22604,19
116.93880,-4.62560,-63.43079,4.60000,63.43079,22604,19
117.49680,-4.05908,-47.68622,4.03348,47.68622,22540,19
118.03180,-3.52382,-33.87294,3.49822,33.87294,22540,19
118.82120,-2.73462,-18.31139,2.70902,18.31139,22540,19
120.12120,-2.14220,-11.33937,2.11660,11.33937,22540,19
121.13080,-3.15815,-30.81556,3.13255,30.81556,22476,20
121.80180,-3.82930,-46.46236,3.80370,46.46236,22476,20
122.48480,-4.51210,-62.38618,4.48650,62.38618,22476,20
123.00180,-4.64313,-64.00608,4.61753,64.00608,22476,20
123.51580,-4.11947,-49.27517,4.09387,49.27517,22412,20
124.19880,-3.43624,-31.69380,3.41064,31.69380,22412,20
125.15980,-2.47518,-14.43738,2.44958,14.43738,22412,20
126.35680,-2.69219,-20.96985,2.66659,20.96984,22476,21
127.27980,-3.61556,-41.34116,3.58996,41.34116,22476,21
127.88480,-4.22045,-55.37965,4.19485,55.37965,22476,21
128.48580,-4.82146,-69.59502,4.79586,69.59502,22476,21
128.92079,-4.41065,-57.20640,4.38505,57.20640,22412,21
129.41680,-3.91249,-43.59009,3.88689,43.59010,22412,21
129.95380,-3.37537,-30.34625,3.34977,30.34625,22412,21
130.88080,-2.44844,-13.96713,2.42284,13.96713,22412,21
132.07580,-2.71534,-21.41479,2.68974,21.41479,22476,22
132.78680,-3.42682,-36.95527,3.40122,36.95528,22476,22
133.37580,-4.01587,-50.64717,3.99027,50.64717,22476,22
133.92780,-4.56761,-63.70172,4.54201,63.70172,22476,22
134.41080,-4.60680,-62.92623,4.58120,62.92623,22476,22
135.01080,-3.99873,-45.91201,3.97313,45.91201,22412,22
135.71980,-3.28949,-28.28515,3.26389,28.28515,22412,22
136.80580,-2.20353,-10.48887,2.17793,10.48887,22412,22
137.85880,-2.81670,-23.36686,2.79110,23.36686,22476,23
138.65680,-3.61497,-41.36961,3.58937,41.36961,22476,23
139.19680,-4.15487,-53.83869,4.12927,53.83869,22476,23
139.78280,-4.74079,-67.73586,4.71519,67.73586,22476,23
140.38378,-4.32293,-54.70633,4.29733,54.70633,22412,23
140.99080,-3.71467,-38.33935,3.68907,38.33935,22412,23
141.52080,-3.18460,-26.11179,3.15900,26.11179,22412,23
142.65580,-2.04984,-8.14430,2.02424,8.14430,22412,23
143.62980,-2.90787,-25.32391,2.88227,25.32391,22476,24
144.18580,-3.46402,-37.85382,3.43842,37.85382,22476,24
145.02180,-4.29994,-57.30909,4.27434,57.30909,22476,24
145.57680,-4.83388,-69.87738,4.80828,69.87738,22476,24
146.11680,-4.26963,-53.25870,4.24403,53.25870,22412,24
146.72080,-3.66488,-36.91508,3.63927,36.91508,22412,24
147.09480,-3.29078,-28.12632,3.26517,28.12632,22412,24
148.28580,-2.09981,-8.90065,2.07421,8.90065,22412,24
149.22280,-2.81496,-23.36593,2.78936,23.36593,22476,25
149.89380,-3.48615,-38.31841,3.46055,38.31841,22476,25
150.52480,-4.11718,-53.03083,4.09158,53.03083,22476,25
151.06680,-4.65903,-65.76553,4.63343,65.76553,22476,25
151.58880,-4.47038,-58.95941,4.44478,58.95940,22412,25
152.17180,-3.88392,-42.74217,3.85832,42.74217,22412,25
152.74180,-3.31394,-28.73299,3.28834,28.73299,22412,25
154.02119,-2.03510,-7.90670,2.00950,7.90670,22412,25
155.08480,-3.00915,-27.28979,2.98355,27.28979,22476,26
155.82180,-3.74619,-44.43232,3.72059,44.43232,22476,26
156.70980,-4.63408,-65.38117,4.60848,65.38117,22476,26
157.40980,-4.32132,-54.80349,4.29572,54.80349,22412,26
158.09278,-3.63705,-36.29775,3.61145,36.29774,22412,26
158.77680,-2.95308,-21.58618,2.92748,21.58618,22412,26
159.87180,-2.11341,-10.16021,2.08781,10.16021,22412,26
160.98780,-3.24418,-32.76311,3.21858,32.76311,22476,27
161.69980,-3.95659,-49.34971,3.93099,49.34970,22476,27
162.34980,-4.60626,-64.64828,4.58066,64.64828,22476,27
162.90680,-4.50933,-60.04605,4.48373,60.04605,22412,27
163.39980,-4.01235,-46.30516,3.98675,46.30516,22412,27
163.85980,-3.55224,-34.15383,3.52664,34.15384,22412,27
164.88580,-2.52620,-14.97801,2.50059,14.97801,22412,27
166.07780,-2.66601,-20.42324,2.64041,20.42323,22604,27
166.95780,-3.54648,-39.74286,3.52088,39.74287,22604,28
167.63580,-4.22433,-55.52306,4.19873,55.52306,22604,28
168.24280,-4.83126,-69.85132,4.80566,69.85133,22604,28
168.67780,-4.41645,-57.32720,4.39085,57.32720,22540,28
169.17380,-3.91836,-43.68315,3.89276,43.68315,22540,28
169.88980,-3.20212,-26.18215,3.17652,26.18215,22540,28
171.08480,-2.00737,-7.43692,1.98177,7.43692,22540,28
172.12120,-3.00145,-27.19430,2.97585,27.19430,22604,29
172.75780,-3.63854,-41.87979,3.61294,41.87979,22604,29
173.32120,-4.20145,-55.02866,4.17585,55.02866,22604,29
173.84680,-4.72739,-67.34368,4.70179,67.34368,22604,29
174.28780,-4.49016,-59.51072,4.46456,59.51072,22540,29
174.68880,-4.08564,-48.28593,4.06004,48.28593,22540,29
175.09180,-3.68240,-37.36867,3.65679,37.36867,22540,29
175.90580,-2.86818,-20.11277,2.84258,20.11277,22540,29
177.33580,-2.16096,-11.41888,2.13536,11.41888,22540,29
178.19680,-3.02792,-27.77247,3.00232,27.77247,22476,30
178.55880,-3.39004,-36.17144,3.36444,36.17144,22476,30
178.92119,-3.75195,-44.66789,3.72635,44.66789,22476,30
179.30580,-4.13695,-53.54808,4.11135,53.54808,22476,30
179.65680,-4.48772,-61.86482,4.46212,61.86481,22476,30
179.99880,-4.82686,-69.84221,4.80126,69.84221,22476,30
180.32120,-4.50410,-59.90091,4.47850,59.90091,22412,30
180.62480,-4.19633,-51.30680,4.17073,51.30680,22412,30
180.93680,-3.88381,-42.85384,3.85821,42.85384,22412,30
181.24080,-3.57990,-34.76438,3.55430,34.76438,22412,30
181.52119,-3.29980,-28.17216,3.27420,28.17216,22412,30
182.06180,-2.75871,-18.48428,2.73310,18.48428,22412,30
183.00180,-2.16376,-11.17535,2.13816,11.17535,22412,30
183.79480,-2.96817,-26.39189,2.94257,26.39189,22476,31
184.22180,-3.39516,-36.21353,3.36956,36.21353,22476,31
184.70780,-3.88117,-47.76245,3.85557,47.76245,22476,31
185.18880,-4.36212,-58.87619,4.33652,58.87619,22476,31
185.62880,-4.80206,-69.16610,4.77646,69.16610,22476,31
185.97280,-4.49820,-59.76756,4.47260,59.76756,22412,31
186.35280,-4.11424,-49.05474,4.08864,49.05474,22412,31
186.76280,-3.70398,-38.03780,3.67838,38.03780,22412,31
187.27378,-3.19287,-25.97880,3.16727,25.97880,22412,31
188.04780,-2.41900,-13.42450,2.39339,13.42450,22412,31
188.92119,-2.45651,-16.44238,2.43091,16.44238,22476,31
189.60778,-3.14509,-30.24302,3.11948,30.24302,22476,32
190.08780,-3.62524,-41.63347,3.59964,41.63347,22476,32
190.62120,-4.15816,-53.96536,4.13256,53.96536,22476,32
191.16378,-4.70108,-66.84998,4.67548,66.84998,22476,32
191.54280,-4.58919,-62.35381,4.56358,62.35381,22476,32
191.93180,-4.19355,-51.27304,4.16795,51.27304,22412,32
192.33480,-3.79001,-40.23618,3.76441,40.23618,22412,32
192.68380,-3.44113,-31.28268,3.41553,31.28268,22412,32
193.13880,-2.98605,-22.11915,2.96045,22.11915,22412,32
194.03878,-2.08608,-8.58152,2.06048,8.58152,22412,32
194.73780,-2.61875,-19.36396,2.59315,19.36396,22476,32
195.29080,-3.17212,-30.94244,3.14651,30.94244,22476,33
195.63080,-3.51235,-39.07219,3.48675,39.07219,22476,33
195.96580,-3.84735,-46.96535,3.82175,46.96535,22476,33
196.43380,-4.31533,-57.77785,4.28973,57.77785,22476,33
196.82120,-4.70226,-66.80326,4.67666,66.80326,22476,33
197.19480,-4.58536,-62.28741,4.55976,62.28741,22476,33
197.54280,-4.23079,-52.27169,4.20519,52.27169,22412,33
197.85480,-3.91833,-43.75209,3.89273,43.75209,22412,33
198.21680,-3.55633,-34.07243,3.53073,34.07243,22412,33
198.69980,-3.07328,-23.59080,3.04768,23.59080,22412,33
199.69680,-2.07627,-8.45379,2.05067,8.45379,22412,33
200.55280,-2.77821,-22.50767,2.75261,22.50767,22476,34
201.06280,-3.28837,-33.74899,3.26277,33.74899,22476,34
201.54880,-3.77451,-45.12559,3.74891,45.12559,22476,34
201.94178,-4.16753,-54.29871,4.14192,54.29871,22476,34
202.31380,-4.53939,-63.06781,4.51379,63.06781,22476,34
202.72119,-4.71231,-66.14094,4.68671,66.14095,22476,34
203.10680,-4.31159,-54.53374,4.28599,54.53374,22412,34
203.42280,-3.99454,-45.94487,3.96894,45.94487,22412,34
203.72680,-3.69037,-37.72552,3.66477,37.72552,22412,34
204.05480,-3.36231,-29.47581,3.33671,29.47581,22412,34
204.60580,-2.81129,-19.14357,2.78569,19.14357,22412,34
205.46080,-2.01141,-7.64117,1.98581,7.64117,22412,34
206.26780,-2.84753,-23.81413,2.82193,23.81413,22476,35
206.67080,-3.25043,-32.83501,3.22483,32.83501,22476,35
207.09680,-3.67670,-42.93124,3.65110,42.93124,22476,35
207.55280,-4.13264,-53.55611,4.10704,53.55611,22476,35
208.11880,-4.69853,-66.78855,4.67293,66.78855,22476,35
208.49778,-4.56417,-61.81677,4.53857,61.81677,22476,35
208.86680,-4.18898,-51.21412,4.16338,51.21412,22412,35
209.21580,-3.83935,-41.75724,3.81375,41.75724,22412,35
209.46380,-3.59149,-35.08437,3.56589,35.08437,22412,35
209.71380,-3.34140,-28.90804,3.31580,28.90804,22412,35
210.11080,-2.94449,-21.25705,2.91889,21.25705,22412,35
210.66378,-2.39141,-12.91557,2.36581,12.91557,22412,35
211.29080,-2.23095,-12.36214,2.20535,12.36214,22412,35
211.83880,-2.78643,-22.68120,2.76083,22.68120,22476,36
212.23780,-3.18564,-31.23072,3.16004,31.23072,22476,36
212.46080,-3.40878,-36.61211,3.38318,36.61211,22476,36
212.73480,-3.68277,-43.10945,3.65717,43.10945,22476,36
212.98080,-3.92890,-48.82277,3.90330,48.82277,22476,36
213.32380,-4.27162,-56.80574,4.24602,56.80574,22476,36
213.63180,-4.57963,-63.99294,4.55403,63.99294,22476,36
214.01880,-4.69267,-65.47721,4.66707,65.47721,22476,36
214.48880,-4.20903,-51.69697,4.18343,51.69698,22412,36
214.85480,-3.84239,-41.74144,3.81679,41.74144,22412,36
215.26780,-3.42957,-30.90658,3.40397,30.90658,22412,36
215.61780,-3.07954,-23.60219,3.05394,23.60219,22412,36
216.38378,-2.31340,-11.89257,2.28780,11.89257,22412,36
217.28180,-2.58914,-18.83654,2.56354,18.83654,22476,37
217.86080,-3.16879,-30.76875,3.14318,30.76875,22476,37
218.22119,-3.52879,-39.40278,3.50319,39.40277,22476,37
218.59478,-3.90289,-48.29650,3.87729,48.29650,22476,37
218.92180,-4.22968,-55.85469,4.20408,55.85469,22476,37
219.16880,-4.47661,-61.70665,4.45101,61.70665,22476,37
219.40078,-4.70872,-66.98583,4.68312,66.98583,22476,37
219.62380,-4.72501,-66.61239,4.69941,66.61240,22476,37
219.82120,-4.51544,-60.31684,4.48984,60.31684,22476,37
220.06380,-4.26846,-53.34187,4.24286,53.34187,22412,37
220.30580,-4.02588,-46.87797,4.00028,46.87797,22412,37
220.52080,-3.81056,-40.96307,3.78496,40.96307,22412,37
220.81380,-3.51767,-33.19362,3.49207,33.19362,22412,37
221.06180,-3.26949,-27.15272,3.24389,27.15272,22412,37
221.76380,-2.56769,-15.47832,2.54209,15.47832,22412,37
222.62120,-2.30381,-13.64447,2.27821,13.64447,22412,37
223.29180,-2.97980,-26.46946,2.95420,26.46946,22604,38
223.62680,-3.31498,-34.39020,3.28938,34.39021,22604,38
223.90280,-3.59108,-40.88197,3.56548,40.88197,22604,38
224.14380,-3.83200,-46.61391,3.80640,46.61391,22604,38
224.40380,-4.09209,-52.54626,4.06649,52.54626,22604,38
224.61880,-4.30696,-57.64333,4.28136,57.64333,22604,38
224.90078,-4.58882,-64.26784,4.56322,64.26784,22604,38
225.16578,-4.80737,-69.23156,4.78177,69.23156,22604,38
225.39680,-4.55307,-61.46769,4.52746,61.46769,22604,38
225.62120,-4.32415,-54.94581,4.29854,54.94581,22540,38
225.82680,-4.11705,-49.24392,4.09145,49.24392,22540,38
226.00580,-3.93790,-44.40938,3.91230,44.40937,22540,38
226.15280,-3.79068,-40.44472,3.76508,40.44473,22540,38
226.27880,-3.66475,-37.05554,3.63915,37.05554,22540,38
226.40780,-3.53583,-33.72607,3.51023,33.72607,22540,38
226.56080,-3.38272,-29.76723,3.35712,29.76723,22540,38
226.67480,-3.26861,-27.24022,3.24301,27.24022,22540,38
226.83780,-3.10571,-24.15202,3.08011,24.15202,22540,38
226.99980,-2.94381,-21.29072,2.91821,21.29072,22540,38
227.17878,-2.76461,-18.40981,2.73901,18.40981,22540,38
227.36680,-2.57676,-15.59423,2.55116,15.59423,22540,38
227.57080,-2.37258,-12.65542,2.34698,12.65542,22540,38
227.84780,-2.09571,-8.59247,2.07010,8.59247,22540,38
228.02119,-2.08904,-9.27550,2.06344,9.27550,22540,38
228.22680,-2.30988,-13.78765,2.28427,13.78765,22604,38
228.35280,-2.43893,-16.09837,2.41333,16.09837,22604,38
228.48880,-2.57626,-18.58633,2.55066,18.58633,22604,38
228.61780,-2.70561,-20.97714,2.68001,20.97714,22604,39
228.72780,-2.81582,-23.22344,2.79022,23.22344,22604,39
228.84880,-2.93700,-25.75108,2.91140,25.75108,22604,39
228.96680,-3.05503,-28.20713,3.02943,28.20712,22604,39
229.06878,-3.15693,-30.57624,3.13133,30.57624,22604,39
229.16880,-3.25686,-33.03535,3.23126,33.03535,22604,39
229.28580,-3.37407,-35.74372,3.34847,35.74372,22604,39
229.40380,-3.49208,-38.57581,3.46648,38.57581,22604,39
229.51380,-3.60209,-41.13771,3.57649,41.13771,22604,39
229.61680,-3.70502,-43.55057,3.67942,43.55057,22604,39
229.72119,-3.80899,-45.94384,3.78339,45.94384,22604,39
229.83780,-3.92620,-48.69335,3.90060,48.69335,22604,39
229.95780,-4.04618,-51.53870,4.02058,51.53870,22604,39
230.05680,-4.14499,-53.79545,4.11939,53.79544,22604,39
230.15980,-4.24791,-56.30632,4.22231,56.30632,22604,39
230.26680,-4.35501,-58.75278,4.32941,58.75278,22604,39
230.35978,-4.44786,-60.99300,4.42225,60.99300,22604,39
230.47280,-4.56095,-63.66009,4.53535,63.66009,22604,39
230.61080,-4.69879,-66.85305,4.67319,66.85305,22604,39
230.72380,-4.81114,-69.51825,4.78554,69.51825,22604,39
230.83178,-4.72813,-66.72907,4.70253,66.72906,22604,39
230.95380,-4.59606,-62.73656,4.57046,62.73656,22604,39
231.05880,-4.48690,-59.57491,4.46130,59.57491,22540,39
231.17780,-4.36565,-56.18515,4.34005,56.18515,22540,39
231.30580,-4.23644,-52.53015,4.21084,52.53015,22540,39
231.43580,-4.10610,-48.95787,4.08050,48.95787,22540,39
231.55880,-3.98298,-45.64361,3.95737,45.64361,22540,39
231.69880,-3.84272,-41.87600,3.81712,41.87600,22540,39
231.81580,-3.72577,-38.75546,3.70017,38.75546,22540,39
231.93680,-3.60482,-35.53984,3.57922,35.53984,22540,39
232.07880,-3.46286,-31.73758,3.43726,31.73758,22540,39
232.20980,-3.33178,-28.61980,3.30618,28.61980,22540,39
232.33380,-3.20769,-26.04625,3.18209,26.04625,22540,39
232.50080,-3.04093,-22.97010,3.01533,22.97010,22540,39
232.70880,-2.83270,-19.35812,2.80710,19.35812,22540,39
232.90880,-2.63282,-16.42212,2.60722,16.42212,22540,39
233.10280,-2.43886,-13.62448,2.41326,13.62448,22540,39
233.29078,-2.25064,-10.92565,2.22504,10.92565,22540,39
233.43780,-2.10377,-8.77113,2.07817,8.77113,22540,39
233.58178,-2.00443,-7.36017,1.97883,7.36017,22540,39
233.74280,-2.01327,-7.78213,1.98767,7.78213,22540,39
233.90980,-2.02086,-8.00348,1.99526,8.00348,22540,39
234.12120,-2.23693,-12.64086,2.21133,12.64086,22540,39
234.29078,-2.41002,-15.79915,2.38442,15.79915,22476,39
234.43780,-2.55794,-18.43137,2.53234,18.43137,22476,39
234.58780,-2.70807,-21.20689,2.68247,21.20689,22476,39
234.70180,-2.82220,-23.44831,2.79660,23.44831,22476,40
234.82120,-2.94135,-25.93132,2.91575,25.93132,22476,40
234.92119,-3.04135,-28.06706,3.01575,28.06706,22476,40
235.01780,-3.13824,-30.27055,3.11264,30.27055,22476,40
235.14780,-3.26818,-33.42002,3.24258,33.42001,22476,40
235.26780,-3.38823,-36.13603,3.36263,36.13604,22476,40
235.39080,-3.51123,-39.18303,3.48563,39.18303,22476,40
235.52180,-3.64232,-42.22517,3.61672,42.22517,22476,40
235.63980,-3.76030,-44.90821,3.73470,44.90821,22476,40
235.78080,-3.90144,-48.30663,3.87584,48.30663,22476,40
235.92180,-4.04250,-51.52787,4.01690,51.52787,22476,40
236.07480,-4.19529,-55.14654,4.16969,55.14654,22476,40
236.20980,-4.33033,-58.29991,4.30473,58.29991,22476,40
236.34278,-4.46313,-61.50320,4.43752,61.50320,22476,40
236.47178,-4.59223,-64.53832,4.56663,64.53832,22476,40
236.63778,-4.75818,-68.31224,4.73257,68.31223,22476,40
236.76180,-4.76221,-67.97492,4.73661,67.97491,22476,40
236.90380,-4.60494,-63.21674,4.57934,63.21674,22476,40
237.04980,-4.45335,-58.77224,4.42775,58.77224,22412,40
237.22119,-4.28002,-53.84996,4.25442,53.84996,22412,40
237.39080,-4.10927,-49.13425,4.08367,49.13425,22412,40
237.55880,-3.94113,-44.61281,3.91553,44.61281,22412,40
237.70678,-3.79290,-40.58944,3.76730,40.58944,22412,40
237.83680,-3.66301,-37.26736,3.63741,37.26736,22412,40
237.94780,-3.55205,-34.35912,3.52645,34.35912,22412,40
238.07680,-3.42301,-30.82661,3.39741,30.82661,22412,40
238.22080,-3.27887,-27.40702,3.25327,27.40702,22412,40
238.37880,-3.12093,-24.39356,3.09533,24.39356,22412,40
238.59180,-2.90795,-20.66003,2.88235,20.66003,22412,40
238.86580,-2.63395,-16.41078,2.60835,16.41078,22412,40
239.24080,-2.25879,-11.10101,2.23319,11.10101,22412,40
239.54480,-2.04427,-8.24650,2.01867,8.24650,22412,40
239.87580,-2.39953,-15.36278,2.37393,15.36278,22476,40
240.15480,-2.68092,-20.50990,2.65531,20.50990,22476,41
240.31380,-2.84011,-23.63758,2.81451,23.63758,22476,41
240.45180,-2.97828,-26.53285,2.95268,26.53285,22476,41
240.55378,-3.08029,-28.71519,3.05469,28.71519,22476,41
240.65780,-3.18417,-31.18237,3.15856,31.18237,22476,41
240.76180,-3.28821,-33.76104,3.26261,33.76104,22476,41
240.85680,-3.38326,-35.89934,3.35766,35.89934,22476,41
240.94378,-3.47032,-38.07156,3.44472,38.07156,22476,41
241.03280,-3.55941,-40.14738,3.53381,40.14738,22476,41
241.12278,-3.64931,-42.25264,3.62370,42.25264,22476,41
241.21978,-3.74630,-44.48808,3.72070,44.48808,22476,41
241.31980,-3.84631,-46.95667,3.82071,46.95667,22476,41
241.41578,-3.94251,-49.08311,3.91691,49.08311,22476,41
241.50580,-4.03245,-51.32533,4.00685,51.32533,22476,41
241.59380,-4.12035,-53.32739,4.09475,53.32739,22476,41
241.68180,-4.20825,-55.47513,4.18265,55.47513,22476,41
241.75878,-4.28525,-57.29826,4.25965,57.29826,22476,41
241.85280,-4.37925,-59.49918,4.35365,59.49918,22476,41
241.93780,-4.46411,-61.57752,4.43851,61.57753,22476,41
242.02680,-4.55322,-63.57993,4.52761,63.57993,22476,41
242.12680,-4.65319,-65.93573,4.62759,65.93573,22476,41
242.22178,-4.74813,-68.17088,4.72253,68.17088,22476,41
242.31678,-4.78660,-68.86586,4.76100,68.86586,22476,41
242.41080,-4.67787,-65.44280,4.65227,65.44280,22476,41
242.50680,-4.57501,-62.41678,4.54940,62.41678,22476,41
242.59880,-4.47928,-59.64161,4.45368,59.64161,22412,41
242.69680,-4.37922,-56.74240,4.35362,56.74240,22412,41
242.80580,-4.26904,-53.57473,4.24344,53.57473,22412,41
242.91280,-4.16152,-50.68074,4.13592,50.68074,22412,41
243.01880,-4.05538,-47.84367,4.02978,47.84367,22412,41
243.15380,-3.92014,-44.07542,3.89454,44.07542,22412,41
243.28180,-3.79196,-40.69995,3.76636,40.69995,22412,41
243.45478,-3.61901,-36.07363,3.59341,36.07363,22412,41
243.63378,-3.44009,-31.27309,3.41449,31.27309,22412,41
243.80680,-3.26688,-27.07675,3.24128,27.07675,22412,41
244.12120,-2.95303,-21.43369,2.92743,21.43369,22412,41
244.32120,-2.75286,-18.18446,2.72726,18.18446,22412,41
244.56478,-2.50903,-14.61323,2.48343,14.61323,22412,41
244.80680,-2.26687,-11.12572,2.24127,11.12572,22412,41
244.98478,-2.08904,-8.50810,2.06344,8.50810,22412,41
245.12278,-2.07136,-8.88677,2.04576,8.88677,22412,41
245.29980,-2.26516,-12.82664,2.23955,12.82664,22412,41
245.48780,-2.45842,-16.48820,2.43282,16.48820,22476,41
245.68080,-2.65284,-19.95640,2.62724,19.95640,22476,42
245.87880,-2.85115,-23.85847,2.82555,23.85847,22476,42
246.07580,-3.04823,-28.06999,3.02263,28.06999,22476,42
246.21180,-3.18429,-31.10959,3.15869,31.10959,22476,42
246.35180,-3.32425,-34.51107,3.29865,34.51107,22476,42
246.49578,-3.46847,-38.00295,3.44287,38.00295,22476,42
246.64780,-3.62042,-41.47479,3.59482,41.47479,22476,42
246.80780,-3.78030,-45.34752,3.75470,45.34752,22476,42
246.96880,-3.94161,-49.05682,3.91601,49.05682,22476,42
247.11280,-4.08550,-52.45607,4.05990,52.45607,22476,42
247.28878,-4.26126,-56.66488,4.23566,56.66488,22476,42
247.43380,-4.40627,-60.10721,4.38067,60.10721,22476,42
247.62580,-4.59826,-64.73093,4.57266,64.73093,22476,42
247.82380,-4.79620,-69.29918,4.77060,69.29919,22476,42
248.01880,-4.65682,-64.73374,4.63122,64.73373,22476,42
248.22780,-4.43895,-58.33896,4.41335,58.33896,22412,42
248.40380,-4.26079,-53.28827,4.23519,53.28827,22412,42
248.54880,-4.11529,-49.39451,4.08969,49.39451,22412,42
248.71978,-3.94417,-44.76268,3.91857,44.76268,22412,42
248.86980,-3.79394,-40.76907,3.76834,40.76907,22412,42
249.07880,-3.58504,-35.11970,3.55944,35.11971,22412,42
249.26380,-3.40003,-30.28812,3.37443,30.28811,22412,42
249.55080,-3.11298,-24.21781,3.08737,24.21781,22412,42
249.85380,-2.80994,-18.96375,2.78434,18.96375,22412,42
250.11680,-2.54710,-15.09150,2.52150,15.09150,22412,42
250.34380,-2.31990,-11.89805,2.29429,11.89805,22412,42
250.55378,-2.10995,-8.77785,2.08435,8.77785,22412,42
250.68780,-2.02510,-7.68230,1.99950,7.68230,22412,42
250.89380,-2.25291,-12.58224,2.22731,12.58224,22412,42
251.09278,-2.45753,-16.42282,2.43193,16.42282,22476,42
251.26780,-2.63370,-19.60364,2.60810,19.60364,22476,43
251.50280,-2.86911,-24.21713,2.84351,24.21713,22476,43
251.66378,-3.03034,-27.62853,3.00474,27.62853,22476,43
251.77880,-3.14512,-30.24903,3.11952,30.24903,22476,43
251.89878,-3.26510,-33.12957,3.23949,33.12957,22476,43
252.01180,-3.37826,-35.76224,3.35266,35.76224,22476,43
252.13080,-3.49732,-38.65604,3.47172,38.65604,22476,43
252.25380,-3.62039,-41.45398,3.59479,41.45398,22476,43
252.39480,-3.76136,-44.84713,3.73576,44.84713,22476,43
252.53380,-3.90044,-48.16124,3.87484,48.16124,22476,43
252.64680,-4.01346,-50.80834,3.98786,50.80834,22476,43
252.76180,-4.12831,-53.49804,4.10271,53.49804,22476,43
252.89380,-4.26022,-56.64254,4.23461,56.64254,22476,43
253.02180,-4.38824,-59.69792,4.36264,59.69792,22476,43
253.12380,-4.49015,-62.24374,4.46455,62.24374,22476,43
253.21880,-4.58523,-64.48781,4.55963,64.48782,22476,43
253.31878,-4.68520,-66.80977,4.65960,66.80978,22476,43
253.40880,-4.77517,-68.93322,4.74957,68.93322,22476,43
253.50580,-4.75458,-67.93801,4.72898,67.93801,22476,43
253.61180,-4.63562,-64.26457,4.61002,64.26457,22476,43
253.72380,-4.51760,-60.85930,4.49200,60.85929,22412,43
253.82680,-4.41190,-57.70520,4.38629,57.70520,22412,43
253.92380,-4.31358,-55.05748,4.28798,55.05748,22412,43
254.05480,-4.18169,-51.30906,4.15609,51.30906,22412,43
254.18580,-4.05047,-47.84059,4.02487,47.84059,22412,43
254.30880,-3.92727,-44.44132,3.90167,44.44131,22412,43
254.45380,-3.78203,-40.57357,3.75643,40.57357,22412,43
254.61180,-3.62413,-36.30457,3.59853,36.30457,22412,43
254.78678,-3.44918,-31.69932,3.42358,31.69932,22412,43
254.94378,-3.29206,-27.72876,3.26646,27.72876,22412,43
255.25280,-2.98310,-21.88993,2.95750,21.88993,22412,43
255.53580,-2.70003,-17.25831,2.67443,17.25831,22412,43
255.99480,-2.24094,-10.71152,2.21534,10.71152,22412,43
256.36380,-2.15247,-10.58741,2.12687,10.58741,22412,43
256.75778,-2.55949,-18.35822,2.53389,18.35822,22476,43
257.13678,-2.93939,-25.79261,2.91379,25.79261,22476,44
257.33780,-3.14017,-30.16572,3.11457,30.16572,22476,44
257.56680,-3.36939,-35.46702,3.34379,35.46702,22476,44
257.77680,-3.57949,-40.42239,3.55389,40.42239,22476,44
257.97080,-3.77341,-45.07473,3.74781,45.07473,22476,44
258.12280,-3.92562,-48.74757,3.90002,48.74757,22476,44
258.28778,-4.09053,-52.63367,4.06493,52.63367,22476,44
258.43180,-4.23427,-56.11879,4.20867,56.11879,22476,44
258.56980,-4.37234,-59.45096,4.34674,59.45096,22476,44
258.69681,-4.49921,-62.48187,4.47361,62.48187,22476,44
258.82380,-4.62626,-65.47391,4.60066,65.47391,22476,44
258.95678,-4.75921,-68.53433,4.73361,68.53433,22476,44
259.05978,-4.74691,-67.84254,4.72131,67.84254,22476,44
259.17578,-4.61706,-63.90867,4.59146,63.90866,22476,44
259.27780,-4.50973,-60.71102,4.48413,60.71101,22412,44
259.39280,-4.39180,-57.17812,4.36620,57.17812,22412,44
259.50180,-4.28146,-54.09465,4.25586,54.09465,22412,44
259.61078,-4.17182,-51.10646,4.14622,51.10646,22412,44
259.71381,-4.06860,-48.36370,4.04300,48.36370,22412,44
259.83178,-3.95042,-45.09348,3.92482,45.09348,22412,44
259.95178,-3.83017,-41.91846,3.80457,41.91846,22412,44
260.06580,-3.71623,-38.97434,3.69063,38.97434,22412,44
260.18280,-3.59925,-35.72265,3.57365,35.72265,22412,44
260.30780,-3.47428,-32.45590,3.44868,32.45589,22412,44
260.46680,-3.31521,-28.32586,3.28961,28.32586,22412,44
260.76080,-3.02126,-22.57541,2.99566,22.57541,22412,44
261.11978,-2.66229,-16.73601,2.63669,16.73601,22412,44
261.69180,-2.09026,-8.44162,2.06466,8.44162,22412,44
262.27178,-2.50733,-17.32328,2.48173,17.32328,22476,44
262.76481,-3.00153,-26.95875,2.97593,26.95875,22476,45
262.97778,-3.21432,-31.83731,3.18871,31.83731,22476,45
263.19078,-3.42768,-36.97500,3.40208,36.97500,22476,45
263.42481,-3.66163,-42.53171,3.63603,42.53172,22476,45
263.62281,-3.85964,-47.31480,3.83404,47.31480,22476,45
263.84478,-4.08175,-52.50165,4.05615,52.50165,22476,45
264.06578,-4.30260,-57.74047,4.27700,57.74047,22476,45
264.23378,-4.47040,-61.88836,4.44480,61.88836,22476,45
264.41478,-4.65149,-66.19366,4.62588,66.19366,22476,45
264.59078,-4.80047,-69.69500,4.77487,69.69499,22476,45
264.83278,-4.53762,-61.53858,4.51202,61.53858,22476,45
265.15378,-4.21091,-52.25363,4.18531,52.25363,22412,45
265.37878,-3.98547,-46.20951,3.95987,46.20951,22412,45
265.58178,-3.78221,-40.67536,3.75661,40.67537,22412,45
265.82581,-3.53837,-34.28889,3.51277,34.28889,22412,45
266.02381,-3.34026,-29.12956,3.31466,29.12955,22412,45
266.47378,-2.89021,-20.22844,2.86461,20.22844,22412,45
266.98678,-2.37717,-12.59753,2.35157,12.59753,22412,45
267.47581,-2.13102,-10.19195,2.10542,10.19195,22412,45
268.07678,-2.74721,-21.84961,2.72161,21.84961,22476,46
268.55578,-3.22635,-32.19897,3.20075,32.19897,22476,46
268.90178,-3.57276,-40.29625,3.54716,40.29625,22476,46
269.15781,-3.82867,-46.53218,3.80307,46.53218,22476,46
269.45378,-4.12457,-53.42166,4.09897,53.42166,22476,46
269.80078,-4.47143,-61.82870,4.44583,61.82870,22476,46
270.08978,-4.76046,-68.68570,4.73486,68.68570,22476,46
270.27678,-4.66939,-65.43733,4.64379,65.43733,22476,46
270.46978,-4.46625,-59.41189,4.44065,59.41189,22412,46
270.73278,-4.19995,-51.94378,4.17435,51.94378,22412,46
270.96878,-3.96354,-45.43671,3.93794,45.43671,22412,46
271.21878,-3.71335,-38.87750,3.68775,38.87750,22412,46
271.48081,-3.45142,-31.89609,3.42582,31.89609,22412,46
271.78778,-3.14433,-24.72940,3.11873,24.72940,22412,46
272.37681,-2.55544,-15.15289,2.52983,15.15289,22412,46
273.09578,-2.18752,-11.33453,2.16192,11.33453,22412,46
273.86481,-2.96766,-26.26347,2.94206,26.26347,22476,47
274.32181,-3.42471,-36.75663,3.39911,36.75663,22476,47
274.67978,-3.78266,-45.30191,3.75706,45.30191,22476,47
274.94981,-4.05286,-51.74201,4.02726,51.74201,22476,47
275.20578,-4.30866,-57.87513,4.28306,57.87513,22476,47
275.47878,-4.58157,-64.35161,4.55597,64.35161,22476,47
275.85481,-4.67723,-65.50889,4.65163,65.50889,22476,47
276.15478,-4.36514,-56.42064,4.33954,56.42064,22412,47
276.40178,-4.11661,-49.53536,4.09101,49.53535,22412,47
276.72981,-3.78821,-40.75285,3.76260,40.75285,22412,47
277.01081,-3.50728,-33.42094,3.48168,33.42094,22412,47
277.35278,-3.16524,-25.16080,3.13964,25.16080,22412,47
278.11078,-2.40728,-12.99103,2.38168,12.99103,22412,47
278.93681,-2.43155,-15.95696,2.40595,15.95696,22604,47
279.58781,-3.08448,-28.71381,3.05888,28.71382,22604,48
279.97278,-3.46963,-37.84074,3.44403,37.84074,22604,48
280.34681,-3.84368,-46.84606,3.81808,46.84606,22604,48
280.73378,-4.23049,-55.94319,4.20489,55.94319,22604,48
281.14178,-4.63847,-65.72471,4.61287,65.72471,22604,48
281.60378,-4.52174,-60.91915,4.49614,60.91915,22604,48
282.01081,-4.10967,-49.37715,4.08407,49.37716,22540,48
282.35981,-3.76025,-39.97043,3.73465,39.97043,22540,48
282.66981,-3.45040,-31.90647,3.42480,31.90648,22540,48
283.25878,-2.86121,-19.67887,2.83561,19.67887,22540,48
283.98278,-2.13733,-9.07320,2.11173,9.07320,22540,48
284.44078,-2.34772,-14.45220,2.32212,14.45220,22604,48
284.81378,-2.72427,-21.41994,2.69867,21.41994,22604,49
285.08881,-2.99967,-26.93084,2.97407,26.93084,22604,49
285.27478,-3.18562,-31.19129,3.16002,31.19129,22604,49
285.49178,-3.40269,-36.28580,3.37709,36.28580,22604,49
285.73178,-3.64275,-41.94340,3.61715,41.94340,22604,49
285.99978,-3.91087,-48.38056,3.88527,48.38057,22604,49
286.20881,-4.11977,-53.28418,4.09417,53.28418,22604,49
286.41478,-4.32575,-58.30156,4.30015,58.30156,22604,49
286.66581,-4.57658,-64.29265,4.55098,64.29265,22604,49
286.88581,-4.79505,-69.51984,4.76945,69.51984,22604,49
287.06681,-4.62673,-64.16398,4.60113,64.16398,22604,49
287.22078,-4.46551,-59.43630,4.43991,59.43630,22540,49
287.35678,-4.32716,-55.45533,4.30156,55.45533,22540,49
287.59181,-4.09086,-48.95966,4.06526,48.95966,22540,49
287.83578,-3.84644,-42.43524,3.82084,42.43524,22540,49
288.14881,-3.53363,-34.19559,3.50803,34.19559,22540,49
288.44681,-3.23536,-26.54192,3.20976,26.54192,22540,49
288.83881,-2.84340,-19.47956,2.81780,19.47956,22540,49
289.55381,-2.12848,-8.95121,2.10288,8.95121,22540,49
290.02119,-2.02165,-7.87769,1.99605,7.87769,22540,49
290.58578,-2.59149,-19.03052,2.56589,19.03052,22476,49
291.03581,-3.04176,-27.92322,3.01616,27.92322,22476,50
291.31281,-3.31879,-34.41874,3.29319,34.41874,22476,50
291.64778,-3.65385,-42.28054,3.62825,42.28054,22476,50
291.87281,-3.87879,-47.69397,3.85319,47.69397,22476,50
292.13378,-4.13980,-53.85624,4.11420,53.85624,22476,50
292.39978,-4.40570,-60.29983,4.38010,60.29983,22476,50
292.75478,-4.76069,-68.79508,4.73509,68.79507,22476,50
293.08381,-4.51507,-60.92795,4.48946,60.92795,22476,50
293.41678,-4.17719,-51.41394,4.15158,51.41394,22412,50
293.75281,-3.84051,-42.28975,3.81491,42.28975,22412,50
294.11381,-3.47961,-32.83695,3.45401,32.83695,22412,50
294.53978,-3.05371,-23.05119,3.02811,23.05119,22412,50
295.12119,-2.47264,-13.91125,2.44704,13.91125,22412,50
295.83178,-2.26695,-12.84058,2.24135,12.84058,22412,50
296.35378,-2.79558,-22.82046,2.76998,22.82046,22476,51
296.61578,-3.05774,-28.27387,3.03214,28.27387,22476,51
296.85581,-3.29782,-33.89608,3.27222,33.89608,22476,51
297.06681,-3.50887,-38.92595,3.48327,38.92595,22476,51
297.25581,-3.69793,-43.34138,3.67233,43.34138,22476,51
297.46381,-3.90599,-48.35480,3.88039,48.35480,22476,51
297.66378,-4.10594,-52.98438,4.08034,52.98438,22476,51
297.84478,-4.28676,-57.39436,4.26116,57.39436,22476,51
298.00978,-4.45168,-61.35699,4.42608,61.35699,22476,51
298.21381,-4.65577,-66.18114,4.63017,66.18114,22476,51
298.41778,-4.75324,-68.06556,4.72763,68.06556,22476,51
298.61278,-4.53933,-61.66643,4.51372,61.66643,22476,51
298.81878,-4.32834,-55.56277,4.30274,55.56277,22412,51
299.02119,-4.12505,-49.97426,4.09945,49.97425,22412,51
299.23578,-3.90976,-44.16211,3.88416,44.16211,22412,51
299.40478,-3.74058,-39.65791,3.71498,39.65791,22412,51
299.58781,-3.55774,-34.89106,3.53214,34.89106,22412,51
299.77978,-3.36561,-29.81983,3.34001,29.81984,22412,51
300.05278,-3.09266,-23.71084,3.06706,23.71084,22412,51
300.45578,-2.68961,-17.12925,2.66401,17.12925,22412,51
301.04778,-2.09765,-8.49697,2.07205,8.49697,22412,51
301.75181,-2.63535,-19.59482,2.60975,19.59482,22476,51
302.21781,-3.10176,-29.24901,3.07616,29.24901,22476,52
302.43078,-3.31487,-34.13728,3.28927,34.13728,22476,52
302.64778,-3.53195,-39.30157,3.50635,39.30157,22476,52
302.83478,-3.71904,-43.69931,3.69344,43.69931,22476,52
303.05078,-3.93518,-48.91386,3.90958,48.91386,22476,52
303.25378,-4.13793,-53.84263,4.11233,53.84263,22476,52
303.49781,-4.38188,-59.63491,4.35628,59.63491,22476,52
303.62078,-4.50482,-62.72081,4.47922,62.72081,22476,52
303.79178,-4.67578,-66.69758,4.65018,66.69758,22476,52
304.00181,-4.73278,-67.42043,4.70718,67.42043,22476,52
304.18178,-4.53807,-61.61673,4.51247,61.61673,22476,52
304.45178,-4.26258,-53.70731,4.23698,53.70731,22412,52
304.68578,-4.02794,-47.44020,4.00234,47.44020,22412,52
304.91478,-3.79862,-41.13818,3.77302,41.13818,22412,52
305.11178,-3.60165,-36.00516,3.57604,36.00516,22412,52
305.33578,-3.37762,-30.12815,3.35202,30.12815,22412,52
305.60878,-3.10464,-23.86981,3.07904,23.86981,22412,52
305.87978,-2.83354,-19.36394,2.80794,19.36394,22412,52
306.23778,-2.47568,-13.96122,2.45008,13.96122,22412,52
306.75581,-2.06908,-8.61799,2.04348,8.61799,22412,52
307.26578,-2.60319,-18.96290,2.57759,18.96290,22476,53
307.72581,-3.06389,-28.23966,3.03829,28.23966,22476,53
308.01378,-3.35192,-34.94303,3.32632,34.94303,22476,53
308.27381,-3.61203,-41.15562,3.58643,41.15562,22476,53
308.54881,-3.88699,-47.91014,3.86139,47.91014,22476,53
308.78878,-4.12691,-53.47985,4.10131,53.47985,22476,53
309.02178,-4.35987,-59.18393,4.33427,59.18393,22476,53
309.35981,-4.69778,-67.27313,4.67218,67.27312,22476,53
309.62878,-4.65117,-64.94191,4.62556,64.94190,22476,53
309.89381,-4.37578,-56.89575,4.35018,56.89575,22412,53
310.21281,-4.05501,-48.09136,4.02941,48.09136,22412,53
310.54081,-3.72661,-39.31011,3.70101,39.31010,22412,53
310.81778,-3.44973,-31.96792,3.42413,31.96792,22412,53
311.09578,-3.17162,-25.23468,3.14601,25.23468,22412,53
311.52119,-2.74650,-17.97980,2.72090,17.97980,22412,53
312.08381,-2.18371,-9.78600,2.15810,9.78600,22412,53
312.53581,-2.28411,-13.20486,2.25851,13.20486,22476,53
312.75778,-2.51079,-17.34134,2.48519,17.34134,22476,53
312.97981,-2.73362,-21.53061,2.70802,21.53061,22476,54
313.17278,-2.92700,-25.39547,2.90140,25.39547,22476,54
313.33781,-3.09200,-28.94538,3.06640,28.94538,22476,54
313.47681,-3.23081,-32.18032,3.20521,32.18032,22476,54
313.66181,-3.41600,-36.58329,3.39040,36.58329,22476,54
313.90578,-3.66006,-42.39228,3.63446,42.39228,22476,54
314.12178,-3.87608,-47.71960,3.85048,47.71960,22476,54
314.40878,-4.16302,-54.52468,4.13742,54.52468,22476,54
314.70578,-4.45986,-61.67198,4.43426,61.67197,22476,54
314.92778,-4.68192,-66.96900,4.65632,66.96900,22476,54
315.08978,-4.77910,-69.06897,4.75350,69.06897,22476,54
315.25278,-4.59609,-63.38155,4.57049,63.38155,22476,54
315.42678,-4.41575,-58.03540,4.39015,58.03540,22412,54
315.57778,-4.26281,-53.81820,4.23721,53.81820,22412,54
315.74678,-4.09318,-49.11193,4.06758,49.11193,22412,54
315.89178,-3.94804,-45.19799,3.92244,45.19799,22412,54
316.03378,-3.80578,-41.47110,3.78018,41.47110,22412,54
316.16778,-3.67187,-37.97626,3.64627,37.97626,22412,54
316.28878,-3.55093,-34.77363,3.52533,34.77363,22412,54
316.48881,-3.35078,-29.52368,3.32518,29.52368,22412,54
316.74078,-3.09882,-23.74486,3.07322,23.74486,22412,54
317.05078,-2.78876,-18.65023,2.76316,18.65023,22412,54
317.39078,-2.44889,-13.53608,2.42329,13.53608,22412,54
317.79581,-2.04402,-7.72778,2.01842,7.72778,22412,54
318.09378,-2.29423,-13.30613,2.26863,13.30613,22412,54
318.40178,-2.60748,-19.05795,2.58188,19.05795,22476,54
318.61678,-2.82302,-23.30412,2.79742,23.30412,22476,55
318.81978,-3.02622,-27.37584,3.00061,27.37584,22476,55
318.95678,-3.16307,-30.55740,3.13747,30.55740,22476,55
319.08678,-3.29306,-33.66095,3.26746,33.66095,22476,55
319.19981,-3.40624,-36.27627,3.38064,36.27626,22476,55
319.32278,-3.52919,-39.31081,3.50359,39.31081,22476,55
319.46281,-3.66926,-42.66868,3.64366,42.66868,22476,55
319.61078,-3.81720,-46.23821,3.79160,46.23821,22476,55
319.78378,-3.99036,-50.34394,3.96476,50.34394,22476,55
319.96578,-4.17219,-54.74501,4.14659,54.74501,22476,55
320.12978,-4.33624,-58.64530,4.31064,58.64530,22476,55
320.32981,-4.53608,-63.41859,4.51048,63.41859,22476,55
320.54178,-4.74802,-68.52557,4.72242,68.52557,22476,55
320.79481,-4.60877,-63.71603,4.58317,63.71603,22476,55
321.01881,-4.37716,-56.94295,4.35156,56.94295,22412,55
321.27478,-4.11932,-49.79499,4.09372,49.79499,22412,55
321.50078,-3.89301,-43.70309,3.86741,43.70309,22412,55
321.77978,-3.61398,-36.32878,3.58837,36.32878,22412,55
322.10378,-3.28991,-27.89334,3.26431,27.89334,22412,55
322.72878,-2.66501,-16.68381,2.63941,16.68381,22412,55
323.54678,-2.18365,-11.15498,2.15805,11.15498,22412,55
324.20378,-2.85213,-23.88513,2.82652,23.88513,22476,56
324.61781,-3.26614,-33.01615,3.24054,33.01615,22476,56
324.90978,-3.55837,-39.90053,3.53277,39.90054,22476,56
325.24078,-3.88938,-47.96888,3.86378,47.96888,22476,56
325.59778,-4.24621,-56.46885,4.22061,56.46885,22476,56
325.92678,-4.57525,-64.38035,4.54965,64.38035,22476,56
326.16678,-4.80062,-69.75082,4.77502,69.75082,22476,56
326.43681,-4.51457,-60.96108,4.48896,60.96108,22412,56
326.66378,-4.28322,-54.34278,4.25762,54.34278,22412,56
326.88478,-4.06139,-48.28847,4.03579,48.28847,22412,56
327.14381,-3.80199,-41.26085,3.77639,41.26085,22412,56
327.35878,-3.58708,-35.60887,3.56148,35.60887,22412,56
327.57778,-3.36799,-29.99024,3.34239,29.99024,22412,56
327.85181,-3.09405,-23.61056,3.06845,23.61056,22412,56
328.12178,-2.82399,-19.08482,2.79839,19.08482,22412,56
328.59778,-2.34786,-12.10715,2.32226,12.10715,22412,56
329.03281,-2.09657,-9.33474,2.07097,9.33474,22412,56
329.46478,-2.54633,-18.01196,2.52073,18.01196,22476,56
329.80278,-2.88512,-24.54075,2.85952,24.54075,22476,57
330.02978,-3.11211,-29.42357,3.08651,29.42357,22476,57
330.17978,-3.26222,-32.94202,3.23662,32.94202,22476,57
330.29881,-3.38133,-35.77067,3.35573,35.77067,22476,57
330.44981,-3.53229,-39.40618,3.50669,39.40619,22476,57
330.64178,-3.72432,-43.99901,3.69872,43.99901,22476,57
330.80278,-3.88539,-48.03732,3.85979,48.03732,22476,57
330.97681,-4.05951,-52.10711,4.03391,52.10711,22476,57
331.19181,-4.27425,-57.22853,4.24865,57.22853,22476,57
331.49878,-4.58128,-64.62017,4.55568,64.62017,22476,57
331.72681,-4.79788,-69.72414,4.77228,69.72414,22476,57
332.01481,-4.49593,-60.40246,4.47033,60.40246,22412,57
332.23978,-4.26701,-53.88483,4.24141,53.88483,22412,57
332.52781,-3.97814,-46.07860,3.95254,46.07860,22412,57
332.82581,-3.68003,-38.15582,3.65443,38.15582,22412,57
333.06281,-3.44305,-31.89600,3.41745,31.89600,22412,57
333.33478,-3.17093,-25.31273,3.14533,25.31273,22412,57
333.79881,-2.70691,-17.30999,2.68131,17.30999,22412,57
334.48778,-2.02048,-7.30887,1.99487,7.30887,22412,57
334.97681,-2.50997,-17.29289,2.48437,17.29289,22604,57
335.46681,-3.00112,-26.88006,2.97552,26.88007,22604,58
335.72119,-3.25513,-32.81916,3.22953,32.81916,22604,58
335.92578,-3.46033,-37.70592,3.43473,37.70592,22604,58
336.12119,-3.65535,-42.40585,3.62975,42.40585,22604,58
336.32981,-3.86432,-47.59285,3.83872,47.59285,22604,58
336.53378,-4.06847,-52.36943,4.04287,52.36943,22604,58
336.74381,-4.27823,-57.36504,4.25263,57.36504,22604,58
336.91081,-4.44512,-61.42729,4.41952,61.42729,22604,58
337.06181,-4.59618,-65.00082,4.57057,65.00082,22604,58
337.24978,-4.78328,-69.51042,4.75768,69.51042,22604,58
337.43281,-4.61828,-64.20612,4.59268,64.20612,22604,58
337.67381,-4.36827,-56.84342,4.34267,56.84342,22540,58
337.84478,-4.19569,-51.99779,4.17009,51.99779,22540,58
338.04578,-3.99425,-46.63410,3.96865,46.63410,22540,58
338.24381,-3.79599,-41.23093,3.77039,41.23093,22540,58
338.43178,-3.60804,-36.29907,3.58244,36.29907,22540,58
338.70778,-3.33200,-29.16299,3.30640,29.16299,22540,58
339.08978,-2.95006,-21.15119,2.92446,21.15119,22540,58
339.69478,-2.34486,-12.05555,2.31926,12.05555,22540,58
340.38378,-2.38304,-14.98575,2.35744,14.98575,22604,58
340.91778,-2.92028,-25.32326,2.89468,25.32326,22604,59
341.12119,-3.12320,-29.69165,3.09760,29.69165,22604,59
341.30478,-3.30729,-34.10856,3.28169,34.10856,22604,59
341.47778,-3.48042,-38.25571,3.45482,38.25571,22604,59
341.63378,-3.63645,-41.89829,3.61085,41.89829,22604,59
341.81681,-3.81940,-46.37003,3.79380,46.37003,22604,59
342.00378,-4.00654,-50.80276,3.98094,50.80276,22604,59
342.19478,-4.19733,-55.38045,4.17173,55.38045,22604,59
342.35378,-4.35631,-59.20417,4.33071,59.20417,22604,59
342.50181,-4.50419,-62.87219,4.47859,62.87219,22604,59
342.66981,-4.67212,-66.87152,4.64652,66.87151,22604,59
342.79981,-4.78763,-69.53308,4.76203,69.53308,22604,59
342.94378,-4.63475,-64.79331,4.60915,64.79331,22604,59
343.06578,-4.50569,-60.91955,4.48009,60.91955,22540,59
343.18078,-4.38768,-57.45573,4.36208,57.45573,22540,59
343.33781,-4.22882,-52.93728,4.20322,52.93728,22540,59
343.45081,-4.11541,-49.96458,4.08980,49.96458,22540,59
343.57278,-3.99327,-46.69677,3.96767,46.69677,22540,59
343.68078,-3.88505,-43.71447,3.85945,43.71447,22540,59
343.78378,-3.78200,-40.88703,3.75640,40.88703,22540,59
343.90281,-3.66308,-37.89540,3.63748,37.89540,22540,59
344.00478,-3.56114,-35.19653,3.53554,35.19653,22540,59
344.10778,-3.45809,-32.49674,3.43249,32.49673,22540,59
344.20678,-3.35901,-29.97237,3.33340,29.97237,22540,59
344.30878,-3.25690,-27.34555,3.23129,27.34555,22540,59
344.44981,-3.11604,-24.24302,3.09044,24.24302,22540,59
344.64881,-2.91705,-20.59930,2.89145,20.59930,22540,59
344.92178,-2.64409,-16.32925,2.61849,16.32925,22540,59
345.31978,-2.24584,-10.63808,2.22024,10.63808,22540,59
345.55578,-2.02133,-7.26322,1.99573,7.26322,22540,59
345.56181,-2.02004,-7.25888,1.99444,7.25888,22540,59