File: data-raw/Experiment 2/Results/INSTRON data/Experiment 2.is_ccyclic_RawData/Specimen_RawData_23.csv
Text Inputs : Specimen label,"Long Plate 1 T6"

Time,Extension,Load,Compressive extension,Compressive load,Segment ID,Total Cycle Count
(sec),(mm),(N),(mm),(N),,
0.00000,-0.02552,-0.00599,0.00000,0.00599,12835,0
0.40000,-0.02552,-0.02324,0.00000,0.02324,12835,0
1.04180,-0.02555,-0.04451,0.00003,0.04451,3220,0
1.41380,-0.20686,-0.01971,0.18134,0.01971,3220,0
1.78380,-0.39255,-0.03788,0.36703,0.03788,3220,0
2.24820,-0.62464,-3.11517,0.59912,3.11517,3220,0
2.72580,-0.89768,-8.24258,0.87216,8.24258,3220,0
3.23180,-1.40878,-16.88450,1.38326,16.88450,22476,0
3.68980,-1.86696,-25.26809,1.84144,25.26809,22476,0
4.08580,-2.26306,-34.12157,2.23754,34.12157,22476,0
4.41680,-2.59412,-41.71145,2.56860,41.71144,22476,0
4.73980,-2.91697,-49.07721,2.89144,49.07721,22476,0
5.05280,-3.22990,-56.23236,3.20438,56.23236,22476,0
5.42380,-3.60110,-64.63622,3.57558,64.63622,22476,0
5.69780,-3.82375,-69.45162,3.79823,69.45162,22476,0
5.95780,-3.53973,-60.57869,3.51421,60.57869,22412,0
6.15880,-3.33501,-54.63577,3.30948,54.63577,22412,0
6.45380,-3.03898,-46.49904,3.01346,46.49904,22412,0
6.76680,-2.72572,-38.58773,2.70020,38.58773,22412,0
6.96380,-2.52866,-33.72948,2.50314,33.72948,22412,0
7.24820,-2.24470,-26.89394,2.21918,26.89394,22412,0
7.66980,-1.82261,-18.90589,1.79709,18.90589,22412,0
8.20580,-1.28648,-10.43275,1.26096,10.43275,22412,0
8.61080,-1.28862,-11.74435,1.26310,11.74435,22412,0
9.06780,-1.75448,-20.19350,1.72895,20.19350,22476,1
9.48180,-2.16886,-29.08369,2.14334,29.08369,22476,1
9.85280,-2.53992,-38.04816,2.51440,38.04816,22476,1
10.17180,-2.85888,-45.67205,2.83336,45.67205,22476,1
10.54820,-3.23483,-54.72697,3.20931,54.72697,22476,1
10.89580,-3.58308,-63.15590,3.55756,63.15590,22476,1
11.23080,-3.83962,-68.95988,3.81410,68.95988,22476,1
11.49280,-3.55438,-60.16877,3.52886,60.16877,22412,1
11.81880,-3.22429,-50.70965,3.19877,50.70964,22412,1
12.17280,-2.86973,-41.44823,2.84421,41.44823,22412,1
12.54780,-2.49476,-32.20061,2.46924,32.20061,22412,1
12.86780,-2.17478,-25.00501,2.14926,25.00501,22412,1
13.34820,-1.69488,-16.34751,1.66936,16.34751,22412,1
13.84820,-1.19478,-8.55363,1.16926,8.55363,22412,1
14.24820,-1.42652,-13.75214,1.40100,13.75214,22476,1
14.68980,-1.87276,-22.23375,1.84724,22.23375,22476,2
15.09680,-2.27997,-31.19317,2.25445,31.19317,22476,2
15.44580,-2.62910,-39.65758,2.60358,39.65758,22476,2
15.70380,-2.88695,-45.87317,2.86143,45.87317,22476,2
16.02780,-3.21089,-53.60971,3.18537,53.60971,22476,2
16.39880,-3.58216,-62.65894,3.55664,62.65894,22476,2
16.75580,-3.84753,-68.71191,3.82201,68.71191,22476,2
17.04820,-3.53250,-59.02809,3.50698,59.02809,22412,2
17.34820,-3.22933,-50.37399,3.20381,50.37399,22412,2
17.60780,-2.96909,-43.58495,2.94357,43.58495,22412,2
17.94820,-2.62891,-35.12816,2.60339,35.12816,22412,2
18.16780,-2.40879,-29.80256,2.38327,29.80256,22412,2
18.56980,-2.00691,-21.42969,1.98139,21.42969,22412,2
19.10180,-1.47491,-12.70511,1.44939,12.70511,22412,2
19.54820,-1.19735,-9.07444,1.17183,9.07444,22412,2
19.98880,-1.65707,-17.78606,1.63155,17.78606,22476,2
20.43080,-2.10013,-26.69249,2.07460,26.69249,22476,3
20.80980,-2.47908,-35.69125,2.45356,35.69125,22476,3
21.18180,-2.85101,-44.66687,2.82549,44.66687,22476,3
21.48680,-3.15604,-52.03100,3.13052,52.03100,22476,3
21.85880,-3.52815,-61.03673,3.50263,61.03673,22476,3
22.22180,-3.89023,-69.83839,3.86471,69.83839,22476,3
22.50780,-3.61660,-61.25581,3.59108,61.25581,22412,3
22.77680,-3.34283,-53.21277,3.31731,53.21276,22412,3
23.12180,-2.99709,-44.06322,2.97156,44.06322,22412,3
23.42180,-2.69691,-36.54126,2.67139,36.54126,22412,3
23.75580,-2.36285,-28.44088,2.33733,28.44088,22412,3
24.20480,-1.91374,-19.52976,1.88822,19.52976,22412,3
24.74820,-1.37075,-10.98531,1.34523,10.98532,22412,3
25.14820,-1.29290,-10.84285,1.26738,10.84285,22412,3
25.62180,-1.77843,-19.79800,1.75291,19.79800,22476,4
26.04080,-2.19794,-28.67852,2.17242,28.67852,22476,4
26.34780,-2.50504,-36.06600,2.47952,36.06600,22476,4
26.64820,-2.80498,-43.38497,2.77946,43.38497,22476,4
27.03680,-3.19393,-52.72534,3.16841,52.72535,22476,4
27.36080,-3.51810,-60.61083,3.49258,60.61083,22476,4
27.70980,-3.86701,-69.09207,3.84149,69.09206,22476,4
27.95080,-3.70324,-63.64058,3.67772,63.64058,22476,4
28.26380,-3.38197,-54.14785,3.35645,54.14785,22412,4
28.62280,-3.02208,-44.46299,2.99656,44.46299,22412,4
28.98280,-2.66186,-35.44556,2.63634,35.44556,22412,4
29.29180,-2.35288,-28.08167,2.32736,28.08167,22412,4
29.74820,-1.89669,-19.10987,1.87117,19.10987,22412,4
30.28480,-1.35975,-10.74195,1.33423,10.74195,22412,4
30.73380,-1.36917,-12.17400,1.34365,12.17400,22412,4
31.11780,-1.76030,-19.30861,1.73478,19.30861,22476,4
31.53780,-2.18091,-28.12031,2.15539,28.12031,22476,5
31.77780,-2.42084,-33.95839,2.39532,33.95839,22476,5
32.08180,-2.72499,-41.21908,2.69947,41.21908,22476,5
32.40280,-3.04612,-49.01440,3.02060,49.01440,22476,5
32.65780,-3.30083,-55.19500,3.27531,55.19500,22476,5
32.96080,-3.60412,-62.55379,3.57860,62.55379,22476,5
33.24280,-3.88595,-69.43031,3.86043,69.43031,22476,5
33.43680,-3.74536,-64.69612,3.71984,64.69612,22476,5
33.64280,-3.53073,-58.28246,3.50521,58.28246,22412,5
33.83080,-3.34058,-52.79762,3.31505,52.79762,22412,5
34.08380,-3.08703,-46.08675,3.06151,46.08675,22412,5
34.31780,-2.85268,-40.02761,2.82716,40.02761,22412,5
34.64820,-2.52273,-31.90587,2.49721,31.90587,22412,5
35.05680,-2.11381,-22.97037,2.08829,22.97037,22412,5
35.55980,-1.61081,-14.44058,1.58529,14.44058,22412,5
36.04880,-1.14754,-7.19697,1.12202,7.19697,22412,5
36.48280,-1.60617,-16.39488,1.58064,16.39488,22476,5
36.88880,-2.01379,-24.29923,1.98827,24.29923,22476,6
37.24380,-2.36886,-32.51318,2.34334,32.51318,22476,6
37.49180,-2.61692,-38.56322,2.59140,38.56322,22476,6
37.75080,-2.87577,-44.73121,2.85025,44.73121,22476,6
38.12180,-3.24669,-53.74545,3.22117,53.74545,22476,6
38.36380,-3.48890,-59.62717,3.46338,59.62717,22476,6
38.67780,-3.80271,-67.22330,3.77719,67.22330,22476,6
38.94380,-3.76113,-65.08414,3.73561,65.08414,22476,6
39.21380,-3.48069,-56.71835,3.45516,56.71835,22412,6
39.47880,-3.21390,-49.18642,3.18838,49.18642,22412,6
39.80780,-2.88444,-40.69221,2.85891,40.69221,22412,6
40.11480,-2.57760,-33.16558,2.55208,33.16558,22412,6
40.47380,-2.21858,-24.98578,2.19306,24.98578,22412,6
40.95380,-1.73849,-16.31602,1.71297,16.31602,22412,6
41.44820,-1.24450,-8.68485,1.21898,8.68485,22412,6
41.84820,-1.46615,-13.65942,1.44063,13.65942,22476,6
42.28980,-1.91237,-22.12658,1.88685,22.12658,22476,7
42.69680,-2.31958,-31.10551,2.29406,31.10551,22476,7
43.00380,-2.62672,-38.66993,2.60120,38.66993,22476,7
43.34580,-2.96882,-46.96666,2.94330,46.96666,22476,7
43.73380,-3.35671,-56.28287,3.33119,56.28288,22476,7
44.05880,-3.68170,-64.19182,3.65617,64.19182,22476,7
44.34820,-3.88359,-68.77943,3.85807,68.77943,22476,7
44.61980,-3.58885,-59.73270,3.56332,59.73270,22412,7
44.89880,-3.30610,-51.62465,3.28058,51.62465,22412,7
45.14480,-3.05978,-45.07165,3.03426,45.07165,22412,7
45.46080,-2.74352,-37.12025,2.71800,37.12025,22412,7
45.72680,-2.47755,-30.57086,2.45203,30.57086,22412,7
46.07780,-2.12658,-23.05535,2.10105,23.05535,22412,7
46.54820,-1.65656,-14.99098,1.63104,14.99098,22412,7
47.05780,-1.16133,-7.20782,1.13581,7.20782,22412,7
47.49080,-1.61392,-16.31924,1.58839,16.31923,22604,7
47.93380,-2.05859,-25.12727,2.03307,25.12727,22604,8
48.25580,-2.38067,-32.57928,2.35514,32.57928,22604,8
48.47580,-2.60071,-37.90151,2.57519,37.90150,22604,8
48.69180,-2.81655,-43.17041,2.79103,43.17041,22604,8
48.95380,-3.07875,-49.45090,3.05323,49.45090,22604,8
49.18480,-3.30954,-55.11455,3.28402,55.11455,22604,8
49.44820,-3.57275,-61.50072,3.54723,61.50072,22604,8
49.68180,-3.80657,-67.14147,3.78105,67.14147,22604,8
49.85180,-3.87177,-68.37836,3.84625,68.37836,22604,8
50.04380,-3.66113,-61.85964,3.63560,61.85965,22604,8
50.18180,-3.51909,-57.70126,3.49357,57.70126,22540,8
50.33280,-3.36638,-53.28688,3.34086,53.28688,22540,8
50.52280,-3.17564,-48.11183,3.15012,48.11183,22540,8
50.66580,-3.03263,-44.34276,3.00711,44.34276,22540,8
50.83380,-2.86434,-39.99100,2.83882,39.99100,22540,8
51.02880,-2.66942,-35.20191,2.64390,35.20192,22540,8
51.21880,-2.47943,-30.56108,2.45391,30.56108,22540,8
51.34280,-2.35543,-27.64282,2.32991,27.64282,22540,8
51.67080,-2.02746,-21.08117,2.00193,21.08117,22540,8
52.01580,-1.68245,-15.36361,1.65693,15.36361,22540,8
52.49380,-1.20451,-7.80421,1.17899,7.80421,22540,8
52.84820,-1.49245,-13.98255,1.46693,13.98255,22604,8
53.30380,-1.95247,-22.72352,1.92695,22.72352,22604,9
53.61280,-2.26161,-29.56217,2.23609,29.56217,22604,9
53.90980,-2.55869,-36.81665,2.53317,36.81665,22604,9
54.21180,-2.86060,-44.12265,2.83508,44.12265,22604,9
54.42180,-3.07074,-49.20808,3.04522,49.20808,22604,9
54.67080,-3.31955,-55.24262,3.29403,55.24262,22604,9
54.99780,-3.64677,-63.17802,3.62125,63.17802,22604,9
55.25880,-3.90747,-69.61603,3.88195,69.61603,22604,9
55.46680,-3.72724,-63.79408,3.70172,63.79408,22604,9
55.66080,-3.52610,-57.77189,3.50058,57.77189,22540,9
55.88080,-3.30390,-51.38985,3.27838,51.38985,22540,9
56.11880,-3.06563,-45.02780,3.04011,45.02781,22540,9
56.38780,-2.79628,-38.37696,2.77076,38.37696,22540,9
56.66780,-2.51638,-31.34901,2.49086,31.34901,22540,9
57.04820,-2.13639,-23.05122,2.11087,23.05122,22540,9
57.54820,-1.63640,-14.58321,1.61088,14.58321,22540,9
57.99980,-1.18446,-7.43967,1.15894,7.43967,22540,9
58.44820,-1.23564,-9.30491,1.21012,9.30491,22540,9
58.91980,-1.71917,-18.35748,1.69365,18.35748,22476,9
59.31380,-2.11364,-26.24577,2.08812,26.24577,22476,10
59.69280,-2.49260,-35.26105,2.46708,35.26105,22476,10
60.05480,-2.85454,-44.02561,2.82902,44.02561,22476,10
60.41480,-3.21450,-52.72025,3.18898,52.72025,22476,10
60.74820,-3.54768,-60.80126,3.52216,60.80126,22476,10
61.10980,-3.90955,-69.63632,3.88403,69.63632,22476,10
61.36580,-3.68678,-62.54496,3.66126,62.54496,22476,10
61.68480,-3.36124,-52.97152,3.33571,52.97152,22412,10
62.03780,-3.00756,-43.52126,2.98204,43.52126,22412,10
62.35480,-2.69037,-35.55897,2.66484,35.55897,22412,10
62.74820,-2.29730,-26.29904,2.27178,26.29904,22412,10
63.17080,-1.87423,-18.34157,1.84871,18.34157,22412,10
63.71880,-1.32635,-9.76473,1.30083,9.76473,22412,10
64.12780,-1.40647,-12.39508,1.38095,12.39508,22412,10
64.57480,-1.86023,-20.80868,1.83471,20.80868,22476,11
64.98180,-2.26754,-29.64171,2.24202,29.64171,22476,11
65.35280,-2.63866,-38.71660,2.61314,38.71659,22476,11
65.69480,-2.98075,-47.04292,2.95523,47.04292,22476,11
66.04820,-3.33355,-55.51226,3.30803,55.51226,22476,11
66.42080,-3.70658,-64.60762,3.68106,64.60762,22476,11
66.72980,-3.84710,-67.31425,3.82158,67.31425,22476,11
67.03580,-3.52395,-57.59101,3.49843,57.59101,22412,11
67.35280,-3.20465,-48.55298,3.17913,48.55297,22412,11
67.72480,-2.83226,-39.05886,2.80674,39.05886,22412,11
68.02680,-2.53034,-31.50381,2.50482,31.50381,22412,11
68.39780,-2.15932,-23.42040,2.13380,23.42040,22412,11
68.90180,-1.65533,-14.76287,1.62981,14.76287,22412,11
69.39180,-1.17021,-7.09436,1.14468,7.09436,22412,11
69.80780,-1.59340,-15.70795,1.56788,15.70795,22476,11
70.24820,-2.03553,-24.34486,2.01001,24.34486,22476,12
70.60680,-2.39445,-32.61862,2.36893,32.61861,22476,12
70.98080,-2.76849,-41.68458,2.74297,41.68458,22476,12
71.32380,-3.11162,-50.05695,3.08610,50.05695,22476,12
71.67380,-3.46162,-58.51639,3.43610,58.51639,22476,12
72.00080,-3.78842,-66.50122,3.76289,66.50121,22476,12
72.26780,-3.81071,-66.08439,3.78519,66.08439,22476,12
72.52780,-3.53826,-57.91678,3.51274,57.91678,22412,12
72.81180,-3.25175,-49.72763,3.22623,49.72763,22412,12
73.14480,-2.91843,-41.06476,2.89291,41.06476,22412,12
73.46180,-2.60151,-33.26476,2.57599,33.26476,22412,12
73.87380,-2.18942,-23.91208,2.16390,23.91208,22412,12
74.37380,-1.68947,-15.27567,1.66394,15.27567,22412,12
74.87180,-1.19150,-7.36319,1.16598,7.36319,22412,12
75.28380,-1.57104,-15.27871,1.54552,15.27871,22476,12
75.73980,-2.02961,-24.16617,2.00409,24.16617,22476,13
76.12780,-2.41754,-33.15830,2.39202,33.15830,22476,13
76.49480,-2.78459,-42.12666,2.75907,42.12666,22476,13
76.84780,-3.13767,-50.68823,3.11215,50.68822,22476,13
77.21480,-3.50470,-59.51206,3.47918,59.51206,22476,13
77.55180,-3.84155,-67.75606,3.81603,67.75607,22476,13
77.84820,-3.73279,-63.69358,3.70727,63.69358,22476,13
78.13480,-3.43781,-54.98119,3.41228,54.98119,22412,13
78.45480,-3.11667,-46.11141,3.09115,46.11141,22412,13
78.78980,-2.78133,-37.60753,2.75581,37.60753,22412,13
79.09580,-2.47544,-30.11329,2.44992,30.11329,22412,13
79.53780,-2.03345,-20.92822,2.00793,20.92822,22412,13
80.04820,-1.52342,-12.67837,1.49790,12.67837,22412,13
80.44820,-1.22359,-8.35053,1.19807,8.35052,22412,13
80.88580,-1.68631,-17.28767,1.66079,17.28767,22476,13
81.32480,-2.12662,-26.19610,2.10110,26.19610,22476,14
81.65680,-2.45867,-34.15476,2.43315,34.15476,22476,14
82.04820,-2.84955,-43.56434,2.82403,43.56434,22476,14
82.34820,-3.14963,-50.90459,3.12411,50.90459,22476,14
82.62780,-3.42967,-57.64713,3.40415,57.64713,22476,14
82.95680,-3.75852,-65.66174,3.73300,65.66174,22476,14
83.25580,-3.81900,-66.23933,3.79348,66.23933,22476,14
83.56680,-3.49442,-56.60056,3.46890,56.60056,22412,14
83.85180,-3.20768,-48.50094,3.18216,48.50094,22412,14
84.12380,-2.93547,-41.38314,2.90995,41.38314,22412,14
84.40080,-2.65840,-34.54966,2.63288,34.54966,22412,14
84.66880,-2.39034,-28.04969,2.36482,28.04969,22412,14
85.13780,-1.92130,-18.92481,1.89578,18.92481,22412,14
85.64820,-1.41136,-10.93868,1.38584,10.93868,22412,14
86.04580,-1.32921,-10.69650,1.30369,10.69650,22412,14
86.44880,-1.74378,-18.39699,1.71826,18.39699,22476,15
86.80880,-2.10463,-25.70279,2.07911,25.70279,22476,15
87.08380,-2.37960,-32.12573,2.35408,32.12573,22476,15
87.33480,-2.63065,-38.25732,2.60513,38.25732,22476,15
87.64280,-2.93868,-45.78796,2.91316,45.78796,22476,15
87.90880,-3.20455,-52.14741,3.17902,52.14741,22476,15
88.24820,-3.54368,-60.43744,3.51816,60.43744,22476,15
88.41780,-3.71361,-64.55795,3.68809,64.55795,22476,15
88.68180,-3.91656,-69.43618,3.89104,69.43618,22476,15
88.84180,-3.73699,-63.65527,3.71147,63.65527,22476,15
89.03780,-3.53413,-57.72109,3.50861,57.72109,22412,15
89.27980,-3.28984,-50.75201,3.26432,50.75201,22412,15
89.43880,-3.13070,-46.40776,3.10518,46.40776,22412,15
89.60480,-2.96465,-42.11610,2.93913,42.11610,22412,15
89.76080,-2.80839,-38.13599,2.78287,38.13599,22412,15
89.99180,-2.57757,-32.43337,2.55205,32.43337,22412,15
90.24820,-2.32148,-26.49390,2.29596,26.49390,22412,15
90.64820,-1.92137,-18.90170,1.89585,18.90170,22412,15
91.14820,-1.42146,-11.07022,1.39594,11.07022,22412,15
91.58180,-1.39042,-11.84020,1.36490,11.84020,22412,15
92.04780,-1.86540,-20.68085,1.83988,20.68085,22476,16
92.42680,-2.24478,-28.75546,2.21926,28.75546,22476,16
92.74880,-2.56686,-36.60630,2.54133,36.60630,22476,16
93.13280,-2.95093,-45.98716,2.92541,45.98716,22476,16
93.47080,-3.28869,-54.15994,3.26317,54.15993,22476,16
93.81580,-3.63390,-62.65189,3.60838,62.65189,22476,16
94.14880,-3.93100,-69.75642,3.90548,69.75642,22476,16
94.38780,-3.66978,-61.63148,3.64426,61.63148,22412,16
94.64780,-3.40464,-53.88910,3.37912,53.88910,22412,16
94.88780,-3.16374,-47.25198,3.13822,47.25198,22412,16
95.14820,-2.90351,-40.46559,2.87799,40.46559,22412,16
95.53480,-2.51659,-30.85050,2.49107,30.85050,22412,16
95.94820,-2.10371,-22.12057,2.07819,22.12057,22412,16
96.44820,-1.60368,-13.74436,1.57816,13.74436,22412,16
96.92480,-1.21577,-8.02559,1.19025,8.02559,22412,16
97.34820,-1.66445,-16.82426,1.63893,16.82426,22476,16
97.74820,-2.06591,-24.77669,2.04039,24.77669,22476,17
98.10180,-2.41984,-33.01718,2.39432,33.01718,22476,17
98.41980,-2.73793,-40.71850,2.71241,40.71850,22476,17
98.74820,-3.06602,-48.77884,3.04050,48.77884,22476,17
99.01580,-3.33388,-55.24318,3.30836,55.24318,22476,17
99.34280,-3.66091,-63.22446,3.63539,63.22446,22476,17
99.64820,-3.91081,-69.18257,3.88529,69.18257,22476,17
99.94580,-3.58762,-59.17957,3.56210,59.17957,22412,17
100.25780,-3.27191,-50.18098,3.24639,50.18098,22412,17
100.53680,-2.99281,-42.73189,2.96729,42.73189,22412,17
100.77980,-2.74958,-36.65516,2.72406,36.65516,22412,17
101.09180,-2.43761,-29.02964,2.41209,29.02964,22412,17
101.54380,-1.98570,-19.85857,1.96018,19.85856,22412,17
102.05280,-1.47666,-11.87053,1.45114,11.87053,22412,17
102.47580,-1.31303,-10.19310,1.28751,10.19310,22412,17
102.94280,-1.79408,-19.18179,1.76856,19.18179,22604,17
103.35080,-2.20276,-27.67231,2.17724,27.67231,22604,18
103.69280,-2.54480,-35.94884,2.51928,35.94884,22604,18
103.96180,-2.81374,-42.55759,2.78821,42.55759,22604,18
104.34820,-3.19969,-51.89600,3.17417,51.89600,22604,18
104.63780,-3.48994,-59.03420,3.46441,59.03420,22604,18
104.92880,-3.78072,-66.14594,3.75520,66.14594,22604,18
105.24820,-3.78168,-64.96575,3.75616,64.96575,22604,18
105.50180,-3.51777,-57.09407,3.49225,57.09407,22540,18
105.83680,-3.18067,-47.62029,3.15515,47.62029,22540,18
106.19180,-2.82539,-38.48208,2.79987,38.48208,22540,18
106.52880,-2.48850,-30.18997,2.46298,30.18997,22540,18
106.94820,-2.06957,-21.35938,2.04404,21.35938,22540,18
107.43380,-1.58357,-13.40910,1.55805,13.40910,22540,18
107.88080,-1.21466,-7.90105,1.18914,7.90105,22540,18
108.33480,-1.69552,-17.29459,1.67000,17.29459,22604,18
108.74820,-2.10980,-25.65957,2.08428,25.65957,22604,19
109.14780,-2.50970,-35.14581,2.48418,35.14581,22604,19
109.51880,-2.88073,-44.17496,2.85521,44.17496,22604,19
109.89180,-3.25367,-53.15827,3.22815,53.15827,22604,19
110.25680,-3.61889,-62.17306,3.59337,62.17306,22604,19
110.62080,-3.90447,-68.82594,3.87895,68.82594,22604,19
110.91280,-3.58836,-59.13858,3.56284,59.13858,22540,19
111.20880,-3.28882,-50.62433,3.26330,50.62433,22540,19
111.52680,-2.97066,-42.10036,2.94514,42.10035,22540,19
111.89180,-2.60557,-33.03079,2.58005,33.03079,22540,19
112.24820,-2.24941,-24.90543,2.22389,24.90543,22540,19
112.74820,-1.74938,-15.93512,1.72386,15.93512,22540,19
113.26080,-1.23656,-7.92060,1.21103,7.92060,22540,19
113.83980,-1.36073,-11.34614,1.33521,11.34614,22540,19
114.29880,-1.82549,-19.86538,1.79997,19.86538,22476,19
114.71980,-2.24682,-28.86175,2.22130,28.86175,22476,20
115.04820,-2.57488,-36.82065,2.54936,36.82065,22476,20
115.35180,-2.87879,-44.18020,2.85327,44.18020,22476,20
115.74080,-3.26772,-53.63634,3.24220,53.63634,22476,20
116.11780,-3.64489,-62.81839,3.61937,62.81839,22476,20
116.44820,-3.91975,-69.43651,3.89423,69.43651,22476,20
116.74080,-3.60165,-59.58053,3.57613,59.58053,22412,20
117.05080,-3.28784,-50.56278,3.26232,50.56278,22412,20
117.36880,-2.96967,-42.03263,2.94415,42.03263,22412,20
117.70680,-2.63151,-33.71506,2.60599,33.71506,22412,20
118.11280,-2.22548,-24.39162,2.19996,24.39162,22412,20
118.59580,-1.74242,-15.84391,1.71690,15.84391,22412,20
119.12880,-1.20958,-7.43969,1.18406,7.43969,22412,20
119.52780,-1.56378,-14.89306,1.53826,14.89306,22476,20
119.96580,-2.00471,-23.33443,1.97919,23.33443,22476,21
120.34980,-2.38867,-32.09104,2.36315,32.09105,22476,21
120.73880,-2.77769,-41.57411,2.75217,41.57411,22476,21
121.10480,-3.14375,-50.52710,3.11823,50.52710,22476,21
121.44820,-3.48685,-58.87516,3.46132,58.87516,22476,21
121.79380,-3.83261,-67.32303,3.80709,67.32303,22476,21
122.04820,-3.79787,-65.40997,3.77235,65.40997,22476,21
122.34820,-3.48639,-56.18451,3.46087,56.18451,22412,21
122.68480,-3.14768,-46.59423,3.12216,46.59423,22412,21
123.04820,-2.78443,-37.31793,2.75891,37.31793,22412,21
123.42980,-2.40245,-28.06677,2.37693,28.06676,22412,21
123.87380,-1.95856,-19.32751,1.93304,19.32751,22412,21
124.41980,-1.41248,-10.78065,1.38696,10.78065,22412,21
124.82580,-1.37207,-11.28501,1.34655,11.28501,22412,21
125.28180,-1.83812,-19.85566,1.81260,19.85566,22476,22
125.69080,-2.24765,-28.67798,2.22213,28.67798,22476,22
126.06080,-2.61778,-37.65990,2.59226,37.65990,22476,22
126.43980,-2.99689,-47.01977,2.97137,47.01977,22476,22
126.81680,-3.37372,-56.14370,3.34820,56.14370,22476,22
127.18880,-3.74555,-65.17167,3.72003,65.17167,22476,22
127.52180,-3.81269,-65.81092,3.78717,65.81092,22476,22
127.80080,-3.52160,-57.11207,3.49608,57.11207,22412,22
128.13480,-3.18550,-47.65026,3.15998,47.65026,22412,22
128.44820,-2.87221,-39.48374,2.84669,39.48374,22412,22
128.78780,-2.53230,-31.04906,2.50678,31.04906,22412,22
129.21480,-2.10542,-21.98311,2.07990,21.98311,22412,22
129.73580,-1.58443,-13.32274,1.55890,13.32274,22412,22
130.22380,-1.27539,-9.23857,1.24987,9.23857,22412,22
130.65779,-1.72750,-17.84692,1.70198,17.84692,22476,22
131.09680,-2.16745,-26.75589,2.14193,26.75589,22476,23
131.47180,-2.54256,-35.76366,2.51704,35.76366,22476,23
131.81580,-2.88649,-44.15156,2.86097,44.15155,22476,23
132.18780,-3.25844,-53.19768,3.23292,53.19768,22476,23
132.55280,-3.62358,-62.19890,3.59806,62.19890,22476,23
132.88580,-3.93516,-69.81675,3.90964,69.81675,22476,23
133.17380,-3.62701,-60.24591,3.60149,60.24591,22412,23
133.44820,-3.34897,-52.12489,3.32345,52.12489,22412,23
133.78580,-3.01038,-42.96358,2.98486,42.96358,22412,23
134.14819,-2.64823,-33.98794,2.62271,33.98793,22412,23
134.51780,-2.27812,-25.39843,2.25259,25.39843,22412,23
134.99180,-1.80405,-16.74027,1.77853,16.74027,22412,23
135.52580,-1.27015,-8.40352,1.24462,8.40352,22412,23
135.91178,-1.50998,-13.75688,1.48446,13.75688,22476,23
136.34980,-1.95222,-22.19390,1.92670,22.19390,22476,24
136.74820,-2.35040,-31.01823,2.32488,31.01823,22476,24
137.05980,-2.66248,-38.76331,2.63696,38.76331,22476,24
137.44820,-3.05056,-48.19595,3.02504,48.19595,22476,24
137.82080,-3.42347,-57.21844,3.39795,57.21844,22476,24
138.18780,-3.79025,-66.21084,3.76473,66.21084,22476,24
138.48180,-3.79557,-65.24564,3.77005,65.24564,22476,24
138.78480,-3.48100,-55.95062,3.45548,55.95061,22412,24
139.11380,-3.15031,-46.63233,3.12479,46.63233,22412,24
139.46880,-2.79506,-37.53641,2.76953,37.53640,22412,24
139.84819,-2.41613,-28.31198,2.39061,28.31199,22412,24
140.29380,-1.97024,-19.41357,1.94472,19.41357,22412,24
140.84680,-1.41713,-10.75623,1.39161,10.75623,22412,24
141.24820,-1.36316,-11.03214,1.33764,11.03214,22412,24
141.70980,-1.83585,-19.77666,1.81033,19.77666,22476,25
142.12880,-2.25540,-28.76056,2.22988,28.76056,22476,25
142.49080,-2.61754,-37.61216,2.59202,37.61216,22476,25
142.83680,-2.96358,-46.01096,2.93806,46.01096,22476,25
143.21380,-3.34042,-55.20605,3.31490,55.20605,22476,25
143.58180,-3.70833,-64.21212,3.68280,64.21212,22476,25
143.91380,-3.84628,-66.83996,3.82076,66.83996,22476,25
144.21880,-3.52552,-57.18978,3.50000,57.18978,22412,25
144.54820,-3.19434,-47.85075,3.16882,47.85075,22412,25
144.90580,-2.83604,-38.58200,2.81052,38.58200,22412,25
145.24820,-2.49412,-30.10888,2.46860,30.10888,22412,25
145.66580,-2.07620,-21.35052,2.05068,21.35052,22412,25
146.18880,-1.55314,-12.83373,1.52762,12.83373,22412,25
146.65880,-1.30271,-9.71705,1.27719,9.71705,22412,25
147.12680,-1.78662,-18.91310,1.76110,18.91310,22476,25
147.54820,-2.20840,-27.55819,2.18288,27.55819,22476,26
147.91880,-2.57949,-36.60773,2.55397,36.60773,22476,26
148.29080,-2.95155,-45.70430,2.92603,45.70430,22476,26
148.59680,-3.25735,-53.07174,3.23183,53.07174,22476,26
148.90280,-3.56342,-60.62027,3.53790,60.62027,22476,26
149.25780,-3.91837,-69.36706,3.89285,69.36706,22476,26
149.51880,-3.70673,-62.56098,3.68121,62.56098,22476,26
149.82980,-3.38906,-53.20359,3.36354,53.20359,22412,26
150.05880,-3.15929,-46.78740,3.13377,46.78740,22412,26
150.39880,-2.81905,-38.09781,2.79353,38.09781,22412,26
150.74820,-2.47017,-29.51589,2.44465,29.51589,22412,26
151.16480,-2.05317,-20.89547,2.02765,20.89547,22412,26
151.69580,-1.52222,-12.36176,1.49670,12.36176,22412,26
152.12480,-1.29781,-9.60946,1.27229,9.60946,22412,26
152.56780,-1.75743,-18.31767,1.73191,18.31767,22476,27
153.00580,-2.19636,-27.26570,2.17084,27.26570,22476,27
153.37380,-2.56442,-36.20995,2.53890,36.20995,22476,27
153.74820,-2.93841,-45.32579,2.91289,45.32579,22476,27
154.09380,-3.28429,-53.72610,3.25877,53.72610,22476,27
154.46080,-3.65136,-62.77344,3.62584,62.77345,22476,27
154.81280,-3.89446,-68.35867,3.86894,68.35867,22476,27
155.10480,-3.58066,-58.72061,3.55514,58.72061,22412,27
155.44180,-3.24037,-49.01625,3.21485,49.01625,22412,27
155.70980,-2.97226,-41.84013,2.94674,41.84013,22412,27
156.02180,-2.66008,-34.18058,2.63456,34.18058,22412,27
156.42280,-2.25901,-24.88965,2.23349,24.88965,22412,27
156.89780,-1.78393,-16.36238,1.75841,16.36238,22412,27
157.43978,-1.24212,-7.81515,1.21660,7.81515,22412,27
157.83180,-1.54473,-14.33188,1.51921,14.33188,22604,27
158.26380,-1.98023,-22.67857,1.95470,22.67857,22604,27
158.65980,-2.37629,-31.56770,2.35077,31.56770,22604,28
159.01280,-2.72932,-40.16153,2.70380,40.16153,22604,28
159.37880,-3.09541,-49.15205,3.06989,49.15205,22604,28
159.75080,-3.46734,-58.19242,3.44182,58.19242,22604,28
160.09380,-3.81014,-66.66376,3.78462,66.66376,22604,28
160.35280,-3.83070,-66.20838,3.80518,66.20837,22604,28
160.66080,-3.50901,-56.66642,3.48349,56.66642,22540,28
160.99578,-3.17212,-47.18064,3.14660,47.18064,22540,28
161.34819,-2.81985,-38.01773,2.79433,38.01773,22540,28
161.73880,-2.42896,-28.48075,2.40344,28.48075,22540,28
162.16880,-1.99905,-19.84290,1.97353,19.84290,22540,28
162.71680,-1.45110,-11.24772,1.42558,11.24772,22540,28
163.15180,-1.38570,-11.37387,1.36018,11.37387,22540,28
163.61480,-1.85873,-20.11191,1.83321,20.11191,22604,29
164.03678,-2.28113,-29.26708,2.25561,29.26708,22604,29
164.40180,-2.64627,-38.22244,2.62075,38.22244,22604,29
164.76680,-3.01138,-47.16298,2.98586,47.16298,22604,29
165.14819,-3.39222,-56.43290,3.36670,56.43290,22604,29
165.52880,-3.77307,-65.68893,3.74755,65.68893,22604,29
165.81980,-3.83188,-66.24892,3.80635,66.24892,22604,29
166.12780,-3.50991,-56.67829,3.48439,56.67829,22540,29
166.44880,-3.18702,-47.61933,3.16150,47.61933,22540,29
166.80980,-2.82572,-38.21273,2.80020,38.21273,22540,29
167.14819,-2.48786,-29.86907,2.46234,29.86907,22540,29
167.57780,-2.05788,-20.95098,2.03236,20.95098,22540,29
168.11180,-1.52393,-12.33295,1.49841,12.33295,22540,29
168.79780,-1.19803,-7.51122,1.17251,7.51122,22540,29
169.24180,-1.62036,-15.89819,1.59484,15.89819,22476,29
169.66980,-2.04937,-24.26341,2.02385,24.26341,22476,29
170.05780,-2.43735,-33.21946,2.41183,33.21946,22476,30
170.44280,-2.82228,-42.60510,2.79676,42.60510,22476,30
170.81478,-3.19423,-51.65700,3.16870,51.65700,22476,30
171.18780,-3.56729,-60.76518,3.54177,60.76519,22476,30
171.54820,-3.92726,-69.60014,3.90174,69.60014,22476,30
171.83280,-3.68040,-61.69466,3.65488,61.69466,22476,30
172.12180,-3.38601,-53.05247,3.36049,53.05247,22412,30
172.45080,-3.05633,-43.98872,3.03081,43.98872,22412,30
172.74820,-2.75910,-36.47326,2.73358,36.47326,22412,30
173.09180,-2.41509,-28.11096,2.38957,28.11096,22412,30
173.54820,-1.95920,-19.15403,1.93368,19.15403,22412,30
174.08180,-1.42513,-10.81508,1.39960,10.81508,22412,30
174.53280,-1.43864,-12.35222,1.41312,12.35222,22412,30
174.97480,-1.88793,-20.74861,1.86241,20.74861,22476,31
175.38080,-2.29431,-29.55762,2.26879,29.55762,22476,31
175.72980,-2.64342,-38.15109,2.61790,38.15109,22476,31
176.09580,-3.00954,-47.12470,2.98402,47.12470,22476,31
176.47080,-3.38441,-56.19426,3.35889,56.19426,22476,31
176.84819,-3.76120,-65.47199,3.73568,65.47199,22476,31
177.14819,-3.84404,-66.63663,3.81852,66.63663,22476,31
177.45280,-3.52444,-57.06804,3.49892,57.06804,22412,31
177.78380,-3.19140,-47.68130,3.16588,47.68130,22412,31
178.11980,-2.85513,-38.89355,2.82961,38.89355,22412,31
178.47880,-2.49620,-30.03630,2.47068,30.03630,22412,31
178.91880,-2.05624,-20.88043,2.03072,20.88043,22412,31
179.44820,-1.52724,-12.32960,1.50172,12.32960,22412,31
179.84780,-1.26272,-8.68667,1.23720,8.68667,22412,31
180.27680,-1.71323,-17.39298,1.68771,17.39298,22476,31
180.70980,-2.14734,-26.16453,2.12182,26.16453,22476,32
181.08180,-2.51939,-35.07831,2.49387,35.07830,22476,32
181.45280,-2.89038,-44.06828,2.86486,44.06828,22476,32
181.80680,-3.24432,-52.71744,3.21880,52.71744,22476,32
182.17280,-3.61040,-61.75579,3.58488,61.75579,22476,32
182.54280,-3.93177,-69.43335,3.90625,69.43336,22476,32
182.83480,-3.61440,-59.67317,3.58888,59.67317,22412,32
183.14819,-3.29753,-50.57872,3.27201,50.57872,22412,32
183.45980,-2.98532,-42.10096,2.95980,42.10096,22412,32
183.84180,-2.60322,-32.55412,2.57770,32.55412,22412,32
184.24820,-2.19713,-23.51867,2.17161,23.51867,22412,32
184.74820,-1.69726,-14.90277,1.67174,14.90277,22412,32
185.23880,-1.20899,-7.18170,1.18347,7.18170,22412,32
185.64819,-1.61915,-15.64217,1.59363,15.64217,22476,32
186.08480,-2.05834,-24.22398,2.03282,24.22398,22476,33
186.46880,-2.44246,-33.17316,2.41694,33.17316,22476,33
186.81580,-2.78936,-41.57268,2.76384,41.57268,22476,33
187.18880,-3.16240,-50.73341,3.13688,50.73341,22476,33
187.55980,-3.53338,-59.81757,3.50786,59.81757,22476,33
187.93880,-3.91230,-69.16036,3.88678,69.16036,22476,33
188.22280,-3.68083,-61.68270,3.65531,61.68270,22476,33
188.54680,-3.35100,-52.06618,3.32548,52.06618,22412,33
188.87580,-3.02139,-42.99959,2.99587,42.99959,22412,33
189.24820,-2.64924,-33.75046,2.62372,33.75046,22412,33
189.55680,-2.34021,-26.38040,2.31469,26.38040,22412,33
190.04780,-1.84916,-17.30608,1.82364,17.30608,22412,33
190.56380,-1.33319,-9.25568,1.30767,9.25568,22412,33
190.93180,-1.44412,-12.37994,1.41859,12.37994,22412,33
191.36480,-1.88406,-20.59046,1.85854,20.59046,22476,33
191.78280,-2.30238,-29.69151,2.27686,29.69151,22476,34
192.13080,-2.65055,-38.27747,2.62503,38.27747,22476,34
192.49480,-3.01466,-47.19983,2.98914,47.19983,22476,34
192.85880,-3.37851,-55.99408,3.35299,55.99408,22476,34
193.24820,-3.76731,-65.58497,3.74179,65.58498,22476,34
193.54680,-3.83218,-66.19069,3.80666,66.19069,22476,34
193.81780,-3.54794,-57.66008,3.52242,57.66008,22412,34
194.14819,-3.21549,-48.28222,3.18997,48.28222,22412,34
194.49480,-2.86812,-39.13730,2.84260,39.13729,22412,34
194.84278,-2.52022,-30.53389,2.49470,30.53389,22412,34
195.24820,-2.11530,-21.96029,2.08978,21.96029,22412,34
195.77080,-1.59235,-13.21849,1.56683,13.21849,22412,34
196.24820,-1.28991,-9.27082,1.26439,9.27082,22412,34
196.70180,-1.76242,-18.33976,1.73690,18.33976,22476,34
197.13680,-2.19838,-27.18164,2.17286,27.18164,22476,35
197.50878,-2.57048,-36.25249,2.54496,36.25249,22476,35
197.87680,-2.93845,-45.21128,2.91293,45.21128,22476,35
198.22280,-3.28430,-53.61712,3.25878,53.61712,22476,35
198.59380,-3.65537,-62.79227,3.62985,62.79227,22476,35
198.92480,-3.93185,-69.41154,3.90633,69.41154,22476,35
199.21480,-3.61639,-59.64599,3.59087,59.64599,22412,35
199.54580,-3.28149,-50.07401,3.25597,50.07402,22412,35
199.87980,-2.94728,-40.96019,2.92176,40.96019,22412,35
200.18580,-2.64118,-33.47847,2.61566,33.47847,22412,35
200.58380,-2.24311,-24.38136,2.21759,24.38136,22412,35
201.06880,-1.75807,-15.80268,1.73255,15.80268,22412,35
201.59880,-1.22830,-7.48559,1.20278,7.48559,22412,35
201.99880,-1.58356,-14.88099,1.55804,14.88099,22476,35
202.44820,-2.03537,-23.70674,2.00985,23.70674,22476,36
202.79580,-2.38343,-31.61424,2.35791,31.61424,22476,36
203.14280,-2.73046,-40.11258,2.70494,40.11258,22476,36
203.51580,-3.10356,-49.26674,3.07804,49.26674,22476,36
203.88480,-3.47251,-58.18134,3.44699,58.18134,22476,36
204.25280,-3.84029,-67.28202,3.81476,67.28202,22476,36
204.55580,-3.75090,-63.69293,3.72538,63.69293,22476,36
204.87278,-3.42530,-54.14868,3.39978,54.14868,22412,36
205.20980,-3.08740,-44.55341,3.06188,44.55341,22412,36
205.57480,-2.72216,-35.37931,2.69664,35.37931,22412,36
205.95980,-2.33712,-26.29561,2.31160,26.29561,22412,36
206.44480,-1.85207,-17.26970,1.82655,17.26970,22412,36
206.94980,-1.34711,-9.39643,1.32159,9.39643,22412,36
207.35380,-1.47331,-12.81542,1.44778,12.81542,22476,36
207.81780,-1.94320,-21.80182,1.91768,21.80182,22476,37
208.22380,-2.34939,-30.79335,2.32387,30.79335,22476,37
208.58980,-2.71549,-39.76658,2.68997,39.76658,22476,37
208.93380,-3.05956,-48.27152,3.03404,48.27152,22476,37
209.30480,-3.43045,-57.23024,3.40493,57.23024,22476,37
209.67080,-3.79630,-66.22521,3.77078,66.22521,22476,37
209.98080,-3.78427,-64.74423,3.75875,64.74423,22476,37
210.29280,-3.46174,-55.17824,3.43622,55.17824,22412,37
210.59380,-3.15929,-46.66045,3.13377,46.66045,22412,37
210.91980,-2.83305,-38.24640,2.80753,38.24640,22412,37
211.25280,-2.50016,-30.04307,2.47464,30.04308,22412,37
211.68880,-2.06422,-20.96138,2.03870,20.96138,22412,37
212.22380,-1.52926,-12.33245,1.50374,12.33245,22412,37
212.64819,-1.29919,-9.44643,1.27367,9.44643,22412,37
213.09680,-1.76543,-18.33827,1.73990,18.33827,22604,37
213.53580,-2.20532,-27.28775,2.17980,27.28775,22604,38
213.88980,-2.55945,-35.91906,2.53393,35.91906,22604,38
214.27280,-2.94247,-45.26100,2.91695,45.26100,22604,38
214.64819,-3.31731,-54.40392,3.29179,54.40392,22604,38
215.01680,-3.68632,-63.52839,3.66080,63.52839,22604,38
215.34180,-3.90033,-68.28087,3.87481,68.28087,22604,38
215.63880,-3.58162,-58.59029,3.55610,58.59029,22540,38
215.94820,-3.26944,-49.72565,3.24392,49.72565,22540,38
216.30980,-2.90707,-39.92239,2.88155,39.92239,22540,38
216.67580,-2.54115,-30.94211,2.51563,30.94211,22540,38
217.09680,-2.12024,-21.93875,2.09472,21.93875,22540,38
217.61680,-1.60034,-13.29920,1.57482,13.29920,22540,38
218.07080,-1.24616,-8.21249,1.22064,8.21249,22540,38
218.52578,-1.72626,-17.49317,1.70074,17.49317,22604,38
218.94820,-2.14934,-26.12263,2.12382,26.12263,22604,39
219.28780,-2.48945,-34.27357,2.46393,34.27357,22604,39
219.64878,-2.85027,-43.10164,2.82475,43.10164,22604,39
220.04819,-3.24929,-52.70045,3.22377,52.70045,22604,39
220.40980,-3.61139,-61.60783,3.58586,61.60783,22604,39
220.75480,-3.95220,-70.07503,3.92668,70.07503,22604,39
221.01480,-3.69062,-61.79349,3.66510,61.79350,22604,39
221.34478,-3.35488,-52.05100,3.32936,52.05100,22540,39
221.67080,-3.02837,-43.05629,3.00285,43.05629,22540,39
222.04680,-2.65220,-33.69989,2.62668,33.69989,22540,39
222.44820,-2.25112,-24.47493,2.22560,24.47493,22540,39
222.94080,-1.75809,-15.75195,1.73257,15.75195,22540,39
223.44820,-1.25119,-7.78849,1.22567,7.78849,22540,39
224.12480,-1.46132,-12.80466,1.43580,12.80466,22476,39
224.57280,-1.91236,-21.29318,1.88684,21.29318,22476,39
224.98278,-2.32256,-30.32021,2.29704,30.32021,22476,40
225.35180,-2.69159,-39.30742,2.66607,39.30742,22476,40
225.73980,-3.07966,-48.76763,3.05414,48.76763,22476,40
226.11080,-3.45059,-57.81019,3.42507,57.81019,22476,40
226.44820,-3.78739,-66.07675,3.76187,66.07675,22476,40
226.76180,-3.79390,-65.05581,3.76838,65.05581,22476,40
227.06880,-3.47594,-55.60321,3.45042,55.60321,22412,40
227.40180,-3.14141,-46.12919,3.11589,46.12919,22412,40
227.75180,-2.79110,-37.16986,2.76558,37.16986,22412,40
228.14819,-2.39516,-27.49468,2.36964,27.49468,22412,40
228.59180,-1.95126,-18.93927,1.92574,18.93927,22412,40
229.13880,-1.40417,-10.37717,1.37865,10.37717,22412,40
229.54680,-1.42174,-11.90606,1.39622,11.90606,22412,40
229.99280,-1.87608,-20.32533,1.85056,20.32533,22476,41
230.39980,-2.28340,-29.18321,2.25788,29.18321,22476,41
230.76480,-2.64858,-38.12690,2.62306,38.12690,22476,41
231.10880,-2.99273,-46.54430,2.96720,46.54430,22476,41
231.48080,-3.36457,-55.57973,3.33905,55.57973,22476,41
231.82880,-3.71242,-64.14402,3.68690,64.14401,22476,41
232.14280,-3.88660,-67.87170,3.86108,67.87170,22476,41
232.44378,-3.56629,-58.13935,3.54077,58.13935,22412,41
232.73680,-3.27050,-49.73782,3.24498,49.73782,22412,41
233.07380,-2.93327,-40.55170,2.90775,40.55170,22412,41
233.44820,-2.55926,-31.30807,2.53374,31.30807,22412,41
233.85978,-2.14724,-22.45230,2.12172,22.45230,22412,41
234.37078,-1.63632,-13.85834,1.61080,13.85834,22412,41
234.84819,-1.23518,-7.82748,1.20966,7.82749,22412,41
235.27680,-1.69108,-16.86159,1.66556,16.86159,22476,41
235.71080,-2.12654,-25.62416,2.10102,25.62416,22476,42
236.09478,-2.51058,-34.77152,2.48506,34.77152,22476,42
236.46080,-2.87647,-43.68259,2.85095,43.68259,22476,42
236.84819,-3.26346,-53.05527,3.23794,53.05527,22476,42
237.21880,-3.63454,-62.24639,3.60902,62.24639,22476,42
237.55480,-3.95087,-69.97450,3.92535,69.97450,22476,42
237.84478,-3.64106,-60.32070,3.61554,60.32070,22412,42
238.16480,-3.31680,-51.02487,3.29128,51.02487,22412,42
238.50480,-2.97649,-41.63728,2.95097,41.63728,22412,42
238.86880,-2.61237,-32.62624,2.58685,32.62624,22412,42
239.28280,-2.19832,-23.36731,2.17280,23.36731,22412,42
239.78580,-1.69542,-14.80984,1.66990,14.80984,22412,42
240.27680,-1.20986,-7.04865,1.18434,7.04865,22412,42
240.68480,-1.62634,-15.62377,1.60082,15.62377,22476,42
241.14180,-2.08553,-24.72690,2.06001,24.72691,22476,43
241.51780,-2.46161,-33.56366,2.43609,33.56366,22476,43
241.89080,-2.83446,-42.65894,2.80894,42.65894,22476,43
242.22380,-3.16749,-50.80029,3.14197,50.80029,22476,43
242.56878,-3.51255,-59.16411,3.48703,59.16411,22476,43
242.94820,-3.89142,-68.51315,3.86590,68.51315,22476,43
243.21380,-3.73823,-63.28069,3.71271,63.28069,22476,43
243.53180,-3.41228,-53.63970,3.38676,53.63969,22412,43
243.84980,-3.09350,-44.59425,3.06798,44.59425,22412,43
244.23278,-2.71025,-35.01234,2.68473,35.01234,22412,43
244.56980,-2.37317,-26.90742,2.34765,26.90742,22412,43
245.04819,-1.89511,-17.91729,1.86959,17.91729,22412,43
245.56580,-1.37722,-9.83604,1.35170,9.83604,22412,43
245.95980,-1.45406,-12.43593,1.42854,12.43593,22412,43
246.42380,-1.92518,-21.33336,1.89966,21.33336,22476,44
246.82380,-2.32554,-30.16648,2.30002,30.16648,22476,44
247.19480,-2.69662,-39.25035,2.67110,39.25035,22476,44
247.53780,-3.03971,-47.71692,3.01419,47.71692,22476,44
247.90880,-3.41058,-56.70237,3.38506,56.70237,22476,44
248.24820,-3.74941,-65.04426,3.72389,65.04426,22476,44
248.54819,-3.87269,-67.30738,3.84717,67.30738,22476,44
248.85880,-3.54483,-57.45272,3.51931,57.45272,22412,44
249.19080,-3.21060,-48.05608,3.18508,48.05608,22412,44
249.51278,-2.88821,-39.34838,2.86269,39.34838,22412,44
249.87180,-2.52935,-30.51999,2.50383,30.51999,22412,44
250.25180,-2.14932,-22.40457,2.12380,22.40457,22412,44
250.76680,-1.63445,-13.75850,1.60893,13.75850,22412,44
251.24480,-1.24765,-8.03867,1.22213,8.03867,22412,44
251.65980,-1.68818,-16.77608,1.66266,16.77608,22476,44
252.10880,-2.13871,-25.84303,2.11319,25.84303,22476,45
252.44820,-2.47776,-33.89140,2.45224,33.89140,22476,45
252.82978,-2.85964,-43.22034,2.83412,43.22034,22476,45
253.20478,-3.23463,-52.37171,3.20911,52.37172,22476,45
253.56478,-3.59467,-61.20857,3.56915,61.20857,22476,45
253.92380,-3.95056,-69.97190,3.92504,69.97190,22476,45
254.20478,-3.67017,-61.15321,3.64465,61.15321,22476,45
254.53480,-3.33515,-51.51374,3.30963,51.51374,22412,45
254.82978,-3.03972,-43.20262,3.01419,43.20263,22412,45
255.18978,-2.67954,-34.21295,2.65402,34.21295,22412,45
255.59580,-2.27343,-24.85150,2.24791,24.85150,22412,45
256.07181,-1.79741,-16.36086,1.77189,16.36086,22412,45
256.61178,-1.25751,-7.80303,1.23198,7.80303,22412,45
257.04581,-1.61739,-15.41916,1.59187,15.41916,22476,45
257.47480,-2.04882,-23.84476,2.02329,23.84476,22476,46
257.85678,-2.43088,-32.75139,2.40536,32.75139,22476,46
258.24780,-2.82180,-42.25836,2.79628,42.25836,22476,46
258.61280,-3.18680,-51.21318,3.16127,51.21318,22476,46
258.98080,-3.55486,-60.20500,3.52934,60.20500,22476,46
259.34820,-3.92185,-69.22723,3.89633,69.22723,22476,46
259.62280,-3.70586,-62.24635,3.68034,62.24635,22476,46
259.94778,-3.37448,-52.55907,3.34896,52.55907,22412,46
260.26678,-3.05488,-43.57625,3.02936,43.57625,22412,46
260.64819,-2.67367,-34.03674,2.64815,34.03674,22412,46
261.04678,-2.27457,-24.87016,2.24905,24.87016,22412,46
261.51880,-1.80253,-16.39905,1.77701,16.39905,22412,46
262.04819,-1.27358,-8.08948,1.24806,8.08948,22412,46
262.44681,-1.56338,-14.34748,1.53786,14.34748,22476,46
262.87378,-1.99395,-22.71717,1.96843,22.71717,22476,47
263.27478,-2.39491,-31.78609,2.36939,31.78609,22476,47
263.61881,-2.73900,-40.16590,2.71348,40.16590,22476,47
263.99381,-3.11410,-49.39588,3.08858,49.39588,22476,47
264.33678,-3.45706,-57.76471,3.43154,57.76471,22476,47
264.67678,-3.79692,-66.12086,3.77140,66.12086,22476,47
264.95881,-3.84267,-66.34223,3.81714,66.34223,22476,47
265.24678,-3.54123,-57.35583,3.51571,57.35583,22412,47
265.57378,-3.21206,-48.08889,3.18654,48.08889,22412,47
265.88878,-2.89670,-39.53492,2.87118,39.53492,22412,47
266.24819,-2.53780,-30.62738,2.51228,30.62738,22412,47
266.69078,-2.09492,-21.32131,2.06940,21.32131,22412,47
267.14819,-1.63793,-13.76021,1.61241,13.76021,22412,47
267.64881,-1.27907,-8.77720,1.25355,8.77720,22412,47
268.10378,-1.75508,-17.99471,1.72956,17.99471,22604,47
268.53681,-2.18911,-26.85225,2.16359,26.85225,22604,48
268.90478,-2.55716,-35.72781,2.53164,35.72781,22604,48
269.26778,-2.92014,-44.61300,2.89462,44.61300,22604,48
269.64819,-3.30002,-53.89587,3.27450,53.89587,22604,48
269.94819,-3.60016,-61.30964,3.57463,61.30964,22604,48
270.27381,-3.92603,-69.29345,3.90051,69.29346,22604,48
270.57181,-3.67584,-61.30598,3.65032,61.30598,22540,48
270.90281,-3.33954,-51.58054,3.31402,51.58054,22540,48
271.24281,-2.99908,-42.09562,2.97356,42.09562,22540,48
271.61078,-2.63095,-32.96671,2.60543,32.96671,22540,48
272.01278,-2.22888,-23.90791,2.20336,23.90791,22540,48
272.51081,-1.73092,-15.27439,1.70540,15.27439,22540,48
273.00978,-1.23199,-7.33769,1.20647,7.33769,22540,48
273.42881,-1.61668,-15.37282,1.59116,15.37282,22604,48
273.85878,-2.04902,-23.86156,2.02350,23.86156,22604,49
274.24819,-2.43810,-32.89126,2.41258,32.89126,22604,49
274.63081,-2.82105,-42.22443,2.79553,42.22443,22604,49
274.99478,-3.18500,-51.16324,3.15948,51.16325,22604,49
275.34181,-3.53205,-59.65637,3.50653,59.65638,22604,49
275.70678,-3.89699,-68.62344,3.87147,68.62344,22604,49
275.97981,-3.74263,-63.27761,3.71711,63.27761,22604,49
276.30381,-3.41085,-53.55390,3.38533,53.55390,22540,49
276.63378,-3.08012,-44.20510,3.05460,44.20510,22540,49
276.99478,-2.71888,-35.04964,2.69336,35.04964,22540,49
277.38378,-2.32987,-25.95295,2.30435,25.95295,22540,49
277.84822,-1.86578,-17.29315,1.84026,17.29315,22540,49
278.39178,-1.32184,-8.80490,1.29632,8.80490,22540,49
279.04378,-1.41295,-11.84984,1.38743,11.84984,22540,49
279.49078,-1.86472,-20.16536,1.83920,20.16536,22476,49
279.90878,-2.28290,-29.27409,2.25738,29.27409,22476,50
280.27381,-2.64804,-38.17511,2.62252,38.17511,22476,50
280.64819,-3.02216,-47.38820,2.99664,47.38820,22476,50
280.99281,-3.36700,-55.66368,3.34148,55.66368,22476,50
281.36381,-3.73782,-64.78814,3.71230,64.78814,22476,50
281.66778,-3.87160,-67.31904,3.84608,67.31905,22476,50
281.97681,-3.54531,-57.44663,3.51979,57.44663,22412,50
282.30881,-3.21097,-48.08780,3.18545,48.08780,22412,50
282.64819,-2.87164,-38.88534,2.84612,38.88535,22412,50
283.02978,-2.48975,-29.51158,2.46422,29.51158,22412,50
283.44878,-2.07081,-20.91188,2.04529,20.91188,22412,50
283.98481,-1.53478,-12.27773,1.50926,12.27773,22412,50
284.43078,-1.32092,-9.73269,1.29540,9.73269,22412,50
284.86881,-1.77408,-18.34464,1.74856,18.34464,22476,50
285.30078,-2.20699,-27.27261,2.18147,27.27261,22476,51
285.66181,-2.56806,-36.02696,2.54254,36.02696,22476,51
286.04819,-2.95416,-45.50007,2.92864,45.50007,22476,51
286.42778,-3.33400,-54.74561,3.30848,54.74561,22476,51
286.78878,-3.69495,-63.65951,3.66943,63.65951,22476,51
287.07778,-3.93934,-69.50718,3.91382,69.50718,22476,51
287.36881,-3.62304,-59.76352,3.59752,59.76352,22412,51
287.69778,-3.29003,-50.19915,3.26451,50.19915,22412,51
288.03978,-2.94779,-40.65764,2.92227,40.65763,22412,51
288.40681,-2.58081,-31.63046,2.55529,31.63046,22412,51
288.83578,-2.15171,-22.35828,2.12619,22.35828,22412,51
289.34778,-1.63979,-13.78987,1.61427,13.78987,22412,51
289.82481,-1.22789,-7.51416,1.20237,7.51416,22412,51
290.24819,-1.67832,-16.51038,1.65280,16.51038,22476,51
290.68381,-2.11595,-25.30202,2.09043,25.30202,22476,52
291.03681,-2.46903,-33.69289,2.44351,33.69289,22476,52
291.40681,-2.83883,-42.72731,2.81331,42.72731,22476,52
291.74819,-3.17985,-51.09395,3.15433,51.09395,22476,52
292.12578,-3.55787,-60.29371,3.53235,60.29371,22476,52
292.49381,-3.92579,-69.30386,3.90027,69.30386,22476,52
292.74978,-3.72773,-62.80720,3.70221,62.80720,22476,52
293.07981,-3.39053,-52.98655,3.36501,52.98655,22412,52
293.41478,-3.05485,-43.54383,3.02933,43.54383,22412,52
293.77078,-2.69866,-34.57024,2.67314,34.57024,22412,52
294.15878,-2.31060,-25.55291,2.28507,25.55291,22412,52
294.64819,-1.82157,-16.61458,1.79605,16.61458,22412,52
295.17381,-1.29553,-8.40737,1.27001,8.40737,22412,52
295.56778,-1.53155,-13.73537,1.50603,13.73537,22476,52
296.02978,-1.99791,-22.74754,1.97239,22.74754,22476,53
296.38878,-2.35697,-30.79091,2.33145,30.79091,22476,53
296.75581,-2.72399,-39.82963,2.69846,39.82964,22476,53
297.13878,-3.10706,-49.17825,3.08154,49.17825,22476,53
297.50681,-3.47501,-58.19052,3.44948,58.19052,22476,53
297.87681,-3.84478,-67.24435,3.81926,67.24435,22476,53
298.19078,-3.75416,-63.62984,3.72864,63.62984,22476,53
298.50378,-3.43291,-54.19285,3.40739,54.19285,22412,53
298.83478,-3.10103,-44.73853,3.07551,44.73853,22412,53
299.19278,-2.74274,-35.56185,2.71722,35.56185,22412,53
299.57081,-2.36471,-26.55604,2.33919,26.55604,22412,53
300.04819,-1.88763,-17.69648,1.86211,17.69648,22412,53
300.58578,-1.34976,-9.24403,1.32424,9.24403,22412,53
300.98481,-1.48302,-12.84063,1.45750,12.84063,22412,53
301.44778,-1.95185,-21.80449,1.92633,21.80449,22476,54
301.84822,-2.35205,-30.64921,2.32653,30.64921,22476,54
302.21578,-2.72011,-39.71275,2.69459,39.71275,22476,54
302.58678,-3.09117,-48.86103,3.06565,48.86103,22476,54
302.95178,-3.45606,-57.72739,3.43053,57.72739,22476,54
303.33178,-3.83589,-67.02112,3.81037,67.02113,22476,54
303.61078,-3.79490,-64.84509,3.76938,64.84509,22476,54
303.92881,-3.46621,-55.10135,3.44069,55.10135,22412,54
304.24819,-3.14583,-46.06047,3.12031,46.06047,22412,54
304.60581,-2.78758,-36.72227,2.76206,36.72227,22412,54
304.98881,-2.40463,-27.37659,2.37911,27.37659,22412,54
305.44819,-1.94569,-18.66665,1.92017,18.66665,22412,54
305.97478,-1.41860,-10.39381,1.39308,10.39381,22412,54
306.42778,-1.48561,-12.88045,1.46009,12.88045,22412,54
306.86881,-1.93260,-21.37959,1.90707,21.37959,22476,55
307.26081,-2.32490,-30.02589,2.29938,30.02589,22476,55
307.64819,-2.71198,-39.53403,2.68646,39.53403,22476,55
308.02278,-3.08704,-48.75690,3.06151,48.75690,22476,55
308.39481,-3.45894,-57.75513,3.43342,57.75513,22476,55
308.74281,-3.80673,-66.31847,3.78121,66.31847,22476,55
309.04819,-3.80436,-65.13813,3.77884,65.13813,22476,55
309.35678,-3.48431,-55.62494,3.45879,55.62494,22412,55
309.65681,-3.18280,-47.15404,3.15728,47.15404,22412,55
310.01178,-2.82756,-37.64478,2.80204,37.64478,22412,55
310.38981,-2.44967,-28.44761,2.42415,28.44761,22412,55
310.84822,-1.99172,-19.36259,1.96620,19.36259,22412,55
311.35481,-1.48479,-11.43736,1.45927,11.43736,22412,55
311.82081,-1.42771,-11.83799,1.40219,11.83799,22412,55
312.26578,-1.88147,-20.27260,1.85595,20.27260,22476,56
312.67278,-2.28882,-29.15942,2.26330,29.15942,22476,56
313.04819,-2.66396,-38.35224,2.63844,38.35225,22476,56
313.42778,-3.04409,-47.73404,3.01857,47.73404,22476,56
313.80078,-3.41697,-56.75267,3.39145,56.75267,22476,56
314.16678,-3.78276,-65.70925,3.75724,65.70925,22476,56
314.49381,-3.80657,-65.18703,3.78105,65.18703,22476,56
314.80678,-3.48230,-55.51148,3.45678,55.51148,22412,56
315.14178,-3.14580,-45.96734,3.12028,45.96734,22412,56
315.48378,-2.80356,-37.03694,2.77804,37.03695,22412,56
315.84978,-2.43765,-28.13108,2.41213,28.13108,22412,56
316.32481,-1.96269,-18.91179,1.93717,18.91179,22412,56
316.84822,-1.43968,-10.68258,1.41416,10.68258,22412,56
317.24819,-1.40329,-11.33329,1.37777,11.33329,22412,56
317.71681,-1.88252,-20.29630,1.85700,20.29630,22476,57
318.12778,-2.29394,-29.25180,2.26842,29.25180,22476,57
318.48778,-2.65403,-38.13116,2.62851,38.13116,22476,57
318.85278,-3.01918,-47.15698,2.99365,47.15698,22476,57
319.24381,-3.41003,-56.60379,3.38451,56.60379,22476,57
319.54819,-3.71390,-63.99726,3.68837,63.99726,22476,57
319.83478,-3.92321,-68.95584,3.89769,68.95584,22476,57
320.12878,-3.60462,-59.11491,3.57910,59.11491,22412,57
320.44819,-3.28206,-49.87175,3.25654,49.87175,22412,57
320.78181,-2.94784,-40.61639,2.92232,40.61639,22412,57
321.15178,-2.57781,-31.42045,2.55229,31.42045,22412,57
321.57178,-2.15771,-22.41345,2.13219,22.41345,22412,57
322.07678,-1.65284,-13.90114,1.62732,13.90114,22412,57
322.54819,-1.24282,-7.70038,1.21730,7.70038,22412,57
322.97478,-1.69750,-16.81745,1.67198,16.81745,22604,57
323.41378,-2.13804,-25.67245,2.11252,25.67245,22604,58
323.79778,-2.52207,-34.83794,2.49655,34.83794,22604,58
324.15681,-2.88096,-43.66024,2.85544,43.66024,22604,58
324.54778,-3.27195,-53.18957,3.24643,53.18957,22604,58
324.90681,-3.63103,-62.00413,3.60551,62.00413,22604,58
325.24819,-3.95244,-69.92045,3.92692,69.92045,22604,58
325.53378,-3.64673,-60.31585,3.62120,60.31585,22540,58
325.83478,-3.34149,-51.54781,3.31597,51.54781,22540,58
326.15378,-3.02201,-42.65443,2.99649,42.65443,22540,58
326.49281,-2.68287,-34.10434,2.65735,34.10434,22540,58
326.88878,-2.28675,-24.94730,2.26123,24.94730,22540,58
327.36278,-1.81271,-16.40642,1.78719,16.40642,22540,58
327.90781,-1.26777,-7.82681,1.24225,7.82681,22540,58
328.30478,-1.56360,-14.29980,1.53808,14.29980,22604,58
328.74819,-2.01011,-22.94590,1.98459,22.94590,22604,59
329.11278,-2.37522,-31.20424,2.34970,31.20424,22604,59
329.48481,-2.74718,-40.30484,2.72166,40.30484,22604,59
329.83178,-3.09430,-48.88444,3.06878,48.88445,22604,59
330.19278,-3.45520,-57.66586,3.42968,57.66586,22604,59
330.50478,-3.76703,-65.40934,3.74151,65.40934,22604,59
330.80178,-3.85963,-66.78946,3.83411,66.78947,22604,59
331.10778,-3.53838,-57.14775,3.51286,57.14775,22540,59
331.44819,-3.19621,-47.57228,3.17069,47.57228,22540,59
331.77278,-2.87089,-38.74397,2.84537,38.74397,22540,59
332.12681,-2.51702,-29.99091,2.49150,29.99091,22540,59
332.54819,-2.09614,-21.18275,2.07062,21.18275,22540,59
333.05781,-1.58622,-12.85861,1.56070,12.85861,22540,59
333.44819,-1.20867,-6.92697,1.18315,6.92697,22540,59