File: data-raw/Experiment 2/Results/INSTRON data/Experiment 2.is_ccyclic_RawData/Specimen_RawData_17.csv
Text Inputs : Specimen label,"Long Plate 5 T1"

Time,Extension,Load,Compressive extension,Compressive load,Segment ID,Total Cycle Count
(sec),(mm),(N),(mm),(N),,
0.00000,-0.02538,0.00778,0.00000,-0.00778,12835,0
1.82920,-0.40596,-1.20711,0.38058,1.20711,3220,0
2.62920,-0.82413,-7.49338,0.79875,7.49338,3220,0
3.22780,-1.42993,-16.07777,1.40455,16.07777,22476,0
3.76680,-1.96909,-23.98075,1.94371,23.98075,22476,0
4.26080,-2.46298,-32.37885,2.43759,32.37885,22476,0
4.72920,-2.93117,-40.98139,2.90579,40.98138,22476,0
5.20780,-3.41017,-50.03368,3.38479,50.03368,22476,0
5.66980,-3.87209,-58.51114,3.84671,58.51114,22476,0
6.16180,-4.36423,-67.09525,4.33885,67.09525,22476,0
6.54280,-4.32581,-64.52645,4.30043,64.52645,22476,0
6.92780,-3.93275,-55.10005,3.90737,55.10005,22412,0
7.32280,-3.53692,-46.01078,3.51154,46.01078,22412,0
7.73080,-3.12875,-37.44359,3.10337,37.44358,22412,0
8.18680,-2.67285,-28.41140,2.64747,28.41140,22412,0
8.70980,-2.14983,-19.81623,2.12445,19.81623,22412,0
9.32920,-1.53088,-11.99270,1.50550,11.99270,22412,0
9.84280,-1.25096,-9.47027,1.22558,9.47027,22412,0
10.38080,-1.80427,-17.90188,1.77889,17.90187,22476,1
10.89980,-2.32398,-26.55137,2.29860,26.55136,22476,1
11.32920,-2.75289,-35.01310,2.72751,35.01310,22476,1
11.78880,-3.21281,-43.96120,3.18743,43.96120,22476,1
12.22920,-3.65281,-52.52227,3.62743,52.52227,22476,1
12.68980,-4.11367,-61.37848,4.08829,61.37848,22476,1
13.12920,-4.55293,-69.64321,4.52755,69.64321,22476,1
13.49680,-4.22203,-61.06044,4.19665,61.06044,22412,1
13.88080,-3.83495,-52.03618,3.80957,52.03618,22412,1
14.28780,-3.42785,-42.96710,3.40247,42.96710,22412,1
14.72920,-2.98671,-34.00709,2.96133,34.00710,22412,1
15.18280,-2.53267,-25.40742,2.50729,25.40742,22412,1
15.72920,-1.98670,-17.18372,1.96132,17.18372,22412,1
16.36480,-1.35072,-9.33398,1.32534,9.33398,22412,1
16.85980,-1.48524,-12.55074,1.45986,12.55074,22476,1
17.41180,-2.04173,-21.06047,2.01635,21.06047,22476,2
17.87380,-2.50370,-29.34780,2.47832,29.34780,22476,2
18.32380,-2.95386,-38.33108,2.92848,38.33108,22476,2
18.76180,-3.39192,-46.91859,3.36654,46.91859,22476,2
19.22480,-3.85487,-55.88954,3.82949,55.88954,22476,2
19.66680,-4.29698,-64.38457,4.27160,64.38457,22476,2
20.07980,-4.48592,-67.10932,4.46054,67.10932,22476,2
20.43880,-4.11192,-57.98965,4.08654,57.98965,22412,2
20.82920,-3.72067,-48.90971,3.69529,48.90971,22412,2
21.25380,-3.29573,-39.83150,3.27035,39.83150,22412,2
21.69880,-2.85058,-30.85137,2.82520,30.85137,22412,2
22.19080,-2.35863,-22.26170,2.33325,22.26170,22412,2
22.76380,-1.78554,-14.32452,1.76016,14.32452,22412,2
23.40080,-1.22437,-7.75581,1.19899,7.75581,22412,2
23.92380,-1.77463,-16.53047,1.74925,16.53047,22476,2
24.42920,-2.28065,-24.79440,2.25527,24.79440,22476,3
24.87480,-2.72658,-33.38569,2.70120,33.38568,22476,3
25.32920,-3.18053,-42.34731,3.15515,42.34731,22476,3
25.76380,-3.61546,-50.88420,3.59008,50.88420,22476,3
26.22920,-4.08062,-59.88825,4.05524,59.88825,22476,3
26.66980,-4.52167,-68.36294,4.49629,68.36294,22476,3
27.02920,-4.32207,-62.79062,4.29669,62.79063,22476,3
27.41680,-3.92898,-53.42761,3.90360,53.42762,22412,3
27.81880,-3.52643,-44.40643,3.50105,44.40643,22412,3
28.22920,-3.11623,-35.89053,3.09084,35.89053,22412,3
28.69980,-2.64532,-26.74475,2.61994,26.74475,22412,3
29.22920,-2.11620,-18.53953,2.09082,18.53953,22412,3
29.84680,-1.49830,-10.68152,1.47292,10.68152,22412,3
30.35480,-1.42398,-10.97047,1.39860,10.97047,22412,3
30.91280,-1.99023,-19.52121,1.96485,19.52121,22476,4
31.39680,-2.47436,-27.92814,2.44898,27.92814,22476,4
31.82920,-2.90649,-36.59219,2.88110,36.59219,22476,4
32.26780,-3.34555,-45.24700,3.32017,45.24700,22476,4
32.72920,-3.80649,-54.33850,3.78111,54.33850,22476,4
33.16780,-4.24529,-62.88512,4.21991,62.88512,22476,4
33.60880,-4.56822,-68.62622,4.54284,68.62623,22476,4
33.95680,-4.19825,-59.55722,4.17287,59.55722,22412,4
34.34080,-3.81234,-50.58331,3.78696,50.58331,22412,4
34.76080,-3.39237,-41.40256,3.36699,41.40257,22412,4
35.19780,-2.95524,-32.51231,2.92985,32.51231,22412,4
35.67780,-2.47515,-23.75483,2.44977,23.75483,22412,4
36.22980,-1.92324,-15.76705,1.89786,15.76705,22412,4
36.86080,-1.29229,-7.88069,1.26691,7.88069,22412,4
37.34280,-1.63990,-13.96969,1.61452,13.96969,22476,4
37.88280,-2.18221,-22.55340,2.15683,22.55340,22476,5
38.32920,-2.62813,-30.74876,2.60275,30.74876,22476,5
38.78980,-3.08915,-39.94909,3.06377,39.94909,22476,5
39.22920,-3.52814,-48.71094,3.50276,48.71094,22476,5
39.67180,-3.97138,-57.37961,3.94600,57.37961,22476,5
40.12920,-4.42839,-66.24334,4.40301,66.24334,22476,5
40.51380,-4.43304,-65.09950,4.40766,65.09950,22476,5
40.88080,-4.05700,-56.07915,4.03162,56.07915,22412,5
41.27680,-3.65997,-47.06119,3.63459,47.06119,22412,5
41.70880,-3.22780,-37.91435,3.20241,37.91435,22412,5
42.12920,-2.80796,-29.48784,2.78258,29.48783,22412,5
42.62920,-2.30800,-21.00223,2.28262,21.00224,22412,5
43.25280,-1.68405,-12.68353,1.65867,12.68353,22412,5
43.80680,-1.38946,-9.88600,1.36407,9.88600,22412,5
44.32920,-1.92574,-18.15970,1.90036,18.15970,22476,6
44.83180,-2.42914,-26.58709,2.40376,26.58709,22476,6
45.28180,-2.87915,-35.52094,2.85377,35.52094,22476,6
45.72680,-3.32422,-44.39904,3.29884,44.39904,22476,6
46.16380,-3.76116,-53.01078,3.73578,53.01078,22476,6
46.61880,-4.21599,-61.98050,4.19061,61.98050,22476,6
47.05380,-4.63242,-69.99861,4.60703,69.99860,22476,6
47.41380,-4.25172,-60.47542,4.22634,60.47542,22412,6
47.79780,-3.86508,-51.47392,3.83970,51.47392,22412,6
48.20580,-3.45687,-42.50298,3.43149,42.50298,22412,6
48.62920,-3.03388,-33.83852,3.00850,33.83852,22412,6
49.10080,-2.56176,-24.94311,2.53638,24.94311,22412,6
49.65280,-2.00990,-16.70078,1.98452,16.70078,22412,6
50.28180,-1.38093,-8.74770,1.35555,8.74770,22412,6
50.80880,-1.66556,-14.00871,1.64018,14.00871,22476,6
51.32920,-2.18798,-22.26932,2.16260,22.26932,22476,7
51.79780,-2.65696,-30.90025,2.63158,30.90025,22476,7
52.22920,-3.08795,-39.55724,3.06257,39.55724,22476,7
52.67380,-3.53296,-48.47590,3.50758,48.47589,22476,7
53.12920,-3.98815,-57.39710,3.96277,57.39710,22476,7
53.56680,-4.42620,-65.95540,4.40082,65.95540,22476,7
53.94780,-4.46409,-65.58658,4.43871,65.58658,22476,7
54.32920,-4.07275,-56.17034,4.04737,56.17034,22412,7
54.72920,-3.67182,-47.07782,3.64644,47.07782,22412,7
55.13080,-3.26986,-38.55348,3.24448,38.55347,22412,7
55.58580,-2.81480,-29.36725,2.78942,29.36725,22412,7
56.08480,-2.31584,-20.93085,2.29046,20.93085,22412,7
56.68480,-1.71575,-12.86930,1.69037,12.86930,22412,7
57.22580,-1.34756,-8.90609,1.32218,8.90609,22412,7
57.72920,-1.86923,-16.99584,1.84385,16.99584,22604,7
58.24180,-2.38297,-25.53083,2.35759,25.53083,22604,8
58.69180,-2.83303,-34.37244,2.80765,34.37244,22604,8
59.12920,-3.27008,-43.09730,3.24470,43.09730,22604,8
59.56880,-3.71008,-51.89891,3.68470,51.89891,22604,8
60.02920,-4.16981,-60.84017,4.14442,60.84017,22604,8
60.46680,-4.60790,-69.38966,4.58252,69.38966,22604,8
60.82920,-4.30994,-61.71044,4.28456,61.71044,22540,8
61.21980,-3.91528,-52.39714,3.88990,52.39714,22540,8
61.62280,-3.51187,-43.47416,3.48649,43.47416,22540,8
62.03180,-3.10268,-34.99074,3.07730,34.99073,22540,8
62.50480,-2.62971,-25.94538,2.60433,25.94538,22540,8
63.03180,-2.10265,-17.82757,2.07727,17.82757,22540,8
63.66180,-1.47273,-9.78917,1.44735,9.78917,22540,8
64.15680,-1.54443,-12.08172,1.51904,12.08172,22540,8
64.69880,-2.09178,-20.38354,2.06640,20.38354,22604,9
65.17780,-2.57093,-28.93898,2.54555,28.93898,22604,9
65.62080,-3.01400,-37.90389,2.98862,37.90389,22604,9
66.04680,-3.44011,-46.42099,3.41473,46.42099,22604,9
66.50380,-3.89710,-55.44738,3.87172,55.44738,22604,9
66.94180,-4.33520,-64.04181,4.30981,64.04181,22604,9
67.35280,-4.55598,-67.63121,4.53060,67.63122,22604,9
67.72920,-4.16312,-58.09069,4.13774,58.09069,22540,9
68.12080,-3.76984,-48.95512,3.74445,48.95512,22540,9
68.52920,-3.36182,-40.17033,3.33644,40.17033,22540,9
68.95480,-2.93578,-31.49164,2.91040,31.49164,22540,9
69.44080,-2.44971,-22.85796,2.42433,22.85796,22540,9
70.02920,-1.86158,-14.57942,1.83620,14.57942,22540,9
70.57680,-1.31381,-7.63559,1.28843,7.63559,22540,9
71.19580,-1.49456,-11.40352,1.46918,11.40352,22540,9
71.72920,-2.03238,-19.46651,2.00700,19.46651,22476,9
72.22920,-2.53242,-28.17088,2.50704,28.17088,22476,10
72.66080,-2.96449,-36.86529,2.93911,36.86529,22476,10
73.10980,-3.41358,-45.81827,3.38820,45.81826,22476,10
73.54280,-3.84652,-54.39480,3.82114,54.39480,22476,10
74.00480,-4.30862,-63.45062,4.28324,63.45062,22476,10
74.42080,-4.58197,-68.29261,4.55659,68.29261,22476,10
74.77480,-4.20801,-59.08927,4.18263,59.08927,22412,10
75.16380,-3.81734,-49.99609,3.79196,49.99609,22412,10
75.57880,-3.40238,-40.98867,3.37700,40.98867,22412,10
76.02380,-2.95722,-31.85505,2.93184,31.85505,22412,10
76.49680,-2.48415,-23.34883,2.45877,23.34883,22412,10
77.05980,-1.92127,-15.34760,1.89588,15.34760,22412,10
77.68080,-1.30031,-7.39224,1.27493,7.39224,22412,10
78.13880,-1.71456,-14.43519,1.68918,14.43519,22476,10
78.67180,-2.24951,-22.94570,2.22413,22.94570,22476,11
79.13180,-2.70956,-31.48443,2.68418,31.48442,22476,11
79.57680,-3.15440,-40.42663,3.12901,40.42663,22476,11
80.02180,-3.59942,-49.32221,3.57404,49.32221,22476,11
80.45280,-4.03064,-57.90056,4.00526,57.90056,22476,11
80.90980,-4.48755,-66.85203,4.46217,66.85204,22476,11
81.29080,-4.43687,-64.55783,4.41149,64.55783,22476,11
81.66280,-4.05718,-55.47751,4.03180,55.47752,22412,11
82.05380,-3.66535,-46.58819,3.63997,46.58819,22412,11
82.47880,-3.24025,-37.58989,3.21487,37.58989,22412,11
82.92920,-2.79033,-28.55166,2.76495,28.55166,22412,11
83.42920,-2.29040,-20.26751,2.26502,20.26751,22412,11
84.03280,-1.68645,-12.45100,1.66107,12.45100,22412,11
84.58180,-1.39691,-9.42949,1.37153,9.42949,22412,11
85.10980,-1.93927,-17.77900,1.91388,17.77900,22476,12
85.62920,-2.45855,-26.51554,2.43317,26.51554,22476,12
86.05680,-2.88663,-35.00804,2.86125,35.00803,22476,12
86.49680,-3.32674,-43.81606,3.30135,43.81606,22476,12
86.92920,-3.75867,-52.45722,3.73329,52.45722,22476,12
87.38280,-4.21247,-61.45708,4.18709,61.45708,22476,12
87.82920,-4.65311,-69.99930,4.62773,69.99930,22476,12
88.17780,-4.29690,-61.05940,4.27152,61.05940,22412,12
88.56280,-3.90879,-51.96993,3.88341,51.96992,22412,12
88.97080,-3.50043,-42.94613,3.47505,42.94613,22412,12
89.40880,-3.06235,-33.91983,3.03697,33.91983,22412,12
89.85880,-2.61223,-25.38483,2.58685,25.38483,22412,12
90.42920,-2.04237,-16.79665,2.01699,16.79665,22412,12
91.02920,-1.44243,-9.18214,1.41705,9.18214,22412,12
91.52480,-1.62686,-12.94995,1.60147,12.94995,22476,12
92.03980,-2.14553,-21.01164,2.12015,21.01164,22476,13
92.52920,-2.63462,-29.83735,2.60924,29.83735,22476,13
92.95680,-3.06272,-38.52234,3.03734,38.52234,22476,13
93.40080,-3.50667,-47.44453,3.48129,47.44453,22476,13
93.83280,-3.93885,-55.99450,3.91347,55.99450,22476,13
94.28980,-4.39593,-64.98013,4.37055,64.98013,22476,13
94.69580,-4.52757,-66.59269,4.50219,66.59269,22476,13
95.06080,-4.14963,-57.45791,4.12425,57.45791,22412,13
95.45180,-3.75759,-48.41022,3.73221,48.41022,22412,13
95.86480,-3.34461,-39.60768,3.31923,39.60768,22412,13
96.31480,-2.89456,-30.42226,2.86918,30.42226,22412,13
96.80980,-2.39960,-21.86462,2.37422,21.86462,22412,13
97.32920,-1.88046,-14.62791,1.85508,14.62791,22412,13
97.92680,-1.29123,-7.09291,1.26585,7.09291,22412,13
98.40680,-1.78530,-15.29846,1.75992,15.29846,22476,13
98.92920,-2.30893,-23.74214,2.28355,23.74214,22476,14
99.38380,-2.76386,-32.36944,2.73848,32.36944,22476,14
99.82920,-3.20883,-41.30819,3.18345,41.30819,22476,14
100.25380,-3.63374,-49.85443,3.60836,49.85443,22476,14
100.71480,-4.09478,-58.99940,4.06940,58.99940,22476,14
101.14780,-4.52788,-67.48107,4.50250,67.48107,22476,14
101.52880,-4.40149,-63.48822,4.37611,63.48822,22412,14
101.90080,-4.02342,-54.47706,3.99804,54.47706,22412,14
102.29580,-3.62761,-45.49208,3.60223,45.49208,22412,14
102.72780,-3.19553,-36.45642,3.17015,36.45642,22412,14
103.15480,-2.76869,-27.91652,2.74331,27.91652,22412,14
103.68380,-2.23959,-19.33392,2.21421,19.33392,22412,14
104.31080,-1.61261,-11.34781,1.58723,11.34781,22412,14
104.74080,-1.40441,-9.27273,1.37903,9.27273,22412,14
105.28180,-1.96156,-17.92825,1.93618,17.92825,22476,15
105.79780,-2.47788,-26.60687,2.45250,26.60687,22476,15
106.22920,-2.90888,-35.20514,2.88350,35.20514,22476,15
106.66680,-3.34711,-43.98738,3.32173,43.98738,22476,15
107.11680,-3.79701,-53.04161,3.77163,53.04161,22476,15
107.53280,-4.21283,-61.31414,4.18745,61.31414,22476,15
107.98380,-4.65239,-69.85394,4.62701,69.85394,22476,15
108.32920,-4.29207,-60.81957,4.26669,60.81957,22412,15
108.72380,-3.89396,-51.58295,3.86858,51.58295,22412,15
109.12920,-3.48864,-42.54754,3.46326,42.54754,22412,15
109.54480,-3.07256,-33.97665,3.04718,33.97665,22412,15
110.02920,-2.58846,-24.82130,2.56308,24.82130,22412,15
110.56980,-2.04757,-16.69906,2.02219,16.69906,22412,15
111.18280,-1.43468,-8.90430,1.40930,8.90430,22412,15
111.65780,-1.64409,-13.01876,1.61871,13.01876,22476,15
112.19380,-2.18381,-21.42854,2.15843,21.42854,22476,16
112.66780,-2.65780,-30.04108,2.63242,30.04108,22476,16
113.10580,-3.09587,-39.00066,3.07048,39.00066,22476,16
113.52920,-3.51881,-47.58012,3.49343,47.58012,22476,16
113.97580,-3.96601,-56.36026,3.94063,56.36026,22476,16
114.42920,-4.41898,-65.31281,4.39360,65.31281,22476,16
114.82920,-4.51359,-66.15152,4.48821,66.15152,22476,16
115.19580,-4.13471,-57.00912,4.10933,57.00912,22412,16
115.58080,-3.74880,-48.07717,3.72342,48.07717,22412,16
116.01280,-3.31687,-38.91273,3.29149,38.91273,22412,16
116.42920,-2.90082,-30.38355,2.87544,30.38355,22412,16
116.92920,-2.40084,-21.70724,2.37546,21.70724,22412,16
117.44680,-1.88274,-14.59304,1.85736,14.59304,22412,16
118.02680,-1.31642,-7.27746,1.29104,7.27746,22412,16
118.52920,-1.83777,-15.90350,1.81239,15.90350,22476,16
119.02920,-2.33905,-24.05015,2.31367,24.05015,22476,17
119.48980,-2.80001,-32.90470,2.77462,32.90470,22476,17
119.92920,-3.23897,-41.75941,3.21358,41.75941,22476,17
120.35880,-3.66906,-50.40239,3.64368,50.40239,22476,17
120.81580,-4.12576,-59.49204,4.10038,59.49204,22476,17
121.24780,-4.55807,-67.93728,4.53269,67.93729,22476,17
121.62680,-4.38469,-62.94781,4.35931,62.94781,22476,17
121.99480,-4.01141,-54.09143,3.98603,54.09143,22412,17
122.39180,-3.61363,-45.00822,3.58825,45.00822,22412,17
122.82280,-3.18265,-35.97191,3.15727,35.97191,22412,17
123.25980,-2.74572,-27.32000,2.72034,27.32000,22412,17
123.80680,-2.19867,-18.70827,2.17328,18.70827,22412,17
124.42380,-1.58170,-10.79407,1.55632,10.79407,22412,17
124.90780,-1.51492,-10.99641,1.48954,10.99640,22412,17
125.42920,-2.04477,-19.03637,2.01939,19.03638,22604,17
125.92920,-2.54494,-27.70569,2.51956,27.70569,22604,18
126.35980,-2.97601,-36.36732,2.95063,36.36732,22604,18
126.80980,-3.42615,-45.45729,3.40077,45.45729,22604,18
127.23480,-3.85106,-53.95809,3.82568,53.95809,22604,18
127.68580,-4.30209,-62.92342,4.27671,62.92342,22604,18
128.11980,-4.60902,-68.56334,4.58364,68.56334,22604,18
128.46379,-4.24395,-59.55482,4.21857,59.55482,22540,18
128.84680,-3.85893,-50.57280,3.83355,50.57280,22540,18
129.25479,-3.45081,-41.53432,3.42542,41.53432,22540,18
129.69480,-3.01076,-32.48053,2.98538,32.48053,22540,18
130.16280,-2.54268,-23.89092,2.51730,23.89092,22540,18
130.72920,-1.97673,-15.63359,1.95135,15.63359,22540,18
131.33680,-1.36880,-7.91338,1.34342,7.91338,22540,18
131.82480,-1.75084,-14.51790,1.72546,14.51790,22604,18
132.32919,-2.25697,-22.52771,2.23159,22.52771,22604,19
132.80380,-2.73198,-31.35110,2.70660,31.35110,22604,19
133.22980,-3.15791,-39.97343,3.13253,39.97343,22604,19
133.67380,-3.60187,-49.01859,3.57649,49.01859,22604,19
134.12280,-4.05107,-57.91920,4.02569,57.91920,22604,19
134.56080,-4.48905,-66.54657,4.46367,66.54657,22604,19
134.93580,-4.46948,-64.97762,4.44410,64.97762,22604,19
135.32580,-4.07060,-55.44112,4.04522,55.44112,22540,19
135.71580,-3.67982,-46.41816,3.65444,46.41816,22540,19
136.12920,-3.26688,-37.68181,3.24150,37.68181,22540,19
136.56180,-2.83380,-28.94056,2.80842,28.94056,22540,19
137.06680,-2.32886,-20.46698,2.30348,20.46698,22540,19
137.68480,-1.71085,-12.33538,1.68547,12.33538,22540,19
138.47380,-1.32165,-7.67780,1.29627,7.67780,22540,19
138.99380,-1.84390,-16.05526,1.81852,16.05526,22476,19
139.51680,-2.36750,-24.58697,2.34211,24.58697,22476,20
139.95480,-2.80554,-33.02748,2.78016,33.02748,22476,20
140.38780,-3.23844,-41.73935,3.21306,41.73935,22476,20
140.82919,-3.67957,-50.59173,3.65419,50.59173,22476,20
141.27980,-4.13027,-59.54722,4.10489,59.54722,22476,20
141.72920,-4.57943,-68.37767,4.55405,68.37767,22476,20
142.07180,-4.39057,-63.11018,4.36518,63.11018,22476,20
142.44780,-4.00890,-54.00014,3.98352,54.00014,22412,20
142.84380,-3.61215,-44.94654,3.58677,44.94654,22412,20
143.26480,-3.19113,-36.08485,3.16575,36.08485,22412,20
143.72920,-2.72718,-26.91639,2.70179,26.91639,22412,20
144.23880,-2.21716,-18.92283,2.19178,18.92283,22412,20
144.86080,-1.59519,-10.90198,1.56981,10.90198,22412,20
145.33080,-1.50942,-10.73413,1.48404,10.73413,22412,20
145.89180,-2.08024,-19.51229,2.05486,19.51229,22476,21
146.36980,-2.55844,-27.87910,2.53306,27.87910,22476,21
146.81880,-3.00753,-36.94834,2.98215,36.94834,22476,21
147.23380,-3.42268,-45.31274,3.39730,45.31274,22476,21
147.68780,-3.87659,-54.41233,3.85121,54.41233,22476,21
148.12920,-4.31767,-63.21454,4.29229,63.21454,22476,21
148.53180,-4.62035,-68.82906,4.59497,68.82906,22476,21
148.90480,-4.22313,-58.98882,4.19775,58.98882,22412,21
149.28780,-3.83841,-50.05913,3.81303,50.05913,22412,21
149.69080,-3.43540,-41.09493,3.41002,41.09493,22412,21
150.12920,-2.99729,-32.08761,2.97191,32.08760,22412,21
150.61480,-2.51131,-23.29411,2.48593,23.29411,22412,21
151.18280,-1.94332,-15.17873,1.91794,15.17873,22412,21
151.76680,-1.35934,-7.67053,1.33396,7.67053,22412,21
152.22920,-1.77343,-14.66793,1.74805,14.66793,22476,21
152.74480,-2.29160,-22.98984,2.26622,22.98984,22476,22
153.21580,-2.76256,-31.87202,2.73718,31.87201,22476,22
153.64180,-3.18851,-40.44566,3.16313,40.44566,22476,22
154.07980,-3.62644,-49.35741,3.60106,49.35741,22476,22
154.52919,-4.07558,-58.32025,4.05020,58.32025,22476,22
154.96180,-4.50851,-66.90513,4.48313,66.90513,22476,22
155.33680,-4.45191,-64.50781,4.42653,64.50781,22476,22
155.72680,-4.05413,-55.00325,4.02875,55.00325,22412,22
156.11680,-3.66335,-45.92712,3.63797,45.92712,22412,22
156.52919,-3.25131,-37.23518,3.22593,37.23518,22412,22
156.96880,-2.81135,-28.40780,2.78597,28.40780,22412,22
157.48980,-2.29037,-19.78881,2.26499,19.78881,22412,22
158.10280,-1.67745,-11.87856,1.65207,11.87856,22412,22
158.54980,-1.39654,-8.79635,1.37116,8.79635,22412,22
159.08980,-1.95612,-17.47927,1.93074,17.47927,22476,22
159.59480,-2.46159,-26.03734,2.43621,26.03734,22476,23
160.02919,-2.89561,-34.65356,2.87023,34.65356,22476,23
160.46980,-3.33674,-43.51085,3.31136,43.51085,22476,23
160.91380,-3.78067,-52.40466,3.75529,52.40466,22476,23
161.33980,-4.20640,-60.92042,4.18102,60.92043,22476,23
161.77880,-4.64546,-69.58699,4.62008,69.58699,22476,23
162.13980,-4.33024,-61.47846,4.30486,61.47846,22412,23
162.52919,-3.93780,-52.26713,3.91242,52.26714,22412,23
162.92920,-3.53738,-43.20553,3.51200,43.20552,22412,23
163.35280,-3.11318,-34.38221,3.08780,34.38221,22412,23
163.82080,-2.64529,-25.43396,2.61991,25.43396,22412,23
164.35880,-2.10718,-17.28390,2.08180,17.28390,22412,23
164.97980,-1.48629,-9.32384,1.46091,9.32384,22412,23
165.47480,-1.63525,-12.60342,1.60987,12.60342,22476,23
166.01480,-2.17952,-21.04879,2.15414,21.04879,22476,24
166.48080,-2.64549,-29.51551,2.62011,29.51551,22476,24
166.92480,-3.08958,-38.53914,3.06420,38.53914,22476,24
167.33880,-3.50353,-46.93349,3.47815,46.93349,22476,24
167.79480,-3.95976,-56.04059,3.93438,56.04059,22476,24
168.22920,-4.39378,-64.68679,4.36840,64.68679,22476,24
168.62920,-4.55719,-67.03071,4.53181,67.03072,22476,24
169.00480,-4.16659,-57.55366,4.14120,57.55367,22412,24
169.39980,-3.77050,-48.40495,3.74512,48.40495,22412,24
169.81380,-3.35647,-39.34318,3.33109,39.34318,22412,24
170.22920,-2.94144,-30.81759,2.91606,30.81759,22412,24
170.72920,-2.44141,-22.04504,2.41603,22.04504,22412,24
171.32180,-1.84828,-13.95028,1.82290,13.95028,22412,24
171.87078,-1.33884,-7.40813,1.31346,7.40813,22412,24
172.31880,-1.81416,-15.26034,1.78877,15.26034,22476,24
172.80380,-2.30076,-23.06298,2.27538,23.06298,22476,25
173.25480,-2.75173,-31.52949,2.72635,31.52949,22476,25
173.69380,-3.19070,-40.39886,3.16532,40.39886,22476,25
174.12920,-3.62560,-49.25063,3.60022,49.25063,22476,25
174.55880,-4.05576,-57.89054,4.03038,57.89054,22476,25
175.01880,-4.51566,-66.98714,4.49027,66.98714,22476,25
175.39480,-4.45804,-64.56125,4.43266,64.56125,22476,25
175.76580,-4.07924,-55.50962,4.05386,55.50962,22412,25
176.15080,-3.69352,-46.55901,3.66814,46.55901,22412,25
176.57680,-3.26757,-37.42753,3.24219,37.42753,22412,25
177.02080,-2.82352,-28.50747,2.79814,28.50747,22412,25
177.52919,-2.31557,-20.06003,2.29019,20.06002,22412,25
178.12920,-1.71547,-12.31018,1.69009,12.31018,22412,25
178.59080,-1.40886,-8.86258,1.38348,8.86258,22412,25
179.12880,-1.96727,-17.53836,1.94189,17.53836,22476,26
179.62920,-2.46775,-25.98947,2.44237,25.98947,22476,26
180.05380,-2.89273,-34.46727,2.86735,34.46727,22476,26
180.49880,-3.33791,-43.44446,3.31252,43.44446,22476,26
180.92920,-3.76783,-52.10992,3.74245,52.10992,22476,26
181.37380,-4.21258,-60.97675,4.18719,60.97675,22476,26
181.80680,-4.64567,-69.55745,4.62029,69.55745,22476,26
182.15680,-4.34180,-61.70372,4.31642,61.70372,22412,26
182.54180,-3.95302,-52.55285,3.92764,52.55285,22412,26
182.93680,-3.55754,-43.47973,3.53216,43.47973,22412,26
183.37380,-3.12042,-34.43293,3.09504,34.43293,22412,26
183.82919,-2.66553,-25.69517,2.64015,25.69517,22412,26
184.36380,-2.13046,-17.51948,2.10508,17.51948,22412,26
184.88780,-1.60652,-10.85255,1.58114,10.85255,22412,26
185.32919,-1.46468,-9.93309,1.43930,9.93309,22412,26
185.88480,-2.03349,-18.61708,2.00811,18.61708,22476,27
186.37180,-2.52076,-26.89917,2.49538,26.89917,22476,27
186.82080,-2.96982,-35.92392,2.94443,35.92392,22476,27
187.24180,-3.39092,-44.47449,3.36554,44.47449,22476,27
187.68580,-3.83487,-53.38480,3.80949,53.38480,22476,27
188.12920,-4.27784,-62.27338,4.25246,62.27338,22476,27
188.55780,-4.66013,-69.68806,4.63475,69.68806,22476,27
188.91880,-4.27227,-60.01200,4.24688,60.01200,22412,27
189.30780,-3.88087,-50.90583,3.85549,50.90583,22412,27
189.69880,-3.48961,-42.00125,3.46423,42.00126,22412,27
190.12920,-3.05956,-33.16262,3.03418,33.16262,22412,27
190.59880,-2.58945,-24.37952,2.56407,24.37952,22412,27
191.14580,-2.04264,-16.34848,2.01726,16.34848,22412,27
191.77378,-1.41470,-8.26663,1.38932,8.26663,22412,27
192.22920,-1.70084,-13.46836,1.67546,13.46836,22604,27
192.76780,-2.24285,-22.00826,2.21747,22.00826,22604,28
193.22920,-2.70392,-30.54107,2.67854,30.54107,22604,28
193.67380,-3.14881,-39.57216,3.12343,39.57216,22604,28
194.11180,-3.58681,-48.49820,3.56143,48.49820,22604,28
194.53180,-4.00699,-56.88969,3.98161,56.88969,22604,28
194.99480,-4.46985,-66.03373,4.44447,66.03373,22604,28
195.36880,-4.50124,-65.58513,4.47586,65.58513,22604,28
195.73980,-4.11951,-56.43886,4.09413,56.43886,22540,28
196.12920,-3.72976,-47.41587,3.70438,47.41587,22540,28
196.54380,-3.31488,-38.34617,3.28950,38.34617,22540,28
196.97680,-2.88177,-29.55060,2.85639,29.55060,22540,28
197.48480,-2.37380,-20.87910,2.34841,20.87910,22540,28
198.08580,-1.77270,-12.84283,1.74732,12.84283,22540,28
198.61080,-1.41392,-8.84027,1.38854,8.84027,22540,28
199.08280,-1.90516,-16.49843,1.87978,16.49843,22604,29
199.58980,-2.41302,-24.95580,2.38764,24.95580,22604,29
200.02919,-2.85198,-33.56729,2.82660,33.56729,22604,29
200.45380,-3.27712,-42.13102,3.25174,42.13102,22604,29
200.91580,-3.73904,-51.44241,3.71365,51.44241,22604,29
201.34180,-4.16474,-59.99890,4.13936,59.99890,22604,29
201.79780,-4.62082,-69.01520,4.59544,69.01521,22604,29
202.13680,-4.38120,-62.58685,4.35582,62.58685,22604,29
202.52919,-3.98428,-53.19349,3.95890,53.19349,22540,29
202.92880,-3.58366,-43.92239,3.55828,43.92239,22540,29
203.33680,-3.17569,-35.37958,3.15031,35.37959,22540,29
203.80378,-2.70865,-26.28051,2.68327,26.28051,22540,29
204.32919,-2.18370,-18.24042,2.15832,18.24042,22540,29
204.90480,-1.60771,-10.79278,1.58233,10.79278,22540,29
205.59680,-1.37050,-8.26198,1.34512,8.26198,22540,29
206.12920,-1.91725,-16.81495,1.89187,16.81495,22476,29
206.62920,-2.41759,-25.15466,2.39221,25.15466,22476,30
207.07880,-2.86759,-33.96545,2.84221,33.96545,22476,30
207.52680,-3.31574,-43.02338,3.29036,43.02338,22476,30
207.94178,-3.73060,-51.40820,3.70522,51.40820,22476,30
208.39780,-4.18640,-60.49875,4.16102,60.49875,22476,30
208.82919,-4.61743,-69.01744,4.59205,69.01744,22476,30
209.19280,-4.35594,-62.04890,4.33056,62.04890,22412,30
209.56980,-3.97477,-53.01192,3.94939,53.01192,22412,30
209.96180,-3.58220,-43.91778,3.55682,43.91777,22412,30
210.38780,-3.15626,-35.02289,3.13088,35.02289,22412,30
210.83080,-2.71321,-26.35855,2.68782,26.35855,22412,30
211.38280,-2.16127,-17.87760,2.13589,17.87760,22412,30
212.01280,-1.53132,-9.79166,1.50594,9.79167,22412,30
212.48880,-1.60774,-12.05299,1.58236,12.05299,22476,30
213.02919,-2.15339,-20.38595,2.12801,20.38594,22476,31
213.50780,-2.63249,-29.08229,2.60711,29.08229,22476,31
213.92920,-3.05357,-37.62599,3.02819,37.62600,22476,31
214.36180,-3.48653,-46.44708,3.46115,46.44708,22476,31
214.80680,-3.93172,-55.39967,3.90633,55.39967,22476,31
215.24180,-4.36667,-64.03203,4.34128,64.03203,22476,31
215.65480,-4.57276,-67.35481,4.54738,67.35480,22476,31
216.02180,-4.18974,-57.96578,4.16436,57.96578,22412,31
216.40580,-3.80450,-49.05050,3.77912,49.05050,22412,31
216.81280,-3.39756,-39.91841,3.37218,39.91841,22412,31
217.22919,-2.98139,-31.37972,2.95601,31.37972,22412,31
217.72919,-2.48138,-22.53587,2.45599,22.53587,22412,31
218.30580,-1.90450,-14.56382,1.87912,14.56382,22412,31
218.87580,-1.33929,-7.13454,1.31391,7.13454,22412,31
219.36880,-1.84030,-15.48400,1.81492,15.48400,22476,31
219.88778,-2.36063,-23.98250,2.33525,23.98250,22476,32
220.32919,-2.80172,-32.41877,2.77634,32.41877,22476,32
220.76980,-3.24263,-41.40223,3.21725,41.40223,22476,32
221.21480,-3.68773,-50.44395,3.66235,50.44395,22476,32
221.64480,-4.11738,-59.02429,4.09200,59.02429,22476,32
222.10080,-4.57356,-68.02175,4.54818,68.02175,22476,32
222.44080,-4.42274,-63.62745,4.39736,63.62745,22476,32
222.82919,-4.02825,-54.26897,4.00287,54.26897,22412,32
223.22180,-3.63451,-45.01154,3.60913,45.01154,22412,32
223.62920,-3.22741,-36.35940,3.20202,36.35940,22412,32
224.07780,-2.77856,-27.40116,2.75318,27.40116,22412,32
224.62480,-2.23144,-18.82379,2.20606,18.82379,22412,32
225.22919,-1.62755,-11.02464,1.60217,11.02464,22412,32
225.72919,-1.54468,-10.95240,1.51930,10.95240,22412,32
226.25180,-2.07641,-19.10815,2.05103,19.10815,22476,33
226.73380,-2.55866,-27.48137,2.53327,27.48137,22476,33
227.17780,-3.00266,-36.48972,2.97728,36.48972,22476,33
227.62078,-3.44584,-45.52459,3.42046,45.52459,22476,33
228.03980,-3.86474,-53.95299,3.83936,53.95299,22476,33
228.48580,-4.31088,-62.89296,4.28550,62.89296,22476,33
228.89680,-4.62163,-68.70427,4.59625,68.70427,22476,33
229.24480,-4.24985,-59.51048,4.22447,59.51048,22412,33
229.62920,-3.86366,-50.45506,3.83828,50.45506,22412,33
230.02919,-3.46348,-41.25963,3.43810,41.25963,22412,33
230.45678,-3.03548,-32.47344,3.01010,32.47345,22412,33
230.92920,-2.56337,-23.79733,2.53799,23.79733,22412,33
231.50878,-1.98351,-15.39398,1.95813,15.39398,22412,33
232.12880,-1.36351,-7.40986,1.33813,7.40986,22412,33
232.59380,-1.78065,-14.44990,1.75527,14.44990,22476,33
233.12380,-2.31275,-23.06837,2.28737,23.06837,22476,34
233.57280,-2.76171,-31.54811,2.73633,31.54811,22476,34
234.01078,-3.19963,-40.43394,3.17425,40.43394,22476,34
234.43080,-3.61956,-49.06112,3.59418,49.06112,22476,34
234.87580,-4.06467,-57.96264,4.03929,57.96264,22476,34
235.32919,-4.51772,-66.94701,4.49234,66.94701,22476,34
235.66480,-4.50693,-65.65738,4.48155,65.65739,22476,34
236.03080,-4.13038,-56.57024,4.10499,56.57024,22412,34
236.42920,-3.73157,-47.43797,3.70619,47.43797,22412,34
236.82919,-3.33166,-38.50023,3.30628,38.50023,22412,34
237.27280,-2.88758,-29.47560,2.86220,29.47560,22412,34
237.77780,-2.38261,-20.93143,2.35723,20.93143,22412,34
238.37780,-1.78255,-12.84626,1.75717,12.84626,22412,34
238.91280,-1.42666,-8.87365,1.40128,8.87365,22412,34
239.42920,-1.96124,-17.22353,1.93586,17.22353,22476,35
239.92920,-2.46173,-25.69617,2.43635,25.69617,22476,35
240.36980,-2.90277,-34.47523,2.87739,34.47523,22476,35
240.81478,-3.34790,-43.47546,3.32252,43.47546,22476,35
241.22919,-3.76183,-51.93384,3.73645,51.93384,22476,35
241.67980,-4.21258,-60.91034,4.18720,60.91034,22476,35
242.11980,-4.65269,-69.60952,4.62731,69.60951,22476,35
242.47980,-4.33863,-61.49354,4.31325,61.49354,22412,35
242.85880,-3.95608,-52.55209,3.93070,52.55209,22412,35
243.24778,-3.56658,-43.44817,3.54120,43.44817,22412,35
243.67580,-3.13854,-34.47007,3.11316,34.47007,22412,35
244.12920,-2.68559,-25.79376,2.66021,25.79376,22412,35
244.68280,-2.13155,-17.35522,2.10617,17.35522,22412,35
245.31080,-1.50363,-9.28586,1.47825,9.28586,22412,35
245.79480,-1.65953,-12.65567,1.63415,12.65567,22476,35
246.32919,-2.19783,-21.03876,2.17245,21.03876,22476,36
246.78580,-2.65486,-29.40389,2.62948,29.40389,22476,36
247.22919,-3.09782,-38.42930,3.07244,38.42930,22476,36
247.64380,-3.51282,-46.89818,3.48744,46.89817,22476,36
248.09380,-3.96302,-55.93644,3.93764,55.93644,22476,36
248.52919,-4.39804,-64.60735,4.37266,64.60735,22476,36
248.92980,-4.55838,-66.94678,4.53300,66.94678,22476,36
249.30280,-4.17095,-57.52185,4.14557,57.52185,22412,36
249.68780,-3.78487,-48.56873,3.75949,48.56873,22412,36
250.09380,-3.37888,-39.39380,3.35350,39.39380,22412,36
250.52919,-2.94381,-30.47651,2.91843,30.47651,22412,36
251.02919,-2.44375,-21.80769,2.41837,21.80769,22412,36
251.61180,-1.86067,-13.79102,1.83529,13.79102,22412,36
252.16680,-1.35266,-7.34395,1.32728,7.34395,22412,36
252.67480,-1.88892,-16.12301,1.86354,16.12301,22476,36
253.18280,-2.39792,-24.53626,2.37254,24.53625,22476,37
253.62920,-2.84394,-33.24048,2.81856,33.24048,22476,37
254.05680,-3.27201,-41.91685,3.24663,41.91685,22476,37
254.49578,-3.71096,-50.89451,3.68558,50.89451,22476,37
254.92920,-4.14359,-59.56167,4.11821,59.56167,22476,37
255.37780,-4.59279,-68.42197,4.56741,68.42197,22476,37
255.73380,-4.39672,-62.96507,4.37134,62.96507,22412,37
256.12378,-4.00138,-53.54981,3.97600,53.54981,22412,37
256.50878,-3.61567,-44.49314,3.59029,44.49314,22412,37
256.92880,-3.19565,-35.52053,3.17027,35.52053,22412,37
257.37280,-2.75176,-26.80178,2.72638,26.80178,22412,37
257.92920,-2.19571,-18.24925,2.17032,18.24925,22412,37
258.52920,-1.59573,-10.52093,1.57035,10.52093,22412,37
259.02078,-1.58459,-11.51866,1.55920,11.51866,22412,37
259.54080,-2.11164,-19.50012,2.08626,19.50012,22604,37
260.02920,-2.59981,-28.20496,2.57443,28.20496,22604,38
260.45981,-3.03092,-37.00861,3.00554,37.00861,22604,38
260.89680,-3.46798,-45.92816,3.44260,45.92816,22604,38
261.32919,-3.90006,-54.65907,3.87468,54.65907,22604,38
261.76880,-4.34010,-63.44491,4.31472,63.44491,22604,38
262.19181,-4.60344,-68.09290,4.57806,68.09290,22604,38
262.54378,-4.23265,-58.93013,4.20727,58.93013,22540,38
262.92919,-3.84598,-49.93597,3.82060,49.93597,22540,38
263.32919,-3.44592,-40.65430,3.42054,40.65430,22540,38
263.75581,-3.01886,-31.89978,2.99348,31.89978,22540,38
264.23678,-2.53780,-23.27333,2.51242,23.27333,22540,38
264.82919,-1.94593,-14.91713,1.92055,14.91713,22540,38
265.42919,-1.35358,-7.20580,1.32820,7.20580,22540,38
265.92919,-1.86678,-15.71839,1.84139,15.71839,22604,38
266.43478,-2.37404,-24.03094,2.34866,24.03094,22604,39
266.89178,-2.83105,-32.91859,2.80567,32.91859,22604,39
267.32919,-3.26813,-41.80381,3.24275,41.80381,22604,39
267.74978,-3.68911,-50.37472,3.66373,50.37473,22604,39
268.20081,-4.13973,-59.45142,4.11435,59.45142,22604,39
268.63181,-4.57097,-67.98112,4.54559,67.98112,22604,39
268.99478,-4.40216,-63.04678,4.37678,63.04678,22604,39
269.37281,-4.01846,-53.95676,3.99308,53.95676,22540,39
269.75078,-3.63979,-45.09945,3.61441,45.09945,22540,39
270.17081,-3.21964,-35.97202,3.19426,35.97202,22540,39
270.62919,-2.76182,-26.93442,2.73644,26.93442,22540,39
271.15478,-2.23573,-18.72271,2.21035,18.72271,22540,39
271.77278,-1.61779,-10.76660,1.59241,10.76660,22540,39
272.50181,-1.44974,-9.44830,1.42436,9.44830,22540,39
273.02922,-1.98572,-17.68378,1.96034,17.68378,22476,39
273.52922,-2.48587,-26.19939,2.46049,26.19938,22476,40
273.97078,-2.92803,-34.97642,2.90265,34.97642,22476,40
274.40978,-3.36708,-43.90259,3.34170,43.90260,22476,40
274.82981,-3.78704,-52.43426,3.76166,52.43426,22476,40
275.27978,-4.23678,-61.40798,4.21140,61.40798,22476,40
275.72919,-4.67665,-70.11219,4.65127,70.11219,22476,40
276.06878,-4.32345,-61.15925,4.29807,61.15925,22412,40
276.45278,-3.93627,-52.09278,3.91089,52.09278,22412,40
276.84281,-3.54585,-42.94585,3.52047,42.94585,22412,40
277.26881,-3.11970,-34.01379,3.09432,34.01379,22412,40
277.72919,-2.65982,-25.27296,2.63444,25.27296,22412,40
278.29981,-2.08871,-16.72852,2.06333,16.72852,22412,40
278.91378,-1.47476,-8.84734,1.44938,8.84734,22412,40
279.38181,-1.69134,-13.00019,1.66596,13.00019,22476,40
279.91778,-2.23088,-21.53173,2.20550,21.53173,22476,41
280.37281,-2.68606,-29.95463,2.66068,29.95463,22476,41
280.81181,-3.12489,-38.93197,3.09951,38.93197,22476,41
281.22919,-3.54195,-47.49541,3.51657,47.49541,22476,41
281.67578,-3.98911,-56.44289,3.96373,56.44289,22476,41
282.12919,-4.44206,-65.49131,4.41668,65.49131,22476,41
282.50681,-4.52516,-66.12096,4.49978,66.12096,22476,41
282.87378,-4.14587,-56.94642,4.12049,56.94642,22412,41
283.26278,-3.75591,-47.98041,3.73053,47.98041,22412,41
283.65281,-3.36592,-39.03911,3.34054,39.03911,22412,41
284.09681,-2.92190,-29.94232,2.89652,29.94232,22412,41
284.60581,-2.41293,-21.24790,2.38755,21.24790,22412,41
285.19478,-1.82378,-13.27797,1.79840,13.27797,22412,41
285.72919,-1.38561,-7.92208,1.36023,7.92208,22412,41
286.24578,-1.92839,-16.62814,1.90301,16.62814,22476,41
286.74578,-2.42910,-25.03514,2.40372,25.03514,22476,42
287.19581,-2.87908,-33.91723,2.85370,33.91722,22476,42
287.62919,-3.31222,-42.71781,3.28684,42.71781,22476,42
288.05381,-3.73709,-51.38117,3.71171,51.38117,22476,42
288.50978,-4.19286,-60.51075,4.16748,60.51075,22476,42
288.93478,-4.61790,-68.93530,4.59252,68.93530,22476,42
289.30478,-4.36064,-62.04038,4.33526,62.04038,22412,42
289.68781,-3.97346,-52.86416,3.94808,52.86416,22412,42
290.06681,-3.59387,-44.02258,3.56849,44.02258,22412,42
290.49281,-3.16794,-34.87958,3.14256,34.87958,22412,42
290.93681,-2.72395,-26.28862,2.69857,26.28862,22412,42
291.49381,-2.16697,-17.72440,2.14159,17.72440,22412,42
292.10778,-1.55301,-9.87852,1.52763,9.87852,22412,42
292.59478,-1.63061,-12.12560,1.60523,12.12560,22476,42
293.12919,-2.17008,-20.43084,2.14470,20.43084,22476,43
293.59878,-2.64016,-28.96284,2.61478,28.96284,22476,43
294.02922,-3.07017,-37.75714,3.04479,37.75714,22476,43
294.44981,-3.49117,-46.36849,3.46579,46.36849,22476,43
294.89881,-3.94037,-55.47097,3.91499,55.47097,22476,43
295.32919,-4.37038,-64.06023,4.34500,64.06023,22476,43
295.73578,-4.58320,-67.56063,4.55781,67.56063,22476,43
296.10878,-4.19342,-58.01481,4.16804,58.01480,22412,43
296.49878,-3.80216,-48.92701,3.77678,48.92701,22412,43
296.88778,-3.41325,-39.87851,3.38787,39.87851,22412,43
297.32678,-2.97408,-30.89963,2.94870,30.89964,22412,43
297.81878,-2.48205,-22.29173,2.45667,22.29173,22412,43
298.38878,-1.91219,-14.36123,1.88681,14.36123,22412,43
298.96281,-1.35168,-7.09460,1.32630,7.09460,22412,43
299.45378,-1.86193,-15.56850,1.83655,15.56850,22476,43
299.96878,-2.37815,-24.03910,2.35277,24.03910,22476,44
300.41981,-2.82923,-32.81100,2.80385,32.81100,22476,44
300.84478,-3.25425,-41.46726,3.22887,41.46726,22476,44
301.28378,-3.69327,-50.53463,3.66789,50.53463,22476,44
301.72919,-4.13791,-59.41170,4.11253,59.41170,22476,44
302.15978,-4.56920,-67.92398,4.54382,67.92398,22476,44
302.52922,-4.40646,-63.16004,4.38108,63.16004,22476,44
302.90681,-4.02277,-54.05316,3.99739,54.05316,22412,44
303.29081,-3.63812,-45.03804,3.61274,45.03804,22412,44
303.70378,-3.22502,-35.93111,3.19964,35.93111,22412,44
304.14178,-2.78716,-27.26821,2.76178,27.26821,22412,44
304.68781,-2.24107,-18.76428,2.21569,18.76428,22412,44
305.30578,-1.62312,-10.75131,1.59773,10.75131,22412,44
305.78281,-1.56327,-11.02639,1.53789,11.02639,22412,44
306.32481,-2.11397,-19.42566,2.08858,19.42566,22476,45
306.80278,-2.59220,-27.94296,2.56682,27.94296,22476,45
307.22919,-3.01829,-36.64902,2.99291,36.64902,22476,45
307.65578,-3.44541,-45.35072,3.42003,45.35072,22476,45
308.10481,-3.89439,-54.47221,3.86901,54.47221,22476,45
308.52922,-4.31841,-62.97262,4.29303,62.97262,22476,45
308.95481,-4.62662,-68.70568,4.60124,68.70568,22476,45
309.32581,-4.23296,-58.92829,4.20758,58.92829,22412,45
309.70481,-3.85232,-50.11519,3.82694,50.11519,22412,45
310.09478,-3.46218,-40.94423,3.43680,40.94423,22412,45
310.52922,-3.02817,-31.89747,3.00279,31.89747,22412,45
311.00681,-2.55013,-23.33203,2.52475,23.33203,22412,45
311.57178,-1.98523,-15.31349,1.95985,15.31349,22412,45
312.18281,-1.37426,-7.33237,1.34888,7.33237,22412,45
312.65281,-1.79644,-14.52837,1.77106,14.52837,22476,45
313.18078,-2.32642,-23.09332,2.30104,23.09332,22476,46
313.62919,-2.77443,-31.61120,2.74905,31.61120,22476,46
314.06281,-3.20834,-40.48716,3.18296,40.48716,22476,46
314.50181,-3.64734,-49.49765,3.62196,49.49765,22476,46
314.92919,-4.07435,-58.06293,4.04896,58.06293,22476,46
315.37681,-4.52237,-67.01802,4.49698,67.01803,22476,46
315.73481,-4.46121,-64.56969,4.43583,64.56969,22476,46
316.11881,-4.06897,-55.15197,4.04359,55.15197,22412,46
316.50278,-3.68423,-46.17534,3.65885,46.17534,22412,46
316.91581,-3.27130,-36.91157,3.24592,36.91157,22412,46
317.34181,-2.84522,-28.38565,2.81984,28.38565,22412,46
317.85278,-2.33421,-19.93543,2.30883,19.93543,22412,46
318.47581,-1.71118,-11.87786,1.68580,11.87786,22412,46
319.01378,-1.50338,-10.02415,1.47800,10.02415,22412,46
319.42919,-1.92973,-16.57144,1.90435,16.57144,22476,46
319.93178,-2.43342,-25.02395,2.40803,25.02395,22476,47
320.38181,-2.88338,-33.92811,2.85800,33.92811,22476,47
320.82581,-3.32751,-43.00555,3.30213,43.00555,22476,47
321.23881,-3.74040,-51.48786,3.71502,51.48785,22476,47
321.69181,-4.19314,-60.50979,4.16776,60.50979,22476,47
322.12919,-4.63026,-69.13444,4.60488,69.13444,22476,47
322.48481,-4.36896,-62.24733,4.34358,62.24733,22412,47
322.86781,-3.98164,-52.99955,3.95626,52.99955,22412,47
323.25681,-3.59203,-43.95227,3.56665,43.95227,22412,47
323.66678,-3.18207,-35.08019,3.15669,35.08019,22412,47
324.12919,-2.72010,-26.14012,2.69472,26.14012,22412,47
324.65978,-2.18905,-17.97752,2.16367,17.97752,22412,47
325.28581,-1.56318,-9.98352,1.53780,9.98352,22412,47
325.76081,-1.63243,-12.05651,1.60705,12.05651,22604,47
326.30381,-2.18128,-20.48111,2.15590,20.48111,22604,47
326.76578,-2.64336,-28.91447,2.61798,28.91447,22604,48
327.20881,-3.08633,-38.05820,3.06095,38.05820,22604,48
327.62919,-3.50632,-46.66104,3.48093,46.66104,22604,48
328.06281,-3.94052,-55.41640,3.91514,55.41640,22604,48
328.51778,-4.39553,-64.52394,4.37015,64.52394,22604,48
328.88678,-4.60912,-68.19977,4.58374,68.19977,22604,48
329.23378,-4.24311,-59.15591,4.21773,59.15591,22540,48
329.62919,-3.84631,-49.93816,3.82093,49.93816,22540,48
330.02922,-3.44625,-40.54030,3.42087,40.54030,22540,48
330.43978,-3.03521,-32.01430,3.00982,32.01430,22540,48
330.92919,-2.54613,-23.28254,2.52074,23.28254,22540,48
331.51678,-1.95822,-14.92345,1.93284,14.92345,22540,48
332.08078,-1.39429,-7.56401,1.36891,7.56401,22540,48
332.52178,-1.79118,-14.33825,1.76580,14.33825,22604,48
333.02978,-2.30150,-22.59719,2.27612,22.59719,22604,49
333.49781,-2.76954,-31.41077,2.74416,31.41077,22604,49
333.92919,-3.20045,-40.26349,3.17507,40.26349,22604,49
334.34378,-3.61536,-48.85904,3.58998,48.85904,22604,49
334.79881,-4.07044,-57.96271,4.04506,57.96271,22604,49
335.22919,-4.50043,-66.53506,4.47505,66.53506,22604,49
335.62478,-4.46486,-64.54402,4.43948,64.54402,22604,49
335.99678,-4.08494,-55.44057,4.05956,55.44057,22540,49
336.37978,-3.70122,-46.52315,3.67584,46.52315,22540,49
336.78281,-3.29837,-37.37952,3.27299,37.37952,22540,49
337.22919,-2.85222,-28.45395,2.82684,28.45395,22540,49
337.72919,-2.35226,-20.15434,2.32688,20.15434,22540,49
338.32919,-1.75215,-12.29396,1.72677,12.29396,22540,49
339.05278,-1.36520,-7.58905,1.33982,7.58905,22540,49
339.55878,-1.84978,-15.40603,1.82440,15.40603,22476,49
340.07878,-2.37055,-23.91063,2.34517,23.91063,22476,50
340.52922,-2.82059,-32.67593,2.79521,32.67593,22476,50
340.96178,-3.25357,-41.46709,3.22819,41.46709,22476,50
341.39978,-3.69160,-50.49700,3.66622,50.49700,22476,50
341.82919,-4.12031,-59.07123,4.09493,59.07123,22476,50
342.28078,-4.57249,-68.00988,4.54711,68.00987,22476,50
342.63778,-4.42431,-63.55812,4.39893,63.55812,22476,50
343.02922,-4.02717,-54.06008,4.00179,54.06007,22412,50
343.41778,-3.63738,-44.98992,3.61200,44.98992,22412,50
343.82081,-3.23433,-36.03788,3.20895,36.03788,22412,50
344.25878,-2.79648,-27.38228,2.77110,27.38228,22412,50
344.79881,-2.25643,-18.79932,2.23105,18.79932,22412,50
345.40578,-1.64954,-10.90198,1.62416,10.90198,22412,50
345.79578,-1.47675,-9.35492,1.45137,9.35492,22412,50
346.32878,-2.02622,-18.03880,2.00084,18.03880,22476,51
346.82378,-2.52157,-26.47733,2.49619,26.47733,22476,51
347.23881,-2.93669,-34.86158,2.91131,34.86158,22476,51
347.68281,-3.38076,-43.93886,3.35538,43.93887,22476,51
348.12478,-3.82266,-52.91883,3.79728,52.91883,22476,51
348.54481,-4.24246,-61.46997,4.21708,61.46997,22476,51
348.99878,-4.67688,-70.00244,4.65150,70.00243,22476,51
349.32919,-4.32602,-61.15340,4.30064,61.15340,22412,51
349.72919,-3.92280,-51.70495,3.89742,51.70495,22412,51
350.11978,-3.53143,-42.53955,3.50605,42.53955,22412,51
350.52922,-3.12224,-33.79359,3.09686,33.79359,22412,51
351.00181,-2.64932,-24.90877,2.62394,24.90877,22412,51
351.54278,-2.10820,-16.81091,2.08282,16.81091,22412,51
352.14881,-1.50236,-9.01346,1.47697,9.01346,22412,51
352.62919,-1.71501,-13.15141,1.68963,13.15141,22476,51
353.14778,-2.23752,-21.46856,2.21214,21.46856,22476,52
353.62681,-2.71662,-30.34952,2.69124,30.34952,22476,52
354.03681,-3.12652,-38.89885,3.10114,38.89885,22476,52
354.47478,-3.56457,-47.84614,3.53919,47.84614,22476,52
354.92919,-4.01868,-56.94500,3.99330,56.94500,22476,52
355.35481,-4.44466,-65.44109,4.41928,65.44109,22476,52
355.74178,-4.52642,-66.07000,4.50104,66.07000,22476,52
356.12681,-4.12931,-56.51719,4.10393,56.51719,22412,52
356.51678,-3.73854,-47.49312,3.71316,47.49312,22412,52
356.90078,-3.35457,-38.52551,3.32919,38.52551,22412,52
357.32919,-2.92656,-29.82018,2.90118,29.82018,22412,52
357.82919,-2.42655,-21.21897,2.40117,21.21897,22412,52
358.42919,-1.82643,-13.15049,1.80105,13.15049,22412,52
358.92919,-1.38557,-7.56352,1.36019,7.56352,22412,52
359.42919,-1.91387,-16.27357,1.88849,16.27357,22476,52
359.92919,-2.41479,-24.57539,2.38941,24.57539,22476,53
360.37281,-2.85876,-33.32288,2.83338,33.32288,22476,53
360.81578,-3.30193,-42.43039,3.27654,42.43039,22476,53
361.23578,-3.72179,-51.03012,3.69641,51.03012,22476,53
361.68578,-4.17153,-60.04440,4.14615,60.04440,22476,53
362.12919,-4.61467,-68.79857,4.58929,68.79857,22476,53
362.48678,-4.37995,-62.48846,4.35457,62.48846,22412,53
362.85278,-4.00927,-53.60775,3.98389,53.60775,22412,53
363.24781,-3.61356,-44.42245,3.58818,44.42245,22412,53
363.64978,-3.21156,-35.44352,3.18618,35.44352,22412,53
364.11881,-2.74264,-26.37649,2.71726,26.37649,22412,53
364.64481,-2.21655,-18.28016,2.19117,18.28016,22412,53
365.26578,-1.59566,-10.30397,1.57028,10.30397,22412,53
365.72919,-1.61152,-11.59102,1.58614,11.59102,22412,53
366.26881,-2.15869,-20.02173,2.13330,20.02173,22476,54
366.73678,-2.62681,-28.52561,2.60143,28.52561,22476,54
367.16981,-3.05991,-37.42569,3.03453,37.42569,22476,54
367.60778,-3.49787,-46.48216,3.47249,46.48216,22476,54
368.02922,-3.91907,-54.99448,3.89369,54.99448,22476,54
368.47181,-4.36204,-63.82035,4.33666,63.82035,22476,54
368.89481,-4.57821,-67.39002,4.55283,67.39002,22476,54
369.23778,-4.21947,-58.54287,4.19409,58.54287,22412,54
369.62919,-3.82693,-49.42955,3.80155,49.42955,22412,54
370.02922,-3.42697,-40.05580,3.40159,40.05581,22412,54
370.44778,-3.00783,-31.34624,2.98245,31.34624,22412,54
370.92919,-2.52681,-22.84567,2.50143,22.84567,22412,54
371.52922,-1.92692,-14.41091,1.90153,14.41091,22412,54
372.12078,-1.40019,-7.80207,1.37481,7.80207,22412,54
372.62919,-1.93627,-16.52744,1.91089,16.52744,22476,54
373.12878,-2.43713,-24.96492,2.41175,24.96493,22476,55
373.55381,-2.86211,-33.39478,2.83673,33.39478,22476,55
373.99281,-3.30123,-42.36882,3.27585,42.36882,22476,55
374.42919,-3.73711,-51.34107,3.71173,51.34107,22476,55
374.86178,-4.16988,-59.97116,4.14450,59.97116,22476,55
375.31878,-4.62690,-69.06393,4.60152,69.06393,22476,55
375.65681,-4.38430,-62.55542,4.35892,62.55542,22476,55
376.03378,-4.00243,-53.49682,3.97705,53.49682,22412,55
376.42919,-3.60674,-44.23996,3.58136,44.23996,22412,55
376.83178,-3.20371,-35.30525,3.17833,35.30525,22412,55
377.29578,-2.73983,-26.29686,2.71445,26.29686,22412,55
377.82919,-2.20674,-18.12865,2.18136,18.12865,22412,55
378.42919,-1.60680,-10.36059,1.58142,10.36059,22412,55
378.93281,-1.61647,-11.65509,1.59109,11.65509,22412,55
379.46878,-2.15885,-20.06840,2.13347,20.06840,22476,56
379.93178,-2.62199,-28.41147,2.59660,28.41147,22476,56
380.36881,-3.05906,-37.39184,3.03367,37.39184,22476,56
380.80678,-3.49700,-46.45638,3.47162,46.45638,22476,56
381.22919,-3.91919,-54.95960,3.89381,54.95960,22476,56
381.68281,-4.37319,-64.05468,4.34781,64.05468,22476,56
382.08278,-4.59192,-67.71667,4.56654,67.71667,22476,56
382.44181,-4.21554,-58.43185,4.19016,58.43185,22412,56
382.82919,-3.82701,-49.41336,3.80163,49.41336,22412,56
383.22919,-3.42707,-40.03118,3.40169,40.03118,22412,56
383.64278,-3.01293,-31.36363,2.98755,31.36363,22412,56
384.12919,-2.52692,-22.77498,2.50154,22.77498,22412,56
384.72919,-1.92702,-14.41298,1.90164,14.41298,22412,56
385.32578,-1.39529,-7.70447,1.36991,7.70447,22412,56
385.82919,-1.92635,-16.34652,1.90097,16.34652,22476,56
386.32919,-2.42723,-24.77869,2.40184,24.77869,22476,57
386.76578,-2.86420,-33.43464,2.83882,33.43464,22476,57
387.20881,-3.30737,-42.51594,3.28199,42.51595,22476,57
387.62919,-3.72721,-51.11197,3.70183,51.11197,22476,57
388.06878,-4.16700,-59.95241,4.14162,59.95241,22476,57
388.52478,-4.62304,-69.02729,4.59766,69.02729,22476,57
388.86278,-4.38452,-62.58021,4.35914,62.58020,22412,57
389.23978,-4.00258,-53.50388,3.97720,53.50388,22412,57
389.62919,-3.61288,-44.43844,3.58750,44.43844,22412,57
390.02922,-3.21286,-35.41022,3.18748,35.41022,22412,57
390.49478,-2.74698,-26.35379,2.72160,26.35379,22412,57
391.02922,-2.21286,-18.16038,2.18748,18.16038,22412,57
391.63981,-1.60196,-10.33398,1.57658,10.33398,22412,57
392.12919,-1.61227,-11.57970,1.58689,11.57970,22412,57
392.67481,-2.16501,-20.10372,2.13963,20.10372,22604,57
393.13178,-2.62209,-28.42470,2.59671,28.42470,22604,58
393.57081,-3.06114,-37.45750,3.03576,37.45750,22604,58
394.00181,-3.49213,-46.33438,3.46675,46.33438,22604,58
394.43281,-3.92334,-55.03213,3.89796,55.03213,22604,58
394.87778,-4.36830,-63.97658,4.34292,63.97658,22604,58
395.29378,-4.58170,-67.44730,4.55632,67.44730,22604,58
395.63678,-4.22270,-58.60510,4.19732,58.60510,22540,58
396.02919,-3.82914,-49.48117,3.80376,49.48117,22540,58
396.42919,-3.42919,-40.07757,3.40381,40.07757,22540,58
396.83678,-3.02104,-31.45739,2.99566,31.45739,22540,58
397.32919,-2.52904,-22.76373,2.50366,22.76373,22540,58
397.92919,-1.92915,-14.39981,1.90376,14.39981,22540,58
398.50278,-1.36763,-7.08516,1.34225,7.08516,22540,58
398.99281,-1.87599,-15.55799,1.85061,15.55799,22604,58
399.49878,-2.38326,-23.95468,2.35787,23.95468,22604,59
399.93578,-2.82033,-32.48155,2.79495,32.48155,22604,59
400.37378,-3.25830,-41.46800,3.23292,41.46800,22604,59
400.80678,-3.69136,-50.36293,3.66598,50.36293,22604,59
401.23081,-4.11506,-58.82705,4.08968,58.82705,22604,59
401.68778,-4.57218,-67.99635,4.54680,67.99635,22604,59
402.04481,-4.42398,-63.53239,4.39860,63.53239,22604,59
402.42919,-4.03378,-54.22358,4.00840,54.22358,22540,59
402.82378,-3.63807,-45.03959,3.61269,45.03959,22540,59
403.22078,-3.24103,-35.96219,3.21565,35.96219,22540,59
403.65178,-2.81013,-27.39875,2.78475,27.39875,22540,59
404.20378,-2.25809,-18.74764,2.23271,18.74764,22540,59
404.81681,-1.64517,-10.83564,1.61979,10.83564,22540,59
405.12919,-1.35586,-6.95146,1.33048,6.95146,22540,59