File: data-raw/Experiment 2/Results/INSTRON data/Experiment 2.is_ccyclic_RawData/Specimen_RawData_6.csv
Text Inputs : Specimen label,"Long Plate 1 T2"

Time,Extension,Load,Compressive extension,Compressive load,Segment ID,Total Cycle Count
(sec),(mm),(N),(mm),(N),,
0.00000,-0.02636,-0.02120,0.00000,0.02120,12835,0
0.20180,-0.02636,-0.04555,0.00000,0.04555,12835,0
0.35280,-0.02636,-0.07519,0.00000,0.07519,12835,0
0.66280,-0.02636,-0.01990,0.00000,0.01990,12835,0
0.82080,-0.02636,0.00029,0.00000,-0.00029,12835,0
0.94880,-0.02636,-0.01722,0.00000,0.01722,12835,0
1.12180,-0.04592,-0.05013,0.01956,0.05013,3220,0
1.28380,-0.13217,-0.03376,0.10581,0.03376,3220,0
1.44180,-0.21277,-0.04826,0.18641,0.04826,3220,0
1.62380,-0.30418,-0.03541,0.27782,0.03541,3220,0
1.86080,-0.42281,-0.20055,0.39645,0.20055,3220,0
2.06380,-0.52445,-1.96955,0.49809,1.96955,3220,0
2.23480,-0.60989,-3.49605,0.58353,3.49605,3220,0
2.43680,-0.71090,-5.17497,0.68454,5.17497,3220,0
2.60380,-0.79771,-6.64633,0.77135,6.64633,3220,0
2.91780,-1.11574,-12.04990,1.08937,12.04990,22476,0
3.21780,-1.41631,-16.70049,1.38995,16.70049,22476,0
3.44580,-1.64471,-20.31510,1.61835,20.31510,22476,0
3.60680,-1.80563,-23.31985,1.77926,23.31985,22476,0
3.77480,-1.97347,-26.55440,1.94711,26.55440,22476,0
3.89280,-2.09156,-28.89963,2.06520,28.89963,22476,0
4.02580,-2.22475,-31.85852,2.19838,31.85852,22476,0
4.14480,-2.34362,-34.51813,2.31726,34.51813,22476,0
4.30580,-2.50444,-38.03549,2.47808,38.03548,22476,0
4.48280,-2.68165,-41.89667,2.65528,41.89668,22476,0
4.68780,-2.88664,-46.39683,2.86028,46.39683,22476,0
4.85280,-3.05150,-49.94717,3.02514,49.94717,22476,0
4.98880,-3.18773,-52.87733,3.16137,52.87733,22476,0
5.11280,-3.31165,-55.56713,3.28529,55.56713,22476,0
5.26780,-3.46656,-58.83684,3.44020,58.83685,22476,0
5.40280,-3.60164,-61.85208,3.57528,61.85208,22476,0
5.54880,-3.74753,-65.03052,3.72117,65.03053,22476,0
5.70680,-3.90560,-68.27860,3.87924,68.27860,22476,0
5.83080,-3.90697,-67.62643,3.88061,67.62643,22476,0
5.95580,-3.76839,-63.43928,3.74203,63.43928,22476,0
6.09780,-3.62025,-59.09904,3.59388,59.09904,22412,0
6.24920,-3.46665,-54.84560,3.44029,54.84560,22412,0
6.37080,-3.34393,-51.57484,3.31757,51.57484,22412,0
6.49780,-3.21663,-48.13605,3.19026,48.13605,22412,0
6.61680,-3.09735,-44.83921,3.07099,44.83921,22412,0
6.75480,-2.95930,-41.43050,2.93294,41.43050,22412,0
6.88180,-2.83238,-38.39334,2.80602,38.39334,22412,0
7.02380,-2.69035,-35.01667,2.66399,35.01667,22412,0
7.16780,-2.54627,-31.56191,2.51991,31.56191,22412,0
7.27480,-2.43913,-29.19068,2.41277,29.19068,22412,0
7.44580,-2.26856,-25.60659,2.24220,25.60659,22412,0
7.60280,-2.11128,-22.68807,2.08491,22.68807,22412,0
7.84880,-1.86538,-18.56580,1.83902,18.56580,22412,0
8.08780,-1.62635,-14.93076,1.59999,14.93076,22412,0
8.47780,-1.23643,-9.37730,1.21007,9.37730,22412,0
8.67380,-1.13412,-8.33337,1.10776,8.33337,22412,0
8.89280,-1.37356,-13.01775,1.34719,13.01775,22476,0
9.02080,-1.50487,-15.30488,1.47851,15.30488,22476,0
9.18780,-1.67380,-18.30699,1.64744,18.30699,22476,0
9.32980,-1.81619,-20.93670,1.78983,20.93670,22476,1
9.46880,-1.95526,-23.59351,1.92889,23.59351,22476,1
9.59980,-2.08639,-26.22470,2.06003,26.22470,22476,1
9.69980,-2.18654,-28.26001,2.16017,28.26001,22476,1
9.80580,-2.29263,-30.66021,2.26627,30.66021,22476,1
9.89180,-2.37838,-32.66257,2.35202,32.66257,22476,1
9.97480,-2.46128,-34.63419,2.43492,34.63419,22476,1
10.06680,-2.55347,-36.66447,2.52711,36.66447,22476,1
10.16580,-2.65256,-39.02720,2.62620,39.02719,22476,1
10.26680,-2.75353,-41.24929,2.72717,41.24929,22476,1
10.35280,-2.83949,-43.23528,2.81313,43.23528,22476,1
10.44180,-2.92846,-45.25586,2.90210,45.25586,22476,1
10.53780,-3.02432,-47.57846,2.99796,47.57846,22476,1
10.62080,-3.10743,-49.34635,3.08107,49.34635,22476,1
10.69980,-3.18662,-51.16967,3.16026,51.16967,22476,1
10.78280,-3.26958,-53.02202,3.24322,53.02201,22476,1
10.88780,-3.37447,-55.38446,3.34811,55.38446,22476,1
10.98680,-3.47345,-57.68567,3.44709,57.68567,22476,1
11.09780,-3.58456,-60.25987,3.55820,60.25988,22476,1
11.18480,-3.67144,-62.30009,3.64508,62.30009,22476,1
11.28080,-3.76752,-64.44009,3.74116,64.44009,22476,1
11.39280,-3.87944,-66.85120,3.85308,66.85120,22476,1
11.49580,-3.98077,-69.28119,3.95441,69.28119,22476,1
11.59880,-3.89753,-66.33748,3.87117,66.33748,22476,1
11.68980,-3.79833,-63.50052,3.77197,63.50052,22476,1
11.78380,-3.69957,-60.65154,3.67321,60.65154,22476,1
11.88580,-3.59497,-57.65450,3.56861,57.65450,22412,1
11.99280,-3.48649,-54.53833,3.46012,54.53833,22412,1
12.07980,-3.39892,-52.21466,3.37256,52.21466,22412,1
12.16780,-3.31056,-49.80696,3.28420,49.80696,22412,1
12.25980,-3.21842,-47.36070,3.19206,47.36070,22412,1
12.35980,-3.11825,-44.66604,3.09189,44.66604,22412,1
12.44380,-3.03412,-42.70386,3.00775,42.70386,22412,1
12.53180,-2.94613,-40.41940,2.91977,40.41940,22412,1
12.61980,-2.85822,-38.42650,2.83186,38.42650,22412,1
12.70380,-2.77425,-36.28387,2.74789,36.28387,22412,1
12.78980,-2.68818,-34.40214,2.66182,34.40213,22412,1
12.87280,-2.60519,-32.34149,2.57883,32.34149,22412,1
12.97580,-2.50204,-30.06766,2.47568,30.06766,22412,1
13.07680,-2.40106,-27.72210,2.37470,27.72210,22412,1
13.17880,-2.29931,-25.69446,2.27294,25.69446,22412,1
13.28380,-2.19420,-23.67379,2.16784,23.67379,22412,1
13.40280,-2.07499,-21.57004,2.04863,21.57004,22412,1
13.51580,-1.96202,-19.58492,1.93566,19.58492,22412,1
13.64980,-1.82816,-17.58119,1.80180,17.58118,22412,1
13.75980,-1.71820,-15.91364,1.69184,15.91364,22412,1
13.87580,-1.60207,-14.21079,1.57571,14.21079,22412,1
14.00980,-1.46789,-12.40839,1.44153,12.40839,22412,1
14.13480,-1.34303,-10.61272,1.31667,10.61271,22412,1
14.24580,-1.23228,-8.92230,1.20592,8.92230,22412,1
14.35580,-1.14383,-7.72110,1.11747,7.72110,22412,1
14.44180,-1.23699,-9.94601,1.21063,9.94601,22412,1
14.53780,-1.34094,-11.98875,1.31458,11.98875,22412,1
14.64680,-1.45471,-13.93876,1.42835,13.93876,22476,1
14.73780,-1.54790,-15.58526,1.52154,15.58526,22476,1
14.84280,-1.65437,-17.46103,1.62801,17.46103,22476,1
14.95680,-1.76901,-19.54610,1.74265,19.54610,22476,1
15.09580,-1.90824,-22.15293,1.88188,22.15294,22476,2
15.19980,-2.01231,-24.20603,1.98595,24.20604,22476,2
15.30380,-2.11642,-26.37660,2.09006,26.37660,22476,2
15.39280,-2.20553,-28.20235,2.17917,28.20235,22476,2
15.47980,-2.29262,-30.21896,2.26626,30.21896,22476,2
15.56180,-2.37441,-32.04321,2.34805,32.04321,22476,2
15.65980,-2.47228,-34.34059,2.44591,34.34060,22476,2
15.76280,-2.57545,-36.66046,2.54908,36.66046,22476,2
15.86980,-2.68252,-39.19562,2.65616,39.19562,22476,2
15.96480,-2.77756,-41.26262,2.75120,41.26262,22476,2
16.05880,-2.87150,-43.56486,2.84514,43.56486,22476,2
16.15780,-2.97041,-45.72200,2.94405,45.72200,22476,2
16.24580,-3.05843,-47.90078,3.03207,47.90078,22476,2
16.33780,-3.15059,-49.85674,3.12423,49.85674,22476,2
16.43880,-3.25158,-52.16027,3.22522,52.16027,22476,2
16.52780,-3.34044,-54.16131,3.31408,54.16131,22476,2
16.61380,-3.42646,-56.21765,3.40010,56.21765,22476,2
16.70280,-3.51552,-58.17961,3.48916,58.17961,22476,2
16.78880,-3.60154,-60.18769,3.57518,60.18769,22476,2
16.87780,-3.69048,-62.23014,3.66412,62.23014,22476,2
16.95980,-3.77248,-64.14230,3.74612,64.14230,22476,2
17.05180,-3.86443,-66.27669,3.83807,66.27670,22476,2
17.14380,-3.95644,-68.28628,3.93008,68.28629,22476,2
17.23580,-4.00718,-69.36947,3.98082,69.36948,22476,2
17.33080,-3.89864,-65.96508,3.87228,65.96508,22476,2
17.41580,-3.80718,-63.30614,3.78082,63.30614,22476,2
17.50780,-3.71114,-60.36625,3.68478,60.36625,22412,2
17.61880,-3.59773,-57.22710,3.57137,57.22710,22412,2
17.72380,-3.49149,-54.19956,3.46513,54.19956,22412,2
17.83980,-3.37490,-51.10494,3.34854,51.10494,22412,2
17.97480,-3.23963,-47.48660,3.21327,47.48660,22412,2
18.08280,-3.13148,-44.60113,3.10512,44.60114,22412,2
18.20280,-3.01131,-41.59536,2.98495,41.59536,22412,2
18.33680,-2.87741,-38.44006,2.85105,38.44006,22412,2
18.44980,-2.76442,-35.65714,2.73806,35.65714,22412,2
18.58780,-2.62643,-32.41479,2.60006,32.41479,22412,2
18.70680,-2.50727,-29.63710,2.48090,29.63710,22412,2
18.81680,-2.39728,-27.19259,2.37092,27.19259,22412,2
18.96580,-2.24852,-24.26606,2.22216,24.26606,22412,2
19.14780,-2.06622,-21.07721,2.03986,21.07721,22412,2
19.36380,-1.85037,-17.61871,1.82401,17.61871,22412,2
19.56480,-1.64941,-14.68966,1.62305,14.68966,22412,2
19.83680,-1.37731,-10.85758,1.35095,10.85758,22412,2
20.02280,-1.19150,-8.11636,1.16514,8.11636,22412,2
20.24920,-1.31452,-11.25204,1.28816,11.25204,22412,2
20.53680,-1.61205,-16.58462,1.58569,16.58462,22476,2
20.75780,-1.83434,-20.49277,1.80798,20.49277,22476,3
20.92080,-1.99750,-23.66433,1.97114,23.66433,22476,3
21.06880,-2.14571,-26.67860,2.11934,26.67860,22476,3
21.18880,-2.26583,-29.32141,2.23947,29.32141,22476,3
21.29780,-2.37461,-31.72094,2.34825,31.72094,22476,3
21.43180,-2.50853,-34.84185,2.48217,34.84185,22476,3
21.56180,-2.63879,-37.84410,2.61243,37.84410,22476,3
21.70180,-2.77877,-40.98330,2.75241,40.98330,22476,3
21.86380,-2.94069,-44.71038,2.91433,44.71038,22476,3
22.00080,-3.07766,-47.98863,3.05130,47.98863,22476,3
22.12080,-3.19787,-50.66838,3.17151,50.66838,22476,3
22.24080,-3.31775,-53.38849,3.29139,53.38849,22476,3
22.34920,-3.42567,-55.91293,3.39931,55.91293,22476,3
22.46980,-3.54680,-58.68154,3.52044,58.68155,22476,3
22.58680,-3.66371,-61.31407,3.63735,61.31406,22476,3
22.71280,-3.78973,-64.26145,3.76337,64.26145,22476,3
22.81880,-3.89564,-66.62279,3.86928,66.62279,22476,3
22.92880,-4.00559,-69.19765,3.97923,69.19765,22476,3
23.04180,-3.93091,-66.60178,3.90454,66.60178,22476,3
23.15280,-3.81047,-63.01328,3.78411,63.01328,22476,3
23.27080,-3.68767,-59.44300,3.66131,59.44300,22412,3
23.37480,-3.58169,-56.53955,3.55533,56.53955,22412,3
23.50380,-3.45137,-52.82319,3.42501,52.82319,22412,3
23.62780,-3.32693,-49.49881,3.30057,49.49881,22412,3
23.74480,-3.20979,-46.38363,3.18343,46.38363,22412,3
23.85880,-3.09556,-43.45097,3.06920,43.45097,22412,3
23.99580,-2.95854,-40.07325,2.93218,40.07325,22412,3
24.14920,-2.80565,-36.35536,2.77929,36.35536,22412,3
24.29080,-2.66364,-33.07792,2.63728,33.07792,22412,3
24.44920,-2.50550,-29.37351,2.47914,29.37351,22412,3
24.64880,-2.30570,-25.22026,2.27933,25.22026,22412,3
24.84920,-2.10554,-21.58649,2.07918,21.58649,22412,3
25.11680,-1.83760,-17.21856,1.81124,17.21856,22412,3
25.50580,-1.44832,-11.75510,1.42196,11.75510,22412,3
25.75280,-1.20175,-8.10895,1.17539,8.10895,22412,3
26.22180,-1.56453,-15.57097,1.53817,15.57097,22476,3
26.65180,-1.99670,-23.43898,1.97034,23.43897,22476,4
26.94180,-2.28690,-29.52558,2.26054,29.52558,22476,4
27.13480,-2.47970,-33.97690,2.45334,33.97690,22476,4
27.31580,-2.66094,-38.16031,2.63458,38.16031,22476,4
27.47280,-2.81802,-41.66800,2.79166,41.66800,22476,4
27.60580,-2.95096,-44.73073,2.92460,44.73073,22476,4
27.78080,-3.12600,-48.86671,3.09964,48.86671,22476,4
27.94280,-3.28803,-52.56277,3.26167,52.56277,22476,4
28.08780,-3.43287,-55.85044,3.40651,55.85044,22476,4
28.21680,-3.56203,-58.76793,3.53567,58.76793,22476,4
28.36380,-3.70891,-62.25068,3.68255,62.25068,22476,4
28.52480,-3.86988,-65.94764,3.84352,65.94765,22476,4
28.65280,-3.99788,-68.78408,3.97152,68.78408,22476,4
28.78280,-3.95939,-67.20628,3.93303,67.20628,22476,4
28.91280,-3.81808,-62.98391,3.79172,62.98391,22476,4
29.04780,-3.67823,-58.89838,3.65187,58.89838,22412,4
29.16380,-3.56045,-55.67876,3.53409,55.67876,22412,4
29.28580,-3.43744,-52.30153,3.41108,52.30153,22412,4
29.41680,-3.30610,-48.68615,3.27974,48.68615,22412,4
29.54880,-3.17400,-45.15096,3.14764,45.15096,22412,4
29.66580,-3.05671,-42.33924,3.03035,42.33924,22412,4
29.78480,-2.93783,-39.42953,2.91147,39.42953,22412,4
29.90680,-2.81586,-36.45135,2.78950,36.45135,22412,4
30.01380,-2.70881,-34.01455,2.68245,34.01455,22412,4
30.13380,-2.58878,-31.09379,2.56242,31.09380,22412,4
30.22680,-2.49571,-29.05004,2.46935,29.05004,22412,4
30.35480,-2.36781,-26.35080,2.34145,26.35080,22412,4
30.51180,-2.21087,-23.33931,2.18451,23.33931,22412,4
30.65480,-2.06769,-20.77288,2.04133,20.77288,22412,4
30.81480,-1.90779,-18.21900,1.88143,18.21900,22412,4
30.95480,-1.76791,-16.15895,1.74155,16.15895,22412,4
31.18980,-1.53261,-12.75358,1.50625,12.75358,22412,4
31.46780,-1.25494,-8.71552,1.22858,8.71552,22412,4
31.96680,-1.58168,-15.66680,1.55532,15.66680,22476,4
32.31580,-1.93276,-22.08536,1.90640,22.08536,22476,5
32.60780,-2.22513,-27.93106,2.19877,27.93106,22476,5
32.80480,-2.42183,-32.39500,2.39547,32.39500,22476,5
32.94920,-2.56608,-35.75685,2.53972,35.75684,22476,5
33.15180,-2.76914,-40.37306,2.74278,40.37306,22476,5
33.33880,-2.95608,-44.72744,2.92972,44.72744,22476,5
33.48380,-3.10107,-48.15264,3.07471,48.15264,22476,5
33.66080,-3.27822,-52.12854,3.25186,52.12854,22476,5
33.83280,-3.45004,-56.07036,3.42368,56.07036,22476,5
34.03780,-3.65511,-60.77940,3.62875,60.77940,22476,5
34.19680,-3.81412,-64.45163,3.78776,64.45163,22476,5
34.40280,-4.02011,-69.19912,3.99375,69.19911,22476,5
34.56680,-3.91203,-65.51981,3.88567,65.51981,22476,5
34.76980,-3.69870,-59.29749,3.67234,59.29749,22412,5
34.99680,-3.46872,-52.91051,3.44236,52.91051,22412,5
35.14180,-3.32328,-48.99163,3.29692,48.99163,22412,5
35.30080,-3.16417,-44.77902,3.13781,44.77902,22412,5
35.41380,-3.05090,-42.01612,3.02454,42.01612,22412,5
35.51580,-2.94896,-39.50055,2.92260,39.50055,22412,5
35.63280,-2.83201,-36.61573,2.80565,36.61573,22412,5
35.74680,-2.71799,-33.96287,2.69163,33.96287,22412,5
35.84780,-2.61704,-31.56355,2.59067,31.56355,22412,5
35.94780,-2.51694,-29.31456,2.49058,29.31456,22412,5
36.08180,-2.38296,-26.51351,2.35660,26.51351,22412,5
36.26080,-2.20404,-23.05573,2.17768,23.05573,22412,5
36.44380,-2.02095,-19.88848,1.99459,19.88848,22412,5
36.67380,-1.79107,-16.35866,1.76470,16.35866,22412,5
36.91380,-1.55081,-12.88934,1.52445,12.88934,22412,5
37.17980,-1.28505,-9.09855,1.25869,9.09855,22412,5
37.42080,-1.28067,-10.10852,1.25431,10.10853,22412,5
37.68680,-1.55957,-15.17642,1.53320,15.17642,22476,5
37.90180,-1.77679,-19.00068,1.75043,19.00068,22476,6
38.11780,-1.99309,-23.05365,1.96673,23.05365,22476,6
38.34920,-2.22441,-27.76326,2.19804,27.76326,22476,6
38.51180,-2.38721,-31.39871,2.36085,31.39871,22476,6
38.66480,-2.54033,-35.02372,2.51397,35.02372,22476,6
38.99380,-2.86936,-42.60263,2.84300,42.60263,22476,6
39.29180,-3.16751,-49.44396,3.14115,49.44396,22476,6
39.55880,-3.43432,-55.59056,3.40796,55.59056,22476,6
39.88380,-3.75937,-63.01969,3.73301,63.01968,22476,6
40.20480,-4.05299,-69.74205,4.02662,69.74205,22476,6
40.57580,-3.65789,-57.97776,3.63153,57.97776,22412,6
40.85880,-3.37264,-50.13342,3.34628,50.13342,22412,6
41.22580,-3.00517,-40.59801,2.97881,40.59801,22412,6
41.47380,-2.75729,-34.71572,2.73093,34.71572,22412,6
41.92780,-2.30330,-24.78546,2.27693,24.78547,22412,6
42.69580,-1.53502,-12.61079,1.50866,12.61079,22412,6
43.26980,-1.39496,-12.19261,1.36860,12.19261,22412,6
43.91380,-2.04742,-23.99417,2.02106,23.99417,22476,7
44.25880,-2.39246,-31.41868,2.36609,31.41868,22476,7
44.62580,-2.75960,-39.97023,2.73323,39.97023,22476,7
44.82580,-2.95955,-44.53772,2.93319,44.53772,22476,7
45.00480,-3.13868,-48.72826,3.11232,48.72826,22476,7
45.21680,-3.35051,-53.49664,3.32415,53.49664,22476,7
45.39280,-3.52665,-57.55316,3.50029,57.55316,22476,7
45.55980,-3.69355,-61.47769,3.66719,61.47770,22476,7
45.70780,-3.84154,-64.93066,3.81518,64.93066,22476,7
45.88380,-4.01760,-68.94086,3.99124,68.94086,22476,7
46.04680,-3.91481,-65.42292,3.88845,65.42292,22476,7
46.16980,-3.78399,-61.62943,3.75763,61.62943,22476,7
46.29780,-3.65231,-57.80314,3.62595,57.80314,22412,7
46.41880,-3.52983,-54.40253,3.50347,54.40253,22412,7
46.53980,-3.40803,-51.14381,3.38167,51.14381,22412,7
46.66780,-3.27981,-47.65909,3.25345,47.65909,22412,7
46.80880,-3.13862,-43.90676,3.11226,43.90676,22412,7
46.92480,-3.02248,-41.03103,2.99612,41.03103,22412,7
47.06880,-2.87854,-37.52410,2.85218,37.52411,22412,7
47.21780,-2.72952,-34.07091,2.70316,34.07090,22412,7
47.37080,-2.57642,-30.38841,2.55006,30.38841,22412,7
47.56380,-2.38346,-26.29678,2.35710,26.29678,22412,7
47.91980,-2.02745,-19.80533,2.00109,19.80533,22412,7
48.63580,-1.31144,-9.34315,1.28508,9.34315,22412,7
49.31980,-1.70891,-17.63357,1.68254,17.63357,22604,7
49.83980,-2.22981,-27.64463,2.20344,27.64463,22604,8
50.09880,-2.48864,-33.66807,2.46228,33.66808,22604,8
50.45780,-2.84783,-41.88934,2.82147,41.88934,22604,8
50.77180,-3.16196,-49.16893,3.13560,49.16893,22604,8
51.13680,-3.52688,-57.51004,3.50051,57.51004,22604,8
51.47880,-3.86876,-65.43635,3.84240,65.43635,22604,8
51.85780,-3.87814,-64.20042,3.85178,64.20042,22604,8
52.27580,-3.45028,-52.11528,3.42392,52.11528,22540,8
52.69680,-3.02871,-40.98383,3.00235,40.98383,22540,8
53.01880,-2.70674,-33.34408,2.68038,33.34408,22540,8
53.41180,-2.31379,-24.85397,2.28743,24.85397,22540,8
53.91880,-1.80679,-16.38025,1.78043,16.38025,22540,8
54.61780,-1.21953,-8.40315,1.19317,8.40315,22540,8
55.14920,-1.77451,-18.82622,1.74814,18.82622,22604,8
55.52980,-2.15609,-26.15442,2.12973,26.15442,22604,9
55.74980,-2.37595,-30.88472,2.34959,30.88472,22604,9
55.92780,-2.55414,-35.05198,2.52778,35.05198,22604,9
56.09880,-2.72507,-39.04613,2.69871,39.04613,22604,9
56.29880,-2.92509,-43.60702,2.89873,43.60701,22604,9
56.45880,-3.08500,-47.45878,3.05864,47.45878,22604,9
56.64180,-3.26818,-51.54768,3.24182,51.54768,22604,9
56.80380,-3.43003,-55.28656,3.40367,55.28656,22604,9
57.02380,-3.65009,-60.29969,3.62373,60.29969,22604,9
57.25780,-3.88404,-65.72904,3.85768,65.72903,22604,9
57.41080,-4.03715,-69.21414,4.01079,69.21413,22604,9
57.57080,-3.93331,-65.78811,3.90695,65.78811,22604,9
57.77880,-3.71462,-59.36387,3.68826,59.36387,22540,9
58.00380,-3.48679,-53.03484,3.46043,53.03484,22540,9
58.18780,-3.30221,-48.12539,3.27585,48.12539,22540,9
58.40580,-3.08384,-42.30460,3.05748,42.30460,22540,9
58.64920,-2.84097,-36.40115,2.81461,36.40115,22540,9
58.92780,-2.56188,-29.88178,2.53552,29.88178,22540,9
59.44920,-2.04089,-19.87118,2.01453,19.87118,22540,9
60.24920,-1.24109,-8.17804,1.21472,8.17804,22540,9
60.99580,-1.47806,-13.62476,1.45170,13.62476,22476,9
61.37680,-1.86183,-20.41580,1.83547,20.41580,22476,9
61.69180,-2.17708,-26.63765,2.15072,26.63765,22476,10
61.89280,-2.37793,-31.05322,2.35157,31.05322,22476,10
62.09180,-2.57704,-35.60979,2.55068,35.60979,22476,10
62.33780,-2.82311,-41.25838,2.79675,41.25838,22476,10
62.54480,-3.02998,-46.05545,3.00362,46.05545,22476,10
62.71580,-3.20121,-49.99587,3.17484,49.99586,22476,10
62.87380,-3.35901,-53.57886,3.33265,53.57886,22476,10
63.00680,-3.49203,-56.68310,3.46567,56.68310,22476,10
63.14580,-3.63107,-59.92247,3.60471,59.92247,22476,10
63.25780,-3.74304,-62.50747,3.71668,62.50747,22476,10
63.36380,-3.84897,-64.96683,3.82261,64.96683,22476,10
63.48180,-3.96694,-67.61944,3.94058,67.61945,22476,10
63.60180,-4.02808,-68.83384,4.00172,68.83383,22476,10
63.72380,-3.88917,-64.53971,3.86281,64.53971,22476,10
63.85080,-3.75536,-60.59592,3.72900,60.59592,22412,10
63.97780,-3.62529,-56.92941,3.59893,56.92941,22412,10
64.07680,-3.52525,-54.16107,3.49889,54.16107,22412,10
64.18980,-3.41150,-51.04265,3.38514,51.04264,22412,10
64.32880,-3.27229,-47.36416,3.24593,47.36416,22412,10
64.43380,-3.16714,-44.43204,3.14078,44.43204,22412,10
64.55080,-3.04987,-41.53792,3.02351,41.53792,22412,10
64.67580,-2.92500,-38.55697,2.89864,38.55697,22412,10
64.79080,-2.81001,-35.58448,2.78365,35.58448,22412,10
64.89880,-2.70200,-33.15853,2.67564,33.15854,22412,10
65.00680,-2.59396,-30.59797,2.56760,30.59797,22412,10
65.12379,-2.47681,-27.94726,2.45045,27.94726,22412,10
65.23180,-2.36897,-25.87112,2.34261,25.87112,22412,10
65.36280,-2.23810,-23.37876,2.21174,23.37876,22412,10
65.52980,-2.07083,-20.35877,2.04447,20.35877,22412,10
65.79080,-1.80999,-16.40082,1.78363,16.40082,22412,10
65.99080,-1.60993,-13.48272,1.58357,13.48272,22412,10
66.24920,-1.35188,-9.81718,1.32552,9.81718,22412,10
66.61980,-1.36713,-11.46688,1.34077,11.46688,22412,10
67.06680,-1.82368,-19.50939,1.79732,19.50939,22476,11
67.49180,-2.24923,-27.89768,2.22287,27.89768,22476,11
67.74920,-2.50603,-33.86971,2.47967,33.86971,22476,11
67.96180,-2.71910,-38.77994,2.69274,38.77995,22476,11
68.15880,-2.91613,-43.31581,2.88977,43.31581,22476,11
68.35480,-3.11215,-47.97209,3.08579,47.97210,22476,11
68.55780,-3.31520,-52.50276,3.28884,52.50275,22476,11
68.69980,-3.45708,-55.80021,3.43072,55.80021,22476,11
68.87580,-3.63317,-59.84807,3.60681,59.84807,22476,11
69.01180,-3.76920,-62.99794,3.74284,62.99794,22476,11
69.17880,-3.93606,-66.82533,3.90970,66.82533,22476,11
69.32680,-4.04668,-69.23817,4.02032,69.23817,22476,11
69.43380,-3.92539,-65.56650,3.89903,65.56650,22476,11
69.56680,-3.78417,-61.39892,3.75781,61.39892,22412,11
69.68980,-3.65777,-57.69931,3.63141,57.69931,22412,11
69.82480,-3.52128,-53.91740,3.49492,53.91740,22412,11
69.94920,-3.39660,-50.54360,3.37024,50.54359,22412,11
70.07180,-3.27340,-47.28430,3.24704,47.28430,22412,11
70.20580,-3.13923,-43.65999,3.11287,43.65998,22412,11
70.31380,-3.03105,-40.85825,3.00469,40.85825,22412,11
70.43480,-2.91013,-38.04837,2.88377,38.04837,22412,11
70.54080,-2.80414,-35.48778,2.77778,35.48778,22412,11
70.66380,-2.68116,-32.58494,2.65479,32.58494,22412,11
70.79380,-2.55103,-29.63869,2.52467,29.63869,22412,11
70.94920,-2.39603,-26.24956,2.36967,26.24956,22412,11
71.15580,-2.18912,-22.43223,2.16275,22.43223,22412,11
71.51980,-1.82510,-16.55959,1.79874,16.55959,22412,11
72.05780,-1.28715,-8.74495,1.26079,8.74495,22412,11
72.50880,-1.54097,-14.44932,1.51461,14.44932,22476,11
72.92180,-1.95724,-21.99813,1.93088,21.99813,22476,12
73.21580,-2.25159,-27.91465,2.22523,27.91465,22476,12
73.37780,-2.41334,-31.52635,2.38698,31.52635,22476,12
73.54920,-2.58450,-35.49273,2.55814,35.49273,22476,12
73.69080,-2.72650,-38.84095,2.70014,38.84095,22476,12
73.81780,-2.85353,-41.74531,2.82717,41.74531,22476,12
73.95780,-2.99338,-44.99425,2.96701,44.99425,22476,12
74.13680,-3.17269,-49.13210,3.14633,49.13211,22476,12
74.30280,-3.33848,-52.95875,3.31212,52.95875,22476,12
74.44920,-3.48450,-56.35422,3.45814,56.35423,22476,12
74.59580,-3.63154,-59.73267,3.60518,59.73267,22476,12
74.77580,-3.81154,-63.90437,3.78518,63.90437,22476,12
74.92280,-3.95844,-67.32137,3.93208,67.32137,22476,12
75.05980,-4.05611,-69.40647,4.02975,69.40647,22476,12
75.19180,-3.90753,-64.88659,3.88117,64.88659,22476,12
75.32280,-3.76961,-60.83396,3.74325,60.83396,22412,12
75.45780,-3.63155,-56.93416,3.60519,56.93416,22412,12
75.57980,-3.50841,-53.47859,3.48205,53.47860,22412,12
75.71480,-3.37278,-49.74907,3.34642,49.74907,22412,12
75.85480,-3.23258,-46.01926,3.20622,46.01926,22412,12
75.98480,-3.10235,-42.64315,3.07599,42.64315,22412,12
76.13280,-2.95429,-39.02647,2.92793,39.02647,22412,12
76.27780,-2.80941,-35.49347,2.78305,35.49347,22412,12
76.44480,-2.64244,-31.49318,2.61608,31.49318,22412,12
76.57980,-2.50732,-28.50647,2.48096,28.50647,22412,12
76.76680,-2.32041,-24.78325,2.29405,24.78325,22412,12
77.12380,-1.96321,-18.66824,1.93685,18.66824,22412,12
77.66980,-1.41723,-10.64918,1.39087,10.64918,22412,12
78.35180,-1.64613,-16.28666,1.61976,16.28666,22476,12
78.97180,-2.26783,-28.18086,2.24147,28.18086,22476,13
79.26780,-2.56374,-35.03638,2.53738,35.03638,22476,13
79.58280,-2.87880,-42.28674,2.85244,42.28674,22476,13
79.84920,-3.14491,-48.49205,3.11855,48.49205,22476,13
80.08080,-3.37674,-53.74322,3.35038,53.74323,22476,13
80.34980,-3.64581,-59.99206,3.61945,59.99206,22476,13
80.56180,-3.85772,-64.96594,3.83136,64.96594,22476,13
80.81180,-4.04039,-68.93050,4.01403,68.93050,22476,13
81.03180,-3.79792,-61.66633,3.77156,61.66633,22476,13
81.24180,-3.58329,-55.56085,3.55693,55.56085,22412,13
81.48280,-3.34096,-48.91615,3.31460,48.91615,22412,13
81.77080,-3.05258,-41.26565,3.02622,41.26565,22412,13
82.05180,-2.77178,-34.54198,2.74542,34.54198,22412,13
82.57680,-2.24682,-23.30828,2.22046,23.30828,22412,13
83.36580,-1.45741,-11.18024,1.43105,11.18023,22412,13
84.00280,-1.56392,-14.78075,1.53755,14.78075,22476,13
84.80680,-2.37097,-30.53713,2.34461,30.53713,22476,14
85.34920,-2.91305,-43.00653,2.88669,43.00653,22476,14
85.84920,-3.41307,-54.49910,3.38671,54.49910,22476,14
86.35780,-3.92204,-66.32273,3.89568,66.32273,22476,14
86.78880,-3.79667,-61.51990,3.77031,61.51990,22412,14
87.24920,-3.33117,-48.59516,3.30481,48.59517,22412,14
87.71280,-2.86699,-36.71263,2.84063,36.71263,22412,14
88.16880,-2.41088,-26.36382,2.38452,26.36382,22412,14
89.14920,-1.43076,-10.73781,1.40440,10.73781,22412,14
90.20580,-2.00209,-22.73086,1.97573,22.73086,22476,15
90.96980,-2.76636,-39.60758,2.74000,39.60758,22476,15
91.69680,-3.49332,-56.37937,3.46696,56.37937,22476,15
92.42280,-3.93887,-65.51941,3.91250,65.51941,22476,15
93.11280,-3.23544,-45.88860,3.20907,45.88860,22412,15
93.68280,-2.66530,-31.92351,2.63894,31.92351,22412,15
94.54920,-1.79929,-16.01523,1.77293,16.01523,22412,15
95.64780,-1.67933,-16.82182,1.65297,16.82182,22476,15
96.56080,-2.59362,-35.51032,2.56726,35.51032,22476,16
96.99280,-3.02558,-45.51686,2.99922,45.51686,22476,16
97.61280,-3.64565,-59.91279,3.61929,59.91279,22476,16
98.18980,-3.94009,-65.52266,3.91373,65.52266,22476,16
98.82580,-3.29082,-47.47743,3.26446,47.47743,22412,16
99.38280,-2.73359,-33.54349,2.70723,33.54350,22412,16
100.06580,-2.05044,-19.73650,2.02408,19.73650,22412,16
101.16780,-1.45410,-12.68719,1.42774,12.68719,22412,16
102.14920,-2.44180,-31.91284,2.41544,31.91284,22476,17
102.81980,-3.11297,-47.60385,3.08661,47.60385,22476,17
103.64180,-3.93488,-66.48086,3.90852,66.48086,22476,17
104.33380,-3.53382,-53.90594,3.50745,53.90594,22412,17
105.00380,-2.86281,-36.44871,2.83645,36.44872,22412,17
105.87580,-1.99071,-18.83964,1.96435,18.83964,22412,17
106.97180,-1.50428,-13.60941,1.47792,13.60941,22604,17
108.01980,-2.55722,-34.63792,2.53086,34.63792,22604,18
108.80080,-3.33818,-52.69197,3.31182,52.69197,22604,18
109.59580,-4.05282,-68.89246,4.02645,68.89246,22604,18
110.24920,-3.37243,-49.48094,3.34607,49.48094,22540,18
110.96780,-2.65312,-31.42101,2.62676,31.42101,22540,18
111.85480,-1.76616,-15.34960,1.73980,15.34960,22540,18
112.86280,-1.65467,-16.18158,1.62831,16.18158,22604,18
113.80280,-2.59638,-35.45487,2.57002,35.45486,22604,19
114.31580,-3.10938,-47.47054,3.08302,47.47054,22604,19
114.86080,-3.65440,-60.04170,3.62804,60.04170,22604,19
115.34680,-4.01583,-67.81358,3.98947,67.81358,22604,19
115.77580,-3.56463,-54.78558,3.53826,54.78558,22540,19
116.18380,-3.15545,-43.65797,3.12909,43.65797,22540,19
116.65780,-2.68134,-32.09520,2.65498,32.09520,22540,19
117.22980,-2.10925,-20.65739,2.08289,20.65739,22540,19
118.29180,-1.20501,-7.46262,1.17865,7.46262,22540,19
119.38080,-2.04530,-23.57745,2.01894,23.57745,22476,20
119.90280,-2.56734,-34.91559,2.54098,34.91559,22476,20
120.46280,-3.12745,-47.95356,3.10109,47.95356,22476,20
120.99180,-3.65640,-60.06762,3.63004,60.06762,22476,20
121.46180,-4.04822,-68.83556,4.02186,68.83556,22476,20
121.91580,-3.56748,-54.85765,3.54112,54.85765,22412,20
122.25380,-3.22835,-45.59809,3.20199,45.59809,22412,20
122.71980,-2.76227,-34.02984,2.73591,34.02984,22412,20
123.30080,-2.18119,-21.93739,2.15483,21.93739,22412,20
124.24980,-1.23236,-7.59026,1.20600,7.59026,22412,20
125.26780,-2.20838,-26.64119,2.18202,26.64119,22476,21
126.04920,-2.98945,-44.57380,2.96309,44.57380,22476,21
126.90780,-3.84831,-64.52855,3.82195,64.52856,22476,21
127.55980,-3.65257,-57.22315,3.62621,57.22315,22412,21
128.19480,-3.01527,-39.93443,2.98891,39.93443,22412,21
128.89780,-2.31236,-24.21157,2.28600,24.21157,22412,21
130.00180,-1.20899,-7.16881,1.18263,7.16881,22412,21
131.02980,-2.22657,-27.06430,2.20021,27.06430,22476,22
131.80980,-3.00653,-44.89370,2.98017,44.89370,22476,22
132.53880,-3.73543,-61.88332,3.70907,61.88332,22476,22
133.14920,-3.80758,-61.59817,3.78122,61.59817,22476,22
133.65480,-3.29573,-47.50564,3.26937,47.50564,22412,22
133.99880,-2.95143,-38.49418,2.92507,38.49418,22412,22
134.47780,-2.47235,-27.31185,2.44599,27.31185,22412,22
135.27580,-1.67452,-13.92387,1.64816,13.92387,22412,22
136.34920,-1.84934,-19.55163,1.82298,19.55163,22476,23
137.16880,-2.66985,-37.10236,2.64349,37.10236,22476,23
137.63080,-3.13202,-47.90537,3.10566,47.90537,22476,23
137.99680,-3.49787,-56.35959,3.47151,56.35958,22476,23
138.39580,-3.89679,-65.60959,3.87043,65.60959,22476,23
138.84480,-3.80371,-61.39926,3.77735,61.39926,22412,23
139.30680,-3.33591,-48.49956,3.30955,48.49956,22412,23
139.75280,-2.88971,-36.87663,2.86335,36.87663,22412,23
140.13080,-2.51164,-28.10296,2.48528,28.10296,22412,23
140.90580,-1.73676,-14.87564,1.71039,14.87564,22412,23
141.75780,-1.53881,-14.01906,1.51245,14.01906,22476,23
142.39180,-2.17699,-25.97872,2.15063,25.97872,22476,24
142.74919,-2.53395,-33.98045,2.50759,33.98045,22476,24
143.05180,-2.83702,-40.90066,2.81066,40.90065,22476,24
143.46480,-3.25014,-50.55267,3.22378,50.55267,22476,24
143.89380,-3.67886,-60.42192,3.65249,60.42192,22476,24
144.31478,-4.07439,-69.58578,4.04802,69.58578,22476,24
144.73580,-3.62881,-56.48672,3.60245,56.48672,22412,24
145.13280,-3.23001,-45.53542,3.20365,45.53542,22412,24
145.59480,-2.76795,-33.99808,2.74159,33.99808,22412,24
146.14980,-2.21286,-22.33689,2.18650,22.33689,22412,24
147.25480,-1.30211,-9.39458,1.27574,9.39458,22412,24
148.24919,-2.31412,-28.86762,2.28776,28.86761,22476,25
148.60280,-2.66819,-37.01608,2.64183,37.01608,22476,25
148.99280,-3.05812,-46.08705,3.03176,46.08704,22476,25
149.37580,-3.44110,-54.94292,3.41474,54.94292,22476,25
149.76280,-3.82811,-63.99027,3.80175,63.99026,22476,25
150.10180,-3.98383,-66.73934,3.95747,66.73933,22476,25
150.58180,-3.48571,-52.55559,3.45935,52.55560,22412,25
151.07280,-2.99388,-39.42538,2.96752,39.42538,22412,25
151.49380,-2.57289,-29.47245,2.54653,29.47245,22412,25
152.14920,-1.91790,-17.52391,1.89154,17.52390,22412,25
153.02480,-1.38483,-11.15015,1.35847,11.15015,22412,25
153.93280,-2.30430,-28.64176,2.27794,28.64176,22476,26
154.55580,-2.92730,-42.97358,2.90094,42.97358,22476,26
155.11180,-3.48330,-55.92705,3.45693,55.92704,22476,26
155.68480,-4.05631,-69.27335,4.02995,69.27335,22476,26
156.16780,-3.61690,-56.06873,3.59054,56.06873,22412,26
156.69980,-3.08301,-41.60351,3.05665,41.60350,22412,26
157.23480,-2.54805,-28.85048,2.52169,28.85048,22412,26
158.29780,-1.48500,-11.20622,1.45864,11.20622,22412,26
159.33480,-1.98620,-22.17029,1.95984,22.17029,22476,27
160.06980,-2.72143,-38.26652,2.69507,38.26652,22476,27
160.48080,-3.13264,-47.90927,3.10628,47.90928,22476,27
160.94480,-3.59645,-58.52803,3.57009,58.52803,22476,27
161.37480,-4.02649,-68.50768,4.00013,68.50768,22476,27
161.65780,-3.86349,-63.11823,3.83713,63.11823,22476,27
162.03180,-3.48196,-52.34043,3.45560,52.34043,22412,27
162.37780,-3.13540,-42.98290,3.10904,42.98290,22412,27
162.73880,-2.77438,-34.03079,2.74802,34.03079,22412,27
163.22180,-2.29139,-23.69331,2.26503,23.69331,22412,27
164.27480,-1.23852,-7.44743,1.21216,7.44743,22412,27
165.28480,-2.20646,-26.51486,2.18009,26.51486,22604,28
165.98280,-2.90458,-42.43735,2.87822,42.43735,22604,28
166.74919,-3.67046,-60.25962,3.64409,60.25962,22604,28
167.32780,-3.91512,-64.59513,3.88876,64.59513,22604,28
167.93280,-3.29864,-47.51724,3.27228,47.51724,22540,28
168.54919,-2.68245,-31.81196,2.65609,31.81196,22540,28
169.62980,-1.60139,-12.81842,1.57503,12.81842,22540,28
170.74919,-1.95233,-21.41083,1.92597,21.41083,22604,29
171.66080,-2.86481,-41.48438,2.83845,41.48438,22604,29
172.47780,-3.68154,-60.49455,3.65518,60.49454,22604,29
173.17080,-3.79181,-61.03299,3.76544,61.03299,22540,29
173.84920,-3.10847,-42.21990,3.08211,42.21990,22540,29
174.68680,-2.27062,-23.25595,2.24426,23.25595,22540,29
175.75180,-1.21399,-7.04709,1.18763,7.04709,22540,29
176.85080,-1.92826,-21.12279,1.90190,21.12279,22476,29
177.57180,-2.64962,-36.67326,2.62326,36.67326,22476,30
177.99180,-3.06949,-46.43080,3.04312,46.43081,22476,30
178.40780,-3.48547,-56.07858,3.45911,56.07858,22476,30
178.74919,-3.82639,-63.93499,3.80003,63.93499,22476,30
179.05980,-4.03325,-68.32027,4.00689,68.32027,22476,30
179.41280,-3.65660,-57.24177,3.63024,57.24177,22412,30
179.83580,-3.23147,-45.62235,3.20511,45.62235,22412,30
180.35280,-2.71428,-32.59463,2.68792,32.59463,22412,30
180.96980,-2.09719,-20.19193,2.07083,20.19193,22412,30
181.98780,-1.36388,-10.56989,1.33752,10.56989,22412,30
182.95880,-2.34857,-29.61622,2.32221,29.61622,22476,31
183.60280,-2.99260,-44.49268,2.96624,44.49268,22476,31
184.09780,-3.48763,-56.02519,3.46127,56.02519,22476,31
184.48480,-3.87454,-65.03903,3.84817,65.03903,22476,31
184.82978,-3.94962,-65.71218,3.92326,65.71217,22476,31
185.17180,-3.59491,-55.46559,3.56855,55.46559,22412,31
185.52680,-3.23855,-45.77694,3.21219,45.77694,22412,31
185.80680,-2.95826,-38.34325,2.93190,38.34325,22412,31
186.18480,-2.58032,-29.44203,2.55395,29.44203,22412,31
186.84920,-1.91631,-17.37461,1.88995,17.37461,22412,31
187.71778,-1.39234,-11.18281,1.36598,11.18281,22412,31
188.52980,-2.21572,-26.65987,2.18936,26.65987,22476,32
188.89878,-2.58472,-35.10219,2.55836,35.10219,22476,32
189.28878,-2.97472,-44.13937,2.94835,44.13937,22476,32
189.74880,-3.43472,-54.72811,3.40835,54.72811,22476,32
190.05178,-3.73756,-61.85837,3.71119,61.85838,22476,32
190.41378,-4.07271,-69.55028,4.04635,69.55029,22476,32
190.76280,-3.69964,-58.34785,3.67328,58.34785,22412,32
191.21080,-3.24880,-46.10652,3.22244,46.10652,22412,32
191.56780,-2.89159,-36.67098,2.86523,36.67097,22412,32
192.10580,-2.35358,-24.75473,2.32722,24.75473,22412,32
193.21978,-1.23976,-7.45589,1.21340,7.45589,22412,32
194.18080,-2.15889,-25.50689,2.13252,25.50689,22476,33
194.68978,-2.66794,-36.99682,2.64158,36.99681,22476,33
195.19480,-3.17309,-48.72475,3.14673,48.72475,22476,33
195.63080,-3.60881,-58.81600,3.58245,58.81601,22476,33
196.12980,-4.07419,-69.53374,4.04783,69.53374,22476,33
196.45180,-3.72727,-59.13498,3.70091,59.13498,22412,33
196.83980,-3.33590,-48.46443,3.30954,48.46443,22412,33
197.16178,-3.01362,-39.72248,2.98726,39.72248,22412,33
197.53080,-2.64475,-30.80889,2.61839,30.80889,22412,33
198.28780,-1.88771,-16.85058,1.86135,16.85058,22412,33
199.12580,-1.38635,-11.02350,1.35999,11.02350,22412,33
199.84180,-2.11395,-24.60267,2.08759,24.60267,22476,34
200.17580,-2.44788,-31.84475,2.42152,31.84475,22476,34
200.44919,-2.72106,-38.20390,2.69470,38.20390,22476,34
200.78580,-3.05801,-45.99931,3.03165,45.99931,22476,34
201.04580,-3.31810,-52.07031,3.29174,52.07031,22476,34
201.30680,-3.57904,-58.11479,3.55268,58.11479,22476,34
201.58180,-3.85391,-64.60050,3.82755,64.60049,22476,34
201.84920,-4.06853,-69.31096,4.04217,69.31097,22476,34
202.24919,-3.64087,-56.68714,3.61451,56.68714,22412,34
202.67678,-3.21094,-45.02676,3.18458,45.02676,22412,34
203.01780,-2.86984,-36.00356,2.84348,36.00356,22412,34
203.52480,-2.36279,-24.83667,2.33643,24.83667,22412,34
204.48780,-1.39983,-9.82014,1.37347,9.82014,22412,34
205.47780,-2.04005,-23.08723,2.01368,23.08722,22476,35
206.17878,-2.74121,-38.70851,2.71485,38.70851,22476,35
206.75878,-3.32125,-52.14913,3.29488,52.14913,22476,35
207.48680,-4.04913,-69.04325,4.02277,69.04325,22476,35
207.94480,-3.64319,-56.76135,3.61683,56.76134,22412,35
208.40880,-3.17715,-44.11280,3.15078,44.11280,22412,35
208.86580,-2.72002,-32.47821,2.69366,32.47821,22412,35
209.64920,-1.93695,-17.60057,1.91059,17.60057,22412,35
210.63980,-1.53102,-13.61695,1.50466,13.61695,22476,35
211.47880,-2.37521,-30.22772,2.34885,30.22772,22476,36
211.97180,-2.86843,-41.51287,2.84207,41.51287,22476,36
212.33480,-3.23146,-50.00011,3.20510,50.00011,22476,36
212.69880,-3.59528,-58.39954,3.56892,58.39954,22476,36
212.93380,-3.83023,-64.00588,3.80387,64.00588,22476,36
213.21080,-4.08178,-69.74493,4.05542,69.74493,22476,36
213.52180,-3.74816,-59.67368,3.72180,59.67368,22412,36
213.94919,-3.31732,-47.92747,3.29096,47.92747,22412,36
214.38480,-2.88113,-36.29601,2.85477,36.29601,22412,36
215.02680,-2.23921,-22.43344,2.21285,22.43344,22412,36
216.04919,-1.24310,-7.52384,1.21674,7.52384,22412,36
216.86980,-2.09020,-24.04368,2.06384,24.04368,22476,37
217.45580,-2.67640,-37.17024,2.65004,37.17024,22476,37
218.13778,-3.35835,-52.94099,3.33199,52.94099,22476,37
218.69680,-3.91726,-66.00361,3.89090,66.00362,22476,37
219.10778,-3.84539,-62.55748,3.81903,62.55748,22476,37
219.55680,-3.38953,-49.84563,3.36317,49.84563,22412,37
219.97980,-2.96601,-38.53352,2.93965,38.53352,22412,37
220.63080,-2.31512,-23.82749,2.28876,23.82749,22412,37
221.64920,-1.29718,-8.23372,1.27082,8.23372,22412,37
222.44919,-1.98712,-22.05475,1.96076,22.05475,22604,37
222.97780,-2.51648,-33.48573,2.49012,33.48573,22604,38
223.41480,-2.95345,-43.60563,2.92709,43.60563,22604,38
223.88980,-3.42845,-54.56604,3.40209,54.56604,22604,38
224.27080,-3.80934,-63.50318,3.78298,63.50319,22604,38
224.62680,-4.00389,-67.27286,3.97753,67.27286,22604,38
224.89680,-3.71664,-58.82814,3.69028,58.82814,22540,38
225.14780,-3.46283,-51.86176,3.43647,51.86176,22540,38
225.32680,-3.28352,-47.11826,3.25716,47.11826,22540,38
225.57180,-3.03820,-40.29710,3.01184,40.29710,22540,38
225.76380,-2.84628,-35.36535,2.81992,35.36535,22540,38
225.98380,-2.62634,-30.25478,2.59998,30.25478,22540,38
226.22280,-2.38726,-25.19654,2.36090,25.19654,22540,38
226.51278,-2.09721,-19.99613,2.07085,19.99613,22540,38
227.09980,-1.51022,-11.42019,1.48386,11.42019,22540,38
227.73180,-1.57901,-14.49856,1.55264,14.49856,22604,38
228.34920,-2.19964,-26.41273,2.17328,26.41273,22604,39
228.76680,-2.61767,-35.76837,2.59131,35.76837,22604,39
229.14180,-2.99257,-44.54551,2.96620,44.54551,22604,39
229.65580,-3.50665,-56.45490,3.48029,56.45490,22604,39
230.04919,-3.89950,-65.59458,3.87314,65.59458,22604,39
230.50080,-3.81152,-61.61619,3.78516,61.61618,22604,39
230.81980,-3.48716,-52.54522,3.46080,52.54522,22540,39
231.35880,-2.94736,-37.94332,2.92100,37.94332,22540,39
231.94919,-2.35742,-24.56444,2.33106,24.56444,22540,39
232.98080,-1.32540,-8.69830,1.29904,8.69830,22540,39
233.98478,-1.74551,-17.69477,1.71915,17.69477,22476,39
234.77980,-2.54094,-34.23961,2.51458,34.23961,22476,40
235.54480,-3.30608,-52.01109,3.27972,52.01109,22476,40
236.33280,-4.08259,-69.88358,4.05623,69.88358,22476,40
236.89580,-3.50158,-52.83812,3.47521,52.83812,22412,40
237.39180,-3.00469,-39.56956,2.97833,39.56956,22412,40
238.07580,-2.32075,-23.75773,2.29439,23.75773,22412,40
239.28780,-1.34096,-9.94819,1.31460,9.94819,22412,40
240.25380,-2.32299,-29.09765,2.29663,29.09765,22476,41
241.04780,-3.11715,-47.58082,3.09079,47.58081,22476,41
241.67080,-3.73989,-61.95676,3.71353,61.95676,22476,41
242.24880,-3.84534,-62.62495,3.81898,62.62495,22476,41
242.67180,-3.41523,-50.59503,3.38886,50.59503,22412,41
242.98780,-3.09879,-42.02546,3.07243,42.02546,22412,41
243.29280,-2.79387,-34.12109,2.76751,34.12109,22412,41
243.63378,-2.45266,-26.43190,2.42630,26.43190,22412,41
244.37580,-1.71083,-14.15340,1.68447,14.15340,22412,41
245.24919,-1.61951,-15.24709,1.59315,15.24709,22476,41
245.96180,-2.33514,-29.33963,2.30878,29.33963,22476,42
246.26780,-2.64125,-36.43294,2.61489,36.43294,22476,42
246.49180,-2.86516,-41.58910,2.83880,41.58910,22476,42
246.68080,-3.05412,-46.02070,3.02776,46.02070,22476,42
246.90680,-3.28033,-51.31548,3.25396,51.31548,22476,42
247.15078,-3.52421,-56.91683,3.49785,56.91683,22476,42
247.41578,-3.78913,-63.10385,3.76277,63.10386,22476,42
247.70678,-4.07907,-69.80854,4.05271,69.80853,22476,42
247.99778,-3.79850,-61.20572,3.77214,61.20572,22412,42
248.31580,-3.47561,-52.19853,3.44925,52.19853,22412,42
248.56180,-3.22919,-45.48706,3.20283,45.48706,22412,42
248.83580,-2.95492,-38.14829,2.92856,38.14829,22412,42
249.06080,-2.73006,-32.46471,2.70370,32.46471,22412,42
249.28480,-2.50596,-27.42116,2.47960,27.42116,22412,42
249.57580,-2.21504,-21.97866,2.18868,21.97866,22412,42
250.03180,-1.75916,-14.84928,1.73280,14.84928,22412,42
250.46280,-1.32798,-8.66415,1.30162,8.66415,22412,42
250.94178,-1.63880,-15.53016,1.61244,15.53016,22476,42
251.44919,-2.14826,-25.31316,2.12190,25.31316,22476,43
251.75280,-2.45215,-32.01560,2.42579,32.01560,22476,43
252.04980,-2.74934,-39.05767,2.72298,39.05767,22476,43
252.34920,-3.04830,-45.77998,3.02194,45.77998,22476,43
252.64180,-3.34130,-52.64714,3.31494,52.64714,22476,43
252.95780,-3.65721,-60.07176,3.63085,60.07176,22476,43
253.28380,-3.98316,-67.53581,3.95680,67.53581,22476,43
253.68580,-3.75570,-60.04084,3.72933,60.04084,22412,43
253.98380,-3.45356,-51.59607,3.42720,51.59607,22412,43
254.37780,-3.05894,-40.95007,3.03258,40.95007,22412,43
254.81380,-2.62312,-30.03423,2.59676,30.03423,22412,43
255.44919,-1.98796,-18.23637,1.96160,18.23637,22412,43
256.30680,-1.33061,-9.61583,1.30425,9.61583,22412,43
256.97980,-2.02111,-22.70013,1.99475,22.70013,22476,44
257.35980,-2.40127,-30.84387,2.37491,30.84387,22476,44
257.62078,-2.66240,-36.98965,2.63604,36.98965,22476,44
257.93078,-2.97236,-44.11418,2.94600,44.11418,22476,44
258.16980,-3.21156,-49.68008,3.18520,49.68008,22476,44
258.35181,-3.39339,-53.87869,3.36703,53.87869,22476,44
258.63181,-3.67319,-60.42651,3.64683,60.42651,22476,44
258.88880,-3.93027,-66.37182,3.90390,66.37182,22476,44
259.15280,-3.96648,-66.15852,3.94012,66.15852,22476,44
259.44919,-3.65652,-57.16463,3.63016,57.16463,22412,44
259.74780,-3.35550,-48.98214,3.32914,48.98214,22412,44
260.04919,-3.05406,-40.76814,3.02770,40.76814,22412,44
260.46780,-2.63525,-30.21548,2.60889,30.21548,22412,44
260.92380,-2.17919,-21.21173,2.15283,21.21173,22412,44
261.94919,-1.29663,-8.78042,1.27027,8.78042,22412,44
262.94919,-2.31847,-29.03581,2.29210,29.03581,22476,45
263.48981,-2.85957,-41.59077,2.83321,41.59077,22476,45
264.06778,-3.43753,-54.94352,3.41117,54.94352,22476,45
264.71878,-4.07622,-69.75394,4.04986,69.75394,22476,45
265.13981,-3.63746,-56.72115,3.61110,56.72115,22412,45
265.54919,-3.22653,-45.47777,3.20017,45.47777,22412,45
265.94878,-2.82637,-34.82257,2.80001,34.82257,22412,45
266.54919,-2.22643,-22.10741,2.20007,22.10741,22412,45
267.64919,-1.33120,-9.56662,1.30484,9.56662,22412,45
268.53181,-2.23170,-27.06931,2.20534,27.06931,22476,46
268.98278,-2.68275,-37.55959,2.65639,37.55959,22476,46
269.59281,-3.29285,-51.68128,3.26649,51.68128,22476,46
270.40681,-4.07134,-69.48537,4.04498,69.48537,22476,46
270.96478,-3.48525,-52.44588,3.45889,52.44588,22412,46
271.55881,-2.89058,-36.57241,2.86422,36.57241,22412,46
272.31778,-2.13155,-20.36845,2.10519,20.36845,22412,46
273.44919,-1.46295,-12.39052,1.43659,12.39052,22412,46
274.51378,-2.53583,-34.14254,2.50947,34.14254,22476,47
275.04919,-3.07085,-46.48747,3.04449,46.48747,22476,47
275.67778,-3.69969,-61.02241,3.67333,61.02241,22476,47
276.14178,-3.99790,-67.23102,3.97154,67.23102,22476,47
276.48881,-3.63267,-56.54054,3.60631,56.54054,22412,47
276.97078,-3.14875,-43.47250,3.12239,43.47250,22412,47
277.39778,-2.72162,-32.03287,2.69526,32.03287,22412,47
277.98578,-2.13366,-20.36360,2.10730,20.36360,22412,47
279.22981,-1.59237,-14.70054,1.56601,14.70054,22604,47
280.02278,-2.38881,-30.65376,2.36245,30.65376,22604,48
280.57878,-2.94498,-43.56401,2.91862,43.56401,22604,48
281.24781,-3.61390,-58.99325,3.58754,58.99326,22604,48
281.72581,-4.06794,-69.49014,4.04158,69.49014,22604,48
282.17481,-3.59431,-55.51098,3.56795,55.51098,22540,48
282.76178,-3.00562,-39.62186,2.97926,39.62186,22540,48
283.18781,-2.57964,-28.88824,2.55328,28.88824,22540,48
283.87578,-1.89170,-16.68766,1.86534,16.68766,22540,48
284.90978,-1.62920,-15.31815,1.60284,15.31815,22604,48
285.60581,-2.32789,-29.24224,2.30153,29.24224,22604,49
285.93178,-2.65405,-36.86428,2.62769,36.86428,22604,49
286.26081,-2.98287,-44.47596,2.95651,44.47596,22604,49
286.78078,-3.50295,-56.61602,3.47659,56.61602,22604,49
287.16081,-3.88288,-65.51867,3.85651,65.51867,22604,49
287.50181,-3.92270,-65.12339,3.89634,65.12339,22604,49
287.83078,-3.58221,-55.36272,3.55585,55.36272,22540,49
288.28181,-3.12975,-43.12207,3.10339,43.12207,22540,49
288.70678,-2.70467,-31.82407,2.67831,31.82407,22540,49
289.15781,-2.25381,-22.38238,2.22745,22.38238,22540,49
290.13478,-1.27683,-7.77959,1.25047,7.77959,22540,49
291.01378,-1.71649,-17.11084,1.69013,17.11084,22476,49
291.70378,-2.40708,-31.21829,2.38072,31.21829,22476,50
292.20881,-2.91225,-43.11189,2.88589,43.11189,22476,50
292.64678,-3.35015,-53.07802,3.32379,53.07802,22476,50
293.03078,-3.73402,-62.03558,3.70766,62.03558,22476,50
293.35181,-4.05515,-69.47664,4.02878,69.47664,22476,50
293.73481,-3.70318,-58.70034,3.67682,58.70034,22412,50
294.15878,-3.27625,-47.10659,3.24989,47.10659,22412,50
294.60581,-2.82898,-35.11165,2.80262,35.11165,22412,50
294.98578,-2.44882,-26.04805,2.42246,26.04806,22412,50
295.49781,-1.93687,-17.29331,1.91051,17.29331,22412,50
296.26678,-1.29049,-8.56134,1.26413,8.56134,22412,50
296.87681,-1.92382,-20.73167,1.89746,20.73167,22476,51
297.23481,-2.28225,-28.15379,2.25588,28.15379,22476,51
297.43478,-2.48202,-32.81125,2.45566,32.81124,22476,51
297.72078,-2.76838,-39.57073,2.74202,39.57073,22476,51
297.99781,-3.04530,-45.85734,3.01894,45.85735,22476,51
298.43578,-3.48322,-56.07795,3.45686,56.07795,22476,51
298.98778,-4.03523,-68.82079,4.00887,68.82079,22476,51
299.39381,-3.72027,-59.06327,3.69391,59.06327,22412,51
299.83078,-3.28018,-47.00183,3.25382,47.00183,22412,51
300.25181,-2.85894,-35.68955,2.83258,35.68955,22412,51
300.92381,-2.18692,-21.24742,2.16056,21.24742,22412,51
301.89178,-1.24807,-7.45785,1.22171,7.45785,22412,51
302.76178,-2.14512,-25.19556,2.11876,25.19556,22476,52
303.27078,-2.65429,-36.72590,2.62793,36.72591,22476,52
303.69278,-3.07619,-46.55911,3.04983,46.55910,22476,52
304.44919,-3.83206,-64.00090,3.80570,64.00090,22476,52
305.06281,-3.70908,-58.72386,3.68272,58.72385,22412,52
305.50581,-3.26318,-46.56959,3.23682,46.56959,22412,52
305.94919,-2.81990,-34.75514,2.79354,34.75514,22412,52
306.59378,-2.17493,-20.97031,2.14857,20.97031,22412,52
307.49578,-1.27306,-7.65195,1.24669,7.65195,22412,52
308.40578,-2.14116,-25.17306,2.11480,25.17306,22476,53
308.97878,-2.71421,-38.23516,2.68785,38.23516,22476,53
309.64578,-3.38124,-53.58108,3.35487,53.58108,22476,53
310.31281,-4.04825,-69.11157,4.02188,69.11157,22476,53
310.83478,-3.57937,-55.12282,3.55301,55.12282,22412,53
311.35081,-3.06183,-41.10762,3.03547,41.10762,22412,53
311.81878,-2.59395,-29.09117,2.56759,29.09117,22412,53
312.74922,-1.66406,-13.29852,1.63770,13.29852,22412,53
313.76678,-1.84356,-19.18649,1.81720,19.18649,22476,53
314.35378,-2.43106,-31.51325,2.40470,31.51325,22476,54
314.78778,-2.86519,-41.65520,2.83883,41.65520,22476,54
315.16181,-3.23937,-50.29299,3.21301,50.29300,22476,54
315.48081,-3.55821,-57.67024,3.53185,57.67023,22476,54
315.77978,-3.85705,-64.79649,3.83069,64.79649,22476,54
315.99178,-4.05894,-69.43338,4.03258,69.43337,22476,54
316.20178,-3.83940,-62.69530,3.81304,62.69530,22476,54
316.39278,-3.64247,-57.00984,3.61611,57.00984,22412,54
316.61078,-3.42252,-50.92542,3.39615,50.92542,22412,54
316.82378,-3.20916,-45.22200,3.18280,45.22200,22412,54
316.98378,-3.04893,-40.85128,3.02257,40.85128,22412,54
317.15578,-2.87707,-36.36399,2.85071,36.36399,22412,54
317.30178,-2.73106,-32.54857,2.70470,32.54857,22412,54
317.41478,-2.61810,-29.62865,2.59174,29.62865,22412,54
317.54678,-2.48594,-26.78283,2.45958,26.78283,22412,54
317.72581,-2.30707,-23.33820,2.28071,23.33820,22412,54
317.96381,-2.06892,-19.30213,2.04256,19.30213,22412,54
318.23378,-1.79908,-15.23917,1.77272,15.23917,22412,54
318.51178,-1.52096,-11.33575,1.49460,11.33575,22412,54
318.81681,-1.26716,-7.82469,1.24080,7.82469,22412,54
319.27381,-1.75219,-17.45494,1.72583,17.45494,22476,54
319.61678,-2.09621,-24.09735,2.06985,24.09735,22476,55
319.81181,-2.29144,-28.22100,2.26508,28.22100,22476,55
319.96878,-2.44823,-31.91107,2.42187,31.91107,22476,55
320.23378,-2.71334,-38.10816,2.68698,38.10816,22476,55
320.48481,-2.96436,-44.06084,2.93800,44.06084,22476,55
320.74381,-3.22355,-50.02988,3.19719,50.02988,22476,55
321.00581,-3.48536,-56.03862,3.45900,56.03862,22476,55
321.30478,-3.78433,-63.06361,3.75797,63.06361,22476,55
321.62978,-4.05695,-69.16056,4.03059,69.16056,22476,55
321.94919,-3.71158,-58.84530,3.68522,58.84530,22412,55
322.35481,-3.30241,-47.75881,3.27605,47.75881,22412,55
322.82778,-2.82917,-35.00867,2.80281,35.00867,22412,55
323.65781,-1.99913,-18.28775,1.97277,18.28775,22412,55
324.61478,-1.46149,-12.11762,1.43513,12.11762,22412,55
325.47378,-2.32943,-29.06975,2.30307,29.06975,22476,56
325.91981,-2.77559,-39.57120,2.74923,39.57121,22476,56
326.40781,-3.26371,-50.98052,3.23735,50.98052,22476,56
326.94778,-3.80352,-63.58812,3.77716,63.58812,22476,56
327.46078,-3.83770,-62.54982,3.81133,62.54982,22476,56
327.94919,-3.34252,-48.76137,3.31616,48.76137,22412,56
328.40578,-2.88534,-36.54203,2.85897,36.54203,22412,56
329.01578,-2.27544,-22.75541,2.24908,22.75541,22412,56
330.04919,-1.24522,-7.21009,1.21886,7.21009,22412,56
331.04378,-2.24363,-27.11323,2.21727,27.11323,22476,57
331.66478,-2.86460,-41.56828,2.83824,41.56828,22476,57
332.34919,-3.54863,-57.46254,3.52227,57.46254,22476,57
332.91081,-4.06594,-69.48709,4.03958,69.48709,22476,57
333.40878,-3.53946,-54.03789,3.51310,54.03789,22412,57
334.06078,-2.88635,-36.48464,2.85999,36.48464,22412,57
334.88778,-2.05919,-19.07221,2.03283,19.07221,22412,57
336.05678,-1.59108,-14.54930,1.56472,14.54930,22604,57
336.85481,-2.39258,-30.58827,2.36621,30.58827,22604,58
337.33381,-2.87167,-41.72576,2.84531,41.72576,22604,58
337.79278,-3.33070,-52.52678,3.30434,52.52678,22604,58
338.52178,-4.05964,-69.45844,4.03328,69.45844,22604,58
339.14919,-3.47511,-52.27251,3.44875,52.27251,22540,58
339.75878,-2.86454,-35.94857,2.83818,35.94857,22540,58
340.54919,-2.07438,-19.26528,2.04802,19.26528,22540,58
341.54919,-1.38831,-10.66974,1.36194,10.66974,22540,58
342.53778,-2.38976,-30.51215,2.36340,30.51215,22604,59
343.14919,-3.00086,-44.81067,2.97450,44.81067,22604,59
343.84919,-3.70072,-61.09624,3.67436,61.09624,22604,59
344.54481,-3.74904,-59.96053,3.72268,59.96053,22540,59
345.06778,-3.22180,-45.51636,3.19544,45.51636,22540,59
345.73678,-2.55260,-28.13233,2.52624,28.13233,22540,59
346.94181,-1.34762,-8.68863,1.32126,8.68863,22540,59
347.10878,-1.22649,-6.96289,1.20012,6.96289,22540,59