File: data-raw/Experiment 2/Results/INSTRON data/Experiment 2.is_ccyclic_RawData/Specimen_RawData_24.csv
Text Inputs : Specimen label,"Short Plate 1 T6"

Time,Extension,Load,Compressive extension,Compressive load,Segment ID,Total Cycle Count
(sec),(mm),(N),(mm),(N),,
0.00000,-0.02564,-0.00928,0.00000,0.00928,12835,0
0.63920,-0.02564,0.03380,0.00000,-0.03380,12835,0
1.14080,-0.02564,0.02186,0.00000,-0.02186,3220,0
1.61080,-0.24969,0.03475,0.22405,-0.03475,3220,0
2.43920,-0.66421,-0.00116,0.63857,0.00116,3220,0
3.23920,-1.06426,0.01046,1.03862,-0.01046,3220,0
3.92880,-1.40912,0.00196,1.38348,-0.00196,3220,0
4.41680,-1.65325,0.03076,1.62761,-0.03076,3220,0
4.93680,-1.91310,0.03173,1.88746,-0.03173,3220,0
5.53920,-2.21431,0.05854,2.18867,-0.05854,3220,0
5.87280,-2.38113,0.06301,2.35549,-0.06301,3220,0
6.31680,-2.60327,0.02969,2.57763,-0.02969,3220,0
6.98480,-2.93720,-2.82913,2.91156,2.82913,3220,0
7.77780,-3.51851,-13.22239,3.49287,13.22239,22476,0
8.54580,-4.28719,-25.09852,4.26155,25.09852,22476,0
9.10380,-4.84526,-36.38638,4.81962,36.38638,22476,0
9.60080,-5.34231,-47.20976,5.31667,47.20976,22476,0
10.15980,-5.90112,-58.96629,5.87548,58.96629,22476,0
10.69980,-6.41699,-69.71518,6.39135,69.71518,22476,0
11.07580,-6.01760,-55.59547,5.99195,55.59547,22412,0
11.50080,-5.59034,-42.59071,5.56470,42.59071,22412,0
11.98980,-5.10120,-29.80365,5.07556,29.80365,22412,0
12.64480,-4.44611,-17.14150,4.42047,17.14150,22412,0
13.41680,-3.80342,-8.93838,3.77778,8.93838,22412,0
14.02480,-4.43392,-21.96975,4.40828,21.96976,22476,1
14.52180,-4.93121,-33.53646,4.90557,33.53646,22476,1
15.03920,-5.44826,-45.76736,5.42262,45.76736,22476,1
15.56780,-5.97723,-57.95253,5.95158,57.95253,22476,1
16.06580,-6.47535,-69.24383,6.44971,69.24384,22476,1
16.45180,-6.13444,-56.53848,6.10880,56.53848,22412,1
16.87080,-5.71250,-43.48861,5.68686,43.48861,22412,1
17.37180,-5.21132,-30.22813,5.18568,30.22813,22412,1
18.02080,-4.56218,-17.79924,4.53654,17.79924,22412,1
18.79480,-3.84122,-7.81629,3.81558,7.81629,22412,1
19.38180,-4.45671,-20.98432,4.43107,20.98432,22476,2
19.91480,-4.99020,-33.43000,4.96456,33.43000,22476,2
20.39480,-5.47021,-44.95440,5.44456,44.95440,22476,2
20.93580,-6.01120,-57.58718,5.98556,57.58718,22476,2
21.38580,-6.46126,-67.95837,6.43562,67.95837,22476,2
21.75280,-6.25560,-59.15968,6.22995,59.15968,22412,2
22.16680,-5.83659,-45.99167,5.81095,45.99166,22412,2
22.63680,-5.36612,-33.02523,5.34048,33.02523,22412,2
23.24680,-4.75624,-20.12756,4.73060,20.12756,22412,2
24.07080,-3.93208,-8.15746,3.90644,8.15746,22412,2
24.64380,-4.37192,-18.52178,4.34628,18.52178,22476,2
25.23920,-4.96819,-31.91105,4.94255,31.91105,22476,3
25.77180,-5.50134,-44.96412,5.47569,44.96412,22476,3
26.33920,-6.06836,-58.28904,6.04272,58.28904,22476,3
26.84080,-6.56815,-69.89802,6.54251,69.89802,22476,3
27.22580,-6.18423,-55.97999,6.15859,55.97998,22412,3
27.65880,-5.74855,-42.52841,5.72291,42.52840,22412,3
28.17580,-5.23137,-28.96764,5.20573,28.96764,22412,3
28.83920,-4.56832,-16.85353,4.54268,16.85353,22412,3
29.58880,-3.93843,-8.83295,3.91279,8.83295,22412,3
30.20180,-4.57497,-22.17148,4.54933,22.17148,22476,4
30.74080,-5.11446,-35.07854,5.08882,35.07854,22476,4
31.24980,-5.62342,-47.48345,5.59778,47.48345,22476,4
31.79680,-6.17047,-60.22748,6.14483,60.22748,22476,4
32.26780,-6.53909,-67.77697,6.51345,67.77697,22476,4
32.65880,-6.12407,-53.53754,6.09842,53.53754,22412,4
33.08380,-5.69750,-40.54768,5.67186,40.54768,22412,4
33.58080,-5.20044,-27.80952,5.17480,27.80952,22412,4
34.24680,-4.53420,-16.05347,4.50855,16.05347,22412,4
34.98180,-4.00603,-10.00986,3.98039,10.00986,22412,4
35.58980,-4.63101,-22.99923,4.60537,22.99923,22476,5
36.13920,-5.18031,-36.17939,5.15467,36.17939,22476,5
36.67980,-5.72147,-49.31511,5.69583,49.31511,22476,5
37.11280,-6.15439,-59.46104,6.12875,59.46104,22476,5
37.53920,-6.58037,-69.44012,6.55473,69.44012,22476,5
37.88880,-6.26826,-57.70573,6.24262,57.70573,22412,5
38.24080,-5.91250,-46.59457,5.88686,46.59457,22412,5
38.67580,-5.47720,-34.38754,5.45156,34.38754,22412,5
39.23920,-4.91413,-21.92184,4.88849,21.92184,22412,5
40.03920,-4.11438,-9.89106,4.08874,9.89106,22412,5
40.63920,-4.33376,-16.55008,4.30812,16.55008,22476,5
41.23920,-4.93605,-29.75542,4.91041,29.75542,22476,6
41.77480,-5.47222,-43.06924,5.44658,43.06924,22476,6
42.30280,-6.00018,-55.59276,5.97454,55.59276,22476,6
42.85480,-6.55226,-68.54547,6.52662,68.54547,22476,6
43.24580,-6.26899,-57.47902,6.24335,57.47902,22412,6
43.65480,-5.85637,-44.44959,5.83073,44.44959,22412,6
44.13480,-5.37603,-31.38209,5.35039,31.38209,22412,6
44.77780,-4.73323,-18.65218,4.70759,18.65218,22412,6
45.56980,-3.94652,-7.18881,3.92088,7.18881,22412,6
46.14180,-4.52845,-20.05553,4.50281,20.05553,22476,6
46.67480,-5.06217,-32.58279,5.03652,32.58279,22476,7
47.11580,-5.50321,-43.52549,5.47756,43.52549,22476,7
47.53920,-5.92614,-53.51187,5.90050,53.51187,22476,7
48.04480,-6.43211,-65.47751,6.40647,65.47751,22476,7
48.44280,-6.40868,-61.81102,6.38304,61.81102,22476,7
48.83380,-6.00944,-48.91253,5.98380,48.91253,22412,7
49.23480,-5.60802,-37.18342,5.58238,37.18342,22412,7
49.72180,-5.12101,-25.39598,5.09537,25.39598,22412,7
50.42480,-4.41789,-13.68103,4.39225,13.68103,22412,7
51.09880,-4.16537,-12.61326,4.13973,12.61326,22412,7
51.70880,-4.78387,-25.49298,4.75823,25.49298,22604,7
52.20780,-5.28306,-37.94616,5.25742,37.94616,22604,8
52.75480,-5.83014,-51.15126,5.80450,51.15126,22604,8
53.28280,-6.35789,-63.46776,6.33225,63.46776,22604,8
53.68680,-6.50049,-64.75713,6.47485,64.75713,22604,8
54.10780,-6.06579,-50.43849,6.04015,50.43849,22540,8
54.50480,-5.66800,-38.62813,5.64236,38.62813,22540,8
55.04880,-5.12391,-25.26842,5.09827,25.26842,22540,8
55.83480,-4.33780,-12.49132,4.31216,12.49132,22540,8
56.46780,-4.22251,-13.56493,4.19687,13.56493,22540,8
57.07980,-4.84066,-26.56667,4.81502,26.56667,22604,9
57.53920,-5.29986,-38.12363,5.27422,38.12363,22604,9
58.04480,-5.80593,-50.36447,5.78029,50.36447,22604,9
58.53920,-6.29976,-62.01842,6.27412,62.01842,22604,9
59.00980,-6.50500,-64.71206,6.47936,64.71205,22604,9
59.42380,-6.07750,-50.56635,6.05186,50.56635,22540,9
59.82480,-5.67575,-38.56266,5.65011,38.56266,22540,9
60.29280,-5.20774,-26.69708,5.18210,26.69708,22540,9
61.03080,-4.46950,-14.16502,4.44386,14.16502,22540,9
61.77780,-3.97186,-7.95040,3.94622,7.95040,22540,9
62.44280,-4.51050,-19.59636,4.48486,19.59636,22476,9
62.98280,-5.05099,-31.88832,5.02535,31.88832,22476,10
63.49480,-5.56319,-44.55044,5.53755,44.55044,22476,10
64.01680,-6.08511,-56.93609,6.05947,56.93609,22476,10
64.53920,-6.60695,-69.23753,6.58131,69.23753,22476,10
64.90880,-6.29864,-57.50414,6.27300,57.50414,22412,10
65.32180,-5.88197,-44.37441,5.85633,44.37440,22412,10
65.77680,-5.42677,-31.88752,5.40113,31.88752,22412,10
66.36580,-4.83781,-19.67961,4.81217,19.67961,22412,10
67.18680,-4.01669,-7.58722,3.99105,7.58722,22412,10
67.73920,-4.51971,-19.18304,4.49407,19.18304,22476,10
68.31580,-5.09785,-32.62089,5.07221,32.62089,22476,11
68.83920,-5.62086,-45.62273,5.59522,45.62273,22476,11
69.40480,-6.18696,-59.04124,6.16132,59.04124,22476,11
69.90580,-6.62272,-68.78683,6.59708,68.78683,22476,11
70.28780,-6.21384,-54.50452,6.18820,54.50452,22412,11
70.67480,-5.82478,-42.45445,5.79914,42.45445,22412,11
71.12780,-5.37145,-30.32551,5.34581,30.32551,22412,11
71.73480,-4.76461,-18.41906,4.73897,18.41906,22412,11
72.48080,-4.01847,-7.42746,3.99283,7.42746,22412,11
73.05980,-4.55472,-19.64661,4.52908,19.64661,22476,11
73.58580,-5.08165,-31.88438,5.05601,31.88438,22476,12
74.08980,-5.58577,-44.59667,5.56013,44.59667,22476,12
74.63920,-6.13468,-57.71359,6.10904,57.71359,22476,12
75.13920,-6.63428,-69.66303,6.60864,69.66302,22476,12
75.51580,-6.27646,-56.46122,6.25082,56.46122,22412,12
75.89280,-5.89647,-44.48567,5.87083,44.48567,22412,12
76.32480,-5.46431,-32.53074,5.43867,32.53074,22412,12
76.93920,-4.85031,-19.52834,4.82467,19.52834,22412,12
77.74080,-4.04836,-7.78844,4.02272,7.78844,22412,12
78.33780,-4.56246,-19.69199,4.53682,19.69199,22476,12
78.83920,-5.06439,-31.29439,5.03874,31.29439,22476,13
79.34080,-5.56634,-44.02862,5.54070,44.02862,22476,13
79.85680,-6.08243,-56.36143,6.05679,56.36143,22476,13
80.40880,-6.63425,-69.51442,6.60861,69.51442,22476,13
80.77880,-6.29756,-57.01503,6.27192,57.01503,22412,13
81.13920,-5.93429,-45.51303,5.90865,45.51303,22412,13
81.59080,-5.48201,-32.87025,5.45637,32.87025,22412,13
82.20480,-4.86800,-19.66881,4.84236,19.66881,22412,13
83.02680,-4.04609,-7.56734,4.02045,7.56734,22412,13
83.58180,-4.54397,-19.14783,4.51833,19.14783,22476,13
84.11580,-5.07914,-31.43132,5.05350,31.43132,22476,14
84.54480,-5.50807,-42.40052,5.48243,42.40052,22476,14
84.99980,-5.96300,-53.43188,5.93736,53.43188,22476,14
85.45880,-6.42192,-64.43725,6.39628,64.43725,22476,14
85.81680,-6.53532,-65.06484,6.50968,65.06484,22476,14
86.15880,-6.17953,-53.05975,6.15389,53.05975,22412,14
86.62680,-5.70997,-38.84898,5.68433,38.84898,22412,14
87.07580,-5.26084,-27.34875,5.23520,27.34875,22412,14
87.78480,-4.55180,-14.78538,4.52616,14.78538,22412,14
88.47180,-4.18273,-11.53668,4.15709,11.53668,22412,14
89.07780,-4.80067,-24.55215,4.77503,24.55215,22476,15
89.58180,-5.30487,-37.03499,5.27923,37.03499,22476,15
90.08080,-5.80398,-49.55778,5.77834,49.55777,22476,15
90.56080,-6.28385,-60.94298,6.25821,60.94298,22476,15
91.03920,-6.55086,-65.57553,6.52521,65.57552,22476,15
91.42080,-6.15301,-52.19696,6.12737,52.19696,22412,15
91.78080,-5.79182,-40.97977,5.76618,40.97977,22412,15
92.23680,-5.33560,-29.02209,5.30996,29.02209,22412,15
92.84480,-4.72769,-17.26875,4.70205,17.26875,22412,15
93.61580,-4.08126,-8.85476,4.05562,8.85476,22412,15
94.20280,-4.69127,-22.01220,4.66563,22.01220,22476,16
94.67580,-5.16475,-33.39278,5.13911,33.39278,22476,16
95.13920,-5.62775,-44.96254,5.60211,44.96254,22476,16
95.58180,-6.07070,-55.84821,6.04506,55.84821,22476,16
96.03920,-6.52751,-66.73950,6.50187,66.73950,22476,16
96.43080,-6.40164,-60.11929,6.37600,60.11929,22476,16
96.84980,-5.97654,-46.60547,5.95090,46.60547,22412,16
97.33920,-5.48721,-32.65015,5.46157,32.65015,22412,16
97.90880,-4.91717,-20.24761,4.89153,20.24761,22412,16
98.63580,-4.19043,-9.38218,4.16479,9.38218,22412,16
99.20480,-4.46525,-17.09967,4.43961,17.09966,22476,16
99.73920,-5.00127,-28.97620,4.97563,28.97620,22476,17
100.07480,-5.33744,-37.56196,5.31180,37.56196,22476,17
100.50880,-5.77157,-48.50181,5.74593,48.50181,22476,17
100.94680,-6.20959,-59.04535,6.18395,59.04535,22476,17
101.35980,-6.62234,-68.91181,6.59670,68.91180,22476,17
101.69880,-6.36596,-58.74481,6.34032,58.74481,22412,17
102.08280,-5.97730,-46.47119,5.95166,46.47119,22412,17
102.55080,-5.50901,-33.11792,5.48337,33.11792,22412,17
103.08480,-4.97497,-21.27472,4.94933,21.27472,22412,17
103.83480,-4.22513,-9.75933,4.19949,9.75933,22412,17
104.37680,-4.42611,-16.14653,4.40047,16.14653,22604,17
104.86180,-4.91401,-26.63146,4.88837,26.63146,22604,17
105.22280,-5.27520,-35.72164,5.24956,35.72164,22604,18
105.61080,-5.66336,-45.55053,5.63772,45.55053,22604,18
105.96380,-6.01623,-54.29465,5.99059,54.29465,22604,18
106.38880,-6.44114,-64.54366,6.41550,64.54366,22604,18
106.78680,-6.49220,-63.08233,6.46656,63.08233,22604,18
107.14080,-6.12800,-51.15170,6.10236,51.15170,22540,18
107.56080,-5.70708,-38.31086,5.68144,38.31086,22540,18
107.96280,-5.30497,-27.92564,5.27933,27.92564,22540,18
108.53280,-4.73501,-17.15333,4.70937,17.15333,22540,18
109.21380,-4.06022,-7.22190,4.03458,7.22190,22540,18
109.73920,-4.59617,-19.48937,4.57053,19.48937,22604,18
110.21280,-5.07118,-30.39484,5.04554,30.39484,22604,19
110.50680,-5.36509,-37.91475,5.33945,37.91475,22604,19
110.94180,-5.80023,-48.84171,5.77459,48.84171,22604,19
111.45880,-6.31706,-61.40990,6.29142,61.40990,22604,19
111.86380,-6.61997,-67.84999,6.59433,67.84998,22604,19
112.20380,-6.25641,-55.04168,6.23077,55.04168,22540,19
112.55180,-5.90603,-44.10702,5.88039,44.10702,22540,19
112.94280,-5.51481,-33.14826,5.48917,33.14825,22540,19
113.47280,-4.98476,-21.33291,4.95911,21.33291,22540,19
114.25480,-4.20301,-9.22063,4.17737,9.22063,22540,19
115.01580,-4.33794,-14.60901,4.31230,14.60900,22476,19
115.61080,-4.93595,-27.29150,4.91031,27.29150,22476,19
116.01680,-5.34214,-37.49271,5.31650,37.49271,22476,20
116.53920,-5.86415,-50.58381,5.83851,50.58381,22476,20
116.98380,-6.30909,-61.39154,6.28345,61.39154,22476,20
117.40680,-6.62772,-68.01838,6.60208,68.01838,22476,20
117.73920,-6.27245,-55.56233,6.24681,55.56233,22412,20
118.13880,-5.86993,-42.92922,5.84429,42.92923,22412,20
118.53920,-5.46981,-31.85071,5.44417,31.85071,22412,20
119.11380,-4.89472,-19.61892,4.86908,19.61893,22412,20
119.89080,-4.11794,-7.89798,4.09230,7.89798,22412,20
120.42680,-4.55872,-18.59797,4.53308,18.59797,22476,20
120.94880,-5.08215,-30.51380,5.05651,30.51380,22476,21
121.38180,-5.51516,-41.51484,5.48952,41.51484,22476,21
121.72380,-5.85715,-50.06661,5.83151,50.06660,22476,21
122.19180,-6.32502,-61.47804,6.29938,61.47805,22476,21
122.57980,-6.65859,-69.05228,6.63295,69.05228,22476,21
122.85480,-6.35826,-58.17308,6.33262,58.17308,22412,21
123.15480,-6.05446,-48.48030,6.02882,48.48030,22412,21
123.45080,-5.75803,-39.42307,5.73239,39.42307,22412,21
123.85780,-5.35086,-28.74426,5.32522,28.74426,22412,21
124.43920,-4.76990,-17.47583,4.74426,17.47583,22412,21
125.15680,-4.07495,-7.31894,4.04931,7.31894,22412,21
125.73880,-4.68168,-21.03325,4.65604,21.03325,22476,21
126.15880,-5.10236,-30.88628,5.07672,30.88628,22476,22
126.47580,-5.41906,-39.01893,5.39342,39.01893,22476,22
126.83920,-5.78236,-48.18283,5.75672,48.18283,22476,22
127.27880,-6.22235,-58.81584,6.19671,58.81584,22476,22
127.75080,-6.67595,-69.80366,6.65031,69.80366,22476,22
128.13480,-6.27046,-55.21066,6.24482,55.21067,22412,22
128.51880,-5.88407,-43.15376,5.85843,43.15376,22412,22
128.92079,-5.48190,-31.88618,5.45625,31.88618,22412,22
129.51480,-4.88785,-19.31477,4.86221,19.31477,22412,22
130.28880,-4.11418,-7.72389,4.08853,7.72389,22412,22
130.84480,-4.59934,-19.19398,4.57370,19.19398,22476,22
131.37280,-5.12848,-31.41013,5.10284,31.41013,22476,23
131.76480,-5.52041,-41.42461,5.49477,41.42461,22476,23
132.13880,-5.89441,-50.85500,5.86877,50.85500,22476,23
132.63919,-6.39411,-63.04315,6.36847,63.04315,22476,23
133.07280,-6.53773,-64.20290,6.51209,64.20290,22476,23
133.48480,-6.11302,-50.12501,6.08738,50.12502,22412,23
133.93919,-5.65823,-36.39961,5.63259,36.39961,22412,23
134.46480,-5.13219,-23.87902,5.10655,23.87902,22412,23
135.23920,-4.35807,-11.31151,4.33243,11.31151,22412,23
135.83920,-4.40417,-15.14452,4.37853,15.14452,22476,23
136.43919,-5.00835,-28.35993,4.98271,28.35993,22476,24
136.95080,-5.52059,-41.32126,5.49495,41.32126,22476,24
137.35980,-5.92947,-51.65457,5.90383,51.65458,22476,24
137.83920,-6.40835,-63.29501,6.38271,63.29501,22476,24
138.23880,-6.55136,-64.75697,6.52572,64.75697,22476,24
138.61780,-6.15855,-51.48286,6.13291,51.48286,22412,24
139.06080,-5.71443,-37.95597,5.68879,37.95597,22412,24
139.49780,-5.27729,-26.77325,5.25165,26.77325,22412,24
140.10280,-4.67242,-15.86916,4.64678,15.86916,22412,24
140.73920,-4.11475,-8.26264,4.08911,8.26264,22412,24
141.33280,-4.73629,-22.03046,4.71065,22.03046,22476,25
141.80480,-5.20882,-33.42773,5.18317,33.42773,22476,25
142.16080,-5.56467,-42.37477,5.53903,42.37477,22476,25
142.52380,-5.92763,-51.47775,5.90198,51.47775,22476,25
142.83920,-6.24276,-59.14762,6.21712,59.14762,22476,25
143.28580,-6.68740,-70.04607,6.66176,70.04607,22476,25
143.61280,-6.36253,-57.88717,6.33689,57.88717,22412,25
143.98580,-5.98569,-45.92218,5.96005,45.92218,22412,25
144.36480,-5.60654,-34.91722,5.58090,34.91722,22412,25
144.78678,-5.18469,-24.79945,5.15905,24.79945,22412,25
145.53920,-4.43247,-12.26670,4.40683,12.26670,22412,25
146.13919,-4.33196,-13.48169,4.30632,13.48169,22412,25
146.73920,-4.93862,-26.56067,4.91298,26.56067,22476,26
147.23920,-5.43888,-39.23155,5.41324,39.23155,22476,26
147.66178,-5.86185,-49.74614,5.83621,49.74614,22476,26
148.17680,-6.37657,-62.39512,6.35093,62.39512,22476,26
148.61080,-6.55776,-64.73689,6.53212,64.73689,22476,26
149.01980,-6.13454,-50.62103,6.10890,50.62103,22412,26
149.41580,-5.73771,-38.44701,5.71207,38.44701,22412,26
149.86680,-5.28658,-26.84052,5.26094,26.84052,22412,26
150.53920,-4.61452,-14.85226,4.58887,14.85227,22412,26
151.18880,-4.20341,-10.56395,4.17777,10.56395,22412,26
151.77780,-4.80766,-23.50658,4.78202,23.50658,22476,27
152.22080,-5.25094,-34.35889,5.22530,34.35889,22476,27
152.71380,-5.74423,-46.86481,5.71859,46.86481,22476,27
153.23380,-6.26407,-59.56215,6.23843,59.56215,22476,27
153.71280,-6.65656,-68.33587,6.63091,68.33587,22476,27
154.09080,-6.25289,-54.16807,6.22725,54.16807,22412,27
154.51080,-5.83095,-41.04403,5.80531,41.04403,22412,27
155.03280,-5.30884,-27.23403,5.28320,27.23404,22412,27
155.66380,-4.67790,-15.77208,4.65226,15.77208,22412,27
156.37280,-4.20966,-10.57549,4.18402,10.57549,22412,27
156.96180,-4.81383,-23.60062,4.78819,23.60062,22604,27
157.46580,-5.31806,-35.90554,5.29242,35.90554,22604,28
158.00480,-5.85709,-49.43123,5.83145,49.43124,22604,28
158.53920,-6.39083,-62.64222,6.36519,62.64222,22604,28
158.96280,-6.58093,-65.36021,6.55529,65.36021,22604,28
159.37078,-6.15792,-51.14696,6.13228,51.14696,22540,28
159.83280,-5.69495,-37.05554,5.66931,37.05554,22540,28
160.38180,-5.14590,-23.81094,5.12026,23.81094,22540,28
161.13919,-4.38876,-11.47620,4.36312,11.47620,22540,28
161.69080,-4.34644,-13.59702,4.32080,13.59702,22540,28
162.28380,-4.94593,-26.52781,4.92029,26.52781,22604,29
162.74080,-5.40311,-38.11904,5.37747,38.11904,22604,29
163.27080,-5.93310,-51.38336,5.90746,51.38337,22604,29
163.75480,-6.41688,-63.14003,6.39124,63.14003,22604,29
164.15680,-6.58080,-65.20868,6.55516,65.20868,22604,29
164.51980,-6.20343,-52.42286,6.17778,52.42286,22540,29
164.85180,-5.86998,-42.10510,5.84433,42.10510,22540,29
165.24280,-5.47883,-31.20865,5.45319,31.20865,22540,29
165.77880,-4.94285,-19.88707,4.91721,19.88707,22540,29
166.57680,-4.14507,-7.79448,4.11943,7.79448,22540,29
167.25780,-4.34691,-14.13594,4.32127,14.13594,22540,29
167.82880,-4.92134,-26.34786,4.89570,26.34786,22476,29
168.25480,-5.34750,-36.93334,5.32186,36.93334,22476,30
168.64878,-5.74175,-46.89235,5.71611,46.89235,22476,30
169.10480,-6.19777,-57.89318,6.17213,57.89318,22476,30
169.53280,-6.62550,-68.35163,6.59986,68.35162,22476,30
169.90680,-6.37367,-58.16514,6.34803,58.16515,22412,30
170.27980,-5.99648,-46.12366,5.97084,46.12366,22412,30
170.66080,-5.61529,-34.90687,5.58965,34.90687,22412,30
171.23920,-5.03723,-21.64059,5.01159,21.64059,22412,30
172.03920,-4.23744,-9.19092,4.21180,9.19092,22412,30
172.59380,-4.54449,-17.67623,4.51885,17.67624,22476,30
173.13680,-5.08967,-30.04689,5.06403,30.04689,22476,31
173.60280,-5.55561,-41.85369,5.52997,41.85369,22476,31
174.13880,-6.09169,-55.14473,6.06605,55.14473,22476,31
174.53920,-6.49154,-64.97816,6.46590,64.97816,22476,31
174.95080,-6.50089,-62.22219,6.47525,62.22219,22476,31
175.33080,-6.11216,-49.50661,6.08652,49.50661,22412,31
175.77480,-5.66754,-36.06527,5.64190,36.06527,22412,31
176.25980,-5.18262,-24.42849,5.15698,24.42849,22412,31
176.91880,-4.52336,-13.25290,4.49771,13.25290,22412,31
177.55380,-4.33046,-13.03504,4.30482,13.03504,22412,31
178.08780,-4.87251,-24.71419,4.84687,24.71419,22476,32
178.40080,-5.18597,-32.37832,5.16033,32.37831,22476,32
178.63919,-5.42379,-38.46200,5.39815,38.46200,22476,32
178.93919,-5.72393,-46.06706,5.69829,46.06706,22476,32
179.13919,-5.92371,-51.02588,5.89807,51.02588,22476,32
179.44980,-6.23490,-58.50673,6.20926,58.50673,22476,32
179.73180,-6.51669,-65.47268,6.49105,65.47268,22476,32
180.01078,-6.61688,-66.33137,6.59124,66.33138,22476,32
180.24480,-6.36745,-57.59772,6.34181,57.59772,22412,32
180.52580,-6.08315,-48.56837,6.05751,48.56837,22412,32
180.80178,-5.80669,-40.05215,5.78105,40.05215,22412,32
181.12180,-5.48646,-31.23747,5.46082,31.23747,22412,32
181.54880,-5.05965,-21.94394,5.03401,21.94394,22412,32
182.11380,-4.49449,-12.76337,4.46885,12.76337,22412,32
182.68880,-4.31207,-12.55293,4.28643,12.55293,22412,32
183.27680,-4.90952,-25.48274,4.88388,25.48274,22476,33
183.70880,-5.34182,-36.27037,5.31618,36.27037,22476,33
184.03980,-5.67300,-44.63383,5.64736,44.63383,22476,33
184.47880,-6.11198,-55.48856,6.08634,55.48856,22476,33
184.89280,-6.52574,-65.60576,6.50010,65.60576,22476,33
185.23680,-6.53761,-63.38010,6.51197,63.38010,22476,33
185.51980,-6.24457,-53.49575,6.21893,53.49575,22412,33
185.84180,-5.92079,-43.47592,5.89515,43.47592,22412,33
186.17780,-5.58475,-33.81297,5.55911,33.81297,22412,33
186.63980,-5.12275,-23.09606,5.09711,23.09606,22412,33
187.35280,-4.40960,-11.61581,4.38396,11.61581,22412,33
187.93919,-4.38836,-14.27287,4.36272,14.27287,22476,33
188.50580,-4.96082,-26.62633,4.93518,26.62633,22476,34
188.88780,-5.34303,-36.19670,5.31739,36.19670,22476,34
189.22880,-5.68419,-44.83279,5.65855,44.83279,22476,34
189.59478,-6.05002,-53.88892,6.02437,53.88892,22476,34
189.89980,-6.35477,-61.47384,6.32913,61.47384,22476,34
190.20880,-6.66391,-69.08999,6.63827,69.08999,22476,34
190.49880,-6.46291,-60.57930,6.43727,60.57930,22476,34
190.80280,-6.15281,-50.48758,6.12717,50.48758,22412,34
191.10180,-5.85294,-41.17320,5.82730,41.17321,22412,34
191.45280,-5.50173,-31.52778,5.47609,31.52778,22412,34
191.86680,-5.08791,-22.34220,5.06227,22.34220,22412,34
192.50380,-4.45089,-12.17234,4.42525,12.17234,22412,34
192.94380,-4.20302,-9.91977,4.17738,9.91977,22412,34
193.32380,-4.59978,-18.65308,4.57414,18.65308,22476,34
193.58880,-4.86588,-24.44817,4.84024,24.44817,22476,35
193.85580,-5.13319,-30.83787,5.10755,30.83787,22476,35
194.02580,-5.30325,-35.17868,5.27761,35.17868,22476,35
194.21580,-5.49311,-40.00718,5.46747,40.00718,22476,35
194.34880,-5.62627,-43.42865,5.60063,43.42865,22476,35
194.48880,-5.76625,-46.97894,5.74061,46.97894,22476,35
194.63280,-5.91009,-50.49371,5.88445,50.49371,22476,35
194.78280,-6.06025,-54.18916,6.03461,54.18916,22476,35
194.94780,-6.22526,-58.16624,6.19962,58.16624,22476,35
195.10880,-6.38593,-62.17709,6.36028,62.17709,22476,35
195.26380,-6.54111,-65.98571,6.51547,65.98571,22476,35
195.40380,-6.68111,-69.39750,6.65546,69.39750,22476,35
195.53920,-6.58427,-65.10098,6.55863,65.10098,22476,35
195.66580,-6.44802,-60.22053,6.42238,60.22053,22476,35
195.82380,-6.28544,-54.84125,6.25980,54.84125,22412,35
195.97280,-6.13493,-50.08408,6.10929,50.08408,22412,35
196.17780,-5.92917,-43.61891,5.90353,43.61891,22412,35
196.29780,-5.80919,-39.95507,5.78354,39.95507,22412,35
196.43380,-5.67314,-35.98301,5.64750,35.98301,22412,35
196.58680,-5.51998,-31.93536,5.49434,31.93536,22412,35
196.72280,-5.38388,-28.54678,5.35824,28.54678,22412,35
196.91880,-5.18824,-24.27023,5.16260,24.27024,22412,35
197.15880,-4.94803,-19.71739,4.92239,19.71739,22412,35
197.47280,-4.63405,-14.76878,4.60841,14.76878,22412,35
197.81080,-4.29606,-9.80604,4.27042,9.80604,22412,35
198.19080,-4.33748,-12.90824,4.31184,12.90824,22412,35
198.53580,-4.69062,-20.39679,4.66498,20.39679,22476,35
198.94280,-5.09854,-29.92734,5.07290,29.92734,22476,36
199.11080,-5.26634,-34.25703,5.24070,34.25703,22476,36
199.32080,-5.47649,-39.53918,5.45085,39.53918,22476,36
199.51880,-5.67450,-44.52702,5.64886,44.52702,22476,36
199.84380,-5.99936,-52.52137,5.97372,52.52137,22476,36
200.16378,-6.31921,-60.36837,6.29357,60.36837,22476,36
200.44380,-6.59932,-67.28986,6.57368,67.28986,22476,36
200.65580,-6.60911,-65.80616,6.58347,65.80616,22476,36
200.90880,-6.34156,-56.49098,6.31592,56.49098,22412,36
201.12380,-6.12408,-49.48531,6.09843,49.48531,22412,36
201.37480,-5.87238,-41.78872,5.84674,41.78872,22412,36
201.65880,-5.58834,-33.72090,5.56270,33.72090,22412,36
201.86980,-5.37715,-28.29636,5.35151,28.29636,22412,36
202.36580,-4.88117,-18.57988,4.85553,18.57988,22412,36
203.10080,-4.14650,-7.53141,4.12086,7.53141,22412,36
203.56880,-4.57089,-17.89918,4.54525,17.89918,22476,36
203.98278,-4.98649,-27.04032,4.96085,27.04032,22476,37
204.23920,-5.24282,-33.63159,5.21718,33.63159,22476,37
204.57380,-5.57778,-42.07614,5.55214,42.07614,22476,37
204.93919,-5.94265,-51.22130,5.91701,51.22130,22476,37
205.13919,-6.14284,-56.10013,6.11720,56.10013,22476,37
205.37480,-6.37848,-61.88599,6.35284,61.88599,22476,37
205.65380,-6.65758,-68.68660,6.63194,68.68660,22476,37
205.89480,-6.52074,-62.60316,6.49510,62.60316,22476,37
206.17580,-6.23116,-52.82042,6.20552,52.82042,22412,37
206.43080,-5.97465,-44.84651,5.94901,44.84651,22412,37
206.73480,-5.67059,-35.76871,5.64495,35.76871,22412,37
207.03920,-5.36642,-27.96486,5.34078,27.96486,22412,37
207.53920,-4.86644,-18.35322,4.84080,18.35322,22412,37
208.03920,-4.36644,-10.76257,4.34080,10.76257,22412,37
208.55178,-4.38763,-13.99219,4.36199,13.99219,22604,37
209.01680,-4.85858,-24.08819,4.83294,24.08819,22604,37
209.28780,-5.12990,-30.58056,5.10426,30.58056,22604,38
209.52680,-5.36877,-36.68615,5.34313,36.68615,22604,38
209.66980,-5.51187,-40.34703,5.48623,40.34703,22604,38
209.88180,-5.72395,-45.71112,5.69831,45.71112,22604,38
210.11480,-5.95687,-51.52245,5.93123,51.52245,22604,38
210.31478,-6.15700,-56.42370,6.13136,56.42370,22604,38
210.52280,-6.36463,-61.52140,6.33899,61.52140,22604,38
210.68180,-6.52378,-65.47727,6.49814,65.47726,22604,38
210.87078,-6.69720,-69.54207,6.67156,69.54207,22604,38
211.01880,-6.53898,-63.25897,6.51334,63.25897,22604,38
211.16178,-6.38825,-58.04426,6.36261,58.04426,22540,38
211.30080,-6.24660,-53.39701,6.22096,53.39701,22540,38
211.47880,-6.06726,-47.84071,6.04162,47.84071,22540,38
211.65780,-5.88775,-42.26991,5.86211,42.26991,22540,38
211.82880,-5.71684,-37.11634,5.69120,37.11634,22540,38
212.01680,-5.52867,-32.01351,5.50303,32.01351,22540,38
212.22580,-5.31974,-26.90323,5.29410,26.90323,22540,38
212.53920,-5.00659,-20.66950,4.98095,20.66950,22540,38
213.08280,-4.46270,-12.16935,4.43706,12.16935,22540,38
213.50878,-4.21172,-9.79088,4.18608,9.79088,22540,38
214.01780,-4.73951,-21.43938,4.71387,21.43938,22604,38
214.24280,-4.96484,-26.46698,4.93920,26.46698,22604,39
214.50680,-5.22917,-33.11980,5.20353,33.11980,22604,39
214.69680,-5.41895,-38.00188,5.39330,38.00188,22604,39
214.93480,-5.65710,-43.96532,5.63146,43.96532,22604,39
215.11880,-5.84099,-48.62885,5.81535,48.62885,22604,39
215.35680,-6.07913,-54.43426,6.05349,54.43426,22604,39
215.61780,-6.33988,-60.86291,6.31424,60.86291,22604,39
215.88780,-6.60992,-67.42678,6.58428,67.42678,22604,39
216.11380,-6.58093,-64.68961,6.55529,64.68961,22604,39
216.32680,-6.35641,-56.91254,6.33077,56.91254,22540,39
216.53920,-6.14173,-50.03772,6.11609,50.03772,22540,39
216.68380,-5.99601,-45.48787,5.97037,45.48787,22540,39
216.88680,-5.79298,-39.34180,5.76734,39.34180,22540,39
217.09180,-5.58788,-33.53212,5.56224,33.53212,22540,39
217.34278,-5.33684,-27.20892,5.31120,27.20892,22540,39
217.73920,-4.94083,-19.42568,4.91519,19.42568,22540,39
218.17480,-4.50475,-12.72786,4.47911,12.72786,22540,39
218.53080,-4.14906,-7.48907,4.12342,7.48907,22540,39
218.92580,-4.13815,-8.58319,4.11251,8.58319,22540,39
219.33919,-4.55436,-17.96077,4.52872,17.96077,22476,39
219.73680,-4.95338,-26.66979,4.92774,26.66979,22476,39
219.93480,-5.15149,-31.51577,5.12585,31.51577,22476,40
220.13919,-5.35544,-36.64524,5.32980,36.64524,22476,40
220.27180,-5.48857,-40.00394,5.46293,40.00394,22476,40
220.41480,-5.63151,-43.65557,5.60587,43.65557,22476,40
220.55080,-5.76770,-47.06281,5.74206,47.06281,22476,40
220.75680,-5.97347,-52.14439,5.94783,52.14439,22476,40
220.99578,-6.21263,-57.83972,6.18699,57.83972,22476,40
221.22680,-6.44345,-63.53766,6.41781,63.53766,22476,40
221.44880,-6.66542,-68.92448,6.63978,68.92448,22476,40
221.64180,-6.55743,-63.88267,6.53179,63.88267,22476,40
221.89980,-6.28861,-54.74649,6.26297,54.74649,22412,40
222.12380,-6.06283,-47.74446,6.03719,47.74446,22412,40
222.30378,-5.88237,-42.06116,5.85673,42.06116,22412,40
222.46778,-5.71847,-37.14501,5.69283,37.14501,22412,40
222.65280,-5.53331,-32.08340,5.50767,32.08340,22412,40
222.85280,-5.33333,-27.17462,5.30769,27.17462,22412,40
223.20080,-4.98525,-20.22828,4.95961,20.22828,22412,40
223.69580,-4.49024,-12.50350,4.46459,12.50350,22412,40
224.14878,-4.21655,-9.97177,4.19090,9.97177,22412,40
224.64180,-4.72799,-21.15685,4.70235,21.15685,22476,41
224.98180,-5.06854,-29.02023,5.04290,29.02023,22476,41
225.17180,-5.25859,-33.94549,5.23295,33.94549,22476,41
225.33280,-5.41951,-37.99365,5.39387,37.99366,22476,41
225.49380,-5.58058,-42.10387,5.55494,42.10387,22476,41
225.75180,-5.83858,-48.56833,5.81294,48.56833,22476,41
225.97080,-6.05767,-53.91439,6.03203,53.91439,22476,41
226.15880,-6.24567,-58.48371,6.22003,58.48371,22476,41
226.37180,-6.45853,-63.76188,6.43289,63.76188,22476,41
226.61480,-6.70122,-69.66782,6.67558,69.66782,22476,41
226.81180,-6.52692,-62.67849,6.50128,62.67849,22476,41
227.07180,-6.25828,-53.59017,6.23264,53.59018,22412,41
227.25280,-6.07601,-48.00534,6.05037,48.00534,22412,41
227.50680,-5.82160,-40.03833,5.79596,40.03833,22412,41
227.72480,-5.60350,-33.92200,5.57786,33.92200,22412,41
228.10580,-5.22258,-24.80705,5.19694,24.80705,22412,41
228.63919,-4.68959,-15.35811,4.66395,15.35811,22412,41
229.16378,-4.16467,-7.65255,4.13903,7.65255,22412,41
229.53480,-4.49021,-16.05518,4.46457,16.05518,22476,41
229.81380,-4.77224,-22.07253,4.74660,22.07253,22476,42
229.99080,-4.94951,-26.09902,4.92387,26.09901,22476,42
230.14180,-5.10085,-29.75614,5.07521,29.75614,22476,42
230.22480,-5.18379,-31.80531,5.15815,31.80531,22476,42
230.33980,-5.29866,-34.79878,5.27302,34.79878,22476,42
230.43680,-5.39554,-37.28188,5.36990,37.28188,22476,42
230.51580,-5.47476,-39.34923,5.44912,39.34923,22476,42
230.63578,-5.59479,-42.30190,5.56915,42.30190,22476,42
230.74080,-5.69988,-44.93571,5.67424,44.93571,22476,42
230.82480,-5.78389,-47.20398,5.75825,47.20398,22476,42
230.93919,-5.89771,-49.91052,5.87207,49.91051,22476,42
231.05480,-6.01369,-52.73533,5.98805,52.73533,22476,42
231.16880,-6.12787,-55.57583,6.10223,55.57583,22476,42
231.27578,-6.23488,-58.15572,6.20924,58.15572,22476,42
231.36080,-6.31960,-60.29061,6.29396,60.29061,22476,42
231.44280,-6.40154,-62.36818,6.37590,62.36818,22476,42
231.58680,-6.54562,-65.84198,6.51997,65.84198,22476,42
231.71480,-6.67369,-68.99660,6.64805,68.99660,22476,42
231.80480,-6.65500,-67.45607,6.62936,67.45608,22476,42
231.89580,-6.55152,-63.60593,6.52588,63.60593,22476,42
232.06580,-6.37250,-57.40862,6.34686,57.40862,22412,42
232.20380,-6.23224,-52.79831,6.20660,52.79831,22412,42
232.32080,-6.11424,-49.14020,6.08860,49.14021,22412,42
232.45580,-5.97863,-44.86560,5.95299,44.86560,22412,42
232.63880,-5.79563,-39.36213,5.76999,39.36213,22412,42
232.84180,-5.59252,-33.56487,5.56688,33.56487,22412,42
232.99680,-5.43743,-29.55220,5.41179,29.55220,22412,42
233.30780,-5.12656,-22.81938,5.10092,22.81939,22412,42
233.53580,-4.89833,-18.74717,4.87269,18.74717,22412,42
233.72178,-4.71265,-15.73311,4.68701,15.73311,22412,42
233.96778,-4.46643,-12.11201,4.44079,12.11201,22412,42
234.16578,-4.26848,-9.17001,4.24284,9.17001,22412,42
234.34580,-4.17769,-8.61302,4.15205,8.61302,22412,42
234.61880,-4.47370,-15.65438,4.44806,15.65438,22476,42
234.83178,-4.68984,-20.13497,4.66420,20.13497,22476,42
235.00580,-4.86441,-24.09488,4.83877,24.09488,22476,43
235.14878,-5.00761,-27.27962,4.98197,27.27962,22476,43
235.27680,-5.13580,-30.54765,5.11016,30.54766,22476,43
235.36380,-5.22289,-32.86587,5.19725,32.86588,22476,43
235.47880,-5.33769,-35.67625,5.31205,35.67625,22476,43
235.59180,-5.45083,-38.71077,5.42519,38.71077,22476,43
235.69680,-5.55578,-41.34482,5.53014,41.34482,22476,43
235.79780,-5.65685,-43.84393,5.63121,43.84393,22476,43
235.93680,-5.79587,-47.44907,5.77023,47.44907,22476,43
236.02680,-5.88570,-49.56213,5.86006,49.56213,22476,43
236.13919,-5.99778,-52.36079,5.97213,52.36079,22476,43
236.28678,-6.14585,-55.99983,6.12021,55.99984,22476,43
236.43080,-6.28962,-59.50879,6.26398,59.50879,22476,43
236.58280,-6.44168,-63.25327,6.41604,63.25327,22476,43
236.72480,-6.58372,-66.74232,6.55808,66.74232,22476,43
236.85880,-6.71180,-69.80976,6.68616,69.80975,22476,43
237.01980,-6.55061,-63.38502,6.52497,63.38502,22476,43
237.15180,-6.41143,-58.52605,6.38579,58.52605,22412,43
237.35880,-6.20094,-51.68152,6.17530,51.68152,22412,43
237.56580,-5.99269,-45.15702,5.96705,45.15702,22412,43
237.75480,-5.80371,-39.45684,5.77807,39.45684,22412,43
237.99880,-5.55961,-32.52234,5.53397,32.52234,22412,43
238.23920,-5.31960,-26.68341,5.29396,26.68341,22412,43
238.62380,-4.93455,-19.22096,4.90891,19.22096,22412,43
239.15780,-4.40054,-11.09605,4.37490,11.09605,22412,43
239.49578,-4.20050,-9.25644,4.17486,9.25644,22412,43
239.93780,-4.66375,-19.57541,4.63811,19.57541,22476,43
240.33919,-5.06587,-28.72386,5.04023,28.72386,22476,44
240.55880,-5.28576,-34.38108,5.26012,34.38108,22476,44
240.79480,-5.52185,-40.37064,5.49621,40.37064,22476,44
240.99778,-5.72495,-45.50020,5.69931,45.50020,22476,44
241.25580,-5.98279,-51.92987,5.95714,51.92987,22476,44
241.47380,-6.20101,-57.25897,6.17537,57.25898,22476,44
241.57580,-6.30268,-59.80811,6.27704,59.80811,22476,44
241.73920,-6.46583,-63.83558,6.44019,63.83558,22476,44
241.99280,-6.71156,-69.78460,6.68592,69.78460,22476,44
242.21978,-6.47621,-60.69368,6.45057,60.69368,22476,44
242.42280,-6.26757,-53.74157,6.24193,53.74157,22412,44
242.57080,-6.11838,-49.08846,6.09274,49.08846,22412,44
242.71978,-5.96881,-44.43011,5.94317,44.43011,22412,44
242.85880,-5.82977,-40.17374,5.80413,40.17374,22412,44
243.07080,-5.61770,-34.09299,5.59206,34.09298,22412,44
243.25680,-5.43160,-29.28120,5.40596,29.28119,22412,44
243.57080,-5.11773,-22.52800,5.09209,22.52800,22412,44
243.96180,-4.72677,-15.88926,4.70113,15.88927,22412,44
244.40078,-4.28771,-9.36735,4.26207,9.36735,22412,44
244.68480,-4.26941,-10.99646,4.24377,10.99646,22412,44
244.96180,-4.55861,-17.41898,4.53297,17.41898,22476,44
245.29880,-4.89754,-24.76455,4.87190,24.76455,22476,45
245.48278,-5.08188,-29.15431,5.05624,29.15431,22476,45
245.59880,-5.19786,-32.06788,5.17222,32.06788,22476,45
245.76980,-5.36876,-36.42299,5.34312,36.42299,22476,45
245.96680,-5.56598,-41.51039,5.54034,41.51039,22476,45
246.12278,-5.72212,-45.39520,5.69648,45.39520,22476,45
246.29480,-5.89382,-49.67064,5.86818,49.67064,22476,45
246.50080,-6.10004,-54.75513,6.07440,54.75513,22476,45
246.76078,-6.35971,-61.20278,6.33407,61.20278,22476,45
246.95780,-6.55681,-65.94173,6.53117,65.94173,22476,45
247.17380,-6.67085,-67.78883,6.64521,67.78883,22476,45
247.48080,-6.34068,-56.14253,6.31504,56.14253,22412,45
247.72580,-6.09324,-48.30739,6.06760,48.30738,22412,45
247.92380,-5.89465,-42.14712,5.86901,42.14712,22412,45
248.11480,-5.70374,-36.42472,5.67810,36.42472,22412,45
248.31380,-5.50450,-30.98348,5.47886,30.98348,22412,45
248.53180,-5.28663,-25.90383,5.26099,25.90383,22412,45
248.78678,-5.03156,-20.80844,5.00591,20.80844,22412,45
249.13919,-4.67971,-15.10975,4.65406,15.10975,22412,45
249.50878,-4.30967,-9.71414,4.28403,9.71414,22412,45
249.93919,-4.39726,-13.86411,4.37162,13.86411,22476,45
250.30480,-4.76933,-21.89194,4.74369,21.89194,22476,46
250.62980,-5.09489,-29.47184,5.06925,29.47184,22476,46
250.90680,-5.37171,-36.49238,5.34607,36.49238,22476,46
251.08280,-5.54791,-41.00097,5.52226,41.00097,22476,46
251.33880,-5.80400,-47.55985,5.77836,47.55985,22476,46
251.53920,-6.00384,-52.40976,5.97820,52.40976,22476,46
251.73180,-6.19702,-57.17982,6.17138,57.17982,22476,46
252.02778,-6.49280,-64.44332,6.46716,64.44332,22476,46
252.24180,-6.70618,-69.66193,6.68054,69.66193,22476,46
252.46280,-6.50241,-61.53484,6.47677,61.53484,22476,46
252.75980,-6.19799,-51.48776,6.17235,51.48776,22412,46
252.97780,-5.97877,-44.70039,5.95313,44.70039,22412,46
253.23920,-5.71780,-36.81246,5.69216,36.81246,22412,46
253.48880,-5.46761,-30.06250,5.44197,30.06250,22412,46
253.84278,-5.11369,-22.37336,5.08805,22.37336,22412,46
254.40278,-4.55370,-13.19616,4.52806,13.19616,22412,46
254.85180,-4.15166,-7.72050,4.12601,7.72050,22412,46
255.26580,-4.59309,-18.08763,4.56745,18.08763,22476,46
255.71080,-5.03971,-28.03838,5.01407,28.03838,22476,47
255.98880,-5.31790,-35.06041,5.29225,35.06041,22476,47
256.39380,-5.72305,-45.41809,5.69741,45.41809,22476,47
256.75480,-6.08395,-54.33740,6.05830,54.33741,22476,47
257.18878,-6.51780,-65.04874,6.49216,65.04874,22476,47
257.53919,-6.57925,-64.23246,6.55361,64.23246,22476,47
257.85480,-6.25125,-53.00457,6.22561,53.00457,22412,47
258.08481,-6.01980,-45.84980,5.99416,45.84980,22412,47
258.27078,-5.83372,-40.17273,5.80808,40.17273,22412,47
258.43917,-5.66568,-35.18192,5.64004,35.18192,22412,47
258.64081,-5.46356,-29.89559,5.43792,29.89558,22412,47
258.94180,-5.16275,-23.23234,5.13711,23.23234,22412,47
259.51678,-4.58759,-13.62704,4.56195,13.62704,22412,47
260.06478,-4.22101,-9.73310,4.19536,9.73310,22412,47
260.62478,-4.79944,-22.54186,4.77380,22.54186,22604,47
261.05078,-5.22586,-32.79893,5.20022,32.79893,22604,48
261.35580,-5.53094,-40.43746,5.50530,40.43746,22604,48
261.59778,-5.77300,-46.81621,5.74736,46.81621,22604,48
261.99180,-6.16701,-56.40333,6.14137,56.40333,22604,48
262.27478,-6.44979,-63.23870,6.42415,63.23870,22604,48
262.58278,-6.70355,-68.99797,6.67791,68.99797,22604,48
262.87281,-6.38761,-57.53515,6.36197,57.53515,22540,48
263.18178,-6.07523,-47.66135,6.04959,47.66135,22540,48
263.41581,-5.84081,-40.36656,5.81517,40.36656,22540,48
263.62978,-5.62674,-34.17024,5.60110,34.17024,22540,48
263.82778,-5.42865,-28.99085,5.40301,28.99085,22540,48
264.19778,-5.05875,-21.30772,5.03311,21.30772,22540,48
264.82878,-4.42769,-11.35139,4.40205,11.35139,22540,48
265.30881,-4.35665,-12.78621,4.33101,12.78621,22540,48
265.78281,-4.83952,-23.34710,4.81388,23.34710,22604,49
266.03581,-5.09296,-29.33155,5.06732,29.33155,22604,49
266.15078,-5.20801,-32.31259,5.18237,32.31259,22604,49
266.33481,-5.39177,-36.94455,5.36613,36.94455,22604,49
266.48678,-5.54399,-40.76377,5.51835,40.76377,22604,49
266.62078,-5.67800,-44.21191,5.65236,44.21191,22604,49
266.78478,-5.84198,-48.36078,5.81634,48.36077,22604,49
266.94878,-6.00591,-52.41542,5.98026,52.41542,22604,49
267.07778,-6.13503,-55.63024,6.10939,55.63025,22604,49
267.25478,-6.31180,-59.90084,6.28616,59.90084,22604,49
267.39778,-6.45483,-63.43190,6.42919,63.43190,22604,49
267.62878,-6.68586,-69.03447,6.66022,69.03447,22604,49
267.79581,-6.59570,-64.76276,6.57006,64.76276,22604,49
267.95981,-6.42170,-58.60743,6.39606,58.60743,22540,49
268.14678,-6.23126,-52.43968,6.20562,52.43968,22540,49
268.31778,-6.05914,-47.09123,6.03350,47.09123,22540,49
268.52678,-5.84979,-40.51491,5.82415,40.51491,22540,49
268.71681,-5.65978,-34.96789,5.63413,34.96789,22540,49
268.93919,-5.43768,-29.12421,5.41204,29.12421,22540,49
269.28978,-5.08677,-21.70498,5.06113,21.70498,22540,49
269.92578,-4.45074,-11.70632,4.42510,11.70632,22540,49
270.37281,-4.14755,-7.85136,4.12190,7.85136,22540,49
270.73919,-4.26819,-11.48010,4.24255,11.48010,22540,49
271.10981,-4.64679,-19.58480,4.62115,19.58480,22476,49
271.35778,-4.89515,-25.10889,4.86951,25.10889,22476,49
271.62478,-5.16237,-31.51672,5.13673,31.51672,22476,50
271.79481,-5.33233,-35.79263,5.30669,35.79263,22476,50
271.99878,-5.53650,-41.00803,5.51086,41.00803,22476,50
272.17481,-5.71260,-45.32081,5.68696,45.32080,22476,50
272.49781,-6.03547,-53.26241,6.00983,53.26241,22476,50
272.72181,-6.25947,-58.74437,6.23383,58.74437,22476,50
272.96178,-6.49930,-64.65068,6.47365,64.65068,22476,50
273.14381,-6.68140,-68.99334,6.65576,68.99335,22476,50
273.32481,-6.57801,-64.31607,6.55237,64.31607,22476,50
273.54278,-6.34935,-56.39081,6.32371,56.39081,22412,50
273.68978,-6.20054,-51.55827,6.17490,51.55827,22412,50
273.84681,-6.04256,-46.69939,6.01692,46.69939,22412,50
273.97981,-5.90928,-42.54396,5.88364,42.54396,22412,50
274.16181,-5.72737,-37.06951,5.70173,37.06951,22412,50
274.31078,-5.57828,-32.84510,5.55264,32.84510,22412,50
274.44181,-5.44720,-29.48791,5.42156,29.48791,22412,50
274.59878,-5.29026,-25.87918,5.26462,25.87918,22412,50
274.79278,-5.09627,-21.98753,5.07063,21.98753,22412,50
275.03078,-4.85820,-17.79791,4.83256,17.79791,22412,50
275.22478,-4.66425,-14.80125,4.63861,14.80125,22412,50
275.43178,-4.45724,-11.83980,4.43160,11.83980,22412,50
275.57778,-4.31127,-9.62591,4.28563,9.62591,22412,50
275.71178,-4.17740,-7.61391,4.15176,7.61391,22412,50
275.92481,-4.33811,-12.38095,4.31247,12.38095,22412,50
276.14678,-4.56817,-17.48263,4.54253,17.48263,22476,50
276.33178,-4.75486,-21.50446,4.72922,21.50446,22476,50
276.56681,-4.99031,-26.80439,4.96466,26.80439,22476,51
276.73081,-5.15455,-30.93747,5.12891,30.93747,22476,51
276.86678,-5.29040,-34.55377,5.26476,34.55377,22476,51
277.00281,-5.42629,-37.95522,5.40065,37.95522,22476,51
277.21478,-5.63851,-43.26946,5.61287,43.26945,22476,51
277.40178,-5.82558,-48.07426,5.79994,48.07426,22476,51
277.54881,-5.97243,-51.66051,5.94679,51.66051,22476,51
277.70178,-6.12561,-55.39788,6.09996,55.39788,22476,51
277.91478,-6.33836,-60.56297,6.31272,60.56297,22476,51
278.15681,-6.58040,-66.46163,6.55476,66.46163,22476,51
278.39178,-6.63443,-66.24118,6.60879,66.24118,22476,51
278.60878,-6.40262,-57.98706,6.37698,57.98706,22412,51
278.79481,-6.21366,-51.94157,6.18802,51.94157,22412,51
279.01981,-5.98739,-44.74212,5.96175,44.74212,22412,51
279.26278,-5.74435,-37.51280,5.71871,37.51280,22412,51
279.41778,-5.58931,-33.03948,5.56367,33.03949,22412,51
279.61381,-5.39312,-27.95070,5.36748,27.95070,22412,51
279.93681,-5.07034,-21.35890,5.04470,21.35890,22412,51
280.33278,-4.67438,-14.86346,4.64874,14.86346,22412,51
280.61278,-4.39419,-10.79433,4.36855,10.79433,22412,51
280.83578,-4.17143,-7.51147,4.14579,7.51147,22412,51
281.01678,-4.29973,-11.52852,4.27408,11.52852,22412,51
281.15478,-4.44537,-14.79267,4.41973,14.79267,22476,51
281.29581,-4.58956,-17.93862,4.56392,17.93862,22476,51
281.43878,-4.73381,-21.05074,4.70817,21.05074,22476,51
281.53978,-4.83506,-23.34853,4.80942,23.34853,22476,52
281.72378,-5.01930,-27.50337,4.99366,27.50337,22476,52
281.81478,-5.11051,-29.91123,5.08487,29.91123,22476,52
281.91678,-5.21253,-32.46390,5.18689,32.46391,22476,52
282.03919,-5.33445,-35.58605,5.30881,35.58605,22476,52
282.13919,-5.43436,-38.17724,5.40872,38.17724,22476,52
282.26481,-5.56054,-41.21334,5.53490,41.21334,22476,52
282.43681,-5.73262,-45.60599,5.70698,45.60599,22476,52
282.57481,-5.87039,-49.06125,5.84475,49.06125,22476,52
282.70881,-6.00445,-52.42854,5.97881,52.42854,22476,52
282.81778,-6.11361,-55.07438,6.08797,55.07438,22476,52
282.98778,-6.28339,-59.26480,6.25775,59.26480,22476,52
283.12978,-6.42527,-62.68587,6.39963,62.68587,22476,52
283.28878,-6.58438,-66.55528,6.55874,66.55528,22476,52
283.48481,-6.65844,-67.21700,6.63280,67.21700,22476,52
283.63581,-6.49161,-61.08970,6.46597,61.08970,22476,52
283.79081,-6.33120,-55.69280,6.30556,55.69280,22412,52
284.03778,-6.08185,-47.88583,6.05621,47.88583,22412,52
284.24281,-5.87629,-41.45652,5.85065,41.45652,22412,52
284.42978,-5.68939,-35.83677,5.66375,35.83677,22412,52
284.56978,-5.54927,-31.91866,5.52363,31.91866,22412,52
284.77478,-5.34421,-26.81778,5.31857,26.81778,22412,52
285.10481,-5.01413,-20.25298,4.98849,20.25298,22412,52
285.53919,-4.58025,-13.42555,4.55461,13.42555,22412,52
285.93919,-4.18044,-7.64637,4.15480,7.64637,22412,52
286.38981,-4.56921,-17.49313,4.54357,17.49313,22476,52
286.73919,-4.92007,-25.23221,4.89443,25.23221,22476,53
286.96878,-5.15040,-30.85625,5.12476,30.85625,22476,53
287.20278,-5.38420,-36.77373,5.35856,36.77373,22476,53
287.43878,-5.62038,-42.87311,5.59474,42.87311,22476,53
287.63919,-5.82053,-47.90205,5.79489,47.90205,22476,53
287.93919,-6.12056,-55.22150,6.09492,55.22150,22476,53
288.15478,-6.33628,-60.49757,6.31064,60.49757,22476,53
288.35678,-6.53828,-65.44343,6.51264,65.44343,22476,53
288.57778,-6.71499,-69.32083,6.68935,69.32083,22476,53
288.82581,-6.44283,-59.21103,6.41718,59.21103,22412,53
289.05578,-6.20859,-51.61852,6.18295,51.61852,22412,53
289.25581,-6.00742,-45.35773,5.98178,45.35773,22412,53
289.47378,-5.78939,-38.77582,5.76375,38.77582,22412,53
289.68878,-5.57436,-32.46224,5.54872,32.46224,22412,53
289.88478,-5.37813,-27.43325,5.35249,27.43325,22412,53
290.24781,-5.01516,-20.20149,4.98951,20.20149,22412,53
290.90478,-4.35832,-10.24563,4.33268,10.24563,22412,53
291.25581,-4.30434,-11.47468,4.27870,11.47468,22412,53
291.56078,-4.62086,-18.49168,4.59522,18.49168,22476,53
291.86678,-4.92820,-25.32624,4.90256,25.32624,22476,54
292.03978,-5.10157,-29.61567,5.07593,29.61567,22476,54
292.16678,-5.22858,-32.89009,5.20294,32.89008,22476,54
292.30578,-5.36751,-36.35690,5.34187,36.35690,22476,54
292.48578,-5.54762,-40.98895,5.52198,40.98895,22476,54
292.67778,-5.73978,-45.78356,5.71413,45.78356,22476,54
292.90281,-5.96457,-51.39945,5.93893,51.39945,22476,54
293.18078,-6.24269,-58.11661,6.21705,58.11661,22476,54
293.52578,-6.58754,-66.54710,6.56190,66.54710,22476,54
293.76678,-6.63035,-65.84251,6.60471,65.84251,22476,54
294.07581,-6.30564,-54.67074,6.28000,54.67074,22412,54
294.34681,-6.03259,-46.08628,6.00695,46.08628,22412,54
294.56578,-5.81347,-39.45756,5.78783,39.45756,22412,54
294.75581,-5.62333,-33.80239,5.59769,33.80239,22412,54
294.93681,-5.44229,-28.99413,5.41665,28.99413,22412,54
295.30678,-5.07239,-21.32830,5.04675,21.32830,22412,54
295.77381,-4.60530,-13.70740,4.57966,13.70740,22412,54
296.30678,-4.21461,-9.22474,4.18897,9.22474,22412,54
296.72278,-4.65121,-19.13590,4.62557,19.13590,22476,54
297.03581,-4.96533,-26.19599,4.93969,26.19599,22476,55
297.20178,-5.13161,-30.29626,5.10597,30.29626,22476,55
297.39578,-5.32552,-35.19874,5.29988,35.19875,22476,55
297.60278,-5.53255,-40.44912,5.50691,40.44912,22476,55
297.74078,-5.67061,-43.96665,5.64497,43.96666,22476,55
297.98481,-5.91444,-50.05152,5.88879,50.05152,22476,55
298.14778,-6.07768,-54.00143,6.05204,54.00143,22476,55
298.33781,-6.26753,-58.64946,6.24189,58.64946,22476,55
298.50378,-6.43338,-62.76510,6.40774,62.76510,22476,55
298.68681,-6.61646,-67.23651,6.59082,67.23651,22476,55
298.83478,-6.69969,-68.65290,6.67405,68.65290,22476,55
299.03281,-6.47952,-60.48561,6.45388,60.48561,22476,55
299.29081,-6.21567,-51.76452,6.19003,51.76452,22412,55
299.57581,-5.92937,-42.91983,5.90373,42.91983,22412,55
299.83919,-5.66637,-34.99463,5.64073,34.99463,22412,55
300.12978,-5.37515,-27.39746,5.34951,27.39746,22412,55
300.76578,-4.73937,-15.74205,4.71373,15.74205,22412,55
301.39381,-4.16219,-7.55678,4.13655,7.55679,22412,55
301.88478,-4.68147,-19.69598,4.65583,19.69598,22476,55
302.33919,-5.13654,-30.28389,5.11090,30.28389,22476,56
302.60778,-5.40528,-37.21677,5.37964,37.21677,22476,56
302.89278,-5.69060,-44.45665,5.66496,44.45665,22476,56
303.09378,-5.89135,-49.45222,5.86571,49.45222,22476,56
303.29581,-6.09363,-54.39751,6.06799,54.39751,22476,56
303.47778,-6.27541,-58.88121,6.24977,58.88121,22476,56
303.70378,-6.50141,-64.42284,6.47577,64.42284,22476,56
303.90478,-6.70239,-69.31473,6.67675,69.31473,22476,56
304.15378,-6.49924,-61.11030,6.47360,61.11030,22476,56
304.43919,-6.20753,-51.52716,6.18189,51.52716,22412,56
304.70978,-5.93532,-43.07158,5.90968,43.07158,22412,56
304.99381,-5.65126,-34.57133,5.62562,34.57133,22412,56
305.17678,-5.46817,-29.69594,5.44253,29.69594,22412,56
305.36978,-5.27521,-25.31005,5.24957,25.31005,22412,56
305.74678,-4.89810,-18.30379,4.87246,18.30379,22412,56
306.35181,-4.29323,-9.19839,4.26758,9.19839,22412,56
306.76278,-4.44487,-14.52063,4.41923,14.52063,22476,56
307.23919,-4.92608,-25.16333,4.90044,25.16333,22476,57
307.50681,-5.19458,-31.70323,5.16894,31.70323,22476,57
307.80178,-5.48944,-39.42576,5.46380,39.42576,22476,57
308.13981,-5.82755,-47.97744,5.80191,47.97744,22476,57
308.47378,-6.16160,-56.06652,6.13596,56.06652,22476,57
308.73919,-6.42630,-62.57439,6.40066,62.57439,22476,57
308.97681,-6.66434,-68.36313,6.63870,68.36313,22476,57
309.21281,-6.54949,-62.85667,6.52384,62.85667,22476,57
309.43919,-6.31474,-54.91433,6.28910,54.91433,22412,57
309.65781,-6.09386,-48.04464,6.06822,48.04464,22412,57
310.02878,-5.72245,-36.58889,5.69681,36.58889,22412,57
310.26678,-5.48421,-30.04446,5.45856,30.04446,22412,57
310.57178,-5.17944,-23.32328,5.15380,23.32328,22412,57
311.13919,-4.61229,-13.79627,4.58665,13.79627,22412,57
311.51578,-4.23547,-8.31717,4.20983,8.31717,22412,57
311.82778,-4.40425,-13.56355,4.37861,13.56355,22412,57
312.07278,-4.65523,-19.08795,4.62959,19.08795,22604,57
312.31578,-4.89925,-24.51197,4.87361,24.51197,22604,57
312.50278,-5.08668,-29.01521,5.06104,29.01521,22604,58
312.63878,-5.22266,-32.42674,5.19702,32.42675,22604,58
312.79481,-5.37852,-36.42161,5.35288,36.42161,22604,58
312.97078,-5.55468,-40.90625,5.52904,40.90625,22604,58
313.13278,-5.71677,-45.01255,5.69112,45.01255,22604,58
313.30578,-5.88956,-49.35318,5.86391,49.35318,22604,58
313.45778,-6.04165,-53.06363,6.01601,53.06363,22604,58
313.65178,-6.23577,-57.88335,6.21013,57.88335,22604,58
313.86078,-6.44449,-62.97841,6.41885,62.97841,22604,58
314.14278,-6.72579,-69.82352,6.70015,69.82352,22604,58
314.36781,-6.51597,-61.50812,6.49033,61.50812,22604,58
314.65178,-6.22486,-51.96413,6.19921,51.96413,22540,58
314.90281,-5.97259,-44.09730,5.94695,44.09730,22540,58
315.14881,-5.72664,-36.73928,5.70099,36.73928,22540,58
315.40781,-5.46742,-29.53665,5.44178,29.53665,22540,58
315.77678,-5.09855,-21.73917,5.07291,21.73917,22540,58
316.53919,-4.33657,-9.82350,4.31093,9.82350,22540,58
317.03681,-4.49283,-15.54059,4.46719,15.54059,22604,58
317.53078,-4.99066,-26.65419,4.96502,26.65419,22604,59
317.82678,-5.28691,-34.13033,5.26127,34.13033,22604,59
318.06978,-5.52995,-40.21999,5.50431,40.21999,22604,59
318.35378,-5.81401,-47.57003,5.78837,47.57003,22604,59
318.66981,-6.13003,-55.24076,6.10439,55.24076,22604,59
318.91581,-6.37573,-61.34282,6.35009,61.34282,22604,59
319.13919,-6.59883,-66.69229,6.57319,66.69229,22604,59
319.41378,-6.59161,-64.28390,6.56597,64.28390,22604,59
319.63678,-6.35777,-56.19413,6.33213,56.19413,22540,59
319.95278,-6.03903,-46.10994,6.01339,46.10994,22540,59
320.33919,-5.65279,-34.61587,5.62715,34.61587,22540,59
320.79778,-5.19388,-23.44888,5.16824,23.44888,22540,59
321.39278,-4.59876,-13.54364,4.57311,13.54364,22540,59
321.84478,-4.14973,-7.04616,4.12408,7.04616,22540,59