File: data-raw/Experiment 2/Results/INSTRON data/Experiment 2.is_ccyclic_RawData/Specimen_RawData_4.csv
Text Inputs : Specimen label,"Long Plate 2 Test 1"

Time,Extension,Load,Compressive extension,Compressive load,Segment ID,Total Cycle Count
(sec),(mm),(N),(mm),(N),,
0.00000,-0.02696,-0.07835,0.00000,0.07835,12835,0
2.67120,-0.76212,-0.14680,0.73515,0.14680,3220,0
3.74980,-1.30161,-4.34529,1.27465,4.34529,3220,0
4.73180,-2.10422,-14.26720,2.07726,14.26720,22476,0
5.63980,-3.01250,-26.21596,2.98554,26.21596,22476,0
6.17980,-3.55251,-35.44730,3.52555,35.44730,22476,0
6.74280,-4.11537,-45.70308,4.08841,45.70308,22476,0
7.25780,-4.63057,-55.06665,4.60361,55.06665,22476,0
7.72780,-5.10043,-63.51224,5.07347,63.51224,22476,0
8.07120,-5.44355,-69.37703,5.41659,69.37703,22476,0
8.56480,-4.99487,-58.34544,4.96791,58.34544,22412,0
8.93680,-4.62153,-49.87112,4.59456,49.87112,22412,0
9.21880,-4.33937,-43.85977,4.31241,43.85977,22412,0
9.60280,-3.95529,-36.13517,3.92833,36.13517,22412,0
9.95580,-3.60219,-29.30219,3.57523,29.30219,22412,0
10.67120,-2.88744,-18.47736,2.86047,18.47736,22412,0
11.67120,-1.88763,-7.29374,1.86067,7.29374,22412,0
12.47120,-2.67330,-18.47787,2.64634,18.47787,22476,1
13.19480,-3.39761,-30.10583,3.37064,30.10583,22476,1
13.59680,-3.79964,-37.66622,3.77268,37.66623,22476,1
13.91580,-4.11840,-43.58704,4.09144,43.58704,22476,1
14.27120,-4.47348,-50.21140,4.44652,50.21140,22476,1
14.69180,-4.89457,-58.16875,4.86760,58.16875,22476,1
15.08780,-5.29072,-65.71013,5.26376,65.71013,22476,1
15.52380,-5.29702,-64.46028,5.27006,64.46028,22476,1
15.93180,-4.88107,-54.85104,4.85411,54.85104,22412,1
16.22780,-4.58445,-48.28130,4.55749,48.28130,22412,1
16.48380,-4.32846,-42.88315,4.30150,42.88315,22412,1
16.87120,-3.94142,-35.17202,3.91445,35.17202,22412,1
17.11780,-3.69435,-30.44384,3.66739,30.44384,22412,1
17.64280,-3.16930,-21.69516,3.14234,21.69516,22412,1
18.57120,-2.24155,-10.78955,2.21459,10.78955,22412,1
19.35580,-2.36688,-13.77298,2.33992,13.77298,22476,1
20.07120,-3.08349,-24.07672,3.05653,24.07672,22476,2
20.62180,-3.63462,-34.01195,3.60766,34.01195,22476,2
21.15580,-4.16855,-43.94894,4.14159,43.94894,22476,2
21.77120,-4.78357,-55.51964,4.75661,55.51964,22476,2
22.37120,-5.38382,-66.93074,5.35685,66.93074,22476,2
22.77180,-5.29562,-63.85829,5.26866,63.85829,22476,2
23.26480,-4.79572,-52.39666,4.76876,52.39666,22412,2
23.66180,-4.39862,-43.92080,4.37166,43.92080,22412,2
24.03380,-4.02652,-36.43103,3.99955,36.43103,22412,2
24.47080,-3.58935,-28.00616,3.56238,28.00616,22412,2
25.10580,-2.95450,-18.56420,2.92754,18.56420,22412,2
26.07120,-1.98945,-7.73808,1.96249,7.73808,22412,2
26.77120,-2.60108,-16.65863,2.57412,16.65863,22476,3
27.48480,-3.31578,-27.54463,3.28882,27.54463,22476,3
27.88280,-3.71380,-35.07037,3.68684,35.07037,22476,3
28.41780,-4.24883,-45.06114,4.22187,45.06114,22476,3
28.89580,-4.72680,-54.12347,4.69983,54.12347,22476,3
29.34080,-5.17187,-62.56229,5.14491,62.56229,22476,3
29.75780,-5.55611,-69.79711,5.52915,69.79710,22476,3
30.02180,-5.26978,-62.93980,5.24282,62.93980,22412,3
30.31080,-4.97618,-56.20295,4.94922,56.20295,22412,3
30.54280,-4.74366,-50.92853,4.71670,50.92853,22412,3
30.83680,-4.44946,-44.65550,4.42250,44.65550,22412,3
31.17120,-4.11536,-37.89735,4.08840,37.89735,22412,3
31.56280,-3.72352,-30.31523,3.69656,30.31523,22412,3
32.15080,-3.13543,-20.68003,3.10846,20.68003,22412,3
32.88280,-2.40355,-12.09740,2.37658,12.09740,22412,3
33.47120,-2.08955,-9.41523,2.06259,9.41523,22412,3
34.27120,-2.90369,-20.64312,2.87673,20.64312,22476,4
34.88280,-3.51561,-31.06668,3.48865,31.06668,22476,4
35.24780,-3.88070,-37.99925,3.85374,37.99925,22476,4
35.64980,-4.28278,-45.55317,4.25582,45.55317,22476,4
35.90980,-4.54259,-50.51817,4.51563,50.51817,22476,4
36.32080,-4.95367,-58.17291,4.92671,58.17291,22476,4
36.71880,-5.35179,-65.76869,5.32483,65.76869,22476,4
37.07120,-5.43562,-66.61236,5.40865,66.61237,22476,4
37.50280,-4.99017,-56.30317,4.96321,56.30317,22412,4
37.81480,-4.67759,-49.24303,4.65063,49.24303,22412,4
38.16480,-4.32748,-41.98058,4.30051,41.98058,22412,4
38.57480,-3.91747,-33.85985,3.89051,33.85985,22412,4
39.27120,-3.22131,-21.80173,3.19435,21.80173,22412,4
40.27120,-2.22144,-10.02820,2.19448,10.02820,22412,4
41.11980,-2.56970,-15.79057,2.54274,15.79057,22476,4
41.91680,-3.36760,-28.02089,3.34064,28.02089,22476,5
42.47120,-3.92158,-38.58180,3.89462,38.58179,22476,5
43.14080,-4.59150,-51.19041,4.56454,51.19041,22476,5
43.81180,-5.26274,-63.91599,5.23578,63.91599,22476,5
44.33780,-5.36733,-64.85016,5.34037,64.85016,22476,5
44.80380,-4.89292,-53.90021,4.86595,53.90021,22412,5
45.36980,-4.32645,-41.77845,4.29949,41.77845,22412,5
46.00380,-3.69232,-29.29270,3.66536,29.29270,22412,5
46.77120,-2.92544,-17.73236,2.89848,17.73236,22412,5
47.74680,-2.00050,-7.55161,1.97354,7.55161,22412,5
48.58380,-2.86660,-19.74230,2.83964,19.74230,22476,6
49.28880,-3.57153,-31.67652,3.54456,31.67652,22476,6
49.77120,-4.05356,-40.85388,4.02660,40.85389,22476,6
50.41680,-4.69964,-53.01578,4.67268,53.01578,22476,6
51.01780,-5.30075,-64.51812,5.27379,64.51813,22476,6
51.50480,-5.38886,-65.20937,5.36190,65.20937,22476,6
52.05180,-4.83246,-52.41271,4.80550,52.41272,22412,6
52.57120,-4.31333,-41.42170,4.28637,41.42170,22412,6
53.07120,-3.81332,-31.39645,3.78636,31.39645,22412,6
53.58780,-3.29624,-22.67359,3.26928,22.67359,22412,6
54.45980,-2.42422,-12.03544,2.39726,12.03544,22412,6
55.33180,-2.42227,-13.53090,2.39531,13.53090,22476,6
56.17120,-3.26341,-26.03245,3.23645,26.03245,22476,7
56.73980,-3.83245,-36.59401,3.80549,36.59401,22476,7
57.26280,-4.35552,-46.54478,4.32856,46.54478,22476,7
57.77120,-4.86339,-56.08124,4.83643,56.08124,22476,7
58.42580,-5.51841,-68.56442,5.49145,68.56442,22476,7
58.77120,-5.31696,-63.36107,5.29000,63.36107,22476,7
59.19780,-4.88446,-53.40420,4.85750,53.40421,22412,7
59.67280,-4.40911,-43.27135,4.38214,43.27135,22412,7
60.09280,-3.98902,-34.78190,3.96205,34.78189,22412,7
60.55980,-3.52197,-26.12829,3.49501,26.12829,22412,7
61.37120,-2.71082,-15.05102,2.68386,15.05102,22412,7
62.26780,-2.17132,-10.13372,2.14436,10.13372,22412,7
63.02380,-2.93812,-20.60086,2.91116,20.60086,22604,8
63.67120,-3.58505,-31.70927,3.55809,31.70927,22604,8
64.24780,-4.16208,-42.78133,4.13512,42.78133,22604,8
64.71480,-4.62915,-51.57323,4.60219,51.57323,22604,8
65.13280,-5.04709,-59.48919,5.02013,59.48919,22604,8
65.57980,-5.49414,-67.94685,5.46718,67.94685,22604,8
65.95580,-5.32161,-63.32414,5.29465,63.32414,22604,8
66.30980,-4.96220,-55.12239,4.93524,55.12239,22540,8
66.64480,-4.62684,-47.76510,4.59988,47.76510,22540,8
67.07180,-4.19957,-38.92460,4.17261,38.92461,22540,8
67.63980,-3.63167,-27.80537,3.60471,27.80537,22540,8
68.45780,-2.81373,-16.14174,2.78677,16.14174,22540,8
69.31380,-2.01469,-7.50740,1.98773,7.50740,22540,8
70.17120,-2.90087,-19.96083,2.87391,19.96083,22604,9
70.87120,-3.60076,-31.89939,3.57380,31.89939,22604,9
71.37980,-4.10970,-41.63670,4.08273,41.63670,22604,9
71.89880,-4.62885,-51.50092,4.60189,51.50092,22604,9
72.51080,-5.24095,-63.15774,5.21399,63.15774,22604,9
73.07120,-5.39378,-64.96539,5.36682,64.96539,22604,9
73.53980,-4.91588,-54.03043,4.88892,54.03043,22540,9
73.99180,-4.46342,-44.20018,4.43646,44.20018,22540,9
74.32280,-4.13235,-37.45847,4.10539,37.45847,22540,9
74.69180,-3.76351,-30.24424,3.73655,30.24424,22540,9
75.51280,-2.94246,-17.60644,2.91550,17.60644,22540,9
76.56780,-2.01029,-7.41485,1.98333,7.41485,22540,9
77.53180,-2.72877,-17.63145,2.70181,17.63145,22476,9
78.27120,-3.46795,-29.48997,3.44099,29.48997,22476,10
78.68980,-3.88701,-37.56915,3.86005,37.56915,22476,10
79.08980,-4.28708,-44.95438,4.26012,44.95438,22476,10
79.57280,-4.76992,-54.09545,4.74296,54.09545,22476,10
80.08880,-5.28611,-63.98276,5.25915,63.98276,22476,10
80.64680,-5.34670,-63.80620,5.31974,63.80620,22476,10
81.05080,-4.93607,-54.39887,4.90911,54.39887,22412,10
81.51380,-4.47264,-44.33561,4.44568,44.33561,22412,10
82.01780,-3.96864,-34.26195,3.94168,34.26194,22412,10
82.47120,-3.51561,-25.83231,3.48865,25.83231,22412,10
83.07120,-2.91571,-17.19360,2.88875,17.19360,22412,10
83.99980,-2.00655,-7.18161,1.97959,7.18161,22412,10
84.77780,-2.80871,-18.58773,2.78175,18.58773,22476,11
85.43180,-3.46273,-29.15300,3.43577,29.15300,22476,11
85.93580,-3.96673,-38.91066,3.93977,38.91066,22476,11
86.57780,-4.60871,-51.04398,4.58175,51.04398,22476,11
87.21980,-5.25090,-63.21031,5.22394,63.21031,22476,11
87.67120,-5.50322,-67.43889,5.47626,67.43889,22476,11
88.04280,-5.11489,-58.39653,5.08793,58.39653,22412,11
88.41380,-4.74260,-49.93813,4.71564,49.93813,22412,11
88.84580,-4.31052,-40.84654,4.28356,40.84654,22412,11
89.33580,-3.82049,-31.15421,3.79352,31.15421,22412,11
90.01980,-3.13639,-19.97399,3.10943,19.97399,22412,11
90.97120,-2.18538,-9.08478,2.15842,9.08478,22412,11
91.67680,-2.58449,-15.31533,2.55753,15.31533,22476,11
92.38780,-3.29664,-26.12393,3.26968,26.12393,22476,12
92.96980,-3.87867,-37.07612,3.85171,37.07612,22476,12
93.44980,-4.35874,-46.20658,4.33178,46.20658,22476,12
93.91680,-4.82555,-55.02422,4.79859,55.02422,22476,12
94.46780,-5.37679,-65.60246,5.34983,65.60246,22476,12
94.88180,-5.39405,-64.87878,5.36709,64.87878,22476,12
95.32380,-4.94284,-54.52576,4.91588,54.52576,22412,12
95.83380,-4.43236,-43.42183,4.40540,43.42183,22412,12
96.28480,-3.98137,-34.33412,3.95441,34.33411,22412,12
96.78380,-3.48236,-25.16595,3.45540,25.16595,22412,12
97.70780,-2.55816,-13.03713,2.53120,13.03713,22412,12
98.62780,-2.38952,-12.71698,2.36256,12.71698,22476,12
99.47120,-3.23548,-24.99612,3.20852,24.99612,22476,13
99.95980,-3.72458,-34.10226,3.69762,34.10226,22476,13
100.47120,-4.23554,-43.84464,4.20858,43.84464,22476,13
100.90380,-4.66862,-52.05223,4.64166,52.05223,22476,13
101.47120,-5.23563,-62.87733,5.20867,62.87733,22476,13
101.93180,-5.53649,-68.15769,5.50953,68.15768,22476,13
102.30980,-5.13977,-58.89161,5.11281,58.89161,22412,13
102.64080,-4.80731,-51.41965,4.78035,51.41965,22412,13
103.16080,-4.28726,-40.22241,4.26030,40.22241,22412,13
103.74380,-3.70413,-28.85704,3.67717,28.85704,22412,13
104.57380,-2.87427,-16.62612,2.84731,16.62612,22412,13
105.49980,-2.06827,-8.02142,2.04131,8.02142,22412,13
106.37120,-2.96323,-20.54796,2.93627,20.54796,22476,14
107.05980,-3.65231,-32.59355,3.62535,32.59355,22476,14
107.65180,-4.24435,-44.01146,4.21739,44.01146,22476,14
108.21680,-4.80924,-54.65189,4.78228,54.65189,22476,14
108.77120,-5.36343,-65.27528,5.33647,65.27528,22476,14
109.29380,-5.31751,-62.97404,5.29055,62.97404,22476,14
109.77980,-4.82615,-51.79321,4.79919,51.79321,22412,14
110.37280,-4.23297,-39.23886,4.20601,39.23885,22412,14
110.92980,-3.67592,-28.26351,3.64896,28.26351,22412,14
111.77180,-2.83398,-16.08284,2.80702,16.08284,22412,14
112.64480,-2.07662,-8.06086,2.04966,8.06086,22412,14
113.48780,-2.94404,-20.21415,2.91708,20.21415,22476,15
114.21580,-3.67215,-32.92881,3.64519,32.92881,22476,15
114.82680,-4.28324,-44.65148,4.25628,44.65148,22476,15
115.47120,-4.92708,-56.89320,4.90012,56.89320,22476,15
116.10780,-5.56402,-69.03747,5.53706,69.03747,22476,15
116.50580,-5.24518,-61.28878,5.21822,61.28878,22412,15
116.98480,-4.76289,-50.30637,4.73592,50.30637,22412,15
117.42280,-4.32483,-40.91293,4.29786,40.91293,22412,15
117.81280,-3.93476,-33.21526,3.90780,33.21526,22412,15
118.37120,-3.37688,-23.32568,3.34992,23.32568,22412,15
119.18080,-2.56652,-13.00836,2.53956,13.00836,22412,15
119.92780,-2.23911,-10.57814,2.21215,10.57814,22412,15
120.68780,-3.00785,-21.21137,2.98089,21.21137,22476,16
121.25780,-3.57780,-31.00527,3.55084,31.00527,22476,16
121.72280,-4.04287,-40.04101,4.01591,40.04101,22476,16
122.16680,-4.48682,-48.60515,4.45986,48.60515,22476,16
122.68180,-5.00183,-58.14866,4.97486,58.14866,22476,16
122.96780,-5.28802,-63.79629,5.26106,63.79629,22476,16
123.41080,-5.47337,-66.62662,5.44641,66.62663,22476,16
123.70580,-5.16563,-59.41392,5.13867,59.41392,22412,16
124.03780,-4.83180,-51.90561,4.80484,51.90561,22412,16
124.45480,-4.41467,-42.81741,4.38771,42.81741,22412,16
124.82580,-4.04358,-35.27635,4.01662,35.27635,22412,16
125.33980,-3.52953,-25.75189,3.50257,25.75189,22412,16
126.07120,-2.79862,-15.57590,2.77166,15.57590,22412,16
127.01580,-2.21708,-10.17494,2.19012,10.17494,22412,16
127.77120,-2.98263,-20.72455,2.95567,20.72455,22476,17
128.41780,-3.62967,-31.90337,3.60271,31.90337,22476,17
128.93880,-4.15059,-42.06462,4.12363,42.06462,22476,17
129.46579,-4.67777,-52.09915,4.65081,52.09915,22476,17
130.02080,-5.23270,-62.69452,5.20573,62.69452,22476,17
130.53780,-5.47118,-66.42766,5.44422,66.42767,22476,17
131.04779,-4.94773,-54.43401,4.92077,54.43401,22412,17
131.57180,-4.42336,-42.93344,4.39640,42.93344,22412,17
132.05080,-3.94432,-33.28157,3.91736,33.28157,22412,17
132.66080,-3.33432,-22.62545,3.30736,22.62545,22412,17
133.47119,-2.52427,-12.49430,2.49731,12.49430,22412,17
134.24980,-2.37087,-12.24518,2.34391,12.24518,22604,17
135.07280,-3.19829,-24.12953,3.17133,24.12953,22604,18
135.66780,-3.79348,-35.11361,3.76652,35.11361,22604,18
136.16080,-4.28655,-44.63743,4.25959,44.63744,22604,18
136.52380,-4.64943,-51.53453,4.62247,51.53453,22604,18
136.97119,-5.09628,-60.02766,5.06932,60.02766,22604,18
137.57120,-5.52775,-67.81884,5.50079,67.81884,22604,18
138.02480,-5.05487,-56.85320,5.02791,56.85320,22540,18
138.41178,-4.66718,-48.10097,4.64022,48.10097,22540,18
138.77780,-4.30114,-40.28580,4.27417,40.28580,22540,18
139.05880,-4.02006,-34.78581,3.99310,34.78581,22540,18
139.37080,-3.70803,-28.68484,3.68107,28.68484,22540,18
139.98580,-3.09288,-19.20900,3.06592,19.20900,22540,18
140.97119,-2.10785,-7.83697,2.08089,7.83697,22540,18
141.75580,-2.77901,-17.73254,2.75205,17.73254,22604,19
142.44080,-3.46412,-28.75759,3.43716,28.75759,22604,19
142.90180,-3.92519,-37.75652,3.89822,37.75652,22604,19
143.31280,-4.33628,-45.53847,4.30931,45.53847,22604,19
143.81478,-4.83811,-55.15082,4.81115,55.15082,22604,19
144.37120,-5.39433,-65.71943,5.36737,65.71944,22604,19
144.86580,-5.34695,-63.44764,5.31998,63.44764,22604,19
145.18978,-5.01749,-55.94668,4.99053,55.94668,22540,19
145.73680,-4.46986,-43.78633,4.44290,43.78633,22540,19
146.22580,-3.98086,-33.91347,3.95390,33.91347,22540,19
146.77119,-3.43584,-24.06372,3.40888,24.06372,22540,19
147.66380,-2.54273,-12.62777,2.51577,12.62777,22540,19
148.48080,-2.04542,-7.42148,2.01846,7.42148,22540,19
149.33480,-2.87884,-19.25202,2.85188,19.25202,22476,19
150.04680,-3.59072,-31.18279,3.56376,31.18279,22476,20
150.53180,-4.07577,-40.55863,4.04881,40.55863,22476,20
151.12980,-4.67389,-52.01660,4.64693,52.01660,22476,20
151.76480,-5.30890,-64.11469,5.28194,64.11469,22476,20
152.27119,-5.43054,-65.42502,5.40357,65.42502,22476,20
152.69780,-4.99409,-55.37147,4.96713,55.37148,22412,20
152.94380,-4.74768,-49.76279,4.72072,49.76279,22412,20
153.41178,-4.27965,-39.81017,4.25269,39.81017,22412,20
153.90880,-3.78264,-30.03454,3.75568,30.03454,22412,20
154.63980,-3.05144,-18.63007,3.02448,18.63007,22412,20
155.51580,-2.17544,-8.55019,2.14848,8.55019,22412,20
156.30580,-2.71507,-16.76542,2.68811,16.76542,22476,21
157.08080,-3.49052,-29.08231,3.46356,29.08231,22476,21
157.64980,-4.05952,-40.14447,4.03256,40.14447,22476,21
158.18978,-4.59948,-50.54975,4.57252,50.54975,22476,21
158.66580,-5.07541,-59.62636,5.04845,59.62636,22476,21
159.03080,-5.44060,-66.59203,5.41364,66.59203,22476,21
159.47119,-5.34650,-63.41831,5.31954,63.41831,22476,21
159.84780,-4.96369,-54.66960,4.93673,54.66960,22412,21
160.37120,-4.44025,-43.12525,4.41329,43.12524,22412,21
160.73480,-4.07616,-35.71635,4.04920,35.71635,22412,21
161.24680,-3.56412,-26.19347,3.53716,26.19347,22412,21
162.00080,-2.81030,-15.59915,2.78334,15.59915,22412,21
162.92980,-2.23647,-10.24290,2.20951,10.24290,22412,21
163.77180,-3.08913,-22.21330,3.06217,22.21330,22476,22
164.45180,-3.76943,-34.53417,3.74247,34.53418,22476,22
165.04780,-4.36542,-46.01172,4.33846,46.01172,22476,22
165.73780,-5.05516,-59.15069,5.02819,59.15069,22476,22
166.27119,-5.58812,-69.40211,5.56116,69.40211,22476,22
166.73780,-5.15066,-58.92751,5.12370,58.92751,22412,22
167.18580,-4.70103,-48.77345,4.67407,48.77345,22412,22
167.70880,-4.17776,-37.74511,4.15079,37.74511,22412,22
168.32180,-3.56476,-26.16921,3.53780,26.16920,22412,22
169.03380,-2.85294,-16.09409,2.82598,16.09409,22412,22
169.96778,-2.20116,-9.64638,2.17420,9.64638,22412,22
170.81380,-3.06073,-21.73290,3.03377,21.73290,22476,23
171.44780,-3.69491,-32.95657,3.66795,32.95657,22476,23
171.95580,-4.20282,-42.87966,4.17586,42.87966,22476,23
172.43480,-4.68195,-52.06895,4.65499,52.06895,22476,23
172.98180,-5.22890,-62.56920,5.20194,62.56920,22476,23
173.37980,-5.61194,-69.86694,5.58498,69.86694,22476,23
173.75980,-5.21311,-60.34167,5.18615,60.34167,22412,23
174.07480,-4.89601,-53.06838,4.86905,53.06839,22412,23
174.55880,-4.41166,-42.39835,4.38470,42.39835,22412,23
174.99280,-3.97759,-33.82530,3.95063,33.82530,22412,23
175.49080,-3.47959,-24.68743,3.45263,24.68743,22412,23
176.42180,-2.54843,-12.62029,2.52147,12.62029,22412,23
177.30980,-2.46583,-13.25161,2.43887,13.25161,22476,23
178.13980,-3.29858,-25.61651,3.27162,25.61651,22476,24
178.77580,-3.93454,-37.66447,3.90758,37.66447,22476,24
179.47119,-4.62954,-51.08282,4.60258,51.08282,22476,24
180.02280,-5.18153,-61.59657,5.15457,61.59657,22476,24
180.61980,-5.47313,-66.35074,5.44617,66.35074,22476,24
181.08780,-4.99282,-55.26482,4.96585,55.26482,22412,24
181.54980,-4.53030,-44.83187,4.50334,44.83187,22412,24
181.97080,-4.10913,-36.26226,4.08217,36.26226,22412,24
182.37780,-3.70226,-28.38360,3.67530,28.38360,22412,24
183.17678,-2.90337,-16.65921,2.87641,16.65921,22412,24
184.07120,-2.12914,-8.36776,2.10218,8.36776,22412,24
184.87120,-2.95318,-19.92136,2.92622,19.92136,22476,25
185.59380,-3.67634,-32.53711,3.64938,32.53711,22476,25
186.15580,-4.23833,-43.54557,4.21137,43.54557,22476,25
186.67119,-4.75328,-53.31258,4.72632,53.31258,22476,25
187.17678,-5.25943,-63.09405,5.23247,63.09405,22476,25
187.69480,-5.47398,-66.28890,5.44702,66.28890,22476,25
188.14380,-5.01261,-55.69221,4.98565,55.69221,22412,25
188.56580,-4.58999,-46.08458,4.56303,46.08458,22412,25
189.07120,-4.08487,-35.73823,4.05790,35.73823,22412,25
189.66280,-3.49302,-24.87639,3.46605,24.87639,22412,25
190.50280,-2.65289,-13.66458,2.62593,13.66458,22412,25
191.39980,-2.39365,-12.24862,2.36669,12.24862,22476,25
192.25180,-3.25002,-24.69417,3.22306,24.69417,22476,26
192.67180,-3.67008,-32.39139,3.64312,32.39139,22476,26
193.16378,-4.16194,-41.99432,4.13498,41.99432,22476,26
193.62580,-4.62399,-50.94710,4.59703,50.94710,22476,26
194.03480,-5.03290,-58.59990,5.00594,58.59990,22476,26
194.47580,-5.47401,-67.18086,5.44704,67.18086,22476,26
194.86980,-5.34012,-63.29200,5.31315,63.29200,22476,26
195.27119,-4.93313,-53.94646,4.90617,53.94646,22412,26
195.64580,-4.55768,-45.41594,4.53072,45.41594,22412,26
195.98980,-4.21363,-38.35298,4.18667,38.35298,22412,26
196.37120,-3.83274,-30.80644,3.80578,30.80644,22412,26
196.94178,-3.26175,-21.35336,3.23478,21.35336,22412,26
197.85980,-2.34385,-10.22576,2.31689,10.22576,22412,26
198.50280,-2.43332,-12.70585,2.40636,12.70585,22476,26
199.28480,-3.21854,-24.13774,3.19158,24.13774,22476,27
199.90078,-3.83473,-35.59702,3.80777,35.59702,22476,27
200.47180,-4.40578,-46.78294,4.37882,46.78294,22476,27
200.97119,-4.90468,-56.25544,4.87772,56.25544,22476,27
201.45478,-5.38882,-65.57629,5.36186,65.57629,22476,27
201.87278,-5.42451,-65.25411,5.39755,65.25410,22476,27
202.27119,-5.01707,-55.82155,4.99011,55.82154,22412,27
202.68880,-4.59840,-46.28700,4.57144,46.28700,22412,27
203.30680,-3.98040,-33.70737,3.95344,33.70737,22412,27
203.99778,-3.28943,-21.65710,3.26247,21.65710,22412,27
204.97119,-2.31656,-9.93848,2.28960,9.93848,22412,27
205.77119,-2.64140,-15.52799,2.61444,15.52799,22604,27
206.51980,-3.39152,-27.03848,3.36456,27.03848,22604,28
207.07120,-3.94240,-37.70293,3.91544,37.70293,22604,28
207.54180,-4.41351,-46.92034,4.38655,46.92035,22604,28
208.07120,-4.94236,-56.97257,4.91540,56.97257,22604,28
208.57120,-5.44240,-66.58683,5.41544,66.58683,22604,28
208.97080,-5.38825,-64.37170,5.36129,64.37170,22604,28
209.40280,-4.94854,-54.24581,4.92158,54.24581,22540,28
209.86980,-4.48115,-43.77181,4.45419,43.77181,22540,28
210.30980,-4.04113,-34.86269,4.01417,34.86269,22540,28
210.89080,-3.46011,-24.21898,3.43315,24.21898,22540,28
211.83980,-2.51115,-12.13203,2.48419,12.13203,22540,28
212.65680,-2.47716,-13.21727,2.45020,13.21727,22604,28
213.42380,-3.24703,-24.56733,3.22007,24.56733,22604,29
213.92580,-3.74915,-33.97759,3.72219,33.97759,22604,29
214.46978,-4.29320,-44.43850,4.26623,44.43850,22604,29
215.02180,-4.84501,-55.06062,4.81805,55.06062,22604,29
215.47080,-5.29418,-63.72648,5.26721,63.72648,22604,29
215.87120,-5.55383,-68.30461,5.52687,68.30460,22604,29
216.34380,-5.05950,-56.77488,5.03254,56.77488,22540,29
216.65580,-4.74688,-49.65286,4.71992,49.65286,22540,29
217.11180,-4.29084,-39.79411,4.26388,39.79411,22540,29
217.61680,-3.78583,-29.80286,3.75887,29.80286,22540,29
218.37880,-3.02372,-17.99111,2.99676,17.99111,22540,29
219.42580,-2.07812,-7.34970,2.05116,7.34970,22540,29
220.27119,-2.68231,-16.18729,2.65535,16.18729,22476,29
220.99778,-3.40980,-27.49306,3.38283,27.49306,22476,30
221.39480,-3.80677,-35.19568,3.77981,35.19568,22476,30
221.83780,-4.24979,-43.78794,4.22283,43.78794,22476,30
222.37180,-4.78366,-53.94152,4.75670,53.94152,22476,30
223.02578,-5.43772,-66.49111,5.41075,66.49111,22476,30
223.52780,-5.26125,-61.52052,5.23429,61.52052,22412,30
224.01380,-4.77148,-50.31464,4.74452,50.31464,22412,30
224.56580,-4.21921,-38.39276,4.19225,38.39276,22412,30
225.07880,-3.70627,-28.28895,3.67931,28.28895,22412,30
225.78380,-3.00134,-17.71665,2.97438,17.71665,22412,30
226.76480,-2.12452,-8.07747,2.09756,8.07747,22412,30
227.59278,-2.97813,-20.21855,2.95117,20.21855,22476,31
228.27578,-3.66126,-32.16610,3.63430,32.16610,22476,31
228.91080,-4.29640,-44.55543,4.26944,44.55543,22476,31
229.55980,-4.94520,-57.00923,4.91824,57.00923,22476,31
230.13980,-5.52516,-68.14060,5.49820,68.14060,22476,31
230.59580,-5.25425,-61.24532,5.22729,61.24532,22412,31
231.07120,-4.77601,-50.37194,4.74905,50.37194,22412,31
231.45080,-4.39599,-41.85086,4.36903,41.85086,22412,31
231.82780,-4.01890,-34.35308,3.99194,34.35308,22412,31
232.28678,-3.55976,-25.79058,3.53280,25.79058,22412,31
233.07120,-2.77591,-15.03860,2.74895,15.03860,22412,31
233.89180,-2.19946,-9.29346,2.17250,9.29346,22412,31
234.74480,-3.06766,-21.66428,3.04070,21.66428,22476,32
235.36580,-3.68889,-32.72952,3.66193,32.72952,22476,32
235.91780,-4.24083,-43.51279,4.21387,43.51279,22476,32
236.47119,-4.79378,-54.10060,4.76682,54.10060,22476,32
236.98980,-5.31292,-64.11263,5.28596,64.11263,22476,32
237.45980,-5.43580,-65.52490,5.40884,65.52489,22476,32
237.88480,-5.00013,-55.47233,4.97317,55.47232,22412,32
238.41880,-4.46548,-43.34103,4.43852,43.34103,22412,32
238.91578,-3.96849,-33.24706,3.94153,33.24706,22412,32
239.47119,-3.41354,-23.38294,3.38658,23.38294,22412,32
240.27119,-2.61334,-13.09859,2.58638,13.09859,22412,32
241.07120,-2.34943,-11.52596,2.32247,11.52596,22412,32
241.80580,-3.09027,-22.02418,3.06331,22.02418,22476,33
242.44780,-3.73249,-33.54092,3.70553,33.54092,22476,33
242.89780,-4.18236,-42.33209,4.15540,42.33209,22476,33
243.34780,-4.63244,-51.10489,4.60548,51.10489,22476,33
243.78980,-5.07424,-59.51611,5.04728,59.51611,22476,33
244.17119,-5.45538,-66.81852,5.42842,66.81852,22476,33
244.56780,-5.36952,-63.96785,5.34256,63.96785,22476,33
245.00080,-4.92949,-53.87510,4.90253,53.87510,22412,33
245.37880,-4.55104,-45.23197,4.52408,45.23197,22412,33
245.85080,-4.07897,-35.35797,4.05201,35.35797,22412,33
246.12980,-3.80016,-29.94699,3.77320,29.94699,22412,33
246.72280,-3.20695,-20.22684,3.17999,20.22684,22412,33
247.66980,-2.26031,-9.13476,2.23335,9.13476,22412,33
248.41980,-2.65916,-15.69253,2.63220,15.69253,22476,33
249.11680,-3.35708,-26.48005,3.33012,26.48005,22476,34
249.52778,-3.76814,-34.41018,3.74118,34.41018,22476,34
249.88480,-4.12487,-41.27457,4.09791,41.27457,22476,34
250.36180,-4.60197,-50.52966,4.57500,50.52966,22476,34
250.78780,-5.02790,-58.53754,5.00094,58.53754,22476,34
251.22780,-5.46797,-67.08184,5.44101,67.08184,22476,34
251.64380,-5.34388,-63.32412,5.31692,63.32412,22476,34
252.07380,-4.90812,-53.39912,4.88115,53.39912,22412,34
252.57120,-4.41077,-42.03309,4.38381,42.03310,22412,34
253.15480,-3.82673,-30.35101,3.79977,30.35101,22412,34
253.86280,-3.11861,-19.13620,3.09165,19.13620,22412,34
254.85380,-2.12756,-7.57534,2.10060,7.57534,22412,34
255.61280,-2.80442,-17.74252,2.77746,17.74252,22476,35
256.29581,-3.48764,-28.78620,3.46068,28.78620,22476,35
256.79581,-3.98759,-38.64331,3.96063,38.64331,22476,35
257.18878,-4.38073,-46.23175,4.35377,46.23175,22476,35
257.67120,-4.86261,-55.50902,4.83565,55.50902,22476,35
258.14978,-5.34173,-64.75033,5.31477,64.75033,22476,35
258.48278,-5.57205,-68.83804,5.54509,68.83804,22476,35
258.93781,-5.09226,-57.50057,5.06530,57.50057,22412,35
259.33881,-4.69040,-48.48281,4.66344,48.48281,22412,35
259.64481,-4.38442,-41.43873,4.35746,41.43873,22412,35
260.06080,-3.96828,-33.15050,3.94132,33.15050,22412,35
260.68878,-3.34032,-22.15819,3.31336,22.15819,22412,35
261.47119,-2.55813,-12.38272,2.53117,12.38272,22412,35
262.17122,-2.33910,-11.34281,2.31214,11.34281,22412,35
262.87119,-3.04615,-21.26930,3.01919,21.26930,22476,36
263.35278,-3.52829,-29.55150,3.50133,29.55150,22476,36
263.75078,-3.92632,-37.40130,3.89936,37.40130,22476,36
264.12681,-4.30243,-44.56212,4.27547,44.56212,22476,36
264.41981,-4.59518,-50.41641,4.56822,50.41640,22476,36
264.87119,-5.04613,-58.92563,5.01917,58.92563,22476,36
265.34478,-5.52020,-68.04641,5.49324,68.04641,22476,36
265.57981,-5.47062,-66.30418,5.44366,66.30418,22476,36
265.91581,-5.12227,-58.19167,5.09531,58.19167,22412,36
266.22478,-4.81202,-51.27779,4.78506,51.27779,22412,36
266.65878,-4.37799,-41.30513,4.35103,41.30513,22412,36
267.00281,-4.03389,-34.34404,4.00693,34.34404,22412,36
267.31478,-3.72187,-28.32256,3.69490,28.32256,22412,36
267.87878,-3.15780,-19.50669,3.13084,19.50669,22412,36
268.46078,-2.57569,-12.60009,2.54873,12.60009,22412,36
269.16581,-2.32496,-11.06121,2.29800,11.06121,22412,36
269.96878,-3.13564,-22.74877,3.10868,22.74877,22476,37
270.50581,-3.67283,-32.40488,3.64586,32.40488,22476,37
271.00681,-4.17372,-42.16507,4.14676,42.16507,22476,37
271.47119,-4.63779,-51.28232,4.61083,51.28232,22476,37
271.99178,-5.15878,-61.14975,5.13182,61.14975,22476,37
272.53478,-5.54416,-68.10883,5.51720,68.10883,22476,37
272.88278,-5.17741,-59.46412,5.15045,59.46412,22412,37
273.17122,-4.88790,-52.88455,4.86093,52.88455,22412,37
273.57081,-4.48751,-43.85291,4.46055,43.85291,22412,37
273.90281,-4.15538,-36.72756,4.12842,36.72756,22412,37
274.31978,-3.73852,-28.55262,3.71156,28.55262,22412,37
275.00681,-3.05139,-18.16503,3.02443,18.16503,22412,37
275.93978,-2.11830,-7.33315,2.09134,7.33315,22412,37
276.60678,-2.74295,-16.82444,2.71599,16.82444,22604,37
277.19778,-3.33443,-26.09780,3.30747,26.09781,22604,38
277.61678,-3.75350,-34.14025,3.72654,34.14025,22604,38
278.02781,-4.16432,-42.06071,4.13736,42.06071,22604,38
278.49078,-4.62738,-51.02493,4.60041,51.02493,22604,38
279.14578,-5.28255,-63.54505,5.25559,63.54505,22604,38
279.61978,-5.47602,-66.43665,5.44906,66.43665,22604,38
280.02278,-5.05988,-56.84287,5.03292,56.84287,22540,38
280.40178,-4.68018,-48.33743,4.65322,48.33743,22540,38
280.76778,-4.31415,-39.91108,4.28719,39.91108,22540,38
281.16981,-3.91218,-31.81805,3.88522,31.81805,22540,38
281.57678,-3.50508,-24.59504,3.47812,24.59504,22540,38
282.37119,-2.71092,-14.03194,2.68396,14.03194,22540,38
283.27119,-2.37555,-11.86860,2.34859,11.86860,22604,38
284.10581,-3.21593,-24.03863,3.18897,24.03863,22604,39
284.58578,-3.69610,-32.96082,3.66914,32.96082,22604,39
284.92381,-4.03402,-39.55730,4.00706,39.55730,22604,39
285.18281,-4.29323,-44.58930,4.26626,44.58930,22604,39
285.52578,-4.63606,-51.20688,4.60910,51.20688,22604,39
285.82778,-4.93796,-56.93644,4.91100,56.93644,22604,39
286.18281,-5.29323,-63.70474,5.26626,63.70474,22604,39
286.50281,-5.61022,-69.78439,5.58326,69.78439,22604,39
286.83578,-5.27780,-61.89918,5.25084,61.89918,22540,39
287.22878,-4.88111,-52.79643,4.85415,52.79643,22540,39
287.60081,-4.50877,-44.32971,4.48181,44.32971,22540,39
288.04581,-4.06365,-34.81447,4.03669,34.81446,22540,39
288.47581,-3.63368,-26.72456,3.60672,26.72456,22540,39
289.37119,-2.73869,-14.36903,2.71173,14.36903,22540,39
290.14778,-2.09677,-7.29773,2.06981,7.29773,22540,39
290.86481,-2.57703,-14.65219,2.55007,14.65219,22476,39
291.57119,-3.28405,-25.26224,3.25709,25.26224,22476,40
292.07119,-3.78409,-34.64198,3.75713,34.64198,22476,40
292.47681,-4.18991,-42.56105,4.16295,42.56105,22476,40
292.98981,-4.70301,-52.47226,4.67605,52.47226,22476,40
293.28978,-5.00282,-58.20973,4.97586,58.20973,22476,40
293.62078,-5.33410,-64.61755,5.30714,64.61755,22476,40
293.92178,-5.59899,-69.55536,5.57203,69.55536,22476,40
294.19581,-5.30155,-62.49296,5.27459,62.49296,22412,40
294.39078,-5.10278,-57.86022,5.07582,57.86022,22412,40
294.69878,-4.79374,-50.91548,4.76678,50.91548,22412,40
294.93878,-4.55358,-45.38150,4.52661,45.38150,22412,40
295.13181,-4.36070,-40.97971,4.33373,40.97971,22412,40
295.32678,-4.16548,-36.84472,4.13852,36.84472,22412,40
295.53181,-3.96061,-32.75265,3.93365,32.75265,22412,40
295.79081,-3.70157,-27.79865,3.67461,27.79865,22412,40
296.21578,-3.27664,-21.15559,3.24968,21.15559,22412,40
296.95881,-2.53353,-12.13009,2.50657,12.13009,22412,40
297.67678,-2.41464,-12.34120,2.38768,12.34120,22476,40
298.42481,-3.16754,-23.14612,3.14058,23.14612,22476,41
298.96781,-3.71065,-33.15563,3.68369,33.15563,22476,41
299.37119,-4.11349,-41.05330,4.08653,41.05330,22476,41
299.81378,-4.55654,-49.60026,4.52958,49.60026,22476,41
300.37119,-5.11349,-60.25562,5.08652,60.25562,22476,41
300.71478,-5.45755,-66.84621,5.43059,66.84621,22476,41
300.95678,-5.54198,-68.08029,5.51502,68.08029,22476,41
301.27119,-5.20979,-60.21868,5.18283,60.21868,22412,41
301.57481,-4.90371,-53.31530,4.87675,53.31530,22412,41
301.77478,-4.70341,-48.81499,4.67645,48.81499,22412,41
302.05578,-4.42235,-42.34457,4.39539,42.34457,22412,41
302.37119,-4.10715,-35.58692,4.08019,35.58691,22412,41
302.62578,-3.85236,-30.62870,3.82540,30.62870,22412,41
302.92578,-3.55218,-25.27754,3.52522,25.27754,22412,41
303.41181,-3.06616,-18.29747,3.03920,18.29747,22412,41
303.95481,-2.52324,-11.99093,2.49628,11.99093,22412,41
304.33381,-2.14422,-7.59176,2.11726,7.59176,22412,41
304.69581,-2.44618,-12.74261,2.41921,12.74261,22476,41
305.02078,-2.77499,-17.18621,2.74803,17.18621,22476,42
305.27381,-3.02818,-21.00051,3.00122,21.00051,22476,42
305.57119,-3.32537,-26.02530,3.29841,26.02530,22476,42
305.71578,-3.47026,-28.52481,3.44329,28.52481,22476,42
305.90178,-3.65636,-32.16534,3.62940,32.16534,22476,42
306.07678,-3.83137,-35.60735,3.80441,35.60735,22476,42
306.37281,-4.12717,-41.40950,4.10021,41.40950,22476,42
306.68978,-4.44438,-47.62994,4.41742,47.62994,22476,42
306.97119,-4.72532,-52.78878,4.69836,52.78878,22476,42
307.23578,-4.99022,-57.85813,4.96326,57.85813,22476,42
307.57278,-5.32740,-64.46721,5.30044,64.46722,22476,42
307.91181,-5.56151,-68.53377,5.53455,68.53377,22476,42
308.13478,-5.31845,-62.80122,5.29149,62.80122,22476,42
308.27781,-5.17197,-59.39505,5.14501,59.39505,22412,42
308.52381,-4.92435,-53.76536,4.89739,53.76536,22412,42
308.82778,-4.62000,-47.00580,4.59304,47.00580,22412,42
309.13478,-4.31296,-39.86969,4.28600,39.86969,22412,42
309.50078,-3.94694,-32.32761,3.91998,32.32761,22412,42
309.83781,-3.60985,-26.12887,3.58289,26.12887,22412,42
310.59281,-2.85501,-15.69701,2.82805,15.69701,22412,42
311.34078,-2.12034,-7.37148,2.09337,7.37148,22412,42
312.03581,-2.83578,-18.12588,2.80882,18.12589,22476,43
312.53978,-3.33999,-26.18968,3.31303,26.18968,22476,43
312.82481,-3.62497,-31.53280,3.59801,31.53280,22476,43
313.13581,-3.93605,-37.59837,3.90909,37.59837,22476,43
313.44581,-4.24606,-43.61486,4.21910,43.61486,22476,43
313.76678,-4.56694,-49.68449,4.53998,49.68449,22476,43
313.99578,-4.79599,-54.09782,4.76903,54.09782,22476,43
314.22778,-5.02788,-58.60199,5.00092,58.60199,22476,43
314.42778,-5.22803,-62.54219,5.20107,62.54219,22476,43
314.66778,-5.46794,-67.08571,5.44098,67.08572,22476,43
314.82678,-5.60960,-69.76502,5.58264,69.76502,22476,43
315.05578,-5.36487,-63.80142,5.33791,63.80142,22476,43
315.26378,-5.15135,-58.82610,5.12439,58.82610,22412,43
315.44078,-4.97314,-54.86465,4.94618,54.86465,22412,43
315.67122,-4.74277,-49.65235,4.71581,49.65235,22412,43
315.82378,-4.58961,-46.14282,4.56264,46.14281,22412,43
315.96381,-4.44959,-42.98380,4.42263,42.98380,22412,43
316.13878,-4.27475,-39.09952,4.24779,39.09952,22412,43
316.27978,-4.13354,-36.06251,4.10658,36.06251,22412,43
316.38878,-4.02464,-34.01083,3.99768,34.01083,22412,43
316.55478,-3.85873,-30.69229,3.83176,30.69229,22412,43
316.74381,-3.66957,-27.18898,3.64261,27.18898,22412,43
316.93281,-3.48063,-24.06316,3.45367,24.06316,22412,43
317.23178,-3.18151,-19.65239,3.15455,19.65239,22412,43
317.55978,-2.85369,-15.71539,2.82673,15.71539,22412,43
317.99078,-2.42265,-10.79943,2.39569,10.79943,22412,43
318.29778,-2.12490,-7.34124,2.09794,7.34124,22412,43
318.57178,-2.41018,-12.19909,2.38322,12.19909,22412,43
318.94278,-2.78635,-17.31444,2.75939,17.31444,22476,44
319.38878,-3.23259,-24.18297,3.20563,24.18297,22476,44
319.71178,-3.55564,-30.00353,3.52868,30.00353,22476,44
319.94378,-3.78779,-34.61670,3.76082,34.61670,22476,44
320.19678,-4.04069,-39.56113,4.01373,39.56113,22476,44
320.42178,-4.26585,-43.91746,4.23889,43.91746,22476,44
320.69278,-4.53667,-49.19816,4.50971,49.19816,22476,44
320.97878,-4.82263,-54.64412,4.79567,54.64412,22476,44
321.29981,-5.14364,-60.88420,5.11668,60.88420,22476,44
321.54678,-5.39083,-65.66161,5.36386,65.66161,22476,44
321.84181,-5.51950,-67.61155,5.49254,67.61154,22476,44
322.13478,-5.20917,-60.31235,5.18221,60.31235,22412,44
322.44078,-4.90085,-53.29061,4.87389,53.29060,22412,44
322.70081,-4.64051,-47.48306,4.61355,47.48306,22412,44
323.00778,-4.33342,-40.36557,4.30646,40.36557,22412,44
323.34378,-3.99738,-33.47138,3.97042,33.47137,22412,44
323.67122,-3.67032,-27.13968,3.64336,27.13968,22412,44
324.08978,-3.25137,-20.66110,3.22441,20.66109,22412,44
324.93281,-2.40846,-10.61630,2.38150,10.61629,22412,44
325.62878,-2.49346,-13.29599,2.46650,13.29599,22476,44
326.35278,-3.22021,-24.04955,3.19325,24.04955,22476,45
326.64481,-3.51233,-29.29469,3.48537,29.29469,22476,45
326.83278,-3.70037,-33.01548,3.67340,33.01548,22476,45
327.16181,-4.02935,-39.43363,4.00239,39.43363,22476,45
327.41181,-4.27952,-44.22634,4.25256,44.22635,22476,45
327.63378,-4.50128,-48.57791,4.47432,48.57791,22476,45
327.86578,-4.73333,-52.98704,4.70637,52.98704,22476,45
328.14278,-5.01021,-58.31824,4.98324,58.31824,22476,45
328.38181,-5.24947,-62.92572,5.22251,62.92572,22476,45
328.64978,-5.51731,-68.01603,5.49035,68.01603,22476,45
328.87119,-5.48514,-66.70146,5.45818,66.70146,22476,45
329.06378,-5.28133,-61.95589,5.25437,61.95589,22412,45
329.23578,-5.10623,-57.91404,5.07927,57.91404,22412,45
329.39678,-4.94444,-54.26492,4.91747,54.26492,22412,45
329.53181,-4.80915,-51.20686,4.78219,51.20686,22412,45
329.73978,-4.60102,-46.49944,4.57406,46.49944,22412,45
329.93878,-4.40212,-41.89595,4.37516,41.89595,22412,45
330.14178,-4.19887,-37.39241,4.17191,37.39241,22412,45
330.28778,-4.05296,-34.51509,4.02600,34.51509,22412,45
330.51081,-3.83006,-30.11970,3.80309,30.11970,22412,45
330.81181,-3.52896,-24.84170,3.50200,24.84170,22412,45
331.31378,-3.02699,-17.77361,3.00003,17.77361,22412,45
331.92881,-2.41208,-10.64925,2.38512,10.64925,22412,45
332.25478,-2.15748,-7.94888,2.13052,7.94888,22412,45
332.70578,-2.63564,-15.22052,2.60868,15.22052,22476,45
333.46781,-3.39920,-27.04219,3.37224,27.04219,22476,46
333.81478,-3.74620,-33.85285,3.71924,33.85284,22476,46
334.10581,-4.03712,-39.48769,4.01015,39.48769,22476,46
334.42178,-4.35321,-45.52614,4.32625,45.52614,22476,46
334.66478,-4.59600,-50.36698,4.56904,50.36698,22476,46
334.90281,-4.83402,-54.91466,4.80706,54.91467,22476,46
335.12778,-5.05893,-59.21904,5.03197,59.21904,22476,46
335.28878,-5.22008,-62.43202,5.19312,62.43202,22476,46
335.48778,-5.41916,-66.12778,5.39220,66.12778,22476,46
335.67381,-5.59798,-69.60033,5.57102,69.60033,22476,46
335.85378,-5.41527,-65.15192,5.38831,65.15192,22476,46
336.07119,-5.19008,-59.78686,5.16312,59.78686,22412,46
336.37119,-4.88817,-52.93201,4.86121,52.93201,22412,46
336.52478,-4.73388,-49.46132,4.70692,49.46132,22412,46
336.68478,-4.57364,-45.83345,4.54668,45.83345,22412,46
336.82678,-4.43172,-42.62245,4.40476,42.62246,22412,46
336.95778,-4.30077,-39.63939,4.27381,39.63939,22412,46
337.15681,-4.10156,-35.44121,4.07460,35.44121,22412,46
337.28281,-3.97574,-33.00722,3.94878,33.00722,22412,46
337.40681,-3.85179,-30.53369,3.82483,30.53369,22412,46
337.53581,-3.72272,-28.08177,3.69576,28.08178,22412,46
337.76578,-3.49272,-24.26322,3.46576,24.26322,22412,46
337.92778,-3.33072,-21.82307,3.30376,21.82306,22412,46
338.07378,-3.18455,-19.72975,3.15759,19.72975,22412,46
338.30278,-2.95573,-16.84750,2.92877,16.84750,22412,46
338.53281,-2.72564,-14.08665,2.69868,14.08665,22412,46
338.79081,-2.46765,-11.20795,2.44069,11.20795,22412,46
339.09978,-2.15867,-7.66402,2.13171,7.66402,22412,46
339.52678,-2.52709,-13.77512,2.50012,13.77512,22476,46
340.03478,-3.03764,-21.14162,3.01068,21.14162,22476,47
340.35581,-3.35881,-26.49189,3.33185,26.49189,22476,47
340.55278,-3.55565,-30.20586,3.52869,30.20586,22476,47
340.73578,-3.73887,-33.81380,3.71191,33.81380,22476,47
340.93178,-3.93482,-37.66812,3.90786,37.66812,22476,47
341.15378,-4.15669,-41.96540,4.12973,41.96540,22476,47
341.33178,-4.33488,-45.32306,4.30792,45.32306,22476,47
341.54378,-4.54672,-49.40483,4.51976,49.40483,22476,47
341.68681,-4.68982,-52.16027,4.66286,52.16027,22476,47
341.90378,-4.90676,-56.36135,4.87980,56.36135,22476,47
342.07119,-5.07359,-59.54171,5.04663,59.54171,22476,47
342.27478,-5.27795,-63.46735,5.25099,63.46735,22476,47
342.42978,-5.43279,-66.47579,5.40583,66.47578,22476,47
342.59281,-5.59288,-69.54542,5.56592,69.54542,22476,47
342.70978,-5.48897,-66.89326,5.46200,66.89326,22476,47
342.86478,-5.32344,-62.96541,5.29648,62.96541,22476,47
342.99381,-5.19083,-59.91215,5.16387,59.91214,22412,47
343.16478,-5.01816,-55.98380,4.99120,55.98380,22412,47
343.29278,-4.88988,-52.99284,4.86292,52.99284,22412,47
343.42978,-4.75257,-49.92328,4.72561,49.92328,22412,47
343.52781,-4.65453,-47.88670,4.62757,47.88670,22412,47
343.69181,-4.49044,-43.99745,4.46348,43.99745,22412,47
343.84578,-4.33648,-40.38099,4.30952,40.38099,22412,47
343.98481,-4.19726,-37.40340,4.17030,37.40340,22412,47
344.11278,-4.06932,-34.76472,4.04236,34.76472,22412,47
344.26278,-3.91946,-31.71230,3.89250,31.71230,22412,47
344.48578,-3.69636,-27.55517,3.66940,27.55517,22412,47
344.89381,-3.28843,-21.18039,3.26147,21.18039,22412,47
345.44778,-2.73438,-14.16211,2.70742,14.16211,22412,47
346.14678,-2.19278,-8.58163,2.16582,8.58162,22412,47
346.70978,-2.77612,-17.21663,2.74916,17.21663,22604,47
347.21178,-3.27852,-25.05903,3.25156,25.05903,22604,48
347.51178,-3.57838,-30.57495,3.55142,30.57495,22604,48
347.76081,-3.82746,-35.44521,3.80050,35.44521,22604,48
348.05178,-4.11834,-41.12835,4.09138,41.12835,22604,48
348.36578,-4.43257,-47.32334,4.40561,47.32334,22604,48
348.58978,-4.65650,-51.52657,4.62954,51.52657,22604,48
348.82678,-4.89347,-56.11071,4.86651,56.11071,22604,48
349.00581,-5.07230,-59.51608,5.04533,59.51608,22604,48
349.27119,-5.33757,-64.73911,5.31061,64.73911,22604,48
349.47878,-5.54543,-68.61985,5.51847,68.61986,22604,48
349.70678,-5.44931,-65.88947,5.42235,65.88947,22604,48
349.95081,-5.19547,-59.97234,5.16851,59.97234,22540,48
350.21078,-4.93354,-53.99112,4.90658,53.99112,22540,48
350.50478,-4.63926,-47.48997,4.61230,47.48997,22540,48
350.80978,-4.33421,-40.29213,4.30725,40.29213,22540,48
351.15078,-3.99316,-33.19041,3.96620,33.19041,22540,48
351.67122,-3.47314,-23.86180,3.44618,23.86180,22540,48
352.46681,-2.67696,-13.53415,2.65000,13.53415,22540,48
353.24078,-2.31621,-10.73307,2.28925,10.73307,22540,48
354.07119,-3.15504,-23.02795,3.12808,23.02795,22604,49
354.56378,-3.64810,-32.06517,3.62114,32.06517,22604,49
354.97278,-4.05714,-39.98710,4.03017,39.98710,22604,49
355.32581,-4.41031,-46.95006,4.38335,46.95007,22604,49
355.72778,-4.81202,-54.55795,4.78506,54.55795,22604,49
356.20881,-5.29319,-63.75009,5.26623,63.75009,22604,49
356.66081,-5.49616,-66.91797,5.46920,66.91797,22604,49
356.94878,-5.19506,-59.94635,5.16809,59.94635,22540,49
357.16181,-4.98039,-55.01931,4.95343,55.01931,22540,49
357.45578,-4.68596,-48.41581,4.65900,48.41581,22540,49
357.71781,-4.42389,-42.47446,4.39693,42.47446,22540,49
358.06281,-4.07874,-34.88581,4.05178,34.88580,22540,49
358.52178,-3.61979,-26.23582,3.59283,26.23582,22540,49
359.06578,-3.07572,-18.32399,3.04876,18.32399,22540,49
359.87119,-2.27107,-8.82534,2.24411,8.82534,22540,49
360.43281,-2.16924,-8.20706,2.14228,8.20706,22540,49
360.96078,-2.71203,-16.56086,2.68507,16.56086,22476,49
361.45178,-3.20340,-23.82029,3.17644,23.82029,22476,50
361.73978,-3.49149,-28.95843,3.46453,28.95843,22476,50
361.94181,-3.69348,-32.89615,3.66652,32.89614,22476,50
362.14178,-3.89359,-36.85776,3.86663,36.85776,22476,50
362.32581,-4.07747,-40.38162,4.05051,40.38162,22476,50
362.51881,-4.27069,-44.20215,4.24373,44.20215,22476,50
362.66278,-4.41466,-47.09822,4.38770,47.09822,22476,50
362.98481,-4.73649,-53.11279,4.70953,53.11279,22476,50
363.27178,-5.02337,-58.63207,4.99640,58.63207,22476,50
363.63081,-5.38267,-65.53691,5.35571,65.53691,22476,50
363.92978,-5.55674,-68.48572,5.52978,68.48573,22476,50
364.17122,-5.29683,-62.36600,5.26987,62.36600,22412,50
364.41778,-5.04591,-56.55769,5.01895,56.55769,22412,50
364.60081,-4.86249,-52.47475,4.83553,52.47475,22412,50
364.86781,-4.59512,-46.46265,4.56816,46.46265,22412,50
365.17178,-4.29121,-39.46816,4.26425,39.46816,22412,50
365.41478,-4.04812,-34.27300,4.02116,34.27300,22412,50
365.87078,-3.59200,-25.77844,3.56504,25.77843,22412,50
366.67578,-2.78721,-14.66407,2.76024,14.66407,22412,50
367.57119,-2.35866,-11.32839,2.33170,11.32839,22412,50
368.37119,-3.16618,-23.15261,3.13922,23.15261,22476,51
368.85678,-3.65229,-31.94854,3.62533,31.94854,22476,51
369.23481,-4.03022,-39.56484,4.00326,39.56484,22476,51
369.67122,-4.46623,-48.14101,4.43927,48.14101,22476,51
370.01981,-4.81514,-54.73395,4.78818,54.73395,22476,51
370.46281,-5.25843,-63.17496,5.23147,63.17496,22476,51
370.81978,-5.60362,-69.79533,5.57666,69.79533,22476,51
371.10481,-5.30503,-62.61213,5.27807,62.61213,22412,51
371.50181,-4.90334,-53.41139,4.87638,53.41139,22412,51
371.76378,-4.64103,-47.53380,4.61407,47.53380,22412,51
372.10481,-4.29994,-39.69653,4.27298,39.69653,22412,51
372.43281,-3.97190,-32.53030,3.94494,32.53030,22412,51
372.74078,-3.66384,-26.80095,3.63688,26.80095,22412,51
373.34078,-3.06377,-18.10002,3.03681,18.10002,22412,51
374.14381,-2.26113,-8.83137,2.23417,8.83137,22412,51
374.73678,-2.60005,-14.71004,2.57309,14.71004,22476,51
375.44778,-3.31294,-25.77055,3.28598,25.77055,22476,52
375.99578,-3.86093,-36.09891,3.83397,36.09891,22476,52
376.57178,-4.43700,-47.43629,4.41004,47.43629,22476,52
377.19078,-5.05575,-59.24626,5.02879,59.24626,22476,52
377.75378,-5.61451,-69.93345,5.58755,69.93345,22476,52
378.10581,-5.25811,-61.40769,5.23115,61.40769,22412,52
378.59078,-4.76971,-50.31203,4.74275,50.31203,22412,52
379.04778,-4.31258,-39.90052,4.28562,39.90052,22412,52
379.57119,-3.78960,-29.05555,3.76264,29.05556,22412,52
380.41581,-2.94454,-16.60112,2.91758,16.60112,22412,52
381.21478,-2.14547,-7.44645,2.11851,7.44646,22412,52
382.03078,-2.91949,-19.32393,2.89253,19.32393,22476,53
382.63878,-3.52758,-29.62750,3.50062,29.62750,22476,53
383.06478,-3.95359,-37.99484,3.92662,37.99484,22476,53
383.41081,-4.29973,-44.69282,4.27277,44.69282,22476,53
383.79081,-4.67961,-52.00192,4.65265,52.00192,22476,53
384.27119,-5.15957,-61.23462,5.13261,61.23462,22476,53
384.54481,-5.43361,-66.43727,5.40665,66.43727,22476,53
384.92178,-5.41605,-65.11910,5.38909,65.11910,22476,53
385.16878,-5.16112,-59.14185,5.13415,59.14185,22412,53
385.42481,-4.90372,-53.32154,4.87676,53.32154,22412,53
385.74078,-4.58721,-46.22402,4.56025,46.22403,22412,53
386.04378,-4.28436,-39.34870,4.25740,39.34870,22412,53
386.33381,-3.99429,-33.00963,3.96733,33.00963,22412,53
386.72678,-3.60116,-25.84352,3.57420,25.84352,22412,53
387.29981,-3.02826,-17.62112,3.00130,17.62112,22412,53
388.07178,-2.25648,-8.69494,2.22952,8.69495,22412,53
388.80678,-2.71858,-16.32437,2.69162,16.32437,22476,53
389.52781,-3.44036,-27.98686,3.41340,27.98686,22476,54
389.96978,-3.88236,-36.51731,3.85540,36.51731,22476,54
390.48278,-4.39549,-46.59235,4.36853,46.59235,22476,54
390.77978,-4.69234,-52.23035,4.66538,52.23035,22476,54
391.11881,-5.03121,-58.74882,5.00425,58.74882,22476,54
391.48081,-5.39347,-65.74445,5.36651,65.74445,22476,54
391.79678,-5.51511,-67.54275,5.48815,67.54275,22476,54
392.17122,-5.12436,-58.29810,5.09740,58.29810,22412,54
392.65681,-4.63702,-47.46836,4.61006,47.46836,22412,54
393.07178,-4.22189,-37.95152,4.19493,37.95152,22412,54
393.57119,-3.72296,-27.77307,3.69599,27.77307,22412,54
394.29981,-2.99397,-17.15996,2.96701,17.15996,22412,54
395.13878,-2.15487,-7.54852,2.12790,7.54852,22412,54
395.92678,-2.88287,-18.76426,2.85591,18.76426,22476,55
396.55178,-3.50800,-29.17345,3.48104,29.17345,22476,55
397.05678,-4.01300,-39.23537,3.98604,39.23537,22476,55
397.51881,-4.47497,-48.23860,4.44801,48.23860,22476,55
397.87119,-4.82694,-54.87419,4.79997,54.87418,22476,55
398.37478,-5.33108,-64.62115,5.30412,64.62115,22476,55
398.82278,-5.46119,-66.13666,5.43423,66.13666,22476,55
399.18378,-5.08869,-57.50739,5.06173,57.50739,22412,55
399.50478,-4.76690,-50.30299,4.73994,50.30299,22412,55
399.87978,-4.39187,-41.71013,4.36491,41.71014,22412,55
400.23278,-4.03875,-33.91990,4.01179,33.91990,22412,55
400.71978,-3.55164,-24.80794,3.52468,24.80794,22412,55
401.18281,-3.08860,-18.32972,3.06164,18.32972,22412,55
401.75378,-2.51772,-11.60257,2.49076,11.60257,22412,55
402.26378,-2.22504,-9.07682,2.19808,9.07682,22412,55
402.93681,-2.91470,-19.30168,2.88774,19.30168,22476,56
403.48778,-3.46581,-28.54427,3.43885,28.54427,22476,56
403.84778,-3.82587,-35.49316,3.79891,35.49316,22476,56
404.09078,-4.06874,-40.17915,4.04178,40.17915,22476,56
404.31278,-4.29099,-44.52549,4.26403,44.52549,22476,56
404.53378,-4.51177,-48.92569,4.48481,48.92569,22476,56
404.75378,-4.73181,-53.05994,4.70485,53.05994,22476,56
404.97119,-4.94875,-57.23722,4.92179,57.23722,22476,56
405.23978,-5.21782,-62.50469,5.19086,62.50469,22476,56
405.60581,-5.58365,-69.37692,5.55668,69.37691,22476,56
405.86978,-5.36083,-63.81442,5.33387,63.81442,22476,56
406.13778,-5.08651,-57.50753,5.05955,57.50753,22412,56
406.34181,-4.88190,-52.89866,4.85494,52.89866,22412,56
406.67578,-4.54743,-45.25770,4.52047,45.25770,22412,56
406.95678,-4.26658,-39.00831,4.23962,39.00831,22412,56
407.20881,-4.01447,-33.33770,3.98751,33.33770,22412,56
407.46781,-3.75555,-28.32165,3.72859,28.32165,22412,56
407.94478,-3.27848,-20.77700,3.25152,20.77700,22412,56
408.77119,-2.45238,-11.00139,2.42542,11.00139,22412,56
409.57119,-2.59273,-14.67677,2.56577,14.67677,22476,56
410.27119,-3.29457,-25.49813,3.26761,25.49813,22476,57
410.67122,-3.69454,-33.06347,3.66757,33.06347,22476,57
411.05381,-4.07745,-40.40074,4.05049,40.40074,22476,57
411.30381,-4.32765,-45.33124,4.30069,45.33124,22476,57
411.54481,-4.56842,-50.07133,4.54146,50.07133,22476,57
411.83381,-4.85748,-55.54960,4.83052,55.54960,22476,57
412.24781,-5.27167,-63.51295,5.24471,63.51295,22476,57
412.67078,-5.52615,-67.78027,5.49919,67.78027,22476,57
413.00778,-5.17126,-59.42298,5.14430,59.42298,22412,57
413.39078,-4.78637,-50.71892,4.75940,50.71892,22412,57
413.84578,-4.33127,-40.37878,4.30431,40.37878,22412,57
414.36578,-3.81129,-29.33264,3.78433,29.33264,22412,57
415.07119,-3.10614,-18.57825,3.07918,18.57825,22412,57
416.07119,-2.11371,-7.09081,2.08675,7.09081,22412,57
416.81978,-2.87711,-18.67094,2.85015,18.67094,22604,57
417.47119,-3.52822,-29.56893,3.50126,29.56894,22604,58
418.02578,-4.08315,-40.49933,4.05619,40.49932,22604,58
418.43078,-4.48818,-48.58262,4.46122,48.58262,22604,58
418.79178,-4.84921,-55.38622,4.82225,55.38622,22604,58
419.25478,-5.31232,-64.23842,5.28536,64.23842,22604,58
419.58978,-5.61493,-69.89354,5.58797,69.89354,22604,58
419.94778,-5.23183,-60.83107,5.20487,60.83107,22540,58
420.27178,-4.90537,-53.34120,4.87841,53.34120,22540,58
420.64778,-4.52899,-44.86077,4.50203,44.86077,22540,58
420.95978,-4.21689,-37.89827,4.18993,37.89827,22540,58
421.38478,-3.79204,-28.90142,3.76508,28.90142,22540,58
421.97678,-3.19984,-19.62765,3.17288,19.62765,22540,58
422.75181,-2.42494,-10.57569,2.39798,10.57569,22540,58
423.52178,-2.60931,-14.85873,2.58235,14.85873,22604,58
424.26578,-3.35507,-26.44474,3.32811,26.44474,22604,59
424.77119,-3.86009,-36.27212,3.83313,36.27212,22604,59
425.37119,-4.46002,-48.19858,4.43306,48.19859,22604,59
425.94181,-5.03091,-58.96337,5.00395,58.96337,22604,59
426.45078,-5.53996,-68.65206,5.51300,68.65206,22604,59
426.85981,-5.22603,-60.86939,5.19906,60.86939,22540,59
427.17778,-4.90516,-53.52187,4.87820,53.52187,22540,59
427.67122,-4.41177,-42.39912,4.38481,42.39912,22540,59
428.13581,-3.94671,-31.83890,3.91975,31.83890,22540,59
428.76778,-3.31468,-21.23184,3.28772,21.23184,22540,59
429.57119,-2.51168,-11.54745,2.48472,11.54745,22540,59
429.98278,-2.11269,-7.02568,2.08573,7.02568,22540,59