File: data-raw/Experiment 2/Results/INSTRON data/Experiment 2.is_ccyclic_RawData/Specimen_RawData_26.csv
Text Inputs : Specimen label,"Long Plate 1 Video"

Time,Extension,Load,Compressive extension,Compressive load,Segment ID,Total Cycle Count
(sec),(mm),(N),(mm),(N),,
0.00000,-0.02664,0.01806,0.00000,-0.01806,12835,0
1.90620,-0.39206,0.02068,0.36542,-0.02068,3220,0
3.50620,-1.19226,0.00763,1.16561,-0.00763,3220,0
4.60620,-1.74222,-3.17922,1.71558,3.17922,3220,0
5.15880,-2.10064,-9.86810,2.07400,9.86810,3220,0
5.61680,-2.56112,-17.32101,2.53448,17.32100,22476,0
6.05280,-2.99714,-25.24040,2.97050,25.24040,22476,0
6.42580,-3.37018,-33.26428,3.34354,33.26427,22476,0
6.76180,-3.70632,-40.69102,3.67968,40.69102,22476,0
7.05580,-4.00016,-47.35468,3.97352,47.35468,22476,0
7.42280,-4.36716,-55.21677,4.34052,55.21677,22476,0
7.80620,-4.75023,-63.55295,4.72359,63.55294,22476,0
8.12480,-5.04184,-69.88285,5.01520,69.88285,22476,0
8.40180,-4.74302,-60.65554,4.71638,60.65554,22476,0
8.69580,-4.44476,-52.17390,4.41812,52.17390,22412,0
9.00620,-4.13423,-44.02471,4.10759,44.02470,22412,0
9.28480,-3.85507,-37.14848,3.82843,37.14848,22412,0
9.63080,-3.50905,-29.01484,3.48241,29.01484,22412,0
10.03780,-3.10212,-20.91044,3.07548,20.91044,22412,0
10.51580,-2.62406,-13.38215,2.59742,13.38215,22412,0
10.97880,-2.27701,-8.59965,2.25037,8.59965,22412,0
11.39480,-2.71589,-16.88015,2.68924,16.88015,22476,0
11.80620,-3.12824,-24.73423,3.10159,24.73422,22476,1
12.16080,-3.48328,-32.62242,3.45664,32.62242,22476,1
12.50620,-3.82824,-40.64769,3.80160,40.64769,22476,1
12.87580,-4.19829,-49.38526,4.17165,49.38527,22476,1
13.20780,-4.53027,-57.18160,4.50363,57.18160,22476,1
13.57580,-4.89807,-65.79867,4.87143,65.79867,22476,1
13.87980,-4.96169,-66.18559,4.93505,66.18559,22476,1
14.16280,-4.66587,-57.51494,4.63923,57.51494,22412,1
14.46680,-4.35947,-49.01009,4.33283,49.01009,22412,1
14.71380,-4.11241,-42.81185,4.08577,42.81185,22412,1
15.07380,-3.75228,-34.05602,3.72564,34.05602,22412,1
15.43980,-3.38613,-25.88106,3.35949,25.88106,22412,1
15.88280,-2.94320,-17.91938,2.91656,17.91938,22412,1
16.38180,-2.44412,-10.36885,2.41748,10.36885,22412,1
16.75080,-2.40141,-10.78283,2.37477,10.78283,22412,1
17.18980,-2.85183,-18.93521,2.82519,18.93521,22476,2
17.58480,-3.24749,-26.68140,3.22085,26.68140,22476,2
17.92780,-3.59054,-34.65025,3.56390,34.65025,22476,2
18.28680,-3.94938,-43.05404,3.92274,43.05404,22476,2
18.63580,-4.29836,-51.30874,4.27172,51.30874,22476,2
19.00080,-4.66360,-59.85948,4.63696,59.85948,22476,2
19.33680,-4.99951,-67.71542,4.97287,67.71542,22476,2
19.61580,-4.90875,-64.18580,4.88211,64.18580,22476,2
19.90620,-4.61003,-55.55680,4.58339,55.55680,22412,2
20.19280,-4.32173,-47.69626,4.29509,47.69626,22412,2
20.52080,-3.99341,-39.44502,3.96677,39.44502,22412,2
20.82880,-3.68558,-32.00597,3.65894,32.00597,22412,2
21.20980,-3.30449,-23.87740,3.27785,23.87741,22412,2
21.68680,-2.82750,-15.86876,2.80086,15.86876,22412,2
22.17680,-2.33758,-8.35917,2.31094,8.35917,22412,2
22.52380,-2.53671,-12.91705,2.51007,12.91705,22412,2
22.95380,-2.97228,-20.85063,2.94563,20.85063,22476,3
23.33180,-3.35052,-28.67743,3.32388,28.67743,22476,3
23.69280,-3.71167,-37.15416,3.68503,37.15416,22476,3
23.97380,-3.99254,-43.72175,3.96589,43.72175,22476,3
24.31180,-4.33052,-51.74344,4.30387,51.74344,22476,3
24.62280,-4.64169,-59.02598,4.61504,59.02598,22476,3
24.94680,-4.96560,-66.69164,4.93896,66.69164,22476,3
25.21480,-4.98885,-66.16481,4.96221,66.16481,22476,3
25.50620,-4.68514,-57.30874,4.65850,57.30874,22412,3
25.80620,-4.38279,-48.95351,4.35614,48.95351,22412,3
26.13680,-4.05176,-40.52708,4.02512,40.52708,22412,3
26.44380,-3.74468,-33.23050,3.71804,33.23050,22412,3
26.81180,-3.37653,-25.07821,3.34989,25.07821,22412,3
27.27880,-2.90951,-16.94662,2.88287,16.94662,22412,3
27.77780,-2.41044,-9.36715,2.38380,9.36715,22412,3
28.17780,-2.54675,-12.87878,2.52011,12.87879,22412,3
28.60180,-2.97641,-20.73139,2.94977,20.73139,22476,4
28.99180,-3.36668,-28.79244,3.34004,28.79244,22476,4
29.30620,-3.68082,-36.11420,3.65418,36.11420,22476,4
29.58580,-3.96072,-42.77863,3.93408,42.77863,22476,4
29.81380,-4.18886,-48.20292,4.16222,48.20292,22476,4
30.17780,-4.55283,-56.76443,4.52619,56.76443,22476,4
30.51980,-4.89465,-64.82202,4.86801,64.82202,22476,4
30.82280,-5.03160,-67.28776,5.00496,67.28776,22476,4
31.10620,-4.73188,-58.40129,4.70524,58.40129,22412,4
31.40620,-4.42913,-50.03082,4.40249,50.03082,22412,4
31.66880,-4.16592,-43.21840,4.13928,43.21840,22412,4
31.98180,-3.85276,-35.57390,3.82611,35.57390,22412,4
32.32780,-3.50672,-27.49682,3.48008,27.49682,22412,4
32.76080,-3.07379,-19.39737,3.04715,19.39737,22412,4
33.25980,-2.57477,-11.89068,2.54812,11.89068,22412,4
33.64680,-2.36917,-9.31557,2.34253,9.31557,22412,4
34.06080,-2.80075,-17.35844,2.77411,17.35843,22476,4
34.45880,-3.19990,-25.10470,3.17326,25.10470,22476,5
34.77780,-3.51895,-32.16986,3.49231,32.16986,22476,5
35.10620,-3.84695,-39.88649,3.82031,39.88649,22476,5
35.40620,-4.14706,-47.09598,4.12042,47.09598,22476,5
35.77080,-4.51197,-55.60415,4.48533,55.60415,22476,5
36.11580,-4.85686,-63.76391,4.83022,63.76391,22476,5
36.41680,-5.10509,-69.42663,5.07845,69.42664,22476,5
36.69580,-4.80127,-60.20588,4.77463,60.20588,22412,5
37.00380,-4.48940,-51.50244,4.46275,51.50244,22412,5
37.30620,-4.18707,-43.59775,4.16043,43.59776,22412,5
37.61480,-3.87782,-35.97091,3.85117,35.97091,22412,5
37.93380,-3.55893,-28.51865,3.53229,28.51865,22412,5
38.35180,-3.14088,-20.43841,3.11424,20.43841,22412,5
38.83880,-2.65385,-12.85200,2.62721,12.85200,22412,5
39.26780,-2.32534,-8.20329,2.29870,8.20329,22412,5
39.66580,-2.74747,-16.30539,2.72083,16.30539,22476,5
40.08680,-3.17000,-24.37067,3.14336,24.37067,22476,6
40.43380,-3.51716,-32.01894,3.49052,32.01894,22476,6
40.80580,-3.88909,-40.74877,3.86245,40.74877,22476,6
41.14880,-4.23221,-48.85940,4.20557,48.85940,22476,6
41.50620,-4.58927,-57.35469,4.56263,57.35469,22476,6
41.80620,-4.88899,-64.45853,4.86235,64.45853,22476,6
42.12880,-5.05687,-67.72219,5.03022,67.72218,22476,6
42.40620,-4.76233,-58.95462,4.73569,58.95462,22412,6
42.68680,-4.47853,-51.10353,4.45189,51.10353,22412,6
43.00620,-4.15922,-42.70603,4.13258,42.70603,22412,6
43.35080,-3.81411,-34.39056,3.78747,34.39056,22412,6
43.70620,-3.45908,-26.29448,3.43244,26.29448,22412,6
44.10620,-3.05911,-19.03743,3.03247,19.03743,22412,6
44.60620,-2.55907,-11.41558,2.53243,11.41558,22412,6
44.99280,-2.40431,-9.82835,2.37767,9.82835,22412,6
45.40620,-2.83232,-17.75670,2.80568,17.75670,22476,6
45.80620,-3.23330,-25.60896,3.20666,25.60896,22476,7
46.15680,-3.58440,-33.50031,3.55776,33.50031,22476,7
46.48680,-3.91422,-41.22043,3.88758,41.22043,22476,7
46.80080,-4.22840,-48.74405,4.20176,48.74405,22476,7
47.10620,-4.53336,-55.90722,4.50672,55.90722,22476,7
47.45280,-4.88021,-64.10509,4.85357,64.10509,22476,7
47.75380,-5.09661,-68.85891,5.06997,68.85892,22476,7
47.99980,-4.82815,-60.75415,4.80151,60.75415,22412,7
48.26680,-4.55713,-53.05387,4.53049,53.05387,22412,7
48.54680,-4.27630,-45.49082,4.24966,45.49082,22412,7
48.84780,-3.97516,-38.17565,3.94852,38.17565,22412,7
49.16580,-3.65726,-30.54369,3.63062,30.54369,22412,7
49.56380,-3.25918,-22.34146,3.23254,22.34146,22412,7
50.02380,-2.79927,-14.88965,2.77263,14.88965,22412,7
50.50620,-2.31740,-7.38288,2.29076,7.38288,22412,7
50.87380,-2.65005,-14.37927,2.62341,14.37927,22604,7
51.29780,-3.07737,-22.28135,3.05072,22.28135,22604,8
51.67380,-3.45353,-30.26712,3.42689,30.26712,22604,8
51.98980,-3.76958,-37.76955,3.74294,37.76955,22604,8
52.32980,-4.10974,-45.75488,4.08310,45.75488,22604,8
52.64580,-4.42547,-53.23784,4.39883,53.23783,22604,8
52.92280,-4.70273,-59.79658,4.67609,59.79657,22604,8
53.23780,-5.01755,-67.23016,4.99091,67.23016,22604,8
53.50180,-4.98027,-65.21358,4.95363,65.21358,22604,8
53.75080,-4.72109,-57.59760,4.69445,57.59760,22540,8
54.05580,-4.41372,-49.06680,4.38708,49.06680,22540,8
54.34480,-4.12460,-41.63463,4.09796,41.63464,22540,8
54.69680,-3.77249,-33.17611,3.74585,33.17611,22540,8
55.06980,-3.39937,-24.93272,3.37273,24.93272,22540,8
55.50620,-2.96338,-17.30105,2.93674,17.30105,22540,8
56.00620,-2.46336,-9.75025,2.43672,9.75025,22540,8
56.41580,-2.54687,-12.47339,2.52023,12.47339,22540,8
56.84780,-2.98542,-20.37071,2.95878,20.37071,22604,9
57.23380,-3.37177,-28.27336,3.34513,28.27336,22604,9
57.59280,-3.73093,-36.76274,3.70429,36.76274,22604,9
57.93580,-4.07396,-44.83628,4.04732,44.83628,22604,9
58.29580,-4.43378,-53.31169,4.40714,53.31169,22604,9
58.60620,-4.74391,-60.69341,4.71727,60.69341,22604,9
58.90620,-5.04381,-67.82341,5.01717,67.82341,22604,9
59.17480,-4.96800,-64.71138,4.94136,64.71138,22604,9
59.46680,-4.66658,-56.00153,4.63994,56.00153,22540,9
59.77580,-4.35591,-47.50328,4.32927,47.50328,22540,9
60.10620,-4.02577,-39.19972,3.99913,39.19972,22540,9
60.44480,-3.68689,-30.98987,3.66025,30.98987,22540,9
60.83380,-3.29778,-22.93878,3.27114,22.93878,22540,9
61.30620,-2.82579,-15.15615,2.79915,15.15615,22540,9
61.79880,-2.33297,-7.51704,2.30633,7.51704,22540,9
62.40620,-2.49630,-11.75295,2.46966,11.75295,22540,9
62.83480,-2.93029,-19.48644,2.90365,19.48644,22476,9
63.22680,-3.32263,-27.25401,3.29599,27.25401,22476,10
63.58780,-3.68372,-35.69266,3.65708,35.69266,22476,10
63.92280,-4.01861,-43.62026,3.99197,43.62026,22476,10
64.29580,-4.39155,-52.35998,4.36491,52.35998,22476,10
64.63180,-4.72779,-60.30437,4.70115,60.30437,22476,10
64.98980,-5.08576,-68.83759,5.05912,68.83759,22476,10
65.22180,-4.94994,-64.14504,4.92330,64.14503,22476,10
65.49080,-4.67247,-56.20122,4.64582,56.20122,22412,10
65.80280,-4.35863,-47.55340,4.33199,47.55340,22412,10
66.11680,-4.04459,-39.57615,4.01795,39.57615,22412,10
66.43280,-3.72858,-31.97776,3.70194,31.97776,22412,10
66.78180,-3.37940,-24.43366,3.35276,24.43366,22412,10
67.22380,-2.93746,-16.85804,2.91082,16.85804,22412,10
67.71680,-2.44449,-9.37228,2.41785,9.37228,22412,10
68.10620,-2.53851,-12.23853,2.51186,12.23853,22412,10
68.52580,-2.96528,-19.89875,2.93864,19.89875,22476,11
68.90880,-3.34867,-27.64517,3.32203,27.64517,22476,11
69.26980,-3.70984,-36.09528,3.68320,36.09528,22476,11
69.59480,-4.03471,-43.85541,4.00807,43.85541,22476,11
69.89880,-4.33869,-51.02755,4.31205,51.02755,22476,11
70.25380,-4.69388,-59.38562,4.66724,59.38562,22476,11
70.60180,-5.04171,-67.62289,5.01507,67.62289,22476,11
70.87980,-4.95839,-64.29631,4.93174,64.29631,22476,11
71.17080,-4.65839,-55.69662,4.63175,55.69662,22412,11
71.43880,-4.38882,-48.27146,4.36218,48.27146,22412,11
71.78080,-4.04681,-39.51404,4.02016,39.51404,22412,11
72.11480,-3.71283,-31.48402,3.68619,31.48402,22412,11
72.50620,-3.32172,-23.27339,3.29508,23.27339,22412,11
72.98980,-2.83767,-15.28509,2.81103,15.28509,22412,11
73.46480,-2.36270,-7.96079,2.33606,7.96079,22412,11
73.78680,-2.58315,-12.94243,2.55651,12.94243,22412,11
74.20620,-3.00761,-20.66101,2.98097,20.66101,22476,12
74.59180,-3.39385,-28.67106,3.36721,28.67106,22476,12
74.93480,-3.73710,-36.67895,3.71046,36.67895,22476,12
75.29380,-4.09621,-45.18884,4.06957,45.18884,22476,12
75.63580,-4.43795,-53.24002,4.41131,53.24002,22476,12
75.98880,-4.79092,-61.70099,4.76427,61.70099,22476,12
76.31580,-5.11809,-69.45176,5.09145,69.45177,22476,12
76.60380,-4.87802,-61.85943,4.85138,61.85943,22476,12
76.87180,-4.60497,-54.12042,4.57833,54.12042,22412,12
77.17480,-4.30106,-45.74089,4.27442,45.74089,22412,12
77.48480,-3.99081,-38.09294,3.96417,38.09294,22412,12
77.82180,-3.65391,-30.08757,3.62727,30.08757,22412,12
78.22380,-3.25188,-21.94246,3.22524,21.94246,22412,12
78.70620,-2.76990,-14.14840,2.74325,14.14840,22412,12
79.16280,-2.31681,-7.17012,2.29017,7.17012,22412,12
79.53680,-2.69438,-14.95597,2.66774,14.95597,22476,12
79.95380,-3.11416,-22.72777,3.08752,22.72777,22476,13
80.32680,-3.48733,-30.74695,3.46069,30.74695,22476,13
80.68680,-3.84731,-39.30420,3.82067,39.30420,22476,13
80.99380,-4.15437,-46.54510,4.12773,46.54510,22476,13
81.33480,-4.49531,-54.53503,4.46867,54.53503,22476,13
81.69480,-4.85514,-63.15262,4.82850,63.15262,22476,13
82.01780,-5.12342,-69.31806,5.09678,69.31805,22476,13
82.29780,-4.81850,-60.10350,4.79186,60.10350,22412,13
82.59680,-4.51564,-51.61975,4.48900,51.61975,22412,13
82.90620,-4.20633,-43.31459,4.17969,43.31459,22412,13
83.25080,-3.86109,-34.91500,3.83445,34.91500,22412,13
83.60620,-3.50606,-26.74893,3.47942,26.74893,22412,13
84.03880,-3.07320,-18.90222,3.04656,18.90222,22412,13
84.53480,-2.57723,-11.34663,2.55059,11.34663,22412,13
84.91780,-2.42430,-9.86226,2.39766,9.86226,22412,13
85.33680,-2.85844,-17.84058,2.83180,17.84058,22476,13
85.74580,-3.26839,-25.88163,3.24175,25.88163,22476,14
86.10480,-3.62748,-34.10184,3.60084,34.10184,22476,14
86.45280,-3.97541,-42.27007,3.94877,42.27007,22476,14
86.80080,-4.32339,-50.52089,4.29675,50.52089,22476,14
87.14880,-4.67157,-58.72563,4.64493,58.72563,22476,14
87.46680,-4.98938,-66.26435,4.96273,66.26434,22476,14
87.75880,-5.00933,-65.71271,4.98269,65.71271,22476,14
88.03980,-4.71668,-57.13278,4.69004,57.13278,22412,14
88.34680,-4.40747,-48.62410,4.38083,48.62410,22412,14
88.67680,-4.07749,-39.97825,4.05085,39.97826,22412,14
88.98780,-3.76633,-32.65790,3.73969,32.65789,22412,14
89.36080,-3.39318,-24.46223,3.36654,24.46223,22412,14
89.80620,-2.94824,-16.80738,2.92160,16.80738,22412,14
90.30620,-2.44827,-9.24852,2.42163,9.24852,22412,14
90.67780,-2.56158,-12.42052,2.53494,12.42052,22412,14
91.10620,-2.99626,-20.28598,2.96962,20.28598,22476,15
91.49180,-3.38256,-28.22576,3.35592,28.22576,22476,15
91.80620,-3.69680,-35.62647,3.67016,35.62647,22476,15
92.12580,-4.01666,-43.18504,3.99002,43.18504,22476,15
92.42880,-4.31965,-50.40867,4.29301,50.40867,22476,15
92.78380,-4.67484,-58.79056,4.64820,58.79056,22476,15
93.12080,-5.01163,-66.76641,4.98499,66.76641,22476,15
93.41880,-4.99394,-65.16635,4.96730,65.16634,22476,15
93.70620,-4.69672,-56.53869,4.67008,56.53869,22412,15
94.00980,-4.39075,-48.14137,4.36411,48.14137,22412,15
94.34080,-4.05980,-39.53801,4.03316,39.53801,22412,15
94.69580,-3.70475,-31.02624,3.67811,31.02624,22412,15
95.02980,-3.37056,-24.00781,3.34391,24.00781,22412,15
95.50480,-2.89553,-15.94756,2.86889,15.94756,22412,15
96.00380,-2.39656,-8.35064,2.36992,8.35064,22412,15
96.38280,-2.64147,-13.79884,2.61483,13.79884,22476,15
96.80380,-3.06670,-21.68993,3.04006,21.68993,22476,16
97.18580,-3.44897,-29.76080,3.42233,29.76080,22476,16
97.52280,-3.78601,-37.68968,3.75937,37.68968,22476,16
97.88280,-4.14608,-46.24471,4.11944,46.24471,22476,16
98.21880,-4.48200,-54.14376,4.45536,54.14376,22476,16
98.58280,-4.84586,-62.83421,4.81922,62.83421,22476,16
98.90620,-5.14013,-69.74699,5.11349,69.74699,22476,16
99.18080,-4.84277,-60.70268,4.81613,60.70268,22412,16
99.48280,-4.53652,-52.09063,4.50988,52.09063,22412,16
99.75680,-4.26193,-44.52085,4.23529,44.52085,22412,16
100.09880,-3.91978,-36.08545,3.89314,36.08545,22412,16
100.44280,-3.57597,-28.08220,3.54933,28.08220,22412,16
100.86980,-3.14889,-19.89929,3.12225,19.89929,22412,16
101.36580,-2.65288,-12.35142,2.62624,12.35142,22412,16
101.77580,-2.40048,-9.10274,2.37384,9.10275,22412,16
102.13180,-2.77530,-16.25006,2.74866,16.25006,22476,16
102.55580,-3.20118,-24.32803,3.17454,24.32803,22476,17
102.91680,-3.56229,-32.32377,3.53565,32.32377,22476,17
103.20580,-3.85124,-39.22857,3.82460,39.22857,22476,17
103.48780,-4.13337,-45.89426,4.10673,45.89426,22476,17
103.81180,-4.45727,-53.52591,4.43062,53.52591,22476,17
104.17680,-4.82214,-62.25746,4.79550,62.25746,22476,17
104.47880,-5.12431,-69.44000,5.09767,69.44000,22476,17
104.72080,-4.93249,-63.24106,4.90585,63.24107,22476,17
105.01380,-4.63231,-54.66084,4.60567,54.66084,22412,17
105.30620,-4.33922,-46.68874,4.31258,46.68874,22412,17
105.61980,-4.02503,-38.64666,3.99839,38.64666,22412,17
105.93580,-3.70917,-31.00515,3.68253,31.00515,22412,17
106.32880,-3.31608,-22.89031,3.28944,22.89031,22412,17
106.80620,-2.83902,-15.05877,2.81238,15.05877,22412,17
107.29180,-2.35312,-7.50024,2.32648,7.50024,22412,17
107.63280,-2.64804,-13.84369,2.62140,13.84369,22604,17
108.05780,-3.07713,-21.81959,3.05049,21.81959,22604,17
108.42580,-3.44536,-29.58265,3.41872,29.58265,22604,18
108.74980,-3.76941,-37.23565,3.74276,37.23565,22604,18
109.02580,-4.04540,-43.74872,4.01876,43.74872,22604,18
109.30620,-4.32530,-50.39812,4.29866,50.39812,22604,18
109.61280,-4.63240,-57.69035,4.60576,57.69035,22604,18
109.97380,-4.99330,-66.22456,4.96666,66.22456,22604,18
110.27580,-5.01297,-65.66018,4.98633,65.66018,22604,18
110.49880,-4.77950,-58.77538,4.75286,58.77538,22540,18
110.80480,-4.47072,-50.21698,4.44408,50.21698,22540,18
111.08080,-4.19453,-42.75417,4.16789,42.75417,22540,18
111.42280,-3.85233,-34.48432,3.82569,34.48432,22540,18
111.74980,-3.52531,-26.87074,3.49867,26.87074,22540,18
112.19480,-3.08043,-18.82445,3.05379,18.82445,22540,18
112.68380,-2.59143,-11.38959,2.56479,11.38959,22540,18
113.09980,-2.48498,-10.83316,2.45834,10.83316,22540,18
113.50620,-2.90271,-18.51692,2.87607,18.51692,22604,18
113.90620,-3.30351,-26.32541,3.27687,26.32541,22604,19
114.21580,-3.61370,-33.56318,3.58706,33.56318,22604,19
114.58780,-3.98558,-42.28109,3.95894,42.28109,22604,19
114.90480,-4.30254,-49.80287,4.27590,49.80287,22604,19
115.24180,-4.63968,-57.77066,4.61304,57.77066,22604,19
115.59980,-4.99755,-66.29250,4.97091,66.29250,22604,19
115.90180,-5.01300,-65.61487,4.98636,65.61487,22604,19
116.18480,-4.71877,-57.01973,4.69213,57.01973,22540,19
116.49080,-4.41068,-48.52608,4.38404,48.52608,22540,19
116.76280,-4.13863,-41.26387,4.11199,41.26387,22540,19
117.04980,-3.85152,-34.39409,3.82488,34.39409,22540,19
117.40620,-3.49546,-26.27556,3.46882,26.27556,22540,19
117.84280,-3.05855,-18.45563,3.03191,18.45563,22540,19
118.33380,-2.56759,-10.94402,2.54095,10.94402,22540,19
119.00620,-2.36639,-8.48228,2.33975,8.48228,22540,19
119.40620,-2.78034,-16.43391,2.75370,16.43391,22476,19
119.81780,-3.19334,-24.26905,3.16670,24.26905,22476,20
120.10620,-3.48127,-30.45316,3.45463,30.45316,22476,20
120.34780,-3.72341,-36.19008,3.69677,36.19008,22476,20
120.57380,-3.94923,-41.48271,3.92259,41.48271,22476,20
120.78580,-4.16141,-46.61701,4.13477,46.61701,22476,20
121.10620,-4.48133,-54.05261,4.45469,54.05261,22476,20
121.34380,-4.71941,-59.79089,4.69277,59.79089,22476,20
121.66180,-5.03720,-67.30336,5.01056,67.30336,22476,20
121.90620,-5.00721,-65.49810,4.98057,65.49810,22476,20
122.14180,-4.76015,-58.23674,4.73351,58.23674,22412,20
122.43180,-4.46756,-50.14417,4.44092,50.14417,22412,20
122.74780,-4.15135,-41.60203,4.12471,41.60203,22412,20
122.99580,-3.90306,-35.57000,3.87642,35.57000,22412,20
123.27180,-3.62721,-29.09113,3.60057,29.09113,22412,20
123.67980,-3.21925,-21.08981,3.19261,21.08981,22412,20
124.10620,-2.79320,-14.28126,2.76656,14.28126,22412,20
124.57680,-2.33011,-7.10533,2.30347,7.10533,22412,20
124.93680,-2.70155,-14.83094,2.67491,14.83094,22476,20
125.30980,-3.07733,-21.77949,3.05069,21.77949,22476,21
125.70380,-3.47155,-30.10407,3.44491,30.10407,22476,21
126.00780,-3.77558,-37.28556,3.74894,37.28556,22476,21
126.35880,-4.12669,-45.57731,4.10005,45.57731,22476,21
126.70680,-4.47458,-53.78938,4.44794,53.78938,22476,21
127.04880,-4.81645,-62.08296,4.78981,62.08296,22476,21
127.40080,-5.14592,-69.80395,5.11928,69.80396,22476,21
127.66180,-4.86475,-61.19658,4.83811,61.19658,22476,21
127.93780,-4.58421,-53.24151,4.55757,53.24150,22412,21
128.23380,-4.28739,-45.06110,4.26075,45.06110,22412,21
128.53479,-3.98620,-37.48210,3.95956,37.48210,22412,21
128.86679,-3.65436,-29.70734,3.62772,29.70734,22412,21
129.25380,-3.26726,-21.88929,3.24062,21.88929,22412,21
129.72080,-2.80032,-14.34606,2.77368,14.34606,22412,21
130.20580,-2.32408,-6.99391,2.29744,6.99391,22412,21
130.58080,-2.71202,-14.96103,2.68538,14.96103,22476,21
130.99480,-3.12862,-22.76962,3.10198,22.76962,22476,22
131.36380,-3.49771,-30.70014,3.47107,30.70014,22476,22
131.68480,-3.81876,-38.34857,3.79212,38.34857,22476,22
132.02380,-4.15782,-46.34070,4.13118,46.34070,22476,22
132.38180,-4.51571,-54.81943,4.48906,54.81943,22476,22
132.71380,-4.84753,-62.73616,4.82089,62.73616,22476,22
133.04680,-5.13973,-69.53425,5.11309,69.53425,22476,22
133.29380,-4.86910,-61.29042,4.84246,61.29042,22476,22
133.59780,-4.56031,-52.52871,4.53367,52.52871,22412,22
133.83180,-4.32571,-46.14940,4.29907,46.14939,22412,22
134.16380,-3.99344,-37.60658,3.96680,37.60658,22412,22
134.47880,-3.67864,-30.19963,3.65200,30.19963,22412,22
134.88780,-3.26949,-21.90455,3.24285,21.90455,22412,22
135.35480,-2.80256,-14.41643,2.77592,14.41643,22412,22
135.81280,-2.34527,-7.30268,2.31863,7.30268,22412,22
136.18780,-2.70880,-14.87914,2.68216,14.87914,22476,22
136.60620,-3.12969,-22.74768,3.10305,22.74768,22476,23
136.97380,-3.49782,-30.66799,3.47118,30.66799,22476,23
137.24380,-3.76786,-37.02312,3.74122,37.02312,22476,23
137.51880,-4.04282,-43.58912,4.01618,43.58912,22476,23
137.83680,-4.36072,-51.17099,4.33408,51.17099,22476,23
138.14880,-4.67291,-58.49315,4.64627,58.49315,22476,23
138.46680,-4.99067,-66.09012,4.96403,66.09012,22476,23
138.73980,-5.05926,-66.86300,5.03262,66.86300,22476,23
139.01980,-4.76441,-58.19934,4.73777,58.19934,22412,23
139.32180,-4.45990,-49.72886,4.43325,49.72886,22412,23
139.64680,-4.13472,-40.95820,4.10807,40.95819,22412,23
140.00080,-3.78063,-32.50984,3.75398,32.50985,22412,23
140.32180,-3.45958,-25.48768,3.43294,25.48768,22412,23
140.77080,-3.01046,-17.57176,2.98382,17.57176,22412,23
141.27180,-2.50952,-10.00687,2.48288,10.00688,22412,23
141.62880,-2.50993,-11.18600,2.48329,11.18600,22412,23
142.06780,-2.95928,-19.37996,2.93264,19.37996,22476,24
142.46480,-3.35681,-27.31644,3.33017,27.31644,22476,24
142.80620,-3.69794,-35.35228,3.67130,35.35228,22476,24
143.11780,-4.00981,-42.77442,3.98317,42.77443,22476,24
143.47680,-4.36879,-51.30703,4.34215,51.30703,22476,24
143.80680,-4.69898,-59.09140,4.67234,59.09140,22476,24
144.16780,-5.05983,-67.66372,5.03319,67.66372,22476,24
144.40619,-4.99871,-65.15304,4.97207,65.15304,22476,24
144.70380,-4.68970,-56.15916,4.66306,56.15916,22412,24
144.97980,-4.41189,-48.48533,4.38525,48.48533,22412,24
145.29680,-4.09485,-39.97965,4.06821,39.97965,22412,24
145.57180,-3.81972,-33.45236,3.79308,33.45236,22412,24
145.85680,-3.53470,-26.86841,3.50806,26.86841,22412,24
146.30380,-3.08779,-18.78905,3.06115,18.78905,22412,24
146.78880,-2.60283,-11.39641,2.57619,11.39641,22412,24
147.16780,-2.44533,-9.85480,2.41869,9.85480,22412,24
147.58180,-2.87482,-17.83954,2.84818,17.83954,22476,24
147.98780,-3.28179,-25.81385,3.25515,25.81385,22476,25
148.30620,-3.59999,-33.02421,3.57335,33.02422,22476,25
148.58180,-3.87592,-39.50184,3.84928,39.50184,22476,25
148.85880,-4.15305,-46.12721,4.12641,46.12721,22476,25
149.20619,-4.49997,-54.33584,4.47332,54.33584,22476,25
149.56180,-4.85570,-62.85281,4.82906,62.85281,22476,25
149.86980,-5.15254,-69.97289,5.12590,69.97289,22476,25
150.11580,-4.89406,-61.98164,4.86742,61.98164,22412,25
150.32680,-4.67849,-55.79838,4.65185,55.79838,22412,25
150.63980,-4.36380,-47.20773,4.33716,47.20773,22412,25
150.94780,-4.05579,-39.04227,4.02915,39.04227,22412,25
151.20619,-3.79773,-32.90527,3.77109,32.90527,22412,25
151.59180,-3.41163,-24.45310,3.38499,24.45310,22412,25
152.00380,-2.99957,-17.34327,2.97293,17.34327,22412,25
152.49280,-2.51062,-9.94999,2.48398,9.94999,22412,25
152.84380,-2.51901,-11.33712,2.49237,11.33712,22412,25
153.27480,-2.96027,-19.31895,2.93363,19.31895,22476,26
153.67680,-3.36276,-27.37610,3.33612,27.37610,22476,26
153.94280,-3.62891,-33.74724,3.60227,33.74724,22476,26
154.22180,-3.90781,-40.23017,3.88117,40.23018,22476,26
154.57680,-4.26288,-48.71979,4.23624,48.71980,22476,26
154.88980,-4.57596,-56.21935,4.54932,56.21935,22476,26
155.13780,-4.82371,-62.09905,4.79707,62.09905,22476,26
155.40619,-5.09193,-68.45452,5.06529,68.45452,22476,26
155.67780,-4.94462,-63.42257,4.91798,63.42257,22476,26
155.94180,-4.67346,-55.66420,4.64682,55.66420,22412,26
156.15880,-4.45507,-49.59768,4.42843,49.59768,22412,26
156.42980,-4.18395,-42.23403,4.15731,42.23402,22412,26
156.70619,-3.90769,-35.35113,3.88105,35.35114,22412,26
157.06980,-3.54378,-27.00869,3.51714,27.00869,22412,26
157.50619,-3.10781,-19.02347,3.08117,19.02347,22412,26
158.00380,-2.60984,-11.48729,2.58320,11.48729,22412,26
158.40619,-2.46719,-10.28139,2.44055,10.28139,22412,26
158.82780,-2.90295,-18.33600,2.87631,18.33600,22476,26
159.23280,-3.30888,-26.31593,3.28224,26.31593,22476,27
159.59780,-3.67401,-34.78126,3.64737,34.78126,22476,27
159.90619,-3.98184,-42.06173,3.95520,42.06173,22476,27
160.24780,-4.32387,-50.20315,4.29723,50.20315,22476,27
160.60620,-4.68200,-58.66236,4.65536,58.66236,22476,27
160.94980,-5.02583,-66.87518,4.99919,66.87518,22476,27
161.20980,-5.04143,-66.28008,5.01479,66.28008,22476,27
161.50619,-4.73218,-57.26072,4.70554,57.26072,22412,27
161.80620,-4.43012,-48.86993,4.40348,48.86993,22412,27
162.09380,-4.14199,-41.01798,4.11535,41.01798,22412,27
162.42980,-3.80589,-32.96501,3.77925,32.96501,22412,27
162.80620,-3.42986,-24.77009,3.40322,24.77009,22412,27
163.25580,-2.97979,-16.95276,2.95315,16.95276,22412,27
163.74880,-2.48680,-9.49391,2.46016,9.49391,22412,27
164.10620,-2.54922,-11.87490,2.52258,11.87490,22412,27
164.53180,-2.98358,-19.72558,2.95694,19.72558,22604,27
164.92780,-3.38002,-27.78287,3.35338,27.78287,22604,28
165.24480,-3.69720,-35.23888,3.67056,35.23888,22604,28
165.55780,-4.01003,-42.74875,3.98339,42.74875,22604,28
165.87580,-4.32805,-50.28126,4.30141,50.28126,22604,28
166.19380,-4.64613,-57.74149,4.61949,57.74149,22604,28
166.49980,-4.95189,-65.12569,4.92525,65.12569,22604,28
166.73380,-5.12763,-69.10087,5.10099,69.10087,22604,28
166.94580,-4.89261,-61.92011,4.86597,61.92011,22604,28
167.21080,-4.62215,-54.23428,4.59551,54.23428,22540,28
167.42580,-4.40613,-48.34805,4.37949,48.34805,22540,28
167.61180,-4.22015,-43.18183,4.19351,43.18183,22540,28
167.85080,-3.98085,-37.09872,3.95421,37.09872,22540,28
168.07780,-3.75400,-31.63631,3.72736,31.63631,22540,28
168.33380,-3.49791,-26.09361,3.47127,26.09361,22540,28
168.75680,-3.07501,-18.50489,3.04837,18.50489,22540,28
169.26180,-2.57009,-10.80921,2.54345,10.80921,22540,28
169.62380,-2.47164,-10.32303,2.44500,10.32303,22540,28
170.04580,-2.90723,-18.37005,2.88058,18.37005,22604,28
170.44580,-3.30805,-26.29074,3.28141,26.29074,22604,29
170.80620,-3.66825,-34.61642,3.64161,34.61642,22604,29
171.00619,-3.86814,-39.32970,3.84150,39.32970,22604,29
171.24578,-4.10837,-44.98331,4.08173,44.98331,22604,29
171.53180,-4.39405,-51.83057,4.36740,51.83057,22604,29
171.83980,-4.70225,-59.10153,4.67561,59.10153,22604,29
172.11580,-4.97804,-65.67515,4.95140,65.67515,22604,29
172.34980,-5.12354,-68.82439,5.09690,68.82439,22604,29
172.61080,-4.83952,-60.29395,4.81288,60.29395,22540,29
172.86180,-4.58494,-53.05625,4.55830,53.05625,22540,29
173.10620,-4.34023,-46.47474,4.31359,46.47474,22540,29
173.31280,-4.13320,-40.78338,4.10656,40.78338,22540,29
173.57380,-3.87203,-34.53625,3.84539,34.53625,22540,29
173.85180,-3.59413,-27.98510,3.56749,27.98510,22540,29
174.27880,-3.16717,-19.85472,3.14052,19.85472,22540,29
174.70619,-2.74018,-13.23950,2.71354,13.23950,22540,29
175.20619,-2.33010,-7.07245,2.30346,7.07245,22540,29
175.66080,-2.48003,-10.81914,2.45339,10.81914,22540,29
176.04780,-2.87344,-17.92129,2.84680,17.92129,22476,29
176.45280,-3.27893,-25.82490,3.25229,25.82490,22476,30
176.66880,-3.49503,-30.65015,3.46839,30.65015,22476,30
176.93780,-3.76406,-36.96835,3.73742,36.96835,22476,30
177.15580,-3.98193,-42.07563,3.95529,42.07563,22476,30
177.43180,-4.25801,-48.69507,4.23137,48.69506,22476,30
177.65080,-4.47703,-53.83200,4.45039,53.83200,22476,30
177.95380,-4.77983,-61.06947,4.75319,61.06947,22476,30
178.22380,-5.04993,-67.42218,5.02329,67.42218,22476,30
178.48780,-4.98364,-64.66361,4.95700,64.66361,22476,30
178.77180,-4.68977,-56.17084,4.66313,56.17085,22412,30
179.00680,-4.45311,-49.56681,4.42647,49.56681,22412,30
179.30080,-4.15893,-41.52644,4.13229,41.52644,22412,30
179.52080,-3.93871,-36.06084,3.91207,36.06084,22412,30
179.83980,-3.61981,-28.66731,3.59317,28.66731,22412,30
180.25980,-3.19990,-20.47251,3.17326,20.47251,22412,30
180.75180,-2.70794,-12.79453,2.68130,12.79453,22412,30
181.20478,-2.42294,-9.17176,2.39630,9.17176,22412,30
181.60620,-2.84256,-17.13569,2.81592,17.13569,22476,30
181.97880,-3.21681,-24.34387,3.19017,24.34387,22476,31
182.26580,-3.50387,-30.63033,3.47723,30.63033,22476,31
182.60620,-3.84395,-38.78044,3.81731,38.78045,22476,31
182.89080,-4.12907,-45.47956,4.10243,45.47956,22476,31
183.15180,-4.38981,-51.75532,4.36317,51.75533,22476,31
183.37780,-4.61597,-57.11200,4.58933,57.11200,22476,31
183.69480,-4.93272,-64.65775,4.90608,64.65775,22476,31
183.96180,-5.11346,-68.61710,5.08682,68.61710,22476,31
184.20619,-4.84675,-60.52535,4.82011,60.52535,22412,31
184.50619,-4.54240,-52.00374,4.51576,52.00374,22412,31
184.79580,-4.25185,-44.05312,4.22520,44.05312,22412,31
185.04880,-3.99867,-37.47454,3.97203,37.47454,22412,31
185.29380,-3.75379,-31.63170,3.72715,31.63170,22412,31
185.59980,-3.44773,-25.05885,3.42109,25.05886,22412,31
186.00080,-3.04677,-17.97783,3.02013,17.97783,22412,31
186.49980,-2.54780,-10.43336,2.52116,10.43336,22412,31
186.82180,-2.44737,-9.76174,2.42073,9.76174,22412,31
187.18380,-2.82451,-16.84431,2.79787,16.84431,22476,31
187.52378,-3.16587,-23.31167,3.13923,23.31167,22476,32
187.87180,-3.51394,-30.84494,3.48730,30.84494,22476,32
188.18180,-3.82402,-38.23043,3.79738,38.23043,22476,32
188.43180,-4.07412,-44.17602,4.04748,44.17602,22476,32
188.70619,-4.34792,-50.73303,4.32128,50.73303,22476,32
188.98080,-4.62302,-57.23460,4.59638,57.23460,22476,32
189.23580,-4.87775,-63.28268,4.85111,63.28268,22476,32
189.49080,-5.13301,-69.34041,5.10637,69.34041,22476,32
189.70619,-4.97013,-64.11895,4.94349,64.11895,22476,32
189.93780,-4.73024,-57.16938,4.70360,57.16938,22412,32
190.20780,-4.45826,-49.57676,4.43162,49.57676,22412,32
190.46380,-4.20213,-42.61160,4.17549,42.61160,22412,32
190.76180,-3.90385,-35.15567,3.87721,35.15567,22412,32
191.00619,-3.65999,-29.48928,3.63335,29.48928,22412,32
191.37180,-3.29392,-22.09343,3.26728,22.09343,22412,32
191.85180,-2.81405,-14.38279,2.78741,14.38279,22412,32
192.31780,-2.35063,-7.11668,2.32399,7.11668,22412,32
192.70619,-2.73937,-15.21611,2.71273,15.21611,22476,32
193.07780,-3.11394,-22.22623,3.08730,22.22623,22476,33
193.38980,-3.42604,-28.78086,3.39940,28.78086,22476,33
193.66178,-3.69812,-35.19253,3.67147,35.19253,22476,33
193.87180,-3.90800,-40.12111,3.88136,40.12111,22476,33
194.13980,-4.17617,-46.62729,4.14952,46.62729,22476,33
194.40380,-4.44003,-52.81409,4.41339,52.81409,22476,33
194.70580,-4.74204,-60.01580,4.71540,60.01580,22476,33
194.94380,-4.97986,-65.78884,4.95322,65.78883,22476,33
195.24280,-5.04300,-66.23841,5.01636,66.23841,22476,33
195.51880,-4.75367,-57.75767,4.72703,57.75767,22412,33
195.80580,-4.46439,-49.77214,4.43775,49.77214,22412,33
196.05178,-4.21825,-43.02128,4.19161,43.02128,22412,33
196.34478,-3.92496,-35.58887,3.89832,35.58887,22412,33
196.62380,-3.64606,-29.16449,3.61942,29.16449,22412,33
196.95580,-3.31406,-22.44858,3.28742,22.44858,22412,33
197.38378,-2.88592,-15.45427,2.85928,15.45427,22412,33
197.86980,-2.39991,-8.00095,2.37327,8.00095,22412,33
198.20619,-2.64911,-13.51705,2.62247,13.51705,22412,33
198.61680,-3.06495,-21.31296,3.03831,21.31296,22476,34
198.97580,-3.42417,-28.73419,3.39753,28.73419,22476,34
199.20080,-3.64921,-34.13663,3.62257,34.13663,22476,34
199.40180,-3.85023,-38.85191,3.82359,38.85191,22476,34
199.60620,-4.05430,-43.72469,4.02766,43.72469,22476,34
199.80178,-4.25026,-48.50007,4.22362,48.50007,22476,34
199.99080,-4.43920,-52.84195,4.41256,52.84195,22476,34
200.20478,-4.65327,-57.89430,4.62663,57.89431,22476,34
200.42880,-4.87697,-63.31138,4.85033,63.31138,22476,34
200.63880,-5.08727,-68.28305,5.06063,68.28305,22476,34
200.90680,-4.95856,-63.74894,4.93192,63.74894,22476,34
201.14580,-4.71214,-56.60932,4.68550,56.60932,22412,34
201.39780,-4.45832,-49.58638,4.43168,49.58638,22412,34
201.63280,-4.22317,-43.18226,4.19653,43.18226,22412,34
201.93680,-3.91891,-35.43001,3.89227,35.43001,22412,34
202.10620,-3.75001,-31.42977,3.72337,31.42977,22412,34
202.40619,-3.44999,-24.99713,3.42335,24.99713,22412,34
202.80680,-3.04901,-17.97489,3.02237,17.97489,22412,34
203.30620,-2.55004,-10.39960,2.52340,10.39960,22412,34
203.68880,-2.51601,-11.12858,2.48937,11.12858,22412,34
204.10620,-2.94352,-18.98336,2.91688,18.98336,22476,34
204.50619,-3.34415,-26.89822,3.31751,26.89822,22476,35
204.79880,-3.63724,-33.81190,3.61060,33.81190,22476,35
205.01880,-3.85724,-39.05730,3.83060,39.05730,22476,35
205.28180,-4.12043,-45.23749,4.09379,45.23748,22476,35
205.59580,-4.43421,-52.66055,4.40757,52.66055,22476,35
205.86580,-4.70428,-59.13933,4.67764,59.13933,22476,35
206.13578,-4.97410,-65.58643,4.94746,65.58643,22476,35
206.40380,-5.09815,-67.94884,5.07151,67.94884,22476,35
206.61680,-4.86821,-61.08991,4.84157,61.08991,22412,35
206.90680,-4.57389,-52.67770,4.54725,52.67770,22412,35
207.16178,-4.31825,-45.73643,4.29161,45.73643,22412,35
207.40619,-4.07425,-39.22107,4.04761,39.22107,22412,35
207.70478,-3.77513,-32.00800,3.74849,32.00800,22412,35
208.02980,-3.45009,-24.93585,3.42345,24.93585,22412,35
208.50080,-2.97895,-16.84321,2.95231,16.84320,22412,35
208.99280,-2.48702,-9.37369,2.46038,9.37369,22412,35
209.29180,-2.52246,-11.17170,2.49582,11.17170,22412,35
209.70619,-2.94740,-18.96180,2.92076,18.96180,22476,36
210.07080,-3.31308,-26.25226,3.28644,26.25226,22476,36
210.41280,-3.65518,-34.16614,3.62854,34.16614,22476,36
210.72580,-3.96808,-41.59064,3.94144,41.59064,22476,36
211.08380,-4.32612,-50.16334,4.29948,50.16335,22476,36
211.42180,-4.66424,-58.13468,4.63760,58.13468,22476,36
211.70619,-4.94803,-65.00827,4.92139,65.00827,22476,36
211.99578,-5.09417,-67.76789,5.06753,67.76789,22476,36
212.27080,-4.80055,-59.11273,4.77391,59.11273,22412,36
212.54980,-4.51852,-51.29008,4.49188,51.29008,22412,36
212.80980,-4.25813,-44.06103,4.23149,44.06104,22412,36
213.10620,-3.96202,-36.41547,3.93538,36.41547,22412,36
213.39780,-3.67017,-29.61479,3.64353,29.61479,22412,36
213.74980,-3.31809,-22.42856,3.29145,22.42856,22412,36
214.21880,-2.84902,-14.82364,2.82238,14.82364,22412,36
214.66680,-2.40095,-7.96654,2.37431,7.96654,22412,36
215.00619,-2.65920,-13.67062,2.63256,13.67062,22476,36
215.41080,-3.06887,-21.30255,3.04223,21.30255,22476,37
215.76980,-3.42806,-28.80698,3.40142,28.80698,22476,37
216.06180,-3.72021,-35.70019,3.69357,35.70019,22476,37
216.31678,-3.97505,-41.72422,3.94840,41.72422,22476,37
216.62880,-4.28704,-49.15514,4.26040,49.15514,22476,37
216.85580,-4.51415,-54.57024,4.48751,54.57024,22476,37
217.09080,-4.74905,-60.18002,4.72241,60.18002,22476,37
217.38780,-5.04601,-67.28147,5.01937,67.28147,22476,37
217.62980,-5.02459,-65.73630,4.99795,65.73630,22476,37
217.87580,-4.76690,-58.17095,4.74026,58.17095,22412,37
218.17980,-4.46032,-49.66474,4.43368,49.66473,22412,37
218.40078,-4.23910,-43.52001,4.21246,43.52001,22412,37
218.64780,-3.99188,-37.18203,3.96524,37.18203,22412,37
218.92780,-3.71204,-30.49431,3.68540,30.49431,22412,37
219.29480,-3.34493,-22.92992,3.31829,22.92992,22412,37
219.74778,-2.89185,-15.50223,2.86521,15.50223,22412,37
220.23180,-2.40789,-8.06928,2.38125,8.06928,22412,37
220.60620,-2.66576,-13.78198,2.63912,13.78198,22604,37
221.00780,-3.07193,-21.37203,3.04529,21.37203,22604,37
221.39980,-3.46419,-29.65711,3.43755,29.65711,22604,38
221.63778,-3.70229,-35.26063,3.67565,35.26063,22604,38
221.91378,-3.97808,-41.81742,3.95144,41.81742,22604,38
222.15480,-4.21925,-47.71794,4.19261,47.71795,22604,38
222.36980,-4.43414,-52.67903,4.40750,52.67903,22604,38
222.60620,-4.67021,-58.27308,4.64357,58.27308,22604,38
222.85180,-4.91593,-64.19315,4.88929,64.19315,22604,38
223.08080,-5.14520,-69.63211,5.11856,69.63211,22604,38
223.29580,-4.96771,-63.96190,4.94107,63.96190,22604,38
223.50619,-4.75045,-57.66003,4.72381,57.66003,22540,38
223.74080,-4.51338,-51.13468,4.48674,51.13468,22540,38
223.98680,-4.26702,-44.27327,4.24038,44.27327,22540,38
224.23980,-4.01390,-37.64011,3.98726,37.64011,22540,38
224.44580,-3.80799,-32.76239,3.78135,32.76239,22540,38
224.64480,-3.60903,-28.11974,3.58239,28.11975,22540,38
225.00580,-3.24796,-21.07268,3.22132,21.07268,22540,38
225.42080,-2.83298,-14.56949,2.80634,14.56949,22540,38
225.90480,-2.35509,-7.15371,2.32845,7.15371,22540,38
226.26680,-2.72612,-14.94359,2.69948,14.94359,22604,38
226.68580,-3.14799,-22.83306,3.12135,22.83306,22604,39
227.00580,-3.46814,-29.71128,3.44150,29.71128,22604,39
227.27578,-3.73822,-36.10041,3.71158,36.10041,22604,39
227.50619,-3.96806,-41.52882,3.94142,41.52882,22604,39
227.80620,-4.26813,-48.77834,4.24148,48.77834,22604,39
228.05880,-4.52116,-54.71674,4.49452,54.71674,22604,39
228.33380,-4.79599,-61.26933,4.76935,61.26933,22604,39
228.60580,-5.06815,-67.72615,5.04151,67.72615,22604,39
228.78780,-5.07786,-67.28620,5.05122,67.28620,22604,39
228.97380,-4.87758,-61.30709,4.85094,61.30709,22540,39
229.21778,-4.62912,-54.19390,4.60248,54.19390,22540,39
229.42980,-4.41616,-48.46190,4.38952,48.46189,22540,39
229.73478,-4.11112,-40.06696,4.08448,40.06696,22540,39
230.00619,-3.83998,-33.52360,3.81334,33.52360,22540,39
230.34180,-3.50396,-25.99787,3.47731,25.99787,22540,39
230.79680,-3.04900,-17.89303,3.02236,17.89304,22540,39
231.29580,-2.55010,-10.33631,2.52346,10.33631,22540,39
231.80280,-2.35635,-7.63680,2.32971,7.63680,22540,39
232.12180,-2.60496,-12.92855,2.57832,12.92855,22476,39
232.54580,-3.03212,-20.69846,3.00548,20.69846,22476,39
232.93580,-3.42236,-28.85002,3.39572,28.85002,22476,40
233.25480,-3.74145,-36.30214,3.71481,36.30214,22476,40
233.58780,-4.07454,-44.18802,4.04790,44.18801,22476,40
233.83680,-4.32331,-50.10771,4.29667,50.10772,22476,40
234.11380,-4.60047,-56.68141,4.57383,56.68141,22476,40
234.46778,-4.95422,-65.18040,4.92758,65.18040,22476,40
234.74480,-5.09395,-67.85534,5.06731,67.85534,22476,40
235.01680,-4.80283,-59.18821,4.77619,59.18821,22412,40
235.31678,-4.49962,-50.79205,4.47298,50.79205,22412,40
235.60620,-4.21040,-42.83523,4.18376,42.83523,22412,40
235.86280,-3.95315,-36.14156,3.92651,36.14156,22412,40
236.20619,-3.61025,-28.11047,3.58361,28.11047,22412,40
236.63980,-3.17630,-19.81628,3.14966,19.81628,22412,40
237.12880,-2.68744,-12.41970,2.66079,12.41970,22412,40
237.53878,-2.40813,-8.62713,2.38149,8.62713,22412,40
237.94680,-2.83786,-16.93512,2.81122,16.93513,22476,40
238.35380,-3.24627,-24.92726,3.21963,24.92726,22476,41
238.63680,-3.52924,-31.13379,3.50260,31.13379,22476,41
238.95580,-3.84824,-38.84880,3.82160,38.84880,22476,41
239.30620,-4.19840,-47.14218,4.17176,47.14218,22476,41
239.64580,-4.53829,-55.16656,4.51165,55.16656,22476,41
240.00580,-4.89804,-63.76082,4.87140,63.76083,22476,41
240.31878,-5.12709,-68.88211,5.10045,68.88211,22476,41
240.59580,-4.82626,-59.79051,4.79962,59.79052,22412,41
240.88680,-4.53171,-51.63340,4.50507,51.63340,22412,41
241.17780,-4.24028,-43.62773,4.21364,43.62773,22412,41
241.50619,-3.91208,-35.11725,3.88544,35.11724,22412,41
241.80780,-3.61022,-28.09627,3.58358,28.09627,22412,41
242.23980,-3.17827,-19.88669,3.15162,19.88669,22412,41
242.72580,-2.69241,-12.48281,2.66577,12.48281,22412,41
243.17878,-2.46069,-9.83815,2.43405,9.83815,22412,41
243.59180,-2.88913,-17.90819,2.86249,17.90819,22476,41
243.98880,-3.28712,-25.71612,3.26048,25.71612,22476,42
244.33680,-3.63529,-33.73805,3.60865,33.73806,22476,42
244.70080,-3.99923,-42.27291,3.97259,42.27291,22476,42
245.03180,-4.33022,-50.14768,4.30358,50.14768,22476,42
245.39380,-4.69236,-58.73980,4.66572,58.73980,22476,42
245.72480,-5.02314,-66.64788,4.99650,66.64788,22476,42
246.01278,-5.01631,-65.39668,4.98967,65.39668,22476,42
246.28380,-4.73433,-57.15653,4.70769,57.15652,22412,42
246.59478,-4.42122,-48.52343,4.39458,48.52343,22412,42
246.90278,-4.11316,-40.03563,4.08652,40.03563,22412,42
247.23080,-3.78503,-32.03349,3.75839,32.03349,22412,42
247.61080,-3.40494,-23.90883,3.37830,23.90883,22412,42
248.09080,-2.92492,-15.93184,2.89828,15.93184,22412,42
248.58780,-2.42798,-8.34380,2.40134,8.34380,22412,42
248.92678,-2.61510,-12.83409,2.58846,12.83409,22476,42
249.35280,-3.04689,-20.83005,3.02025,20.83005,22476,43
249.73380,-3.42827,-28.77409,3.40163,28.77409,22476,43
250.04680,-3.74137,-36.13593,3.71473,36.13593,22476,43
250.40619,-4.10050,-44.69180,4.07386,44.69180,22476,43
250.72380,-4.41819,-52.27840,4.39155,52.27840,22476,43
251.05680,-4.75125,-60.19511,4.72461,60.19511,22476,43
251.40619,-5.10032,-68.52553,5.07368,68.52553,22476,43
251.68480,-4.94561,-63.25837,4.91897,63.25837,22476,43
251.93580,-4.68790,-55.84794,4.66125,55.84794,22412,43
252.25380,-4.36821,-47.12547,4.34157,47.12547,22412,43
252.52378,-4.09827,-39.65420,4.07162,39.65420,22412,43
252.82978,-3.79211,-32.19168,3.76547,32.19168,22412,43
253.21380,-3.40802,-23.96973,3.38137,23.96973,22412,43
253.70080,-2.92102,-15.80107,2.89438,15.80107,22412,43
254.19378,-2.42804,-8.29201,2.40140,8.29201,22412,43
254.57280,-2.67676,-13.91386,2.65012,13.91386,22476,43
254.99280,-3.10103,-21.87973,3.07439,21.87973,22476,44
255.35380,-3.46220,-29.55033,3.43556,29.55033,22476,44
255.70619,-3.81425,-37.89994,3.78760,37.89994,22476,44
256.04880,-4.15734,-46.02814,4.13069,46.02814,22476,44
256.40619,-4.51423,-54.48881,4.48759,54.48881,22476,44
256.74478,-4.85302,-62.60293,4.82638,62.60293,22476,44
257.07380,-5.16525,-69.99474,5.13861,69.99474,22476,44
257.32380,-4.89810,-61.80981,4.87146,61.80981,22476,44
257.60580,-4.61098,-53.57174,4.58434,53.57174,22412,44
257.87580,-4.34020,-46.27890,4.31356,46.27890,22412,44
258.19278,-4.02300,-37.81063,3.99636,37.81063,22412,44
258.46978,-3.74610,-31.08461,3.71946,31.08461,22412,44
258.86578,-3.35002,-22.91026,3.32338,22.91026,22412,44
259.32780,-2.88790,-15.31765,2.86126,15.31765,22412,44
259.80780,-2.40795,-7.94636,2.38130,7.94636,22412,44
260.20620,-2.70679,-14.50599,2.68015,14.50599,22476,44
260.61481,-3.11912,-22.27305,3.09248,22.27304,22476,45
261.00580,-3.51021,-30.68494,3.48356,30.68494,22476,45
261.34580,-3.85029,-38.82807,3.82365,38.82807,22476,45
261.69378,-4.19837,-47.11337,4.17173,47.11337,22476,45
262.03680,-4.54129,-55.15400,4.51465,55.15400,22476,45
262.35581,-4.86004,-62.76510,4.83339,62.76510,22476,45
262.67881,-5.16631,-70.03442,5.13967,70.03442,22476,45
262.92778,-4.90022,-61.87632,4.87358,61.87632,22476,45
263.20622,-4.61712,-53.79832,4.59048,53.79832,22412,45
263.50619,-4.31632,-45.54050,4.28968,45.54050,22412,45
263.82081,-4.00105,-37.19880,3.97441,37.19880,22412,45
264.18178,-3.64016,-28.69911,3.61352,28.69911,22412,45
264.60619,-3.21628,-20.45091,3.18964,20.45091,22412,45
265.10481,-2.71732,-12.72270,2.69068,12.72270,22412,45
265.50619,-2.37094,-7.51626,2.34430,7.51626,22412,45
265.90619,-2.79842,-16.13834,2.77178,16.13834,22476,45
266.30619,-3.20027,-23.86860,3.17363,23.86860,22476,46
266.68178,-3.57640,-32.27260,3.54976,32.27259,22476,46
266.99878,-3.89328,-39.77738,3.86663,39.77737,22476,46
267.30619,-4.20046,-47.13978,4.17382,47.13978,22476,46
267.64778,-4.54237,-55.17359,4.51573,55.17359,22476,46
268.00619,-4.90007,-63.67302,4.87343,63.67302,22476,46
268.32678,-5.12377,-68.65883,5.09713,68.65883,22476,46
268.60278,-4.82508,-59.70834,4.79844,59.70834,22412,46
268.90619,-4.51859,-51.15978,4.49195,51.15978,22412,46
269.20622,-4.21831,-42.91650,4.19167,42.91650,22412,46
269.53378,-3.89003,-34.52937,3.86339,34.52937,22412,46
269.90619,-3.51808,-26.08307,3.49144,26.08307,22412,46
270.32678,-3.09720,-18.52391,3.07056,18.52391,22412,46
270.82981,-2.59423,-10.90918,2.56759,10.90918,22412,46
271.21281,-2.48525,-10.34598,2.45861,10.34598,22412,46
271.62681,-2.91237,-18.28032,2.88573,18.28032,22476,46
272.03878,-3.32528,-26.43986,3.29864,26.43986,22476,47
272.39881,-3.68542,-34.81705,3.65878,34.81705,22476,47
272.72878,-4.01533,-42.66373,3.98869,42.66373,22476,47
273.08978,-4.37627,-51.27488,4.34963,51.27488,22476,47
273.41981,-4.70639,-59.04372,4.67975,59.04372,22476,47
273.73278,-5.01923,-66.51269,4.99259,66.51269,22476,47
274.02278,-5.01238,-65.25661,4.98574,65.25661,22476,47
274.30781,-4.71635,-56.60345,4.68971,56.60345,22412,47
274.62178,-4.40034,-47.98681,4.37370,47.98681,22412,47
274.90378,-4.11835,-40.14163,4.09171,40.14163,22412,47
275.23378,-3.78823,-31.99857,3.76159,31.99857,22412,47
275.60981,-3.41215,-24.02730,3.38551,24.02730,22412,47
276.10378,-2.91813,-15.72449,2.89149,15.72449,22412,47
276.58978,-2.43216,-8.34136,2.40552,8.34136,22412,47
276.92678,-2.62123,-12.87431,2.59459,12.87431,22412,47
277.35378,-3.05408,-20.91402,3.02744,20.91402,22604,47
277.70622,-3.40628,-28.19611,3.37964,28.19611,22604,48
278.04278,-3.74352,-36.11799,3.71688,36.11799,22604,48
278.36481,-4.06553,-43.83795,4.03889,43.83794,22604,48
278.70622,-4.40630,-51.93760,4.37966,51.93760,22604,48
279.05678,-4.75732,-60.31299,4.73068,60.31299,22604,48
279.40619,-5.10640,-68.59787,5.07976,68.59787,22604,48
279.68078,-4.94563,-63.20296,4.91899,63.20296,22604,48
279.96781,-4.65152,-54.77292,4.62488,54.77292,22540,48
280.28478,-4.33340,-46.05559,4.30676,46.05558,22540,48
280.59281,-4.02515,-37.83068,3.99851,37.83068,22540,48
280.93978,-3.67829,-29.48317,3.65165,29.48317,22540,48
281.35081,-3.26714,-21.32387,3.24050,21.32387,22540,48
281.82181,-2.79627,-13.83735,2.76963,13.83735,22540,48
282.30078,-2.39956,-8.11631,2.37292,8.11631,22540,48
282.68878,-2.81350,-16.38369,2.78686,16.38369,22604,48
283.09681,-3.22333,-24.28583,3.19669,24.28583,22604,49
283.40878,-3.53536,-31.19400,3.50872,31.19400,22604,49
283.76881,-3.89531,-39.78869,3.86867,39.78868,22604,49
284.10619,-4.23246,-47.94423,4.20582,47.94423,22604,49
284.45978,-4.58647,-56.23598,4.55983,56.23598,22604,49
284.80619,-4.93218,-64.52415,4.90554,64.52415,22604,49
285.10619,-5.12150,-68.54594,5.09485,68.54594,22604,49
285.37978,-4.82608,-59.69154,4.79944,59.69154,22540,49
285.68478,-4.51763,-51.10703,4.49099,51.10703,22540,49
285.99178,-4.21040,-42.68618,4.18376,42.68618,22540,49
286.30619,-3.89610,-34.58642,3.86946,34.58642,22540,49
286.69181,-3.51017,-25.89682,3.48353,25.89683,22540,49
287.11381,-3.08827,-18.34811,3.06163,18.34811,22540,49
287.61178,-2.59034,-10.81491,2.56370,10.81491,22540,49
288.27678,-2.41434,-8.93808,2.38770,8.93808,22540,49
288.68381,-2.83383,-17.00828,2.80719,17.00828,22476,49
289.09281,-3.24353,-24.92495,3.21689,24.92495,22476,49
289.44181,-3.59265,-32.78856,3.56601,32.78856,22476,50
289.80278,-3.95354,-41.25621,3.92690,41.25621,22476,50
290.13581,-4.28654,-49.15816,4.25990,49.15816,22476,50
290.50181,-4.65268,-57.84773,4.62604,57.84773,22476,50
290.83678,-4.98747,-65.88371,4.96083,65.88371,22476,50
291.12681,-5.03721,-66.08631,5.01057,66.08631,22476,50
291.40619,-4.74503,-57.49038,4.71839,57.49038,22412,50
291.70622,-4.44277,-49.09182,4.41613,49.09182,22412,50
292.01081,-4.13756,-40.70147,4.11092,40.70147,22412,50
292.36278,-3.78545,-31.92841,3.75881,31.92841,22412,50
292.73578,-3.41239,-23.99031,3.38575,23.99031,22412,50
293.20622,-2.94239,-16.07754,2.91575,16.07754,22412,50
293.70578,-2.44240,-8.46722,2.41576,8.46722,22412,50
294.05381,-2.61845,-12.84851,2.59181,12.84851,22412,50
294.48481,-3.05536,-20.95352,3.02872,20.95352,22476,51
294.85981,-3.43059,-28.84505,3.40395,28.84505,22476,51
295.20622,-3.77677,-37.04860,3.75013,37.04860,22476,51
295.55881,-4.12986,-45.32435,4.10322,45.32435,22476,51
295.90619,-4.47672,-53.60739,4.45008,53.60739,22476,51
296.24381,-4.81449,-61.66021,4.78785,61.66021,22476,51
296.58578,-5.15619,-69.80766,5.12955,69.80766,22476,51
296.83278,-4.92691,-62.62488,4.90027,62.62488,22476,51
297.10619,-4.64781,-54.61807,4.62117,54.61807,22412,51
297.40619,-4.34669,-46.43166,4.32005,46.43166,22412,51
297.71478,-4.03760,-38.06882,4.01096,38.06882,22412,51
298.07081,-3.68166,-29.51998,3.65502,29.51998,22412,51
298.47581,-3.27654,-21.45027,3.24990,21.45027,22412,51
298.95278,-2.79965,-13.87483,2.77300,13.87483,22412,51
299.41181,-2.35411,-7.03752,2.32747,7.03752,22412,51
299.79678,-2.75723,-15.42285,2.73059,15.42285,22476,51
300.20378,-3.16659,-23.18487,3.13995,23.18487,22476,52
300.57581,-3.53868,-31.30947,3.51204,31.30947,22476,52
300.90619,-3.86874,-39.23017,3.84210,39.23017,22476,52
301.26578,-4.22879,-47.84203,4.20215,47.84203,22476,52
301.60619,-4.56881,-55.84356,4.54216,55.84356,22476,52
301.91878,-4.88149,-63.24753,4.85485,63.24753,22476,52
302.24978,-5.13084,-68.92547,5.10420,68.92547,22476,52
302.51481,-4.84210,-60.15955,4.81546,60.15955,22412,52
302.82178,-4.53117,-51.50871,4.50453,51.50871,22412,52
303.12681,-4.22580,-43.14733,4.19916,43.14732,22412,52
303.45881,-3.89355,-34.53352,3.86691,34.53352,22412,52
303.81181,-3.54071,-26.39787,3.51406,26.39787,22412,52
304.26178,-3.09071,-18.39517,3.06407,18.39517,22412,52
304.75878,-2.59377,-10.85508,2.56713,10.85508,22412,52
305.12681,-2.49125,-10.40095,2.46461,10.40095,22412,52
305.53978,-2.91768,-18.38258,2.89104,18.38258,22476,52
305.93878,-3.31755,-26.30586,3.29091,26.30586,22476,53
306.30478,-3.68375,-34.80077,3.65710,34.80077,22476,53
306.64381,-4.02269,-42.80180,3.99605,42.80180,22476,53
307.00478,-4.38359,-51.42453,4.35695,51.42453,22476,53
307.33781,-4.71676,-59.30238,4.69011,59.30238,22476,53
307.69678,-5.07573,-67.88379,5.04909,67.88379,22476,53
307.97581,-4.98279,-64.27415,4.95615,64.27415,22476,53
308.26278,-4.68713,-55.75931,4.66049,55.75931,22412,53
308.54481,-4.40355,-48.03897,4.37690,48.03897,22412,53
308.85278,-4.09557,-39.59374,4.06893,39.59374,22412,53
309.19478,-3.75345,-31.07887,3.72681,31.07887,22412,53
309.59578,-3.35237,-22.75979,3.32573,22.75979,22412,53
310.05781,-2.89026,-15.26477,2.86362,15.26477,22412,53
310.53778,-2.41029,-7.87429,2.38365,7.87429,22412,53
310.90619,-2.68030,-13.90012,2.65366,13.90012,22476,53
311.30619,-3.08438,-21.52045,3.05774,21.52044,22476,54
311.69378,-3.47268,-29.74371,3.44603,29.74371,22476,54
312.02878,-3.80763,-37.72948,3.78099,37.72948,22476,54
312.37778,-4.15670,-45.97089,4.13006,45.97089,22476,54
312.62178,-4.40044,-51.77283,4.37380,51.77283,22476,54