File: data-raw/Experiment 2/Results/INSTRON data/Experiment 2.is_ccyclic_RawData/Specimen_RawData_7.csv
Text Inputs : Specimen label,"Long Plate 1 T2.2"

Time,Extension,Load,Compressive extension,Compressive load,Segment ID,Total Cycle Count
(sec),(mm),(N),(mm),(N),,
0.00000,-0.02566,-0.01440,0.00000,0.01440,12835,0
1.43680,-0.24080,-0.03139,0.21514,0.03139,3220,0
2.40680,-0.72619,-4.29064,0.70053,4.29064,3220,0
2.91480,-1.09043,-10.65608,1.06477,10.65608,3220,0
3.63920,-1.81633,-22.74806,1.79067,22.74806,22476,0
4.10880,-2.28652,-32.56793,2.26086,32.56792,22476,0
4.45680,-2.63450,-40.41401,2.60884,40.41401,22476,0
4.91580,-3.09330,-50.94612,3.06764,50.94612,22476,0
5.41180,-3.58935,-62.04956,3.56369,62.04956,22476,0
5.89980,-3.83052,-66.05434,3.80486,66.05434,22476,0
6.33920,-3.37703,-52.93287,3.35137,52.93287,22412,0
6.73920,-2.97613,-42.17632,2.95047,42.17633,22412,0
7.10680,-2.60820,-32.36289,2.58254,32.36289,22412,0
7.46480,-2.25042,-24.59379,2.22476,24.59379,22412,0
8.19680,-1.51799,-13.06949,1.49233,13.06949,22412,0
8.80480,-1.30061,-11.57020,1.27495,11.57020,22412,0
9.39380,-1.89918,-22.59227,1.87352,22.59227,22476,1
9.76480,-2.27049,-30.38496,2.24483,30.38496,22476,1
9.99680,-2.50221,-35.84052,2.47655,35.84052,22476,1
10.27380,-2.77944,-42.41370,2.75378,42.41370,22476,1
10.64480,-3.15057,-51.03967,3.12491,51.03967,22476,1
10.93580,-3.44134,-57.64456,3.41568,57.64456,22476,1
11.24880,-3.75441,-64.92133,3.72875,64.92133,22476,1
11.54280,-3.88440,-67.09203,3.85874,67.09203,22476,1
11.80580,-3.60465,-58.75728,3.57899,58.75728,22412,1
12.10580,-3.30161,-50.34287,3.27595,50.34286,22412,1
12.31280,-3.09411,-44.76919,3.06845,44.76920,22412,1
12.59580,-2.81115,-37.32985,2.78549,37.32985,22412,1
12.84780,-2.55904,-30.68416,2.53338,30.68416,22412,1
13.23920,-2.16816,-22.65345,2.14250,22.65345,22412,1
13.83920,-1.56786,-13.43640,1.54220,13.43640,22412,1
14.36180,-1.22674,-9.38713,1.20108,9.38713,22412,1
14.90580,-1.78903,-19.94651,1.76336,19.94651,22476,2
15.29480,-2.17848,-27.87611,2.15282,27.87611,22476,2
15.53920,-2.42219,-33.72398,2.39653,33.72398,22476,2
15.84880,-2.73248,-40.78910,2.70682,40.78910,22476,2
16.10180,-2.98542,-46.85599,2.95976,46.85599,22476,2
16.44980,-3.33345,-54.78249,3.30779,54.78249,22476,2
16.77880,-3.66241,-62.55252,3.63675,62.55252,22476,2
17.13680,-3.96950,-69.22783,3.94384,69.22783,22476,2
17.43920,-3.64194,-59.36797,3.61628,59.36797,22412,2
17.70180,-3.37575,-51.97967,3.35009,51.97967,22412,2
17.90580,-3.17132,-46.52998,3.14566,46.52998,22412,2
18.13980,-2.93709,-40.18158,2.91143,40.18158,22412,2
18.42680,-2.65015,-32.65412,2.62449,32.65412,22412,2
18.76280,-2.31425,-25.11721,2.28859,25.11721,22412,2
19.43920,-1.63813,-14.28074,1.61247,14.28074,22412,2
20.12780,-1.35607,-11.93430,1.33041,11.93430,22412,2
20.79180,-2.02934,-24.49143,2.00368,24.49143,22476,3
21.20480,-2.44227,-33.84548,2.41661,33.84548,22476,3
21.51680,-2.75455,-41.15621,2.72889,41.15621,22476,3
21.84680,-3.08447,-48.86968,3.05881,48.86968,22476,3
22.23920,-3.47643,-57.86164,3.45077,57.86164,22476,3
22.73920,-3.97626,-69.45723,3.95060,69.45722,22476,3
23.03980,-3.72288,-61.44852,3.69722,61.44852,22476,3
23.41280,-3.34449,-50.92235,3.31883,50.92235,22412,3
23.73080,-3.02601,-42.39824,3.00035,42.39824,22412,3
24.04980,-2.70703,-34.02115,2.68136,34.02115,22412,3
24.47480,-2.28228,-24.18966,2.25662,24.18966,22412,3
25.21880,-1.53787,-12.67414,1.51221,12.67414,22412,3
25.81980,-1.36466,-11.96874,1.33900,11.96874,22412,3
26.47780,-2.03136,-24.45809,2.00570,24.45809,22476,4
26.83920,-2.39225,-32.56128,2.36659,32.56128,22476,4
27.20180,-2.75550,-41.03097,2.72983,41.03097,22476,4
27.64180,-3.19565,-51.32768,3.16999,51.32768,22476,4
27.97080,-3.52448,-58.91865,3.49882,58.91865,22476,4
28.32080,-3.87428,-67.01062,3.84862,67.01062,22476,4
28.51580,-3.94285,-67.92410,3.91719,67.92410,22476,4
28.72180,-3.71901,-61.30122,3.69335,61.30122,22412,4
28.83980,-3.59787,-57.77202,3.57221,57.77202,22412,4
28.98580,-3.45012,-53.69561,3.42446,53.69561,22412,4
29.16080,-3.27461,-48.88474,3.24895,48.88474,22412,4
29.31480,-3.12032,-44.80109,3.09466,44.80109,22412,4
29.48580,-2.94923,-40.15726,2.92356,40.15726,22412,4
29.63920,-2.79628,-36.18575,2.77062,36.18575,22412,4
29.86580,-2.56915,-30.25310,2.54349,30.25310,22412,4
30.14780,-2.28741,-24.08263,2.26175,24.08263,22412,4
30.82380,-1.61117,-13.58449,1.58551,13.58449,22412,4
31.47380,-1.34753,-11.50160,1.32187,11.50160,22412,4
32.10380,-1.98732,-23.46255,1.96166,23.46255,22476,5
32.61580,-2.49939,-34.97117,2.47373,34.97116,22476,5
33.09880,-2.98262,-46.38862,2.95696,46.38862,22476,5
33.53280,-3.41656,-56.50055,3.39090,56.50055,22476,5
34.05880,-3.94240,-68.48783,3.91674,68.48783,22476,5
34.43480,-3.68061,-60.09148,3.65495,60.09148,22412,5
34.86080,-3.25056,-48.23106,3.22490,48.23106,22412,5
35.30480,-2.80627,-36.40943,2.78061,36.40943,22412,5
35.70780,-2.40316,-26.21309,2.37749,26.21309,22412,5
36.37580,-1.73531,-15.23882,1.70965,15.23882,22412,5
37.04180,-1.26362,-9.39316,1.23796,9.39316,22412,5
37.64880,-1.88829,-21.51766,1.86263,21.51766,22476,6
38.04080,-2.28068,-29.77024,2.25502,29.77024,22476,6
38.42180,-2.66171,-38.82960,2.63605,38.82960,22476,6
38.66180,-2.90171,-44.33329,2.87605,44.33329,22476,6
39.06380,-3.30374,-53.45163,3.27808,53.45163,22476,6
39.42680,-3.66651,-62.05535,3.64085,62.05535,22476,6
39.74780,-3.98747,-69.44320,3.96180,69.44320,22476,6
40.03920,-3.72431,-61.26084,3.69865,61.26084,22476,6
40.37380,-3.38410,-51.72524,3.35844,51.72524,22412,6
40.65580,-3.10144,-44.10434,3.07577,44.10434,22412,6
41.01680,-2.74049,-34.68654,2.71483,34.68653,22412,6
41.42080,-2.33649,-24.72288,2.31083,24.72288,22412,6
42.13920,-1.61843,-13.44141,1.59277,13.44141,22412,6
42.82780,-1.45132,-13.06457,1.42566,13.06457,22412,6
43.46180,-2.09164,-25.42759,2.06598,25.42759,22476,7
43.99580,-2.62598,-37.64633,2.60032,37.64634,22476,7
44.45280,-3.08288,-48.42929,3.05721,48.42929,22476,7
44.92980,-3.55981,-59.47948,3.53415,59.47948,22476,7
45.35980,-3.98973,-69.40735,3.96407,69.40735,22476,7
45.72880,-3.66629,-59.44440,3.64063,59.44440,22412,7
46.14680,-3.24487,-47.96166,3.21921,47.96166,22412,7
46.51680,-2.87464,-38.12658,2.84898,38.12658,22412,7
46.92780,-2.46338,-27.38978,2.43772,27.38978,22412,7
47.63380,-1.75769,-15.46470,1.73202,15.46470,22412,7
48.33920,-1.32071,-10.42231,1.29505,10.42231,22412,7
48.90580,-1.90170,-21.56472,1.87604,21.56472,22604,7
49.38480,-2.38083,-31.73207,2.35517,31.73207,22604,8
49.80980,-2.80611,-41.77515,2.78045,41.77515,22604,8
50.30980,-3.30614,-53.42032,3.28048,53.42032,22604,8
50.80480,-3.80096,-65.08520,3.77530,65.08521,22604,8
51.21680,-3.81857,-63.82981,3.79291,63.82981,22604,8
51.59280,-3.43354,-52.81294,3.40787,52.81294,22540,8
51.99180,-3.03379,-42.15279,3.00813,42.15279,22540,8
52.42180,-2.60383,-30.86197,2.57817,30.86197,22540,8
52.99380,-2.03179,-19.47247,2.00613,19.47247,22540,8
53.74280,-1.28292,-8.55480,1.25726,8.55480,22540,8
54.37680,-1.72232,-18.02739,1.69666,18.02739,22604,8
54.95180,-2.29833,-29.83077,2.27267,29.83077,22604,9
55.44580,-2.79235,-41.40012,2.76669,41.40012,22604,9
55.91980,-3.26646,-52.57909,3.24080,52.57909,22604,9
56.36180,-3.70811,-62.86807,3.68245,62.86807,22604,9
56.83920,-3.85299,-64.81306,3.82733,64.81306,22604,9
57.31880,-3.36156,-50.89241,3.33590,50.89241,22540,9
57.79280,-2.88715,-38.32721,2.86149,38.32721,22540,9
58.15080,-2.52907,-28.89349,2.50340,28.89349,22540,9
58.70580,-1.97394,-18.58809,1.94828,18.58809,22540,9
59.47980,-1.20032,-7.29120,1.17466,7.29120,22540,9
60.22080,-1.54093,-14.90199,1.51527,14.90199,22476,9
60.86780,-2.18973,-27.49445,2.16407,27.49446,22476,10
61.29880,-2.62092,-37.54415,2.59526,37.54416,22476,10
61.72180,-3.04382,-47.51414,3.01816,47.51414,22476,10
62.10980,-3.43179,-56.38589,3.40612,56.38589,22476,10
62.56680,-3.88870,-66.97885,3.86304,66.97885,22476,10
62.92280,-3.77640,-62.61745,3.75074,62.61745,22476,10
63.22080,-3.47158,-53.86601,3.44592,53.86601,22412,10
63.62580,-3.06549,-42.99188,3.03983,42.99187,22412,10
64.07480,-2.61663,-31.17144,2.59097,31.17144,22412,10
64.73920,-1.95245,-18.17452,1.92679,18.17452,22412,10
65.53080,-1.20022,-7.42120,1.17456,7.42120,22412,10
66.13920,-1.83636,-20.04431,1.81070,20.04431,22476,11
66.73980,-2.43765,-33.02981,2.41199,33.02981,22476,11
67.23920,-2.93699,-44.78826,2.91133,44.78826,22476,11
67.80380,-3.50191,-57.84879,3.47625,57.84879,22476,11
68.35380,-4.00733,-69.57086,3.98167,69.57086,22476,11
68.76780,-3.56557,-56.50347,3.53991,56.50347,22412,11
69.26480,-3.06658,-43.03774,3.04092,43.03774,22412,11
69.68580,-2.64575,-31.94420,2.62009,31.94420,22412,11
70.27980,-2.05160,-19.58461,2.02594,19.58461,22412,11
71.04080,-1.29074,-8.52934,1.26507,8.52934,22412,11
71.65780,-1.72699,-18.02826,1.70133,18.02826,22476,11
72.29180,-2.36190,-31.12329,2.33624,31.12329,22476,12
72.79380,-2.86414,-43.09192,2.83848,43.09192,22476,12
73.30480,-3.37502,-54.96535,3.34936,54.96535,22476,12
73.73180,-3.80196,-64.96566,3.77630,64.96566,22476,12
74.17380,-3.79400,-62.92104,3.76833,62.92104,22476,12
74.65180,-3.30808,-49.28855,3.28242,49.28855,22412,12
75.10780,-2.85179,-37.24146,2.82612,37.24146,22412,12
75.53920,-2.42064,-26.29589,2.39498,26.29589,22412,12
76.26780,-1.69178,-14.18808,1.66611,14.18808,22412,12
76.97380,-1.41948,-12.10978,1.39382,12.10978,22412,12
77.62680,-2.08088,-24.91644,2.05522,24.91644,22476,13
78.19880,-2.65307,-37.95421,2.62741,37.95421,22476,13
78.68380,-3.13822,-49.40151,3.11256,49.40152,22476,13
79.17680,-3.63093,-60.98525,3.60527,60.98525,22476,13
79.65280,-3.94969,-67.55435,3.92403,67.55435,22476,13
80.04780,-3.53539,-55.48102,3.50973,55.48102,22412,13
80.45980,-3.12192,-44.24549,3.09626,44.24548,22412,13
80.84480,-2.73687,-34.20473,2.71121,34.20473,22412,13
81.43920,-2.14290,-20.96935,2.11724,20.96935,22412,13
82.24980,-1.33174,-9.05358,1.30608,9.05358,22412,13
82.87580,-1.70892,-17.58810,1.68326,17.58810,22476,13
83.50080,-2.33503,-30.41704,2.30937,30.41704,22476,14
83.98580,-2.82019,-41.78219,2.79453,41.78218,22476,14
84.47180,-3.30624,-53.23071,3.28058,53.23071,22476,14
84.94280,-3.77709,-64.25102,3.75143,64.25102,22476,14
85.35780,-3.87013,-65.05595,3.84447,65.05595,22476,14
85.77180,-3.44453,-52.89500,3.41887,52.89500,22412,14
86.17980,-3.03579,-41.90703,3.01013,41.90704,22412,14
86.56180,-2.65392,-31.87792,2.62826,31.87792,22412,14
87.16380,-2.05176,-19.48351,2.02609,19.48351,22412,14
87.93920,-1.27697,-8.26808,1.25131,8.26808,22412,14
88.54580,-1.73319,-17.93203,1.70753,17.93203,22476,14
89.17580,-2.36398,-30.92876,2.33832,30.92876,22476,15
89.70780,-2.89624,-43.51538,2.87058,43.51538,22476,15
90.15180,-3.34016,-53.87820,3.31450,53.87820,22476,15
90.63920,-3.82699,-65.42534,3.80133,65.42535,22476,15
91.05080,-3.80352,-63.07097,3.77786,63.07097,22476,15
91.33920,-3.50826,-54.55944,3.48260,54.55944,22412,15
91.66180,-3.18415,-45.81955,3.15849,45.81955,22412,15
92.02280,-2.82298,-36.26027,2.79732,36.26027,22412,15
92.41380,-2.43180,-26.40880,2.40614,26.40880,22412,15
93.11580,-1.73003,-14.71781,1.70437,14.71781,22412,15
93.83080,-1.39518,-11.57186,1.36952,11.57186,22412,15
94.47380,-2.04821,-23.98320,2.02254,23.98320,22476,16
95.02380,-2.59836,-36.45125,2.57270,36.45125,22476,16
95.45980,-3.03437,-46.87746,3.00871,46.87746,22476,16
95.89380,-3.46828,-56.90704,3.44262,56.90704,22476,16
96.38580,-3.96019,-68.42376,3.93453,68.42376,22476,16
96.69680,-3.76600,-62.02359,3.74034,62.02359,22412,16
97.10780,-3.34848,-50.28937,3.32282,50.28938,22412,16
97.45880,-2.99700,-40.89659,2.97134,40.89659,22412,16
97.84980,-2.60610,-30.63306,2.58044,30.63306,22412,16
98.36480,-2.09097,-20.00658,2.06531,20.00658,22412,16
99.13920,-1.31703,-8.78568,1.29137,8.78568,22412,16
99.75380,-1.71738,-17.56052,1.69172,17.56052,22476,16
100.29080,-2.25549,-28.40241,2.22983,28.40241,22476,17
100.78280,-2.74761,-40.00715,2.72195,40.00715,22476,17
101.06680,-3.03152,-46.72023,3.00585,46.72023,22476,17
101.43920,-3.40350,-55.46089,3.37784,55.46088,22476,17
101.74780,-3.71229,-62.75445,3.68663,62.75445,22476,17
102.03680,-4.00139,-69.37577,3.97573,69.37577,22476,17
102.33920,-3.73274,-61.03979,3.70708,61.03979,22476,17
102.63920,-3.42782,-52.45576,3.40216,52.45576,22412,17
102.91380,-3.15233,-44.93063,3.12667,44.93063,22412,17
103.16980,-2.89622,-38.29599,2.87056,38.29599,22412,17
103.49380,-2.57212,-29.78451,2.54646,29.78451,22412,17
104.03580,-2.03011,-19.10165,2.00445,19.10165,22412,17
104.68880,-1.37718,-9.65621,1.35152,9.65621,22412,17
105.23920,-1.60061,-15.35716,1.57495,15.35716,22604,17
105.87380,-2.23849,-27.94381,2.21283,27.94381,22604,18
106.33780,-2.70249,-38.97369,2.67683,38.97369,22604,18
106.67580,-3.04045,-47.03845,3.01479,47.03845,22604,18
107.20580,-3.57043,-59.27940,3.54477,59.27940,22604,18
107.58880,-3.95329,-68.19613,3.92763,68.19613,22604,18
107.94080,-3.74918,-61.45660,3.72352,61.45660,22604,18
108.23920,-3.44595,-52.82024,3.42029,52.82024,22540,18
108.55280,-3.13138,-44.37985,3.10572,44.37985,22540,18
108.77580,-2.90832,-38.58996,2.88266,38.58996,22540,18
109.05380,-2.63031,-31.14765,2.60465,31.14765,22540,18
109.48580,-2.19833,-21.73766,2.17267,21.73766,22540,18
110.20880,-1.47511,-11.04032,1.44945,11.04031,22540,18
110.83920,-1.57634,-14.95909,1.55068,14.95909,22604,18
111.45580,-2.19661,-26.97093,2.17095,26.97093,22604,19
111.70580,-2.44640,-32.90117,2.42074,32.90117,22604,19
112.12780,-2.86869,-42.78588,2.84303,42.78588,22604,19
112.35780,-3.09867,-48.45592,3.07301,48.45592,22604,19
112.75680,-3.49760,-57.54858,3.47194,57.54858,22604,19
113.19680,-3.93747,-67.84475,3.91181,67.84475,22604,19
113.51980,-3.80447,-62.92796,3.77881,62.92796,22604,19
113.86780,-3.44913,-52.83157,3.42346,52.83157,22540,19
114.26180,-3.05437,-42.33517,3.02871,42.33517,22540,19
114.60680,-2.70943,-33.34118,2.68377,33.34118,22540,19
115.05780,-2.25863,-22.73962,2.23297,22.73962,22540,19
115.83080,-1.48534,-11.14148,1.45968,11.14148,22540,19
116.53920,-1.28842,-9.38455,1.26276,9.38455,22540,19
117.11180,-1.87250,-20.57427,1.84684,20.57427,22476,19
117.55380,-2.31475,-29.81955,2.28909,29.81955,22476,20
117.83920,-2.59968,-36.52313,2.57401,36.52313,22476,20
118.13080,-2.89174,-43.44498,2.86608,43.44498,22476,20
118.40180,-3.16292,-49.82153,3.13726,49.82153,22476,20
118.64180,-3.40272,-55.38469,3.37706,55.38469,22476,20
118.96880,-3.72959,-63.04791,3.70392,63.04791,22476,20
119.31080,-3.99837,-68.98817,3.97271,68.98817,22476,20
119.58680,-3.69776,-59.90362,3.67210,59.90362,22412,20
119.83280,-3.44823,-52.95629,3.42257,52.95629,22412,20
120.13920,-3.14169,-44.66878,3.11603,44.66877,22412,20
120.43280,-2.84755,-36.99077,2.82189,36.99077,22412,20
120.72780,-2.55249,-29.28703,2.52682,29.28703,22412,20
121.37580,-1.90451,-17.16221,1.87884,17.16221,22412,20
122.12180,-1.25904,-8.28124,1.23337,8.28124,22412,20
122.74080,-1.90350,-21.05148,1.87784,21.05148,22476,21
123.26280,-2.42570,-32.36520,2.40004,32.36520,22476,21
123.73080,-2.89394,-43.44309,2.86828,43.44309,22476,21
124.13920,-3.30202,-52.97724,3.27636,52.97724,22476,21
124.60080,-3.76382,-63.82738,3.73815,63.82738,22476,21
124.98780,-3.90414,-66.05047,3.87847,66.05047,22476,21
125.33480,-3.54327,-55.60682,3.51761,55.60682,22412,21
125.73920,-3.13781,-44.51413,3.11215,44.51413,22412,21
125.99580,-2.88070,-37.76683,2.85504,37.76683,22412,21
126.37780,-2.49859,-27.89008,2.47293,27.89008,22412,21
127.04180,-1.83468,-16.01987,1.80902,16.01987,22412,21
127.73920,-1.29548,-9.07788,1.26982,9.07788,22412,21
128.36780,-1.94465,-21.76924,1.91899,21.76925,22476,22
128.77780,-2.35503,-30.67833,2.32937,30.67833,22476,22
129.00279,-2.57995,-35.97608,2.55429,35.97608,22476,22
129.27080,-2.84803,-42.38719,2.82237,42.38719,22476,22
129.38880,-2.96604,-45.14922,2.94037,45.14922,22476,22
129.61380,-3.19127,-50.46219,3.16561,50.46219,22476,22
129.81680,-3.39404,-55.15348,3.36838,55.15348,22476,22
130.03780,-3.61497,-60.35984,3.58931,60.35984,22476,22
130.23180,-3.80890,-64.88990,3.78324,64.88990,22476,22
130.50580,-3.97877,-68.34313,3.95311,68.34312,22476,22
130.69780,-3.76774,-62.02397,3.74208,62.02397,22476,22
130.93880,-3.52126,-54.91885,3.49560,54.91885,22412,22
131.08780,-3.37134,-50.87478,3.34568,50.87478,22412,22
131.32380,-3.13497,-44.48932,3.10931,44.48932,22412,22
131.50180,-2.95676,-39.74831,2.93110,39.74831,22412,22
131.74080,-2.71782,-33.65902,2.69216,33.65902,22412,22
131.94580,-2.51278,-28.24048,2.48712,28.24048,22412,22
132.30880,-2.14984,-20.80379,2.12418,20.80379,22412,22
132.68780,-1.77094,-15.07077,1.74528,15.07077,22412,22
133.20880,-1.25000,-7.57203,1.22434,7.57203,22412,22
133.69680,-1.69464,-17.06901,1.66898,17.06901,22476,22
134.13919,-2.13809,-25.79395,2.11243,25.79395,22476,23
134.38580,-2.38492,-31.31994,2.35926,31.31994,22476,23
134.60680,-2.60614,-36.57056,2.58048,36.57056,22476,23
134.83920,-2.83821,-42.09729,2.81255,42.09729,22476,23
135.07080,-3.07018,-47.68413,3.04452,47.68413,22476,23
135.40080,-3.40014,-55.32073,3.37448,55.32073,22476,23
135.82680,-3.82603,-65.42021,3.80037,65.42021,22476,23
136.08780,-3.96955,-68.18568,3.94389,68.18568,22476,23
136.33920,-3.69837,-60.05782,3.67271,60.05782,22412,23
136.67680,-3.35644,-50.56445,3.33078,50.56445,22412,23
136.98680,-3.04591,-42.29264,3.02025,42.29264,22412,23
137.23920,-2.79405,-35.68857,2.76838,35.68857,22412,23
137.54080,-2.49189,-27.91002,2.46623,27.91002,22412,23
138.01580,-2.01696,-18.77024,1.99130,18.77024,22412,23
138.71580,-1.31692,-8.60658,1.29126,8.60658,22412,23
139.28678,-1.69698,-17.06017,1.67132,17.06017,22476,23
139.83080,-2.24242,-27.98966,2.21675,27.98966,22476,24
140.10380,-2.51529,-34.47639,2.48963,34.47639,22476,24
140.40180,-2.81344,-41.39256,2.78778,41.39256,22476,24
140.75280,-3.16465,-49.65927,3.13899,49.65927,22476,24
141.10480,-3.51639,-58.02004,3.49073,58.02003,22476,24
141.45180,-3.86331,-66.17650,3.83765,66.17651,22476,24
141.64080,-3.99378,-69.00091,3.96812,69.00091,22476,24
141.88180,-3.72890,-61.01210,3.70324,61.01210,22412,24
142.18380,-3.42191,-52.36644,3.39625,52.36644,22412,24
142.49480,-3.11028,-43.89098,3.08462,43.89098,22412,24
142.82180,-2.78331,-35.41762,2.75765,35.41762,22412,24
143.11180,-2.49313,-27.90241,2.46747,27.90240,22412,24
143.64780,-1.95709,-17.69255,1.93142,17.69255,22412,24
144.33920,-1.26640,-7.78050,1.24074,7.78050,22412,24
144.91080,-1.74755,-18.04598,1.72189,18.04598,22476,24
145.42980,-2.26765,-28.52484,2.24199,28.52484,22476,25
145.76080,-2.59851,-36.33048,2.57284,36.33048,22476,25
146.14380,-2.98155,-45.34034,2.95589,45.34034,22476,25
146.46880,-3.30665,-53.00222,3.28099,53.00222,22476,25
146.74680,-3.58456,-59.52665,3.55890,59.52665,22476,25
147.10780,-3.94540,-68.01064,3.91974,68.01064,22476,25
147.33680,-3.88806,-65.54046,3.86239,65.54047,22476,25
147.56680,-3.64742,-58.44279,3.62176,58.44279,22412,25
147.76180,-3.45006,-52.90716,3.42440,52.90716,22412,25
148.03920,-3.17254,-45.41063,3.14688,45.41063,22412,25
148.38580,-2.82537,-36.31107,2.79971,36.31107,22412,25
148.63378,-2.57731,-29.93319,2.55164,29.93319,22412,25
149.09680,-2.11430,-20.11481,2.08863,20.11481,22412,25
149.85180,-1.35934,-9.04297,1.33368,9.04296,22412,25
150.41178,-1.64563,-16.05365,1.61996,16.05365,22476,25
150.96880,-2.20478,-27.01198,2.17911,27.01198,22476,26
151.48680,-2.72274,-39.37139,2.69707,39.37140,22476,26
151.79780,-3.03375,-46.71362,3.00809,46.71362,22476,26
152.25878,-3.49473,-57.35262,3.46907,57.35262,22476,26
152.75180,-3.98757,-69.03426,3.96191,69.03426,22476,26
153.13919,-3.68824,-59.60133,3.66258,59.60133,22412,26
153.56478,-3.25880,-47.84459,3.23314,47.84459,22412,26
153.97780,-2.84556,-36.89088,2.81990,36.89088,22412,26
154.48980,-2.33356,-24.21505,2.30790,24.21505,22412,26
155.25780,-1.56532,-12.21666,1.53966,12.21666,22412,26
155.84580,-1.47270,-12.68019,1.44704,12.68019,22412,26
156.44180,-2.07564,-24.42545,2.04997,24.42545,22476,27
156.95680,-2.59077,-36.04937,2.56511,36.04937,22476,27
157.40780,-3.04187,-46.77349,3.01621,46.77349,22476,27
157.83920,-3.47274,-56.80435,3.44708,56.80435,22476,27
158.33080,-3.96463,-68.42688,3.93897,68.42688,22476,27
158.62880,-3.80871,-62.94650,3.78305,62.94650,22476,27
158.93978,-3.49066,-53.96120,3.46499,53.96120,22412,27
159.23580,-3.19379,-45.84419,3.16813,45.84419,22412,27
159.58180,-2.84767,-36.83002,2.82201,36.83002,22412,27
160.04480,-2.38460,-25.20098,2.35894,25.20098,22412,27
160.83280,-1.59654,-12.55471,1.57088,12.55471,22412,27
161.49180,-1.51455,-13.48555,1.48889,13.48555,22604,27
162.10580,-2.13395,-25.51900,2.10829,25.51900,22604,28
162.65880,-2.68699,-38.31569,2.66133,38.31569,22604,28
163.15180,-3.18024,-49.99318,3.15458,49.99318,22604,28
163.63919,-3.66686,-61.38839,3.64119,61.38839,22604,28
164.09780,-3.95134,-67.41758,3.92568,67.41759,22604,28
164.47380,-3.55738,-55.92884,3.53172,55.92884,22540,28
164.76080,-3.26908,-48.11638,3.24342,48.11638,22540,28
165.09680,-2.93280,-39.13186,2.90714,39.13186,22540,28
165.31980,-2.70974,-33.41815,2.68408,33.41814,22540,28
165.69580,-2.33382,-24.13327,2.30816,24.13327,22540,28
166.42880,-1.60070,-12.64579,1.57504,12.64579,22540,28
167.05080,-1.46181,-12.43606,1.43614,12.43606,22540,28
167.63919,-2.05706,-23.89450,2.03139,23.89450,22604,29
168.05178,-2.46989,-33.21215,2.44423,33.21215,22604,29
168.43780,-2.85627,-42.31305,2.83061,42.31305,22604,29
168.80178,-3.22037,-51.04697,3.19471,51.04697,22604,29
169.18978,-3.60811,-60.06142,3.58245,60.06142,22604,29
169.46180,-3.88009,-66.47355,3.85443,66.47355,22604,29
169.76780,-3.86835,-64.99809,3.84269,64.99809,22604,29
170.01680,-3.60929,-57.40843,3.58363,57.40842,22540,29
170.28780,-3.33624,-49.87203,3.31058,49.87203,22540,29
170.56880,-3.05477,-42.37068,3.02911,42.37069,22540,29
170.83920,-2.78494,-35.32377,2.75928,35.32376,22540,29
171.04380,-2.57981,-30.01565,2.55415,30.01565,22540,29
171.33920,-2.28502,-23.19573,2.25936,23.19573,22540,29
171.73980,-1.88391,-16.58864,1.85825,16.58864,22540,29
172.29180,-1.33180,-8.72136,1.30614,8.72136,22540,29
172.73920,-1.23625,-7.71924,1.21059,7.71924,22540,29
173.29780,-1.76425,-18.41000,1.73859,18.41000,22476,29
173.84278,-2.30974,-29.55386,2.28408,29.55386,22476,30
174.18978,-2.65674,-37.78830,2.63108,37.78830,22476,30
174.43919,-2.90569,-43.69986,2.88003,43.69986,22476,30
174.72380,-3.19093,-50.40453,3.16527,50.40453,22476,30
175.02980,-3.49667,-57.51389,3.47101,57.51389,22476,30
175.27680,-3.74353,-63.32723,3.71787,63.32723,22476,30
175.57880,-4.00292,-69.29272,3.97726,69.29272,22476,30
175.76180,-3.79918,-63.04530,3.77352,63.04530,22476,30
175.94880,-3.60595,-57.38094,3.58029,57.38094,22412,30
176.12880,-3.42411,-52.32416,3.39845,52.32416,22412,30
176.31180,-3.24071,-47.48695,3.21505,47.48695,22412,30
176.56280,-2.98935,-40.72701,2.96369,40.72701,22412,30
176.79080,-2.76152,-34.83866,2.73586,34.83866,22412,30
177.02480,-2.52742,-28.73951,2.50175,28.73951,22412,30
177.43580,-2.11641,-20.08975,2.09075,20.08975,22412,30
177.99380,-1.55830,-12.09521,1.53264,12.09521,22412,30
178.49380,-1.40763,-11.31988,1.38197,11.31988,22412,30
179.06180,-1.98646,-22.44788,1.96080,22.44788,22476,31
179.47080,-2.39561,-31.26545,2.36995,31.26545,22476,31
179.81780,-2.74288,-39.67358,2.71722,39.67358,22476,31
180.08780,-3.01281,-46.11051,2.98715,46.11051,22476,31
180.38080,-3.30596,-53.02313,3.28030,53.02312,22476,31
180.66280,-3.58781,-59.61080,3.56215,59.61079,22476,31
180.91080,-3.83576,-65.51445,3.81010,65.51444,22476,31
181.17180,-3.96577,-67.97487,3.94010,67.97487,22476,31
181.37180,-3.74861,-61.42274,3.72295,61.42274,22412,31
181.62180,-3.49367,-54.19603,3.46801,54.19603,22412,31
181.93919,-3.17573,-45.54664,3.15007,45.54664,22412,31
182.28780,-2.82659,-36.43955,2.80092,36.43955,22412,31
182.73680,-2.37754,-25.24721,2.35188,25.24721,22412,31
183.37380,-1.74064,-14.59690,1.71498,14.59690,22412,31
184.06180,-1.41414,-11.39368,1.38848,11.39368,22412,31
184.72080,-2.08371,-24.36624,2.05805,24.36624,22476,32
185.24578,-2.60900,-36.40289,2.58334,36.40289,22476,32
185.73920,-3.10195,-48.30533,3.07629,48.30533,22476,32
186.21180,-3.57491,-59.30053,3.54925,59.30053,22476,32
186.67380,-4.02929,-69.97892,4.00363,69.97891,22476,32
187.04880,-3.64257,-58.33034,3.61691,58.33034,22412,32
187.45478,-3.23393,-47.21070,3.20827,47.21070,22412,32
187.80178,-2.88673,-38.00462,2.86107,38.00462,22412,32
188.14380,-2.54462,-29.06601,2.51896,29.06601,22412,32
188.59380,-2.09459,-19.70283,2.06893,19.70283,22412,32
189.36080,-1.32761,-8.53840,1.30195,8.53839,22412,32
189.95880,-1.74685,-17.88094,1.72119,17.88094,22476,32
190.43919,-2.22801,-27.33476,2.20234,27.33476,22476,33
190.68380,-2.47281,-33.18457,2.44715,33.18457,22476,33
190.97180,-2.76108,-39.98670,2.73542,39.98669,22476,33
191.26580,-3.05500,-47.11232,3.02933,47.11232,22476,33
191.59780,-3.38699,-54.82794,3.36133,54.82793,22476,33
192.02280,-3.81190,-64.95334,3.78624,64.95334,22476,33
192.33080,-3.95178,-67.54056,3.92612,67.54056,22476,33
192.63919,-3.62637,-57.94975,3.60071,57.94975,22412,33
192.93919,-3.32408,-49.52312,3.29842,49.52312,22412,33
193.18978,-3.07264,-42.88657,3.04698,42.88657,22412,33
193.48180,-2.78087,-35.24823,2.75521,35.24823,22412,33
193.90580,-2.35678,-24.76186,2.33112,24.76186,22412,33
194.48380,-1.77883,-15.06974,1.75317,15.06974,22412,33
195.11880,-1.32517,-9.38204,1.29951,9.38204,22412,33
195.65780,-1.88261,-20.30354,1.85695,20.30354,22476,34
196.02880,-2.25412,-27.91199,2.22846,27.91199,22476,34
196.34580,-2.57113,-35.47242,2.54547,35.47242,22476,34
196.63180,-2.85719,-42.25666,2.83153,42.25666,22476,34
196.95080,-3.17627,-49.90812,3.15060,49.90812,22476,34
197.22180,-3.44705,-56.35528,3.42139,56.35528,22476,34
197.40780,-3.63303,-60.64473,3.60737,60.64473,22476,34
197.64380,-3.86894,-66.23178,3.84327,66.23178,22476,34
197.88180,-3.95190,-67.52779,3.92624,67.52779,22476,34
198.13780,-3.67867,-59.44598,3.65301,59.44598,22412,34
198.40880,-3.40448,-51.73300,3.37882,51.73300,22412,34
198.69980,-3.11291,-43.95153,3.08725,43.95153,22412,34
198.91680,-2.89594,-38.31468,2.87028,38.31468,22412,34
199.18580,-2.62693,-31.28112,2.60127,31.28112,22412,34
199.43919,-2.37388,-25.19710,2.34822,25.19710,22412,34
200.03920,-1.77396,-14.94924,1.74830,14.94924,22412,34
200.59180,-1.24850,-7.44278,1.22284,7.44278,22412,34
201.18280,-1.86559,-20.03021,1.83993,20.03021,22476,35
201.53920,-2.22220,-27.29259,2.19654,27.29259,22476,35
201.73920,-2.42202,-31.89179,2.39636,31.89178,22476,35
201.99280,-2.67623,-38.04075,2.65057,38.04075,22476,35
202.21180,-2.89525,-43.34548,2.86959,43.34549,22476,35
202.36080,-3.04421,-46.84932,3.01855,46.84932,22476,35
202.52080,-3.20442,-50.60566,3.17876,50.60566,22476,35
202.70180,-3.38522,-54.82746,3.35956,54.82746,22476,35
202.89180,-3.57518,-59.28429,3.54952,59.28429,22476,35
203.04080,-3.72406,-62.88818,3.69840,62.88818,22476,35
203.23920,-3.92208,-67.49449,3.89642,67.49449,22476,35
203.43180,-3.93827,-67.19007,3.91261,67.19007,22476,35
203.63280,-3.72305,-60.77643,3.69738,60.77643,22476,35
203.78180,-3.57081,-56.45541,3.54515,56.45541,22412,35
203.97780,-3.37343,-50.99444,3.34777,50.99444,22412,35
204.11480,-3.23613,-47.39315,3.21047,47.39315,22412,35
204.29980,-3.05079,-42.35336,3.02513,42.35336,22412,35
204.41780,-2.93289,-39.28398,2.90723,39.28398,22412,35
204.59380,-2.75699,-34.70483,2.73133,34.70483,22412,35
204.75180,-2.59888,-30.66853,2.57322,30.66853,22412,35
204.93080,-2.41976,-26.28601,2.39410,26.28601,22412,35
205.16780,-2.18291,-21.26073,2.15725,21.26073,22412,35
205.43919,-1.91184,-16.94042,1.88618,16.94042,22412,35
205.81180,-1.53884,-11.72863,1.51318,11.72863,22412,35
206.15480,-1.28966,-8.36315,1.26400,8.36315,22412,35
206.51780,-1.67720,-16.38678,1.65154,16.38678,22476,35
206.77480,-1.93580,-21.47949,1.91013,21.47949,22476,36
206.98880,-2.15026,-25.80134,2.12460,25.80134,22476,36
207.10480,-2.26630,-28.32343,2.24064,28.32343,22476,36
207.20680,-2.36825,-30.64887,2.34259,30.64887,22476,36
207.30178,-2.46301,-32.93291,2.43735,32.93291,22476,36
207.39980,-2.56129,-35.25767,2.53562,35.25767,22476,36
207.48880,-2.65032,-37.36353,2.62466,37.36353,22476,36
207.56880,-2.73029,-39.34339,2.70463,39.34339,22476,36
207.64680,-2.80831,-41.14718,2.78265,41.14717,22476,36
207.72080,-2.88232,-42.96710,2.85666,42.96709,22476,36
207.78678,-2.94829,-44.55502,2.92263,44.55502,22476,36
207.85180,-3.01320,-46.14815,2.98754,46.14816,22476,36
207.92080,-3.08230,-47.88370,3.05664,47.88370,22476,36
208.01780,-3.17950,-49.98570,3.15383,49.98570,22476,36
208.12180,-3.28344,-52.46693,3.25778,52.46693,22476,36
208.20780,-3.36928,-54.51103,3.34362,54.51102,22476,36
208.28980,-3.45122,-56.43710,3.42556,56.43710,22476,36
208.36780,-3.52934,-58.20019,3.50368,58.20019,22476,36
208.43080,-3.59223,-59.73812,3.56657,59.73812,22476,36
208.51480,-3.67611,-61.80863,3.65044,61.80864,22476,36
208.60180,-3.76322,-63.83321,3.73755,63.83321,22476,36
208.68880,-3.85018,-65.88189,3.82452,65.88189,22476,36
208.79580,-3.95711,-68.32555,3.93145,68.32555,22476,36
208.87980,-4.00755,-69.54641,3.98189,69.54641,22476,36
208.98180,-3.89230,-65.86415,3.86663,65.86415,22476,36
209.07780,-3.78924,-62.77221,3.76358,62.77221,22476,36
209.15980,-3.70372,-60.28187,3.67806,60.28187,22412,36
209.26880,-3.59233,-57.08567,3.56666,57.08567,22412,36
209.34780,-3.51243,-54.81242,3.48677,54.81242,22412,36
209.45780,-3.40166,-51.86339,3.37599,51.86340,22412,36
209.60580,-3.25333,-47.87259,3.22767,47.87259,22412,36
209.73680,-3.12214,-44.24879,3.09648,44.24879,22412,36
209.83178,-3.02697,-41.76711,3.00131,41.76711,22412,36
209.92080,-2.93802,-39.41609,2.91236,39.41609,22412,36
210.03920,-2.82001,-36.33765,2.79435,36.33765,22412,36
210.19178,-2.66707,-32.39626,2.64141,32.39626,22412,36
210.31880,-2.53998,-29.20602,2.51432,29.20602,22412,36
210.48278,-2.37601,-25.34219,2.35035,25.34219,22412,36
210.69780,-2.16105,-20.83964,2.13539,20.83964,22412,36
211.05980,-1.79906,-15.23679,1.77340,15.23679,22412,36
211.51780,-1.34097,-8.64041,1.31531,8.64041,22412,36
211.90980,-1.54427,-13.77170,1.51861,13.77170,22476,36
212.26980,-1.90885,-20.94301,1.88319,20.94301,22476,37
212.59180,-2.23134,-27.49044,2.20568,27.49044,22476,37
212.77180,-2.41111,-31.62730,2.38545,31.62730,22476,37
212.94480,-2.58434,-35.85894,2.55868,35.85894,22476,37
213.13780,-2.77739,-40.37642,2.75173,40.37643,22476,37
213.26380,-2.90335,-43.54269,2.87769,43.54269,22476,37
213.45280,-3.09235,-48.10424,3.06668,48.10424,22476,37
213.63919,-3.27849,-52.35745,3.25283,52.35744,22476,37
213.78180,-3.42131,-55.70699,3.39565,55.70699,22476,37
213.97080,-3.61025,-60.15462,3.58459,60.15462,22476,37
214.13880,-3.77827,-64.18610,3.75261,64.18610,22476,37
214.25680,-3.89616,-67.03042,3.87050,67.03043,22476,37
214.38980,-4.01353,-69.70712,3.98787,69.70712,22476,37
214.50580,-3.89020,-65.82368,3.86454,65.82368,22476,37
214.63919,-3.74851,-61.67592,3.72285,61.67593,22476,37
214.71380,-3.67093,-59.37287,3.64527,59.37287,22412,37
214.81980,-3.56304,-56.36333,3.53738,56.36333,22412,37
214.96880,-3.41278,-52.14490,3.38712,52.14490,22412,37
215.08980,-3.29145,-48.87908,3.26579,48.87908,22412,37
215.23980,-3.14128,-44.78778,3.11562,44.78778,22412,37
215.36980,-3.01108,-41.36499,2.98542,41.36499,22412,37
215.50878,-2.87216,-37.74530,2.84650,37.74530,22412,37
215.64380,-2.73717,-34.31563,2.71150,34.31563,22412,37
215.83178,-2.54905,-29.40863,2.52339,29.40863,22412,37
216.03920,-2.34214,-24.58465,2.31647,24.58465,22412,37
216.33919,-2.04206,-18.77339,2.01639,18.77339,22412,37
216.73920,-1.64220,-12.96596,1.61654,12.96596,22412,37
217.23920,-1.33421,-9.41193,1.30855,9.41193,22412,37
217.85180,-1.96503,-22.09734,1.93937,22.09734,22604,37
218.30880,-2.42229,-31.86970,2.39663,31.86970,22604,38
218.53980,-2.65354,-37.44141,2.62788,37.44141,22604,38
218.78180,-2.89547,-43.22217,2.86981,43.22217,22604,38
219.10580,-3.21962,-50.99472,3.19396,50.99472,22604,38
219.38680,-3.50046,-57.62490,3.47480,57.62490,22604,38
219.62180,-3.73533,-63.26491,3.70967,63.26491,22604,38
219.83919,-3.95226,-68.41236,3.92659,68.41235,22604,38
220.08580,-3.82362,-63.97425,3.79796,63.97425,22604,38
220.23180,-3.67115,-59.52767,3.64548,59.52767,22540,38
220.50780,-3.39186,-51.66754,3.36620,51.66755,22540,38
220.67780,-3.22146,-47.16942,3.19579,47.16942,22540,38
220.94680,-2.95220,-39.86049,2.92654,39.86049,22540,38
221.19980,-2.69921,-33.44648,2.67355,33.44648,22540,38
221.57580,-2.32328,-24.33177,2.29762,24.33177,22540,38
222.29580,-1.60317,-12.56459,1.57751,12.56459,22540,38
222.94580,-1.53021,-13.57735,1.50455,13.57735,22540,38
223.54380,-2.13356,-25.39372,2.10790,25.39372,22604,39
223.97780,-2.56767,-35.41308,2.54201,35.41308,22604,39
224.40380,-2.99352,-45.45186,2.96786,45.45187,22604,39
224.84180,-3.43154,-55.97571,3.40588,55.97570,22604,39
225.22580,-3.81544,-65.19803,3.78978,65.19803,22604,39
225.50980,-3.94440,-67.66007,3.91874,67.66007,22604,39
225.78678,-3.64970,-58.89920,3.62403,58.89920,22540,39
226.08980,-3.34374,-50.43727,3.31808,50.43727,22540,39
226.44980,-2.98326,-40.66528,2.95760,40.66528,22540,39
226.76380,-2.66940,-32.68965,2.64374,32.68965,22540,39
227.11280,-2.32042,-24.28380,2.29475,24.28380,22540,39
227.71778,-1.71539,-14.01942,1.68973,14.01942,22540,39
228.53380,-1.25672,-7.79583,1.23106,7.79583,22540,39
229.06580,-1.75262,-17.95124,1.72695,17.95123,22476,39
229.53678,-2.22421,-27.30696,2.19855,27.30696,22476,40
229.83178,-2.51918,-34.38821,2.49352,34.38821,22476,40
230.16378,-2.85115,-42.25705,2.82549,42.25705,22476,40
230.48780,-3.17543,-49.95967,3.14977,49.95967,22476,40
230.90680,-3.59416,-59.98148,3.56850,59.98148,22476,40
231.23920,-3.92604,-67.97953,3.90038,67.97953,22476,40
231.54380,-3.79763,-63.45218,3.77197,63.45218,22476,40
231.87180,-3.46181,-53.75339,3.43615,53.75340,22412,40
232.14680,-3.18614,-46.32208,3.16048,46.32208,22412,40
232.45980,-2.87300,-38.09319,2.84734,38.09319,22412,40
232.68380,-2.64900,-32.22305,2.62334,32.22305,22412,40
233.05980,-2.27312,-23.41122,2.24746,23.41122,22412,40
233.74980,-1.58284,-12.28784,1.55718,12.28784,22412,40
234.23920,-1.40159,-10.88150,1.37593,10.88150,22412,40
234.80780,-1.98296,-22.43078,1.95730,22.43078,22476,41
235.24480,-2.42024,-31.78150,2.39458,31.78150,22476,41
235.50680,-2.68238,-38.17883,2.65672,38.17883,22476,41
235.71180,-2.88736,-43.04725,2.86170,43.04725,22476,41
235.91880,-3.09435,-48.06777,3.06869,48.06778,22476,41
236.10280,-3.27846,-52.33660,3.25280,52.33660,22476,41
236.43978,-3.61531,-60.40642,3.58965,60.40642,22476,41
236.66780,-3.84318,-65.93794,3.81752,65.93794,22476,41
236.98278,-3.83836,-64.67387,3.81270,64.67387,22476,41
237.15078,-3.66206,-59.46950,3.63640,59.46950,22412,41
237.36480,-3.44482,-53.25255,3.41916,53.25255,22412,41
237.56280,-3.24635,-47.97662,3.22069,47.97662,22412,41
237.79880,-3.00995,-41.62952,2.98429,41.62952,22412,41
237.94178,-2.86704,-37.94764,2.84138,37.94764,22412,41
238.13578,-2.67301,-32.93500,2.64735,32.93501,22412,41
238.33280,-2.47584,-27.88405,2.45018,27.88405,22412,41
238.70580,-2.10294,-19.95802,2.07728,19.95802,22412,41
239.14380,-1.66508,-13.30348,1.63942,13.30348,22412,41
239.68380,-1.36149,-10.05076,1.33583,10.05076,22412,41
240.18880,-1.88180,-20.38832,1.85614,20.38832,22476,42
240.58480,-2.27842,-28.47232,2.25276,28.47232,22476,42
240.78380,-2.47713,-33.26578,2.45147,33.26578,22476,42
241.09580,-2.78938,-40.68865,2.76372,40.68864,22476,42
241.33580,-3.02931,-46.41735,3.00365,46.41735,22476,42
241.54480,-3.23849,-51.42704,3.21283,51.42704,22476,42
241.86280,-3.55634,-58.89611,3.53068,58.89611,22476,42
242.27778,-3.97112,-68.95414,3.94546,68.95414,22476,42
242.54980,-3.76466,-62.45992,3.73900,62.45992,22476,42
242.73680,-3.57220,-56.86265,3.54654,56.86265,22412,42
243.00878,-3.29841,-49.29666,3.27275,49.29666,22412,42
243.22780,-3.07899,-43.43782,3.05333,43.43782,22412,42
243.47780,-2.82907,-36.85780,2.80341,36.85780,22412,42
243.63919,-2.66809,-32.75677,2.64243,32.75677,22412,42
243.97080,-2.33608,-24.76370,2.31042,24.76370,22412,42
244.33080,-1.97596,-17.72412,1.95030,17.72412,22412,42
244.78878,-1.51800,-11.23020,1.49234,11.23020,22412,42
245.23920,-1.40890,-11.09700,1.38324,11.09700,22412,42
245.80980,-1.99105,-22.49218,1.96539,22.49218,22476,43
246.13980,-2.32133,-29.42217,2.29567,29.42217,22476,43
246.47780,-2.65949,-37.54940,2.63383,37.54940,22476,43
246.73920,-2.92049,-43.80158,2.89483,43.80157,22476,43
247.08380,-3.26557,-51.97595,3.23991,51.97595,22476,43
247.43078,-3.61236,-60.25884,3.58669,60.25883,22476,43
247.85180,-4.00946,-69.90225,3.98380,69.90225,22476,43
248.20380,-3.63427,-58.55788,3.60861,58.55788,22412,43
248.53920,-3.29653,-49.14711,3.27087,49.14711,22412,43
248.83280,-3.00212,-41.33651,2.97646,41.33651,22412,43
249.08380,-2.75123,-34.86581,2.72557,34.86581,22412,43
249.29880,-2.53613,-29.36659,2.51047,29.36659,22412,43
249.68780,-2.14720,-20.84999,2.12154,20.84999,22412,43
250.23920,-1.59612,-12.36945,1.57045,12.36945,22412,43
250.85880,-1.50616,-13.02596,1.48050,13.02596,22412,43
251.49978,-2.15352,-25.74421,2.12786,25.74421,22476,44
251.85880,-2.51235,-34.07313,2.48669,34.07312,22476,44
252.15078,-2.80458,-40.98125,2.77892,40.98125,22476,44
252.57978,-3.23366,-51.30919,3.20799,51.30919,22476,44
252.89878,-3.55251,-58.80193,3.52685,58.80193,22476,44
253.23080,-3.88442,-66.86337,3.85876,66.86337,22476,44
253.53580,-3.81563,-63.93867,3.78997,63.93867,22476,44
253.78980,-3.55314,-56.34930,3.52748,56.34930,22412,44
254.03920,-3.30256,-49.42389,3.27690,49.42389,22412,44
254.32380,-3.01717,-41.84184,2.99151,41.84184,22412,44
254.57880,-2.76227,-35.16877,2.73661,35.16877,22412,44
254.88980,-2.45102,-27.29665,2.42536,27.29665,22412,44
255.44580,-1.89520,-16.59874,1.86954,16.59874,22412,44
256.15680,-1.28684,-8.29333,1.26118,8.29333,22412,44
256.70880,-1.86396,-19.98032,1.83830,19.98032,22476,45
257.27180,-2.42746,-31.93970,2.40180,31.93970,22476,45
257.64178,-2.79768,-40.71280,2.77202,40.71280,22476,45
258.03378,-3.18977,-50.23424,3.16411,50.23424,22476,45
258.37580,-3.53161,-58.28383,3.50595,58.28383,22476,45
258.74780,-3.90343,-67.25557,3.87777,67.25557,22476,45
259.02578,-3.83884,-64.50285,3.81318,64.50285,22476,45
259.40478,-3.44912,-53.25411,3.42346,53.25410,22412,45
259.73178,-3.12141,-44.41713,3.09575,44.41713,22412,45
260.03580,-2.81735,-36.38423,2.79169,36.38423,22412,45
260.24180,-2.61133,-31.18110,2.58567,31.18110,22412,45
260.66480,-2.18835,-21.60071,2.16269,21.60071,22412,45
261.41678,-1.43617,-10.01375,1.41050,10.01375,22412,45
262.02780,-1.68973,-16.53474,1.66407,16.53474,22476,45
262.63919,-2.30262,-28.92615,2.27696,28.92615,22476,46
262.96878,-2.63273,-36.91821,2.60707,36.91821,22476,46
263.33919,-3.00266,-45.57559,2.97699,45.57559,22476,46
263.69981,-3.36365,-54.19250,3.33799,54.19250,22476,46
263.93578,-3.59966,-59.88313,3.57400,59.88313,22476,46
264.23919,-3.90259,-67.22040,3.87693,67.22040,22476,46
264.50478,-3.86141,-65.08807,3.83575,65.08807,22476,46
264.69778,-3.65908,-59.12605,3.63342,59.12605,22412,46
264.85378,-3.50077,-54.66817,3.47511,54.66817,22412,46
265.07678,-3.27684,-48.61933,3.25118,48.61933,22412,46
265.25078,-3.10249,-43.88220,3.07683,43.88220,22412,46
265.46978,-2.88353,-38.22989,2.85787,38.22989,22412,46
265.67481,-2.67853,-32.81869,2.65287,32.81869,22412,46
265.90878,-2.44432,-26.97865,2.41866,26.97865,22412,46
266.18281,-2.17052,-21.21232,2.14485,21.21232,22412,46
266.61781,-1.73561,-14.25503,1.70994,14.25503,22412,46
267.06078,-1.29256,-7.81362,1.26690,7.81362,22412,46
267.49381,-1.66342,-15.99806,1.63775,15.99806,22476,46
267.81578,-1.98737,-22.46268,1.96170,22.46268,22476,47
268.07778,-2.24988,-27.82271,2.22422,27.82271,22476,47
268.29778,-2.46964,-33.00666,2.44398,33.00666,22476,47
268.54881,-2.72080,-38.97377,2.69514,38.97377,22476,47
268.82581,-2.99779,-45.49791,2.97213,45.49791,22476,47
269.20578,-3.37782,-54.48613,3.35216,54.48613,22476,47
269.51278,-3.68468,-61.99772,3.65901,61.99772,22476,47
269.87378,-4.00120,-69.30177,3.97554,69.30177,22476,47
270.09478,-3.75747,-61.97246,3.73181,61.97246,22412,47
270.41581,-3.43029,-52.56554,3.40463,52.56554,22412,47
270.70278,-3.14279,-44.78141,3.11713,44.78141,22412,47
270.99078,-2.85463,-37.29423,2.82897,37.29423,22412,47
271.23919,-2.60662,-30.86622,2.58095,30.86622,22412,47
271.65878,-2.18664,-21.40228,2.16098,21.40228,22412,47
272.21681,-1.62869,-12.78109,1.60303,12.78109,22412,47
272.71878,-1.38834,-10.49441,1.36268,10.49441,22412,47
273.23919,-1.92245,-21.12739,1.89679,21.12739,22604,47
273.76581,-2.44984,-32.38356,2.42418,32.38356,22604,48
274.16378,-2.84798,-41.78749,2.82232,41.78749,22604,48
274.56378,-3.24814,-51.45849,3.22248,51.45849,22604,48
275.01981,-3.70378,-62.38469,3.67812,62.38469,22604,48
275.49281,-3.87802,-65.43459,3.85236,65.43459,22604,48
275.91981,-3.43847,-52.80900,3.41281,52.80900,22540,48
276.33781,-3.01976,-41.56925,2.99410,41.56925,22540,48
276.69778,-2.65985,-32.23007,2.63418,32.23007,22540,48
277.07778,-2.27997,-23.33137,2.25431,23.33137,22540,48
277.73919,-1.61887,-12.62749,1.59321,12.62749,22540,48
278.40978,-1.56340,-13.99610,1.53774,13.99610,22604,48
278.93178,-2.08997,-24.43470,2.06431,24.43470,22604,49
279.28378,-2.44202,-32.24501,2.41636,32.24501,22604,49
279.61481,-2.77328,-40.06368,2.74762,40.06368,22604,49
279.98278,-3.14135,-48.90219,3.11568,48.90219,22604,49
280.40378,-3.56218,-58.93911,3.53652,58.93911,22604,49
280.73919,-3.89704,-66.96985,3.87138,66.96985,22604,49
281.06578,-3.77828,-62.65415,3.75261,62.65415,22604,49
281.30478,-3.53260,-55.50864,3.50694,55.50864,22540,49
281.71281,-3.12300,-44.30894,3.09733,44.30894,22540,49
282.14578,-2.68988,-33.09157,2.66422,33.09158,22540,49
282.54081,-2.29498,-23.65626,2.26932,23.65626,22540,49
283.32181,-1.51381,-11.10994,1.48815,11.10994,22540,49
284.06778,-1.29530,-8.88979,1.26964,8.88978,22540,49
284.66778,-1.90757,-21.04292,1.88191,21.04292,22476,49
285.20178,-2.44164,-32.46629,2.41598,32.46629,22476,50
285.68578,-2.92586,-43.91216,2.90019,43.91216,22476,50
286.10778,-3.34778,-53.89162,3.32212,53.89162,22476,50
286.59281,-3.83267,-65.50318,3.80701,65.50318,22476,50
286.99878,-3.80940,-63.47154,3.78374,63.47154,22476,50
287.38181,-3.41826,-52.32226,3.39260,52.32226,22412,50
287.71578,-3.08356,-43.29790,3.05790,43.29790,22412,50
287.97778,-2.82169,-36.40782,2.79603,36.40782,22412,50
288.26578,-2.53363,-29.11893,2.50796,29.11893,22412,50
288.80381,-1.99559,-17.97942,1.96993,17.97942,22412,50
289.44778,-1.35165,-8.72805,1.32598,8.72805,22412,50
290.03778,-1.72865,-17.33735,1.70299,17.33735,22476,50
290.58478,-2.27713,-28.54223,2.25147,28.54223,22476,51
291.03919,-2.73112,-39.21946,2.70545,39.21946,22476,51
291.37078,-3.06302,-47.17220,3.03736,47.17220,22476,51
291.73678,-3.42901,-55.79392,3.40335,55.79392,22476,51
292.13919,-3.83096,-65.35297,3.80530,65.35297,22476,51
292.54778,-3.80851,-63.40775,3.78285,63.40775,22476,51
292.84978,-3.49903,-54.43620,3.47337,54.43620,22412,51
293.27578,-3.07174,-42.92328,3.04608,42.92328,22412,51
293.65878,-2.68886,-32.95850,2.66320,32.95850,22412,51
294.13919,-2.20888,-21.83702,2.18322,21.83702,22412,51
294.93681,-1.41082,-9.61076,1.38516,9.61076,22412,51
295.53919,-1.70140,-16.75498,1.67574,16.75498,22476,51
296.15378,-2.31804,-29.38771,2.29238,29.38771,22476,52
296.57878,-2.74318,-39.44442,2.71752,39.44442,22476,52
296.99781,-3.16237,-49.41796,3.13671,49.41796,22476,52
297.38081,-3.54519,-58.54598,3.51953,58.54598,22476,52
297.72981,-3.89398,-66.82963,3.86832,66.82963,22476,52
298.07878,-3.81363,-63.40802,3.78797,63.40802,22476,52
298.38678,-3.49806,-54.38197,3.47240,54.38197,22412,52
298.71478,-3.16911,-45.40019,3.14345,45.40019,22412,52
299.11381,-2.77002,-35.05214,2.74436,35.05214,22412,52
299.56378,-2.31997,-24.12295,2.29431,24.12295,22412,52
300.22378,-1.66002,-13.11861,1.63436,13.11861,22412,52
300.83178,-1.42176,-11.37906,1.39610,11.37906,22412,52
301.46781,-2.06809,-24.05490,2.04243,24.05490,22476,53
301.83919,-2.43915,-32.23346,2.41348,32.23346,22476,53
302.10981,-2.71030,-38.77727,2.68464,38.77727,22476,53
302.39278,-2.99325,-45.33986,2.96759,45.33986,22476,53
302.63778,-3.23846,-51.30063,3.21280,51.30063,22476,53
302.82081,-3.42126,-55.69449,3.39560,55.69450,22476,53
303.04981,-3.65014,-61.11936,3.62447,61.11936,22476,53
303.29678,-3.89712,-66.96405,3.87146,66.96405,22476,53
303.53919,-3.89879,-66.03692,3.87312,66.03693,22476,53
303.76981,-3.65544,-58.90010,3.62977,58.90010,22412,53
303.97981,-3.44272,-52.95629,3.41706,52.95629,22412,53
304.28281,-3.13913,-44.71103,3.11347,44.71103,22412,53
304.53778,-2.88404,-38.08439,2.85838,38.08439,22412,53
304.81978,-2.60196,-30.79230,2.57630,30.79230,22412,53
305.05978,-2.36199,-25.08926,2.33633,25.08926,22412,53
305.42178,-1.99994,-18.08160,1.97428,18.08160,22412,53
305.93578,-1.48585,-10.71749,1.46019,10.71749,22412,53
306.40978,-1.48877,-12.57533,1.46311,12.57533,22412,53
306.95278,-2.03912,-23.51190,2.01346,23.51190,22476,54
307.33978,-2.42617,-31.88174,2.40051,31.88174,22476,54
307.77978,-2.86637,-42.33945,2.84071,42.33945,22476,54
308.20081,-3.28749,-52.41128,3.26183,52.41128,22476,54
308.53919,-3.62522,-60.54416,3.59955,60.54416,22476,54
308.96978,-4.00783,-69.54306,3.98217,69.54306,22476,54
309.29581,-3.65543,-58.88187,3.62977,58.88187,22412,54
309.56281,-3.38567,-51.40615,3.36001,51.40615,22412,54
309.84078,-3.10713,-43.89748,3.08147,43.89748,22412,54
310.17881,-2.76917,-35.04313,2.74351,35.04313,22412,54
310.57878,-2.36909,-25.28068,2.34343,25.28068,22412,54
311.20778,-1.74018,-14.26193,1.71452,14.26193,22412,54
311.90578,-1.45728,-12.00570,1.43162,12.00570,22412,54
312.50778,-2.06826,-24.01472,2.04260,24.01472,22476,55
313.01178,-2.57249,-35.42953,2.54683,35.42953,22476,55
313.45481,-3.01543,-45.87634,2.98977,45.87634,22476,55
313.90578,-3.46642,-56.79314,3.44076,56.79314,22476,55
314.22378,-3.78442,-64.32984,3.75876,64.32984,22476,55
314.49578,-3.99787,-69.23631,3.97221,69.23631,22476,55
314.73919,-3.73077,-61.11570,3.70511,61.11570,22476,55
314.94778,-3.51759,-55.01133,3.49193,55.01133,22412,55
315.22981,-3.23444,-47.40670,3.20878,47.40670,22412,55
315.41378,-3.05011,-42.41502,3.02445,42.41502,22412,55
315.65978,-2.80422,-35.97372,2.77856,35.97372,22412,55
315.95481,-2.50913,-28.41846,2.48347,28.41846,22412,55
316.44981,-2.01414,-18.29093,1.98848,18.29093,22412,55
317.23778,-1.25697,-7.38510,1.23131,7.38510,22412,55
317.80078,-1.84680,-19.53290,1.82114,19.53290,22476,55
318.29278,-2.33931,-29.96348,2.31365,29.96348,22476,56
318.71878,-2.76556,-39.96671,2.73990,39.96671,22476,56
319.19778,-3.24470,-51.49047,3.21904,51.49047,22476,56
319.56978,-3.61644,-60.41341,3.59078,60.41341,22476,56
319.92178,-3.96831,-68.73208,3.94265,68.73208,22476,56
320.22378,-3.74676,-61.72952,3.72110,61.72952,22476,56
320.43919,-3.52681,-55.40401,3.50115,55.40401,22412,56
320.80578,-3.15843,-45.23382,3.13277,45.23382,22412,56
321.13878,-2.82526,-36.54853,2.79959,36.54853,22412,56
321.53919,-2.42511,-26.61029,2.39945,26.61029,22412,56
322.18781,-1.77633,-14.75528,1.75067,14.75528,22412,56
322.76778,-1.32326,-8.85019,1.29760,8.85019,22412,56
323.32081,-1.89904,-20.45466,1.87338,20.45466,22476,57
323.65078,-2.22947,-27.53353,2.20381,27.53353,22476,57
323.92178,-2.50057,-33.87470,2.47490,33.87470,22476,57
324.19278,-2.77172,-40.26375,2.74606,40.26375,22476,57
324.47378,-3.05266,-47.03462,3.02700,47.03463,22476,57
324.79278,-3.37165,-54.39056,3.34599,54.39056,22476,57
325.22581,-3.80456,-64.84140,3.77890,64.84141,22476,57
325.63278,-3.82944,-64.05456,3.80378,64.05457,22476,57
325.93578,-3.51769,-54.96050,3.49203,54.96050,22412,57
326.28181,-3.17049,-45.50011,3.14483,45.50011,22412,57
326.62578,-2.82632,-36.55876,2.80066,36.55876,22412,57
326.97681,-2.47518,-27.56108,2.44952,27.56108,22412,57
327.65378,-1.79837,-15.04594,1.77271,15.04594,22412,57
328.29481,-1.33863,-9.29461,1.31297,9.29461,22412,57
328.92381,-1.98619,-22.41783,1.96052,22.41783,22604,58
329.39778,-2.46047,-32.82731,2.43481,32.82731,22604,58
329.72278,-2.78565,-40.49981,2.75999,40.49981,22604,58
330.06281,-3.12577,-48.67458,3.10011,48.67458,22604,58
330.54481,-3.60758,-60.03854,3.58192,60.03854,22604,58
331.00878,-3.99590,-68.99910,3.97024,68.99911,22604,58
331.33919,-3.64026,-58.36630,3.61460,58.36630,22540,58
331.78878,-3.18746,-45.99525,3.16180,45.99525,22540,58
332.23919,-2.73731,-34.19086,2.71165,34.19086,22540,58
332.73919,-2.23738,-22.41497,2.21171,22.41497,22540,58
333.42678,-1.54913,-11.57647,1.52347,11.57647,22540,58
333.98278,-1.52330,-13.15633,1.49764,13.15633,22604,58
334.49178,-2.03832,-23.42752,2.01266,23.42752,22604,59
334.97478,-2.52157,-34.34468,2.49590,34.34468,22604,59
335.23919,-2.78569,-40.43331,2.76003,40.43331,22604,59
335.50078,-3.04761,-46.73788,3.02195,46.73788,22604,59
335.75878,-3.30570,-52.84806,3.28004,52.84806,22604,59
335.97078,-3.51762,-57.93170,3.49196,57.93170,22604,59
336.23378,-3.78046,-64.19598,3.75480,64.19598,22604,59
336.44378,-3.99045,-69.22672,3.96479,69.22672,22604,59
336.70378,-3.77996,-62.59537,3.75430,62.59538,22604,59
336.94278,-3.53483,-55.52654,3.50917,55.52654,22540,59
337.24978,-3.22647,-47.21212,3.20081,47.21212,22540,59
337.47078,-3.00518,-41.16514,2.97952,41.16513,22540,59
337.70178,-2.77431,-35.21317,2.74865,35.21317,22540,59
337.90781,-2.56818,-29.95279,2.54252,29.95279,22540,59
338.19981,-2.27640,-23.26199,2.25074,23.26199,22540,59
338.37178,-2.10417,-19.74602,2.07851,19.74602,22540,59
338.62478,-1.85128,-15.81554,1.82562,15.81554,22540,59
338.94778,-1.52815,-11.23988,1.50249,11.23987,22540,59
339.15878,-1.31720,-8.12399,1.29154,8.12399,22540,59
339.24978,-1.25721,-7.31321,1.23155,7.31321,22540,59