File: data-raw/Experiment 2/Results/INSTRON data/Experiment 2.is_ccyclic_RawData/Specimen_RawData_22.csv
Text Inputs : Specimen label,"Short Plate 6 T1"

Time,Extension,Load,Compressive extension,Compressive load,Segment ID,Total Cycle Count
(sec),(mm),(N),(mm),(N),,
0.00000,-0.02554,0.04036,0.00000,-0.04036,12835,0
0.76520,-0.02554,0.06570,0.00000,-0.06570,12835,0
1.23680,-0.14201,0.07029,0.11647,-0.07029,3220,0
2.06520,-0.55804,-4.97880,0.53250,4.97880,3220,0
2.68880,-1.04423,-11.70483,1.01869,11.70483,22476,0
3.38480,-1.74127,-19.83556,1.71573,19.83556,22476,0
3.98380,-2.34031,-28.04043,2.31477,28.04043,22476,0
4.54880,-2.90531,-37.17038,2.87977,37.17038,22476,0
4.94480,-3.30128,-43.54249,3.27574,43.54249,22476,0
5.45480,-3.81121,-51.61797,3.78567,51.61797,22476,0
6.02980,-4.38637,-60.14831,4.36083,60.14832,22476,0
6.56520,-4.92124,-67.87696,4.89570,67.87697,22476,0
6.93480,-4.82048,-63.22063,4.79494,63.22063,22476,0
7.34080,-4.40755,-53.76824,4.38201,53.76824,22412,0
7.73780,-4.01010,-45.41732,3.98456,45.41732,22412,0
8.22180,-3.52596,-36.23151,3.50042,36.23151,22412,0
8.57980,-3.16785,-29.68766,3.14231,29.68766,22412,0
9.16580,-2.58186,-21.09413,2.55632,21.09413,22412,0
9.88780,-1.86003,-13.05618,1.83449,13.05618,22412,0
10.56520,-1.36668,-9.19463,1.34114,9.19463,22412,0
11.11280,-1.93274,-17.55195,1.90720,17.55195,22476,1
11.68280,-2.50309,-26.22056,2.47755,26.22056,22476,1
12.16520,-2.98523,-34.61555,2.95969,34.61555,22476,1
12.66520,-3.48526,-43.24684,3.45972,43.24683,22476,1
13.15780,-3.97828,-51.63724,3.95274,51.63724,22476,1
13.58980,-4.41040,-58.54580,4.38486,58.54580,22476,1
14.10080,-4.92132,-66.60056,4.89578,66.60056,22476,1
14.53480,-4.92563,-63.79612,4.90009,63.79612,22476,1
14.93780,-4.51450,-54.40680,4.48896,54.40680,22412,1
15.34580,-4.10598,-45.75034,4.08044,45.75034,22412,1
15.81280,-3.63898,-36.74544,3.61344,36.74544,22412,1
16.26780,-3.18383,-28.58952,3.15829,28.58953,22412,1
16.83280,-2.61895,-20.62269,2.59341,20.62269,22412,1
17.56520,-1.88700,-12.66925,1.86146,12.66925,22412,1
18.21480,-1.42915,-9.17113,1.40361,9.17113,22412,1
18.76780,-1.99985,-17.62435,1.97431,17.62435,22476,2
19.36520,-2.59721,-26.61932,2.57167,26.61932,22476,2
19.76520,-2.99726,-33.71922,2.97172,33.71922,22476,2
20.18980,-3.42237,-41.07349,3.39683,41.07349,22476,2
20.71180,-3.94433,-50.14526,3.91879,50.14526,22476,2
21.25780,-4.49022,-58.97295,4.46468,58.97295,22476,2
21.71480,-4.94737,-66.24475,4.92182,66.24475,22476,2
22.10080,-5.02783,-65.46285,5.00229,65.46285,22476,2
22.49680,-4.62004,-55.97578,4.59450,55.97578,22412,2
22.86520,-4.25111,-48.00924,4.22557,48.00924,22412,2
23.28680,-3.82909,-39.64154,3.80355,39.64154,22412,2
23.74980,-3.36622,-31.09600,3.34068,31.09600,22412,2
24.26520,-2.85115,-23.09970,2.82560,23.09970,22412,2
24.96480,-2.15084,-15.03080,2.12530,15.03080,22412,2
25.69380,-1.42201,-7.52370,1.39647,7.52370,22412,2
26.20680,-1.87391,-15.26701,1.84837,15.26701,22476,2
26.77880,-2.44708,-23.61199,2.42154,23.61199,22476,3
27.26520,-2.93334,-31.75912,2.90780,31.75912,22476,3
27.73880,-3.40741,-40.17209,3.38187,40.17208,22476,3
28.15980,-3.82838,-47.71554,3.80284,47.71555,22476,3
28.66780,-4.33646,-56.09098,4.31092,56.09098,22476,3
29.22880,-4.89736,-65.10792,4.87181,65.10792,22476,3
29.66780,-5.06422,-65.82719,5.03868,65.82719,22476,3
30.04280,-4.67642,-56.74864,4.65088,56.74863,22412,3
30.43480,-4.28324,-48.21380,4.25770,48.21380,22412,3
30.86520,-3.85326,-39.68464,3.82772,39.68464,22412,3
31.34880,-3.36930,-30.68359,3.34376,30.68359,22412,3
31.92380,-2.79410,-22.10298,2.76856,22.10298,22412,3
32.64180,-2.07592,-13.97938,2.05038,13.97938,22412,3
33.32480,-1.42395,-7.53327,1.39841,7.53327,22412,3
33.86520,-1.99050,-16.53330,1.96496,16.53330,22476,3
34.43380,-2.56015,-25.04260,2.53461,25.04259,22476,4
34.95580,-3.08211,-34.16652,3.05657,34.16652,22476,4
35.40480,-3.53133,-42.05534,3.50578,42.05534,22476,4
35.87480,-4.00132,-50.06066,3.97578,50.06066,22476,4
36.42080,-4.54716,-59.05927,4.52162,59.05927,22476,4
36.96520,-5.09120,-67.80072,5.06566,67.80071,22476,4
37.33480,-4.98260,-63.25806,4.95706,63.25806,22412,4
37.74880,-4.56155,-53.73704,4.53601,53.73704,22412,4
38.10780,-4.20216,-46.15533,4.17662,46.15533,22412,4
38.56520,-3.74531,-37.32993,3.71977,37.32993,22412,4
39.06520,-3.24524,-28.22533,3.21970,28.22533,22412,4
39.69780,-2.61217,-19.53736,2.58663,19.53736,22412,4
40.46520,-1.84524,-11.57368,1.81970,11.57368,22412,4
41.05280,-1.60403,-10.67634,1.57849,10.67634,22412,4
41.64480,-2.20706,-19.30831,2.18151,19.30831,22476,5
42.18080,-2.74330,-27.66600,2.71776,27.66600,22476,5
42.68480,-3.24736,-36.68061,3.22182,36.68061,22476,5
43.19380,-3.75641,-45.63559,3.73087,45.63559,22476,5
43.66520,-4.22729,-53.57306,4.20175,53.57306,22476,5
44.21980,-4.78227,-62.67302,4.75673,62.67302,22476,5
44.69680,-5.22374,-69.53468,5.19820,69.53468,22476,5
45.06520,-4.82984,-59.44023,4.80430,59.44022,22412,5
45.44780,-4.44437,-50.94050,4.41883,50.94050,22412,5
45.89680,-3.99528,-41.85165,3.96974,41.85165,22412,5
46.37780,-3.51421,-32.84247,3.48867,32.84247,22412,5
46.95180,-2.94023,-23.56393,2.91469,23.56392,22412,5
47.56520,-2.32738,-16.24060,2.30184,16.24060,22412,5
48.31580,-1.57605,-8.59426,1.55051,8.59426,22412,5
48.86520,-1.85095,-14.08622,1.82541,14.08622,22476,5
49.45680,-2.44510,-22.75448,2.41956,22.75448,22476,6
49.96520,-2.95330,-31.11402,2.92776,31.11402,22476,6
50.43680,-3.42537,-39.61689,3.39982,39.61689,22476,6
50.85680,-3.84540,-47.00452,3.81986,47.00452,22476,6
51.37780,-4.36646,-55.69169,4.34092,55.69169,22476,6
51.86520,-4.85331,-63.57109,4.82777,63.57109,22476,6
52.32880,-5.19069,-68.13439,5.16515,68.13439,22476,6
52.70780,-4.79011,-58.26142,4.76457,58.26142,22412,6
53.08580,-4.41051,-49.94290,4.38497,49.94289,22412,6
53.56520,-3.93136,-40.27981,3.90582,40.27981,22412,6
53.99780,-3.49833,-32.24569,3.47279,32.24569,22412,6
54.56520,-2.93133,-23.21894,2.90579,23.21894,22412,6
55.26520,-2.23142,-15.10385,2.20588,15.10385,22412,6
55.99980,-1.49625,-7.54780,1.47071,7.54780,22412,6
56.51980,-1.93900,-15.19417,1.91346,15.19417,22476,6
57.10180,-2.52232,-23.71573,2.49678,23.71573,22476,7
57.62480,-3.04535,-32.65675,3.01981,32.65675,22476,7
58.13580,-3.55639,-41.66830,3.53085,41.66830,22476,7
58.59080,-4.01149,-49.53643,3.98595,49.53643,22476,7
59.14780,-4.56834,-58.70428,4.54280,58.70428,22476,7
59.56880,-4.98949,-65.66397,4.96395,65.66397,22476,7
60.01680,-5.07396,-64.79049,5.04842,64.79049,22476,7
60.41580,-4.66523,-55.30256,4.63969,55.30256,22412,7
60.85580,-4.22443,-45.96623,4.19889,45.96623,22412,7
61.32980,-3.75052,-36.76231,3.72498,36.76231,22412,7
61.76780,-3.31249,-28.81338,3.28695,28.81338,22412,7
62.38380,-2.69633,-20.03055,2.67079,20.03054,22412,7
63.15880,-1.92141,-11.94881,1.89586,11.94881,22412,7
63.76280,-1.60817,-10.24280,1.58263,10.24280,22412,7
64.33179,-2.19017,-18.67026,2.16463,18.67026,22604,7
64.88980,-2.74856,-27.23704,2.72302,27.23705,22604,8
65.38280,-3.24163,-35.92346,3.21609,35.92346,22604,8
65.89980,-3.75864,-45.02672,3.73310,45.02672,22604,8
66.44280,-4.30163,-54.29215,4.27608,54.29215,22604,8
66.86980,-4.72863,-61.24189,4.70309,61.24189,22604,8
67.36520,-5.22363,-69.32284,5.19809,69.32284,22604,8
67.69480,-4.96267,-61.92144,4.93713,61.92144,22540,8
68.12080,-4.53175,-52.22933,4.50621,52.22932,22540,8
68.56520,-4.08750,-43.01481,4.06196,43.01481,22540,8
69.05080,-3.60152,-33.87361,3.57598,33.87362,22540,8
69.53080,-3.12146,-25.67765,3.09592,25.67765,22540,8
70.17780,-2.47448,-17.45791,2.44893,17.45791,22540,8
70.96380,-1.68848,-9.47465,1.66294,9.47465,22540,8
71.50680,-1.79145,-12.83800,1.76591,12.83800,22604,8
72.07880,-2.36766,-21.13580,2.34212,21.13580,22604,9
72.63480,-2.92373,-30.19949,2.89819,30.19949,22604,9
73.13980,-3.42874,-39.27463,3.40320,39.27462,22604,9
73.58980,-3.87879,-47.12777,3.85325,47.12777,22604,9
74.06980,-4.35882,-55.08831,4.33328,55.08831,22604,9
74.62380,-4.91268,-64.10194,4.88714,64.10194,22604,9
75.07680,-5.16748,-66.85640,5.14194,66.85640,22604,9
75.46520,-4.76311,-57.11575,4.73757,57.11575,22540,9
75.90280,-4.32382,-47.67796,4.29828,47.67796,22540,9
76.36520,-3.86182,-38.53435,3.83628,38.53435,22540,9
76.81480,-3.41175,-30.23454,3.38621,30.23454,22540,9
77.35780,-2.86884,-22.12087,2.84330,22.12086,22540,9
78.06520,-2.16149,-14.12807,2.13595,14.12807,22540,9
78.85180,-1.46508,-7.30808,1.43954,7.30808,22540,9
79.56520,-1.88328,-14.46334,1.85774,14.46334,22476,9
80.16520,-2.48427,-23.13735,2.45873,23.13735,22476,10
80.64680,-2.96642,-31.07645,2.94088,31.07645,22476,10
81.15080,-3.47045,-39.93550,3.44491,39.93550,22476,10
81.66520,-3.98444,-48.84708,3.95890,48.84708,22476,10
82.19980,-4.51934,-57.65052,4.49380,57.65052,22476,10
82.69880,-5.01844,-65.74102,4.99290,65.74103,22476,10
83.10380,-5.13906,-65.81295,5.11352,65.81295,22476,10
83.46520,-4.76576,-57.08002,4.74022,57.08002,22412,10
83.89480,-4.33464,-47.73265,4.30910,47.73265,22412,10
84.27180,-3.95753,-40.12766,3.93199,40.12767,22412,10
84.72280,-3.50651,-31.77556,3.48097,31.77556,22412,10
85.24280,-2.98651,-23.62540,2.96097,23.62540,22412,10
85.92880,-2.30065,-15.56161,2.27511,15.56161,22412,10
86.66520,-1.56432,-8.06590,1.53878,8.06590,22412,10
87.19680,-1.92475,-14.64398,1.89921,14.64398,22476,10
87.77980,-2.50948,-23.17034,2.48394,23.17034,22476,11
88.30880,-3.03850,-32.04490,3.01296,32.04490,22476,11
88.81780,-3.54755,-41.10977,3.52201,41.10977,22476,11
89.28680,-4.01663,-49.17327,3.99109,49.17327,22476,11
89.77280,-4.50257,-57.23540,4.47703,57.23540,22476,11
90.32980,-5.05954,-66.25627,5.03400,66.25627,22476,11
90.68680,-5.16365,-66.23959,5.13811,66.23959,22476,11
91.07680,-4.75990,-56.74367,4.73436,56.74368,22412,11
91.46520,-4.37096,-48.26481,4.34542,48.26481,22412,11
91.89980,-3.93578,-39.60492,3.91024,39.60492,22412,11
92.34680,-3.48880,-31.28694,3.46326,31.28694,22412,11
92.91880,-2.91678,-22.55837,2.89124,22.55837,22412,11
93.63280,-2.20267,-14.49334,2.17713,14.49334,22412,11
94.36280,-1.48527,-7.16886,1.45973,7.16886,22412,11
94.86780,-2.00880,-15.74539,1.98326,15.74539,22476,11
95.46520,-2.60686,-24.63376,2.58132,24.63376,22476,12
95.96520,-3.10677,-33.21986,3.08123,33.21986,22476,12
96.46780,-3.60987,-42.12325,3.58433,42.12325,22476,12
96.96520,-4.10685,-50.67267,4.08131,50.67267,22476,12
97.48280,-4.62497,-59.07122,4.59942,59.07122,22476,12
98.03980,-5.18192,-68.10728,5.15637,68.10728,22476,12
98.40880,-5.00894,-62.35804,4.98340,62.35804,22476,12
98.82780,-4.58424,-52.72555,4.55869,52.72555,22412,12
99.26580,-4.14587,-43.58584,4.12033,43.58585,22412,12
99.69580,-3.71599,-35.35786,3.69045,35.35786,22412,12
100.22680,-3.18478,-26.20733,3.15924,26.20733,22412,12
100.87480,-2.53681,-17.98519,2.51127,17.98519,22412,12
101.65280,-1.75896,-10.05801,1.73341,10.05801,22412,12
102.18580,-1.77023,-12.26141,1.74469,12.26141,22412,12
102.77380,-2.36405,-20.75689,2.33851,20.75689,22476,13
103.32080,-2.91116,-29.55445,2.88562,29.55445,22476,13
103.77180,-3.36228,-37.67492,3.33674,37.67492,22476,13
104.25680,-3.84719,-46.08540,3.82165,46.08540,22476,13
104.76520,-4.35523,-54.61284,4.32969,54.61284,22476,13
105.26520,-4.85506,-62.80010,4.82952,62.80010,22476,13
105.75280,-5.27812,-69.18427,5.25258,69.18427,22476,13
106.07180,-4.93327,-60.31542,4.90773,60.31542,22412,13
106.49680,-4.50514,-50.86470,4.47960,50.86470,22412,13
106.96380,-4.03798,-41.24842,4.01244,41.24842,22412,13
107.38980,-3.61200,-33.32210,3.58646,33.32210,22412,13
107.95580,-3.04586,-24.12232,3.02032,24.12232,22412,13
108.63280,-2.36911,-16.06266,2.34357,16.06266,22412,13
109.37180,-1.62993,-8.55122,1.60439,8.55122,22412,13
109.89980,-1.91971,-14.24990,1.89416,14.24990,22476,13
110.47880,-2.50090,-22.70587,2.47536,22.70587,22476,14
111.00580,-3.02798,-31.56411,3.00244,31.56411,22476,14
111.43180,-3.45409,-39.21805,3.42854,39.21805,22476,14
111.92080,-3.94311,-47.78888,3.91756,47.78888,22476,14
112.42180,-4.44410,-55.96809,4.41856,55.96809,22476,14
112.96520,-4.98710,-64.80588,4.96156,64.80588,22476,14
113.38580,-5.20993,-67.00437,5.18439,67.00436,22476,14
113.70880,-4.87120,-58.82354,4.84566,58.82354,22412,14
114.04880,-4.52912,-51.30383,4.50358,51.30383,22412,14
114.46520,-4.11298,-42.63617,4.08744,42.63617,22412,14
114.91380,-3.66398,-34.16005,3.63844,34.16005,22412,14
115.45480,-3.12292,-25.09775,3.09737,25.09775,22412,14
116.10380,-2.47393,-17.08555,2.44839,17.08555,22412,14
116.86520,-1.71301,-9.41688,1.68747,9.41688,22412,14
117.40680,-1.85936,-13.27631,1.83382,13.27631,22476,14
117.97280,-2.42889,-21.58236,2.40334,21.58236,22476,15
118.51280,-2.96900,-30.46498,2.94346,30.46498,22476,15
118.93280,-3.38922,-37.96178,3.36368,37.96178,22476,15
119.45380,-3.91009,-47.07350,3.88455,47.07350,22476,15
119.93480,-4.39120,-55.10542,4.36566,55.10542,22476,15
120.37180,-4.82797,-62.13943,4.80243,62.13943,22476,15
120.83080,-5.28716,-69.56722,5.26162,69.56721,22476,15
121.11880,-5.03294,-62.47437,5.00740,62.47437,22412,15
121.50080,-4.64552,-53.71236,4.61998,53.71236,22412,15
121.94680,-4.19892,-44.19926,4.17338,44.19926,22412,15
122.36520,-3.78107,-36.15219,3.75553,36.15219,22412,15
122.87080,-3.27501,-27.12444,3.24947,27.12444,22412,15
123.54080,-2.60495,-18.52520,2.57941,18.52520,22412,15
124.27280,-1.87309,-10.98868,1.84755,10.98868,22412,15
124.82580,-1.68358,-10.71320,1.65804,10.71320,22412,15
125.40580,-2.27413,-19.24643,2.24859,19.24643,22476,16
125.96520,-2.83318,-27.93566,2.80764,27.93566,22476,16
126.46520,-3.33329,-36.90241,3.30775,36.90240,22476,16
126.87580,-3.74428,-44.12292,3.71874,44.12292,22476,16
127.36520,-4.23320,-52.43158,4.20766,52.43158,22476,16
127.90880,-4.77716,-61.25005,4.75161,61.25005,22476,16
128.29180,-5.16010,-67.43508,5.13456,67.43508,22476,16
128.66520,-5.07072,-63.36227,5.04518,63.36227,22476,16
129.03180,-4.69681,-54.79507,4.67127,54.79507,22412,16
129.46520,-4.26316,-45.40122,4.23761,45.40122,22412,16
129.89079,-3.83716,-37.16134,3.81162,37.16133,22412,16
130.30580,-3.42214,-29.57414,3.39660,29.57413,22412,16
130.85579,-2.87224,-21.62944,2.84670,21.62944,22412,16
131.49580,-2.23218,-14.54681,2.20663,14.54681,22412,16
132.22280,-1.51856,-7.22000,1.49302,7.22000,22412,16
132.75680,-2.07204,-16.25603,2.04650,16.25603,22476,16
133.30880,-2.62506,-24.56631,2.59952,24.56631,22476,17
133.78180,-3.09789,-32.62020,3.07235,32.62020,22476,17
134.28580,-3.60202,-41.60836,3.57648,41.60836,22476,17
134.76520,-4.08096,-49.82002,4.05542,49.82002,22476,17
135.30480,-4.62111,-58.60525,4.59557,58.60525,22476,17
135.79880,-5.11494,-66.66362,5.08940,66.66362,22476,17
136.18980,-5.10132,-63.99927,5.07578,63.99926,22476,17
136.60380,-4.67865,-54.32235,4.65311,54.32235,22412,17
136.99580,-4.28609,-45.84013,4.26055,45.84013,22412,17
137.46519,-3.81707,-36.67135,3.79153,36.67135,22412,17
137.88180,-3.40015,-29.12377,3.37461,29.12377,22412,17
138.49380,-2.78797,-20.49821,2.76243,20.49821,22412,17
139.25080,-2.03096,-12.51247,2.00541,12.51247,22412,17
139.86520,-1.60672,-9.23170,1.58118,9.23170,22412,17
140.44780,-2.20762,-18.19017,2.18208,18.19017,22604,17
141.00580,-2.76606,-26.75165,2.74052,26.75165,22604,18
141.51480,-3.27509,-35.71954,3.24955,35.71954,22604,18
141.96519,-3.72508,-43.69924,3.69954,43.69924,22604,18
142.36520,-4.12496,-50.48633,4.09942,50.48633,22604,18
142.87780,-4.63808,-58.83329,4.61254,58.83329,22604,18
143.35980,-5.11990,-66.67056,5.09436,66.67056,22604,18
143.70280,-5.18063,-65.83916,5.15509,65.83916,22604,18
144.06520,-4.80620,-57.00841,4.78066,57.00841,22540,18
144.46519,-4.40512,-48.30268,4.37958,48.30268,22540,18
144.86520,-4.00502,-40.01584,3.97948,40.01584,22540,18
145.36520,-3.50500,-30.79212,3.47946,30.79212,22540,18
145.95780,-2.91201,-22.05889,2.88647,22.05889,22540,18
146.66519,-2.20491,-14.11282,2.17937,14.11282,22540,18
147.36680,-1.51763,-7.17819,1.49209,7.17819,22540,18
147.86520,-2.03579,-15.65833,2.01025,15.65833,22604,18
148.43978,-2.61193,-24.28112,2.58639,24.28112,22604,19
148.95580,-3.12788,-33.14422,3.10234,33.14422,22604,19
149.39980,-3.57192,-40.95786,3.54638,40.95786,22604,19
149.87980,-4.05195,-49.21391,4.02641,49.21391,22604,19
150.43080,-4.60299,-58.23030,4.57745,58.23030,22604,19
150.91880,-5.09086,-66.16040,5.06532,66.16040,22604,19
151.32280,-5.17293,-65.50213,5.14738,65.50213,22604,19
151.69780,-4.78685,-56.47350,4.76131,56.47350,22540,19
152.07780,-4.40600,-48.19530,4.38046,48.19530,22540,19
152.46519,-4.01889,-40.19254,3.99335,40.19254,22540,19
152.94880,-3.53475,-31.16859,3.50921,31.16859,22540,19
153.46519,-3.01878,-23.35540,2.99324,23.35540,22540,19
154.16519,-2.31898,-15.28943,2.29344,15.28943,22540,19
154.92180,-1.56167,-7.48847,1.53613,7.48847,22540,19
155.66519,-1.87017,-13.55306,1.84463,13.55306,22476,19
156.26380,-2.47081,-22.25933,2.44527,22.25933,22476,20
156.77378,-2.98094,-30.60228,2.95540,30.60228,22476,20
157.28480,-3.49209,-39.67043,3.46654,39.67043,22476,20
157.76520,-3.97205,-48.08406,3.94651,48.08406,22476,20
158.29180,-4.49899,-56.65117,4.47345,56.65117,22476,20
158.84480,-5.05195,-65.55761,5.02641,65.55762,22476,20
159.26680,-5.16662,-65.44463,5.14108,65.44463,22476,20
159.66880,-4.75289,-55.76637,4.72735,55.76637,22412,20
160.10080,-4.32005,-46.37611,4.29451,46.37611,22412,20
160.52780,-3.89306,-37.85571,3.86752,37.85571,22412,20
161.02480,-3.39607,-28.88160,3.37053,28.88160,22412,20
161.65980,-2.76095,-20.07126,2.73541,20.07126,22412,20
162.38580,-2.03488,-12.44954,2.00934,12.44954,22412,20
163.00280,-1.63744,-9.64498,1.61190,9.64498,22412,20
163.56520,-2.21561,-18.21269,2.19007,18.21269,22476,21
164.14878,-2.80000,-27.13962,2.77446,27.13962,22476,21
164.65280,-3.30410,-36.12301,3.27856,36.12301,22476,21
165.15680,-3.80804,-44.92677,3.78250,44.92677,22476,21
165.63680,-4.28809,-53.06051,4.26255,53.06050,22476,21
166.09980,-4.75101,-60.54217,4.72547,60.54218,22476,21
166.53678,-5.18794,-67.70853,5.16240,67.70853,22476,21
166.89680,-5.10815,-63.76543,5.08261,63.76543,22476,21
167.30680,-4.69045,-54.22558,4.66491,54.22558,22412,21
167.63080,-4.36608,-47.35746,4.34054,47.35746,22412,21
168.07978,-3.91691,-38.23056,3.89137,38.23056,22412,21
168.56680,-3.42988,-29.30153,3.40434,29.30153,22412,21
169.06980,-2.92687,-22.08063,2.90133,22.08063,22412,21
169.78480,-2.21185,-14.07097,2.18631,14.07097,22412,21
170.50080,-1.53692,-7.41121,1.51138,7.41121,22412,21
171.05480,-2.11904,-16.75958,2.09349,16.75958,22476,21
171.61080,-2.67591,-25.15387,2.65037,25.15387,22476,22
172.12780,-3.19286,-34.17906,3.16732,34.17906,22476,22
172.63780,-3.70291,-43.14943,3.67737,43.14943,22476,22
173.02180,-4.08677,-49.65867,4.06123,49.65867,22476,22
173.56520,-4.62997,-58.53462,4.60443,58.53462,22476,22
173.99980,-5.06477,-65.63985,5.03923,65.63985,22476,22
174.41178,-5.19239,-65.84203,5.16684,65.84203,22476,22
174.80580,-4.78579,-56.30202,4.76025,56.30202,22412,22
175.20280,-4.38800,-47.73602,4.36246,47.73602,22412,22
175.61080,-3.97989,-39.26285,3.95435,39.26285,22412,22
176.06520,-3.52575,-30.85184,3.50021,30.85184,22412,22
176.58080,-3.00978,-23.11751,2.98424,23.11751,22412,22
177.27880,-2.31192,-15.04930,2.28638,15.04930,22412,22
178.03080,-1.55960,-7.33129,1.53406,7.33129,22412,22
178.56520,-2.05060,-15.69936,2.02506,15.69936,22476,22
179.13080,-2.61783,-24.17304,2.59229,24.17304,22476,23
179.59780,-3.08469,-32.14136,3.05915,32.14136,22476,23
180.10280,-3.58981,-41.11660,3.56427,41.11660,22476,23
180.57580,-4.06282,-49.17877,4.03727,49.17877,22476,23
181.12180,-4.60890,-58.15694,4.58336,58.15694,22476,23
181.66519,-5.15182,-66.96765,5.12628,66.96765,22476,23
182.00680,-5.17603,-65.34961,5.15049,65.34961,22476,23
182.40180,-4.76973,-55.91241,4.74419,55.91241,22412,23
182.76520,-4.40596,-48.01982,4.38042,48.01982,22412,23
183.21980,-3.95084,-38.71463,3.92530,38.71463,22412,23
183.70980,-3.46086,-29.68632,3.43532,29.68632,22412,23
184.30980,-2.86090,-21.14965,2.83536,21.14965,22412,23
185.06080,-2.10967,-12.97492,2.08413,12.97492,22412,23
185.69480,-1.59578,-8.48374,1.57024,8.48374,22412,23
186.26520,-2.18918,-17.64478,2.16364,17.64478,22476,23
186.82180,-2.74680,-26.20618,2.72126,26.20618,22476,24
187.33180,-3.25690,-35.15732,3.23136,35.15732,22476,24
187.77580,-3.70081,-43.03475,3.67527,43.03476,22476,24
188.22580,-4.15071,-50.71618,4.12517,50.71618,22476,24
188.71778,-4.64284,-58.66176,4.61730,58.66176,22476,24
189.16519,-5.08961,-65.91219,5.06407,65.91219,22476,24
189.56520,-5.18647,-65.59017,5.16093,65.59016,22476,24
189.96519,-4.77457,-55.93329,4.74903,55.93329,22412,24
190.38280,-4.35581,-46.91742,4.33027,46.91742,22412,24
190.85778,-3.88075,-37.22711,3.85521,37.22711,22412,24
191.36519,-3.37382,-28.14775,3.34828,28.14775,22412,24
191.96519,-2.77358,-19.90247,2.74804,19.90247,22412,24
192.72780,-2.01061,-12.03131,1.98507,12.03131,22412,24
193.32580,-1.68246,-10.14393,1.65692,10.14393,22412,24
193.88980,-2.26050,-18.62855,2.23496,18.62855,22476,25
194.46080,-2.83169,-27.48702,2.80615,27.48702,22476,25
194.96519,-3.33575,-36.53510,3.31021,36.53510,22476,25
195.46519,-3.83574,-45.23687,3.81020,45.23687,22476,25
195.95380,-4.32476,-53.49801,4.29921,53.49801,22476,25
196.48880,-4.85962,-62.23369,4.83408,62.23369,22476,25
196.98180,-5.33565,-69.80193,5.31011,69.80193,22476,25
197.34780,-4.94945,-59.80745,4.92391,59.80745,22412,25
197.76520,-4.52965,-50.57621,4.50410,50.57621,22412,25
198.20080,-4.09352,-41.23699,4.06798,41.23698,22412,25
198.68380,-3.61054,-32.14025,3.58500,32.14025,22412,25
199.26280,-3.03151,-23.11675,3.00597,23.11674,22412,25
199.86519,-2.42948,-16.12260,2.40394,16.12260,22412,25
200.65980,-1.63449,-8.07657,1.60895,8.07657,22412,25
201.16519,-1.98148,-14.56567,1.95594,14.56567,22476,25
201.74778,-2.56645,-23.22594,2.54091,23.22594,22476,26
202.26520,-3.08344,-31.94905,3.05789,31.94905,22476,26
202.76520,-3.58351,-40.86472,3.55797,40.86472,22476,26
203.18480,-4.00363,-48.16546,3.97809,48.16546,22476,26
203.72980,-4.54848,-57.12561,4.52294,57.12561,22476,26
204.26520,-5.08345,-65.77025,5.05791,65.77025,22476,26
204.66519,-5.18455,-65.54893,5.15901,65.54893,22476,26
205.06520,-4.77249,-55.87099,4.74695,55.87099,22412,26
205.45980,-4.37678,-47.32704,4.35123,47.32704,22412,26
205.81980,-4.01662,-39.68619,3.99108,39.68619,22412,26
206.30080,-3.53546,-30.78074,3.50992,30.78074,22412,26
206.77480,-3.06137,-23.56056,3.03583,23.56056,22412,26
207.46280,-2.37367,-15.49191,2.34813,15.49191,22412,26
208.16519,-1.67148,-8.40432,1.64594,8.40432,22412,26
208.66780,-1.95386,-14.08569,1.92832,14.08569,22476,26
209.26520,-2.55335,-22.96590,2.52781,22.96589,22476,27
209.77980,-3.06838,-31.57461,3.04283,31.57461,22476,27
210.27180,-3.56047,-40.38625,3.53492,40.38625,22476,27
210.76520,-4.05349,-48.92352,4.02795,48.92352,22476,27
211.29680,-4.58544,-57.64942,4.55990,57.64942,22476,27
211.78878,-5.07740,-65.64364,5.05186,65.64364,22476,27
212.19780,-5.21258,-66.07091,5.18704,66.07092,22476,27
212.60180,-4.79544,-56.24846,4.76990,56.24846,22412,27
212.96519,-4.43156,-48.34232,4.40601,48.34232,22412,27
213.41080,-3.98554,-39.09161,3.95999,39.09161,22412,27
213.89080,-3.50551,-30.18745,3.47997,30.18745,22412,27
214.47880,-2.91752,-21.63007,2.89198,21.63008,22412,27
215.22180,-2.17432,-13.45252,2.14878,13.45252,22412,27
215.88578,-1.58626,-7.92771,1.56072,7.92771,22412,27
216.44980,-2.17780,-17.27568,2.15225,17.27568,22604,27
216.99680,-2.72549,-25.74132,2.69995,25.74132,22604,28
217.50080,-3.22951,-34.57575,3.20397,34.57575,22604,28
218.02280,-3.75157,-43.70878,3.72603,43.70878,22604,28
218.49380,-4.22247,-51.71162,4.19693,51.71162,22604,28
219.03678,-4.76549,-60.53848,4.73995,60.53848,22604,28
219.53380,-5.26265,-68.64975,5.23711,68.64976,22604,28
219.90280,-5.04443,-61.90304,5.01889,61.90305,22540,28
220.28580,-4.65676,-53.18936,4.63122,53.18936,22540,28
220.71280,-4.22937,-43.85827,4.20383,43.85827,22540,28
221.17980,-3.76241,-34.79716,3.73687,34.79716,22540,28
221.66519,-3.27736,-26.46221,3.25182,26.46221,22540,28
222.32080,-2.62129,-18.15485,2.59575,18.15485,22540,28
223.07080,-1.87143,-10.49614,1.84589,10.49614,22540,28
223.65680,-1.82946,-12.30047,1.80392,12.30047,22540,28
224.23580,-2.41422,-20.78842,2.38868,20.78842,22604,29
224.76520,-2.94337,-29.35931,2.91783,29.35930,22604,29
225.26520,-3.44343,-38.35001,3.41789,38.35001,22604,29
225.64980,-3.82845,-44.96288,3.80291,44.96288,22604,29
226.16519,-4.34353,-53.68198,4.31799,53.68198,22604,29
226.66519,-4.84331,-61.83137,4.81777,61.83137,22604,29
227.14380,-5.32251,-69.58806,5.29697,69.58806,22604,29
227.49280,-5.01955,-61.23433,4.99401,61.23433,22540,29
227.91378,-4.59455,-51.78434,4.56901,51.78434,22540,29
228.29680,-4.21130,-43.40810,4.18575,43.40810,22540,29
228.77780,-3.73040,-34.18581,3.70486,34.18581,22540,29
229.32280,-3.18518,-25.14395,3.15964,25.14396,22540,29
229.98278,-2.52522,-17.05427,2.49968,17.05428,22540,29
230.76520,-1.74333,-9.09160,1.71779,9.09160,22540,29
231.51680,-1.75652,-11.57052,1.73098,11.57051,22540,29
232.11680,-2.36160,-20.17942,2.33606,20.17942,22476,29
232.66519,-2.90968,-28.99968,2.88414,28.99968,22476,30
233.11880,-3.36378,-37.05047,3.33824,37.05047,22476,30
233.54480,-3.78967,-44.41735,3.76412,44.41735,22476,30
234.03580,-4.28072,-52.72095,4.25518,52.72095,22476,30
234.52880,-4.77360,-60.70684,4.74806,60.70684,22476,30
234.96519,-5.20960,-67.78108,5.18406,67.78107,22476,30
235.31678,-5.10537,-63.41468,5.07983,63.41468,22476,30
235.68780,-4.72730,-54.77322,4.70176,54.77322,22412,30
236.11480,-4.29961,-45.42902,4.27407,45.42902,22412,30
236.57680,-3.83763,-36.14481,3.81209,36.14481,22412,30
237.08780,-3.32667,-27.09232,3.30113,27.09232,22412,30
237.75280,-2.66147,-18.57249,2.63593,18.57249,22412,30
238.47980,-1.93456,-11.10571,1.90902,11.10571,22412,30
239.06520,-1.77073,-11.38177,1.74519,11.38177,22412,30
239.66519,-2.37941,-20.11866,2.35387,20.11866,22476,31
240.19280,-2.90760,-28.72725,2.88206,28.72725,22476,31
240.65980,-3.37471,-37.04616,3.34917,37.04616,22476,31
241.12680,-3.84164,-45.17666,3.81610,45.17665,22476,31
241.65980,-4.37471,-54.17355,4.34917,54.17355,22476,31
242.14280,-4.85749,-62.05456,4.83195,62.05455,22476,31
242.65278,-5.34654,-69.78805,5.32100,69.78806,22476,31
242.99778,-4.97981,-60.28508,4.95427,60.28508,22412,31
243.41780,-4.55660,-50.98566,4.53106,50.98566,22412,31
243.77180,-4.20247,-43.12858,4.17693,43.12858,22412,31
244.19680,-3.77761,-34.92381,3.75207,34.92381,22412,31
244.64980,-3.32465,-26.99393,3.29911,26.99393,22412,31
245.26520,-2.70948,-18.99560,2.68394,18.99560,22412,31
246.03280,-1.94156,-11.14487,1.91602,11.14487,22412,31
246.61180,-1.76721,-11.28279,1.74167,11.28279,22412,31
247.18380,-2.34835,-19.64770,2.32281,19.64770,22476,32
247.74380,-2.90853,-28.68378,2.88299,28.68378,22476,32
248.18480,-3.34962,-36.59048,3.32408,36.59048,22476,32
248.66519,-3.82957,-44.94950,3.80403,44.94950,22476,32
249.18380,-4.34863,-53.70383,4.32309,53.70383,22476,32
249.67180,-4.83641,-61.66172,4.81086,61.66172,22476,32
250.16378,-5.32858,-69.61346,5.30304,69.61346,22476,32
250.49180,-5.02902,-61.43733,5.00348,61.43733,22412,32
250.92180,-4.59470,-51.75315,4.56916,51.75315,22412,32
251.35380,-4.16240,-42.30579,4.13686,42.30579,22412,32
251.82978,-3.68644,-33.21725,3.66090,33.21725,22412,32
252.36519,-3.15137,-24.51551,3.12583,24.51551,22412,32
253.06520,-2.45140,-16.17759,2.42586,16.17759,22412,32
253.81478,-1.70146,-8.58943,1.67592,8.58943,22412,32
254.35778,-1.97803,-14.29433,1.95249,14.29433,22476,32
254.91680,-2.53923,-22.67195,2.51369,22.67195,22476,33
255.40380,-3.02631,-30.75825,3.00077,30.75826,22476,33
255.81080,-3.43351,-38.14585,3.40797,38.14585,22476,33
256.32678,-3.94944,-47.13736,3.92390,47.13736,22476,33
256.80680,-4.42951,-55.06228,4.40396,55.06228,22476,33
257.36481,-4.98743,-64.07443,4.96189,64.07442,22476,33
257.79178,-5.29014,-68.06729,5.26460,68.06729,22476,33
258.14680,-4.91358,-58.73234,4.88804,58.73234,22412,33
258.56519,-4.49353,-49.49338,4.46799,49.49339,22412,33
258.99180,-4.06631,-40.23757,4.04077,40.23757,22412,33
259.45178,-3.60636,-31.65400,3.58082,31.65400,22412,33
259.96517,-3.09322,-23.66323,3.06768,23.66323,22412,33
260.66480,-2.39346,-15.53976,2.36792,15.53976,22412,33
261.40078,-1.65732,-8.04674,1.63178,8.04674,22412,33
261.92578,-2.00840,-14.74878,1.98286,14.74878,22476,33
262.48678,-2.57118,-23.11562,2.54564,23.11562,22476,34
263.01581,-3.10018,-32.03172,3.07464,32.03172,22476,34
263.47478,-3.55929,-40.15770,3.53375,40.15770,22476,34
263.98778,-4.07225,-49.01857,4.04671,49.01857,22476,34
264.53478,-4.61939,-58.06465,4.59385,58.06465,22476,34
265.06519,-5.14932,-66.65908,5.12378,66.65908,22476,34
265.45481,-5.14487,-64.23829,5.11933,64.23830,22476,34
265.81281,-4.77824,-55.75385,4.75270,55.75385,22412,34
266.23981,-4.35050,-46.43186,4.32496,46.43186,22412,34
266.60081,-3.98941,-38.78693,3.96386,38.78693,22412,34
267.09281,-3.49739,-29.72078,3.47185,29.72078,22412,34
267.69878,-2.89143,-21.04675,2.86589,21.04675,22412,34
268.44278,-2.14717,-13.01570,2.12163,13.01570,22412,34
269.08381,-1.63077,-8.52084,1.60522,8.52084,22412,34
269.64081,-2.21079,-17.61392,2.18525,17.61392,22476,35
270.19181,-2.76230,-26.16379,2.73676,26.16379,22476,35
270.66519,-3.23536,-34.52573,3.20982,34.52573,22476,35
271.12878,-3.69937,-42.65255,3.67383,42.65255,22476,35
271.65078,-4.22133,-51.54571,4.19579,51.54571,22476,35
272.17881,-4.74936,-60.22175,4.72382,60.22175,22476,35
272.73178,-5.30247,-69.18970,5.27693,69.18970,22476,35
273.06519,-5.06463,-62.18164,5.03909,62.18164,22412,35
273.45278,-4.67177,-53.26686,4.64623,53.26686,22412,35
273.86522,-4.25941,-44.21447,4.23387,44.21447,22412,35
274.35278,-3.77139,-34.62000,3.74585,34.62000,22412,35
274.86522,-3.25934,-25.94362,3.23380,25.94362,22412,35
275.52178,-2.60228,-17.64441,2.57674,17.64441,22412,35
276.27978,-1.84439,-10.00871,1.81885,10.00871,22412,35
276.84578,-1.86929,-12.69004,1.84375,12.69004,22476,35
277.42278,-2.45107,-21.21766,2.42553,21.21766,22476,36
277.95678,-2.98521,-30.04024,2.95967,30.04024,22476,36
278.41278,-3.44136,-38.19028,3.41582,38.19028,22476,36
278.86881,-3.89741,-46.07518,3.87187,46.07518,22476,36
279.41181,-4.44034,-55.20973,4.41480,55.20973,22476,36
279.96519,-4.99334,-64.11035,4.96780,64.11035,22476,36
280.36522,-5.31982,-68.89012,5.29428,68.89012,22476,36
280.74178,-4.91644,-58.74376,4.89090,58.74376,22412,36
281.16519,-4.49141,-49.41619,4.46587,49.41619,22412,36
281.58881,-4.06720,-40.10961,4.04166,40.10961,22412,36
282.03878,-3.61725,-31.70197,3.59171,31.70197,22412,36
282.60181,-3.05409,-23.00043,3.02854,23.00043,22412,36
283.30278,-2.35342,-15.01479,2.32788,15.01479,22412,36
284.05078,-1.60517,-7.36876,1.57963,7.36876,22412,36
284.56519,-2.07583,-15.64190,2.05029,15.64190,22476,36
285.12281,-2.63532,-24.10209,2.60978,24.10209,22476,37
285.64278,-3.15526,-33.11607,3.12972,33.11607,22476,37
286.15978,-3.67233,-42.17925,3.64679,42.17925,22476,37
286.62578,-4.13829,-50.14855,4.11275,50.14855,22476,37
287.16181,-4.67436,-58.93369,4.64882,58.93369,22476,37
287.66519,-5.17723,-67.07413,5.15169,67.07413,22476,37
288.02578,-5.15832,-64.52093,5.13278,64.52094,22476,37
288.36522,-4.81038,-56.36874,4.78484,56.36874,22412,37
288.76481,-4.40948,-47.75313,4.38394,47.75312,22412,37
289.16181,-4.01240,-39.11943,3.98686,39.11943,22412,37
289.58678,-3.58725,-31.07515,3.56171,31.07515,22412,37
290.16519,-3.00932,-22.43372,2.98377,22.43372,22412,37
290.86578,-2.30844,-14.53815,2.28290,14.53815,22412,37
291.60081,-1.58569,-7.18317,1.56015,7.18317,22412,37
292.10581,-2.10906,-16.06088,2.08352,16.06088,22604,37
292.67481,-2.67935,-24.79411,2.65381,24.79411,22604,38
293.17778,-3.18235,-33.59529,3.15681,33.59529,22604,38
293.68878,-3.69339,-42.56336,3.66784,42.56336,22604,38
294.22078,-4.22539,-51.66601,4.19985,51.66602,22604,38
294.76519,-4.76937,-60.47507,4.74383,60.47507,22604,38
295.29581,-5.30052,-69.12436,5.27498,69.12437,22604,38
295.66519,-5.01756,-61.09896,4.99202,61.09896,22540,38
296.05381,-4.62468,-52.32817,4.59914,52.32817,22540,38
296.46519,-4.21332,-43.23735,4.18778,43.23735,22540,38
296.94778,-3.73043,-33.70085,3.70489,33.70085,22540,38
297.46519,-3.21336,-25.15267,3.18781,25.15267,22540,38
298.16519,-2.51327,-16.59860,2.48773,16.59859,22540,38
298.91581,-1.76237,-9.02320,1.73683,9.02320,22540,38
299.43078,-1.94991,-13.67751,1.92437,13.67751,22604,38
299.99781,-2.52026,-22.25870,2.49472,22.25870,22604,39
300.52878,-3.05130,-31.11146,3.02576,31.11146,22604,39
301.03878,-3.56134,-40.16066,3.53580,40.16066,22604,39
301.48881,-4.01144,-48.06733,3.98590,48.06733,22604,39
302.03478,-4.55724,-57.06128,4.53170,57.06128,22604,39
302.53778,-5.06034,-65.15884,5.03480,65.15884,22604,39
302.96078,-5.23689,-66.39785,5.21135,66.39785,22604,39
303.35081,-4.83260,-56.79285,4.80706,56.79285,22540,39
303.76519,-4.41755,-47.81738,4.39201,47.81738,22540,39
304.18178,-4.00056,-38.74088,3.97502,38.74088,22540,39
304.60878,-3.57329,-30.70477,3.54775,30.70477,22540,39
305.15578,-3.02636,-22.55179,3.00082,22.55179,22540,39
305.86522,-2.31756,-14.57541,2.29202,14.57541,22540,39
306.56878,-1.61335,-7.34095,1.58781,7.34095,22540,39
307.34878,-1.96430,-14.26485,1.93876,14.26485,22476,39
307.91378,-2.53074,-22.69199,2.50520,22.69199,22476,40
308.44778,-3.06471,-31.61475,3.03917,31.61475,22476,40
308.96381,-3.58075,-40.68901,3.55521,40.68901,22476,40
309.36522,-3.98190,-47.68137,3.95636,47.68137,22476,40
309.90681,-4.52376,-56.61212,4.49822,56.61211,22476,40
310.46519,-5.08173,-65.55024,5.05619,65.55024,22476,40
310.86522,-5.21008,-65.85801,5.18454,65.85802,22476,40
311.25778,-4.80388,-56.25110,4.77834,56.25111,22412,40
311.67178,-4.38906,-47.30741,4.36352,47.30741,22412,40
312.11078,-3.94991,-37.79649,3.92437,37.79649,22412,40
312.52781,-3.53276,-30.06032,3.50722,30.06032,22412,40
313.11481,-2.94585,-21.48600,2.92031,21.48600,22412,40
313.76519,-2.29599,-14.38336,2.27044,14.38336,22412,40
314.48481,-1.58514,-7.11702,1.55960,7.11702,22412,40
315.00778,-2.12367,-16.31117,2.09813,16.31117,22476,40
315.56519,-2.68184,-24.89436,2.65630,24.89436,22476,41
316.06519,-3.18175,-33.67532,3.15621,33.67532,22476,41
316.49281,-3.60983,-41.09930,3.58429,41.09930,22476,41
317.01578,-4.13281,-50.15224,4.10726,50.15224,22476,41
317.56519,-4.68189,-59.08410,4.65635,59.08410,22476,41
318.06519,-5.18180,-67.12615,5.15626,67.12614,22476,41
318.44078,-5.16126,-64.41177,5.13572,64.41177,22476,41
318.84978,-4.74350,-54.79366,4.71796,54.79366,22412,41
319.24381,-4.34896,-46.24465,4.32342,46.24465,22412,41
319.66519,-3.92788,-37.25883,3.90234,37.25883,22412,41
320.13778,-3.45486,-28.57448,3.42932,28.57448,22412,41
320.66519,-2.92783,-21.17557,2.90229,21.17557,22412,41
321.41678,-2.17564,-13.10537,2.15010,13.10537,22412,41
322.07878,-1.65156,-8.64166,1.62602,8.64166,22412,41
322.62281,-2.21730,-17.65206,2.19176,17.65207,22476,42
323.17278,-2.76786,-26.23621,2.74232,26.23621,22476,42
323.64578,-3.24094,-34.69252,3.21540,34.69252,22476,42
324.09578,-3.69086,-42.57765,3.66532,42.57765,22476,42
324.62978,-4.22485,-51.64149,4.19931,51.64149,22476,42
325.16519,-4.75986,-60.31112,4.73432,60.31112,22476,42
325.71178,-5.30695,-69.15159,5.28141,69.15159,22476,42
326.07178,-5.03118,-61.31743,5.00564,61.31743,22412,42
326.49381,-4.60508,-51.80321,4.57954,51.80321,22412,42
326.91878,-4.17969,-42.39736,4.15415,42.39737,22412,42
327.35181,-3.74690,-33.77459,3.72135,33.77459,22412,42
327.83678,-3.26182,-25.58528,3.23628,25.58528,22412,42
328.48978,-2.60877,-17.44198,2.58323,17.44198,22412,42
329.26519,-1.83386,-9.71338,1.80832,9.71338,22412,42
329.79178,-1.88358,-12.72024,1.85804,12.72024,22476,42
330.36522,-2.46158,-21.32797,2.43604,21.32797,22476,43
330.88778,-2.98475,-30.03145,2.95921,30.03145,22476,43
331.39978,-3.49690,-39.27336,3.47136,39.27336,22476,43
331.91378,-4.01084,-48.06471,3.98530,48.06471,22476,43
332.45978,-4.55670,-57.05024,4.53116,57.05024,22476,43
332.89778,-4.99485,-64.10940,4.96931,64.10940,22476,43
333.33978,-5.26885,-67.32284,5.24331,67.32285,22476,43
333.70578,-4.88468,-57.90637,4.85914,57.90637,22412,43
334.14381,-4.44493,-48.39525,4.41939,48.39525,22412,43
334.56519,-4.02387,-39.06289,3.99833,39.06290,22412,43
335.01278,-3.57574,-30.55552,3.55020,30.55552,22412,43
335.58278,-3.00585,-22.02365,2.98031,22.02365,22412,43
336.32178,-2.26701,-13.89711,2.24147,13.89711,22412,43
337.02478,-1.61063,-7.53715,1.58509,7.53715,22412,43
337.54778,-2.16193,-16.82785,2.13639,16.82785,22476,43
338.08178,-2.69683,-25.16028,2.67129,25.16028,22476,44
338.58678,-3.20176,-34.07928,3.17622,34.07928,22476,44
339.06519,-3.67988,-42.40276,3.65434,42.40276,22476,44
339.58178,-4.19682,-51.16324,4.17128,51.16325,22476,44
340.13478,-4.74993,-60.14426,4.72439,60.14426,22476,44
340.66519,-5.28005,-68.69066,5.25450,68.69066,22476,44
341.04778,-5.03730,-61.44645,5.01176,61.44645,22412,44
341.46519,-4.61609,-52.02033,4.59055,52.02032,22412,44
341.81778,-4.26285,-44.24568,4.23731,44.24567,22412,44
342.26519,-3.81583,-34.93870,3.79029,34.93870,22412,44
342.73481,-3.34597,-26.61003,3.32043,26.61003,22412,44
343.36578,-2.71477,-18.56616,2.68923,18.56616,22412,44
344.15178,-1.92880,-10.59780,1.90326,10.59780,22412,44
344.70778,-1.81865,-11.72282,1.79311,11.72282,22412,44
345.27578,-2.39466,-20.25628,2.36911,20.25628,22476,45
345.80978,-2.92882,-29.01278,2.90328,29.01278,22476,45
346.31478,-3.43388,-38.15353,3.40834,38.15353,22476,45
346.82481,-3.94388,-46.97458,3.91834,46.97458,22476,45
347.36522,-4.48377,-55.88263,4.45823,55.88263,22476,45
347.90378,-5.02282,-64.50664,4.99727,64.50664,22476,45
348.33678,-5.25351,-66.86608,5.22797,66.86608,22476,45
348.66878,-4.90574,-58.31720,4.88020,58.31720,22412,45
349.06519,-4.50785,-49.57251,4.48231,49.57251,22412,45
349.47878,-4.09373,-40.38354,4.06819,40.38354,22412,45
349.96519,-3.60775,-30.98027,3.58221,30.98027,22412,45
350.55278,-3.01971,-22.05340,2.99417,22.05340,22412,45
351.26519,-2.30787,-14.29893,2.28233,14.29893,22412,45
351.98378,-1.60225,-7.17142,1.57671,7.17142,22412,45
352.48578,-2.12351,-16.15395,2.09797,16.15395,22476,45
353.05178,-2.69076,-25.03133,2.66522,25.03133,22476,46
353.56181,-3.20069,-34.07536,3.17515,34.07536,22476,46
354.06519,-3.70381,-42.85841,3.67827,42.85841,22476,46
354.58781,-4.22683,-51.65952,4.20129,51.65952,22476,46
355.13981,-4.77879,-60.60509,4.75325,60.60509,22476,46
355.66581,-5.30495,-69.08002,5.27941,69.08002,22476,46
356.01378,-5.05775,-61.91410,5.03221,61.91410,22476,46
356.42778,-4.63917,-52.44249,4.61363,52.44249,22412,46
356.82778,-4.23890,-43.71456,4.21336,43.71456,22412,46
357.26519,-3.80189,-34.62475,3.77635,34.62475,22412,46
357.74678,-3.31995,-26.20388,3.29441,26.20388,22412,46
358.38981,-2.67672,-18.07787,2.65118,18.07787,22412,46
359.16519,-1.90189,-10.28141,1.87635,10.28141,22412,46
359.71178,-1.86237,-12.31525,1.83683,12.31525,22412,46
360.26981,-2.42674,-20.72903,2.40120,20.72902,22476,47
360.80578,-2.96289,-29.68783,2.93735,29.68784,22476,47
361.30178,-3.45909,-38.66088,3.43354,38.66088,22476,47
361.82878,-3.98604,-47.70847,3.96050,47.70847,22476,47
362.31078,-4.46795,-55.58301,4.44241,55.58301,22476,47
362.81281,-4.97003,-63.67932,4.94449,63.67932,22476,47
363.24578,-5.34232,-69.25518,5.31678,69.25518,22476,47
363.56578,-4.99634,-60.41496,4.97080,60.41496,22412,47
363.99381,-4.56506,-50.83812,4.53952,50.83812,22412,47
364.41778,-4.14093,-41.36650,4.11539,41.36650,22412,47
364.85378,-3.70500,-32.66789,3.67946,32.66788,22412,47
365.38581,-3.17281,-24.00940,3.14727,24.00940,22412,47
366.06519,-2.49393,-15.93858,2.46839,15.93858,22412,47
366.86078,-1.69793,-8.06789,1.67239,8.06789,22412,47
367.35278,-2.03380,-14.82168,2.00826,14.82168,22604,47
367.89578,-2.57895,-23.22018,2.55341,23.22018,22604,48
368.37281,-3.05605,-31.47211,3.03051,31.47211,22604,48
368.77781,-3.46123,-38.74725,3.43569,38.74725,22604,48
369.26378,-3.94724,-47.04447,3.92170,47.04447,22604,48
369.79178,-4.47511,-55.74936,4.44957,55.74936,22604,48
370.34478,-5.02818,-64.70679,5.00264,64.70679,22604,48
370.74781,-5.30249,-68.10980,5.27695,68.10980,22604,48
371.12078,-4.90811,-58.33548,4.88257,58.33548,22540,48
371.50978,-4.51722,-49.78884,4.49168,49.78885,22540,48
371.93078,-4.09615,-40.28885,4.07061,40.28885,22540,48
372.39278,-3.63412,-31.32631,3.60858,31.32631,22540,48
372.96519,-3.06197,-22.53166,3.03643,22.53166,22540,48
373.67778,-2.34931,-14.56464,2.32377,14.56464,22540,48
374.41778,-1.62163,-7.28730,1.59609,7.28730,22540,48
374.89778,-2.11986,-16.10743,2.09432,16.10743,22604,48
375.46519,-2.68831,-25.04464,2.66277,25.04464,22604,49
375.91878,-3.14228,-33.10182,3.11674,33.10182,22604,49
376.38478,-3.60833,-41.15807,3.58279,41.15807,22604,49
376.86522,-4.08824,-49.30580,4.06270,49.30580,22604,49
377.40578,-4.62942,-58.20434,4.60387,58.20434,22604,49
377.80781,-5.03135,-64.73895,5.00581,64.73895,22604,49
378.22378,-5.25786,-67.00527,5.23232,67.00527,22604,49
378.61078,-4.85382,-57.22247,4.82828,57.22247,22540,49
379.04678,-4.41643,-47.79043,4.39088,47.79043,22540,49
379.42481,-4.03828,-39.19573,4.01274,39.19573,22540,49
379.89778,-3.56518,-30.13232,3.53964,30.13232,22540,49
380.47278,-2.99031,-21.56167,2.96477,21.56166,22540,49
381.21281,-2.25048,-13.55356,2.22494,13.55356,22540,49
381.96078,-1.60730,-7.44900,1.58176,7.44900,22540,49
382.56519,-1.93979,-13.73492,1.91425,13.73492,22476,49
383.15478,-2.53176,-22.68222,2.50622,22.68222,22476,50
383.66519,-3.04177,-31.33777,3.01623,31.33777,22476,50
384.17278,-3.54989,-40.19522,3.52435,40.19522,22476,50
384.70178,-4.07881,-49.20883,4.05327,49.20883,22476,50
385.23578,-4.61294,-57.99931,4.58739,57.99931,22476,50
385.76978,-5.14690,-66.62539,5.12136,66.62539,22476,50
386.16519,-5.16804,-64.67126,5.14250,64.67126,22476,50
386.56519,-4.75863,-55.06585,4.73309,55.06585,22412,50
386.96519,-4.35803,-46.48130,4.33249,46.48130,22412,50
387.37578,-3.94688,-37.29871,3.92134,37.29871,22412,50
387.86578,-3.45692,-28.18678,3.43137,28.18678,22412,50
388.50778,-2.81482,-19.44075,2.78928,19.44075,22412,50
389.26519,-2.05770,-11.77250,2.03216,11.77250,22412,50
389.86522,-1.74665,-10.23567,1.72111,10.23567,22412,50
390.43878,-2.33378,-19.27630,2.30824,19.27630,22476,51
390.96519,-2.86003,-27.85056,2.83449,27.85056,22476,51
391.46519,-3.36016,-36.94903,3.33462,36.94903,22476,51
391.93878,-3.83411,-44.96038,3.80857,44.96038,22476,51
392.42481,-4.32009,-53.12387,4.29455,53.12387,22476,51
392.96519,-4.85998,-61.90220,4.83444,61.90220,22476,51
393.41378,-5.30914,-69.16720,5.28360,69.16721,22476,51
393.71078,-5.10063,-62.87500,5.07509,62.87500,22476,51
394.07678,-4.72867,-54.37754,4.70313,54.37754,22412,51
394.51481,-4.29007,-44.81462,4.26453,44.81462,22412,51
394.96519,-3.84006,-35.16182,3.81452,35.16182,22412,51
395.46519,-3.34020,-26.31010,3.31466,26.31010,22412,51
396.10981,-2.69490,-18.09268,2.66936,18.09268,22412,51
396.86522,-1.94001,-10.54824,1.91447,10.54824,22412,51
397.42178,-1.86394,-12.19690,1.83840,12.19690,22412,51
397.97878,-2.42794,-20.69203,2.40240,20.69203,22476,52
398.49678,-2.94611,-29.56009,2.92057,29.56009,22476,52
398.96519,-3.41436,-37.85060,3.38882,37.85061,22476,52
399.46781,-3.91728,-46.41231,3.89174,46.41231,22476,52
399.96519,-4.41432,-54.71147,4.38878,54.71147,22476,52
400.52478,-4.97419,-63.73373,4.94865,63.73373,22476,52
400.97678,-5.31305,-68.39943,5.28751,68.39943,22476,52
401.35581,-4.91116,-58.31932,4.88562,58.31932,22412,52
401.77478,-4.49033,-49.13753,4.46479,49.13753,22412,52
402.19478,-4.07014,-39.71957,4.04460,39.71957,22412,52
402.66519,-3.60017,-30.56374,3.57463,30.56374,22412,52
403.26278,-3.00219,-21.59741,2.97665,21.59741,22412,52
403.96519,-2.30033,-13.93599,2.27479,13.93599,22412,52
404.67578,-1.63046,-7.52341,1.60492,7.52341,22412,52
405.18681,-2.16934,-16.79087,2.14380,16.79087,22476,52
405.74381,-2.72738,-25.70528,2.70183,25.70528,22476,53
406.18978,-3.17335,-33.64338,3.14781,33.64338,22476,53
406.57278,-3.55633,-40.18228,3.53079,40.18228,22476,53
407.06519,-4.04834,-48.56854,4.02280,48.56853,22476,53
407.56181,-4.54526,-56.79428,4.51971,56.79428,22476,53
408.07878,-5.06231,-65.16688,5.03677,65.16688,22476,53
408.50478,-5.23556,-66.25703,5.21002,66.25703,22476,53
408.87878,-4.84775,-56.93680,4.82221,56.93680,22412,53
409.32278,-4.40258,-47.38068,4.37703,47.38068,22412,53
409.74781,-3.97752,-37.81623,3.95198,37.81623,22412,53
410.23378,-3.49148,-28.69795,3.46594,28.69795,22412,53
410.83578,-2.88951,-20.07394,2.86397,20.07394,22412,53
411.57878,-2.14628,-12.46123,2.12074,12.46123,22412,53
412.21078,-1.73406,-9.64551,1.70852,9.64551,22412,53
412.75878,-2.29829,-18.77897,2.27275,18.77897,22476,54
413.27381,-2.81346,-27.12900,2.78792,27.12900,22476,54
413.75278,-3.29268,-35.68126,3.26713,35.68126,22476,54
414.26519,-3.80469,-44.46732,3.77914,44.46732,22476,54
414.78581,-4.32570,-53.18240,4.30016,53.18240,22476,54
415.27781,-4.81749,-61.14578,4.79195,61.14577,22476,54
415.76978,-5.30976,-69.15586,5.28421,69.15585,22476,54
416.10878,-5.05548,-61.76792,5.02994,61.76793,22412,54
416.47478,-4.68497,-53.34554,4.65943,53.34554,22412,54
416.88581,-4.27359,-44.40845,4.24805,44.40845,22412,54
417.30978,-3.84962,-35.22197,3.82408,35.22197,22412,54
417.76519,-3.39465,-26.94131,3.36911,26.94131,22412,54
418.40178,-2.75750,-18.59311,2.73196,18.59311,22412,54
419.16519,-1.99452,-10.98375,1.96898,10.98375,22412,54
419.74978,-1.84521,-11.71978,1.81967,11.71978,22412,54
420.29378,-2.39745,-20.16855,2.37191,20.16855,22476,55
420.81681,-2.92066,-29.11263,2.89512,29.11263,22476,55
421.31378,-3.41774,-38.08075,3.39220,38.08075,22476,55
421.85378,-3.95769,-47.15062,3.93215,47.15062,22476,55
422.36522,-4.46860,-55.62926,4.44306,55.62926,22476,55
422.92278,-5.02663,-64.61574,5.00109,64.61574,22476,55
423.36978,-5.24173,-66.47261,5.21619,66.47261,22476,55
423.76519,-4.83177,-56.65468,4.80623,56.65469,22412,55
424.16519,-4.43067,-47.96746,4.40513,47.96746,22412,55
424.56878,-4.02658,-38.80635,4.00104,38.80635,22412,55
425.06519,-3.53050,-29.19547,3.50496,29.19547,22412,55
425.57778,-3.01752,-21.64836,2.99198,21.64836,22412,55
426.32878,-2.26672,-13.51096,2.24118,13.51096,22412,55
426.97878,-1.66933,-7.89006,1.64379,7.89006,22412,55
427.48178,-2.20058,-17.15619,2.17504,17.15619,22476,55
428.04081,-2.76062,-26.23760,2.73508,26.23760,22476,56
428.53778,-3.25771,-35.18023,3.23217,35.18023,22476,56
429.00181,-3.72169,-43.16396,3.69615,43.16396,22476,56
429.54178,-4.26170,-52.17164,4.23616,52.17164,22476,56
430.06519,-4.78460,-60.67096,4.75906,60.67096,22476,56
430.60981,-5.32973,-69.50255,5.30419,69.50256,22476,56
430.96578,-5.01956,-60.86333,4.99402,60.86333,22412,56
431.39578,-4.58572,-51.25082,4.56018,51.25082,22412,56
431.81778,-4.16345,-41.89088,4.13791,41.89088,22412,56
432.26519,-3.71659,-32.65680,3.69105,32.65680,22412,56
432.81078,-3.17042,-23.58153,3.14488,23.58153,22412,56
433.52678,-2.45448,-15.43397,2.42894,15.43397,22412,56
434.26578,-1.71555,-8.04857,1.69001,8.04857,22412,56
434.76519,-2.04830,-14.92930,2.02276,14.92930,22476,56
435.32278,-2.60858,-23.71243,2.58304,23.71243,22476,57
435.82578,-3.11150,-32.65151,3.08596,32.65151,22476,57
436.33878,-3.62467,-41.61105,3.59913,41.61105,22476,57
436.86522,-4.15061,-50.42749,4.12507,50.42749,22476,57
437.40578,-4.69172,-59.20687,4.66617,59.20687,22476,57
437.95178,-5.23777,-67.95786,5.21223,67.95786,22476,57
438.26519,-5.15611,-64.28734,5.13057,64.28735,22476,57
438.66519,-4.74733,-54.67230,4.72179,54.67231,22412,57
439.10081,-4.31069,-45.18028,4.28515,45.18028,22412,57
439.48481,-3.92671,-36.64784,3.90117,36.64784,22412,57
439.92881,-3.48268,-28.34371,3.45714,28.34371,22412,57
440.55278,-2.85874,-19.50195,2.83320,19.50195,22412,57
441.31478,-2.09646,-11.91314,2.07092,11.91314,22412,57
441.91081,-1.77057,-10.21631,1.74503,10.21631,22412,57
442.46281,-2.33646,-19.26403,2.31092,19.26403,22604,57
442.96519,-2.83874,-27.61843,2.81320,27.61843,22604,58
443.46519,-3.33886,-36.81983,3.31332,36.81983,22604,58
443.99378,-3.86785,-45.65458,3.84231,45.65458,22604,58
444.53378,-4.40784,-54.61832,4.38230,54.61832,22604,58
444.97981,-4.85373,-61.79962,4.82819,61.79962,22604,58
445.36522,-5.23882,-67.98515,5.21328,67.98515,22604,58
445.75478,-5.06214,-61.98987,5.03660,61.98986,22540,58
446.12778,-4.68419,-53.34665,4.65865,53.34665,22540,58
446.51678,-4.29481,-44.83342,4.26926,44.83342,22540,58
446.94878,-3.86282,-35.35888,3.83728,35.35888,22540,58
447.38178,-3.42975,-27.30841,3.40421,27.30841,22540,58
447.96519,-2.84680,-19.28584,2.82126,19.28584,22540,58
448.74781,-2.06355,-11.48124,2.03801,11.48124,22540,58
449.31978,-1.80733,-10.71501,1.78179,10.71501,22540,58
449.86522,-2.36446,-19.73400,2.33892,19.73400,22604,59
450.36678,-2.86676,-28.16798,2.84122,28.16798,22604,59
450.86522,-3.36490,-37.29040,3.33935,37.29040,22604,59
451.38778,-3.88784,-46.16947,3.86230,46.16948,22604,59
451.94878,-4.44872,-55.29356,4.42318,55.29356,22604,59
452.44181,-4.94171,-63.19484,4.91617,63.19484,22604,59
452.91678,-5.29245,-68.00913,5.26691,68.00913,22604,59
453.25978,-4.92800,-58.80347,4.90246,58.80347,22540,59
453.59681,-4.58886,-51.33446,4.56332,51.33446,22540,59
453.98078,-4.20463,-42.98371,4.17909,42.98371,22540,59
454.35178,-3.83375,-34.69779,3.80821,34.69779,22540,59
454.79578,-3.38980,-26.62847,3.36426,26.62847,22540,59
455.44981,-2.73570,-18.08942,2.71016,18.08942,22540,59
456.22981,-1.95569,-10.39716,1.93015,10.39716,22540,59
456.56519,-1.63005,-7.03562,1.60451,7.03562,22540,59